ts_recv,ts_event,rtype,publisher_id,instrument_id,action,side,depth,price,size,flags,ts_in_delta,sequence,bid_px_00,ask_px_00,bid_sz_00,ask_sz_00,bid_ct_00,ask_ct_00,bid_px_01,ask_px_01,bid_sz_01,ask_sz_01,bid_ct_01,ask_ct_01,bid_px_02,ask_px_02,bid_sz_02,ask_sz_02,bid_ct_02,ask_ct_02,bid_px_03,ask_px_03,bid_sz_03,ask_sz_03,bid_ct_03,ask_ct_03,bid_px_04,ask_px_04,bid_sz_04,ask_sz_04,bid_ct_04,ask_ct_04,bid_px_05,ask_px_05,bid_sz_05,ask_sz_05,bid_ct_05,ask_ct_05,bid_px_06,ask_px_06,bid_sz_06,ask_sz_06,bid_ct_06,ask_ct_06,bid_px_07,ask_px_07,bid_sz_07,ask_sz_07,bid_ct_07,ask_ct_07,bid_px_08,ask_px_08,bid_sz_08,ask_sz_08,bid_ct_08,ask_ct_08,bid_px_09,ask_px_09,bid_sz_09,ask_sz_09,bid_ct_09,ask_ct_09,symbol,ofi_best_level,multi_level_ofi,integrated_ofi
2024-10-21T11:54:29.221230963Z,2024-10-21T11:54:29.221064336Z,10,2,38,C,B,1,233.62,2,130,166627,11405847,233.67,233.74,139,200,1,1,233.53,233.75,10,1,1,1,233.52,233.77,200,8,1,1,233.48,233.78,28,150,1,2,233.45,233.79,15,29,1,1,233.4,233.8,110,25,2,1,233.39,233.94,10,200,1,1,233.31,233.98,110,44,2,3,233.3,234.0,100,155,1,7,233.25,234.13,55,400,2,1,AAPL,,,
2024-10-21T11:54:29.223936626Z,2024-10-21T11:54:29.223769812Z,10,2,38,A,B,0,233.67,2,130,166814,11405848,233.67,233.74,141,200,2,1,233.53,233.75,10,1,1,1,233.52,233.77,200,8,1,1,233.48,233.78,28,150,1,2,233.45,233.79,15,29,1,1,233.4,233.8,110,25,2,1,233.39,233.94,10,200,1,1,233.31,233.98,110,44,2,3,233.3,234.0,100,155,1,7,233.25,234.13,55,400,2,1,AAPL,0,0.0,-0.0
2024-10-21T11:54:29.225196809Z,2024-10-21T11:54:29.225030400Z,10,2,38,A,B,0,233.67,3,130,166409,11405849,233.67,233.74,144,200,3,1,233.53,233.75,10,1,1,1,233.52,233.77,200,8,1,1,233.48,233.78,28,150,1,2,233.45,233.79,15,29,1,1,233.4,233.8,110,25,2,1,233.39,233.94,10,200,1,1,233.31,233.98,110,44,2,3,233.3,234.0,100,155,1,7,233.25,234.13,55,400,2,1,AAPL,0,0.0,-0.0
2024-10-21T11:54:29.712600612Z,2024-10-21T11:54:29.712434212Z,10,2,38,A,B,2,233.52,200,130,166400,11406449,233.67,233.74,144,200,3,1,233.53,233.75,10,1,1,1,233.52,233.77,400,8,2,1,233.48,233.78,28,150,1,2,233.45,233.79,15,29,1,1,233.4,233.8,110,25,2,1,233.39,233.94,10,200,1,1,233.31,233.98,110,44,2,3,233.3,234.0,100,155,1,7,233.25,234.13,55,400,2,1,AAPL,0,0.0,-0.0
2024-10-21T11:54:29.764839221Z,2024-10-21T11:54:29.764673165Z,10,2,38,C,B,2,233.52,200,130,166056,11406501,233.67,233.74,144,200,3,1,233.53,233.75,10,1,1,1,233.52,233.77,200,8,1,1,233.48,233.78,28,150,1,2,233.45,233.79,15,29,1,1,233.4,233.8,110,25,2,1,233.39,233.94,10,200,1,1,233.31,233.98,110,44,2,3,233.3,234.0,100,155,1,7,233.25,234.13,55,400,2,1,AAPL,0,0.0,-0.0
2024-10-21T11:54:29.764851707Z,2024-10-21T11:54:29.764685027Z,10,2,38,A,B,1,233.54,400,130,166680,11406502,233.67,233.74,144,200,3,1,233.54,233.75,400,1,1,1,233.53,233.77,10,8,1,1,233.48,233.78,28,150,1,2,233.45,233.79,15,29,1,1,233.4,233.8,110,25,2,1,233.39,233.94,10,200,1,1,233.31,233.98,110,44,2,3,233.3,234.0,100,155,1,7,233.25,234.13,55,400,2,1,AAPL,0,0.0,-0.0
2024-10-21T11:54:36.289594629Z,2024-10-21T11:54:36.289427977Z,10,2,38,A,A,6,233.9,200,130,166652,11409388,233.67,233.74,144,200,3,1,233.54,233.75,400,1,1,1,233.53,233.77,10,8,1,1,233.48,233.78,28,150,1,2,233.45,233.79,15,29,1,1,233.4,233.8,110,25,2,1,233.39,233.9,10,200,1,1,233.31,233.94,110,200,2,1,233.3,233.98,100,44,1,3,233.25,234.0,55,155,2,7,AAPL,-155,-0.8732394366197183,0.01127208160084643
2024-10-21T11:54:37.990960617Z,2024-10-21T11:54:37.990793976Z,10,2,38,A,A,0,233.73,200,130,166641,11410372,233.67,233.73,144,200,3,1,233.54,233.75,400,1,1,1,233.53,233.77,10,8,1,1,233.48,233.78,28,150,1,2,233.45,233.79,15,29,1,1,233.4,233.8,110,25,2,1,233.39,233.9,10,200,1,1,233.31,233.94,110,200,2,1,233.3,233.98,100,44,1,3,233.25,234.0,55,155,2,7,AAPL,-155,-0.9202226345083488,0.011878557234287147
2024-10-21T11:54:39.124458000Z,2024-10-21T11:54:39.124291588Z,10,2,38,C,A,0,233.73,200,130,166412,11410864,233.67,233.75,144,1,3,1,233.54,233.77,400,8,1,1,233.53,233.78,10,150,1,2,233.48,233.79,28,29,1,1,233.45,233.8,15,25,1,1,233.4,233.9,110,200,2,1,233.39,233.94,10,200,1,1,233.31,233.98,110,44,2,3,233.3,234.0,100,155,1,7,233.25,234.13,55,400,2,1,AAPL,245,1.4,-0.018071692114905405
2024-10-21T11:54:39.134307134Z,2024-10-21T11:54:39.134140341Z,10,2,38,A,A,0,233.74,200,130,166793,11410873,233.67,233.74,144,200,3,1,233.54,233.75,400,1,1,1,233.53,233.77,10,8,1,1,233.48,233.78,28,150,1,2,233.45,233.79,15,29,1,1,233.4,233.8,110,25,2,1,233.39,233.9,10,200,1,1,233.31,233.94,110,200,2,1,233.3,233.98,100,44,1,3,233.25,234.0,55,155,2,7,AAPL,90,0.5357142857142857,-0.006915188309275027
2024-10-21T11:54:41.233347439Z,2024-10-21T11:54:41.233181043Z,10,2,38,C,B,0,233.67,3,130,166396,11411787,233.67,233.74,141,200,2,1,233.54,233.75,400,1,1,1,233.53,233.77,10,8,1,1,233.48,233.78,28,150,1,2,233.45,233.79,15,29,1,1,233.4,233.8,110,25,2,1,233.39,233.9,10,200,1,1,233.31,233.94,110,200,2,1,233.3,233.98,100,44,1,3,233.25,234.0,55,155,2,7,AAPL,90,0.5546218487394958,-0.007159253779014146
2024-10-21T11:54:41.234786818Z,2024-10-21T11:54:41.234620509Z,10,2,38,A,B,0,233.67,1,130,166309,11411790,233.67,233.74,142,200,3,1,233.54,233.75,400,1,1,1,233.53,233.77,10,8,1,1,233.48,233.78,28,150,1,2,233.45,233.79,15,29,1,1,233.4,233.8,110,25,2,1,233.39,233.9,10,200,1,1,233.31,233.94,110,200,2,1,233.3,233.98,100,44,1,3,233.25,234.0,55,155,2,7,AAPL,90,0.5714285714285714,-0.007376200863226696
2024-10-21T11:54:41.236073416Z,2024-10-21T11:54:41.235907431Z,10,2,38,C,B,0,233.67,1,130,165985,11411831,233.67,233.74,141,200,2,1,233.54,233.75,400,1,1,1,233.53,233.77,10,8,1,1,233.48,233.78,28,150,1,2,233.45,233.79,15,29,1,1,233.4,233.8,110,25,2,1,233.39,233.9,10,200,1,1,233.31,233.94,110,200,2,1,233.3,233.98,100,44,1,3,233.25,234.0,55,155,2,7,AAPL,90,0.5864661654135339,-0.007570311412258978
2024-10-21T11:54:41.236144516Z,2024-10-21T11:54:41.235977207Z,10,2,38,C,B,0,233.67,2,130,167309,11411832,233.67,233.74,139,200,1,1,233.54,233.75,400,1,1,1,233.53,233.77,10,8,1,1,233.48,233.78,28,150,1,2,233.45,233.79,15,29,1,1,233.4,233.8,110,25,2,1,233.39,233.9,10,200,1,1,233.31,233.94,110,200,2,1,233.3,233.98,100,44,1,3,233.25,234.0,55,155,2,7,AAPL,90,0.6,-0.007745010906388031
2024-10-21T11:54:41.238784694Z,2024-10-21T11:54:41.238618235Z,10,2,38,A,B,0,233.7,2,130,166459,11411834,233.7,233.74,2,200,1,1,233.67,233.75,139,1,1,1,233.54,233.77,400,8,1,1,233.53,233.78,10,150,1,2,233.48,233.79,28,29,1,1,233.45,233.8,15,25,1,1,233.4,233.9,110,200,2,1,233.39,233.94,10,200,1,1,233.31,233.98,110,44,2,3,233.3,234.0,100,155,1,7,AAPL,190,1.2794612794612794,-0.016515735939547988
2024-10-21T11:54:41.239993456Z,2024-10-21T11:54:41.239827037Z,10,2,38,A,B,0,233.7,3,130,166419,11411835,233.7,233.74,5,200,2,1,233.67,233.75,139,1,1,1,233.54,233.77,400,8,1,1,233.53,233.78,10,150,1,2,233.48,233.79,28,29,1,1,233.45,233.8,15,25,1,1,233.4,233.9,110,200,2,1,233.39,233.94,10,200,1,1,233.31,233.98,110,44,2,3,233.3,234.0,100,155,1,7,AAPL,190,1.2908704883227176,-0.016663010017989817
2024-10-21T11:54:50.970463583Z,2024-10-21T11:54:50.970297264Z,10,2,38,C,A,4,233.79,29,130,166319,11416279,233.7,233.74,5,200,2,1,233.67,233.75,139,1,1,1,233.54,233.77,400,8,1,1,233.53,233.78,10,150,1,2,233.48,233.8,28,25,1,1,233.45,233.9,15,200,1,1,233.4,233.94,110,200,2,1,233.39,233.98,10,44,1,3,233.31,234.0,110,155,2,7,233.3,234.13,100,400,1,1,AAPL,590,4.4224872231686545,-0.05708701962800491
2024-10-21T11:54:50.970503601Z,2024-10-21T11:54:50.970336474Z,10,2,38,A,A,3,233.78,29,130,167127,11416280,233.7,233.74,5,200,2,1,233.67,233.75,139,1,1,1,233.54,233.77,400,8,1,1,233.53,233.78,10,179,1,3,233.48,233.8,28,25,1,1,233.45,233.9,15,200,1,1,233.4,233.94,110,200,2,1,233.39,233.98,10,44,1,3,233.31,234.0,110,155,2,7,233.3,234.13,100,400,1,1,AAPL,590,4.122270742358078,-0.05321171976441267
2024-10-21T11:54:53.247698803Z,2024-10-21T11:54:53.247532557Z,10,2,38,C,B,0,233.7,3,130,166246,11417889,233.7,233.74,2,200,1,1,233.67,233.75,139,1,1,1,233.54,233.77,400,8,1,1,233.53,233.78,10,179,1,3,233.48,233.8,28,25,1,1,233.45,233.9,15,200,1,1,233.4,233.94,110,200,2,1,233.39,233.98,10,44,1,3,233.31,234.0,110,155,2,7,233.3,234.13,100,400,1,1,AAPL,590,3.898348157560356,-0.05032124832867107
2024-10-21T11:54:53.249060172Z,2024-10-21T11:54:53.248893986Z,10,2,38,C,B,0,233.7,2,130,166186,11417890,233.67,233.74,139,200,1,1,233.54,233.75,400,1,1,1,233.53,233.77,10,8,1,1,233.48,233.78,28,179,1,3,233.45,233.8,15,25,1,1,233.4,233.9,110,200,2,1,233.39,233.94,10,200,1,1,233.31,233.98,110,44,2,3,233.3,234.0,100,155,1,7,233.25,234.13,55,400,2,1,AAPL,535,3.4123006833712988,-0.04404717668097673
2024-10-21T11:54:53.251488043Z,2024-10-21T11:54:53.251320969Z,10,2,38,A,B,0,233.67,3,130,167074,11417891,233.67,233.74,142,200,2,1,233.54,233.75,400,1,1,1,233.53,233.77,10,8,1,1,233.48,233.78,28,179,1,3,233.45,233.8,15,25,1,1,233.4,233.9,110,200,2,1,233.39,233.94,10,200,1,1,233.31,233.98,110,44,2,3,233.3,234.0,100,155,1,7,233.25,234.13,55,400,2,1,AAPL,535,3.3126934984520124,-0.0427614121250526
2024-10-21T11:54:53.252712795Z,2024-10-21T11:54:53.252546517Z,10,2,38,A,B,0,233.67,2,130,166278,11417894,233.67,233.74,144,200,3,1,233.54,233.75,400,1,1,1,233.53,233.77,10,8,1,1,233.48,233.78,28,179,1,3,233.45,233.8,15,25,1,1,233.4,233.9,110,200,2,1,233.39,233.94,10,200,1,1,233.31,233.98,110,44,2,3,233.3,234.0,100,155,1,7,233.25,234.13,55,400,2,1,AAPL,535,3.230188679245283,-0.041696410917409776
2024-10-21T11:54:55.503664023Z,2024-10-21T11:54:55.503497741Z,10,2,38,C,B,3,233.48,28,130,166282,11418757,233.67,233.74,144,200,3,1,233.54,233.75,400,1,1,1,233.53,233.77,10,8,1,1,233.45,233.78,15,179,1,3,233.4,233.8,110,25,2,1,233.39,233.9,10,200,1,1,233.31,233.94,110,200,2,1,233.3,233.98,100,44,1,3,233.25,234.0,55,155,2,7,233.24,234.13,1,400,1,1,AAPL,534,3.1847044378179263,-0.041109284340870335
2024-10-21T11:54:55.503707349Z,2024-10-21T11:54:55.503541005Z,10,2,38,A,B,3,233.51,27,130,166344,11418758,233.67,233.74,144,200,3,1,233.54,233.75,400,1,1,1,233.53,233.77,10,8,1,1,233.51,233.78,27,179,1,3,233.45,233.8,15,25,1,1,233.4,233.9,110,200,2,1,233.39,233.94,10,200,1,1,233.31,233.98,110,44,2,3,233.3,234.0,100,155,1,7,233.25,234.13,55,400,2,1,AAPL,589,3.4444444444444446,-0.04446209964778314
2024-10-21T11:54:55.551973702Z,2024-10-21T11:54:55.551806996Z,10,2,38,A,B,1,233.59,400,130,166706,11418795,233.67,233.74,144,200,3,1,233.59,233.75,400,1,1,1,233.53,233.77,10,8,1,1,233.51,233.78,27,179,1,3,233.45,233.8,15,25,1,1,233.4,233.9,110,200,2,1,233.39,233.94,10,200,1,1,233.31,233.98,110,44,2,3,233.3,234.0,100,155,1,7,233.25,234.13,55,400,2,1,AAPL,589,3.385569505369838,-0.04370212123904021
2024-10-21T11:54:58.133095032Z,2024-10-21T11:54:58.132928650Z,10,2,38,C,A,5,233.9,200,130,166382,11420067,233.67,233.74,144,200,3,1,233.59,233.75,400,1,1,1,233.53,233.77,10,8,1,1,233.51,233.78,27,179,1,3,233.45,233.8,15,25,1,1,233.4,233.94,110,200,2,1,233.39,233.98,10,44,1,3,233.31,234.0,110,155,2,7,233.3,234.13,100,400,1,1,233.25,234.17,55,1,2,1,AAPL,745,4.293260765167281,-0.05541891908364735
2024-10-21T11:54:58.134110732Z,2024-10-21T11:54:58.133944065Z,10,2,38,A,A,1,233.75,200,130,166667,11420068,233.67,233.74,144,200,3,1,233.59,233.75,400,201,1,2,233.53,233.77,10,8,1,1,233.51,233.78,27,179,1,3,233.45,233.8,15,25,1,1,233.4,233.94,110,200,2,1,233.39,233.98,10,44,1,3,233.31,234.0,110,155,2,7,233.3,234.13,100,400,1,1,233.25,234.17,55,1,2,1,AAPL,745,4.491511978422973,-0.05797801543176401
2024-10-21T11:55:09.125208612Z,2024-10-21T11:55:09.125042325Z,10,2,38,C,B,1,233.59,400,130,166287,11428279,233.67,233.74,144,200,3,1,233.53,233.75,10,201,1,2,233.51,233.77,27,8,1,1,233.45,233.78,15,179,1,3,233.4,233.8,110,25,2,1,233.39,233.94,10,200,1,1,233.31,233.98,110,44,2,3,233.3,234.0,100,155,1,7,233.25,234.13,55,400,2,1,233.24,234.17,1,1,1,1,AAPL,399,2.232167832167832,-0.02881360700838064
2024-10-21T11:55:09.125222408Z,2024-10-21T11:55:09.125055670Z,10,2,38,A,B,1,233.57,400,130,166738,11428280,233.67,233.74,144,200,3,1,233.57,233.75,400,201,1,2,233.53,233.77,10,8,1,1,233.51,233.78,27,179,1,3,233.45,233.8,15,25,1,1,233.4,233.94,110,200,2,1,233.39,233.98,10,44,1,3,233.31,234.0,110,155,2,7,233.3,234.13,100,400,1,1,233.25,234.17,55,1,2,1,AAPL,454,2.7160607455131154,-0.03505986682735247
2024-10-21T11:55:09.160176239Z,2024-10-21T11:55:09.160009889Z,10,2,38,C,A,3,233.78,29,130,166350,11428375,233.67,233.74,144,200,3,1,233.57,233.75,400,201,1,2,233.53,233.77,10,8,1,1,233.51,233.78,27,150,1,2,233.45,233.8,15,25,1,1,233.4,233.94,110,200,2,1,233.39,233.98,10,44,1,3,233.31,234.0,110,155,2,7,233.3,234.13,100,400,1,1,233.25,234.17,55,1,2,1,AAPL,454,2.8877782825988185,-0.03727645715659724
2024-10-21T11:55:09.160217682Z,2024-10-21T11:55:09.160051447Z,10,2,38,A,A,2,233.77,27,130,166235,11428376,233.67,233.74,144,200,3,1,233.57,233.75,400,201,1,2,233.53,233.77,10,35,1,2,233.51,233.78,27,150,1,2,233.45,233.8,15,25,1,1,233.4,233.94,110,200,2,1,233.39,233.98,10,44,1,3,233.31,234.0,110,155,2,7,233.3,234.13,100,400,1,1,233.25,234.17,55,1,2,1,AAPL,454,3.0551816958277254,-0.03943735925863802
2024-10-21T11:55:13.899318666Z,2024-10-21T11:55:13.899151539Z,10,2,38,A,B,1,233.59,400,130,167127,11431712,233.67,233.74,144,200,3,1,233.59,233.75,400,201,1,2,233.53,233.77,10,35,1,2,233.51,233.78,27,150,1,2,233.45,233.8,15,25,1,1,233.4,233.94,110,200,2,1,233.39,233.98,10,44,1,3,233.31,234.0,110,155,2,7,233.3,234.13,100,400,1,1,233.25,234.17,55,1,2,1,AAPL,109,1.3220133414190418,-0.017065012912801603
2024-10-21T11:55:22.016922342Z,2024-10-21T11:55:22.016715475Z,10,2,38,C,B,3,233.51,27,130,206867,11437208,233.67,233.74,144,200,3,1,233.59,233.75,400,201,1,2,233.53,233.77,10,35,1,2,233.45,233.78,15,150,1,2,233.4,233.8,110,25,2,1,233.39,233.94,10,200,1,1,233.31,233.98,110,44,2,3,233.3,234.0,100,155,1,7,233.25,234.13,55,400,2,1,233.24,234.17,1,1,1,1,AAPL,53,2.789473684210526,-0.03600750684548821
2024-10-21T11:55:22.060339836Z,2024-10-21T11:55:22.060173668Z,10,2,38,A,B,3,233.52,27,130,166168,11437365,233.67,233.74,144,200,3,1,233.59,233.75,400,201,1,2,233.53,233.77,10,35,1,2,233.52,233.78,27,150,1,2,233.45,233.8,15,25,1,1,233.4,233.94,110,200,2,1,233.39,233.98,10,44,1,3,233.31,234.0,110,155,2,7,233.3,234.13,100,400,1,1,233.25,234.17,55,1,2,1,AAPL,108,5.323943661971831,-0.0687233362116121
2024-10-21T11:55:22.132944892Z,2024-10-21T11:55:22.132778490Z,10,2,38,A,B,1,233.6,400,130,166402,11437593,233.67,233.74,144,200,3,1,233.6,233.75,400,201,1,2,233.53,233.77,10,35,1,2,233.52,233.78,27,150,1,2,233.45,233.8,15,25,1,1,233.4,233.94,110,200,2,1,233.39,233.98,10,44,1,3,233.31,234.0,110,155,2,7,233.3,234.13,100,400,1,1,233.25,234.17,55,1,2,1,AAPL,108,5.08235294117647,-0.06560479826587508
2024-10-21T11:55:26.448145163Z,2024-10-21T11:55:26.447978801Z,10,2,38,A,A,0,233.73,200,130,166362,11440665,233.67,233.73,144,200,3,1,233.6,233.75,400,201,1,2,233.53,233.77,10,35,1,2,233.52,233.78,27,150,1,2,233.45,233.8,15,25,1,1,233.4,233.94,110,200,2,1,233.39,233.98,10,44,1,3,233.31,234.0,110,155,2,7,233.3,234.13,100,400,1,1,233.25,234.17,55,1,2,1,AAPL,108,4.909090909090909,-0.06336827105226571
2024-10-21T11:55:30.365451020Z,2024-10-21T11:55:30.365285173Z,10,2,38,C,B,1,233.6,400,130,165847,11442747,233.67,233.73,144,200,3,1,233.53,233.75,10,201,1,2,233.52,233.77,27,35,1,2,233.45,233.78,15,150,1,2,233.4,233.8,110,25,2,1,233.39,233.94,10,200,1,1,233.31,233.98,110,44,2,3,233.3,234.0,100,155,1,7,233.25,234.13,55,400,2,1,233.24,234.17,1,1,1,1,AAPL,53,2.789473684210526,-0.03600750684548821
2024-10-21T11:55:30.365463941Z,2024-10-21T11:55:30.365297270Z,10,2,38,A,B,1,233.54,400,130,166671,11442749,233.67,233.73,144,200,3,1,233.54,233.75,400,201,1,2,233.53,233.77,10,35,1,2,233.52,233.78,27,150,1,2,233.45,233.8,15,25,1,1,233.4,233.94,110,200,2,1,233.39,233.98,10,44,1,3,233.31,234.0,110,155,2,7,233.3,234.13,100,400,1,1,233.25,234.17,55,1,2,1,AAPL,108,5.323943661971831,-0.0687233362116121
2024-10-21T11:55:30.377213560Z,2024-10-21T11:55:30.377046532Z,10,2,38,C,B,3,233.52,27,130,167028,11443045,233.67,233.73,144,200,3,1,233.54,233.75,400,201,1,2,233.53,233.77,10,35,1,2,233.45,233.78,15,150,1,2,233.4,233.8,110,25,2,1,233.39,233.94,10,200,1,1,233.31,233.98,110,44,2,3,233.3,234.0,100,155,1,7,233.25,234.13,55,400,2,1,233.24,234.17,1,1,1,1,AAPL,107,5.986013986013986,-0.07726957267911602
2024-10-21T11:55:30.377277043Z,2024-10-21T11:55:30.377110788Z,10,2,38,A,B,2,233.53,30,130,166255,11443050,233.67,233.73,144,200,3,1,233.54,233.75,400,201,1,2,233.53,233.77,40,35,2,2,233.45,233.78,15,150,1,2,233.4,233.8,110,25,2,1,233.39,233.94,10,200,1,1,233.31,233.98,110,44,2,3,233.3,234.0,100,155,1,7,233.25,234.13,55,400,2,1,233.24,234.17,1,1,1,1,AAPL,107,6.6875,-0.08632460072744993
2024-10-21T11:55:30.509581691Z,2024-10-21T11:55:30.509413271Z,10,2,38,C,A,2,233.77,27,130,168420,11443614,233.67,233.73,144,200,3,1,233.54,233.75,400,201,1,2,233.53,233.77,40,8,2,1,233.45,233.78,15,150,1,2,233.4,233.8,110,25,2,1,233.39,233.94,10,200,1,1,233.31,233.98,110,44,2,3,233.3,234.0,100,155,1,7,233.25,234.13,55,400,2,1,233.24,234.17,1,1,1,1,AAPL,107,7.379310344827586,-0.09525473183718614
2024-10-21T11:55:30.509624409Z,2024-10-21T11:55:30.509458075Z,10,2,38,A,A,4,233.79,27,130,166334,11443615,233.67,233.73,144,200,3,1,233.54,233.75,400,201,1,2,233.53,233.77,40,8,2,1,233.45,233.78,15,150,1,2,233.4,233.79,110,27,2,1,233.39,233.8,10,25,1,1,233.31,233.94,110,200,2,1,233.3,233.98,100,44,1,3,233.25,234.0,55,155,2,7,233.24,234.13,1,400,1,1,AAPL,-293,-9.328509406657018,0.12041567849150324
2024-10-21T11:55:30.560115755Z,2024-10-21T11:55:30.559949308Z,10,2,38,A,B,1,233.55,400,130,166447,11443807,233.67,233.73,144,200,3,1,233.55,233.75,400,201,1,2,233.53,233.77,40,8,2,1,233.45,233.78,15,150,1,2,233.4,233.79,110,27,2,1,233.39,233.8,10,25,1,1,233.31,233.94,110,200,2,1,233.3,233.98,100,44,1,3,233.25,234.0,55,155,2,7,233.24,234.13,1,400,1,1,AAPL,-293,-6.43956043956044,0.08312410972790084
2024-10-21T11:55:31.195089596Z,2024-10-21T11:55:31.194923125Z,10,2,38,A,B,2,233.54,27,130,166471,11444867,233.67,233.73,144,200,3,1,233.55,233.75,400,201,1,2,233.54,233.77,27,8,1,1,233.53,233.78,40,150,2,2,233.45,233.79,15,27,1,1,233.4,233.8,110,25,2,1,233.39,233.94,10,200,1,1,233.31,233.98,110,44,2,3,233.3,234.0,100,155,1,7,233.25,234.13,55,400,2,1,AAPL,-238,-4.0,0.05163340604258687
2024-10-21T11:55:31.195189780Z,2024-10-21T11:55:31.195023714Z,10,2,38,C,B,3,233.53,30,130,166066,11444870,233.67,233.73,144,200,3,1,233.55,233.75,400,201,1,2,233.54,233.77,27,8,1,1,233.53,233.78,10,150,1,2,233.45,233.79,15,27,1,1,233.4,233.8,110,25,2,1,233.39,233.94,10,200,1,1,233.31,233.98,110,44,2,3,233.3,234.0,100,155,1,7,233.25,234.13,55,400,2,1,AAPL,-238,-3.3286713286713288,0.04296765957390097
2024-10-21T11:55:34.079427496Z,2024-10-21T11:55:34.079261198Z,10,2,38,C,B,0,233.67,139,130,166298,11447051,233.67,233.73,5,200,2,1,233.55,233.75,400,201,1,2,233.54,233.77,27,8,1,1,233.53,233.78,10,150,1,2,233.45,233.79,15,27,1,1,233.4,233.8,110,25,2,1,233.39,233.94,10,200,1,1,233.31,233.98,110,44,2,3,233.3,234.0,100,155,1,7,233.25,234.13,55,400,2,1,AAPL,-238,-2.7755102040816326,0.035827261335672524
2024-10-21T11:55:35.303088788Z,2024-10-21T11:55:35.302921978Z,10,2,38,C,B,0,233.67,2,130,166810,11448345,233.67,233.73,3,200,1,1,233.55,233.75,400,201,1,2,233.54,233.77,27,8,1,1,233.53,233.78,10,150,1,2,233.45,233.79,15,27,1,1,233.4,233.8,110,25,2,1,233.39,233.94,10,200,1,1,233.31,233.98,110,44,2,3,233.3,234.0,100,155,1,7,233.25,234.13,55,400,2,1,AAPL,-238,-2.5,0.032270878776616795
2024-10-21T11:55:35.303234088Z,2024-10-21T11:55:35.303067914Z,10,2,38,C,B,0,233.67,3,130,166174,11448346,233.55,233.73,400,200,1,1,233.54,233.75,27,201,1,2,233.53,233.77,10,8,1,1,233.45,233.78,15,150,1,2,233.4,233.79,110,27,2,1,233.39,233.8,10,25,1,1,233.31,233.94,110,200,2,1,233.3,233.98,100,44,1,3,233.25,234.0,55,155,2,7,233.24,234.13,1,400,1,1,AAPL,-239,-2.3481731654897144,0.03031104462800924
2024-10-21T11:55:35.304698115Z,2024-10-21T11:55:35.304531207Z,10,2,38,A,B,0,233.67,2,130,166908,11448347,233.67,233.73,2,200,1,1,233.55,233.75,400,201,1,2,233.54,233.77,27,8,1,1,233.53,233.78,10,150,1,2,233.45,233.79,15,27,1,1,233.4,233.8,110,25,2,1,233.39,233.94,10,200,1,1,233.31,233.98,110,44,2,3,233.3,234.0,100,155,1,7,233.25,234.13,55,400,2,1,AAPL,-184,-1.6853448275862069,0.021755023451133046
2024-10-21T11:55:35.305902949Z,2024-10-21T11:55:35.305736838Z,10,2,38,C,B,0,233.67,2,130,166111,11448348,233.55,233.73,400,200,1,1,233.54,233.75,27,201,1,2,233.53,233.77,10,8,1,1,233.45,233.78,15,150,1,2,233.4,233.79,110,27,2,1,233.39,233.8,10,25,1,1,233.31,233.94,110,200,2,1,233.3,233.98,100,44,1,3,233.25,234.0,55,155,2,7,233.24,234.13,1,400,1,1,AAPL,-185,-1.6192560175054704,0.02090192585969053
2024-10-21T11:55:35.374378511Z,2024-10-21T11:55:35.374212373Z,10,2,38,C,B,0,233.55,400,130,166138,11448379,233.54,233.73,27,200,1,1,233.53,233.75,10,201,1,2,233.45,233.77,15,8,1,1,233.4,233.78,110,150,2,2,233.39,233.79,10,27,1,1,233.31,233.8,110,25,2,1,233.3,233.94,100,200,1,1,233.25,233.98,55,44,2,3,233.24,234.0,1,155,1,7,233.23,234.13,50,400,1,1,AAPL,-235,-1.9570458031996494,0.025262235150137015
2024-10-21T11:55:35.374392676Z,2024-10-21T11:55:35.374226300Z,10,2,38,A,B,2,233.5,200,130,166376,11448380,233.54,233.73,27,200,1,1,233.53,233.75,10,201,1,2,233.5,233.77,200,8,1,1,233.45,233.78,15,150,1,2,233.4,233.79,110,27,2,1,233.39,233.8,10,25,1,1,233.31,233.94,110,200,2,1,233.3,233.98,100,44,1,3,233.25,234.0,55,155,2,7,233.24,234.13,1,400,1,1,AAPL,-234,-1.8855761482675262,0.02433967972192854
2024-10-21T11:55:38.243838236Z,2024-10-21T11:55:38.243671650Z,10,2,38,C,A,0,233.73,200,130,166586,11450385,233.54,233.75,27,201,1,2,233.53,233.77,10,8,1,1,233.5,233.78,200,150,1,2,233.45,233.79,15,27,1,1,233.4,233.8,110,25,2,1,233.39,233.94,10,200,1,1,233.31,233.98,110,44,2,3,233.3,234.0,100,155,1,7,233.25,234.13,55,400,2,1,233.24,234.17,1,1,1,1,AAPL,-233,-1.9706000805477244,0.02543719852661876
2024-10-21T11:55:38.243849825Z,2024-10-21T11:55:38.243683612Z,10,2,38,A,A,0,233.75,200,130,166213,11450386,233.54,233.75,27,401,1,3,233.53,233.77,10,8,1,1,233.5,233.78,200,150,1,2,233.45,233.79,15,27,1,1,233.4,233.8,110,25,2,1,233.39,233.94,10,200,1,1,233.31,233.98,110,44,2,3,233.3,234.0,100,155,1,7,233.25,234.13,55,400,2,1,233.24,234.17,1,1,1,1,AAPL,-233,-2.0636070853462156,0.02663776563751009
2024-10-21T11:55:38.298503075Z,2024-10-21T11:55:38.298336797Z,10,2,38,A,B,2,233.51,200,130,166278,11450436,233.54,233.75,27,401,1,3,233.53,233.77,10,8,1,1,233.51,233.78,200,150,1,2,233.45,233.79,15,27,1,1,233.4,233.8,110,25,2,1,233.39,233.94,10,200,1,1,233.31,233.98,110,44,2,3,233.3,234.0,100,155,1,7,233.25,234.13,55,400,2,1,233.24,234.17,1,1,1,1,AAPL,-233,-2.156539235412475,0.027837366497205536
2024-10-21T11:55:38.572580545Z,2024-10-21T11:55:38.572413983Z,10,2,38,A,A,0,233.74,200,130,166562,11450747,233.54,233.74,27,200,1,1,233.53,233.75,10,201,1,2,233.51,233.77,200,8,1,1,233.45,233.78,15,150,1,2,233.4,233.79,110,27,2,1,233.39,233.8,10,25,1,1,233.31,233.94,110,200,2,1,233.3,233.98,100,44,1,3,233.25,234.0,55,155,2,7,233.24,234.13,1,400,1,1,AAPL,-633,-5.657047104822193,0.0730231525413312
2024-10-21T11:55:44.733677601Z,2024-10-21T11:55:44.733510979Z,10,2,38,A,B,0,233.55,29,130,166622,11455418,233.55,233.74,29,200,1,1,233.54,233.75,27,201,1,2,233.53,233.77,10,8,1,1,233.51,233.78,200,150,1,2,233.45,233.79,15,27,1,1,233.4,233.8,110,25,2,1,233.39,233.94,10,200,1,1,233.31,233.98,110,44,2,3,233.3,234.0,100,155,1,7,233.25,234.13,55,400,2,1,AAPL,-632,-4.868347338935575,0.06284233872690195
2024-10-21T11:55:44.792124247Z,2024-10-21T11:55:44.791957886Z,10,2,38,C,B,1,233.54,27,130,166361,11455485,233.55,233.74,29,200,1,1,233.53,233.75,10,201,1,2,233.51,233.77,200,8,1,1,233.45,233.78,15,150,1,2,233.4,233.79,110,27,2,1,233.39,233.8,10,25,1,1,233.31,233.94,110,200,2,1,233.3,233.98,100,44,1,3,233.25,234.0,55,155,2,7,233.24,234.13,1,400,1,1,AAPL,-633,-4.76329134631114,0.06148623904580584
2024-10-21T11:55:51.294115015Z,2024-10-21T11:55:51.293948230Z,10,2,38,A,A,0,233.73,100,130,166785,11459624,233.55,233.73,29,100,1,1,233.53,233.74,10,200,1,1,233.51,233.75,200,201,1,2,233.45,233.77,15,8,1,1,233.4,233.78,110,150,2,2,233.39,233.79,10,27,1,1,233.31,233.8,110,25,2,1,233.3,233.94,100,200,1,1,233.25,233.98,55,44,2,3,233.24,234.0,1,155,1,7,AAPL,-496,-3.1300428217263914,0.040403692986220784
2024-10-21T11:55:51.294383491Z,2024-10-21T11:55:51.294217665Z,10,2,38,C,A,0,233.73,100,130,165826,11459625,233.55,233.74,29,200,1,1,233.53,233.75,10,201,1,2,233.51,233.77,200,8,1,1,233.45,233.78,15,150,1,2,233.4,233.79,110,27,2,1,233.39,233.8,10,25,1,1,233.31,233.94,110,200,2,1,233.3,233.98,100,44,1,3,233.25,234.0,55,155,2,7,233.24,234.13,1,400,1,1,AAPL,-96,-0.5952873088052913,0.0076841778318856024
2024-10-21T11:55:51.365354478Z,2024-10-21T11:55:51.365188500Z,10,2,38,C,B,2,233.51,200,130,165978,11459674,233.55,233.74,29,200,1,1,233.53,233.75,10,201,1,2,233.45,233.77,15,8,1,1,233.4,233.78,110,150,2,2,233.39,233.79,10,27,1,1,233.31,233.8,110,25,2,1,233.3,233.94,100,200,1,1,233.25,233.98,55,44,2,3,233.24,234.0,1,155,1,7,233.23,234.13,50,400,1,1,AAPL,-146,-0.8835098335854765,0.011404655495034315
2024-10-21T11:55:51.401763373Z,2024-10-21T11:55:51.401597368Z,10,2,38,A,B,2,233.47,200,130,166005,11459719,233.55,233.74,29,200,1,1,233.53,233.75,10,201,1,2,233.47,233.77,200,8,1,1,233.45,233.78,15,150,1,2,233.4,233.79,110,27,2,1,233.39,233.8,10,25,1,1,233.31,233.94,110,200,2,1,233.3,233.98,100,44,1,3,233.25,234.0,55,155,2,7,233.24,234.13,1,400,1,1,AAPL,-145,-0.8665846370188083,0.01118617910836497
2024-10-21T11:55:53.213495106Z,2024-10-21T11:55:53.213328704Z,10,2,38,A,A,6,233.81,26,130,166402,11460545,233.55,233.74,29,200,1,1,233.53,233.75,10,201,1,2,233.47,233.77,200,8,1,1,233.45,233.78,15,150,1,2,233.4,233.79,110,27,2,1,233.39,233.8,10,25,1,1,233.31,233.81,110,26,2,1,233.3,233.94,100,200,1,1,233.25,233.98,55,44,2,3,233.24,234.0,1,155,1,7,AAPL,-300,-1.8477331052181352,0.023851188420014467
2024-10-21T11:55:53.213531364Z,2024-10-21T11:55:53.213365167Z,10,2,38,C,A,4,233.79,27,130,166197,11460546,233.55,233.74,29,200,1,1,233.53,233.75,10,201,1,2,233.47,233.77,200,8,1,1,233.45,233.78,15,150,1,2,233.4,233.8,110,25,2,1,233.39,233.81,10,26,1,1,233.31,233.94,110,200,2,1,233.3,233.98,100,44,1,3,233.25,234.0,55,155,2,7,233.24,234.13,1,400,1,1,AAPL,100,0.6083893691962856,-0.007853303832926277
2024-10-21T11:55:54.691552408Z,2024-10-21T11:55:54.691386316Z,10,2,38,A,B,2,233.47,200,130,166092,11461460,233.55,233.74,29,200,1,1,233.53,233.75,10,201,1,2,233.47,233.77,400,8,2,1,233.45,233.78,15,150,1,2,233.4,233.8,110,25,2,1,233.39,233.81,10,26,1,1,233.31,233.94,110,200,2,1,233.3,233.98,100,44,1,3,233.25,234.0,55,155,2,7,233.24,234.13,1,400,1,1,AAPL,100,0.6136950904392765,-0.007921791947748308
2024-10-21T11:55:54.691564851Z,2024-10-21T11:55:54.691398035Z,10,2,38,C,A,0,233.74,200,130,166816,11461461,233.55,233.75,29,201,1,2,233.53,233.77,10,8,1,1,233.47,233.78,400,150,2,2,233.45,233.8,15,25,1,1,233.4,233.81,110,26,2,1,233.39,233.94,10,200,1,1,233.31,233.98,110,44,2,3,233.3,234.0,100,155,1,7,233.25,234.13,55,400,2,1,233.24,234.17,1,1,1,1,AAPL,101,0.6522441072005166,-0.008419396206492208
2024-10-21T11:55:54.691573831Z,2024-10-21T11:55:54.691407713Z,10,2,38,A,A,1,233.76,200,130,166118,11461462,233.55,233.75,29,201,1,2,233.53,233.76,10,200,1,1,233.47,233.77,400,8,2,1,233.45,233.78,15,150,1,2,233.4,233.8,110,25,2,1,233.39,233.81,10,26,1,1,233.31,233.94,110,200,2,1,233.3,233.98,100,44,1,3,233.25,234.0,55,155,2,7,233.24,234.13,1,400,1,1,AAPL,-299,-1.904169825625474,0.024579693445140487
2024-10-21T11:55:54.746022499Z,2024-10-21T11:55:54.745856609Z,10,2,38,C,B,2,233.47,200,130,165890,11461600,233.55,233.75,29,201,1,2,233.53,233.76,10,200,1,1,233.47,233.77,200,8,1,1,233.45,233.78,15,150,1,2,233.4,233.8,110,25,2,1,233.39,233.81,10,26,1,1,233.31,233.94,110,200,2,1,233.3,233.98,100,44,1,3,233.25,234.0,55,155,2,7,233.24,234.13,1,400,1,1,AAPL,-299,-1.880503144654088,0.0242741956080715
2024-10-21T11:55:54.746035106Z,2024-10-21T11:55:54.745868744Z,10,2,38,A,B,2,233.48,200,130,166362,11461601,233.55,233.75,29,201,1,2,233.53,233.76,10,200,1,1,233.48,233.77,200,8,1,1,233.45,233.78,15,150,1,2,233.4,233.8,110,25,2,1,233.39,233.81,10,26,1,1,233.31,233.94,110,200,2,1,233.3,233.98,100,44,1,3,233.25,234.0,55,155,2,7,233.24,234.13,1,400,1,1,AAPL,-299,-1.859402460456942,0.02400182055933959
2024-10-21T11:55:54.762658342Z,2024-10-21T11:55:54.762492206Z,10,2,38,C,B,0,233.55,29,130,166136,11461707,233.53,233.75,10,201,1,2,233.48,233.76,200,200,1,1,233.45,233.77,15,8,1,1,233.4,233.78,110,150,2,2,233.39,233.8,10,25,1,1,233.31,233.81,110,26,2,1,233.3,233.94,100,200,1,1,233.25,233.98,55,44,2,3,233.24,234.0,1,155,1,7,233.23,234.13,50,400,1,1,AAPL,-349,-2.134828596916019,0.027557117943972708
2024-10-21T11:55:54.762696483Z,2024-10-21T11:55:54.762530320Z,10,2,38,A,B,0,233.56,28,130,166163,11461708,233.56,233.75,28,201,1,2,233.53,233.76,10,200,1,1,233.48,233.77,200,8,1,1,233.45,233.78,15,150,1,2,233.4,233.8,110,25,2,1,233.39,233.81,10,26,1,1,233.31,233.94,110,200,2,1,233.3,233.98,100,44,1,3,233.25,234.0,55,155,2,7,233.24,234.13,1,400,1,1,AAPL,-348,-2.1096023278370515,0.027231488395399232
2024-10-21T11:55:55.306858576Z,2024-10-21T11:55:55.306692496Z,10,2,38,C,B,2,233.48,200,130,166080,11462057,233.56,233.75,28,201,1,2,233.53,233.76,10,200,1,1,233.45,233.77,15,8,1,1,233.4,233.78,110,150,2,2,233.39,233.8,10,25,1,1,233.31,233.81,110,26,2,1,233.3,233.94,100,200,1,1,233.25,233.98,55,44,2,3,233.24,234.0,1,155,1,7,233.23,234.13,50,400,1,1,AAPL,-451,-2.840538219295734,0.03666666581409583
2024-10-21T11:55:55.306871673Z,2024-10-21T11:55:55.306705027Z,10,2,38,A,B,2,233.46,400,130,166646,11462058,233.56,233.75,28,201,1,2,233.53,233.76,10,200,1,1,233.46,233.77,400,8,1,1,233.45,233.78,15,150,1,2,233.4,233.8,110,25,2,1,233.39,233.81,10,26,1,1,233.31,233.94,110,200,2,1,233.3,233.98,100,44,1,3,233.25,234.0,55,155,2,7,233.24,234.13,1,400,1,1,AAPL,-450,-2.8022201164207394,0.03617204227296427
2024-10-21T11:55:55.361248847Z,2024-10-21T11:55:55.361082355Z,10,2,38,A,A,0,233.75,200,130,166492,11462096,233.56,233.75,28,401,1,3,233.53,233.77,10,8,1,1,233.46,233.78,400,150,1,2,233.45,233.8,15,25,1,1,233.4,233.81,110,26,2,1,233.39,233.94,10,200,1,1,233.31,233.98,110,44,2,3,233.3,234.0,100,155,1,7,233.25,234.13,55,400,2,1,233.24,234.17,1,1,1,1,AAPL,-449,-2.916768168899716,0.03765066879922291
2024-10-21T11:55:55.706272013Z,2024-10-21T11:55:55.706105479Z,10,2,38,A,B,2,233.47,200,130,166534,11462281,233.56,233.75,28,401,1,3,233.53,233.77,10,8,1,1,233.47,233.78,200,150,1,2,233.45,233.8,15,25,1,1,233.4,233.81,110,26,2,1,233.39,233.94,10,200,1,1,233.31,233.98,110,44,2,3,233.3,234.0,100,155,1,7,233.25,234.13,55,400,2,1,233.24,234.17,1,1,1,1,AAPL,-400,-2.813455657492355,0.036317074586529
2024-10-21T11:55:58.151746575Z,2024-10-21T11:55:58.151580102Z,10,2,38,A,B,2,233.47,200,130,166473,11463546,233.56,233.75,28,401,1,3,233.53,233.77,10,8,1,1,233.47,233.78,400,150,2,2,233.45,233.8,15,25,1,1,233.4,233.81,110,26,2,1,233.39,233.94,10,200,1,1,233.31,233.98,110,44,2,3,233.3,234.0,100,155,1,7,233.25,234.13,55,400,2,1,233.24,234.17,1,1,1,1,AAPL,-400,-2.9348822989911345,0.03788449235775252
2024-10-21T11:56:07.493822226Z,2024-10-21T11:56:07.493655598Z,10,2,38,C,A,7,234.0,2,130,166628,11471731,233.56,233.75,28,401,1,3,233.53,233.77,10,8,1,1,233.47,233.78,400,150,2,2,233.45,233.8,15,25,1,1,233.4,233.81,110,26,2,1,233.39,233.94,10,200,1,1,233.31,233.98,110,44,2,3,233.3,234.0,100,153,1,6,233.25,234.13,55,400,2,1,233.24,234.17,1,1,1,1,AAPL,-55,-0.3957583790948684,0.005108588270640341
2024-10-21T11:56:10.953659035Z,2024-10-21T11:56:10.953492365Z,10,2,38,C,A,0,233.75,200,130,166670,11474926,233.56,233.75,28,201,1,2,233.53,233.77,10,8,1,1,233.47,233.78,400,150,2,2,233.45,233.8,15,25,1,1,233.4,233.81,110,26,2,1,233.39,233.94,10,200,1,1,233.31,233.98,110,44,2,3,233.3,234.0,100,153,1,6,233.25,234.13,55,400,2,1,233.24,234.17,1,1,1,1,AAPL,-55,-0.416430058678781,0.005375425577024944
2024-10-21T11:56:10.953670665Z,2024-10-21T11:56:10.953504236Z,10,2,38,A,A,1,233.77,200,130,166429,11474927,233.56,233.75,28,201,1,2,233.53,233.77,10,208,1,2,233.47,233.78,400,150,2,2,233.45,233.8,15,25,1,1,233.4,233.81,110,26,2,1,233.39,233.94,10,200,1,1,233.31,233.98,110,44,2,3,233.3,234.0,100,153,1,6,233.25,234.13,55,400,2,1,233.24,234.17,1,1,1,1,AAPL,-55,-0.4370860927152318,0.005642060925183334
2024-10-21T11:56:11.008321762Z,2024-10-21T11:56:11.008155483Z,10,2,38,C,B,2,233.47,200,130,166279,11475150,233.56,233.75,28,201,1,2,233.53,233.77,10,208,1,2,233.47,233.78,200,150,1,2,233.45,233.8,15,25,1,1,233.4,233.81,110,26,2,1,233.39,233.94,10,200,1,1,233.31,233.98,110,44,2,3,233.3,234.0,100,153,1,6,233.25,234.13,55,400,2,1,233.24,234.17,1,1,1,1,AAPL,-55,-0.4577264989597125,0.005908494544309638
2024-10-21T11:56:11.008333820Z,2024-10-21T11:56:11.008167451Z,10,2,38,A,B,2,233.48,400,130,166369,11475151,233.56,233.75,28,201,1,2,233.53,233.77,10,208,1,2,233.48,233.78,400,150,1,2,233.45,233.8,15,25,1,1,233.4,233.81,110,26,2,1,233.39,233.94,10,200,1,1,233.31,233.98,110,44,2,3,233.3,234.0,100,153,1,6,233.25,234.13,55,400,2,1,233.24,234.17,1,1,1,1,AAPL,-55,-0.4783512951408584,0.0061747266632513126
2024-10-21T11:56:11.038918460Z,2024-10-21T11:56:11.038752302Z,10,2,38,C,B,0,233.56,28,130,166158,11475414,233.53,233.75,10,201,1,2,233.48,233.77,400,208,1,2,233.45,233.78,15,150,1,2,233.4,233.8,110,25,2,1,233.39,233.81,10,26,1,1,233.31,233.94,110,200,2,1,233.3,233.98,100,44,1,3,233.25,234.0,55,153,2,6,233.24,234.13,1,400,1,1,233.23,234.17,50,1,1,1,AAPL,-105,-0.9438202247191011,0.012183163223531733
2024-10-21T11:56:11.038969093Z,2024-10-21T11:56:11.038803026Z,10,2,38,A,B,0,233.57,26,130,166067,11475415,233.57,233.75,26,201,1,2,233.53,233.77,10,208,1,2,233.48,233.78,400,150,1,2,233.45,233.8,15,25,1,1,233.4,233.81,110,26,2,1,233.39,233.94,10,200,1,1,233.31,233.98,110,44,2,3,233.3,234.0,100,153,1,6,233.25,234.13,55,400,2,1,233.24,234.17,1,1,1,1,AAPL,-104,-0.9734181954324223,0.012565224233501109
2024-10-21T11:56:14.983045514Z,2024-10-21T11:56:14.982879375Z,10,2,38,C,A,1,233.77,200,130,166139,11478870,233.57,233.75,26,201,1,2,233.53,233.77,10,8,1,1,233.48,233.78,400,150,1,2,233.45,233.8,15,25,1,1,233.4,233.81,110,26,2,1,233.39,233.94,10,200,1,1,233.31,233.98,110,44,2,3,233.3,234.0,100,153,1,6,233.25,234.13,55,400,2,1,233.24,234.17,1,1,1,1,AAPL,-97,-2.735357917570499,0.03530896150743061
2024-10-21T11:56:14.983058049Z,2024-10-21T11:56:14.982891924Z,10,2,38,A,A,2,233.78,200,130,166125,11478871,233.57,233.75,26,201,1,2,233.53,233.77,10,8,1,1,233.48,233.78,400,350,1,3,233.45,233.8,15,25,1,1,233.4,233.81,110,26,2,1,233.39,233.94,10,200,1,1,233.31,233.98,110,44,2,3,233.3,234.0,100,153,1,6,233.25,234.13,55,400,2,1,233.24,234.17,1,1,1,1,AAPL,-97,-2.9393939393939394,0.037942730197961565
2024-10-21T11:56:15.037129152Z,2024-10-21T11:56:15.036962807Z,10,2,38,A,A,1,233.77,200,130,166345,11478943,233.57,233.75,26,201,1,2,233.53,233.77,10,208,1,2,233.48,233.78,400,150,1,2,233.45,233.8,15,25,1,1,233.4,233.81,110,26,2,1,233.39,233.94,10,200,1,1,233.31,233.98,110,44,2,3,233.3,234.0,100,153,1,6,233.25,234.13,55,400,2,1,233.24,234.17,1,1,1,1,AAPL,-97,-3.142548596112311,0.04056512191790707
2024-10-21T11:56:15.039252622Z,2024-10-21T11:56:15.039085832Z,10,2,38,C,A,4,233.81,26,130,166790,11478955,233.57,233.75,26,201,1,2,233.53,233.77,10,208,1,2,233.48,233.78,400,150,1,2,233.45,233.8,15,25,1,1,233.4,233.94,110,200,2,1,233.39,233.98,10,44,1,3,233.31,234.0,110,153,2,6,233.3,234.13,100,400,1,1,233.25,234.17,55,1,2,1,233.24,234.41,1,600,1,2,AAPL,503,10.540929927963326,-0.13606602875924662
2024-10-21T11:56:15.039369586Z,2024-10-21T11:56:15.039203352Z,10,2,38,A,A,4,233.84,28,130,166234,11478956,233.57,233.75,26,201,1,2,233.53,233.77,10,208,1,2,233.48,233.78,400,150,1,2,233.45,233.8,15,25,1,1,233.4,233.84,110,28,2,1,233.39,233.94,10,200,1,1,233.31,233.98,110,44,2,3,233.3,234.0,100,153,1,6,233.25,234.13,55,400,2,1,233.24,234.17,1,1,1,1,AAPL,502,11.162851536952257,-0.1440940115001427
2024-10-21T11:56:17.923045221Z,2024-10-21T11:56:17.922879284Z,10,2,38,C,A,4,233.84,28,130,165937,11481519,233.57,233.75,26,201,1,2,233.53,233.77,10,208,1,2,233.48,233.78,400,150,1,2,233.45,233.8,15,25,1,1,233.4,233.94,110,200,2,1,233.39,233.98,10,44,1,3,233.31,234.0,110,153,2,6,233.3,234.13,100,400,1,1,233.25,234.17,55,1,2,1,233.24,234.41,1,600,1,2,AAPL,1150,25.254901960784313,-0.32599915187672496
2024-10-21T11:56:17.923122278Z,2024-10-21T11:56:17.922956219Z,10,2,38,A,A,4,233.83,30,130,166059,11481520,233.57,233.75,26,201,1,2,233.53,233.77,10,208,1,2,233.48,233.78,400,150,1,2,233.45,233.8,15,25,1,1,233.4,233.83,110,30,2,1,233.39,233.94,10,200,1,1,233.31,233.98,110,44,2,3,233.3,234.0,100,153,1,6,233.25,234.13,55,400,2,1,233.24,234.17,1,1,1,1,AAPL,1149,26.992952231793264,-0.34843451571808326
2024-10-21T11:56:23.203528631Z,2024-10-21T11:56:23.203362495Z,10,2,38,C,A,1,233.77,200,130,166136,11484712,233.57,233.75,26,201,1,2,233.53,233.77,10,8,1,1,233.48,233.78,400,150,1,2,233.45,233.8,15,25,1,1,233.4,233.83,110,30,2,1,233.39,233.94,10,200,1,1,233.31,233.98,110,44,2,3,233.3,234.0,100,153,1,6,233.25,234.13,55,400,2,1,233.24,234.17,1,1,1,1,AAPL,1149,26.992952231793264,-0.34843451571808326
2024-10-21T11:56:23.203540531Z,2024-10-21T11:56:23.203374367Z,10,2,38,A,A,2,233.78,200,130,166164,11484713,233.57,233.75,26,201,1,2,233.53,233.77,10,8,1,1,233.48,233.78,400,350,1,3,233.45,233.8,15,25,1,1,233.4,233.83,110,30,2,1,233.39,233.94,10,200,1,1,233.31,233.98,110,44,2,3,233.3,234.0,100,153,1,6,233.25,234.13,55,400,2,1,233.24,234.17,1,1,1,1,AAPL,1149,28.747458952306488,-0.37108230519425994
2024-10-21T11:56:23.231147559Z,2024-10-21T11:56:23.230980890Z,10,2,38,A,B,2,233.49,400,130,166669,11484750,233.57,233.75,26,201,1,2,233.53,233.77,10,8,1,1,233.49,233.78,400,350,1,3,233.45,233.8,15,25,1,1,233.4,233.83,110,30,2,1,233.39,233.94,10,200,1,1,233.31,233.98,110,44,2,3,233.3,234.0,100,153,1,6,233.25,234.13,55,400,2,1,233.24,234.17,1,1,1,1,AAPL,1149,30.496487119437937,-0.3936593755776149
2024-10-21T11:56:23.259172222Z,2024-10-21T11:56:23.259005865Z,10,2,38,A,B,2,233.5,200,130,166357,11484879,233.57,233.75,26,201,1,2,233.53,233.77,10,8,1,1,233.5,233.78,200,350,1,3,233.45,233.8,15,25,1,1,233.4,233.83,110,30,2,1,233.39,233.94,10,200,1,1,233.31,233.98,110,44,2,3,233.3,234.0,100,153,1,6,233.25,234.13,55,400,2,1,233.24,234.17,1,1,1,1,AAPL,1149,32.24006235385815,-0.41616605758876923
2024-10-21T11:56:23.260590051Z,2024-10-21T11:56:23.260424017Z,10,2,38,C,B,0,233.57,26,130,166034,11484896,233.53,233.75,10,201,1,2,233.5,233.77,200,8,1,1,233.45,233.78,15,350,1,3,233.4,233.8,110,25,2,1,233.39,233.83,10,30,1,1,233.31,233.94,110,200,2,1,233.3,233.98,100,44,1,3,233.25,234.0,55,153,2,6,233.24,234.13,1,400,1,1,233.23,234.17,50,1,1,1,AAPL,1099,31.305847076461767,-0.40410687840152043
2024-10-21T11:56:23.260686828Z,2024-10-21T11:56:23.260520532Z,10,2,38,A,B,0,233.58,27,130,166296,11484897,233.58,233.75,27,201,1,2,233.53,233.77,10,8,1,1,233.5,233.78,200,350,1,3,233.45,233.8,15,25,1,1,233.4,233.83,110,30,2,1,233.39,233.94,10,200,1,1,233.31,233.98,110,44,2,3,233.3,234.0,100,153,1,6,233.25,234.13,55,400,2,1,233.24,234.17,1,1,1,1,AAPL,1100,32.93413173652695,-0.4251253491530357
2024-10-21T11:56:24.985463111Z,2024-10-21T11:56:24.985297090Z,10,2,38,C,B,2,233.5,200,130,166021,11486304,233.58,233.75,27,201,1,2,233.53,233.77,10,8,1,1,233.45,233.78,15,350,1,3,233.4,233.8,110,25,2,1,233.39,233.83,10,30,1,1,233.31,233.94,110,200,2,1,233.3,233.98,100,44,1,3,233.25,234.0,55,153,2,6,233.24,234.13,1,400,1,1,233.23,234.17,50,1,1,1,AAPL,1050,31.79524152847873,-0.4104241540155157
2024-10-21T11:56:24.985475867Z,2024-10-21T11:56:24.985309618Z,10,2,38,A,B,2,233.48,400,130,166249,11486305,233.58,233.75,27,201,1,2,233.53,233.77,10,8,1,1,233.48,233.78,400,350,1,3,233.45,233.8,15,25,1,1,233.4,233.83,110,30,2,1,233.39,233.94,10,200,1,1,233.31,233.98,110,44,2,3,233.3,234.0,100,153,1,6,233.25,234.13,55,400,2,1,233.24,234.17,1,1,1,1,AAPL,1051,33.293016558675305,-0.42975796058916255
2024-10-21T11:56:25.053368268Z,2024-10-21T11:56:25.053201827Z,10,2,38,A,A,1,233.77,200,130,166441,11486393,233.58,233.75,27,201,1,2,233.53,233.77,10,208,1,2,233.48,233.78,400,150,1,2,233.45,233.8,15,25,1,1,233.4,233.83,110,30,2,1,233.39,233.94,10,200,1,1,233.31,233.98,110,44,2,3,233.3,234.0,100,153,1,6,233.25,234.13,55,400,2,1,233.24,234.17,1,1,1,1,AAPL,1051,34.756290438533426,-0.448646414186719
2024-10-21T11:56:29.970777659Z,2024-10-21T11:56:29.970611371Z,10,2,38,A,A,7,234.0,1,130,166288,11488797,233.58,233.75,27,201,1,2,233.53,233.77,10,208,1,2,233.48,233.78,400,150,1,2,233.45,233.8,15,25,1,1,233.4,233.83,110,30,2,1,233.39,233.94,10,200,1,1,233.31,233.98,110,44,2,3,233.3,234.0,100,154,1,7,233.25,234.13,55,400,2,1,233.24,234.17,1,1,1,1,AAPL,1051,34.756290438533426,-0.448646414186719
2024-10-21T11:56:34.567962213Z,2024-10-21T11:56:34.567796323Z,10,2,38,C,A,1,233.77,200,130,165890,11492628,233.58,233.75,27,201,1,2,233.53,233.77,10,8,1,1,233.48,233.78,400,150,1,2,233.45,233.8,15,25,1,1,233.4,233.83,110,30,2,1,233.39,233.94,10,200,1,1,233.31,233.98,110,44,2,3,233.3,234.0,100,154,1,7,233.25,234.13,55,400,2,1,233.24,234.17,1,1,1,1,AAPL,1100,29.72972972972973,-0.3837618016678754
2024-10-21T11:56:34.567975518Z,2024-10-21T11:56:34.567809267Z,10,2,38,A,A,2,233.78,200,130,166251,11492629,233.58,233.75,27,201,1,2,233.53,233.77,10,8,1,1,233.48,233.78,400,350,1,3,233.45,233.8,15,25,1,1,233.4,233.83,110,30,2,1,233.39,233.94,10,200,1,1,233.31,233.98,110,44,2,3,233.3,234.0,100,154,1,7,233.25,234.13,55,400,2,1,233.24,234.17,1,1,1,1,AAPL,1100,31.334332833583204,-0.4044745825674908
2024-10-21T11:56:34.623579638Z,2024-10-21T11:56:34.623413180Z,10,2,38,A,A,1,233.77,200,130,166458,11492694,233.58,233.75,27,201,1,2,233.53,233.77,10,208,1,2,233.48,233.78,400,150,1,2,233.45,233.8,15,25,1,1,233.4,233.83,110,30,2,1,233.39,233.94,10,200,1,1,233.31,233.98,110,44,2,3,233.3,234.0,100,154,1,7,233.25,234.13,55,400,2,1,233.24,234.17,1,1,1,1,AAPL,1100,32.93413173652695,-0.4251253491530357
2024-10-21T11:56:42.272792276Z,2024-10-21T11:56:42.272625996Z,10,2,38,A,B,2,233.49,200,130,166280,11497144,233.58,233.75,27,201,1,2,233.53,233.77,10,208,1,2,233.49,233.78,200,150,1,2,233.45,233.8,15,25,1,1,233.4,233.83,110,30,2,1,233.39,233.94,10,200,1,1,233.31,233.98,110,44,2,3,233.3,234.0,100,154,1,7,233.25,234.13,55,400,2,1,233.24,234.17,1,1,1,1,AAPL,-98,-21.77777777777778,0.2811152106763063
2024-10-21T11:56:43.878875408Z,2024-10-21T11:56:43.878708550Z,10,2,38,A,A,0,233.72,100,130,166858,11498282,233.58,233.72,27,100,1,1,233.53,233.75,10,201,1,2,233.49,233.77,200,208,1,2,233.45,233.78,15,150,1,2,233.4,233.8,110,25,2,1,233.39,233.83,10,30,1,1,233.31,233.94,110,200,2,1,233.3,233.98,100,44,1,3,233.25,234.0,55,154,2,7,233.24,234.13,1,400,1,1,AAPL,-449,-17.34334763948498,0.2238740277018171
2024-10-21T11:56:43.879158080Z,2024-10-21T11:56:43.878991240Z,10,2,38,C,A,0,233.72,100,130,166840,11498283,233.58,233.75,27,201,1,2,233.53,233.77,10,208,1,2,233.49,233.78,200,150,1,2,233.45,233.8,15,25,1,1,233.4,233.83,110,30,2,1,233.39,233.94,10,200,1,1,233.31,233.98,110,44,2,3,233.3,234.0,100,154,1,7,233.25,234.13,55,400,2,1,233.24,234.17,1,1,1,1,AAPL,-448,-19.145299145299145,0.24713425114400556
2024-10-21T11:56:47.448863756Z,2024-10-21T11:56:47.448697059Z,10,2,38,C,A,1,233.77,200,130,166697,11501263,233.58,233.75,27,201,1,2,233.53,233.77,10,8,1,1,233.49,233.78,200,150,1,2,233.45,233.8,15,25,1,1,233.4,233.83,110,30,2,1,233.39,233.94,10,200,1,1,233.31,233.98,110,44,2,3,233.3,234.0,100,154,1,7,233.25,234.13,55,400,2,1,233.24,234.17,1,1,1,1,AAPL,-399,-15.383132530120482,0.19857088203365938
2024-10-21T11:56:47.557849873Z,2024-10-21T11:56:47.557683879Z,10,2,38,A,A,1,233.77,200,130,165994,11501298,233.58,233.75,27,201,1,2,233.53,233.77,10,208,1,2,233.49,233.78,200,150,1,2,233.45,233.8,15,25,1,1,233.4,233.83,110,30,2,1,233.39,233.94,10,200,1,1,233.31,233.98,110,44,2,3,233.3,234.0,100,154,1,7,233.25,234.13,55,400,2,1,233.24,234.17,1,1,1,1,AAPL,-399,-17.22302158273381,0.222320816665383
2024-10-21T11:56:51.014820854Z,2024-10-21T11:56:51.014654312Z,10,2,38,A,B,2,233.49,200,130,166542,11503024,233.58,233.75,27,201,1,2,233.53,233.77,10,208,1,2,233.49,233.78,400,150,2,2,233.45,233.8,15,25,1,1,233.4,233.83,110,30,2,1,233.39,233.94,10,200,1,1,233.31,233.98,110,44,2,3,233.3,234.0,100,154,1,7,233.25,234.13,55,400,2,1,233.24,234.17,1,1,1,1,AAPL,-399,-17.22302158273381,0.222320816665383
2024-10-21T11:56:51.014832334Z,2024-10-21T11:56:51.014666179Z,10,2,38,C,A,1,233.77,200,130,166155,11503025,233.58,233.75,27,201,1,2,233.53,233.77,10,8,1,1,233.49,233.78,400,150,2,2,233.45,233.8,15,25,1,1,233.4,233.83,110,30,2,1,233.39,233.94,10,200,1,1,233.31,233.98,110,44,2,3,233.3,234.0,100,154,1,7,233.25,234.13,55,400,2,1,233.24,234.17,1,1,1,1,AAPL,-399,-19.045346062052506,0.24584402161088498
2024-10-21T11:56:51.014842838Z,2024-10-21T11:56:51.014676787Z,10,2,38,A,A,3,233.79,200,130,166051,11503026,233.58,233.75,27,201,1,2,233.53,233.77,10,8,1,1,233.49,233.78,400,150,2,2,233.45,233.79,15,200,1,1,233.4,233.8,110,25,2,1,233.39,233.83,10,30,1,1,233.31,233.94,110,200,2,1,233.3,233.98,100,44,1,3,233.25,234.0,55,154,2,7,233.24,234.13,1,400,1,1,AAPL,-799,-21.43658536585366,0.2767109790904244
2024-10-21T11:56:55.866202310Z,2024-10-21T11:56:55.866035650Z,10,2,38,A,A,2,233.78,200,130,166660,11506229,233.58,233.75,27,201,1,2,233.53,233.77,10,8,1,1,233.49,233.78,400,350,2,3,233.45,233.8,15,25,1,1,233.4,233.83,110,30,2,1,233.39,233.94,10,200,1,1,233.31,233.98,110,44,2,3,233.3,234.0,100,154,1,7,233.25,234.13,55,400,2,1,233.24,234.17,1,1,1,1,AAPL,-798,-17.602941176470587,0.2272249523271194
2024-10-21T11:57:04.890567315Z,2024-10-21T11:57:04.890399029Z,10,2,38,A,A,0,233.72,100,130,168286,11513463,233.58,233.72,27,100,1,1,233.53,233.75,10,201,1,2,233.49,233.77,400,8,2,1,233.45,233.78,15,350,1,3,233.4,233.8,110,25,2,1,233.39,233.83,10,30,1,1,233.31,233.94,110,200,2,1,233.3,233.98,100,44,1,3,233.25,234.0,55,154,2,7,233.24,234.13,1,400,1,1,AAPL,-799,-13.775862068965518,0.17782366994839185
2024-10-21T11:57:04.890891078Z,2024-10-21T11:57:04.890725062Z,10,2,38,C,A,0,233.72,100,130,166016,11513464,233.58,233.75,27,201,1,2,233.53,233.77,10,8,1,1,233.49,233.78,400,350,2,3,233.45,233.8,15,25,1,1,233.4,233.83,110,30,2,1,233.39,233.94,10,200,1,1,233.31,233.98,110,44,2,3,233.3,234.0,100,154,1,7,233.25,234.13,55,400,2,1,233.24,234.17,1,1,1,1,AAPL,-798,-15.685503685503685,0.20247399519402615
2024-10-21T11:57:06.459110448Z,2024-10-21T11:57:06.458943234Z,10,2,38,A,B,0,233.67,1,130,167214,11514372,233.67,233.75,1,201,1,2,233.58,233.77,27,8,1,1,233.53,233.78,10,350,1,3,233.49,233.8,400,25,2,1,233.45,233.83,15,30,1,1,233.4,233.94,110,200,2,1,233.39,233.98,10,44,1,3,233.31,234.0,110,154,2,7,233.3,234.13,100,400,1,1,233.25,234.17,55,1,2,1,AAPL,-743,-15.372413793103448,0.19843252080849333
2024-10-21T11:57:06.459453253Z,2024-10-21T11:57:06.459285665Z,10,2,38,T,N,0,233.68,1,130,167588,11514373,233.67,233.75,1,201,1,2,233.58,233.77,27,8,1,1,233.53,233.78,10,350,1,3,233.49,233.8,400,25,2,1,233.45,233.83,15,30,1,1,233.4,233.94,110,200,2,1,233.39,233.98,10,44,1,3,233.31,234.0,110,154,2,7,233.3,234.13,100,400,1,1,233.25,234.17,55,1,2,1,AAPL,-743,-16.047516198704106,0.2071469799656698
2024-10-21T11:57:07.554309980Z,2024-10-21T11:57:07.554141976Z,10,2,38,T,N,0,233.68,1,130,168004,11515087,233.67,233.75,1,201,1,2,233.58,233.77,27,8,1,1,233.53,233.78,10,350,1,3,233.49,233.8,400,25,2,1,233.45,233.83,15,30,1,1,233.4,233.94,110,200,2,1,233.39,233.98,10,44,1,3,233.31,234.0,110,154,2,7,233.3,234.13,100,400,1,1,233.25,234.17,55,1,2,1,AAPL,-743,-15.16326530612245,0.1957327586206227
2024-10-21T11:57:08.621300353Z,2024-10-21T11:57:08.621131954Z,10,2,38,T,N,0,233.68,1,130,168399,11515684,233.67,233.75,1,201,1,2,233.58,233.77,27,8,1,1,233.53,233.78,10,350,1,3,233.49,233.8,400,25,2,1,233.45,233.83,15,30,1,1,233.4,233.94,110,200,2,1,233.39,233.98,10,44,1,3,233.31,234.0,110,154,2,7,233.3,234.13,100,400,1,1,233.25,234.17,55,1,2,1,AAPL,-743,-14.37137330754352,0.1855107383444973
2024-10-21T11:57:10.160255594Z,2024-10-21T11:57:10.160087903Z,10,2,38,T,N,0,233.68,1,130,167691,11516600,233.67,233.75,1,201,1,2,233.58,233.77,27,8,1,1,233.53,233.78,10,350,1,3,233.49,233.8,400,25,2,1,233.45,233.83,15,30,1,1,233.4,233.94,110,200,2,1,233.39,233.98,10,44,1,3,233.31,234.0,110,154,2,7,233.3,234.13,100,400,1,1,233.25,234.17,55,1,2,1,AAPL,-743,-14.996330275229358,0.19357790256241397
2024-10-21T11:57:14.111053066Z,2024-10-21T11:57:14.110885099Z,10,2,38,T,N,0,233.68,1,130,167967,11518245,233.67,233.75,1,201,1,2,233.58,233.77,27,8,1,1,233.53,233.78,10,350,1,3,233.49,233.8,400,25,2,1,233.45,233.83,15,30,1,1,233.4,233.94,110,200,2,1,233.39,233.98,10,44,1,3,233.31,234.0,110,154,2,7,233.3,234.13,100,400,1,1,233.25,234.17,55,1,2,1,AAPL,-343,-8.331983805668017,0.10755217574457873
2024-10-21T11:57:14.837835451Z,2024-10-21T11:57:14.837669309Z,10,2,38,C,B,1,233.58,27,130,166142,11518715,233.67,233.75,1,201,1,2,233.53,233.77,10,8,1,1,233.49,233.78,400,350,2,3,233.45,233.8,15,25,1,1,233.4,233.83,110,30,2,1,233.39,233.94,10,200,1,1,233.31,233.98,110,44,2,3,233.3,234.0,100,154,1,7,233.25,234.13,55,400,2,1,233.24,234.17,1,1,1,1,AAPL,-344,-9.259757738896367,0.11952820779710556
2024-10-21T11:57:14.894688317Z,2024-10-21T11:57:14.894521785Z,10,2,38,A,B,1,233.59,29,130,166532,11518781,233.67,233.75,1,201,1,2,233.59,233.77,29,8,1,1,233.53,233.78,10,350,1,3,233.49,233.8,400,25,2,1,233.45,233.83,15,30,1,1,233.4,233.94,110,200,2,1,233.39,233.98,10,44,1,3,233.31,234.0,110,154,2,7,233.3,234.13,100,400,1,1,233.25,234.17,55,1,2,1,AAPL,-289,-7.957446808510638,0.10271752053152919
2024-10-21T11:57:15.098931948Z,2024-10-21T11:57:15.098765695Z,10,2,38,C,A,2,233.78,200,130,166253,11518952,233.67,233.75,1,201,1,2,233.59,233.77,29,8,1,1,233.53,233.78,10,150,1,2,233.49,233.8,400,25,2,1,233.45,233.83,15,30,1,1,233.4,233.94,110,200,2,1,233.39,233.98,10,44,1,3,233.31,234.0,110,154,2,7,233.3,234.13,100,400,1,1,233.25,234.17,55,1,2,1,AAPL,-289,-8.112280701754386,0.10471617085128145
2024-10-21T11:57:15.098943891Z,2024-10-21T11:57:15.098777532Z,10,2,38,A,A,3,233.8,200,130,166359,11518953,233.67,233.75,1,201,1,2,233.59,233.77,29,8,1,1,233.53,233.78,10,150,1,2,233.49,233.8,400,225,2,2,233.45,233.83,15,30,1,1,233.4,233.94,110,200,2,1,233.39,233.98,10,44,1,3,233.31,234.0,110,154,2,7,233.3,234.13,100,400,1,1,233.25,234.17,55,1,2,1,AAPL,-289,-8.248079034028539,0.10646910345883581
2024-10-21T11:57:15.158304832Z,2024-10-21T11:57:15.158138746Z,10,2,38,C,B,3,233.49,200,130,166086,11519035,233.67,233.75,1,201,1,2,233.59,233.77,29,8,1,1,233.53,233.78,10,150,1,2,233.49,233.8,200,225,1,2,233.45,233.83,15,30,1,1,233.4,233.94,110,200,2,1,233.39,233.98,10,44,1,3,233.31,234.0,110,154,2,7,233.3,234.13,100,400,1,1,233.25,234.17,55,1,2,1,AAPL,-289,-8.368148914167529,0.1080190076775111
2024-10-21T11:57:15.158317508Z,2024-10-21T11:57:15.158151037Z,10,2,38,A,B,3,233.5,400,130,166471,11519036,233.67,233.75,1,201,1,2,233.59,233.77,29,8,1,1,233.53,233.78,10,150,1,2,233.5,233.8,400,225,1,2,233.45,233.83,15,30,1,1,233.4,233.94,110,200,2,1,233.39,233.98,10,44,1,3,233.31,234.0,110,154,2,7,233.3,234.13,100,400,1,1,233.25,234.17,55,1,2,1,AAPL,-289,-8.47507331378299,0.10939922541281236
2024-10-21T11:57:15.238726868Z,2024-10-21T11:57:15.238560230Z,10,2,38,A,A,3,233.79,200,130,166638,11519174,233.67,233.75,1,201,1,2,233.59,233.77,29,8,1,1,233.53,233.78,10,150,1,2,233.5,233.79,400,200,1,1,233.45,233.8,15,25,1,1,233.4,233.83,110,30,2,1,233.39,233.94,10,200,1,1,233.31,233.98,110,44,2,3,233.3,234.0,100,154,1,7,233.25,234.13,55,400,2,1,AAPL,-689,-14.91745602165088,0.1925597659720831
2024-10-21T11:57:15.426846547Z,2024-10-21T11:57:15.426680348Z,10,2,38,A,A,2,233.78,200,130,166199,11519431,233.67,233.75,1,201,1,2,233.59,233.77,29,8,1,1,233.53,233.78,10,350,1,3,233.5,233.8,400,25,1,1,233.45,233.83,15,30,1,1,233.4,233.94,110,200,2,1,233.39,233.98,10,44,1,3,233.31,234.0,110,154,2,7,233.3,234.13,100,400,1,1,233.25,234.17,55,1,2,1,AAPL,-688,-15.249022164276402,0.19683973829012258
2024-10-21T11:57:15.993417928Z,2024-10-21T11:57:15.993250474Z,10,2,38,T,N,0,233.68,1,130,167454,11519726,233.67,233.75,1,201,1,2,233.59,233.77,29,8,1,1,233.53,233.78,10,350,1,3,233.5,233.8,400,25,1,1,233.45,233.83,15,30,1,1,233.4,233.94,110,200,2,1,233.39,233.98,10,44,1,3,233.31,234.0,110,154,2,7,233.3,234.13,100,400,1,1,233.25,234.17,55,1,2,1,AAPL,-689,-14.751889168765745,0.19042257083653025
2024-10-21T11:57:17.249309759Z,2024-10-21T11:57:17.249143876Z,10,2,38,C,A,2,233.78,200,130,165883,11520279,233.67,233.75,1,201,1,2,233.59,233.77,29,8,1,1,233.53,233.78,10,150,1,2,233.5,233.8,400,25,1,1,233.45,233.83,15,30,1,1,233.4,233.94,110,200,2,1,233.39,233.98,10,44,1,3,233.31,234.0,110,154,2,7,233.3,234.13,100,400,1,1,233.25,234.17,55,1,2,1,AAPL,-689,-15.087591240875913,0.1947559311861808
2024-10-21T11:57:17.249321783Z,2024-10-21T11:57:17.249155657Z,10,2,38,A,A,3,233.8,200,130,166126,11520280,233.67,233.75,1,201,1,2,233.59,233.77,29,8,1,1,233.53,233.78,10,150,1,2,233.5,233.8,400,225,1,2,233.45,233.83,15,30,1,1,233.4,233.94,110,200,2,1,233.39,233.98,10,44,1,3,233.31,234.0,110,154,2,7,233.3,234.13,100,400,1,1,233.25,234.17,55,1,2,1,AAPL,-689,-15.401176470588235,0.19880379955985433
2024-10-21T11:57:17.305025226Z,2024-10-21T11:57:17.304858834Z,10,2,38,A,A,2,233.78,200,130,166392,11520350,233.67,233.75,1,201,1,2,233.59,233.77,29,8,1,1,233.53,233.78,10,350,1,3,233.5,233.8,400,25,1,1,233.45,233.83,15,30,1,1,233.4,233.94,110,200,2,1,233.39,233.98,10,44,1,3,233.31,234.0,110,154,2,7,233.3,234.13,100,400,1,1,233.25,234.17,55,1,2,1,AAPL,-689,-15.694760820045559,0.20259348954067402
2024-10-21T11:57:17.495322650Z,2024-10-21T11:57:17.495155713Z,10,2,38,T,N,0,233.68,1,130,166937,11520659,233.67,233.75,1,201,1,2,233.59,233.77,29,8,1,1,233.53,233.78,10,350,1,3,233.5,233.8,400,25,1,1,233.45,233.83,15,30,1,1,233.4,233.94,110,200,2,1,233.39,233.98,10,44,1,3,233.31,234.0,110,154,2,7,233.3,234.13,100,400,1,1,233.25,234.17,55,1,2,1,AAPL,-689,-15.970198675496688,0.20614893819817587
2024-10-21T11:57:20.112278421Z,2024-10-21T11:57:20.112111433Z,10,2,38,A,A,0,233.72,20,130,166988,11522305,233.67,233.72,1,20,1,1,233.59,233.75,29,201,1,2,233.53,233.77,10,8,1,1,233.5,233.78,400,350,1,3,233.45,233.8,15,25,1,1,233.4,233.83,110,30,2,1,233.39,233.94,10,200,1,1,233.31,233.98,110,44,2,3,233.3,234.0,100,154,1,7,233.25,234.13,55,400,2,1,AAPL,-1089,-21.13630348478165,0.2728348350172687
2024-10-21T11:57:22.737375024Z,2024-10-21T11:57:22.737207625Z,10,2,38,T,N,0,233.68,1,130,167399,11523551,233.67,233.72,1,20,1,1,233.59,233.75,29,201,1,2,233.53,233.77,10,8,1,1,233.5,233.78,400,350,1,3,233.45,233.8,15,25,1,1,233.4,233.83,110,30,2,1,233.39,233.94,10,200,1,1,233.31,233.98,110,44,2,3,233.3,234.0,100,154,1,7,233.25,234.13,55,400,2,1,AAPL,-1089,-18.403379867744306,0.2375572963168026
2024-10-21T11:57:23.434601515Z,2024-10-21T11:57:23.434433631Z,10,2,38,T,N,0,233.68,3,130,167884,11524035,233.67,233.72,1,20,1,1,233.59,233.75,29,201,1,2,233.53,233.77,10,8,1,1,233.5,233.78,400,350,1,3,233.45,233.8,15,25,1,1,233.4,233.83,110,30,2,1,233.39,233.94,10,200,1,1,233.31,233.98,110,44,2,3,233.3,234.0,100,154,1,7,233.25,234.13,55,400,2,1,AAPL,-1089,-16.453257790368273,0.2123844350533602
2024-10-21T11:57:23.522346730Z,2024-10-21T11:57:23.522180556Z,10,2,38,C,B,1,233.59,29,130,166174,11524292,233.67,233.72,1,20,1,1,233.53,233.75,10,201,1,2,233.5,233.77,400,8,1,1,233.45,233.78,15,350,1,3,233.4,233.8,110,25,2,1,233.39,233.83,10,30,1,1,233.31,233.94,110,200,2,1,233.3,233.98,100,44,1,3,233.25,234.0,55,154,2,7,233.24,234.13,1,400,1,1,AAPL,-1090,-15.231973169368361,0.19661966387094637
2024-10-21T11:57:23.522487271Z,2024-10-21T11:57:23.522320812Z,10,2,38,A,B,3,233.47,27,130,166459,11524293,233.67,233.72,1,20,1,1,233.53,233.75,10,201,1,2,233.5,233.77,400,8,1,1,233.47,233.78,27,350,1,3,233.45,233.8,15,25,1,1,233.4,233.83,110,30,2,1,233.39,233.94,10,200,1,1,233.31,233.98,110,44,2,3,233.3,234.0,100,154,1,7,233.25,234.13,55,400,2,1,AAPL,-1035,-13.344904537565089,0.17226071864691456
2024-10-21T11:57:23.576153028Z,2024-10-21T11:57:23.575986228Z,10,2,38,A,A,2,233.77,200,130,166800,11524341,233.67,233.72,1,20,1,1,233.53,233.75,10,201,1,2,233.5,233.77,400,208,1,2,233.47,233.78,27,150,1,2,233.45,233.8,15,25,1,1,233.4,233.83,110,30,2,1,233.39,233.94,10,200,1,1,233.31,233.98,110,44,2,3,233.3,234.0,100,154,1,7,233.25,234.13,55,400,2,1,AAPL,-1035,-12.453208556149733,0.16075039347817402
2024-10-21T11:57:23.893319325Z,2024-10-21T11:57:23.893151634Z,10,2,38,T,A,0,233.67,1,130,167691,11524531,233.67,233.72,1,20,1,1,233.53,233.75,10,201,1,2,233.5,233.77,400,208,1,2,233.47,233.78,27,150,1,2,233.45,233.8,15,25,1,1,233.4,233.83,110,30,2,1,233.39,233.94,10,200,1,1,233.31,233.98,110,44,2,3,233.3,234.0,100,154,1,7,233.25,234.13,55,400,2,1,AAPL,-1035,-11.725672668419989,0.15135910450274812
2024-10-21T11:57:23.893319325Z,2024-10-21T11:57:23.893151634Z,10,2,38,C,B,0,233.67,1,130,167691,11524531,233.53,233.72,10,20,1,1,233.5,233.75,400,201,1,2,233.47,233.77,27,208,1,2,233.45,233.78,15,150,1,2,233.4,233.8,110,25,2,1,233.39,233.83,10,30,1,1,233.31,233.94,110,200,2,1,233.3,233.98,100,44,1,3,233.25,234.0,55,154,2,7,233.24,234.13,1,400,1,1,AAPL,-1036,-11.244011976047904,0.14514165897674774
2024-10-21T11:57:23.893366480Z,2024-10-21T11:57:23.893200066Z,10,2,38,A,A,0,233.71,23,130,166414,11524532,233.53,233.71,10,23,1,1,233.5,233.72,400,20,1,1,233.47,233.75,27,201,1,2,233.45,233.77,15,208,1,2,233.4,233.78,110,150,2,2,233.39,233.8,10,25,1,1,233.31,233.83,110,30,2,1,233.3,233.94,100,200,1,1,233.25,233.98,55,44,2,3,233.24,234.0,1,154,1,7,AAPL,-1190,-12.98417894162575,0.16760434585564205
2024-10-21T11:57:23.964455827Z,2024-10-21T11:57:23.964289822Z,10,2,38,C,B,1,233.5,400,130,166005,11524643,233.53,233.71,10,23,1,1,233.47,233.72,27,20,1,1,233.45,233.75,15,201,1,2,233.4,233.77,110,208,2,2,233.39,233.78,10,150,1,2,233.31,233.8,110,25,2,1,233.3,233.83,100,30,1,1,233.25,233.94,55,200,2,1,233.24,233.98,1,44,1,3,233.23,234.0,50,154,1,7,AAPL,-1240,-13.480624232859899,0.17401263618069782
2024-10-21T11:57:23.964468660Z,2024-10-21T11:57:23.964302478Z,10,2,38,A,B,1,233.49,200,130,166182,11524644,233.53,233.71,10,23,1,1,233.49,233.72,200,20,1,1,233.47,233.75,27,201,1,2,233.45,233.77,15,208,1,2,233.4,233.78,110,150,2,2,233.39,233.8,10,25,1,1,233.31,233.83,110,30,2,1,233.3,233.94,100,200,1,1,233.25,233.98,55,44,2,3,233.24,234.0,1,154,1,7,AAPL,-1239,-13.536360532604984,0.17473209992971014
2024-10-21T11:57:23.993929216Z,2024-10-21T11:57:23.993763323Z,10,2,38,C,A,0,233.71,23,130,165893,11524653,233.53,233.72,10,20,1,1,233.49,233.75,200,201,1,2,233.47,233.77,27,208,1,2,233.45,233.78,15,150,1,2,233.4,233.8,110,25,2,1,233.39,233.83,10,30,1,1,233.31,233.94,110,200,2,1,233.3,233.98,100,44,1,3,233.25,234.0,55,154,2,7,233.24,234.13,1,400,1,1,AAPL,-839,-8.847100175746926,0.11420147891844568
2024-10-21T11:57:25.745730581Z,2024-10-21T11:57:25.745564633Z,10,2,38,C,B,1,233.49,200,130,165948,11525365,233.53,233.72,10,20,1,1,233.47,233.75,27,201,1,2,233.45,233.77,15,208,1,2,233.4,233.78,110,150,2,2,233.39,233.8,10,25,1,1,233.31,233.83,110,30,2,1,233.3,233.94,100,200,1,1,233.25,233.98,55,44,2,3,233.24,234.0,1,154,1,7,233.23,234.13,50,400,1,1,AAPL,-490,-4.973041547732318,0.06419376837517937
2024-10-21T11:57:25.813958448Z,2024-10-21T11:57:25.813792371Z,10,2,38,C,A,2,233.77,200,130,166077,11525510,233.53,233.72,10,20,1,1,233.47,233.75,27,201,1,2,233.45,233.77,15,8,1,1,233.4,233.78,110,150,2,2,233.39,233.8,10,25,1,1,233.31,233.83,110,30,2,1,233.3,233.94,100,200,1,1,233.25,233.98,55,44,2,3,233.24,234.0,1,154,1,7,233.23,234.13,50,400,1,1,AAPL,-490,-4.786856127886323,0.06179042152964991
2024-10-21T11:57:25.853139618Z,2024-10-21T11:57:25.852973172Z,10,2,38,A,A,3,233.78,200,130,166446,11525536,233.53,233.72,10,20,1,1,233.47,233.75,27,201,1,2,233.45,233.77,15,8,1,1,233.4,233.78,110,350,2,3,233.39,233.8,10,25,1,1,233.31,233.83,110,30,2,1,233.3,233.94,100,200,1,1,233.25,233.98,55,44,2,3,233.24,234.0,1,154,1,7,233.23,234.13,50,400,1,1,AAPL,-490,-4.623924507354982,0.05968724289963206
2024-10-21T11:57:25.863140339Z,2024-10-21T11:57:25.862973670Z,10,2,38,A,B,1,233.49,400,130,166669,11525541,233.53,233.72,10,20,1,1,233.49,233.75,400,201,1,2,233.47,233.77,27,8,1,1,233.45,233.78,15,350,1,3,233.4,233.8,110,25,2,1,233.39,233.83,10,30,1,1,233.31,233.94,110,200,2,1,233.3,233.98,100,44,1,3,233.25,234.0,55,154,2,7,233.24,234.13,1,400,1,1,AAPL,-489,-4.49980281319837,0.05808503644136153
2024-10-21T11:57:25.868840178Z,2024-10-21T11:57:25.868673528Z,10,2,38,A,B,0,233.54,200,130,166650,11525550,233.54,233.72,200,20,1,1,233.53,233.75,10,201,1,2,233.47,233.77,27,8,1,1,233.45,233.78,15,350,1,3,233.4,233.8,110,25,2,1,233.39,233.83,10,30,1,1,233.31,233.94,110,200,2,1,233.3,233.98,100,44,1,3,233.25,234.0,55,154,2,7,233.24,234.13,1,400,1,1,AAPL,-489,-4.396603396603396,0.056752902096259945
2024-10-21T11:57:26.000516279Z,2024-10-21T11:57:26.000349886Z,10,2,38,A,B,0,233.54,200,130,166393,11525708,233.54,233.72,400,20,2,1,233.53,233.75,10,201,1,2,233.47,233.77,27,8,1,1,233.45,233.78,15,350,1,3,233.4,233.8,110,25,2,1,233.39,233.83,10,30,1,1,233.31,233.94,110,200,2,1,233.3,233.98,100,44,1,3,233.25,234.0,55,154,2,7,233.24,234.13,1,400,1,1,AAPL,-489,-4.303246521584017,0.055547818737574285
2024-10-21T11:57:28.039458831Z,2024-10-21T11:57:28.039292565Z,10,2,38,C,B,0,233.54,200,130,166266,11526531,233.54,233.72,200,20,1,1,233.53,233.75,10,201,1,2,233.47,233.77,27,8,1,1,233.45,233.78,15,350,1,3,233.4,233.8,110,25,2,1,233.39,233.83,10,30,1,1,233.31,233.94,110,200,2,1,233.3,233.98,100,44,1,3,233.25,234.0,55,154,2,7,233.24,234.13,1,400,1,1,AAPL,-544,-4.406387410321685,0.05687919758452059
2024-10-21T11:57:28.039469716Z,2024-10-21T11:57:28.039302990Z,10,2,38,C,B,0,233.54,200,130,166726,11526532,233.53,233.72,10,20,1,1,233.47,233.75,27,201,1,2,233.45,233.77,15,8,1,1,233.4,233.78,110,350,2,3,233.39,233.8,10,25,1,1,233.31,233.83,110,30,2,1,233.3,233.94,100,200,1,1,233.25,233.98,55,44,2,3,233.24,234.0,1,154,1,7,233.23,234.13,50,400,1,1,AAPL,-594,-4.703915530136384,0.060719795139390555
2024-10-21T11:57:28.039515596Z,2024-10-21T11:57:28.039347712Z,10,2,38,T,N,0,233.68,50,130,167884,11526533,233.53,233.72,10,20,1,1,233.47,233.75,27,201,1,2,233.45,233.77,15,8,1,1,233.4,233.78,110,350,2,3,233.39,233.8,10,25,1,1,233.31,233.83,110,30,2,1,233.3,233.94,100,200,1,1,233.25,233.98,55,44,2,3,233.24,234.0,1,154,1,7,233.23,234.13,50,400,1,1,AAPL,-594,-4.606581429469713,0.059463372354012486
2024-10-21T11:57:28.153873361Z,2024-10-21T11:57:28.153707091Z,10,2,38,A,B,1,233.48,400,130,166270,11526618,233.53,233.72,10,20,1,1,233.48,233.75,400,201,1,2,233.47,233.77,27,8,1,1,233.45,233.78,15,350,1,3,233.4,233.8,110,25,2,1,233.39,233.83,10,30,1,1,233.31,233.94,110,200,2,1,233.3,233.98,100,44,1,3,233.25,234.0,55,154,2,7,233.24,234.13,1,400,1,1,AAPL,-593,-4.5326360253444635,0.05850885908496694
2024-10-21T11:57:28.163878325Z,2024-10-21T11:57:28.163711748Z,10,2,38,A,B,0,233.54,200,130,166577,11526622,233.54,233.72,200,20,1,1,233.53,233.75,10,201,1,2,233.47,233.77,27,8,1,1,233.45,233.78,15,350,1,3,233.4,233.8,110,25,2,1,233.39,233.83,10,30,1,1,233.31,233.94,110,200,2,1,233.3,233.98,100,44,1,3,233.25,234.0,55,154,2,7,233.24,234.13,1,400,1,1,AAPL,-593,-4.471577726218097,0.05772069709720159
2024-10-21T11:57:28.163892251Z,2024-10-21T11:57:28.163725884Z,10,2,38,A,A,2,233.77,200,130,166367,11526623,233.54,233.72,200,20,1,1,233.53,233.75,10,201,1,2,233.47,233.77,27,208,1,2,233.45,233.78,15,150,1,2,233.4,233.8,110,25,2,1,233.39,233.83,10,30,1,1,233.31,233.94,110,200,2,1,233.3,233.98,100,44,1,3,233.25,234.0,55,154,2,7,233.24,234.13,1,400,1,1,AAPL,-593,-4.4150767798976265,0.05699136302141278
2024-10-21T11:57:29.332119420Z,2024-10-21T11:57:29.331953680Z,10,2,38,C,A,2,233.77,200,130,165740,11527067,233.54,233.72,200,20,1,1,233.53,233.75,10,201,1,2,233.47,233.77,27,8,1,1,233.45,233.78,15,150,1,2,233.4,233.8,110,25,2,1,233.39,233.83,10,30,1,1,233.31,233.94,110,200,2,1,233.3,233.98,100,44,1,3,233.25,234.0,55,154,2,7,233.24,234.13,1,400,1,1,AAPL,-593,-4.277727682596934,0.05521841259378542
2024-10-21T11:57:29.332132648Z,2024-10-21T11:57:29.331966683Z,10,2,38,A,A,3,233.78,200,130,165965,11527068,233.54,233.72,200,20,1,1,233.53,233.75,10,201,1,2,233.47,233.77,27,8,1,1,233.45,233.78,15,350,1,3,233.4,233.8,110,25,2,1,233.39,233.83,10,30,1,1,233.31,233.94,110,200,2,1,233.3,233.98,100,44,1,3,233.25,234.0,55,154,2,7,233.24,234.13,1,400,1,1,AAPL,-593,-4.231659559655383,0.05462374906942019
2024-10-21T11:57:30.995359196Z,2024-10-21T11:57:30.995192991Z,10,2,38,A,B,0,233.54,200,130,166205,11528694,233.54,233.72,400,20,2,1,233.53,233.75,10,201,1,2,233.47,233.77,27,8,1,1,233.45,233.78,15,350,1,3,233.4,233.8,110,25,2,1,233.39,233.83,10,30,1,1,233.31,233.94,110,200,2,1,233.3,233.98,100,44,1,3,233.25,234.0,55,154,2,7,233.24,234.13,1,400,1,1,AAPL,-593,-4.108313619466036,0.053031556316044885
2024-10-21T11:57:31.496401280Z,2024-10-21T11:57:31.496234971Z,10,2,38,A,A,1,233.74,500,130,166309,11528948,233.54,233.72,400,20,2,1,233.53,233.74,10,500,1,1,233.47,233.75,27,201,1,2,233.45,233.77,15,8,1,1,233.4,233.78,110,350,2,3,233.39,233.8,10,25,1,1,233.31,233.83,110,30,2,1,233.3,233.94,100,200,1,1,233.25,233.98,55,44,2,3,233.24,234.0,1,154,1,7,AAPL,-747,-5.23292469352014,0.06754843137270121
2024-10-21T11:57:36.264708785Z,2024-10-21T11:57:36.264542456Z,10,2,38,C,A,0,233.72,20,130,166329,11532750,233.54,233.74,400,500,2,1,233.53,233.75,10,201,1,2,233.47,233.77,27,8,1,1,233.45,233.78,15,350,1,3,233.4,233.8,110,25,2,1,233.39,233.83,10,30,1,1,233.31,233.94,110,200,2,1,233.3,233.98,100,44,1,3,233.25,234.0,55,154,2,7,233.24,234.13,1,400,1,1,AAPL,-2,-0.011491250979367982,0.00014833310693874527
2024-10-21T11:57:36.268101167Z,2024-10-21T11:57:36.267934826Z,10,2,38,C,B,0,233.54,200,130,166341,11532755,233.54,233.74,200,500,1,1,233.53,233.75,10,201,1,2,233.47,233.77,27,8,1,1,233.45,233.78,15,350,1,3,233.4,233.8,110,25,2,1,233.39,233.83,10,30,1,1,233.31,233.94,110,200,2,1,233.3,233.98,100,44,1,3,233.25,234.0,55,154,2,7,233.24,234.13,1,400,1,1,AAPL,-2,-0.011440107671601616,0.00014767293114467984
2024-10-21T11:57:37.888147782Z,2024-10-21T11:57:37.887981490Z,10,2,38,A,B,0,233.65,1,130,166292,11533577,233.65,233.74,1,500,1,1,233.54,233.75,200,201,1,2,233.53,233.77,10,8,1,1,233.47,233.78,27,350,1,3,233.45,233.8,15,25,1,1,233.4,233.83,110,30,2,1,233.39,233.94,10,200,1,1,233.31,233.98,110,44,2,3,233.3,234.0,100,154,1,7,233.25,234.13,55,400,2,1,AAPL,53,0.271144483868306,-0.003500028307944972
2024-10-21T11:57:38.017129745Z,2024-10-21T11:57:38.016963535Z,10,2,38,A,B,1,233.54,200,130,166210,11533703,233.65,233.74,1,500,1,1,233.54,233.75,400,201,2,2,233.53,233.77,10,8,1,1,233.47,233.78,27,350,1,3,233.45,233.8,15,25,1,1,233.4,233.83,110,30,2,1,233.39,233.94,10,200,1,1,233.31,233.98,110,44,2,3,233.3,234.0,100,154,1,7,233.25,234.13,55,400,2,1,AAPL,53,0.2697630030221091,-0.0034821956675770366
2024-10-21T11:57:40.885606594Z,2024-10-21T11:57:40.885440558Z,10,2,38,C,B,3,233.47,27,130,166036,11535145,233.65,233.74,1,500,1,1,233.54,233.75,400,201,2,2,233.53,233.77,10,8,1,1,233.45,233.78,15,350,1,3,233.4,233.8,110,25,2,1,233.39,233.83,10,30,1,1,233.31,233.94,110,200,2,1,233.3,233.98,100,44,1,3,233.25,234.0,55,154,2,7,233.24,234.13,1,400,1,1,AAPL,452,2.3105431309904154,-0.029825302915334525
2024-10-21T11:57:40.885648201Z,2024-10-21T11:57:40.885481569Z,10,2,38,A,B,3,233.48,26,130,166632,11535146,233.65,233.74,1,500,1,1,233.54,233.75,400,201,2,2,233.53,233.77,10,8,1,1,233.48,233.78,26,350,1,3,233.45,233.8,15,25,1,1,233.4,233.83,110,30,2,1,233.39,233.94,10,200,1,1,233.31,233.98,110,44,2,3,233.3,234.0,100,154,1,7,233.25,234.13,55,400,2,1,AAPL,507,2.5789595375722545,-0.03329011624271757
2024-10-21T11:57:41.319317780Z,2024-10-21T11:57:41.319151873Z,10,2,38,C,A,3,233.78,200,130,165907,11535430,233.65,233.74,1,500,1,1,233.54,233.75,400,201,2,2,233.53,233.77,10,8,1,1,233.48,233.78,26,150,1,2,233.45,233.8,15,25,1,1,233.4,233.83,110,30,2,1,233.39,233.94,10,200,1,1,233.31,233.98,110,44,2,3,233.3,234.0,100,154,1,7,233.25,234.13,55,400,2,1,AAPL,507,2.5670886075949366,-0.03313688210581208
2024-10-21T11:57:41.319329838Z,2024-10-21T11:57:41.319163898Z,10,2,38,A,A,4,233.79,200,130,165940,11535431,233.65,233.74,1,500,1,1,233.54,233.75,400,201,2,2,233.53,233.77,10,8,1,1,233.48,233.78,26,150,1,2,233.45,233.79,15,200,1,1,233.4,233.8,110,25,2,1,233.39,233.83,10,30,1,1,233.31,233.94,110,200,2,1,233.3,233.98,100,44,1,3,233.25,234.0,55,154,2,7,AAPL,353,1.8117164014957108,-0.023386272148110593
2024-10-21T11:57:41.375862954Z,2024-10-21T11:57:41.375697228Z,10,2,38,C,B,1,233.54,200,130,165726,11535542,233.65,233.74,1,500,1,1,233.54,233.75,200,201,1,2,233.53,233.77,10,8,1,1,233.48,233.78,26,150,1,2,233.45,233.79,15,200,1,1,233.4,233.8,110,25,2,1,233.39,233.83,10,30,1,1,233.31,233.94,110,200,2,1,233.3,233.98,100,44,1,3,233.25,234.0,55,154,2,7,AAPL,353,1.8353552859618716,-0.023691411178119362
2024-10-21T11:57:41.375875655Z,2024-10-21T11:57:41.375709324Z,10,2,38,A,B,1,233.55,400,130,166331,11535543,233.65,233.74,1,500,1,1,233.55,233.75,400,201,1,2,233.53,233.77,10,8,1,1,233.48,233.78,26,150,1,2,233.45,233.79,15,200,1,1,233.4,233.8,110,25,2,1,233.39,233.83,10,30,1,1,233.31,233.94,110,200,2,1,233.3,233.98,100,44,1,3,233.25,234.0,55,154,2,7,AAPL,353,1.858291242797183,-0.023987476571182585
2024-10-21T11:57:41.965826689Z,2024-10-21T11:57:41.965660865Z,10,2,38,C,B,1,233.55,400,130,165824,11536042,233.65,233.74,1,500,1,1,233.53,233.75,10,201,1,2,233.48,233.77,26,8,1,1,233.45,233.78,15,150,1,2,233.4,233.79,110,200,2,1,233.39,233.8,10,25,1,1,233.31,233.83,110,30,2,1,233.3,233.94,100,200,1,1,233.25,233.98,55,44,2,3,233.24,234.0,1,154,1,7,AAPL,352,1.8823529411764706,-0.024298073431805584
2024-10-21T11:57:42.074339748Z,2024-10-21T11:57:42.074173420Z,10,2,38,A,B,2,233.49,200,130,166328,11536099,233.65,233.74,1,500,1,1,233.53,233.75,10,201,1,2,233.49,233.77,200,8,1,1,233.48,233.78,26,150,1,2,233.45,233.79,15,200,1,1,233.4,233.8,110,25,2,1,233.39,233.83,10,30,1,1,233.31,233.94,110,200,2,1,233.3,233.98,100,44,1,3,233.25,234.0,55,154,2,7,AAPL,407,2.2013729977116703,-0.028416096460508335
2024-10-21T11:57:42.169388484Z,2024-10-21T11:57:42.169221771Z,10,2,38,A,B,2,233.5,200,130,166713,11536143,233.65,233.74,1,500,1,1,233.53,233.75,10,201,1,2,233.5,233.77,200,8,1,1,233.48,233.78,26,150,1,2,233.45,233.79,15,200,1,1,233.4,233.8,110,25,2,1,233.39,233.83,10,30,1,1,233.31,233.94,110,200,2,1,233.3,233.98,100,44,1,3,233.25,234.0,55,154,2,7,AAPL,407,2.225563909774436,-0.028728361256777656
2024-10-21T11:57:42.208045550Z,2024-10-21T11:57:42.207878969Z,10,2,38,C,B,2,233.5,200,130,166581,11536169,233.65,233.74,1,500,1,1,233.53,233.75,10,201,1,2,233.48,233.77,26,8,1,1,233.45,233.78,15,150,1,2,233.4,233.79,110,200,2,1,233.39,233.8,10,25,1,1,233.31,233.83,110,30,2,1,233.3,233.94,100,200,1,1,233.25,233.98,55,44,2,3,233.24,234.0,1,154,1,7,AAPL,406,2.2517416300304363,-0.029066272471589487
2024-10-21T11:57:42.313426957Z,2024-10-21T11:57:42.313260974Z,10,2,38,A,B,2,233.49,200,130,165983,11536217,233.65,233.74,1,500,1,1,233.53,233.75,10,201,1,2,233.49,233.77,200,8,1,1,233.48,233.78,26,150,1,2,233.45,233.79,15,200,1,1,233.4,233.8,110,25,2,1,233.39,233.83,10,30,1,1,233.31,233.94,110,200,2,1,233.3,233.98,100,44,1,3,233.25,234.0,55,154,2,7,AAPL,461,2.5826330532212887,-0.03333753527399517
2024-10-21T11:57:42.380325383Z,2024-10-21T11:57:42.380159117Z,10,2,38,A,B,2,233.49,200,130,166266,11536247,233.65,233.74,1,500,1,1,233.53,233.75,10,201,1,2,233.49,233.77,400,8,2,1,233.48,233.78,26,150,1,2,233.45,233.79,15,200,1,1,233.4,233.8,110,25,2,1,233.39,233.83,10,30,1,1,233.31,233.94,110,200,2,1,233.3,233.98,100,44,1,3,233.25,234.0,55,154,2,7,AAPL,461,2.6077747812931658,-0.03366207353753205
2024-10-21T11:57:42.412490406Z,2024-10-21T11:57:42.412324426Z,10,2,38,C,B,2,233.49,200,130,165980,11536276,233.65,233.74,1,500,1,1,233.53,233.75,10,201,1,2,233.49,233.77,200,8,1,1,233.48,233.78,26,150,1,2,233.45,233.79,15,200,1,1,233.4,233.8,110,25,2,1,233.39,233.83,10,30,1,1,233.31,233.94,110,200,2,1,233.3,233.98,100,44,1,3,233.25,234.0,55,154,2,7,AAPL,461,2.6322346223721778,-0.033977809764074496
2024-10-21T11:57:42.412502842Z,2024-10-21T11:57:42.412336614Z,10,2,38,A,B,2,233.5,200,130,166228,11536277,233.65,233.74,1,500,1,1,233.53,233.75,10,201,1,2,233.5,233.77,200,8,1,1,233.48,233.78,26,150,1,2,233.45,233.79,15,200,1,1,233.4,233.8,110,25,2,1,233.39,233.83,10,30,1,1,233.31,233.94,110,200,2,1,233.3,233.98,100,44,1,3,233.25,234.0,55,154,2,7,AAPL,461,2.656039946226234,-0.034285097252207436
2024-10-21T11:57:48.073129275Z,2024-10-21T11:57:48.072962640Z,10,2,38,A,B,2,233.5,200,130,166635,11540432,233.65,233.74,1,500,1,1,233.53,233.75,10,201,1,2,233.5,233.77,400,8,2,1,233.48,233.78,26,150,1,2,233.45,233.79,15,200,1,1,233.4,233.8,110,25,2,1,233.39,233.83,10,30,1,1,233.31,233.94,110,200,2,1,233.3,233.98,100,44,1,3,233.25,234.0,55,154,2,7,AAPL,310,2.0190380761523046,-0.026062453200353844
2024-10-21T11:57:48.073140030Z,2024-10-21T11:57:48.072974095Z,10,2,38,C,A,4,233.79,200,130,165935,11540433,233.65,233.74,1,500,1,1,233.53,233.75,10,201,1,2,233.5,233.77,400,8,2,1,233.48,233.78,26,150,1,2,233.45,233.8,15,25,1,1,233.4,233.83,110,30,2,1,233.39,233.94,10,200,1,1,233.31,233.98,110,44,2,3,233.3,234.0,100,154,1,7,233.25,234.13,55,400,2,1,AAPL,710,4.54319232136509,-0.05864512346465164
2024-10-21T11:57:48.073150753Z,2024-10-21T11:57:48.072984615Z,10,2,38,A,A,4,233.8,200,130,166138,11540434,233.65,233.74,1,500,1,1,233.53,233.75,10,201,1,2,233.5,233.77,400,8,2,1,233.48,233.78,26,150,1,2,233.45,233.8,15,225,1,2,233.4,233.83,110,30,2,1,233.39,233.94,10,200,1,1,233.31,233.98,110,44,2,3,233.3,234.0,100,154,1,7,233.25,234.13,55,400,2,1,AAPL,710,4.470429503035754,-0.057705875428751226
2024-10-21T11:57:48.076825301Z,2024-10-21T11:57:48.076659157Z,10,2,38,C,A,5,233.83,30,130,166144,11540485,233.65,233.74,1,500,1,1,233.53,233.75,10,201,1,2,233.5,233.77,400,8,2,1,233.48,233.78,26,150,1,2,233.45,233.8,15,225,1,2,233.4,233.94,110,200,2,1,233.39,233.98,10,44,1,3,233.31,234.0,110,154,2,7,233.3,234.13,100,400,1,1,233.25,234.17,55,1,2,1,AAPL,711,4.607597765363128,-0.05947649157497757
2024-10-21T11:57:48.076908946Z,2024-10-21T11:57:48.076742621Z,10,2,38,A,A,5,233.86,28,130,166325,11540488,233.65,233.74,1,500,1,1,233.53,233.75,10,201,1,2,233.5,233.77,400,8,2,1,233.48,233.78,26,150,1,2,233.45,233.8,15,225,1,2,233.4,233.86,110,28,2,1,233.39,233.94,10,200,1,1,233.31,233.98,110,44,2,3,233.3,234.0,100,154,1,7,233.25,234.13,55,400,2,1,AAPL,311,1.9840510366826156,-0.025610828196562227
2024-10-21T11:57:48.136642704Z,2024-10-21T11:57:48.136477014Z,10,2,38,C,B,2,233.5,200,130,165690,11540727,233.65,233.74,1,500,1,1,233.53,233.75,10,201,1,2,233.5,233.77,200,8,1,1,233.48,233.78,26,150,1,2,233.45,233.8,15,225,1,2,233.4,233.86,110,28,2,1,233.39,233.94,10,200,1,1,233.31,233.98,110,44,2,3,233.3,234.0,100,154,1,7,233.25,234.13,55,400,2,1,AAPL,311,1.955578093306288,-0.02524328943491785
2024-10-21T11:57:48.136655500Z,2024-10-21T11:57:48.136488492Z,10,2,38,A,B,2,233.51,200,130,167008,11540728,233.65,233.74,1,500,1,1,233.53,233.75,10,201,1,2,233.51,233.77,200,8,1,1,233.48,233.78,26,150,1,2,233.45,233.8,15,225,1,2,233.4,233.86,110,28,2,1,233.39,233.94,10,200,1,1,233.31,233.98,110,44,2,3,233.3,234.0,100,154,1,7,233.25,234.13,55,400,2,1,AAPL,311,1.9296170625302957,-0.024908175324082626
2024-10-21T11:57:48.194778031Z,2024-10-21T11:57:48.194611663Z,10,2,38,C,B,3,233.48,26,130,166368,11540865,233.65,233.74,1,500,1,1,233.53,233.75,10,201,1,2,233.51,233.77,200,8,1,1,233.45,233.78,15,150,1,2,233.4,233.8,110,225,2,2,233.39,233.86,10,28,1,1,233.31,233.94,110,200,2,1,233.3,233.98,100,44,1,3,233.25,234.0,55,154,2,7,233.24,234.13,1,400,1,1,AAPL,309,1.9489120151371806,-0.025157241354713564
2024-10-21T11:57:48.194826771Z,2024-10-21T11:57:48.194659897Z,10,2,38,A,B,3,233.49,29,130,166874,11540868,233.65,233.74,1,500,1,1,233.53,233.75,10,201,1,2,233.51,233.77,200,8,1,1,233.49,233.78,29,150,1,2,233.45,233.8,15,225,1,2,233.4,233.86,110,28,2,1,233.39,233.94,10,200,1,1,233.31,233.98,110,44,2,3,233.3,234.0,100,154,1,7,233.25,234.13,55,400,2,1,AAPL,364,2.264044943820225,-0.029225087970733865
2024-10-21T11:57:51.070775104Z,2024-10-21T11:57:51.070607242Z,10,2,38,T,N,0,233.71,50,130,167862,11543012,233.65,233.74,1,500,1,1,233.53,233.75,10,201,1,2,233.51,233.77,200,8,1,1,233.49,233.78,29,150,1,2,233.45,233.8,15,225,1,2,233.4,233.86,110,28,2,1,233.39,233.94,10,200,1,1,233.31,233.98,110,44,2,3,233.3,234.0,100,154,1,7,233.25,234.13,55,400,2,1,AAPL,364,2.2898047722342736,-0.029557604890756352
2024-10-21T11:57:51.271362157Z,2024-10-21T11:57:51.271195500Z,10,2,38,A,A,4,233.79,200,130,166657,11543518,233.65,233.74,1,500,1,1,233.53,233.75,10,201,1,2,233.51,233.77,200,8,1,1,233.49,233.78,29,150,1,2,233.45,233.79,15,200,1,1,233.4,233.8,110,25,2,1,233.39,233.86,10,28,1,1,233.31,233.94,110,200,2,1,233.3,233.98,100,44,1,3,233.25,234.0,55,154,2,7,AAPL,210,1.3363028953229399,-0.017249467497523454
2024-10-21T11:57:51.287274496Z,2024-10-21T11:57:51.287108312Z,10,2,38,C,A,6,233.86,28,130,166184,11543617,233.65,233.74,1,500,1,1,233.53,233.75,10,201,1,2,233.51,233.77,200,8,1,1,233.49,233.78,29,150,1,2,233.45,233.79,15,200,1,1,233.4,233.8,110,25,2,1,233.39,233.94,10,200,1,1,233.31,233.98,110,44,2,3,233.3,234.0,100,154,1,7,233.25,234.13,55,400,2,1,AAPL,610,3.826386078510725,-0.04939233651686149
2024-10-21T11:57:51.287324161Z,2024-10-21T11:57:51.287157718Z,10,2,38,A,A,6,233.85,29,130,166443,11543618,233.65,233.74,1,500,1,1,233.53,233.75,10,201,1,2,233.51,233.77,200,8,1,1,233.49,233.78,29,150,1,2,233.45,233.79,15,200,1,1,233.4,233.8,110,25,2,1,233.39,233.85,10,29,1,1,233.31,233.94,110,200,2,1,233.3,233.98,100,44,1,3,233.25,234.0,55,154,2,7,AAPL,456,2.8915089666105223,-0.03732461413719546
2024-10-21T11:57:51.322868054Z,2024-10-21T11:57:51.322699915Z,10,2,38,T,N,0,233.71,7,130,168139,11543733,233.65,233.74,1,500,1,1,233.53,233.75,10,201,1,2,233.51,233.77,200,8,1,1,233.49,233.78,29,150,1,2,233.45,233.79,15,200,1,1,233.4,233.8,110,25,2,1,233.39,233.85,10,29,1,1,233.31,233.94,110,200,2,1,233.3,233.98,100,44,1,3,233.25,234.0,55,154,2,7,AAPL,456,2.9213744903902152,-0.037710128816193324
2024-10-21T11:57:52.318095141Z,2024-10-21T11:57:52.317929239Z,10,2,38,C,A,4,233.79,200,130,165902,11544404,233.65,233.74,1,500,1,1,233.53,233.75,10,201,1,2,233.51,233.77,200,8,1,1,233.49,233.78,29,150,1,2,233.45,233.8,15,25,1,1,233.4,233.85,110,29,2,1,233.39,233.94,10,200,1,1,233.31,233.98,110,44,2,3,233.3,234.0,100,154,1,7,233.25,234.13,55,400,2,1,AAPL,1010,6.287492925863045,-0.0811611688077448
2024-10-21T11:57:52.318108707Z,2024-10-21T11:57:52.317942384Z,10,2,38,A,A,4,233.8,200,130,166323,11544405,233.65,233.74,1,500,1,1,233.53,233.75,10,201,1,2,233.51,233.77,200,8,1,1,233.49,233.78,29,150,1,2,233.45,233.8,15,225,1,2,233.4,233.85,110,29,2,1,233.39,233.94,10,200,1,1,233.31,233.98,110,44,2,3,233.3,234.0,100,154,1,7,233.25,234.13,55,400,2,1,AAPL,1010,6.211449760332822,-0.08017957689709837
2024-10-21T11:57:58.266750822Z,2024-10-21T11:57:58.266584280Z,10,2,38,A,A,4,233.79,200,130,166542,11548474,233.65,233.74,1,500,1,1,233.53,233.75,10,201,1,2,233.51,233.77,200,8,1,1,233.49,233.78,29,150,1,2,233.45,233.79,15,200,1,1,233.4,233.8,110,25,2,1,233.39,233.85,10,29,1,1,233.31,233.94,110,200,2,1,233.3,233.98,100,44,1,3,233.25,234.0,55,154,2,7,AAPL,401,2.6022608331588866,-0.0335908975568033
2024-10-21T11:58:06.284887079Z,2024-10-21T11:58:06.284720780Z,10,2,38,C,B,2,233.51,200,130,166299,11554578,233.65,233.74,1,500,1,1,233.53,233.75,10,201,1,2,233.49,233.77,29,8,1,1,233.45,233.78,15,150,1,2,233.4,233.79,110,200,2,1,233.39,233.8,10,25,1,1,233.31,233.85,110,29,2,1,233.3,233.94,100,200,1,1,233.25,233.98,55,44,2,3,233.24,234.0,1,154,1,7,AAPL,392,2.2735621072982117,-0.029347938862292006
2024-10-21T11:58:06.284899850Z,2024-10-21T11:58:06.284733562Z,10,2,38,A,B,2,233.49,200,130,166288,11554579,233.65,233.74,1,500,1,1,233.53,233.75,10,201,1,2,233.49,233.77,229,8,2,1,233.45,233.78,15,150,1,2,233.4,233.79,110,200,2,1,233.39,233.8,10,25,1,1,233.31,233.85,110,29,2,1,233.3,233.94,100,200,1,1,233.25,233.98,55,44,2,3,233.24,234.0,1,154,1,7,AAPL,392,2.3414020748192392,-0.030223641009524287
2024-10-21T11:58:06.339737678Z,2024-10-21T11:58:06.339571308Z,10,2,38,A,A,3,233.78,200,130,166370,11554687,233.65,233.74,1,500,1,1,233.53,233.75,10,201,1,2,233.49,233.77,229,8,2,1,233.45,233.78,15,350,1,3,233.4,233.8,110,25,2,1,233.39,233.85,10,29,1,1,233.31,233.94,110,200,2,1,233.3,233.98,100,44,1,3,233.25,234.0,55,154,2,7,233.24,234.13,1,400,1,1,AAPL,792,4.6843116959929025,-0.060466741957310076
2024-10-21T11:58:06.359996032Z,2024-10-21T11:58:06.359829740Z,10,2,38,A,B,2,233.49,200,130,166292,11554809,233.65,233.74,1,500,1,1,233.53,233.75,10,201,1,2,233.49,233.77,429,8,3,1,233.45,233.78,15,350,1,3,233.4,233.8,110,25,2,1,233.39,233.85,10,29,1,1,233.31,233.94,110,200,2,1,233.3,233.98,100,44,1,3,233.25,234.0,55,154,2,7,233.24,234.13,1,400,1,1,AAPL,792,4.643216080402009,-0.059936265305716406
2024-10-21T11:58:06.360372874Z,2024-10-21T11:58:06.360206541Z,10,2,38,A,A,5,233.84,29,130,166333,11554810,233.65,233.74,1,500,1,1,233.53,233.75,10,201,1,2,233.49,233.77,429,8,3,1,233.45,233.78,15,350,1,3,233.4,233.8,110,25,2,1,233.39,233.84,10,29,1,1,233.31,233.85,110,29,2,1,233.3,233.94,100,200,1,1,233.25,233.98,55,44,2,3,233.24,234.0,1,154,1,7,AAPL,638,3.835496652548162,-0.049509939009000505
2024-10-21T11:58:06.360409628Z,2024-10-21T11:58:06.360243785Z,10,2,38,C,A,6,233.85,29,130,165843,11554811,233.65,233.74,1,500,1,1,233.53,233.75,10,201,1,2,233.49,233.77,429,8,3,1,233.45,233.78,15,350,1,3,233.4,233.8,110,25,2,1,233.39,233.84,10,29,1,1,233.31,233.94,110,200,2,1,233.3,233.98,100,44,1,3,233.25,234.0,55,154,2,7,233.24,234.13,1,400,1,1,AAPL,1038,6.184974093264248,-0.07983781968009837
2024-10-21T11:58:06.414826565Z,2024-10-21T11:58:06.414660818Z,10,2,38,C,B,2,233.49,200,130,165747,11554881,233.65,233.74,1,500,1,1,233.53,233.75,10,201,1,2,233.49,233.77,229,8,2,1,233.45,233.78,15,350,1,3,233.4,233.8,110,25,2,1,233.39,233.84,10,29,1,1,233.31,233.94,110,200,2,1,233.3,233.98,100,44,1,3,233.25,234.0,55,154,2,7,233.24,234.13,1,400,1,1,AAPL,1038,6.135205024011821,-0.07919538303983033
2024-10-21T11:58:06.414839107Z,2024-10-21T11:58:06.414672832Z,10,2,38,A,B,2,233.51,200,130,166275,11554882,233.65,233.74,1,500,1,1,233.53,233.75,10,201,1,2,233.51,233.77,200,8,1,1,233.49,233.78,29,350,1,3,233.45,233.8,15,25,1,1,233.4,233.84,110,29,2,1,233.39,233.94,10,200,1,1,233.31,233.98,110,44,2,3,233.3,234.0,100,154,1,7,233.25,234.13,55,400,2,1,AAPL,1093,6.372434701492537,-0.08225762710550875
2024-10-21T11:58:14.036518564Z,2024-10-21T11:58:14.036350634Z,10,2,38,T,N,0,233.73,87,130,167930,11561326,233.65,233.74,1,500,1,1,233.53,233.75,10,201,1,2,233.51,233.77,200,8,1,1,233.49,233.78,29,350,1,3,233.45,233.8,15,25,1,1,233.4,233.84,110,29,2,1,233.39,233.94,10,200,1,1,233.31,233.98,110,44,2,3,233.3,234.0,100,154,1,7,233.25,234.13,55,400,2,1,AAPL,546,3.42534504391468,-0.04421555787210231
2024-10-21T11:58:14.036543021Z,2024-10-21T11:58:14.036377136Z,10,2,38,C,A,3,233.78,200,130,165885,11561327,233.65,233.74,1,500,1,1,233.53,233.75,10,201,1,2,233.51,233.77,200,8,1,1,233.49,233.78,29,150,1,2,233.45,233.8,15,25,1,1,233.4,233.84,110,29,2,1,233.39,233.94,10,200,1,1,233.31,233.98,110,44,2,3,233.3,234.0,100,154,1,7,233.25,234.13,55,400,2,1,AAPL,546,3.2972824595113917,-0.0425624810172628
2024-10-21T11:58:14.144875530Z,2024-10-21T11:58:14.144708873Z,10,2,38,A,A,3,233.78,200,130,166657,11561371,233.65,233.74,1,500,1,1,233.53,233.75,10,201,1,2,233.51,233.77,200,8,1,1,233.49,233.78,29,350,1,3,233.45,233.8,15,25,1,1,233.4,233.84,110,29,2,1,233.39,233.94,10,200,1,1,233.31,233.98,110,44,2,3,233.3,234.0,100,154,1,7,233.25,234.13,55,400,2,1,AAPL,546,3.1976573938506587,-0.0412764856504428
2024-10-21T11:58:18.578872390Z,2024-10-21T11:58:18.578706483Z,10,2,38,C,A,3,233.78,200,130,165907,11564710,233.65,233.74,1,500,1,1,233.53,233.75,10,201,1,2,233.51,233.77,200,8,1,1,233.49,233.78,29,150,1,2,233.45,233.8,15,25,1,1,233.4,233.84,110,29,2,1,233.39,233.94,10,200,1,1,233.31,233.98,110,44,2,3,233.3,234.0,100,154,1,7,233.25,234.13,55,400,2,1,AAPL,700,3.867403314917127,-0.049921801422390624
2024-10-21T11:58:18.578884023Z,2024-10-21T11:58:18.578717695Z,10,2,38,A,A,4,233.79,200,130,166328,11564711,233.65,233.74,1,500,1,1,233.53,233.75,10,201,1,2,233.51,233.77,200,8,1,1,233.49,233.78,29,150,1,2,233.45,233.79,15,200,1,1,233.4,233.8,110,25,2,1,233.39,233.84,10,29,1,1,233.31,233.94,110,200,2,1,233.3,233.98,100,44,1,3,233.25,234.0,55,154,2,7,AAPL,546,3.1179442126070724,-0.040247519886918694
2024-10-21T11:58:18.649746443Z,2024-10-21T11:58:18.649580622Z,10,2,38,C,A,4,233.79,200,130,165821,11564816,233.65,233.74,1,500,1,1,233.53,233.75,10,201,1,2,233.51,233.77,200,8,1,1,233.49,233.78,29,150,1,2,233.45,233.8,15,25,1,1,233.4,233.84,110,29,2,1,233.39,233.94,10,200,1,1,233.31,233.98,110,44,2,3,233.3,234.0,100,154,1,7,233.25,234.13,55,400,2,1,AAPL,946,5.289137380191693,-0.06827404449161548
2024-10-21T11:58:18.666361221Z,2024-10-21T11:58:18.666193529Z,10,2,38,T,B,0,233.74,65,130,167692,11564831,233.65,233.74,1,500,1,1,233.53,233.75,10,201,1,2,233.51,233.77,200,8,1,1,233.49,233.78,29,150,1,2,233.45,233.8,15,25,1,1,233.4,233.84,110,29,2,1,233.39,233.94,10,200,1,1,233.31,233.98,110,44,2,3,233.3,234.0,100,154,1,7,233.25,234.13,55,400,2,1,AAPL,946,5.194947830862164,-0.06705821268024051
2024-10-21T11:58:18.666361221Z,2024-10-21T11:58:18.666193529Z,10,2,38,C,A,0,233.74,65,130,167692,11564831,233.65,233.74,1,435,1,1,233.53,233.75,10,201,1,2,233.51,233.77,200,8,1,1,233.49,233.78,29,150,1,2,233.45,233.8,15,25,1,1,233.4,233.84,110,29,2,1,233.39,233.94,10,200,1,1,233.31,233.98,110,44,2,3,233.3,234.0,100,154,1,7,233.25,234.13,55,400,2,1,AAPL,946,5.115241635687732,-0.06602933709535273
2024-10-21T11:58:18.722126458Z,2024-10-21T11:58:18.721960191Z,10,2,38,A,A,5,233.83,400,130,166267,11565202,233.65,233.74,1,435,1,1,233.53,233.75,10,201,1,2,233.51,233.77,200,8,1,1,233.49,233.78,29,150,1,2,233.45,233.8,15,25,1,1,233.4,233.83,110,400,2,1,233.39,233.84,10,29,1,1,233.31,233.94,110,200,2,1,233.3,233.98,100,44,1,3,233.25,234.0,55,154,2,7,AAPL,792,4.3949730700179535,-0.0567318572676179
2024-10-21T11:58:18.722718534Z,2024-10-21T11:58:18.722551669Z,10,2,38,A,A,7,233.9,27,130,166865,11565205,233.65,233.74,1,435,1,1,233.53,233.75,10,201,1,2,233.51,233.77,200,8,1,1,233.49,233.78,29,150,1,2,233.45,233.8,15,25,1,1,233.4,233.83,110,400,2,1,233.39,233.84,10,29,1,1,233.31,233.9,110,27,2,1,233.3,233.94,100,200,1,1,233.25,233.98,55,44,2,3,AAPL,748,4.3250883392226145,-0.055829760597284735
2024-10-21T11:58:18.722745911Z,2024-10-21T11:58:18.722579315Z,10,2,38,C,A,6,233.84,29,130,166596,11565206,233.65,233.74,1,435,1,1,233.53,233.75,10,201,1,2,233.51,233.77,200,8,1,1,233.49,233.78,29,150,1,2,233.45,233.8,15,25,1,1,233.4,233.83,110,400,2,1,233.39,233.9,10,27,1,1,233.31,233.94,110,200,2,1,233.3,233.98,100,44,1,3,233.25,234.0,55,154,2,7,AAPL,902,5.326495726495726,-0.0687562791575644
2024-10-21T11:58:18.734002535Z,2024-10-21T11:58:18.733836431Z,10,2,38,C,A,5,233.83,400,130,166104,11565231,233.65,233.74,1,435,1,1,233.53,233.75,10,201,1,2,233.51,233.77,200,8,1,1,233.49,233.78,29,150,1,2,233.45,233.8,15,25,1,1,233.4,233.9,110,27,2,1,233.39,233.94,10,200,1,1,233.31,233.98,110,44,2,3,233.3,234.0,100,154,1,7,233.25,234.13,55,400,2,1,AAPL,1302,7.5587808417997095,-0.09757140009789275
2024-10-21T11:58:18.771912264Z,2024-10-21T11:58:18.771745684Z,10,2,38,A,A,5,233.83,200,130,166580,11565306,233.65,233.74,1,435,1,1,233.53,233.75,10,201,1,2,233.51,233.77,200,8,1,1,233.49,233.78,29,150,1,2,233.45,233.8,15,25,1,1,233.4,233.83,110,200,2,1,233.39,233.9,10,27,1,1,233.31,233.94,110,200,2,1,233.3,233.98,100,44,1,3,233.25,234.0,55,154,2,7,AAPL,1148,6.791942527116496,-0.08767278158012992
2024-10-21T11:58:19.575062840Z,2024-10-21T11:58:19.574896952Z,10,2,38,C,A,5,233.83,200,130,165888,11566008,233.65,233.74,1,435,1,1,233.53,233.75,10,201,1,2,233.51,233.77,200,8,1,1,233.49,233.78,29,150,1,2,233.45,233.8,15,25,1,1,233.4,233.9,110,27,2,1,233.39,233.94,10,200,1,1,233.31,233.98,110,44,2,3,233.3,234.0,100,154,1,7,233.25,234.13,55,400,2,1,AAPL,1548,9.016679904686258,-0.11639047366867476
2024-10-21T11:58:19.575074157Z,2024-10-21T11:58:19.574907103Z,10,2,38,A,A,5,233.85,200,130,167054,11566009,233.65,233.74,1,435,1,1,233.53,233.75,10,201,1,2,233.51,233.77,200,8,1,1,233.49,233.78,29,150,1,2,233.45,233.8,15,25,1,1,233.4,233.85,110,200,2,1,233.39,233.9,10,27,1,1,233.31,233.94,110,200,2,1,233.3,233.98,100,44,1,3,233.25,234.0,55,154,2,7,AAPL,1394,8.260208682210484,-0.10662567722126884
2024-10-21T11:58:19.604637959Z,2024-10-21T11:58:19.604471701Z,10,2,38,A,B,2,233.52,200,130,166258,11566140,233.65,233.74,1,435,1,1,233.53,233.75,10,201,1,2,233.52,233.77,200,8,1,1,233.49,233.78,29,150,1,2,233.45,233.8,15,25,1,1,233.4,233.85,110,200,2,1,233.39,233.9,10,27,1,1,233.31,233.94,110,200,2,1,233.3,233.98,100,44,1,3,233.25,234.0,55,154,2,7,AAPL,1394,8.393376818866031,-0.10834465833923647
2024-10-21T11:58:19.632669907Z,2024-10-21T11:58:19.632503658Z,10,2,38,A,A,5,233.84,200,130,166249,11566182,233.65,233.74,1,435,1,1,233.53,233.75,10,201,1,2,233.52,233.77,200,8,1,1,233.49,233.78,29,150,1,2,233.45,233.8,15,25,1,1,233.4,233.84,110,200,2,1,233.39,233.9,10,27,1,1,233.31,233.94,110,200,2,1,233.3,233.98,100,44,1,3,233.25,234.0,55,154,2,7,AAPL,1394,8.519740862975187,-0.10997580983890431
2024-10-21T11:58:21.722523136Z,2024-10-21T11:58:21.722356897Z,10,2,38,A,A,5,233.84,200,130,166239,11567782,233.65,233.74,1,435,1,1,233.53,233.75,10,201,1,2,233.52,233.77,200,8,1,1,233.49,233.78,29,150,1,2,233.45,233.8,15,25,1,1,233.4,233.84,110,400,2,2,233.39,233.9,10,27,1,1,233.31,233.94,110,200,2,1,233.3,233.98,100,44,1,3,233.25,234.0,55,154,2,7,AAPL,1394,8.639809296781884,-0.11152569538781398
2024-10-21T11:58:21.794830742Z,2024-10-21T11:58:21.794663862Z,10,2,38,A,B,1,233.55,200,130,166880,11567840,233.65,233.74,1,435,1,1,233.55,233.75,200,201,1,2,233.53,233.77,10,8,1,1,233.49,233.78,29,150,1,2,233.45,233.8,15,25,1,1,233.4,233.84,110,400,2,2,233.39,233.9,10,27,1,1,233.31,233.94,110,200,2,1,233.3,233.98,100,44,1,3,233.25,234.0,55,154,2,7,AAPL,1394,8.754041167577626,-0.1130002405297642
2024-10-21T11:58:32.993512492Z,2024-10-21T11:58:32.993346096Z,10,2,38,A,B,1,233.56,200,130,166396,11577193,233.65,233.74,1,435,1,1,233.56,233.75,200,201,1,2,233.53,233.77,10,8,1,1,233.49,233.78,29,150,1,2,233.45,233.8,15,25,1,1,233.4,233.84,110,400,2,2,233.39,233.9,10,27,1,1,233.31,233.94,110,200,2,1,233.3,233.98,100,44,1,3,233.25,234.0,55,154,2,7,AAPL,694,4.417568427753023,-0.05702352608777099
2024-10-21T11:58:37.947719334Z,2024-10-21T11:58:37.947553299Z,10,2,38,C,A,5,233.84,200,130,166035,11580485,233.65,233.74,1,435,1,1,233.56,233.75,200,201,1,2,233.53,233.77,10,8,1,1,233.49,233.78,29,150,1,2,233.45,233.8,15,25,1,1,233.4,233.84,110,200,2,1,233.39,233.9,10,27,1,1,233.31,233.94,110,200,2,1,233.3,233.98,100,44,1,3,233.25,234.0,55,154,2,7,AAPL,694,4.872074882995319,-0.06289045517589656
2024-10-21T11:58:37.947728963Z,2024-10-21T11:58:37.947562931Z,10,2,38,C,A,5,233.84,200,130,166032,11580486,233.65,233.74,1,435,1,1,233.56,233.75,200,201,1,2,233.53,233.77,10,8,1,1,233.49,233.78,29,150,1,2,233.45,233.8,15,25,1,1,233.4,233.9,110,27,2,1,233.39,233.94,10,200,1,1,233.31,233.98,110,44,2,3,233.3,234.0,100,154,1,7,233.25,234.13,55,400,2,1,AAPL,1094,7.446175891097975,-0.09611785581239572
2024-10-21T11:58:37.947740754Z,2024-10-21T11:58:37.947573917Z,10,2,38,A,A,5,233.85,400,130,166837,11580487,233.65,233.74,1,435,1,1,233.56,233.75,200,201,1,2,233.53,233.77,10,8,1,1,233.49,233.78,29,150,1,2,233.45,233.8,15,25,1,1,233.4,233.85,110,400,2,1,233.39,233.9,10,27,1,1,233.31,233.94,110,200,2,1,233.3,233.98,100,44,1,3,233.25,234.0,55,154,2,7,AAPL,940,6.4917127071823195,-0.08379730953044139
2024-10-21T11:58:40.491589839Z,2024-10-21T11:58:40.491423845Z,10,2,38,C,B,3,233.49,29,130,165994,11582081,233.65,233.74,1,435,1,1,233.56,233.75,200,201,1,2,233.53,233.77,10,8,1,1,233.45,233.78,15,150,1,2,233.4,233.8,110,25,2,1,233.39,233.85,10,400,1,1,233.31,233.9,110,27,2,1,233.3,233.94,100,200,1,1,233.25,233.98,55,44,2,3,233.24,234.0,1,154,1,7,AAPL,245,2.072507552870091,-0.02675265600091737
2024-10-21T11:58:40.491633125Z,2024-10-21T11:58:40.491466764Z,10,2,38,A,B,3,233.5,26,130,166361,11582082,233.65,233.74,1,435,1,1,233.56,233.75,200,201,1,2,233.53,233.77,10,8,1,1,233.5,233.78,26,150,1,2,233.45,233.8,15,25,1,1,233.4,233.85,110,400,2,1,233.39,233.9,10,27,1,1,233.31,233.94,110,200,2,1,233.3,233.98,100,44,1,3,233.25,234.0,55,154,2,7,AAPL,300,2.575107296137339,-0.033240390156171806
2024-10-21T11:58:50.556894132Z,2024-10-21T11:58:50.556727313Z,10,2,38,A,A,5,233.84,400,130,166819,11587782,233.65,233.74,1,435,1,1,233.56,233.75,200,201,1,2,233.53,233.77,10,8,1,1,233.5,233.78,26,150,1,2,233.45,233.8,15,25,1,1,233.4,233.84,110,400,2,1,233.39,233.9,10,27,1,1,233.31,233.94,110,200,2,1,233.3,233.98,100,44,1,3,233.25,234.0,55,154,2,7,AAPL,300,2.5377643504531724,-0.03275835428683759
2024-10-21T11:58:53.131507522Z,2024-10-21T11:58:53.131341094Z,10,2,38,A,B,1,233.56,200,130,166428,11589174,233.65,233.74,1,435,1,1,233.56,233.75,400,201,2,2,233.53,233.77,10,8,1,1,233.5,233.78,26,150,1,2,233.45,233.8,15,25,1,1,233.4,233.84,110,400,2,1,233.39,233.9,10,27,1,1,233.31,233.94,110,200,2,1,233.3,233.98,100,44,1,3,233.25,234.0,55,154,2,7,AAPL,300,2.5377643504531724,-0.03275835428683759
2024-10-21T11:58:53.954474192Z,2024-10-21T11:58:53.954307531Z,10,2,38,T,B,0,233.74,40,130,166661,11589595,233.65,233.74,1,435,1,1,233.56,233.75,400,201,2,2,233.53,233.77,10,8,1,1,233.5,233.78,26,150,1,2,233.45,233.8,15,25,1,1,233.4,233.84,110,400,2,1,233.39,233.9,10,27,1,1,233.31,233.94,110,200,2,1,233.3,233.98,100,44,1,3,233.25,234.0,55,154,2,7,AAPL,300,2.575107296137339,-0.033240390156171806
2024-10-21T11:58:53.954474192Z,2024-10-21T11:58:53.954307531Z,10,2,38,C,A,0,233.74,40,130,166661,11589595,233.65,233.74,1,395,1,1,233.56,233.75,400,201,2,2,233.53,233.77,10,8,1,1,233.5,233.78,26,150,1,2,233.45,233.8,15,25,1,1,233.4,233.84,110,400,2,1,233.39,233.9,10,27,1,1,233.31,233.94,110,200,2,1,233.3,233.98,100,44,1,3,233.25,234.0,55,154,2,7,AAPL,300,2.6049204052098407,-0.033625228247704905
2024-10-21T11:58:53.954484330Z,2024-10-21T11:58:53.954317948Z,10,2,38,A,B,0,233.66,100,130,166382,11589596,233.66,233.74,100,395,1,1,233.65,233.75,1,201,1,2,233.56,233.77,400,8,2,1,233.53,233.78,10,150,1,2,233.5,233.8,26,25,1,1,233.45,233.84,15,400,1,1,233.4,233.9,110,27,2,1,233.39,233.94,10,200,1,1,233.31,233.98,110,44,2,3,233.3,234.0,100,154,1,7,AAPL,400,3.4379028792436617,-0.044377658824741616
2024-10-21T11:58:53.954646013Z,2024-10-21T11:58:53.954477659Z,10,2,38,T,B,0,233.74,395,0,168354,11589601,233.66,233.74,100,395,1,1,233.65,233.75,1,201,1,2,233.56,233.77,400,8,2,1,233.53,233.78,10,150,1,2,233.5,233.8,26,25,1,1,233.45,233.84,15,400,1,1,233.4,233.9,110,27,2,1,233.39,233.94,10,200,1,1,233.31,233.98,110,44,2,3,233.3,234.0,100,154,1,7,AAPL,400,3.409531189461449,-0.0440114270800818
2024-10-21T11:58:53.954646013Z,2024-10-21T11:58:53.954477659Z,10,2,38,T,N,0,233.74,40,130,168354,11589602,233.66,233.75,100,201,1,2,233.65,233.77,1,8,1,1,233.56,233.78,400,150,2,2,233.53,233.8,10,25,1,1,233.5,233.84,26,400,1,1,233.45,233.9,15,27,1,1,233.4,233.94,110,200,2,1,233.39,233.98,10,44,1,3,233.31,234.0,110,154,2,7,233.3,234.13,100,400,1,1,AAPL,800,6.2317429406037,-0.0804415284013038
2024-10-21T11:58:53.954667578Z,2024-10-21T11:58:53.954501480Z,10,2,38,A,B,0,233.7,100,130,166098,11589603,233.7,233.75,100,201,1,2,233.66,233.77,100,8,1,1,233.65,233.78,1,150,1,2,233.56,233.8,400,25,2,1,233.53,233.84,10,400,1,1,233.5,233.9,26,27,1,1,233.45,233.94,15,200,1,1,233.4,233.98,110,44,2,3,233.39,234.0,10,154,1,7,233.31,234.13,110,400,2,1,AAPL,910,6.58869395711501,-0.08504917759451444
2024-10-21T11:58:53.954668924Z,2024-10-21T11:58:53.954502815Z,10,2,38,A,B,1,233.68,100,130,166109,11589604,233.7,233.75,100,201,1,2,233.68,233.77,100,8,1,1,233.66,233.78,100,150,1,2,233.65,233.8,1,25,1,1,233.56,233.84,400,400,2,1,233.53,233.9,10,27,1,1,233.5,233.94,26,200,1,1,233.45,233.98,15,44,1,3,233.4,234.0,110,154,2,7,233.39,234.13,10,400,1,1,AAPL,920,6.4383904023994,-0.08310900647694562
2024-10-21T11:58:53.954674047Z,2024-10-21T11:58:53.954507571Z,10,2,38,A,B,1,233.68,100,130,166476,11589605,233.7,233.75,100,201,1,2,233.68,233.77,200,8,2,1,233.66,233.78,100,150,1,2,233.65,233.8,1,25,1,1,233.56,233.84,400,400,2,1,233.53,233.9,10,27,1,1,233.5,233.94,26,200,1,1,233.45,233.98,15,44,1,3,233.4,234.0,110,154,2,7,233.39,234.13,10,400,1,1,AAPL,920,6.257084561323963,-0.08076864694941044
2024-10-21T11:58:53.954681864Z,2024-10-21T11:58:53.954515456Z,10,2,38,A,B,1,233.68,100,130,166408,11589606,233.7,233.75,100,201,1,2,233.68,233.77,300,8,3,1,233.66,233.78,100,150,1,2,233.65,233.8,1,25,1,1,233.56,233.84,400,400,2,1,233.53,233.9,10,27,1,1,233.5,233.94,26,200,1,1,233.45,233.98,15,44,1,3,233.4,234.0,110,154,2,7,233.39,234.13,10,400,1,1,AAPL,920,6.106616884463804,-0.0788263572855091
2024-10-21T11:58:53.954686890Z,2024-10-21T11:58:53.954518683Z,10,2,38,A,B,1,233.68,100,130,168207,11589607,233.7,233.75,100,201,1,2,233.68,233.77,400,8,4,1,233.66,233.78,100,150,1,2,233.65,233.8,1,25,1,1,233.56,233.84,400,400,2,1,233.53,233.9,10,27,1,1,233.5,233.94,26,200,1,1,233.45,233.98,15,44,1,3,233.4,234.0,110,154,2,7,233.39,234.13,10,400,1,1,AAPL,920,5.9797361881093485,-0.07718853665705015
2024-10-21T11:58:53.954688296Z,2024-10-21T11:58:53.954521070Z,10,2,38,A,B,0,233.7,40,130,167226,11589608,233.7,233.75,140,201,2,2,233.68,233.77,400,8,4,1,233.66,233.78,100,150,1,2,233.65,233.8,1,25,1,1,233.56,233.84,400,400,2,1,233.53,233.9,10,27,1,1,233.5,233.94,26,200,1,1,233.45,233.98,15,44,1,3,233.4,234.0,110,154,2,7,233.39,234.13,10,400,1,1,AAPL,920,5.87129941499734,-0.0757887966730401
2024-10-21T11:58:53.954700521Z,2024-10-21T11:58:53.954534910Z,10,2,38,C,A,4,233.84,400,130,165611,11589609,233.7,233.75,140,201,2,2,233.68,233.77,400,8,4,1,233.66,233.78,100,150,1,2,233.65,233.8,1,25,1,1,233.56,233.9,400,27,2,1,233.53,233.94,10,200,1,1,233.5,233.98,26,44,1,3,233.45,234.0,15,154,1,7,233.4,234.13,110,400,2,1,233.39,234.17,10,1,1,1,AAPL,921,6.192144373673036,-0.07993037618004491
2024-10-21T11:58:53.954701970Z,2024-10-21T11:58:53.954535707Z,10,2,38,A,B,2,233.67,40,130,166263,11589610,233.7,233.75,140,201,2,2,233.68,233.77,400,8,4,1,233.67,233.78,40,150,1,2,233.66,233.8,100,25,1,1,233.65,233.9,1,27,1,1,233.56,233.94,400,200,2,1,233.53,233.98,10,44,1,3,233.5,234.0,26,154,1,7,233.45,234.13,15,400,1,1,233.4,234.17,110,1,2,1,AAPL,1031,7.1559951414194005,-0.09237210069392168
2024-10-21T11:58:53.954713634Z,2024-10-21T11:58:53.954546864Z,10,2,38,C,B,1,233.68,100,130,166770,11589611,233.7,233.75,140,201,2,2,233.68,233.77,300,8,3,1,233.67,233.78,40,150,1,2,233.66,233.8,100,25,1,1,233.65,233.9,1,27,1,1,233.56,233.94,400,200,2,1,233.53,233.98,10,44,1,3,233.5,234.0,26,154,1,7,233.45,234.13,15,400,1,1,233.4,234.17,110,1,2,1,AAPL,1031,7.371807967313585,-0.09515788851106984
2024-10-21T11:58:53.954714820Z,2024-10-21T11:58:53.954549208Z,10,2,38,C,B,0,233.7,100,130,165612,11589612,233.7,233.75,40,201,1,2,233.68,233.77,300,8,3,1,233.67,233.78,40,150,1,2,233.66,233.8,100,25,1,1,233.65,233.9,1,27,1,1,233.56,233.94,400,200,2,1,233.53,233.98,10,44,1,3,233.5,234.0,26,154,1,7,233.45,234.13,15,400,1,1,233.4,234.17,110,1,2,1,AAPL,1031,7.579615705931495,-0.0978403438477824
2024-10-21T11:58:53.954724743Z,2024-10-21T11:58:53.954555754Z,10,2,38,T,N,0,233.74,110,130,168989,11589613,233.7,233.75,40,201,1,2,233.68,233.77,300,8,3,1,233.67,233.78,40,150,1,2,233.66,233.8,100,25,1,1,233.65,233.9,1,27,1,1,233.56,233.94,400,200,2,1,233.53,233.98,10,44,1,3,233.5,234.0,26,154,1,7,233.45,234.13,15,400,1,1,233.4,234.17,110,1,2,1,AAPL,1031,7.77985564304462,-0.10042511134250841
2024-10-21T11:58:53.954731951Z,2024-10-21T11:58:53.954564591Z,10,2,38,C,B,1,233.68,100,130,167360,11589614,233.7,233.75,40,201,1,2,233.68,233.77,200,8,2,1,233.67,233.78,40,150,1,2,233.66,233.8,100,25,1,1,233.65,233.9,1,27,1,1,233.56,233.94,400,200,2,1,233.53,233.98,10,44,1,3,233.5,234.0,26,154,1,7,233.45,234.13,15,400,1,1,233.4,234.17,110,1,2,1,AAPL,1031,7.972933784436926,-0.10291743186062265
2024-10-21T11:58:53.954737728Z,2024-10-21T11:58:53.954570870Z,10,2,38,C,B,1,233.68,100,130,166858,11589615,233.7,233.75,40,201,1,2,233.68,233.77,100,8,1,1,233.67,233.78,40,150,1,2,233.66,233.8,100,25,1,1,233.65,233.9,1,27,1,1,233.56,233.94,400,200,2,1,233.53,233.98,10,44,1,3,233.5,234.0,26,154,1,7,233.45,234.13,15,400,1,1,233.4,234.17,110,1,2,1,AAPL,1031,8.159227603672049,-0.10532217796357049
2024-10-21T11:58:53.954832820Z,2024-10-21T11:58:53.954666995Z,10,2,38,C,B,3,233.66,100,130,165825,11589616,233.7,233.75,40,201,1,2,233.68,233.77,100,8,1,1,233.67,233.78,40,150,1,2,233.65,233.8,1,25,1,1,233.56,233.9,400,27,2,1,233.53,233.94,10,200,1,1,233.5,233.98,26,44,1,3,233.45,234.0,15,154,1,7,233.4,234.13,110,400,2,1,233.39,234.17,10,1,1,1,AAPL,1021,8.388686996365934,-0.10828412046188268
2024-10-21T11:58:53.955116146Z,2024-10-21T11:58:53.954950395Z,10,2,38,C,B,1,233.68,100,130,165751,11589618,233.7,233.75,40,201,1,2,233.67,233.77,40,8,1,1,233.65,233.78,1,150,1,2,233.56,233.8,400,25,2,1,233.53,233.9,10,27,1,1,233.5,233.94,26,200,1,1,233.45,233.98,15,44,1,3,233.4,234.0,110,154,2,7,233.39,234.13,10,400,1,1,233.31,234.17,110,1,2,1,AAPL,911,7.638819875776398,-0.09860457208303643
2024-10-21T11:58:54.013732422Z,2024-10-21T11:58:54.013566047Z,10,2,38,A,A,4,233.84,200,130,166375,11590027,233.7,233.75,40,201,1,2,233.67,233.77,40,8,1,1,233.65,233.78,1,150,1,2,233.56,233.8,400,25,2,1,233.53,233.84,10,200,1,1,233.5,233.9,26,27,1,1,233.45,233.94,15,200,1,1,233.4,233.98,110,44,2,3,233.39,234.0,10,154,1,7,233.31,234.13,110,400,2,1,AAPL,511,4.117410071942446,-0.053148976522110286
2024-10-21T11:58:54.013755259Z,2024-10-21T11:58:54.013589130Z,10,2,38,C,A,4,233.84,200,130,166129,11590028,233.7,233.75,40,201,1,2,233.67,233.77,40,8,1,1,233.65,233.78,1,150,1,2,233.56,233.8,400,25,2,1,233.53,233.9,10,27,1,1,233.5,233.94,26,200,1,1,233.45,233.98,15,44,1,3,233.4,234.0,110,154,2,7,233.39,234.13,10,400,1,1,233.31,234.17,110,1,2,1,AAPL,512,4.2056365953830905,-0.054287835499244444
2024-10-21T11:58:54.021610376Z,2024-10-21T11:58:54.021444014Z,10,2,38,A,A,4,233.84,200,130,166362,11590029,233.7,233.75,40,201,1,2,233.67,233.77,40,8,1,1,233.65,233.78,1,150,1,2,233.56,233.8,400,25,2,1,233.53,233.84,10,200,1,1,233.5,233.9,26,27,1,1,233.45,233.94,15,200,1,1,233.4,233.98,110,44,2,3,233.39,234.0,10,154,1,7,233.31,234.13,110,400,2,1,AAPL,112,0.8875974111742174,-0.011457419383376827
2024-10-21T11:58:54.043514811Z,2024-10-21T11:58:54.043347922Z,10,2,38,A,A,4,233.84,200,130,166889,11590054,233.7,233.75,40,201,1,2,233.67,233.77,40,8,1,1,233.65,233.78,1,150,1,2,233.56,233.8,400,25,2,1,233.53,233.84,10,400,1,2,233.5,233.9,26,27,1,1,233.45,233.94,15,200,1,1,233.4,233.98,110,44,2,3,233.39,234.0,10,154,1,7,233.31,234.13,110,400,2,1,AAPL,112,0.8592995916346986,-0.01109214118177587
2024-10-21T11:58:54.063932439Z,2024-10-21T11:58:54.063766628Z,10,2,38,C,B,1,233.67,40,130,165811,11590066,233.7,233.75,40,201,1,2,233.65,233.77,1,8,1,1,233.56,233.78,400,150,2,2,233.53,233.8,10,25,1,1,233.5,233.84,26,400,1,2,233.45,233.9,15,27,1,1,233.4,233.94,110,200,2,1,233.39,233.98,10,44,1,3,233.31,234.0,110,154,2,7,233.3,234.13,100,400,1,1,AAPL,12,0.0895000582682671,-0.001155298212350155
2024-10-21T11:58:54.213932055Z,2024-10-21T11:58:54.213766156Z,10,2,38,C,B,0,233.7,40,130,165899,11590218,233.65,233.75,1,201,1,2,233.56,233.77,400,8,2,1,233.53,233.78,10,150,1,2,233.5,233.8,26,25,1,1,233.45,233.84,15,400,1,2,233.4,233.9,110,27,2,1,233.39,233.94,10,200,1,1,233.31,233.98,110,44,2,3,233.3,234.0,100,154,1,7,233.25,234.13,55,400,2,1,AAPL,-43,-0.3140770252324037,0.004054216643118126
2024-10-21T11:58:58.704824203Z,2024-10-21T11:58:58.704657287Z,10,2,38,A,B,2,233.54,26,130,166916,11592894,233.65,233.75,1,201,1,2,233.56,233.77,400,8,2,1,233.54,233.78,26,150,1,2,233.53,233.8,10,25,1,1,233.5,233.84,26,400,1,2,233.45,233.9,15,27,1,1,233.4,233.94,110,200,2,1,233.39,233.98,10,44,1,3,233.31,234.0,110,154,2,7,233.3,234.13,100,400,1,1,AAPL,-189,-1.3526491977375044,0.017460471314989984
2024-10-21T11:58:58.704911600Z,2024-10-21T11:58:58.704745556Z,10,2,38,C,B,4,233.5,26,130,166044,11592895,233.65,233.75,1,201,1,2,233.56,233.77,400,8,2,1,233.54,233.78,26,150,1,2,233.53,233.8,10,25,1,1,233.45,233.84,15,400,1,2,233.4,233.9,110,27,2,1,233.39,233.94,10,200,1,1,233.31,233.98,110,44,2,3,233.3,234.0,100,154,1,7,233.25,234.13,55,400,2,1,AAPL,-244,-1.7126562842728668,0.022107569334312252
2024-10-21T11:58:58.758575390Z,2024-10-21T11:58:58.758409305Z,10,2,38,C,B,1,233.56,200,130,166085,11592914,233.65,233.75,1,201,1,2,233.56,233.77,200,8,1,1,233.54,233.78,26,150,1,2,233.53,233.8,10,25,1,1,233.45,233.84,15,400,1,2,233.4,233.9,110,27,2,1,233.39,233.94,10,200,1,1,233.31,233.98,110,44,2,3,233.3,234.0,100,154,1,7,233.25,234.13,55,400,2,1,AAPL,-244,-1.6822312754622377,0.02171483262587013
2024-10-21T11:58:58.758589359Z,2024-10-21T11:58:58.758422757Z,10,2,38,A,B,1,233.61,200,130,166602,11592915,233.65,233.75,1,201,1,2,233.61,233.77,200,8,1,1,233.54,233.78,26,150,1,2,233.53,233.8,10,25,1,1,233.45,233.84,15,400,1,2,233.4,233.9,110,27,2,1,233.39,233.94,10,200,1,1,233.31,233.98,110,44,2,3,233.3,234.0,100,154,1,7,233.25,234.13,55,400,2,1,AAPL,-244,-1.6545672118069406,0.02135773516799465
2024-10-21T11:58:58.912542023Z,2024-10-21T11:58:58.912375357Z,10,2,38,A,B,0,233.66,100,130,166666,11592972,233.66,233.75,100,201,1,2,233.65,233.77,1,8,1,1,233.61,233.78,200,150,1,2,233.54,233.8,26,25,1,1,233.53,233.84,10,400,1,2,233.45,233.9,15,27,1,1,233.4,233.94,110,200,2,1,233.39,233.98,10,44,1,3,233.31,234.0,110,154,2,7,233.3,234.13,100,400,1,1,AAPL,-144,-0.9574468085106382,0.012359059957002176
2024-10-21T11:58:58.912719366Z,2024-10-21T11:58:58.912551174Z,10,2,38,T,B,0,233.75,1,0,168192,11592975,233.66,233.75,100,201,1,2,233.65,233.77,1,8,1,1,233.61,233.78,200,150,1,2,233.54,233.8,26,25,1,1,233.53,233.84,10,400,1,2,233.45,233.9,15,27,1,1,233.4,233.94,110,200,2,1,233.39,233.98,10,44,1,3,233.31,234.0,110,154,2,7,233.3,234.13,100,400,1,1,AAPL,-144,-0.940152339499456,0.01213581687181585
2024-10-21T11:58:58.912719366Z,2024-10-21T11:58:58.912551174Z,10,2,38,T,B,0,233.75,200,130,168192,11592976,233.66,233.75,100,200,1,1,233.65,233.77,1,8,1,1,233.61,233.78,200,150,1,2,233.54,233.8,26,25,1,1,233.53,233.84,10,400,1,2,233.45,233.9,15,27,1,1,233.4,233.94,110,200,2,1,233.39,233.98,10,44,1,3,233.31,234.0,110,154,2,7,233.3,234.13,100,400,1,1,AAPL,-144,-0.9243580846634282,0.011931939078543669
2024-10-21T11:58:58.912719366Z,2024-10-21T11:58:58.912551174Z,10,2,38,C,A,0,233.75,200,130,168192,11592976,233.66,233.77,100,8,1,1,233.65,233.78,1,150,1,2,233.61,233.8,200,25,1,1,233.54,233.84,26,400,1,2,233.53,233.9,10,27,1,1,233.45,233.94,15,200,1,1,233.4,233.98,110,44,2,3,233.39,234.0,10,154,1,7,233.31,234.13,110,400,2,1,233.3,234.17,100,1,1,1,AAPL,-143,-0.9345601513457734,0.01206363094141444
2024-10-21T11:58:58.912744804Z,2024-10-21T11:58:58.912577219Z,10,2,38,A,B,0,233.68,100,130,167585,11592979,233.71,233.77,100,8,1,1,233.68,233.78,200,150,2,2,233.66,233.8,100,25,1,1,233.65,233.84,1,400,1,2,233.61,233.9,200,27,1,1,233.54,233.94,26,200,1,1,233.53,233.98,10,44,1,3,233.45,234.0,15,154,1,7,233.4,234.13,110,400,2,1,233.39,234.17,10,1,1,1,AAPL,-133,-0.8912371134020619,0.011504401939127926
2024-10-21T11:58:58.912755099Z,2024-10-21T11:58:58.912588388Z,10,2,38,A,B,1,233.68,100,130,166711,11592981,233.71,233.77,100,8,1,1,233.68,233.78,400,150,4,2,233.66,233.8,100,25,1,1,233.65,233.84,1,400,1,2,233.61,233.9,200,27,1,1,233.54,233.94,26,200,1,1,233.53,233.98,10,44,1,3,233.45,234.0,15,154,1,7,233.4,234.13,110,400,2,1,233.39,234.17,10,1,1,1,AAPL,-133,-0.9132263325036478,0.011788246508735825
2024-10-21T11:58:58.912761550Z,2024-10-21T11:58:58.912594900Z,10,2,38,A,B,1,233.7,38,130,166650,11592982,233.71,233.77,100,8,1,1,233.7,233.78,38,150,1,2,233.68,233.8,400,25,4,1,233.66,233.84,100,400,1,2,233.65,233.9,1,27,1,1,233.61,233.94,200,200,1,1,233.54,233.98,26,44,1,3,233.53,234.0,10,154,1,7,233.45,234.13,15,400,1,1,233.4,234.17,110,1,2,1,AAPL,-23,-0.16034687978234993,0.002069813887865984
2024-10-21T11:58:58.912776419Z,2024-10-21T11:58:58.912609151Z,10,2,38,A,B,3,233.67,38,130,167268,11592984,233.71,233.77,100,8,1,1,233.7,233.78,38,150,1,2,233.68,233.8,400,25,4,1,233.67,233.84,38,400,1,2,233.66,233.9,100,27,1,1,233.65,233.94,1,200,1,1,233.61,233.98,200,44,1,3,233.54,234.0,26,154,1,7,233.53,234.13,10,400,1,1,233.45,234.17,15,1,1,1,AAPL,-8,-0.05705552725420275,0.0007364928014225331
2024-10-21T11:58:58.912779652Z,2024-10-21T11:58:58.912613899Z,10,2,38,C,B,2,233.68,100,130,165753,11592985,233.71,233.77,100,8,1,1,233.7,233.78,38,150,1,2,233.68,233.8,300,25,3,1,233.67,233.84,38,400,1,2,233.66,233.9,100,27,1,1,233.65,233.94,1,200,1,1,233.61,233.98,200,44,1,3,233.54,234.0,26,154,1,7,233.53,234.13,10,400,1,1,233.45,234.17,15,1,1,1,AAPL,-8,-0.05833474648126166,0.0007530054128645872
2024-10-21T11:58:58.912783553Z,2024-10-21T11:58:58.912617614Z,10,2,38,C,A,3,233.84,200,130,165939,11592986,233.71,233.77,100,8,1,1,233.7,233.78,38,150,1,2,233.68,233.8,300,25,3,1,233.67,233.84,38,200,1,1,233.66,233.9,100,27,1,1,233.65,233.94,1,200,1,1,233.61,233.98,200,44,1,3,233.54,234.0,26,154,1,7,233.53,234.13,10,400,1,1,233.45,234.17,15,1,1,1,AAPL,-8,-0.05961049957662997,0.000769473282260397
2024-10-21T11:58:58.912786801Z,2024-10-21T11:58:58.912620981Z,10,2,38,C,B,0,233.71,100,130,165820,11592987,233.7,233.77,38,8,1,1,233.68,233.78,300,150,3,2,233.67,233.8,38,25,1,1,233.66,233.84,100,200,1,1,233.65,233.9,1,27,1,1,233.61,233.94,200,200,1,1,233.54,233.98,26,44,1,3,233.53,234.0,10,154,1,7,233.45,234.13,15,400,1,1,233.4,234.17,110,1,2,1,AAPL,-118,-0.8908648603305093,0.011499596765629406
2024-10-21T11:58:58.912794208Z,2024-10-21T11:58:58.912628049Z,10,2,38,C,A,3,233.84,200,130,166159,11592988,233.7,233.77,38,8,1,1,233.68,233.78,300,150,3,2,233.67,233.8,38,25,1,1,233.66,233.9,100,27,1,1,233.65,233.94,1,200,1,1,233.61,233.98,200,44,1,3,233.54,234.0,26,154,1,7,233.53,234.13,10,400,1,1,233.45,234.17,15,1,1,1,233.4,234.41,110,600,2,2,AAPL,482,3.510727575013855,-0.04531770559639919
2024-10-21T11:58:58.912804792Z,2024-10-21T11:58:58.912639087Z,10,2,38,C,B,1,233.68,100,130,165705,11592990,233.7,233.77,38,8,1,1,233.68,233.78,200,150,2,2,233.67,233.8,38,25,1,1,233.66,233.9,100,27,1,1,233.65,233.94,1,200,1,1,233.61,233.98,200,44,1,3,233.54,234.0,26,154,1,7,233.53,234.13,10,400,1,1,233.45,234.17,15,1,1,1,233.4,234.41,110,600,2,2,AAPL,482,3.3961472153511734,-0.04383866203765696
2024-10-21T11:58:58.912808391Z,2024-10-21T11:58:58.912642543Z,10,2,38,C,B,1,233.68,100,130,165848,11592991,233.7,233.77,38,8,1,1,233.68,233.78,100,150,1,2,233.67,233.8,38,25,1,1,233.66,233.9,100,27,1,1,233.65,233.94,1,200,1,1,233.61,233.98,200,44,1,3,233.54,234.0,26,154,1,7,233.53,234.13,10,400,1,1,233.45,234.17,15,1,1,1,233.4,234.41,110,600,2,2,AAPL,482,3.2931463952743574,-0.04250909124622054
2024-10-21T11:58:58.912849846Z,2024-10-21T11:58:58.912684059Z,10,2,38,C,B,3,233.66,100,130,165787,11592992,233.7,233.77,38,8,1,1,233.68,233.78,100,150,1,2,233.67,233.8,38,25,1,1,233.65,233.9,1,27,1,1,233.61,233.94,200,200,1,1,233.54,233.98,26,44,1,3,233.53,234.0,10,154,1,7,233.45,234.13,15,400,1,1,233.4,234.17,110,1,2,1,233.39,234.41,10,600,1,2,AAPL,472,3.1550371734533798,-0.04072632886409348
2024-10-21T11:58:58.913120559Z,2024-10-21T11:58:58.912954809Z,10,2,38,C,B,1,235.0,1000,130,165750,11592994,233.7,233.77,38,8,1,1,233.67,233.78,38,150,1,2,233.65,233.8,1,25,1,1,233.61,233.9,200,27,1,1,233.54,233.94,26,200,1,1,233.53,233.98,10,44,1,3,233.45,234.0,15,154,1,7,233.4,234.13,110,400,2,1,233.39,234.17,10,1,1,1,233.31,234.41,110,600,2,2,AAPL,362,2.355084249560861,-0.03040025533051923
2024-10-21T11:58:58.926633058Z,2024-10-21T11:58:58.926466671Z,10,2,38,A,A,3,233.85,200,130,166387,11593007,233.7,233.77,38,8,1,1,233.67,233.78,38,150,1,2,233.65,233.8,1,25,1,1,233.61,233.85,200,200,1,1,233.54,233.9,26,27,1,1,233.53,233.94,10,200,1,1,233.45,233.98,15,44,1,3,233.4,234.0,110,154,2,7,233.39,234.13,10,400,1,1,233.31,234.17,110,1,2,1,AAPL,361,2.3783748869655086,-0.03070089906504544
2024-10-21T11:58:58.945632815Z,2024-10-21T11:58:58.945466491Z,10,2,38,A,A,3,233.85,200,130,166324,11593017,233.7,233.77,38,8,1,1,233.67,233.78,38,150,1,2,233.65,233.8,1,25,1,1,233.61,233.85,200,400,1,2,233.54,233.9,26,27,1,1,233.53,233.94,10,200,1,1,233.45,233.98,15,44,1,3,233.4,234.0,110,154,2,7,233.39,234.13,10,400,1,1,233.31,234.17,110,1,2,1,AAPL,361,2.4077470659911495,-0.031080045476542056
2024-10-21T11:58:58.980361981Z,2024-10-21T11:58:58.980196081Z,10,2,38,C,A,3,233.85,200,130,165900,11593035,233.7,233.77,38,8,1,1,233.67,233.78,38,150,1,2,233.65,233.8,1,25,1,1,233.61,233.85,200,200,1,1,233.54,233.9,26,27,1,1,233.53,233.94,10,200,1,1,233.45,233.98,15,44,1,3,233.4,234.0,110,154,2,7,233.39,234.13,10,400,1,1,233.31,234.17,110,1,2,1,AAPL,361,2.4367040244523688,-0.03145383207503867
2024-10-21T11:58:58.980371284Z,2024-10-21T11:58:58.980205607Z,10,2,38,C,A,3,233.85,200,130,165677,11593036,233.7,233.77,38,8,1,1,233.67,233.78,38,150,1,2,233.65,233.8,1,25,1,1,233.61,233.9,200,27,1,1,233.54,233.94,26,200,1,1,233.53,233.98,10,44,1,3,233.45,234.0,15,154,1,7,233.4,234.13,110,400,2,1,233.39,234.17,10,1,1,1,233.31,234.41,110,600,2,2,AAPL,961,6.323138783964907,-0.08162129807402227
2024-10-21T11:58:58.983554818Z,2024-10-21T11:58:58.983388525Z,10,2,38,C,B,3,233.61,200,130,166293,11593038,233.7,233.77,38,8,1,1,233.67,233.78,38,150,1,2,233.65,233.8,1,25,1,1,233.54,233.9,26,27,1,1,233.53,233.94,10,200,1,1,233.45,233.98,15,44,1,3,233.4,234.0,110,154,2,7,233.39,234.13,10,400,1,1,233.31,234.17,110,1,2,1,233.3,234.41,100,600,1,2,AAPL,861,5.534065677223325,-0.07143566504460387
2024-10-21T11:58:58.983567276Z,2024-10-21T11:58:58.983400771Z,10,2,38,A,B,3,233.56,400,130,166505,11593039,233.7,233.77,38,8,1,1,233.67,233.78,38,150,1,2,233.65,233.8,1,25,1,1,233.56,233.9,400,27,1,1,233.54,233.94,26,200,1,1,233.53,233.98,10,44,1,3,233.45,234.0,15,154,1,7,233.4,234.13,110,400,2,1,233.39,234.17,10,1,1,1,233.31,234.41,110,600,2,2,AAPL,971,6.1014362657091565,-0.07875948403758146
2024-10-21T11:58:59.013929420Z,2024-10-21T11:58:59.013763041Z,10,2,38,C,B,1,233.67,38,130,166379,11593062,233.7,233.77,38,8,1,1,233.65,233.78,1,150,1,2,233.56,233.8,400,25,1,1,233.54,233.9,26,27,1,1,233.53,233.94,10,200,1,1,233.45,233.98,15,44,1,3,233.4,234.0,110,154,2,7,233.39,234.13,10,400,1,1,233.31,234.17,110,1,2,1,233.3,234.41,100,600,1,2,AAPL,871,5.360289354351112,-0.0691924991847417
2024-10-21T11:58:59.013989405Z,2024-10-21T11:58:59.013823110Z,10,2,38,A,A,3,233.85,200,130,166295,11593063,233.7,233.77,38,8,1,1,233.65,233.78,1,150,1,2,233.56,233.8,400,25,1,1,233.54,233.85,26,200,1,1,233.53,233.9,10,27,1,1,233.45,233.94,15,200,1,1,233.4,233.98,110,44,2,3,233.39,234.0,10,154,1,7,233.31,234.13,110,400,2,1,233.3,234.17,100,1,1,1,AAPL,870,5.418523489932886,-0.06994420587674989
2024-10-21T11:58:59.163929286Z,2024-10-21T11:58:59.163763153Z,10,2,38,C,B,0,233.7,38,130,166133,11593111,233.65,233.77,1,8,1,1,233.56,233.78,400,150,1,2,233.54,233.8,26,25,1,1,233.53,233.85,10,200,1,1,233.45,233.9,15,27,1,1,233.4,233.94,110,200,2,1,233.39,233.98,10,44,1,3,233.31,234.0,110,154,2,7,233.3,234.13,100,400,1,1,233.25,234.17,55,1,2,1,AAPL,815,5.148011348428884,-0.06645234006631844
2024-10-21T11:59:00.168394703Z,2024-10-21T11:59:00.168228588Z,10,2,38,C,B,2,233.54,26,130,166115,11594290,233.65,233.77,1,8,1,1,233.56,233.78,400,150,1,2,233.53,233.8,10,25,1,1,233.45,233.85,15,200,1,1,233.4,233.9,110,27,2,1,233.39,233.94,10,200,1,1,233.31,233.98,110,44,2,3,233.3,234.0,100,154,1,7,233.25,234.13,55,400,2,1,233.24,234.17,1,1,1,1,AAPL,814,5.228282395760853,-0.06748850696140724
2024-10-21T11:59:00.168436220Z,2024-10-21T11:59:00.168269867Z,10,2,38,A,B,2,233.55,30,130,166353,11594291,233.65,233.77,1,8,1,1,233.56,233.78,400,150,1,2,233.55,233.8,30,25,1,1,233.53,233.85,10,200,1,1,233.45,233.9,15,27,1,1,233.4,233.94,110,200,2,1,233.39,233.98,10,44,1,3,233.31,234.0,110,154,2,7,233.3,234.13,100,400,1,1,233.25,234.17,55,1,2,1,AAPL,869,5.6576124659800415,-0.07303045042188717
2024-10-21T11:59:00.853997755Z,2024-10-21T11:59:00.853830846Z,10,2,38,A,A,3,233.84,200,130,166909,11595138,233.65,233.77,1,8,1,1,233.56,233.78,400,150,1,2,233.55,233.8,30,25,1,1,233.53,233.84,10,200,1,1,233.45,233.9,15,27,1,1,233.4,233.94,110,200,2,1,233.39,233.98,10,44,1,3,233.31,234.0,110,154,2,7,233.3,234.13,100,400,1,1,233.25,234.17,55,1,2,1,AAPL,815,5.306277467310509,-0.06849529476106825
2024-10-21T11:59:01.071691307Z,2024-10-21T11:59:01.071525039Z,10,2,38,C,B,1,233.56,400,130,166268,11595523,233.65,233.77,1,8,1,1,233.55,233.78,30,150,1,2,233.53,233.8,10,25,1,1,233.45,233.84,15,200,1,1,233.4,233.9,110,27,2,1,233.39,233.94,10,200,1,1,233.31,233.98,110,44,2,3,233.3,234.0,100,154,1,7,233.25,234.13,55,400,2,1,233.24,234.17,1,1,1,1,AAPL,814,5.3875115282373995,-0.06954389257414983
2024-10-21T11:59:01.071703415Z,2024-10-21T11:59:01.071537379Z,10,2,38,A,B,2,233.54,400,130,166036,11595524,233.65,233.77,1,8,1,1,233.55,233.78,30,150,1,2,233.54,233.8,400,25,1,1,233.53,233.84,10,200,1,1,233.45,233.9,15,27,1,1,233.4,233.94,110,200,2,1,233.39,233.98,10,44,1,3,233.31,234.0,110,154,2,7,233.3,234.13,100,400,1,1,233.25,234.17,55,1,2,1,AAPL,869,5.828114013737898,-0.07523134433345491
2024-10-21T11:59:01.127500003Z,2024-10-21T11:59:01.127333717Z,10,2,38,A,A,3,233.83,200,130,166286,11595689,233.65,233.77,1,8,1,1,233.55,233.78,30,150,1,2,233.54,233.8,400,25,1,1,233.53,233.83,10,200,1,1,233.45,233.9,15,27,1,1,233.4,233.94,110,200,2,1,233.39,233.98,10,44,1,3,233.31,234.0,110,154,2,7,233.3,234.13,100,400,1,1,233.25,234.17,55,1,2,1,AAPL,869,5.904232946885954,-0.07621391427914542
2024-10-21T11:59:01.142037998Z,2024-10-21T11:59:01.141872098Z,10,2,38,C,A,3,233.83,200,130,165900,11595742,233.65,233.77,1,8,1,1,233.55,233.78,30,150,1,2,233.54,233.8,400,25,1,1,233.53,233.9,10,27,1,1,233.45,233.94,15,200,1,1,233.4,233.98,110,44,2,3,233.39,234.0,10,154,1,7,233.31,234.13,110,400,2,1,233.3,234.17,100,1,1,1,233.25,234.41,55,600,2,2,AAPL,1469,9.793333333333333,-0.12641578912760018
2024-10-21T11:59:01.142051431Z,2024-10-21T11:59:01.141884696Z,10,2,38,A,A,3,233.89,400,130,166735,11595743,233.65,233.77,1,8,1,1,233.55,233.78,30,150,1,2,233.54,233.8,400,25,1,1,233.53,233.89,10,400,1,1,233.45,233.9,15,27,1,1,233.4,233.94,110,200,2,1,233.39,233.98,10,44,1,3,233.31,234.0,110,154,2,7,233.3,234.13,100,400,1,1,233.25,234.17,55,1,2,1,AAPL,1468,9.91067719152472,-0.1279305048967501
2024-10-21T11:59:01.197168571Z,2024-10-21T11:59:01.197001468Z,10,2,38,A,B,1,233.55,400,130,167103,11595894,233.65,233.77,1,8,1,1,233.55,233.78,430,150,2,2,233.53,233.8,10,25,1,1,233.45,233.89,15,400,1,1,233.4,233.9,110,27,2,1,233.39,233.94,10,200,1,1,233.31,233.98,110,44,2,3,233.3,234.0,100,154,1,7,233.25,234.13,55,400,2,1,233.24,234.17,1,1,1,1,AAPL,1467,10.055249766330874,-0.1297966985111472
2024-10-21T11:59:01.197180089Z,2024-10-21T11:59:01.197013688Z,10,2,38,A,A,3,233.84,200,130,166401,11595895,233.65,233.77,1,8,1,1,233.55,233.78,430,150,2,2,233.53,233.8,10,25,1,1,233.45,233.84,15,200,1,1,233.4,233.9,110,27,2,1,233.39,233.94,10,200,1,1,233.31,233.98,110,44,2,3,233.3,234.0,100,154,1,7,233.25,234.13,55,400,2,1,233.24,234.17,1,1,1,1,AAPL,1467,10.206542056074767,-0.13174963256801198
2024-10-21T11:59:01.308774903Z,2024-10-21T11:59:01.308608556Z,10,2,38,A,A,3,233.83,200,130,166347,11596082,233.65,233.77,1,8,1,1,233.55,233.78,430,150,2,2,233.53,233.8,10,25,1,1,233.45,233.83,15,200,1,1,233.4,233.9,110,27,2,1,233.39,233.94,10,200,1,1,233.31,233.98,110,44,2,3,233.3,234.0,100,154,1,7,233.25,234.13,55,400,2,1,233.24,234.17,1,1,1,1,AAPL,1467,10.357802928044856,-0.13370216107320881
2024-10-21T11:59:01.341868800Z,2024-10-21T11:59:01.341702894Z,10,2,38,C,B,1,233.55,30,130,165906,11596156,233.65,233.77,1,8,1,1,233.55,233.78,400,150,1,2,233.53,233.8,10,25,1,1,233.45,233.83,15,200,1,1,233.4,233.9,110,27,2,1,233.39,233.94,10,200,1,1,233.31,233.98,110,44,2,3,233.3,234.0,100,154,1,7,233.25,234.13,55,400,2,1,233.24,234.17,1,1,1,1,AAPL,1467,10.509032392026578,-0.13565428415305159
2024-10-21T11:59:01.341924075Z,2024-10-21T11:59:01.341757997Z,10,2,38,A,B,2,233.53,27,130,166078,11596157,233.65,233.77,1,8,1,1,233.55,233.78,400,150,1,2,233.53,233.8,37,25,2,1,233.45,233.83,15,200,1,1,233.4,233.9,110,27,2,1,233.39,233.94,10,200,1,1,233.31,233.98,110,44,2,3,233.3,234.0,100,154,1,7,233.25,234.13,55,400,2,1,233.24,234.17,1,1,1,1,AAPL,1467,10.660230457801307,-0.13760600193380165
2024-10-21T11:59:01.498895489Z,2024-10-21T11:59:01.498729008Z,10,2,38,A,B,1,233.59,200,130,166481,11596259,233.65,233.77,1,8,1,1,233.59,233.78,200,150,1,2,233.53,233.8,37,25,2,1,233.45,233.83,15,200,1,1,233.4,233.9,110,27,2,1,233.39,233.94,10,200,1,1,233.31,233.98,110,44,2,3,233.3,234.0,100,154,1,7,233.25,234.13,55,400,2,1,233.24,234.17,1,1,1,1,AAPL,1467,10.811397135146356,-0.13955731454166806
2024-10-21T11:59:01.983861981Z,2024-10-21T11:59:01.983695936Z,10,2,38,A,B,1,233.59,200,130,166045,11596500,233.65,233.77,1,8,1,1,233.59,233.78,400,150,2,2,233.53,233.8,37,25,2,1,233.45,233.83,15,200,1,1,233.4,233.9,110,27,2,1,233.39,233.94,10,200,1,1,233.31,233.98,110,44,2,3,233.3,234.0,100,154,1,7,233.25,234.13,55,400,2,1,233.24,234.17,1,1,1,1,AAPL,1467,10.962532433834976,-0.14150822210280736
2024-10-21T11:59:02.037559250Z,2024-10-21T11:59:02.037392833Z,10,2,38,C,B,1,233.59,200,130,166417,11596603,233.65,233.77,1,8,1,1,233.59,233.78,200,150,1,2,233.53,233.8,37,25,2,1,233.45,233.83,15,200,1,1,233.4,233.9,110,27,2,1,233.39,233.94,10,200,1,1,233.31,233.98,110,44,2,3,233.3,234.0,100,154,1,7,233.25,234.13,55,400,2,1,233.24,234.17,1,1,1,1,AAPL,1467,11.113636363636363,-0.14345872474332375
2024-10-21T11:59:02.037571727Z,2024-10-21T11:59:02.037405330Z,10,2,38,A,B,1,233.6,200,130,166397,11596604,233.65,233.77,1,8,1,1,233.6,233.78,200,150,1,2,233.53,233.8,37,25,2,1,233.45,233.83,15,200,1,1,233.4,233.9,110,27,2,1,233.39,233.94,10,200,1,1,233.31,233.98,110,44,2,3,233.3,234.0,100,154,1,7,233.25,234.13,55,400,2,1,233.24,234.17,1,1,1,1,AAPL,1467,11.264708934315658,-0.1454088225892691
2024-10-21T11:59:02.587441184Z,2024-10-21T11:59:02.587275146Z,10,2,38,A,B,1,233.61,200,130,166038,11596977,233.65,233.77,1,8,1,1,233.61,233.78,200,150,1,2,233.53,233.8,37,25,2,1,233.45,233.83,15,200,1,1,233.4,233.9,110,27,2,1,233.39,233.94,10,200,1,1,233.31,233.98,110,44,2,3,233.3,234.0,100,154,1,7,233.25,234.13,55,400,2,1,233.24,234.17,1,1,1,1,AAPL,1467,11.41575015563395,-0.147358515766643
2024-10-21T11:59:05.075802504Z,2024-10-21T11:59:05.075636621Z,10,2,38,C,A,3,233.83,200,130,165883,11598871,233.65,233.77,1,8,1,1,233.61,233.78,200,150,1,2,233.53,233.8,37,25,2,1,233.45,233.9,15,27,1,1,233.4,233.94,110,200,2,1,233.39,233.98,10,44,1,3,233.31,234.0,110,154,2,7,233.3,234.13,100,400,1,1,233.25,234.17,55,1,2,1,233.24,234.41,1,600,1,2,AAPL,2067,15.806409417920209,-0.20403468888771084
2024-10-21T11:59:05.075814633Z,2024-10-21T11:59:05.075648273Z,10,2,38,A,A,3,233.85,200,130,166360,11598872,233.65,233.77,1,8,1,1,233.61,233.78,200,150,1,2,233.53,233.8,37,25,2,1,233.45,233.85,15,200,1,1,233.4,233.9,110,27,2,1,233.39,233.94,10,200,1,1,233.31,233.98,110,44,2,3,233.3,234.0,100,154,1,7,233.25,234.13,55,400,2,1,233.24,234.17,1,1,1,1,AAPL,2066,16.005030434126464,-0.20659855878230304
2024-10-21T11:59:05.130136063Z,2024-10-21T11:59:05.129969945Z,10,2,38,A,B,1,233.62,200,130,166118,11598935,233.65,233.77,1,8,1,1,233.62,233.78,200,150,1,2,233.53,233.8,37,25,2,1,233.45,233.85,15,200,1,1,233.4,233.9,110,27,2,1,233.39,233.94,10,200,1,1,233.31,233.98,110,44,2,3,233.3,234.0,100,154,1,7,233.25,234.13,55,400,2,1,233.24,234.17,1,1,1,1,AAPL,2066,16.2112569790252,-0.2092606035146821
2024-10-21T11:59:05.149700903Z,2024-10-21T11:59:05.149534519Z,10,2,38,C,B,2,233.53,27,130,166384,11599037,233.65,233.77,1,8,1,1,233.62,233.78,200,150,1,2,233.53,233.8,10,25,1,1,233.45,233.85,15,200,1,1,233.4,233.9,110,27,2,1,233.39,233.94,10,200,1,1,233.31,233.98,110,44,2,3,233.3,234.0,100,154,1,7,233.25,234.13,55,400,2,1,233.24,234.17,1,1,1,1,AAPL,2066,16.417442035910074,-0.21192211270519473
2024-10-21T11:59:05.149791992Z,2024-10-21T11:59:05.149624943Z,10,2,38,A,B,2,233.54,27,130,167049,11599038,233.65,233.77,1,8,1,1,233.62,233.78,200,150,1,2,233.54,233.8,27,25,1,1,233.53,233.85,10,200,1,1,233.45,233.9,15,27,1,1,233.4,233.94,110,200,2,1,233.39,233.98,10,44,1,3,233.31,234.0,110,154,2,7,233.3,234.13,100,400,1,1,233.25,234.17,55,1,2,1,AAPL,2121,17.019910727719544,-0.21969899035323087
2024-10-21T11:59:22.128357765Z,2024-10-21T11:59:22.128191719Z,10,2,38,C,B,1,233.62,200,130,166046,11607753,233.65,233.77,1,8,1,1,233.54,233.78,27,150,1,2,233.53,233.8,10,25,1,1,233.45,233.85,15,200,1,1,233.4,233.9,110,27,2,1,233.39,233.94,10,200,1,1,233.31,233.98,110,44,2,3,233.3,234.0,100,154,1,7,233.25,234.13,55,400,2,1,233.24,234.17,1,1,1,1,AAPL,653,13.70614692653673,-0.1769237623843063
2024-10-21T11:59:22.128370118Z,2024-10-21T11:59:22.128203635Z,10,2,38,A,B,1,233.6,200,130,166483,11607754,233.65,233.77,1,8,1,1,233.6,233.78,200,150,1,2,233.54,233.8,27,25,1,1,233.53,233.85,10,200,1,1,233.45,233.9,15,27,1,1,233.4,233.94,110,200,2,1,233.39,233.98,10,44,1,3,233.31,234.0,110,154,2,7,233.3,234.13,100,400,1,1,233.25,234.17,55,1,2,1,AAPL,708,15.66804979253112,-0.20224869420830707
2024-10-21T11:59:22.227282918Z,2024-10-21T11:59:22.227115805Z,10,2,38,A,B,1,233.61,200,130,167113,11607900,233.65,233.77,1,8,1,1,233.61,233.78,200,150,1,2,233.54,233.8,27,25,1,1,233.53,233.85,10,200,1,1,233.45,233.9,15,27,1,1,233.4,233.94,110,200,2,1,233.39,233.98,10,44,1,3,233.31,234.0,110,154,2,7,233.3,234.13,100,400,1,1,233.25,234.17,55,1,2,1,AAPL,708,16.3594351732991,-0.2111733397325825
2024-10-21T11:59:22.702960044Z,2024-10-21T11:59:22.702793943Z,10,2,38,C,B,1,233.61,200,130,166101,11608195,233.65,233.77,1,8,1,1,233.54,233.78,27,150,1,2,233.53,233.8,10,25,1,1,233.45,233.85,15,200,1,1,233.4,233.9,110,27,2,1,233.39,233.94,10,200,1,1,233.31,233.98,110,44,2,3,233.3,234.0,100,154,1,7,233.25,234.13,55,400,2,1,233.24,234.17,1,1,1,1,AAPL,707,16.33632862644416,-0.2108750723035817
2024-10-21T11:59:22.702972049Z,2024-10-21T11:59:22.702805375Z,10,2,38,A,B,1,233.59,200,130,166674,11608196,233.65,233.77,1,8,1,1,233.59,233.78,200,150,1,2,233.54,233.8,27,25,1,1,233.53,233.85,10,200,1,1,233.45,233.9,15,27,1,1,233.4,233.94,110,200,2,1,233.39,233.98,10,44,1,3,233.31,234.0,110,154,2,7,233.3,234.13,100,400,1,1,233.25,234.17,55,1,2,1,AAPL,762,18.251497005988025,-0.23559673894880956
2024-10-21T11:59:22.748565679Z,2024-10-21T11:59:22.748399070Z,10,2,38,A,A,3,233.84,200,130,166609,11608273,233.65,233.77,1,8,1,1,233.59,233.78,200,150,1,2,233.54,233.8,27,25,1,1,233.53,233.84,10,200,1,1,233.45,233.9,15,27,1,1,233.4,233.94,110,200,2,1,233.39,233.98,10,44,1,3,233.31,234.0,110,154,2,7,233.3,234.13,100,400,1,1,233.25,234.17,55,1,2,1,AAPL,762,18.814814814814813,-0.24286824323735304
2024-10-21T11:59:24.992377577Z,2024-10-21T11:59:24.992210687Z,10,2,38,A,A,3,233.84,200,130,166890,11609787,233.65,233.77,1,8,1,1,233.59,233.78,200,150,1,2,233.54,233.8,27,25,1,1,233.53,233.84,10,400,1,2,233.45,233.9,15,27,1,1,233.4,233.94,110,200,2,1,233.39,233.98,10,44,1,3,233.31,234.0,110,154,2,7,233.3,234.13,100,400,1,1,233.25,234.17,55,1,2,1,AAPL,762,19.311510031678985,-0.24927975969029267
2024-10-21T11:59:29.283442922Z,2024-10-21T11:59:29.283276904Z,10,2,38,C,A,3,233.84,200,130,166018,11611911,233.65,233.77,1,8,1,1,233.59,233.78,200,150,1,2,233.54,233.8,27,25,1,1,233.53,233.84,10,200,1,1,233.45,233.9,15,27,1,1,233.4,233.94,110,200,2,1,233.39,233.98,10,44,1,3,233.31,234.0,110,154,2,7,233.3,234.13,100,400,1,1,233.25,234.17,55,1,2,1,AAPL,108,5.08235294117647,-0.06560479826587508
2024-10-21T11:59:29.283453171Z,2024-10-21T11:59:29.283287223Z,10,2,38,C,A,3,233.84,200,130,165948,11611912,233.65,233.77,1,8,1,1,233.59,233.78,200,150,1,2,233.54,233.8,27,25,1,1,233.53,233.9,10,27,1,1,233.45,233.94,15,200,1,1,233.4,233.98,110,44,2,3,233.39,234.0,10,154,1,7,233.31,234.13,110,400,2,1,233.3,234.17,100,1,1,1,233.25,234.41,55,600,2,2,AAPL,708,12.808040201005024,-0.1653306850770671
2024-10-21T11:59:29.283464537Z,2024-10-21T11:59:29.283298495Z,10,2,38,A,A,3,233.89,400,130,166042,11611913,233.65,233.77,1,8,1,1,233.59,233.78,200,150,1,2,233.54,233.8,27,25,1,1,233.53,233.89,10,400,1,1,233.45,233.9,15,27,1,1,233.4,233.94,110,200,2,1,233.39,233.98,10,44,1,3,233.31,234.0,110,154,2,7,233.3,234.13,100,400,1,1,233.25,234.17,55,1,2,1,AAPL,707,13.453853472882969,-0.17366706980070848
2024-10-21T11:59:29.341972985Z,2024-10-21T11:59:29.341806485Z,10,2,38,A,A,3,233.88,400,130,166500,11611985,233.65,233.77,1,8,1,1,233.59,233.78,200,150,1,2,233.54,233.8,27,25,1,1,233.53,233.88,10,400,1,1,233.45,233.9,15,27,1,1,233.4,233.94,110,200,2,1,233.39,233.98,10,44,1,3,233.31,234.0,110,154,2,7,233.3,234.13,100,400,1,1,233.25,234.17,55,1,2,1,AAPL,707,14.05058717253839,-0.18136991815410936
2024-10-21T11:59:29.368272089Z,2024-10-21T11:59:29.368105783Z,10,2,38,A,A,3,233.83,400,130,166306,11612038,233.65,233.77,1,8,1,1,233.59,233.78,200,150,1,2,233.54,233.8,27,25,1,1,233.53,233.83,10,400,1,1,233.45,233.9,15,27,1,1,233.4,233.94,110,200,2,1,233.39,233.98,10,44,1,3,233.31,234.0,110,154,2,7,233.3,234.13,100,400,1,1,233.25,234.17,55,1,2,1,AAPL,707,14.589853826311263,-0.1883309616789798
2024-10-21T11:59:29.441719865Z,2024-10-21T11:59:29.441553398Z,10,2,38,A,A,4,233.89,28,130,166467,11612272,233.65,233.77,1,8,1,1,233.59,233.78,200,150,1,2,233.54,233.8,27,25,1,1,233.53,233.83,10,400,1,1,233.45,233.89,15,28,1,1,233.4,233.9,110,27,2,1,233.39,233.94,10,200,1,1,233.31,233.98,110,44,2,3,233.3,234.0,100,154,1,7,233.25,234.13,55,400,2,1,AAPL,307,4.933250927070457,-0.06368013705684926
2024-10-21T11:59:29.441815353Z,2024-10-21T11:59:29.441648558Z,10,2,38,C,A,5,233.9,27,130,166795,11612275,233.65,233.77,1,8,1,1,233.59,233.78,200,150,1,2,233.54,233.8,27,25,1,1,233.53,233.83,10,400,1,1,233.45,233.89,15,28,1,1,233.4,233.94,110,200,2,1,233.39,233.98,10,44,1,3,233.31,234.0,110,154,2,7,233.3,234.13,100,400,1,1,233.25,234.17,55,1,2,1,AAPL,308,5.1517323775388295,-0.06650037241805096
2024-10-21T11:59:29.504458424Z,2024-10-21T11:59:29.504292026Z,10,2,38,A,B,1,233.59,200,130,166398,11612308,233.65,233.77,1,8,1,1,233.59,233.78,400,150,2,2,233.54,233.8,27,25,1,1,233.53,233.83,10,400,1,1,233.45,233.89,15,28,1,1,233.4,233.94,110,200,2,1,233.39,233.98,10,44,1,3,233.31,234.0,110,154,2,7,233.3,234.13,100,400,1,1,233.25,234.17,55,1,2,1,AAPL,308,5.341040462427746,-0.06894402772160443
2024-10-21T11:59:29.550493679Z,2024-10-21T11:59:29.550327634Z,10,2,38,C,B,1,233.59,200,130,166045,11612321,233.65,233.77,1,8,1,1,233.59,233.78,200,150,1,2,233.54,233.8,27,25,1,1,233.53,233.83,10,400,1,1,233.45,233.89,15,28,1,1,233.4,233.94,110,200,2,1,233.39,233.98,10,44,1,3,233.31,234.0,110,154,2,7,233.3,234.13,100,400,1,1,233.25,234.17,55,1,2,1,AAPL,308,5.518477043673013,-0.07123444148316577
2024-10-21T11:59:29.550507093Z,2024-10-21T11:59:29.550340581Z,10,2,38,A,B,1,233.6,200,130,166512,11612322,233.65,233.77,1,8,1,1,233.6,233.78,200,150,1,2,233.54,233.8,27,25,1,1,233.53,233.83,10,400,1,1,233.45,233.89,15,28,1,1,233.4,233.94,110,200,2,1,233.39,233.98,10,44,1,3,233.31,234.0,110,154,2,7,233.3,234.13,100,400,1,1,233.25,234.17,55,1,2,1,AAPL,308,5.685124864277959,-0.07338559013001761
2024-10-21T11:59:30.102880517Z,2024-10-21T11:59:30.102712999Z,10,2,38,T,B,0,233.77,8,130,167518,11612948,233.65,233.77,1,8,1,1,233.6,233.78,200,150,1,2,233.54,233.8,27,25,1,1,233.53,233.83,10,400,1,1,233.45,233.89,15,28,1,1,233.4,233.94,110,200,2,1,233.39,233.98,10,44,1,3,233.31,234.0,110,154,2,7,233.3,234.13,100,400,1,1,233.25,234.17,55,1,2,1,AAPL,308,5.841938883034773,-0.07540980060592771
2024-10-21T11:59:30.102880517Z,2024-10-21T11:59:30.102712999Z,10,2,38,C,A,0,233.77,8,130,167518,11612948,233.65,233.78,1,150,1,2,233.6,233.8,200,25,1,1,233.54,233.83,27,400,1,1,233.53,233.89,10,28,1,1,233.45,233.94,15,200,1,1,233.4,233.98,110,44,2,3,233.39,234.0,10,154,1,7,233.31,234.13,110,400,2,1,233.3,234.17,100,1,1,1,233.25,234.41,55,600,2,2,AAPL,908,13.515080297688993,-0.17445740717718541
2024-10-21T11:59:30.102902312Z,2024-10-21T11:59:30.102735583Z,10,2,38,A,B,0,233.68,100,130,166729,11612949,233.68,233.78,100,150,1,2,233.65,233.8,1,25,1,1,233.6,233.83,200,400,1,1,233.54,233.89,27,28,1,1,233.53,233.94,10,200,1,1,233.45,233.98,15,44,1,3,233.4,234.0,110,154,2,7,233.39,234.13,10,400,1,1,233.31,234.17,110,1,2,1,233.3,234.41,100,600,1,2,AAPL,1008,12.39471257300953,-0.15999530676583942
2024-10-21T11:59:30.102913346Z,2024-10-21T11:59:30.102746947Z,10,2,38,A,B,0,233.68,100,130,166399,11612950,233.68,233.78,200,150,2,2,233.65,233.8,1,25,1,1,233.6,233.83,200,400,1,1,233.54,233.89,27,28,1,1,233.53,233.94,10,200,1,1,233.45,233.98,15,44,1,3,233.4,234.0,110,154,2,7,233.39,234.13,10,400,1,1,233.31,234.17,110,1,2,1,233.3,234.41,100,600,1,2,AAPL,1008,10.709840627371616,-0.13824638744111797
2024-10-21T11:59:30.102919154Z,2024-10-21T11:59:30.102753002Z,10,2,38,A,B,0,233.71,23,130,166152,11612951,233.71,233.78,23,150,1,2,233.68,233.8,200,25,2,1,233.65,233.83,1,400,1,1,233.6,233.89,200,28,1,1,233.54,233.94,27,200,1,1,233.53,233.98,10,44,1,3,233.45,234.0,15,154,1,7,233.4,234.13,110,400,2,1,233.39,234.17,10,1,1,1,233.31,234.41,110,600,2,2,AAPL,1118,10.549431696332832,-0.13617577257382227
2024-10-21T11:59:30.102932550Z,2024-10-21T11:59:30.102766235Z,10,2,38,A,B,2,233.67,23,130,166315,11612953,233.71,233.78,23,150,1,2,233.68,233.8,200,25,2,1,233.67,233.83,23,400,1,1,233.65,233.89,1,28,1,1,233.6,233.94,200,200,1,1,233.54,233.98,27,44,1,3,233.53,234.0,10,154,1,7,233.45,234.13,15,400,1,1,233.4,234.17,110,1,2,1,233.39,234.41,10,600,1,2,AAPL,1128,9.840318604210127,-0.1270222915199008
2024-10-21T11:59:30.102947096Z,2024-10-21T11:59:30.102781049Z,10,2,38,C,B,1,233.68,100,130,166047,11612954,233.71,233.78,23,150,1,2,233.68,233.8,100,25,1,1,233.67,233.83,23,400,1,1,233.65,233.89,1,28,1,1,233.6,233.94,200,200,1,1,233.54,233.98,27,44,1,3,233.53,234.0,10,154,1,7,233.45,234.13,15,400,1,1,233.4,234.17,110,1,2,1,233.39,234.41,10,600,1,2,AAPL,1128,9.203467618561959,-0.11880159513725241
2024-10-21T11:59:30.102950618Z,2024-10-21T11:59:30.102784354Z,10,2,38,C,B,1,233.68,100,130,166264,11612955,233.71,233.78,23,150,1,2,233.67,233.8,23,25,1,1,233.65,233.83,1,400,1,1,233.6,233.89,200,28,1,1,233.54,233.94,27,200,1,1,233.53,233.98,10,44,1,3,233.45,234.0,15,154,1,7,233.4,234.13,110,400,2,1,233.39,234.17,10,1,1,1,233.31,234.41,110,600,2,2,AAPL,1018,7.720309419080842,-0.09965646775245228
2024-10-21T11:59:30.167107134Z,2024-10-21T11:59:30.166940785Z,10,2,38,C,A,2,233.83,200,130,166349,11613018,233.71,233.78,23,150,1,2,233.67,233.8,23,25,1,1,233.65,233.83,1,200,1,1,233.6,233.89,200,28,1,1,233.54,233.94,27,200,1,1,233.53,233.98,10,44,1,3,233.45,234.0,15,154,1,7,233.4,234.13,110,400,2,1,233.39,234.17,10,1,1,1,233.31,234.41,110,600,2,2,AAPL,1018,7.248528002190882,-0.0935665473870457
2024-10-21T11:59:30.203930522Z,2024-10-21T11:59:30.203764599Z,10,2,38,C,B,1,233.67,23,130,165923,11613033,233.71,233.78,23,150,1,2,233.65,233.8,1,25,1,1,233.6,233.83,200,200,1,1,233.54,233.89,27,28,1,1,233.53,233.94,10,200,1,1,233.45,233.98,15,44,1,3,233.4,234.0,110,154,2,7,233.39,234.13,10,400,1,1,233.31,234.17,110,1,2,1,233.3,234.41,100,600,1,2,AAPL,918,6.1941771835561665,-0.07995661640457068
2024-10-21T11:59:30.353929412Z,2024-10-21T11:59:30.353763576Z,10,2,38,C,B,0,233.71,23,130,165836,11613099,233.65,233.78,1,150,1,2,233.6,233.8,200,25,1,1,233.54,233.83,27,200,1,1,233.53,233.89,10,28,1,1,233.45,233.94,15,200,1,1,233.4,233.98,110,44,2,3,233.39,234.0,10,154,1,7,233.31,234.13,110,400,2,1,233.3,234.17,100,1,1,1,233.25,234.41,55,600,2,2,AAPL,863,5.581889581889582,-0.07205299281664757
2024-10-21T11:59:33.215114965Z,2024-10-21T11:59:33.214948750Z,10,2,38,A,B,1,233.6,200,130,166215,11614193,233.65,233.78,1,150,1,2,233.6,233.8,400,25,2,1,233.54,233.83,27,200,1,1,233.53,233.89,10,28,1,1,233.45,233.94,15,200,1,1,233.4,233.98,110,44,2,3,233.39,234.0,10,154,1,7,233.31,234.13,110,400,2,1,233.3,234.17,100,1,1,1,233.25,234.41,55,600,2,2,AAPL,863,5.374637603350156,-0.06937771142638365
2024-10-21T11:59:33.268762813Z,2024-10-21T11:59:33.268596579Z,10,2,38,C,B,1,233.6,200,130,166234,11614270,233.65,233.78,1,150,1,2,233.6,233.8,200,25,1,1,233.54,233.83,27,200,1,1,233.53,233.89,10,28,1,1,233.45,233.94,15,200,1,1,233.4,233.98,110,44,2,3,233.39,234.0,10,154,1,7,233.31,234.13,110,400,2,1,233.3,234.17,100,1,1,1,233.25,234.41,55,600,2,2,AAPL,863,5.1946227929374,-0.06705401697645336
2024-10-21T11:59:40.586248814Z,2024-10-21T11:59:40.586082406Z,10,2,38,A,B,0,233.77,1,130,166408,11618353,233.77,233.78,1,150,1,2,233.65,233.8,1,25,1,1,233.6,233.83,200,200,1,1,233.54,233.89,27,28,1,1,233.53,233.94,10,200,1,1,233.45,233.98,15,44,1,3,233.4,234.0,110,154,2,7,233.39,234.13,10,400,1,1,233.31,234.17,110,1,2,1,233.3,234.41,100,600,1,2,AAPL,963,5.59673790776153,-0.0722446602263473
2024-10-21T11:59:40.711629689Z,2024-10-21T11:59:40.711462280Z,10,2,38,T,A,0,233.77,1,130,167409,11618393,233.77,233.78,1,150,1,2,233.65,233.8,1,25,1,1,233.6,233.83,200,200,1,1,233.54,233.89,27,28,1,1,233.53,233.94,10,200,1,1,233.45,233.98,15,44,1,3,233.4,234.0,110,154,2,7,233.39,234.13,10,400,1,1,233.31,234.17,110,1,2,1,233.3,234.41,100,600,1,2,AAPL,963,5.421534130893737,-0.06998306828854492
2024-10-21T11:59:40.711629689Z,2024-10-21T11:59:40.711462280Z,10,2,38,C,B,0,233.77,1,130,167409,11618393,233.65,233.78,1,150,1,2,233.6,233.8,200,25,1,1,233.54,233.83,27,200,1,1,233.53,233.89,10,28,1,1,233.45,233.94,15,200,1,1,233.4,233.98,110,44,2,3,233.39,234.0,10,154,1,7,233.31,234.13,110,400,2,1,233.3,234.17,100,1,1,1,233.25,234.41,55,600,2,2,AAPL,908,4.98444647758463,-0.06434098721866727
2024-10-21T11:59:44.915922829Z,2024-10-21T11:59:44.915756078Z,10,2,38,A,B,1,233.61,200,130,166751,11621712,233.65,233.78,1,150,1,2,233.61,233.8,200,25,1,1,233.54,233.83,27,200,1,1,233.53,233.89,10,28,1,1,233.45,233.94,15,200,1,1,233.4,233.98,110,44,2,3,233.39,234.0,10,154,1,7,233.31,234.13,110,400,2,1,233.3,234.17,100,1,1,1,233.25,234.41,55,600,2,2,AAPL,800,3.5983935742971886,-0.04644932913068056
2024-10-21T11:59:56.140500513Z,2024-10-21T11:59:56.140334654Z,10,2,38,C,B,1,233.61,200,130,165859,11629360,233.65,233.78,1,150,1,2,233.54,233.8,27,25,1,1,233.53,233.83,10,200,1,1,233.45,233.89,15,28,1,1,233.4,233.94,110,200,2,1,233.39,233.98,10,44,1,3,233.31,234.0,110,154,2,7,233.3,234.13,100,400,1,1,233.25,234.17,55,1,2,1,233.24,234.41,1,600,1,2,AAPL,44,0.13289036544850497,-0.0017153955495876035
2024-10-21T11:59:56.140515113Z,2024-10-21T11:59:56.140348516Z,10,2,38,A,B,1,233.59,200,130,166597,11629361,233.65,233.78,1,150,1,2,233.59,233.8,200,25,1,1,233.54,233.83,27,200,1,1,233.53,233.89,10,28,1,1,233.45,233.94,15,200,1,1,233.4,233.98,110,44,2,3,233.39,234.0,10,154,1,7,233.31,234.13,110,400,2,1,233.3,234.17,100,1,1,1,233.25,234.41,55,600,2,2,AAPL,99,0.29954614220877457,-0.0038666468972890318
2024-10-21T11:59:56.303991491Z,2024-10-21T11:59:56.303825659Z,10,2,38,C,A,2,233.83,200,130,165832,11629887,233.65,233.78,1,150,1,2,233.59,233.8,200,25,1,1,233.54,233.89,27,28,1,1,233.53,233.94,10,200,1,1,233.45,233.98,15,44,1,3,233.4,234.0,110,154,2,7,233.39,234.13,10,400,1,1,233.31,234.17,110,1,2,1,233.3,234.41,100,600,1,2,233.25,234.43,55,5,2,1,AAPL,104,0.36164927968206656,-0.004668296025708301
2024-10-21T11:59:56.304004867Z,2024-10-21T11:59:56.303838548Z,10,2,38,A,A,2,233.85,200,130,166319,11629888,233.65,233.78,1,150,1,2,233.59,233.8,200,25,1,1,233.54,233.85,27,200,1,1,233.53,233.89,10,28,1,1,233.45,233.94,15,200,1,1,233.4,233.98,110,44,2,3,233.39,234.0,10,154,1,7,233.31,234.13,110,400,2,1,233.3,234.17,100,1,1,1,233.25,234.41,55,600,2,2,AAPL,-496,-1.695364238410596,0.021884357527983837
2024-10-21T11:59:56.366844504Z,2024-10-21T11:59:56.366678187Z,10,2,38,A,A,2,233.84,200,130,166317,11630234,233.65,233.78,1,150,1,2,233.59,233.8,200,25,1,1,233.54,233.84,27,200,1,1,233.53,233.89,10,28,1,1,233.45,233.94,15,200,1,1,233.4,233.98,110,44,2,3,233.39,234.0,10,154,1,7,233.31,234.13,110,400,2,1,233.3,234.17,100,1,1,1,233.25,234.41,55,600,2,2,AAPL,-496,-1.6731634182908546,0.02159778153805358
2024-10-21T11:59:56.374489545Z,2024-10-21T11:59:56.374323675Z,10,2,38,C,A,3,233.89,28,130,165870,11630290,233.65,233.78,1,150,1,2,233.59,233.8,200,25,1,1,233.54,233.84,27,200,1,1,233.53,233.94,10,200,1,1,233.45,233.98,15,44,1,3,233.4,234.0,110,154,2,7,233.39,234.13,10,400,1,1,233.31,234.17,110,1,2,1,233.3,234.41,100,600,1,2,233.25,234.43,55,5,2,1,AAPL,-491,-1.8198665678280206,0.023491477359998285
2024-10-21T11:59:56.374545521Z,2024-10-21T11:59:56.374379339Z,10,2,38,A,A,3,233.92,27,130,166182,11630291,233.65,233.78,1,150,1,2,233.59,233.8,200,25,1,1,233.54,233.84,27,200,1,1,233.53,233.92,10,27,1,1,233.45,233.94,15,200,1,1,233.4,233.98,110,44,2,3,233.39,234.0,10,154,1,7,233.31,234.13,110,400,2,1,233.3,234.17,100,1,1,1,233.25,234.41,55,600,2,2,AAPL,-1091,-3.966617088084614,0.05120248768113411
2024-10-21T11:59:57.076425198Z,2024-10-21T11:59:57.076259289Z,10,2,38,C,A,3,233.92,27,130,165909,11631174,233.65,233.78,1,150,1,2,233.59,233.8,200,25,1,1,233.54,233.84,27,200,1,1,233.53,233.94,10,200,1,1,233.45,233.98,15,44,1,3,233.4,234.0,110,154,2,7,233.39,234.13,10,400,1,1,233.31,234.17,110,1,2,1,233.3,234.41,100,600,1,2,233.25,234.43,55,5,2,1,AAPL,-1086,-4.265095729013255,0.055055354896661114
2024-10-21T11:59:57.076481289Z,2024-10-21T11:59:57.076314960Z,10,2,38,A,A,3,233.91,26,130,166329,11631175,233.65,233.78,1,150,1,2,233.59,233.8,200,25,1,1,233.54,233.84,27,200,1,1,233.53,233.91,10,26,1,1,233.45,233.94,15,200,1,1,233.4,233.98,110,44,2,3,233.39,234.0,10,154,1,7,233.31,234.13,110,400,2,1,233.3,234.17,100,1,1,1,233.25,234.41,55,600,2,2,AAPL,-1686,-6.478864912799291,0.08363146568440874
2024-10-21T11:59:57.121963263Z,2024-10-21T11:59:57.121796841Z,10,2,38,A,B,1,233.61,200,130,166422,11631246,233.65,233.78,1,150,1,2,233.61,233.8,200,25,1,1,233.54,233.84,27,200,1,1,233.53,233.91,10,26,1,1,233.45,233.94,15,200,1,1,233.4,233.98,110,44,2,3,233.39,234.0,10,154,1,7,233.31,234.13,110,400,2,1,233.3,234.17,100,1,1,1,233.25,234.41,55,600,2,2,AAPL,-1686,-6.361406818488074,0.08211527531526887
2024-10-21T11:59:58.069437531Z,2024-10-21T11:59:58.069271668Z,10,2,38,C,B,1,233.61,200,130,165863,11632068,233.65,233.78,1,150,1,2,233.54,233.8,27,25,1,1,233.53,233.84,10,200,1,1,233.45,233.91,15,26,1,1,233.4,233.94,110,200,2,1,233.39,233.98,10,44,1,3,233.31,234.0,110,154,2,7,233.3,234.13,100,400,1,1,233.25,234.17,55,1,2,1,233.24,234.41,1,600,1,2,AAPL,-1687,-6.30890052356021,0.0814375056038183
2024-10-21T11:59:58.069450306Z,2024-10-21T11:59:58.069284093Z,10,2,38,A,B,1,233.59,200,130,166213,11632069,233.65,233.78,1,150,1,2,233.59,233.8,200,25,1,1,233.54,233.84,27,200,1,1,233.53,233.91,10,26,1,1,233.45,233.94,15,200,1,1,233.4,233.98,110,44,2,3,233.39,234.0,10,154,1,7,233.31,234.13,110,400,2,1,233.3,234.17,100,1,1,1,233.25,234.41,55,600,2,2,AAPL,-1632,-6.018670047251354,0.07769110859652116
2024-10-21T12:00:01.682174453Z,2024-10-21T12:00:01.682008523Z,10,2,38,C,A,3,233.91,26,130,165930,11639355,233.65,233.78,1,150,1,2,233.59,233.8,200,25,1,1,233.54,233.84,27,200,1,1,233.53,233.94,10,200,1,1,233.45,233.98,15,44,1,3,233.4,234.0,110,154,2,7,233.39,234.13,10,400,1,1,233.31,234.17,110,1,2,1,233.3,234.41,100,600,1,2,233.25,234.43,55,5,2,1,AAPL,-1672,-7.006285543250524,0.09043959657624016
2024-10-21T12:00:01.682225908Z,2024-10-21T12:00:01.682052966Z,10,2,38,A,A,3,233.9,26,130,172942,11639356,233.65,233.78,1,150,1,2,233.59,233.8,200,25,1,1,233.54,233.84,27,200,1,1,233.53,233.9,10,26,1,1,233.45,233.94,15,200,1,1,233.4,233.98,110,44,2,3,233.39,234.0,10,154,1,7,233.31,234.13,110,400,2,1,233.3,234.17,100,1,1,1,233.25,234.41,55,600,2,2,AAPL,-2272,-9.289900504293309,0.11991730120835224
2024-10-21T12:00:01.884805082Z,2024-10-21T12:00:01.884638806Z,10,2,38,A,B,1,233.61,200,130,166276,11639901,233.65,233.78,1,150,1,2,233.61,233.8,200,25,1,1,233.54,233.84,27,200,1,1,233.53,233.9,10,26,1,1,233.45,233.94,15,200,1,1,233.4,233.98,110,44,2,3,233.39,234.0,10,154,1,7,233.31,234.13,110,400,2,1,233.3,234.17,100,1,1,1,233.25,234.41,55,600,2,2,AAPL,-2272,-9.097097097097096,0.11742852705581316
2024-10-21T12:00:02.064451153Z,2024-10-21T12:00:02.064285089Z,10,2,38,C,B,1,233.61,200,130,166064,11640243,233.65,233.78,1,150,1,2,233.54,233.8,27,25,1,1,233.53,233.84,10,200,1,1,233.45,233.9,15,26,1,1,233.4,233.94,110,200,2,1,233.39,233.98,10,44,1,3,233.31,234.0,110,154,2,7,233.3,234.13,100,400,1,1,233.25,234.17,55,1,2,1,233.24,234.41,1,600,1,2,AAPL,-2273,-8.993599441405795,0.11609254293562196
2024-10-21T12:00:02.160522798Z,2024-10-21T12:00:02.160356498Z,10,2,38,C,B,1,233.54,27,130,166300,11640336,233.65,233.78,1,150,1,2,233.53,233.8,10,25,1,1,233.45,233.84,15,200,1,1,233.4,233.9,110,26,2,1,233.39,233.94,10,200,1,1,233.31,233.98,110,44,2,3,233.3,234.0,100,154,1,7,233.25,234.13,55,400,2,1,233.24,234.17,1,1,1,1,233.23,234.41,50,600,1,2,AAPL,-2323,-9.047711781888998,0.11679104404764294
2024-10-21T12:00:02.160610908Z,2024-10-21T12:00:02.160444679Z,10,2,38,A,B,2,233.49,26,130,166229,11640337,233.65,233.78,1,150,1,2,233.53,233.8,10,25,1,1,233.49,233.84,26,200,1,1,233.45,233.9,15,26,1,1,233.4,233.94,110,200,2,1,233.39,233.98,10,44,1,3,233.31,234.0,110,154,2,7,233.3,234.13,100,400,1,1,233.25,234.17,55,1,2,1,233.24,234.41,1,600,1,2,AAPL,-2322,-8.963429500203171,0.11570309872952296
2024-10-21T12:00:02.178913898Z,2024-10-21T12:00:02.178747608Z,10,2,38,A,B,3,233.48,400,130,166290,11640354,233.65,233.78,1,150,1,2,233.53,233.8,10,25,1,1,233.49,233.84,26,200,1,1,233.48,233.9,400,26,1,1,233.45,233.94,15,200,1,1,233.4,233.98,110,44,2,3,233.39,234.0,10,154,1,7,233.31,234.13,110,400,2,1,233.3,234.17,100,1,1,1,233.25,234.41,55,600,2,2,AAPL,-2267,-8.637013048861796,0.11148960043675057
2024-10-21T12:00:02.220042789Z,2024-10-21T12:00:02.219875510Z,10,2,38,A,B,1,233.56,200,130,167279,11640428,233.65,233.78,1,150,1,2,233.56,233.8,200,25,1,1,233.53,233.84,10,200,1,1,233.49,233.9,26,26,1,1,233.45,233.94,15,200,1,1,233.4,233.98,110,44,2,3,233.39,234.0,10,154,1,7,233.31,234.13,110,400,2,1,233.3,234.17,100,1,1,1,233.25,234.41,55,600,2,2,AAPL,-2267,-8.536309844002153,0.11018968807017364
2024-10-21T12:00:02.605637435Z,2024-10-21T12:00:02.605471012Z,10,2,38,A,A,2,233.84,200,130,166423,11641451,233.65,233.78,1,150,1,2,233.56,233.8,200,25,1,1,233.53,233.84,10,400,1,2,233.49,233.9,26,26,1,1,233.45,233.94,15,200,1,1,233.4,233.98,110,44,2,3,233.39,234.0,10,154,1,7,233.31,234.13,110,400,2,1,233.3,234.17,100,1,1,1,233.25,234.41,55,600,2,2,AAPL,-2267,-8.446777881276992,0.10903397802387914
2024-10-21T12:00:02.834204113Z,2024-10-21T12:00:02.834037742Z,10,2,38,A,B,1,233.56,200,130,166371,11642029,233.65,233.78,1,150,1,2,233.56,233.8,400,25,2,1,233.53,233.84,10,400,1,2,233.49,233.9,26,26,1,1,233.45,233.94,15,200,1,1,233.4,233.98,110,44,2,3,233.39,234.0,10,154,1,7,233.31,234.13,110,400,2,1,233.3,234.17,100,1,1,1,233.25,234.41,55,600,2,2,AAPL,-2267,-8.366655969191271,0.10799973621897152
2024-10-21T12:00:03.047805689Z,2024-10-21T12:00:03.047639596Z,10,2,38,C,B,1,233.56,200,130,166093,11642521,233.65,233.78,1,150,1,2,233.56,233.8,200,25,1,1,233.53,233.84,10,400,1,2,233.49,233.9,26,26,1,1,233.45,233.94,15,200,1,1,233.4,233.98,110,44,2,3,233.39,234.0,10,154,1,7,233.31,234.13,110,400,2,1,233.3,234.17,100,1,1,1,233.25,234.41,55,600,2,2,AAPL,-2267,-8.294534644408873,0.10706876880726682
2024-10-21T12:00:03.047816248Z,2024-10-21T12:00:03.047650452Z,10,2,38,C,B,1,233.56,200,130,165796,11642522,233.65,233.78,1,150,1,2,233.53,233.8,10,25,1,1,233.49,233.84,26,400,1,2,233.45,233.9,15,26,1,1,233.4,233.94,110,200,2,1,233.39,233.98,10,44,1,3,233.31,234.0,110,154,2,7,233.3,234.13,100,400,1,1,233.25,234.17,55,1,2,1,233.24,234.41,1,600,1,2,AAPL,-2268,-8.26530612244898,0.10669147677167184
2024-10-21T12:00:03.057632178Z,2024-10-21T12:00:03.057465668Z,10,2,38,A,B,1,233.55,200,130,166510,11642541,233.65,233.78,1,150,1,2,233.55,233.8,200,25,1,1,233.53,233.84,10,400,1,2,233.49,233.9,26,26,1,1,233.45,233.94,15,200,1,1,233.4,233.98,110,44,2,3,233.39,234.0,10,154,1,7,233.31,234.13,110,400,2,1,233.3,234.17,100,1,1,1,233.25,234.41,55,600,2,2,AAPL,-2213,-8.00528695652174,0.10333505797837786
2024-10-21T12:00:03.060919018Z,2024-10-21T12:00:03.060752951Z,10,2,38,C,B,1,233.55,200,130,166067,11642554,233.65,233.78,1,150,1,2,233.53,233.8,10,25,1,1,233.49,233.84,26,400,1,2,233.45,233.9,15,26,1,1,233.4,233.94,110,200,2,1,233.39,233.98,10,44,1,3,233.31,234.0,110,154,2,7,233.3,234.13,100,400,1,1,233.25,234.17,55,1,2,1,233.24,234.41,1,600,1,2,AAPL,-2214,-7.9831730769230775,0.10304960424725422
2024-10-21T12:00:03.163064101Z,2024-10-21T12:00:03.162897564Z,10,2,38,A,B,1,233.55,400,130,166537,11642717,233.65,233.78,1,150,1,2,233.55,233.8,400,25,1,1,233.53,233.84,10,400,1,2,233.49,233.9,26,26,1,1,233.45,233.94,15,200,1,1,233.4,233.98,110,44,2,3,233.39,234.0,10,154,1,7,233.31,234.13,110,400,2,1,233.3,234.17,100,1,1,1,233.25,234.41,55,600,2,2,AAPL,-2159,-7.734885803851321,0.09984462485082406
2024-10-21T12:00:03.902220253Z,2024-10-21T12:00:03.902053598Z,10,2,38,A,B,1,233.56,400,130,166655,11643778,233.65,233.78,1,150,1,2,233.56,233.8,400,25,1,1,233.53,233.84,10,400,1,2,233.49,233.9,26,26,1,1,233.45,233.94,15,200,1,1,233.4,233.98,110,44,2,3,233.39,234.0,10,154,1,7,233.31,234.13,110,400,2,1,233.3,234.17,100,1,1,1,233.25,234.41,55,600,2,2,AAPL,-2159,-7.688935281837161,0.09925147936056755
2024-10-21T12:00:04.046984715Z,2024-10-21T12:00:04.046818528Z,10,2,38,C,B,1,233.56,400,130,166187,11644129,233.65,233.78,1,150,1,2,233.53,233.8,10,25,1,1,233.49,233.84,26,400,1,2,233.45,233.9,15,26,1,1,233.4,233.94,110,200,2,1,233.39,233.98,10,44,1,3,233.31,234.0,110,154,2,7,233.3,234.13,100,400,1,1,233.25,234.17,55,1,2,1,233.24,234.41,1,600,1,2,AAPL,-2160,-7.674542547521763,0.09906569288682507
2024-10-21T12:00:04.147446688Z,2024-10-21T12:00:04.147280360Z,10,2,38,A,B,1,233.56,400,130,166328,11644350,233.65,233.78,1,150,1,2,233.56,233.8,400,25,1,1,233.53,233.84,10,400,1,2,233.49,233.9,26,26,1,1,233.45,233.94,15,200,1,1,233.4,233.98,110,44,2,3,233.39,234.0,10,154,1,7,233.31,234.13,110,400,2,1,233.3,234.17,100,1,1,1,233.25,234.41,55,600,2,2,AAPL,-2105,-7.439858625014251,0.09603631032120072
2024-10-21T12:00:06.012274881Z,2024-10-21T12:00:06.012108650Z,10,2,38,C,B,1,233.56,400,130,166231,11647927,233.65,233.78,1,150,1,2,233.53,233.8,10,25,1,1,233.49,233.84,26,400,1,2,233.45,233.9,15,26,1,1,233.4,233.94,110,200,2,1,233.39,233.98,10,44,1,3,233.31,234.0,110,154,2,7,233.3,234.13,100,400,1,1,233.25,234.17,55,1,2,1,233.24,234.41,1,600,1,2,AAPL,-2106,-7.466376944190302,0.09637861810659672
2024-10-21T12:00:06.012288800Z,2024-10-21T12:00:06.012122140Z,10,2,38,A,B,2,233.52,200,130,166660,11647928,233.65,233.78,1,150,1,2,233.53,233.8,10,25,1,1,233.52,233.84,200,400,1,2,233.49,233.9,26,26,1,1,233.45,233.94,15,200,1,1,233.4,233.98,110,44,2,3,233.39,234.0,10,154,1,7,233.31,234.13,110,400,2,1,233.3,234.17,100,1,1,1,233.25,234.41,55,600,2,2,AAPL,-2051,-7.234966653805875,0.0933914927351337
2024-10-21T12:00:06.101461393Z,2024-10-21T12:00:06.101295300Z,10,2,38,C,B,2,233.52,200,130,166093,11648114,233.65,233.78,1,150,1,2,233.53,233.8,10,25,1,1,233.49,233.84,26,400,1,2,233.45,233.9,15,26,1,1,233.4,233.94,110,200,2,1,233.39,233.98,10,44,1,3,233.31,234.0,110,154,2,7,233.3,234.13,100,400,1,1,233.25,234.17,55,1,2,1,233.24,234.41,1,600,1,2,AAPL,-2052,-7.225352112676056,0.09326738485861642
2024-10-21T12:00:06.101473795Z,2024-10-21T12:00:06.101307454Z,10,2,38,A,B,2,233.5,400,130,166341,11648115,233.65,233.78,1,150,1,2,233.53,233.8,10,25,1,1,233.5,233.84,400,400,1,2,233.49,233.9,26,26,1,1,233.45,233.94,15,200,1,1,233.4,233.98,110,44,2,3,233.39,234.0,10,154,1,7,233.31,234.13,110,400,2,1,233.3,234.17,100,1,1,1,233.25,234.41,55,600,2,2,AAPL,-1997,-7.00015464714676,0.09036045681425753
2024-10-21T12:00:07.067544847Z,2024-10-21T12:00:07.067376608Z,10,2,38,T,A,0,233.65,1,130,168239,11649200,233.65,233.78,1,150,1,2,233.53,233.8,10,25,1,1,233.5,233.84,400,400,1,2,233.49,233.9,26,26,1,1,233.45,233.94,15,200,1,1,233.4,233.98,110,44,2,3,233.39,234.0,10,154,1,7,233.31,234.13,110,400,2,1,233.3,234.17,100,1,1,1,233.25,234.41,55,600,2,2,AAPL,-1997,-6.970679166251123,0.0899799769459113
2024-10-21T12:00:07.067544847Z,2024-10-21T12:00:07.067376608Z,10,2,38,C,B,0,233.65,1,130,168239,11649200,233.53,233.78,10,150,1,2,233.5,233.8,400,25,1,1,233.49,233.84,26,400,1,2,233.45,233.9,15,26,1,1,233.4,233.94,110,200,2,1,233.39,233.98,10,44,1,3,233.31,234.0,110,154,2,7,233.3,234.13,100,400,1,1,233.25,234.17,55,1,2,1,233.24,234.41,1,600,1,2,AAPL,-1998,-6.964705882352941,0.08990287169768067
2024-10-21T12:00:07.067586376Z,2024-10-21T12:00:07.067419673Z,10,2,38,A,A,0,233.72,19,130,166703,11649202,233.53,233.72,10,19,1,1,233.5,233.78,400,150,1,2,233.49,233.8,26,25,1,1,233.45,233.84,15,400,1,2,233.4,233.9,110,26,2,1,233.39,233.94,10,200,1,1,233.31,233.98,110,44,2,3,233.3,234.0,100,154,1,7,233.25,234.13,55,400,2,1,233.24,234.17,1,1,1,1,AAPL,-1999,-7.1610592051120685,0.09243746940813895
2024-10-21T12:00:07.067587561Z,2024-10-21T12:00:07.067421371Z,10,2,38,C,B,1,233.5,200,130,166190,11649203,233.53,233.72,10,19,1,1,233.5,233.78,200,150,1,2,233.49,233.8,26,25,1,1,233.45,233.84,15,400,1,2,233.4,233.9,110,26,2,1,233.39,233.94,10,200,1,1,233.31,233.98,110,44,2,3,233.3,234.0,100,154,1,7,233.25,234.13,55,400,2,1,233.24,234.17,1,1,1,1,AAPL,-1999,-7.353889346047728,0.09492658864918399
2024-10-21T12:00:07.067633143Z,2024-10-21T12:00:07.067467022Z,10,2,38,A,A,1,233.76,19,130,166121,11649204,233.53,233.72,10,19,1,1,233.5,233.76,200,19,1,1,233.49,233.78,26,150,1,2,233.45,233.8,15,25,1,1,233.4,233.84,110,400,2,2,233.39,233.9,10,26,1,1,233.31,233.94,110,200,2,1,233.3,233.98,100,44,1,3,233.25,234.0,55,154,2,7,233.24,234.13,1,400,1,1,AAPL,-2399,-8.885185185185184,0.11469309360756101
2024-10-21T12:00:07.086844298Z,2024-10-21T12:00:07.086677914Z,10,2,38,A,B,1,233.5,200,130,166384,11649237,233.53,233.72,10,19,1,1,233.5,233.76,400,19,2,1,233.49,233.78,26,150,1,2,233.45,233.8,15,25,1,1,233.4,233.84,110,400,2,2,233.39,233.9,10,26,1,1,233.31,233.94,110,200,2,1,233.3,233.98,100,44,1,3,233.25,234.0,55,154,2,7,233.24,234.13,1,400,1,1,AAPL,-2399,-8.942733330226924,0.11543594529254546
2024-10-21T12:00:07.089165016Z,2024-10-21T12:00:07.088999005Z,10,2,38,C,B,1,233.5,200,130,166011,11649239,233.53,233.72,10,19,1,1,233.5,233.76,200,19,1,1,233.49,233.78,26,150,1,2,233.45,233.8,15,25,1,1,233.4,233.84,110,400,2,2,233.39,233.9,10,26,1,1,233.31,233.94,110,200,2,1,233.3,233.98,100,44,1,3,233.25,234.0,55,154,2,7,233.24,234.13,1,400,1,1,AAPL,-2399,-8.99817034123136,0.1161515457172903
2024-10-21T12:00:07.089175420Z,2024-10-21T12:00:07.089009480Z,10,2,38,C,B,1,233.5,200,130,165940,11649240,233.53,233.72,10,19,1,1,233.49,233.76,26,19,1,1,233.45,233.78,15,150,1,2,233.4,233.8,110,25,2,1,233.39,233.84,10,400,1,2,233.31,233.9,110,26,2,1,233.3,233.94,100,200,1,1,233.25,233.98,55,44,2,3,233.24,234.0,1,154,1,7,233.23,234.13,50,400,1,1,AAPL,-2449,-9.21997131588383,0.11901463066350845
2024-10-21T12:00:07.149755425Z,2024-10-21T12:00:07.149589050Z,10,2,38,C,B,1,233.49,26,130,166375,11649363,233.53,233.72,10,19,1,1,233.45,233.76,15,19,1,1,233.4,233.78,110,150,2,2,233.39,233.8,10,25,1,1,233.31,233.84,110,400,2,2,233.3,233.9,100,26,1,1,233.25,233.94,55,200,2,1,233.24,233.98,1,44,1,3,233.23,234.0,50,154,1,7,233.2,234.13,50,400,3,1,AAPL,-2499,-9.441788946489764,0.12187793061062863
2024-10-21T12:00:07.149847104Z,2024-10-21T12:00:07.149680427Z,10,2,38,A,B,2,233.43,29,130,166677,11649364,233.53,233.72,10,19,1,1,233.45,233.76,15,19,1,1,233.43,233.78,29,150,1,2,233.4,233.8,110,25,2,1,233.39,233.84,10,400,1,2,233.31,233.9,110,26,2,1,233.3,233.94,100,200,1,1,233.25,233.98,55,44,2,3,233.24,234.0,1,154,1,7,233.23,234.13,50,400,1,1,AAPL,-2449,-9.284508013096675,0.119847693036468
2024-10-21T12:00:07.173932656Z,2024-10-21T12:00:07.173766393Z,10,2,38,C,A,1,233.76,19,130,166263,11649378,233.53,233.72,10,19,1,1,233.45,233.78,15,150,1,2,233.43,233.8,29,25,1,1,233.4,233.84,110,400,2,2,233.39,233.9,10,26,1,1,233.31,233.94,110,200,2,1,233.3,233.98,100,44,1,3,233.25,234.0,55,154,2,7,233.24,234.13,1,400,1,1,233.23,234.17,50,1,1,1,AAPL,-2448,-9.470833512444655,0.12225284807744852
2024-10-21T12:00:07.191118135Z,2024-10-21T12:00:07.190951663Z,10,2,38,A,B,2,233.44,200,130,166472,11649387,233.53,233.72,10,19,1,1,233.45,233.78,15,150,1,2,233.44,233.8,200,25,1,1,233.43,233.84,29,400,1,2,233.4,233.9,110,26,2,1,233.39,233.94,10,200,1,1,233.31,233.98,110,44,2,3,233.3,234.0,100,154,1,7,233.25,234.13,55,400,2,1,233.24,234.17,1,1,1,1,AAPL,-2447,-9.676509778637438,0.12490778961886231
2024-10-21T12:00:07.323930762Z,2024-10-21T12:00:07.323764357Z,10,2,38,C,A,0,233.72,19,130,166405,11649551,233.53,233.78,10,150,1,2,233.45,233.8,15,25,1,1,233.44,233.84,200,400,1,2,233.43,233.9,29,26,1,1,233.4,233.94,110,200,2,1,233.39,233.98,10,44,1,3,233.31,234.0,110,154,2,7,233.3,234.13,100,400,1,1,233.25,234.17,55,1,2,1,233.24,234.41,1,600,1,2,AAPL,-1847,-7.274700410625996,0.09390439003500636
2024-10-21T12:00:07.337675975Z,2024-10-21T12:00:07.337509459Z,10,2,38,A,B,2,233.44,200,130,166516,11649571,233.53,233.78,10,150,1,2,233.45,233.8,15,25,1,1,233.44,233.84,400,400,2,2,233.43,233.9,29,26,1,1,233.4,233.94,110,200,2,1,233.39,233.98,10,44,1,3,233.31,234.0,110,154,2,7,233.3,234.13,100,400,1,1,233.25,234.17,55,1,2,1,233.24,234.41,1,600,1,2,AAPL,-1847,-7.246985735889156,0.0935466392715
2024-10-21T12:00:07.338280058Z,2024-10-21T12:00:07.338114020Z,10,2,38,C,B,2,233.44,200,130,166038,11649572,233.53,233.78,10,150,1,2,233.45,233.8,15,25,1,1,233.44,233.84,200,400,1,2,233.43,233.9,29,26,1,1,233.4,233.94,110,200,2,1,233.39,233.98,10,44,1,3,233.31,234.0,110,154,2,7,233.3,234.13,100,400,1,1,233.25,234.17,55,1,2,1,233.24,234.41,1,600,1,2,AAPL,-1847,-7.2205999680868045,0.09320604250582894
2024-10-21T12:00:07.646887094Z,2024-10-21T12:00:07.646720038Z,10,2,38,T,N,0,233.66,38,130,167056,11649813,233.53,233.78,10,150,1,2,233.45,233.8,15,25,1,1,233.44,233.84,200,400,1,2,233.43,233.9,29,26,1,1,233.4,233.94,110,200,2,1,233.39,233.98,10,44,1,3,233.31,234.0,110,154,2,7,233.3,234.13,100,400,1,1,233.25,234.17,55,1,2,1,233.24,234.41,1,600,1,2,AAPL,-1847,-7.195449764307141,0.09288139483487665
2024-10-21T12:00:07.956336345Z,2024-10-21T12:00:07.956169614Z,10,2,38,A,B,2,233.44,200,130,166731,11650434,233.53,233.78,10,150,1,2,233.45,233.8,15,25,1,1,233.44,233.84,400,400,2,2,233.43,233.9,29,26,1,1,233.4,233.94,110,200,2,1,233.39,233.98,10,44,1,3,233.31,234.0,110,154,2,7,233.3,234.13,100,400,1,1,233.25,234.17,55,1,2,1,233.24,234.41,1,600,1,2,AAPL,-1847,-7.171450323563,0.09257160161769235
2024-10-21T12:00:07.966018430Z,2024-10-21T12:00:07.965852395Z,10,2,38,C,A,2,233.84,200,130,166035,11650499,233.53,233.78,10,150,1,2,233.45,233.8,15,25,1,1,233.44,233.84,400,200,2,1,233.43,233.9,29,26,1,1,233.4,233.94,110,200,2,1,233.39,233.98,10,44,1,3,233.31,234.0,110,154,2,7,233.3,234.13,100,400,1,1,233.25,234.17,55,1,2,1,233.24,234.41,1,600,1,2,AAPL,-1847,-7.1485244315433,0.09227566614480694
2024-10-21T12:00:07.966030960Z,2024-10-21T12:00:07.965864571Z,10,2,38,A,A,2,233.83,400,130,166389,11650500,233.53,233.78,10,150,1,2,233.45,233.8,15,25,1,1,233.44,233.83,400,400,2,1,233.43,233.9,29,26,1,1,233.4,233.94,110,200,2,1,233.39,233.98,10,44,1,3,233.31,234.0,110,154,2,7,233.3,234.13,100,400,1,1,233.25,234.17,55,1,2,1,233.24,234.41,1,600,1,2,AAPL,-1847,-7.126601630751311,0.09199267892608604
2024-10-21T12:00:08.010300330Z,2024-10-21T12:00:08.010134216Z,10,2,38,C,B,2,233.44,200,130,166114,11650572,233.53,233.78,10,150,1,2,233.45,233.8,15,25,1,1,233.44,233.83,200,400,1,1,233.43,233.9,29,26,1,1,233.4,233.94,110,200,2,1,233.39,233.98,10,44,1,3,233.31,234.0,110,154,2,7,233.3,234.13,100,400,1,1,233.25,234.17,55,1,2,1,233.24,234.41,1,600,1,2,AAPL,-1847,-7.105617497239341,0.0917218083545672
2024-10-21T12:00:08.010312267Z,2024-10-21T12:00:08.010145977Z,10,2,38,A,B,1,233.45,200,130,166290,11650573,233.53,233.78,10,150,1,2,233.45,233.8,215,25,2,1,233.43,233.83,29,400,1,1,233.4,233.9,110,26,2,1,233.39,233.94,10,200,1,1,233.31,233.98,110,44,2,3,233.3,234.0,100,154,1,7,233.25,234.13,55,400,2,1,233.24,234.17,1,1,1,1,233.23,234.41,50,600,1,2,AAPL,-1897,-7.264909654284023,0.0937780075105891
2024-10-21T12:00:08.944880282Z,2024-10-21T12:00:08.944714285Z,10,2,38,C,A,3,233.9,26,130,165997,11651577,233.53,233.78,10,150,1,2,233.45,233.8,215,25,2,1,233.43,233.83,29,400,1,1,233.4,233.94,110,200,2,1,233.39,233.98,10,44,1,3,233.31,234.0,110,154,2,7,233.3,234.13,100,400,1,1,233.25,234.17,55,1,2,1,233.24,234.41,1,600,1,2,233.23,234.43,50,5,1,1,AAPL,-1892,-7.3634025992077285,0.09504938906498304
2024-10-21T12:00:08.944922066Z,2024-10-21T12:00:08.944755705Z,10,2,38,A,A,3,233.89,27,130,166361,11651579,233.53,233.78,10,150,1,2,233.45,233.8,215,25,2,1,233.43,233.83,29,400,1,1,233.4,233.89,110,27,2,1,233.39,233.94,10,200,1,1,233.31,233.98,110,44,2,3,233.3,234.0,100,154,1,7,233.25,234.13,55,400,2,1,233.24,234.17,1,1,1,1,233.23,234.41,50,600,1,2,AAPL,-2492,-9.653663177925784,0.12461287766605289
2024-10-21T12:00:11.760167332Z,2024-10-21T12:00:11.760000282Z,10,2,38,A,B,1,233.46,200,130,167050,11654094,233.53,233.78,10,150,1,2,233.46,233.8,200,25,1,1,233.45,233.83,15,400,1,1,233.43,233.89,29,27,1,1,233.4,233.94,110,200,2,1,233.39,233.98,10,44,1,3,233.31,234.0,110,154,2,7,233.3,234.13,100,400,1,1,233.25,234.17,55,1,2,1,233.24,234.41,1,600,1,2,AAPL,-2491,-9.62256485397449,0.12421144956909762
2024-10-21T12:00:14.055899330Z,2024-10-21T12:00:14.055732875Z,10,2,38,C,B,1,233.46,200,130,166455,11656987,233.53,233.78,10,150,1,2,233.45,233.8,15,25,1,1,233.43,233.83,29,400,1,1,233.4,233.89,110,27,2,1,233.39,233.94,10,200,1,1,233.31,233.98,110,44,2,3,233.3,234.0,100,154,1,7,233.25,234.13,55,400,2,1,233.24,234.17,1,1,1,1,233.23,234.41,50,600,1,2,AAPL,-2541,-9.773395482251702,0.12615842433747157
2024-10-21T12:00:14.159146604Z,2024-10-21T12:00:14.158979266Z,10,2,38,A,B,1,233.45,200,130,167338,11657107,233.53,233.78,10,150,1,2,233.45,233.8,215,25,2,1,233.43,233.83,29,400,1,1,233.4,233.89,110,27,2,1,233.39,233.94,10,200,1,1,233.31,233.98,110,44,2,3,233.3,234.0,100,154,1,7,233.25,234.13,55,400,2,1,233.24,234.17,1,1,1,1,233.23,234.41,50,600,1,2,AAPL,-2541,-9.732835392128699,0.12563486043686034
2024-10-21T12:00:14.450699829Z,2024-10-21T12:00:14.450532708Z,10,2,38,T,N,0,233.65,38,130,167121,11657642,233.53,233.78,10,150,1,2,233.45,233.8,215,25,2,1,233.43,233.83,29,400,1,1,233.4,233.89,110,27,2,1,233.39,233.94,10,200,1,1,233.31,233.98,110,44,2,3,233.3,234.0,100,154,1,7,233.25,234.13,55,400,2,1,233.24,234.17,1,1,1,1,233.23,234.41,50,600,1,2,AAPL,-2541,-9.693924137715374,0.12513258028717292
2024-10-21T12:00:15.203870674Z,2024-10-21T12:00:15.203702787Z,10,2,38,T,N,0,233.66,38,130,167887,11658325,233.53,233.78,10,150,1,2,233.45,233.8,215,25,2,1,233.43,233.83,29,400,1,1,233.4,233.89,110,27,2,1,233.39,233.94,10,200,1,1,233.31,233.98,110,44,2,3,233.3,234.0,100,154,1,7,233.25,234.13,55,400,2,1,233.24,234.17,1,1,1,1,233.23,234.41,50,600,1,2,AAPL,-2541,-9.656563179993258,0.12465031191212143
2024-10-21T12:00:15.820036179Z,2024-10-21T12:00:15.819869942Z,10,2,38,C,B,1,233.45,200,130,166237,11659423,233.53,233.78,10,150,1,2,233.45,233.8,15,25,1,1,233.43,233.83,29,400,1,1,233.4,233.89,110,27,2,1,233.39,233.94,10,200,1,1,233.31,233.98,110,44,2,3,233.3,234.0,100,154,1,7,233.25,234.13,55,400,2,1,233.24,234.17,1,1,1,1,233.23,234.41,50,600,1,2,AAPL,-2541,-9.620661678536015,0.12418688271155136
2024-10-21T12:00:15.820048842Z,2024-10-21T12:00:15.819882720Z,10,2,38,A,B,2,233.43,200,130,166122,11659424,233.53,233.78,10,150,1,2,233.45,233.8,15,25,1,1,233.43,233.83,229,400,2,1,233.4,233.89,110,27,2,1,233.39,233.94,10,200,1,1,233.31,233.98,110,44,2,3,233.3,234.0,100,154,1,7,233.25,234.13,55,400,2,1,233.24,234.17,1,1,1,1,233.23,234.41,50,600,1,2,AAPL,-2541,-9.586135754074686,0.12374120994237447
2024-10-21T12:00:15.838721297Z,2024-10-21T12:00:15.838554673Z,10,2,38,A,A,2,233.82,400,130,166624,11659500,233.53,233.78,10,150,1,2,233.45,233.8,15,25,1,1,233.43,233.82,229,400,2,1,233.4,233.89,110,27,2,1,233.39,233.94,10,200,1,1,233.31,233.98,110,44,2,3,233.3,234.0,100,154,1,7,233.25,234.13,55,400,2,1,233.24,234.17,1,1,1,1,233.23,234.41,50,600,1,2,AAPL,-2541,-9.55290783423465,0.12331229227311172
2024-10-21T12:00:15.866744266Z,2024-10-21T12:00:15.866578232Z,10,2,38,C,B,2,233.43,29,130,166034,11659636,233.53,233.78,10,150,1,2,233.45,233.8,15,25,1,1,233.43,233.82,200,400,1,1,233.4,233.89,110,27,2,1,233.39,233.94,10,200,1,1,233.31,233.98,110,44,2,3,233.3,234.0,100,154,1,7,233.25,234.13,55,400,2,1,233.24,234.17,1,1,1,1,233.23,234.41,50,600,1,2,AAPL,-2541,-9.52090607170229,0.12289920227338377
2024-10-21T12:00:15.866800115Z,2024-10-21T12:00:15.866633819Z,10,2,38,A,B,3,233.41,26,130,166296,11659637,233.53,233.78,10,150,1,2,233.45,233.8,15,25,1,1,233.43,233.82,200,400,1,1,233.41,233.89,26,27,1,1,233.4,233.94,110,200,2,1,233.39,233.98,10,44,1,3,233.31,234.0,110,154,2,7,233.3,234.13,100,400,1,1,233.25,234.17,55,1,2,1,233.24,234.41,1,600,1,2,AAPL,-2540,-9.499302260675412,0.12262033268667923
2024-10-21T12:00:15.951337950Z,2024-10-21T12:00:15.951171652Z,10,2,38,C,A,3,233.89,27,130,166298,11659913,233.53,233.78,10,150,1,2,233.45,233.8,15,25,1,1,233.43,233.82,200,400,1,1,233.41,233.94,26,200,1,1,233.4,233.98,110,44,2,3,233.39,234.0,10,154,1,7,233.31,234.13,110,400,2,1,233.3,234.17,100,1,1,1,233.25,234.41,55,600,2,2,233.24,234.43,1,5,1,1,AAPL,-2535,-9.620493358633777,0.12418470997908702
2024-10-21T12:00:15.951417682Z,2024-10-21T12:00:15.951251227Z,10,2,38,A,A,3,233.88,27,130,166455,11659915,233.53,233.78,10,150,1,2,233.45,233.8,15,25,1,1,233.43,233.82,200,400,1,1,233.41,233.88,26,27,1,1,233.4,233.94,110,200,2,1,233.39,233.98,10,44,1,3,233.31,234.0,110,154,2,7,233.3,234.13,100,400,1,1,233.25,234.17,55,1,2,1,233.24,234.41,1,600,1,2,AAPL,-3135,-11.873370475066553,0.15326563970829346
2024-10-21T12:00:16.054885768Z,2024-10-21T12:00:16.054719712Z,10,2,38,C,B,2,233.43,200,130,166056,11660064,233.53,233.78,10,150,1,2,233.45,233.8,15,25,1,1,233.41,233.82,26,400,1,1,233.4,233.88,110,27,2,1,233.39,233.94,10,200,1,1,233.31,233.98,110,44,2,3,233.3,234.0,100,154,1,7,233.25,234.13,55,400,2,1,233.24,234.17,1,1,1,1,233.23,234.41,50,600,1,2,AAPL,-3185,-12.02308086391458,0.15519815403233939
2024-10-21T12:00:16.158164700Z,2024-10-21T12:00:16.157998016Z,10,2,38,A,B,2,233.43,200,130,166684,11660229,233.53,233.78,10,150,1,2,233.45,233.8,15,25,1,1,233.43,233.82,200,400,1,1,233.41,233.88,26,27,1,1,233.4,233.94,110,200,2,1,233.39,233.98,10,44,1,3,233.31,234.0,110,154,2,7,233.3,234.13,100,400,1,1,233.25,234.17,55,1,2,1,233.24,234.41,1,600,1,2,AAPL,-3238,-12.265151515151516,0.15832288708891695
2024-10-21T12:00:16.339082802Z,2024-10-21T12:00:16.338916301Z,10,2,38,A,B,2,233.43,200,130,166501,11660347,233.53,233.78,10,150,1,2,233.45,233.8,15,25,1,1,233.43,233.82,400,400,2,1,233.41,233.88,26,27,1,1,233.4,233.94,110,200,2,1,233.39,233.98,10,44,1,3,233.31,234.0,110,154,2,7,233.3,234.13,100,400,1,1,233.25,234.17,55,1,2,1,233.24,234.41,1,600,1,2,AAPL,-2643,-9.897241037502065,0.12775706629767447
2024-10-21T12:00:16.393721035Z,2024-10-21T12:00:16.393554950Z,10,2,38,C,B,2,233.43,200,130,166085,11660378,233.53,233.78,10,150,1,2,233.45,233.8,15,25,1,1,233.43,233.82,200,400,1,1,233.41,233.88,26,27,1,1,233.4,233.94,110,200,2,1,233.39,233.98,10,44,1,3,233.31,234.0,110,154,2,7,233.3,234.13,100,400,1,1,233.25,234.17,55,1,2,1,233.24,234.41,1,600,1,2,AAPL,-2048,-7.604602098511913,0.09816287698619346
2024-10-21T12:00:16.393733214Z,2024-10-21T12:00:16.393566799Z,10,2,38,A,B,2,233.44,200,130,166415,11660379,233.53,233.78,10,150,1,2,233.45,233.8,15,25,1,1,233.44,233.82,200,400,1,1,233.41,233.88,26,27,1,1,233.4,233.94,110,200,2,1,233.39,233.98,10,44,1,3,233.31,234.0,110,154,2,7,233.3,234.13,100,400,1,1,233.25,234.17,55,1,2,1,233.24,234.41,1,600,1,2,AAPL,-2048,-7.591479944674965,0.09799349161188935
2024-10-21T12:00:30.258048610Z,2024-10-21T12:00:30.257881806Z,10,2,38,A,B,1,233.45,200,130,166804,11677039,233.53,233.78,10,150,1,2,233.45,233.8,215,25,2,1,233.41,233.82,26,400,1,1,233.4,233.88,110,27,2,1,233.39,233.94,10,200,1,1,233.31,233.98,110,44,2,3,233.3,234.0,100,154,1,7,233.25,234.13,55,400,2,1,233.24,234.17,1,1,1,1,233.23,234.41,50,600,1,2,AAPL,-742,-2.4934192103052366,0.03218593163001915
2024-10-21T12:00:31.950037293Z,2024-10-21T12:00:31.949871042Z,10,2,38,C,B,1,233.45,200,130,166251,11678778,233.53,233.78,10,150,1,2,233.45,233.8,15,25,1,1,233.41,233.82,26,400,1,1,233.4,233.88,110,27,2,1,233.39,233.94,10,200,1,1,233.31,233.98,110,44,2,3,233.3,234.0,100,154,1,7,233.25,234.13,55,400,2,1,233.24,234.17,1,1,1,1,233.23,234.41,50,600,1,2,AAPL,-743,-2.485411633525367,0.032082567014196095
2024-10-21T12:00:31.950049605Z,2024-10-21T12:00:31.949883226Z,10,2,38,A,B,2,233.44,200,130,166379,11678779,233.53,233.78,10,150,1,2,233.45,233.8,15,25,1,1,233.44,233.82,200,400,1,1,233.41,233.88,26,27,1,1,233.4,233.94,110,200,2,1,233.39,233.98,10,44,1,3,233.31,234.0,110,154,2,7,233.3,234.13,100,400,1,1,233.25,234.17,55,1,2,1,233.24,234.41,1,600,1,2,AAPL,-742,-2.4813869576696295,0.032030615083533824
2024-10-21T12:00:34.385936218Z,2024-10-21T12:00:34.385769828Z,10,2,38,A,B,1,233.45,200,130,166390,11681405,233.53,233.78,10,150,1,2,233.45,233.8,215,25,2,1,233.41,233.82,26,400,1,1,233.4,233.88,110,27,2,1,233.39,233.94,10,200,1,1,233.31,233.98,110,44,2,3,233.3,234.0,100,154,1,7,233.25,234.13,55,400,2,1,233.24,234.17,1,1,1,1,233.23,234.41,50,600,1,2,AAPL,-742,-2.4934192103052366,0.03218593163001915
2024-10-21T12:00:34.428154041Z,2024-10-21T12:00:34.427987983Z,10,2,38,C,B,2,233.41,26,130,166058,11681603,233.53,233.78,10,150,1,2,233.45,233.8,215,25,2,1,233.4,233.82,110,400,2,1,233.39,233.88,10,27,1,1,233.31,233.94,110,200,2,1,233.3,233.98,100,44,1,3,233.25,234.0,55,154,2,7,233.24,234.13,1,400,1,1,233.23,234.17,50,1,1,1,233.2,234.41,50,600,3,2,AAPL,-792,-2.648596321393998,0.034189012326359555
2024-10-21T12:00:34.428230329Z,2024-10-21T12:00:34.428063663Z,10,2,38,A,B,2,233.42,28,130,166666,11681604,233.53,233.78,10,150,1,2,233.45,233.8,215,25,2,1,233.42,233.82,28,400,1,1,233.4,233.88,110,27,2,1,233.39,233.94,10,200,1,1,233.31,233.98,110,44,2,3,233.3,234.0,100,154,1,7,233.25,234.13,55,400,2,1,233.24,234.17,1,1,1,1,233.23,234.41,50,600,1,2,AAPL,-742,-2.4706567884791477,0.031892106287854376
2024-10-21T12:00:35.519955046Z,2024-10-21T12:00:35.519789038Z,10,2,38,C,B,1,233.45,200,130,166008,11682997,233.53,233.78,10,150,1,2,233.45,233.8,15,25,1,1,233.42,233.82,28,400,1,1,233.4,233.88,110,27,2,1,233.39,233.94,10,200,1,1,233.31,233.98,110,44,2,3,233.3,234.0,100,154,1,7,233.25,234.13,55,400,2,1,233.24,234.17,1,1,1,1,233.23,234.41,50,600,1,2,AAPL,-742,-2.4813869576696295,0.032030615083533824
2024-10-21T12:00:35.519967135Z,2024-10-21T12:00:35.519800735Z,10,2,38,A,B,2,233.44,200,130,166400,11682998,233.53,233.78,10,150,1,2,233.45,233.8,15,25,1,1,233.44,233.82,200,400,1,1,233.42,233.88,28,27,1,1,233.4,233.94,110,200,2,1,233.39,233.98,10,44,1,3,233.31,234.0,110,154,2,7,233.3,234.13,100,400,1,1,233.25,234.17,55,1,2,1,233.24,234.41,1,600,1,2,AAPL,-741,-2.477432296890672,0.031979566932093674
2024-10-21T12:00:40.233309644Z,2024-10-21T12:00:40.233143021Z,10,2,38,A,A,2,233.81,400,130,166623,11688061,233.53,233.78,10,150,1,2,233.45,233.8,15,25,1,1,233.44,233.81,200,400,1,1,233.42,233.88,28,27,1,1,233.4,233.94,110,200,2,1,233.39,233.98,10,44,1,3,233.31,234.0,110,154,2,7,233.3,234.13,100,400,1,1,233.25,234.17,55,1,2,1,233.24,234.41,1,600,1,2,AAPL,-98,-0.30931088900578646,0.003992693681357323
2024-10-21T12:00:40.246205478Z,2024-10-21T12:00:40.246039339Z,10,2,38,C,B,2,233.44,200,130,166139,11688185,233.53,233.78,10,150,1,2,233.45,233.8,15,25,1,1,233.42,233.81,28,400,1,1,233.4,233.88,110,27,2,1,233.39,233.94,10,200,1,1,233.31,233.98,110,44,2,3,233.3,234.0,100,154,1,7,233.25,234.13,55,400,2,1,233.24,234.17,1,1,1,1,233.23,234.41,50,600,1,2,AAPL,-148,-0.4659216118369275,0.0060142799419981565
2024-10-21T12:00:40.246217496Z,2024-10-21T12:00:40.246051577Z,10,2,38,A,B,2,233.42,200,130,165919,11688186,233.53,233.78,10,150,1,2,233.45,233.8,15,25,1,1,233.42,233.81,228,400,2,1,233.4,233.88,110,27,2,1,233.39,233.94,10,200,1,1,233.31,233.98,110,44,2,3,233.3,234.0,100,154,1,7,233.25,234.13,55,400,2,1,233.24,234.17,1,1,1,1,233.23,234.41,50,600,1,2,AAPL,-148,-0.4649435956018849,0.006001655364653108
2024-10-21T12:00:40.301271156Z,2024-10-21T12:00:40.301104866Z,10,2,38,A,A,1,233.8,400,130,166290,11688350,233.53,233.78,10,150,1,2,233.45,233.8,15,425,1,2,233.42,233.88,228,27,2,1,233.4,233.94,110,200,2,1,233.39,233.98,10,44,1,3,233.31,234.0,110,154,2,7,233.3,234.13,100,400,1,1,233.25,234.17,55,1,2,1,233.24,234.41,1,600,1,2,233.23,234.43,50,5,1,1,AAPL,-143,-0.4862567299518277,0.0062767727946358085
2024-10-21T12:00:40.317691287Z,2024-10-21T12:00:40.317525489Z,10,2,38,C,B,2,233.42,28,130,165798,11688460,233.53,233.78,10,150,1,2,233.45,233.8,15,425,1,2,233.42,233.88,200,27,1,1,233.4,233.94,110,200,2,1,233.39,233.98,10,44,1,3,233.31,234.0,110,154,2,7,233.3,234.13,100,400,1,1,233.25,234.17,55,1,2,1,233.24,234.41,1,600,1,2,233.23,234.43,50,5,1,1,AAPL,-143,-0.5227049065092084,0.006747258669560592
2024-10-21T12:00:40.317745864Z,2024-10-21T12:00:40.317579213Z,10,2,38,A,B,3,233.4,29,130,166651,11688461,233.53,233.78,10,150,1,2,233.45,233.8,15,425,1,2,233.42,233.88,200,27,1,1,233.4,233.94,139,200,3,1,233.39,233.98,10,44,1,3,233.31,234.0,110,154,2,7,233.3,234.13,100,400,1,1,233.25,234.17,55,1,2,1,233.24,234.41,1,600,1,2,233.23,234.43,50,5,1,1,AAPL,-143,-0.55859375,0.007210524476650315
2024-10-21T12:00:40.436920479Z,2024-10-21T12:00:40.436754233Z,10,2,38,C,A,2,233.88,27,130,166246,11688670,233.53,233.78,10,150,1,2,233.45,233.8,15,425,1,2,233.42,233.94,200,200,1,1,233.4,233.98,139,44,3,3,233.39,234.0,10,154,1,7,233.31,234.13,110,400,2,1,233.3,234.17,100,1,1,1,233.25,234.41,55,600,2,2,233.24,234.43,1,5,1,1,233.23,234.5,50,63,1,4,AAPL,-80,-0.3296250515039143,0.004254916031527555
2024-10-21T12:00:40.436959883Z,2024-10-21T12:00:40.436793684Z,10,2,38,A,A,2,233.87,30,130,166199,11688671,233.53,233.78,10,150,1,2,233.45,233.8,15,425,1,2,233.42,233.87,200,30,1,1,233.4,233.94,139,200,3,1,233.39,233.98,10,44,1,3,233.31,234.0,110,154,2,7,233.3,234.13,100,400,1,1,233.25,234.17,55,1,2,1,233.24,234.41,1,600,1,2,233.23,234.43,50,5,1,1,AAPL,-85,-0.3707742639040349,0.004786084529574574
2024-10-21T12:00:51.186722645Z,2024-10-21T12:00:51.186556234Z,10,2,38,A,B,0,233.58,500,130,166411,11699374,233.58,233.78,500,150,1,2,233.53,233.8,10,425,1,2,233.45,233.87,15,30,1,1,233.42,233.94,200,200,1,1,233.4,233.98,139,44,3,3,233.39,234.0,10,154,1,7,233.31,234.13,110,400,2,1,233.3,234.17,100,1,1,1,233.25,234.41,55,600,2,2,233.24,234.43,1,5,1,1,AAPL,-34,-0.1625821876867902,0.0020986680280310264
2024-10-21T12:00:51.249833598Z,2024-10-21T12:00:51.249667336Z,10,2,38,A,A,0,233.74,1,130,166262,11699412,233.58,233.74,500,1,1,1,233.53,233.78,10,150,1,2,233.45,233.8,15,425,1,2,233.42,233.87,200,30,1,1,233.4,233.94,139,200,3,1,233.39,233.98,10,44,1,3,233.31,234.0,110,154,2,7,233.3,234.13,100,400,1,1,233.25,234.17,55,1,2,1,233.24,234.41,1,600,1,2,AAPL,-634,-2.9557109557109555,0.038153355980186564
2024-10-21T12:00:51.987755445Z,2024-10-21T12:00:51.987589245Z,10,2,38,A,B,3,233.42,200,130,166200,11699997,233.58,233.74,500,1,1,1,233.53,233.78,10,150,1,2,233.45,233.8,15,425,1,2,233.42,233.87,400,30,2,1,233.4,233.94,139,200,3,1,233.39,233.98,10,44,1,3,233.31,234.0,110,154,2,7,233.3,234.13,100,400,1,1,233.25,234.17,55,1,2,1,233.24,234.41,1,600,1,2,AAPL,-635,-3.0588589492699083,0.039484826538663455
2024-10-21T12:00:51.987815133Z,2024-10-21T12:00:51.987648731Z,10,2,38,C,A,2,233.8,200,130,166402,11699998,233.58,233.74,500,1,1,1,233.53,233.78,10,150,1,2,233.45,233.8,15,225,1,2,233.42,233.87,400,30,2,1,233.4,233.94,139,200,3,1,233.39,233.98,10,44,1,3,233.31,234.0,110,154,2,7,233.3,234.13,100,400,1,1,233.25,234.17,55,1,2,1,233.24,234.41,1,600,1,2,AAPL,-635,-2.9803975704030923,0.03847201948024056
2024-10-21T12:00:51.988333005Z,2024-10-21T12:00:51.988166858Z,10,2,38,C,B,4,233.4,29,130,166147,11699999,233.58,233.74,500,1,1,1,233.53,233.78,10,150,1,2,233.45,233.8,15,225,1,2,233.42,233.87,400,30,2,1,233.4,233.94,110,200,2,1,233.39,233.98,10,44,1,3,233.31,234.0,110,154,2,7,233.3,234.13,100,400,1,1,233.25,234.17,55,1,2,1,233.24,234.41,1,600,1,2,AAPL,-635,-2.91395793499044,0.03761439331209484
2024-10-21T12:00:51.988415192Z,2024-10-21T12:00:51.988248573Z,10,2,38,A,B,2,233.45,26,130,166619,11700000,233.58,233.74,500,1,1,1,233.53,233.78,10,150,1,2,233.45,233.8,41,225,2,2,233.42,233.87,400,30,2,1,233.4,233.94,110,200,2,1,233.39,233.98,10,44,1,3,233.31,234.0,110,154,2,7,233.3,234.13,100,400,1,1,233.25,234.17,55,1,2,1,233.24,234.41,1,600,1,2,AAPL,-635,-2.8569737153682215,0.03687882097465135
2024-10-21T12:00:52.042919153Z,2024-10-21T12:00:52.042752970Z,10,2,38,C,B,3,233.42,200,130,166183,11700053,233.58,233.74,500,1,1,1,233.53,233.78,10,150,1,2,233.45,233.8,41,225,2,2,233.42,233.87,200,30,1,1,233.4,233.94,110,200,2,1,233.39,233.98,10,44,1,3,233.31,234.0,110,154,2,7,233.3,234.13,100,400,1,1,233.25,234.17,55,1,2,1,233.24,234.41,1,600,1,2,AAPL,-635,-2.807560517298552,0.036240978044702846
2024-10-21T12:00:52.042931909Z,2024-10-21T12:00:52.042765437Z,10,2,38,A,B,2,233.49,200,130,166472,11700054,233.58,233.74,500,1,1,1,233.53,233.78,10,150,1,2,233.49,233.8,200,225,1,2,233.45,233.87,41,30,2,1,233.4,233.94,110,200,2,1,233.39,233.98,10,44,1,3,233.31,234.0,110,154,2,7,233.3,234.13,100,400,1,1,233.25,234.17,55,1,2,1,233.24,234.41,1,600,1,2,AAPL,-635,-2.7643034825870645,0.03568260103533872
2024-10-21T12:00:53.989490901Z,2024-10-21T12:00:53.989325211Z,10,2,38,C,B,2,233.49,200,130,165690,11702543,233.58,233.74,500,1,1,1,233.53,233.78,10,150,1,2,233.45,233.8,41,225,2,2,233.4,233.87,110,30,2,1,233.39,233.94,10,200,1,1,233.31,233.98,110,44,2,3,233.3,234.0,100,154,1,7,233.25,234.13,55,400,2,1,233.24,234.17,1,1,1,1,233.23,234.41,50,600,1,2,AAPL,-685,-2.9267818993979415,0.037779929552426886
2024-10-21T12:00:53.989503201Z,2024-10-21T12:00:53.989336874Z,10,2,38,A,B,2,233.47,400,130,166327,11702544,233.58,233.74,500,1,1,1,233.53,233.78,10,150,1,2,233.47,233.8,400,225,1,2,233.45,233.87,41,30,2,1,233.4,233.94,110,200,2,1,233.39,233.98,10,44,1,3,233.31,234.0,110,154,2,7,233.3,234.13,100,400,1,1,233.25,234.17,55,1,2,1,233.24,234.41,1,600,1,2,AAPL,-684,-2.8868703550784476,0.03726473730901811
2024-10-21T12:00:53.998707417Z,2024-10-21T12:00:53.998541135Z,10,2,38,C,B,3,233.45,26,130,166282,11702633,233.58,233.74,500,1,1,1,233.53,233.78,10,150,1,2,233.47,233.8,400,225,1,2,233.45,233.87,15,30,1,1,233.4,233.94,110,200,2,1,233.39,233.98,10,44,1,3,233.31,234.0,110,154,2,7,233.3,234.13,100,400,1,1,233.25,234.17,55,1,2,1,233.24,234.41,1,600,1,2,AAPL,-684,-2.85495652173913,0.036852782330221996
2024-10-21T12:00:53.998760827Z,2024-10-21T12:00:53.998594585Z,10,2,38,A,B,5,233.39,27,130,166242,11702634,233.58,233.74,500,1,1,1,233.53,233.78,10,150,1,2,233.47,233.8,400,225,1,2,233.45,233.87,15,30,1,1,233.4,233.94,110,200,2,1,233.39,233.98,37,44,2,3,233.31,234.0,110,154,2,7,233.3,234.13,100,400,1,1,233.25,234.17,55,1,2,1,233.24,234.41,1,600,1,2,AAPL,-684,-2.8262127096934138,0.03648174710057993
2024-10-21T12:00:57.883166284Z,2024-10-21T12:00:57.883000000Z,10,2,38,C,B,5,233.39,27,130,166284,11706826,233.58,233.74,500,1,1,1,233.53,233.78,10,150,1,2,233.47,233.8,400,225,1,2,233.45,233.87,15,30,1,1,233.4,233.94,110,200,2,1,233.39,233.98,10,44,1,3,233.31,234.0,110,154,2,7,233.3,234.13,100,400,1,1,233.25,234.17,55,1,2,1,233.24,234.41,1,600,1,2,AAPL,-635,-2.807072939690559,0.03623468422155015
2024-10-21T12:00:57.883222977Z,2024-10-21T12:00:57.883056751Z,10,2,38,A,B,4,233.4,27,130,166226,11706827,233.58,233.74,500,1,1,1,233.53,233.78,10,150,1,2,233.47,233.8,400,225,1,2,233.45,233.87,15,30,1,1,233.4,233.94,137,200,3,1,233.39,233.98,10,44,1,3,233.31,234.0,110,154,2,7,233.3,234.13,100,400,1,1,233.25,234.17,55,1,2,1,233.24,234.41,1,600,1,2,AAPL,-635,-2.765788952682637,0.035701776005490925
2024-10-21T12:00:58.996787112Z,2024-10-21T12:00:58.996621223Z,10,2,38,C,B,2,233.47,400,130,165889,11707811,233.58,233.74,500,1,1,1,233.53,233.78,10,150,1,2,233.45,233.8,15,225,1,2,233.4,233.87,137,30,3,1,233.39,233.94,10,200,1,1,233.31,233.98,110,44,2,3,233.3,234.0,100,154,1,7,233.25,234.13,55,400,2,1,233.24,234.17,1,1,1,1,233.23,234.41,50,600,1,2,AAPL,-685,-2.9306175595238098,0.03782944160160697
2024-10-21T12:00:58.996799769Z,2024-10-21T12:00:58.996633732Z,10,2,38,A,B,2,233.45,400,130,166037,11707812,233.58,233.74,500,1,1,1,233.53,233.78,10,150,1,2,233.45,233.8,415,225,2,2,233.4,233.87,137,30,3,1,233.39,233.94,10,200,1,1,233.31,233.98,110,44,2,3,233.3,234.0,100,154,1,7,233.25,234.13,55,400,2,1,233.24,234.17,1,1,1,1,233.23,234.41,50,600,1,2,AAPL,-685,-2.88370461322575,0.03722387280039152
2024-10-21T12:01:00.317708313Z,2024-10-21T12:01:00.317542037Z,10,2,38,C,B,2,233.45,200,130,166276,11709726,233.58,233.74,500,1,1,1,233.53,233.78,10,150,1,2,233.45,233.8,215,225,2,2,233.4,233.87,137,30,3,1,233.39,233.94,10,200,1,1,233.31,233.98,110,44,2,3,233.3,234.0,100,154,1,7,233.25,234.13,55,400,2,1,233.24,234.17,1,1,1,1,233.23,234.41,50,600,1,2,AAPL,-640,-2.5495468578826808,0.032910447034414494
2024-10-21T12:01:01.594785033Z,2024-10-21T12:01:01.594618675Z,10,2,38,A,B,2,233.45,200,130,166358,11711154,233.58,233.74,500,1,1,1,233.53,233.78,10,150,1,2,233.45,233.8,415,225,3,2,233.4,233.87,137,30,3,1,233.39,233.94,10,200,1,1,233.31,233.98,110,44,2,3,233.3,234.0,100,154,1,7,233.25,234.13,55,400,2,1,233.24,234.17,1,1,1,1,233.23,234.41,50,600,1,2,AAPL,-698,-2.400458540313336,0.030985962625098465
2024-10-21T12:01:02.481581752Z,2024-10-21T12:01:02.481414409Z,10,2,38,C,B,2,233.45,200,130,167343,11712155,233.58,233.74,500,1,1,1,233.53,233.78,10,150,1,2,233.45,233.8,215,225,2,2,233.4,233.87,137,30,3,1,233.39,233.94,10,200,1,1,233.31,233.98,110,44,2,3,233.3,234.0,100,154,1,7,233.25,234.13,55,400,2,1,233.24,234.17,1,1,1,1,233.23,234.41,50,600,1,2,AAPL,-698,-2.3856808778557297,0.03079520736359
2024-10-21T12:01:02.481593552Z,2024-10-21T12:01:02.481427194Z,10,2,38,A,B,2,233.47,400,130,166358,11712156,233.58,233.74,500,1,1,1,233.53,233.78,10,150,1,2,233.47,233.8,400,225,1,2,233.45,233.87,15,30,1,1,233.4,233.94,137,200,3,1,233.39,233.98,10,44,1,3,233.31,234.0,110,154,2,7,233.3,234.13,100,400,1,1,233.25,234.17,55,1,2,1,233.24,234.41,1,600,1,2,AAPL,-697,-2.379042580424951,0.030709517886921278
2024-10-21T12:01:02.481603814Z,2024-10-21T12:01:02.481437815Z,10,2,38,C,A,2,233.8,200,130,165999,11712157,233.58,233.74,500,1,1,1,233.53,233.78,10,150,1,2,233.47,233.8,400,25,1,1,233.45,233.87,15,30,1,1,233.4,233.94,137,200,3,1,233.39,233.98,10,44,1,3,233.31,234.0,110,154,2,7,233.3,234.13,100,400,1,1,233.25,234.17,55,1,2,1,233.24,234.41,1,600,1,2,AAPL,-697,-2.376136363636364,0.03067200341904806
2024-10-21T12:01:02.481616073Z,2024-10-21T12:01:02.481449719Z,10,2,38,A,A,3,233.82,200,130,166354,11712158,233.58,233.74,500,1,1,1,233.53,233.78,10,150,1,2,233.47,233.8,400,25,1,1,233.45,233.82,15,200,1,1,233.4,233.87,137,30,3,1,233.39,233.94,10,200,1,1,233.31,233.98,110,44,2,3,233.3,234.0,100,154,1,7,233.25,234.13,55,400,2,1,233.24,234.17,1,1,1,1,AAPL,-698,-2.4924525239409188,0.03217345330262798
2024-10-21T12:01:02.537579110Z,2024-10-21T12:01:02.537411197Z,10,2,38,A,A,3,233.81,200,130,167913,11712262,233.58,233.74,500,1,1,1,233.53,233.78,10,150,1,2,233.47,233.8,400,25,1,1,233.45,233.81,15,200,1,1,233.4,233.87,137,30,3,1,233.39,233.94,10,200,1,1,233.31,233.98,110,44,2,3,233.3,234.0,100,154,1,7,233.25,234.13,55,400,2,1,233.24,234.17,1,1,1,1,AAPL,-698,-2.605322947095099,0.03363042439985758
2024-10-21T12:01:02.855371321Z,2024-10-21T12:01:02.855205010Z,10,2,38,A,B,2,233.48,400,130,166311,11713011,233.58,233.74,500,1,1,1,233.53,233.78,10,150,1,2,233.48,233.8,400,25,1,1,233.45,233.81,15,200,1,1,233.4,233.87,137,30,3,1,233.39,233.94,10,200,1,1,233.31,233.98,110,44,2,3,233.3,234.0,100,154,1,7,233.25,234.13,55,400,2,1,233.24,234.17,1,1,1,1,AAPL,-698,-2.718156741846503,0.035086922684788864
2024-10-21T12:01:04.580398859Z,2024-10-21T12:01:04.580232646Z,10,2,38,C,B,2,233.48,400,130,166213,11716647,233.58,233.74,500,1,1,1,233.53,233.78,10,150,1,2,233.45,233.8,15,25,1,1,233.4,233.81,137,200,3,1,233.39,233.87,10,30,1,1,233.31,233.94,110,200,2,1,233.3,233.98,100,44,1,3,233.25,234.0,55,154,2,7,233.24,234.13,1,400,1,1,233.23,234.17,50,1,1,1,AAPL,-748,-3.0217338611941504,0.03900560285191785
2024-10-21T12:01:04.580410426Z,2024-10-21T12:01:04.580244325Z,10,2,38,A,B,2,233.46,400,130,166101,11716648,233.58,233.74,500,1,1,1,233.53,233.78,10,150,1,2,233.46,233.8,400,25,1,1,233.45,233.81,15,200,1,1,233.4,233.87,137,30,3,1,233.39,233.94,10,200,1,1,233.31,233.98,110,44,2,3,233.3,234.0,100,154,1,7,233.25,234.13,55,400,2,1,233.24,234.17,1,1,1,1,AAPL,-747,-3.137894821875757,0.04050504936421044
2024-10-21T12:01:04.634868574Z,2024-10-21T12:01:04.634702173Z,10,2,38,A,A,2,233.79,200,130,166401,11716763,233.58,233.74,500,1,1,1,233.53,233.78,10,150,1,2,233.46,233.79,400,200,1,1,233.45,233.8,15,25,1,1,233.4,233.87,137,30,3,1,233.39,233.94,10,200,1,1,233.31,233.98,110,44,2,3,233.3,234.0,100,154,1,7,233.25,234.13,55,400,2,1,233.24,234.17,1,1,1,1,AAPL,-747,-3.258056699781924,0.042056141122402656
2024-10-21T12:01:04.659147866Z,2024-10-21T12:01:04.658981181Z,10,2,38,C,A,4,233.87,30,130,166685,11716996,233.58,233.74,500,1,1,1,233.53,233.78,10,150,1,2,233.46,233.79,400,200,1,1,233.45,233.8,15,25,1,1,233.4,233.94,137,200,3,1,233.39,233.98,10,44,1,3,233.31,234.0,110,154,2,7,233.3,234.13,100,400,1,1,233.25,234.17,55,1,2,1,233.24,234.41,1,600,1,2,AAPL,-147,-0.6341087659836696,0.008185298847299629
2024-10-21T12:01:04.659209598Z,2024-10-21T12:01:04.659042935Z,10,2,38,A,A,4,233.86,30,130,166663,11716998,233.58,233.74,500,1,1,1,233.53,233.78,10,150,1,2,233.46,233.79,400,200,1,1,233.45,233.8,15,25,1,1,233.4,233.86,137,30,3,1,233.39,233.94,10,200,1,1,233.31,233.98,110,44,2,3,233.3,234.0,100,154,1,7,233.25,234.13,55,400,2,1,233.24,234.17,1,1,1,1,AAPL,-148,-0.6611213801601972,0.008533987166311725
2024-10-21T12:01:04.741795770Z,2024-10-21T12:01:04.741629959Z,10,2,38,C,B,2,233.46,400,130,165811,11717393,233.58,233.74,500,1,1,1,233.53,233.78,10,150,1,2,233.45,233.79,15,200,1,1,233.4,233.8,137,25,3,1,233.39,233.86,10,30,1,1,233.31,233.94,110,200,2,1,233.3,233.98,100,44,1,3,233.25,234.0,55,154,2,7,233.24,234.13,1,400,1,1,233.23,234.17,50,1,1,1,AAPL,-198,-0.9113924050632911,0.01176457352869068
2024-10-21T12:01:04.741807815Z,2024-10-21T12:01:04.741641481Z,10,2,38,A,B,2,233.45,400,130,166334,11717394,233.58,233.74,500,1,1,1,233.53,233.78,10,150,1,2,233.45,233.79,415,200,2,1,233.4,233.8,137,25,3,1,233.39,233.86,10,30,1,1,233.31,233.94,110,200,2,1,233.3,233.98,100,44,1,3,233.25,234.0,55,154,2,7,233.24,234.13,1,400,1,1,233.23,234.17,50,1,1,1,AAPL,-198,-0.938101788170564,0.012109347634471886
2024-10-21T12:01:04.804593020Z,2024-10-21T12:01:04.804426665Z,10,2,38,A,A,1,233.78,200,130,166355,11717856,233.58,233.74,500,1,1,1,233.53,233.78,10,350,1,3,233.45,233.8,415,25,2,1,233.4,233.86,137,30,3,1,233.39,233.94,10,200,1,1,233.31,233.98,110,44,2,3,233.3,234.0,100,154,1,7,233.25,234.13,55,400,2,1,233.24,234.17,1,1,1,1,233.23,234.41,50,600,1,2,AAPL,402,1.8730343622597554,-0.024177785939568926
2024-10-21T12:01:04.819075580Z,2024-10-21T12:01:04.818909404Z,10,2,38,C,B,3,233.4,27,130,166176,11717981,233.58,233.74,500,1,1,1,233.53,233.78,10,350,1,3,233.45,233.8,415,25,2,1,233.4,233.86,110,30,2,1,233.39,233.94,10,200,1,1,233.31,233.98,110,44,2,3,233.3,234.0,100,154,1,7,233.25,234.13,55,400,2,1,233.24,234.17,1,1,1,1,233.23,234.41,50,600,1,2,AAPL,402,1.844293062699847,-0.023806783141976835
2024-10-21T12:01:04.819161084Z,2024-10-21T12:01:04.818994775Z,10,2,38,A,B,5,233.37,28,130,166309,11717982,233.58,233.74,500,1,1,1,233.53,233.78,10,350,1,3,233.45,233.8,415,25,2,1,233.4,233.86,110,30,2,1,233.39,233.94,10,200,1,1,233.37,233.98,28,44,1,3,233.31,234.0,110,154,2,7,233.3,234.13,100,400,1,1,233.25,234.17,55,1,2,1,233.24,234.41,1,600,1,2,AAPL,403,1.8285180489757789,-0.023603153719741282
2024-10-21T12:01:04.857173618Z,2024-10-21T12:01:04.857007035Z,10,2,38,A,B,2,233.5,400,130,166583,11718365,233.58,233.74,500,1,1,1,233.53,233.78,10,350,1,3,233.5,233.8,400,25,1,1,233.45,233.86,15,30,1,1,233.4,233.94,110,200,2,1,233.39,233.98,10,44,1,3,233.37,234.0,28,154,1,7,233.31,234.13,110,400,2,1,233.3,234.17,100,1,1,1,233.25,234.41,55,600,2,2,AAPL,458,2.0496100242935684,-0.02645708665332654
2024-10-21T12:01:05.923098824Z,2024-10-21T12:01:05.922932529Z,10,2,38,C,A,3,233.86,30,130,166295,11720081,233.58,233.74,500,1,1,1,233.53,233.78,10,350,1,3,233.5,233.8,400,25,1,1,233.45,233.94,15,200,1,1,233.4,233.98,110,44,2,3,233.39,234.0,10,154,1,7,233.37,234.13,28,400,1,1,233.31,234.17,110,1,2,1,233.3,234.41,100,600,1,2,233.25,234.43,55,5,2,1,AAPL,463,2.1230416507451277,-0.02740496789956177
2024-10-21T12:01:05.923132218Z,2024-10-21T12:01:05.922966254Z,10,2,38,C,B,6,233.37,28,130,165964,11720082,233.58,233.74,500,1,1,1,233.53,233.78,10,350,1,3,233.5,233.8,400,25,1,1,233.45,233.94,15,200,1,1,233.4,233.98,110,44,2,3,233.39,234.0,10,154,1,7,233.31,234.13,110,400,2,1,233.3,234.17,100,1,1,1,233.25,234.41,55,600,2,2,233.24,234.43,1,5,1,1,AAPL,462,2.1764705882352944,-0.02809464740552521
2024-10-21T12:01:05.923194726Z,2024-10-21T12:01:05.923028260Z,10,2,38,A,A,3,233.85,29,130,166466,11720083,233.58,233.74,500,1,1,1,233.53,233.78,10,350,1,3,233.5,233.8,400,25,1,1,233.45,233.85,15,29,1,1,233.4,233.94,110,200,2,1,233.39,233.98,10,44,1,3,233.31,234.0,110,154,2,7,233.3,234.13,100,400,1,1,233.25,234.17,55,1,2,1,233.24,234.41,1,600,1,2,AAPL,-138,-0.6430805076951377,0.008301109242973989
2024-10-21T12:01:05.923227216Z,2024-10-21T12:01:05.923061114Z,10,2,38,A,B,4,233.42,30,130,166102,11720084,233.58,233.74,500,1,1,1,233.53,233.78,10,350,1,3,233.5,233.8,400,25,1,1,233.45,233.85,15,29,1,1,233.42,233.94,30,200,1,1,233.4,233.98,110,44,2,3,233.39,234.0,10,154,1,7,233.31,234.13,110,400,2,1,233.3,234.17,100,1,1,1,233.25,234.41,55,600,2,2,AAPL,-83,-0.38163169063900027,0.0049262360103706
2024-10-21T12:01:06.781590289Z,2024-10-21T12:01:06.781424093Z,10,2,38,C,B,2,233.5,400,130,166196,11721177,233.58,233.74,500,1,1,1,233.53,233.78,10,350,1,3,233.45,233.8,15,25,1,1,233.42,233.85,30,29,1,1,233.4,233.94,110,200,2,1,233.39,233.98,10,44,1,3,233.31,234.0,110,154,2,7,233.3,234.13,100,400,1,1,233.25,234.17,55,1,2,1,233.24,234.41,1,600,1,2,AAPL,-84,-0.3825789923142613,0.0049384641133814935
2024-10-21T12:01:06.781603653Z,2024-10-21T12:01:06.781437182Z,10,2,38,A,B,2,233.46,200,130,166471,11721178,233.58,233.74,500,1,1,1,233.53,233.78,10,350,1,3,233.46,233.8,200,25,1,1,233.45,233.85,15,29,1,1,233.42,233.94,30,200,1,1,233.4,233.98,110,44,2,3,233.39,234.0,10,154,1,7,233.31,234.13,110,400,2,1,233.3,234.17,100,1,1,1,233.25,234.41,55,600,2,2,AAPL,-29,-0.1305159165751921,0.001684745328886822
2024-10-21T12:01:07.185378576Z,2024-10-21T12:01:07.185212354Z,10,2,38,C,B,2,233.46,200,130,166222,11721941,233.58,233.74,500,1,1,1,233.53,233.78,10,350,1,3,233.45,233.8,15,25,1,1,233.42,233.85,30,29,1,1,233.4,233.94,110,200,2,1,233.39,233.98,10,44,1,3,233.31,234.0,110,154,2,7,233.3,234.13,100,400,1,1,233.25,234.17,55,1,2,1,233.24,234.41,1,600,1,2,AAPL,-30,-0.13389299187078266,0.001728337803880226
2024-10-21T12:01:07.185391192Z,2024-10-21T12:01:07.185224829Z,10,2,38,A,B,2,233.45,400,130,166363,11721942,233.58,233.74,500,1,1,1,233.53,233.78,10,350,1,3,233.45,233.8,415,25,2,1,233.42,233.85,30,29,1,1,233.4,233.94,110,200,2,1,233.39,233.98,10,44,1,3,233.31,234.0,110,154,2,7,233.3,234.13,100,400,1,1,233.25,234.17,55,1,2,1,233.24,234.41,1,600,1,2,AAPL,-30,-0.1328390485016991,0.0017147331323997801
2024-10-21T12:01:07.565934131Z,2024-10-21T12:01:07.565767784Z,10,2,38,A,B,2,233.46,400,130,166347,11722744,233.58,233.74,500,1,1,1,233.53,233.78,10,350,1,3,233.46,233.8,400,25,1,1,233.45,233.85,15,29,1,1,233.42,233.94,30,200,1,1,233.4,233.98,110,44,2,3,233.39,234.0,10,154,1,7,233.31,234.13,110,400,2,1,233.3,234.17,100,1,1,1,233.25,234.41,55,600,2,2,AAPL,25,0.10957812422174627,-0.0014144729453316122
2024-10-21T12:01:07.595966036Z,2024-10-21T12:01:07.595799579Z,10,2,38,C,B,4,233.42,30,130,166457,11722855,233.58,233.74,500,1,1,1,233.53,233.78,10,350,1,3,233.46,233.8,400,25,1,1,233.45,233.85,15,29,1,1,233.4,233.94,110,200,2,1,233.39,233.98,10,44,1,3,233.31,234.0,110,154,2,7,233.3,234.13,100,400,1,1,233.25,234.17,55,1,2,1,233.24,234.41,1,600,1,2,AAPL,24,0.10445884514943418,-0.0013483914915851103
2024-10-21T12:01:07.596018631Z,2024-10-21T12:01:07.595852119Z,10,2,38,A,B,4,233.43,29,130,166512,11722856,233.58,233.74,500,1,1,1,233.53,233.78,10,350,1,3,233.46,233.8,400,25,1,1,233.45,233.85,15,29,1,1,233.43,233.94,29,200,1,1,233.4,233.98,110,44,2,3,233.39,234.0,10,154,1,7,233.31,234.13,110,400,2,1,233.3,234.17,100,1,1,1,233.25,234.41,55,600,2,2,AAPL,79,0.3406928233253645,-0.004397782720638464
2024-10-21T12:01:09.438007491Z,2024-10-21T12:01:09.437841151Z,10,2,38,A,B,0,233.59,1,130,166340,11724947,233.59,233.74,1,1,1,1,233.58,233.78,500,350,1,3,233.53,233.8,10,25,1,1,233.46,233.85,400,29,1,1,233.45,233.94,15,200,1,1,233.43,233.98,29,44,1,3,233.4,234.0,110,154,2,7,233.39,234.13,10,400,1,1,233.31,234.17,110,1,2,1,233.3,234.41,100,600,1,2,AAPL,179,0.7636726728089684,-0.009857755299693264
2024-10-21T12:01:11.781867916Z,2024-10-21T12:01:11.781701764Z,10,2,38,C,B,3,233.46,400,130,166152,11727281,233.59,233.74,1,1,1,1,233.58,233.78,500,350,1,3,233.53,233.8,10,25,1,1,233.45,233.85,15,29,1,1,233.43,233.94,29,200,1,1,233.4,233.98,110,44,2,3,233.39,234.0,10,154,1,7,233.31,234.13,110,400,2,1,233.3,234.17,100,1,1,1,233.25,234.41,55,600,2,2,AAPL,723,3.0123635704904665,-0.03888464784575776
2024-10-21T12:01:11.781879282Z,2024-10-21T12:01:11.781713240Z,10,2,38,A,B,3,233.45,400,130,166042,11727282,233.59,233.74,1,1,1,1,233.58,233.78,500,350,1,3,233.53,233.8,10,25,1,1,233.45,233.85,415,29,2,1,233.43,233.94,29,200,1,1,233.4,233.98,110,44,2,3,233.39,234.0,10,154,1,7,233.31,234.13,110,400,2,1,233.3,234.17,100,1,1,1,233.25,234.41,55,600,2,2,AAPL,723,2.989180154820549,-0.03858538816707303
2024-10-21T12:01:13.839145940Z,2024-10-21T12:01:13.838979517Z,10,2,38,C,B,4,233.43,29,130,166423,11728924,233.59,233.74,1,1,1,1,233.58,233.78,500,350,1,3,233.53,233.8,10,25,1,1,233.45,233.85,415,29,2,1,233.4,233.94,110,200,2,1,233.39,233.98,10,44,1,3,233.31,234.0,110,154,2,7,233.3,234.13,100,400,1,1,233.25,234.17,55,1,2,1,233.24,234.41,1,600,1,2,AAPL,722,3.073741827580964,-0.039676939963392735
2024-10-21T12:01:13.839237535Z,2024-10-21T12:01:13.839070933Z,10,2,38,A,B,4,233.44,28,130,166602,11728925,233.59,233.74,1,1,1,1,233.58,233.78,500,350,1,3,233.53,233.8,10,25,1,1,233.45,233.85,415,29,2,1,233.44,233.94,28,200,1,1,233.4,233.98,110,44,2,3,233.39,234.0,10,154,1,7,233.31,234.13,110,400,2,1,233.3,234.17,100,1,1,1,233.25,234.41,55,600,2,2,AAPL,777,3.27783773177671,-0.04231148163663471
2024-10-21T12:01:33.939462146Z,2024-10-21T12:01:33.939295458Z,10,2,38,A,B,3,233.5,400,130,166688,11745736,233.59,233.74,1,1,1,1,233.58,233.78,500,350,1,3,233.53,233.8,10,25,1,1,233.5,233.85,400,29,1,1,233.45,233.94,15,200,1,1,233.44,233.98,28,44,1,3,233.4,234.0,110,154,2,7,233.39,234.13,10,400,1,1,233.31,234.17,110,1,2,1,233.3,234.41,100,600,1,2,AAPL,100,0.2857142857142857,-0.003688100431613348
2024-10-21T12:01:35.963067057Z,2024-10-21T12:01:35.962900590Z,10,2,38,A,A,1,233.78,200,130,166467,11747687,233.59,233.74,1,1,1,1,233.58,233.78,500,550,1,4,233.53,233.8,10,25,1,1,233.5,233.85,400,29,1,1,233.45,233.94,15,200,1,1,233.44,233.98,28,44,1,3,233.4,234.0,110,154,2,7,233.39,234.13,10,400,1,1,233.31,234.17,110,1,2,1,233.3,234.41,100,600,1,2,AAPL,100,0.2857142857142857,-0.003688100431613348
2024-10-21T12:01:35.963634861Z,2024-10-21T12:01:35.963468384Z,10,2,38,A,A,2,233.8,28,130,166477,11747688,233.59,233.74,1,1,1,1,233.58,233.78,500,550,1,4,233.53,233.8,10,53,1,2,233.5,233.85,400,29,1,1,233.45,233.94,15,200,1,1,233.44,233.98,28,44,1,3,233.4,234.0,110,154,2,7,233.39,234.13,10,400,1,1,233.31,234.17,110,1,2,1,233.3,234.41,100,600,1,2,AAPL,100,0.2857142857142857,-0.003688100431613348
2024-10-21T12:01:35.963668351Z,2024-10-21T12:01:35.963501831Z,10,2,38,C,A,3,233.85,29,130,166520,11747689,233.59,233.74,1,1,1,1,233.58,233.78,500,550,1,4,233.53,233.8,10,53,1,2,233.5,233.94,400,200,1,1,233.45,233.98,15,44,1,3,233.44,234.0,28,154,1,7,233.4,234.13,110,400,2,1,233.39,234.17,10,1,1,1,233.31,234.41,110,600,2,2,233.3,234.43,100,5,1,1,AAPL,105,0.38095238095238093,-0.00491746724215113
2024-10-21T12:01:36.018160396Z,2024-10-21T12:01:36.017994443Z,10,2,38,C,A,1,233.78,200,130,165953,11747708,233.59,233.74,1,1,1,1,233.58,233.78,500,350,1,3,233.53,233.8,10,53,1,2,233.5,233.94,400,200,1,1,233.45,233.98,15,44,1,3,233.44,234.0,28,154,1,7,233.4,234.13,110,400,2,1,233.39,234.17,10,1,1,1,233.31,234.41,110,600,2,2,233.3,234.43,100,5,1,1,AAPL,105,0.45454545454545453,-0.005867432504839417
2024-10-21T12:01:36.018174483Z,2024-10-21T12:01:36.018008103Z,10,2,38,A,A,0,233.74,200,130,166380,11747709,233.59,233.74,1,201,1,2,233.58,233.78,500,150,1,2,233.53,233.8,10,53,1,2,233.5,233.94,400,200,1,1,233.45,233.98,15,44,1,3,233.44,234.0,28,154,1,7,233.4,234.13,110,400,2,1,233.39,234.17,10,1,1,1,233.31,234.41,110,600,2,2,233.3,234.43,100,5,1,1,AAPL,105,0.5217391304347826,-0.006734792092511331
2024-10-21T12:01:37.328539236Z,2024-10-21T12:01:37.328372588Z,10,2,38,A,A,2,233.79,28,130,166648,11748684,233.59,233.74,1,201,1,2,233.58,233.78,500,150,1,2,233.53,233.79,10,28,1,1,233.5,233.8,400,53,1,2,233.45,233.94,15,200,1,1,233.44,233.98,28,44,1,3,233.4,234.0,110,154,2,7,233.39,234.13,10,400,1,1,233.31,234.17,110,1,2,1,233.3,234.41,100,600,1,2,AAPL,-495,-2.2247191011235956,0.028717456169753373
2024-10-21T12:01:37.328615431Z,2024-10-21T12:01:37.328448858Z,10,2,38,A,A,0,233.73,200,130,166573,11748686,233.59,233.73,1,200,1,1,233.58,233.74,500,1,1,1,233.53,233.78,10,150,1,2,233.5,233.79,400,28,1,1,233.45,233.8,15,53,1,2,233.44,233.94,28,200,1,1,233.4,233.98,110,44,2,3,233.39,234.0,10,154,1,7,233.31,234.13,110,400,2,1,233.3,234.17,100,1,1,1,AAPL,-496,-2.4676616915422884,0.031853444523784934
2024-10-21T12:01:37.328648871Z,2024-10-21T12:01:37.328482738Z,10,2,38,C,A,4,233.8,28,130,166133,11748688,233.59,233.73,1,200,1,1,233.58,233.74,500,1,1,1,233.53,233.78,10,150,1,2,233.5,233.79,400,28,1,1,233.45,233.8,15,25,1,1,233.44,233.94,28,200,1,1,233.4,233.98,110,44,2,3,233.39,234.0,10,154,1,7,233.31,234.13,110,400,2,1,233.3,234.17,100,1,1,1,AAPL,-496,-2.6915887850467293,0.03474397415949771
2024-10-21T12:01:37.359390875Z,2024-10-21T12:01:37.359224760Z,10,2,38,C,B,5,233.44,28,130,166115,11748965,233.59,233.73,1,200,1,1,233.58,233.74,500,1,1,1,233.53,233.78,10,150,1,2,233.5,233.79,400,28,1,1,233.45,233.8,15,25,1,1,233.4,233.94,110,200,2,1,233.39,233.98,10,44,1,3,233.31,234.0,110,154,2,7,233.3,234.13,100,400,1,1,233.25,234.17,55,1,2,1,AAPL,-551,-3.2671212570412096,0.0421731496137939
2024-10-21T12:01:37.359504379Z,2024-10-21T12:01:37.359337685Z,10,2,38,A,B,5,233.42,29,130,166694,11748966,233.59,233.73,1,200,1,1,233.58,233.74,500,1,1,1,233.53,233.78,10,150,1,2,233.5,233.79,400,28,1,1,233.45,233.8,15,25,1,1,233.42,233.94,29,200,1,1,233.4,233.98,110,44,2,3,233.39,234.0,10,154,1,7,233.31,234.13,110,400,2,1,233.3,234.17,100,1,1,1,AAPL,-451,-2.8560736902705814,0.0368672031343226
2024-10-21T12:01:37.397118895Z,2024-10-21T12:01:37.396952090Z,10,2,38,A,B,3,233.51,200,130,166805,11749029,233.59,233.73,1,200,1,1,233.58,233.74,500,1,1,1,233.53,233.78,10,150,1,2,233.51,233.79,200,28,1,1,233.45,233.8,15,25,1,1,233.42,233.94,29,200,1,1,233.4,233.98,110,44,2,3,233.39,234.0,10,154,1,7,233.31,234.13,110,400,2,1,233.3,234.17,100,1,1,1,AAPL,-451,-3.0276923076923077,0.03908251657377344
2024-10-21T12:01:37.923172468Z,2024-10-21T12:01:37.923006207Z,10,2,38,C,A,3,233.79,28,130,166261,11749436,233.59,233.73,1,200,1,1,233.58,233.74,500,1,1,1,233.53,233.78,10,150,1,2,233.51,233.8,200,25,1,1,233.45,233.94,15,200,1,1,233.42,233.98,29,44,1,3,233.4,234.0,110,154,2,7,233.39,234.13,10,400,1,1,233.31,234.17,110,1,2,1,233.3,234.41,100,600,1,2,AAPL,149,0.9061988304093567,-0.011697533041460907
2024-10-21T12:01:37.923201552Z,2024-10-21T12:01:37.923035401Z,10,2,38,C,B,5,233.42,29,130,166151,11749437,233.59,233.73,1,200,1,1,233.58,233.74,500,1,1,1,233.53,233.78,10,150,1,2,233.51,233.8,200,25,1,1,233.45,233.94,15,200,1,1,233.4,233.98,110,44,2,3,233.39,234.0,10,154,1,7,233.31,234.13,110,400,2,1,233.3,234.17,100,1,1,1,233.25,234.41,55,600,2,2,AAPL,94,0.5338742393509127,-0.0068914363440207215
2024-10-21T12:01:37.923265552Z,2024-10-21T12:01:37.923099010Z,10,2,38,A,B,4,233.47,27,130,166542,11749438,233.59,233.73,1,200,1,1,233.58,233.74,500,1,1,1,233.53,233.78,10,150,1,2,233.51,233.8,200,25,1,1,233.47,233.94,27,200,1,1,233.45,233.98,15,44,1,3,233.4,234.0,110,154,2,7,233.39,234.13,10,400,1,1,233.31,234.17,110,1,2,1,233.3,234.41,100,600,1,2,AAPL,194,1.0337477797513321,-0.013343979714380798
2024-10-21T12:01:37.923308087Z,2024-10-21T12:01:37.923141688Z,10,2,38,A,A,2,233.78,28,130,166399,11749439,233.59,233.73,1,200,1,1,233.58,233.74,500,1,1,1,233.53,233.78,10,178,1,3,233.51,233.8,200,25,1,1,233.47,233.94,27,200,1,1,233.45,233.98,15,44,1,3,233.4,234.0,110,154,2,7,233.39,234.13,10,400,1,1,233.31,234.17,110,1,2,1,233.3,234.41,100,600,1,2,AAPL,194,0.9807266982622432,-0.012659564957044995
