ts_recv,ts_event,rtype,publisher_id,instrument_id,action,side,depth,price,size,flags,ts_in_delta,sequence,bid_px_00,ask_px_00,bid_sz_00,ask_sz_00,bid_ct_00,ask_ct_00,bid_px_01,ask_px_01,bid_sz_01,ask_sz_01,bid_ct_01,ask_ct_01,bid_px_02,ask_px_02,bid_sz_02,ask_sz_02,bid_ct_02,ask_ct_02,bid_px_03,ask_px_03,bid_sz_03,ask_sz_03,bid_ct_03,ask_ct_03,bid_px_04,ask_px_04,bid_sz_04,ask_sz_04,bid_ct_04,ask_ct_04,bid_px_05,ask_px_05,bid_sz_05,ask_sz_05,bid_ct_05,ask_ct_05,bid_px_06,ask_px_06,bid_sz_06,ask_sz_06,bid_ct_06,ask_ct_06,bid_px_07,ask_px_07,bid_sz_07,ask_sz_07,bid_ct_07,ask_ct_07,bid_px_08,ask_px_08,bid_sz_08,ask_sz_08,bid_ct_08,ask_ct_08,bid_px_09,ask_px_09,bid_sz_09,ask_sz_09,bid_ct_09,ask_ct_09,symbol,ofi_best_level,multi_level_ofi,integrated_ofi
2024-10-21T12:15:38.712982908Z,2024-10-21T12:15:38.712816410Z,10,2,38,C,A,0,234.1,200,130,166498,12503722,233.76,234.1,200,200,1,1,233.74,234.13,28,400,1,1,233.7,234.17,1200,31,1,2,233.66,234.41,1,600,1,2,233.58,234.43,505,105,2,2,233.53,234.5,10,63,1,4,233.5,234.75,100,1,1,1,233.45,234.79,15,2000,1,1,233.4,234.89,110,2,2,2,233.39,235.0,10,213,1,6,AAPL,-1257,-6.513865546218487,0.08408326616367902
2024-10-21T12:15:38.816780965Z,2024-10-21T12:15:38.816614723Z,10,2,38,A,A,0,234.1,200,130,166242,12504039,233.76,234.1,200,400,1,2,233.74,234.13,28,400,1,1,233.7,234.17,1200,31,1,2,233.66,234.41,1,600,1,2,233.58,234.43,505,105,2,2,233.53,234.5,10,63,1,4,233.5,234.75,100,1,1,1,233.45,234.79,15,2000,1,1,233.4,234.89,110,2,2,2,233.39,235.0,10,213,1,6,AAPL,-1257,-6.587050954974833,0.08502796914535629
2024-10-21T12:15:39.207247997Z,2024-10-21T12:15:39.207080252Z,10,2,38,A,A,0,234.0,22,130,167745,12504453,233.76,234.0,200,22,1,1,233.74,234.1,28,400,1,2,233.7,234.13,1200,400,1,1,233.66,234.17,1,31,1,2,233.58,234.41,505,600,2,2,233.53,234.43,10,105,1,2,233.5,234.5,100,63,1,4,233.45,234.75,15,1,1,1,233.4,234.79,110,2000,2,1,233.39,234.89,10,2,1,2,AAPL,-1259,-6.765552876334826,0.0873321346915969
2024-10-21T12:15:39.207269463Z,2024-10-21T12:15:39.207103673Z,10,2,38,C,B,0,233.76,200,130,165790,12504456,233.74,234.0,28,22,1,1,233.7,234.1,1200,400,1,2,233.66,234.13,1,400,1,1,233.58,234.17,505,31,2,2,233.53,234.41,10,600,1,2,233.5,234.43,100,105,1,2,233.45,234.5,15,63,1,4,233.4,234.75,110,1,2,1,233.39,234.79,10,2000,1,1,233.31,234.89,110,2,2,2,AAPL,-1369,-7.487523073767689,0.09665157978027132
2024-10-21T12:15:39.207333984Z,2024-10-21T12:15:39.207167970Z,10,2,38,C,A,1,234.1,200,130,166014,12504459,233.74,234.0,28,22,1,1,233.7,234.1,1200,200,1,1,233.66,234.13,1,400,1,1,233.58,234.17,505,31,2,2,233.53,234.41,10,600,1,2,233.5,234.43,100,105,1,2,233.45,234.5,15,63,1,4,233.4,234.75,110,1,2,1,233.39,234.79,10,2000,1,1,233.31,234.89,110,2,2,2,AAPL,-1369,-7.616391885473912,0.09831506370053458
2024-10-21T12:15:39.207408030Z,2024-10-21T12:15:39.207241805Z,10,2,38,C,A,1,234.1,200,130,166225,12504461,233.74,234.0,28,22,1,1,233.7,234.13,1200,400,1,1,233.66,234.17,1,31,1,2,233.58,234.41,505,600,2,2,233.53,234.43,10,105,1,2,233.5,234.5,100,63,1,4,233.45,234.75,15,1,1,1,233.4,234.79,110,2000,2,1,233.39,234.89,10,2,1,2,233.31,235.0,110,213,2,6,AAPL,-1156,-6.4469525959367955,0.08321953028082851
2024-10-21T12:15:39.207701481Z,2024-10-21T12:15:39.207535631Z,10,2,38,C,A,0,234.0,22,130,165850,12504467,233.74,234.13,28,400,1,1,233.7,234.17,1200,31,1,2,233.66,234.41,1,600,1,2,233.58,234.43,505,105,2,2,233.53,234.5,10,63,1,4,233.5,234.75,100,1,1,1,233.45,234.79,15,2000,1,1,233.4,234.89,110,2,2,2,233.39,235.0,10,213,1,6,233.31,235.03,110,2,2,1,AAPL,-1154,-6.540398049294846,0.08442575703984598
2024-10-21T12:15:39.274873761Z,2024-10-21T12:15:39.274707573Z,10,2,38,C,B,0,233.74,28,130,166188,12504518,233.7,234.13,1200,400,1,1,233.66,234.17,1,31,1,2,233.58,234.41,505,600,2,2,233.53,234.43,10,105,1,2,233.5,234.5,100,63,1,4,233.45,234.75,15,1,1,1,233.4,234.79,110,2000,2,1,233.39,234.89,10,2,1,2,233.31,235.0,110,213,2,6,233.3,235.03,100,2,1,1,AAPL,-1254,-7.223880597014925,0.09324839001720912
2024-10-21T12:15:39.274960881Z,2024-10-21T12:15:39.274794258Z,10,2,38,A,B,1,233.69,28,130,166623,12504519,233.7,234.13,1200,400,1,1,233.69,234.17,28,31,1,2,233.66,234.41,1,600,1,2,233.58,234.43,505,105,2,2,233.53,234.5,10,63,1,4,233.5,234.75,100,1,1,1,233.45,234.79,15,2000,1,1,233.4,234.89,110,2,2,2,233.39,235.0,10,213,1,6,233.31,235.03,110,2,2,1,AAPL,-1144,-6.690927995840915,0.08636885050274148
2024-10-21T12:15:39.314289508Z,2024-10-21T12:15:39.314122970Z,10,2,38,A,B,0,233.76,200,130,166538,12504563,233.76,234.13,200,400,1,1,233.7,234.17,1200,31,1,2,233.69,234.41,28,600,1,2,233.66,234.43,1,105,1,2,233.58,234.5,505,63,2,4,233.53,234.75,10,1,1,1,233.5,234.79,100,2000,1,1,233.45,234.89,15,2,1,2,233.4,235.0,110,213,2,6,233.39,235.03,10,2,1,1,AAPL,-1134,-6.774545454545454,0.08744821405212667
2024-10-21T12:15:39.314303543Z,2024-10-21T12:15:39.314137186Z,10,2,38,A,A,0,234.1,400,130,166357,12504564,233.76,234.1,200,400,1,1,233.7,234.13,1200,400,1,1,233.69,234.17,28,31,1,2,233.66,234.41,1,600,1,2,233.58,234.43,505,105,2,2,233.53,234.5,10,63,1,4,233.5,234.75,100,1,1,1,233.45,234.79,15,2000,1,1,233.4,234.89,110,2,2,2,233.39,235.0,10,213,1,6,AAPL,-1347,-8.104589387441592,0.10461688866255303
2024-10-21T12:15:40.360705214Z,2024-10-21T12:15:40.360537773Z,10,2,38,C,A,0,234.1,400,130,167441,12505301,233.76,234.13,200,400,1,1,233.7,234.17,1200,31,1,2,233.69,234.41,28,600,1,2,233.66,234.43,1,105,1,2,233.58,234.5,505,63,2,4,233.53,234.75,10,1,1,1,233.5,234.79,100,2000,1,1,233.45,234.89,15,2,1,2,233.4,235.0,110,213,2,6,233.39,235.03,10,2,1,1,AAPL,-1345,-8.258394627438438,0.1066022607646117
2024-10-21T12:15:40.360715053Z,2024-10-21T12:15:40.360548894Z,10,2,38,A,A,1,234.15,400,130,166159,12505302,233.76,234.13,200,400,1,1,233.7,234.15,1200,400,1,1,233.69,234.17,28,31,1,2,233.66,234.41,1,600,1,2,233.58,234.43,505,105,2,2,233.53,234.5,10,63,1,4,233.5,234.75,100,1,1,1,233.45,234.79,15,2000,1,1,233.4,234.89,110,2,2,2,233.39,235.0,10,213,1,6,AAPL,-1558,-9.62820027746248,0.12428419359639195
2024-10-21T12:15:40.361263637Z,2024-10-21T12:15:40.361097351Z,10,2,38,C,A,2,234.17,30,130,166286,12505308,233.76,234.13,200,400,1,1,233.7,234.15,1200,400,1,1,233.69,234.17,28,1,1,1,233.66,234.41,1,600,1,2,233.58,234.43,505,105,2,2,233.53,234.5,10,63,1,4,233.5,234.75,100,1,1,1,233.45,234.79,15,2000,1,1,233.4,234.89,110,2,2,2,233.39,235.0,10,213,1,6,AAPL,-1558,-9.688452210683415,0.1250619467296038
2024-10-21T12:15:40.361312977Z,2024-10-21T12:15:40.361146693Z,10,2,38,A,A,3,234.22,27,130,166284,12505309,233.76,234.13,200,400,1,1,233.7,234.15,1200,400,1,1,233.69,234.17,28,1,1,1,233.66,234.22,1,27,1,1,233.58,234.41,505,600,2,2,233.53,234.43,10,105,1,2,233.5,234.5,100,63,1,4,233.45,234.75,15,1,1,1,233.4,234.79,110,2000,2,1,233.39,234.89,10,2,1,2,AAPL,-1560,-9.88752873920338,0.1276316965372588
2024-10-21T12:15:43.401012118Z,2024-10-21T12:15:43.400846263Z,10,2,38,C,B,0,233.76,200,130,165855,12511389,233.7,234.13,1200,400,1,1,233.69,234.15,28,400,1,1,233.66,234.17,1,1,1,1,233.58,234.22,505,27,2,1,233.53,234.41,10,600,1,2,233.5,234.43,100,105,1,2,233.45,234.5,15,63,1,4,233.4,234.75,110,1,2,1,233.39,234.79,10,2000,1,1,233.31,234.89,110,2,2,2,AAPL,-1670,-10.717679728478865,0.13834757731373787
2024-10-21T12:15:43.401025404Z,2024-10-21T12:15:43.400859035Z,10,2,38,A,B,0,233.74,200,130,166369,12511390,233.74,234.13,200,400,1,1,233.7,234.15,1200,400,1,1,233.69,234.17,28,1,1,1,233.66,234.22,1,27,1,1,233.58,234.41,505,600,2,2,233.53,234.43,10,105,1,2,233.5,234.5,100,63,1,4,233.45,234.75,15,1,1,1,233.4,234.79,110,2000,2,1,233.39,234.89,10,2,1,2,AAPL,-1660,-10.850342233458717,0.14006003156030072
2024-10-21T12:15:43.425571225Z,2024-10-21T12:15:43.425405296Z,10,2,38,C,A,3,234.22,27,130,165929,12511697,233.74,234.13,200,400,1,1,233.7,234.15,1200,400,1,1,233.69,234.17,28,1,1,1,233.66,234.41,1,600,1,2,233.58,234.43,505,105,2,2,233.53,234.5,10,63,1,4,233.5,234.75,100,1,1,1,233.45,234.79,15,2000,1,1,233.4,234.89,110,2,2,2,233.39,235.0,10,213,1,6,AAPL,-1447,-9.505839416058393,0.12270471658624248
2024-10-21T12:15:43.425623021Z,2024-10-21T12:15:43.425456541Z,10,2,38,A,A,3,234.21,26,130,166480,12511698,233.74,234.13,200,400,1,1,233.7,234.15,1200,400,1,1,233.69,234.17,28,1,1,1,233.66,234.21,1,26,1,1,233.58,234.41,505,600,2,2,233.53,234.43,10,105,1,2,233.5,234.5,100,63,1,4,233.45,234.75,15,1,1,1,233.4,234.79,110,2000,2,1,233.39,234.89,10,2,1,2,AAPL,-1449,-9.688183807439826,0.12505848208618894
2024-10-21T12:15:43.454501811Z,2024-10-21T12:15:43.454335483Z,10,2,38,A,A,1,234.14,400,130,166328,12511807,233.74,234.13,200,400,1,1,233.7,234.14,1200,400,1,1,233.69,234.17,28,1,1,1,233.66,234.21,1,26,1,1,233.58,234.41,505,600,2,2,233.53,234.43,10,105,1,2,233.5,234.5,100,63,1,4,233.45,234.75,15,1,1,1,233.4,234.79,110,2000,2,1,233.39,234.89,10,2,1,2,AAPL,-1449,-9.857142857142858,0.12723946489066051
2024-10-21T12:15:43.462491808Z,2024-10-21T12:15:43.462325554Z,10,2,38,A,A,0,234.13,400,130,166254,12511952,233.74,234.13,200,800,1,2,233.7,234.17,1200,1,1,1,233.69,234.21,28,26,1,1,233.66,234.41,1,600,1,2,233.58,234.43,505,105,2,2,233.53,234.5,10,63,1,4,233.5,234.75,100,1,1,1,233.45,234.79,15,2000,1,1,233.4,234.89,110,2,2,2,233.39,235.0,10,213,1,6,AAPL,-1236,-8.443938395157907,0.1089973249389444
2024-10-21T12:15:43.490633387Z,2024-10-21T12:15:43.490467184Z,10,2,38,A,B,3,233.66,30,130,166203,12512344,233.74,234.13,200,800,1,2,233.7,234.17,1200,1,1,1,233.69,234.21,28,26,1,1,233.66,234.41,31,600,2,2,233.58,234.43,505,105,2,2,233.53,234.5,10,63,1,4,233.5,234.75,100,1,1,1,233.45,234.79,15,2000,1,1,233.4,234.89,110,2,2,2,233.39,235.0,10,213,1,6,AAPL,-1236,-8.478769958604376,0.1094469430035768
2024-10-21T12:15:43.546265076Z,2024-10-21T12:15:43.546099003Z,10,2,38,C,B,2,233.69,28,130,166073,12512634,233.74,234.13,200,800,1,2,233.7,234.17,1200,1,1,1,233.66,234.21,31,26,2,1,233.58,234.41,505,600,2,2,233.53,234.43,10,105,1,2,233.5,234.5,100,63,1,4,233.45,234.75,15,1,1,1,233.4,234.79,110,2000,2,1,233.39,234.89,10,2,1,2,233.31,235.0,110,213,2,6,AAPL,-1346,-9.216503220565194,0.11896986327006306
2024-10-21T12:15:43.594979866Z,2024-10-21T12:15:43.594813115Z,10,2,38,A,A,0,234.12,200,130,166751,12512827,233.74,234.12,200,200,1,1,233.7,234.13,1200,400,1,1,233.66,234.17,31,1,2,1,233.58,234.21,505,26,2,1,233.53,234.41,10,600,1,2,233.5,234.43,100,105,1,2,233.45,234.5,15,63,1,4,233.4,234.75,110,1,2,1,233.39,234.79,10,2000,1,1,233.31,234.89,110,2,2,2,AAPL,-1348,-9.326030556356299,0.12038368062047929
2024-10-21T12:15:43.981450269Z,2024-10-21T12:15:43.981284269Z,10,2,38,A,A,3,234.19,28,130,166000,12513411,233.74,234.12,200,200,1,1,233.7,234.13,1200,400,1,1,233.66,234.17,31,1,2,1,233.58,234.19,505,28,2,1,233.53,234.21,10,26,1,1,233.5,234.41,100,600,1,2,233.45,234.43,15,105,1,2,233.4,234.5,110,63,2,4,233.39,234.75,10,1,1,1,233.31,234.79,110,2000,2,1,AAPL,-3348,-20.99491133384734,0.27100969543216225
2024-10-21T12:15:43.981745796Z,2024-10-21T12:15:43.981579878Z,10,2,38,C,A,4,234.21,26,130,165918,12513419,233.74,234.12,200,200,1,1,233.7,234.13,1200,400,1,1,233.66,234.17,31,1,2,1,233.58,234.19,505,28,2,1,233.53,234.41,10,600,1,2,233.5,234.43,100,105,1,2,233.45,234.5,15,63,1,4,233.4,234.75,110,1,2,1,233.39,234.79,10,2000,1,1,233.31,234.89,110,2,2,2,AAPL,-3346,-21.2042724996167,0.2737122029525919
2024-10-21T12:15:46.504609799Z,2024-10-21T12:15:46.504444030Z,10,2,38,C,B,0,233.74,200,130,165769,12517721,233.7,234.12,1200,200,1,1,233.66,234.13,31,400,2,1,233.58,234.17,505,1,2,1,233.53,234.19,10,28,1,1,233.5,234.41,100,600,1,2,233.45,234.43,15,105,1,2,233.4,234.5,110,63,2,4,233.39,234.75,10,1,1,1,233.31,234.79,110,2000,2,1,233.3,234.89,100,2,1,2,AAPL,-3859,-23.423368740515933,0.3023570772660739
2024-10-21T12:15:46.504623049Z,2024-10-21T12:15:46.504456348Z,10,2,38,A,B,0,233.73,200,130,166701,12517722,233.73,234.12,200,200,1,1,233.7,234.13,1200,400,1,1,233.66,234.17,31,1,2,1,233.58,234.19,505,28,2,1,233.53,234.41,10,600,1,2,233.5,234.43,100,105,1,2,233.45,234.5,15,63,1,4,233.4,234.75,110,1,2,1,233.39,234.79,10,2000,1,1,233.31,234.89,110,2,2,2,AAPL,-3749,-23.022301228183583,0.2971799568373873
2024-10-21T12:15:46.504635795Z,2024-10-21T12:15:46.504469490Z,10,2,38,A,A,0,234.12,200,130,166305,12517724,233.73,234.12,200,400,1,2,233.7,234.13,1200,400,1,1,233.66,234.17,31,1,2,1,233.58,234.19,505,28,2,1,233.53,234.41,10,600,1,2,233.5,234.43,100,105,1,2,233.45,234.5,15,63,1,4,233.4,234.75,110,1,2,1,233.39,234.79,10,2000,1,1,233.31,234.89,110,2,2,2,AAPL,-3749,-23.285714285714285,0.3005801851764879
2024-10-21T12:15:46.593857210Z,2024-10-21T12:15:46.593690522Z,10,2,38,A,A,3,234.18,30,130,166688,12518020,233.73,234.12,200,400,1,2,233.7,234.13,1200,400,1,1,233.66,234.17,31,1,2,1,233.58,234.18,505,30,2,1,233.53,234.19,10,28,1,1,233.5,234.41,100,600,1,2,233.45,234.43,15,105,1,2,233.4,234.5,110,63,2,4,233.39,234.75,10,1,1,1,233.31,234.79,110,2000,2,1,AAPL,-5749,-32.63648609641105,0.4212832346048082
2024-10-21T12:15:46.594225497Z,2024-10-21T12:15:46.594059334Z,10,2,38,C,A,4,234.19,28,130,166163,12518032,233.73,234.12,200,400,1,2,233.7,234.13,1200,400,1,1,233.66,234.17,31,1,2,1,233.58,234.18,505,30,2,1,233.53,234.41,10,600,1,2,233.5,234.43,100,105,1,2,233.45,234.5,15,63,1,4,233.4,234.75,110,1,2,1,233.39,234.79,10,2000,1,1,233.31,234.89,110,2,2,2,AAPL,-5747,-33.00028710881424,0.42597930595283773
2024-10-21T12:15:50.469902981Z,2024-10-21T12:15:50.469736889Z,10,2,38,C,A,0,234.12,200,130,166092,12522085,233.73,234.12,200,200,1,1,233.7,234.13,1200,400,1,1,233.66,234.17,31,1,2,1,233.58,234.18,505,30,2,1,233.53,234.41,10,600,1,2,233.5,234.43,100,105,1,2,233.45,234.5,15,63,1,4,233.4,234.75,110,1,2,1,233.39,234.79,10,2000,1,1,233.31,234.89,110,2,2,2,AAPL,-4077,-31.937331701346388,0.4122583039131
2024-10-21T12:15:55.593624526Z,2024-10-21T12:15:55.593458354Z,10,2,38,C,B,2,233.66,30,130,166172,12526601,233.73,234.12,200,200,1,1,233.7,234.13,1200,400,1,1,233.66,234.17,1,1,1,1,233.58,234.18,505,30,2,1,233.53,234.41,10,600,1,2,233.5,234.43,100,105,1,2,233.45,234.5,15,63,1,4,233.4,234.75,110,1,2,1,233.39,234.79,10,2000,1,1,233.31,234.89,110,2,2,2,AAPL,-4077,-32.489978266119294,0.41939206003234003
2024-10-21T12:15:55.594134274Z,2024-10-21T12:15:55.593967834Z,10,2,38,A,B,1,233.71,29,130,166440,12526613,233.73,234.12,200,200,1,1,233.71,234.13,29,400,1,1,233.7,234.17,1200,1,1,1,233.66,234.18,1,30,1,1,233.58,234.41,505,600,2,2,233.53,234.43,10,105,1,2,233.5,234.5,100,63,1,4,233.45,234.75,15,1,1,1,233.4,234.79,110,2000,2,1,233.39,234.89,10,2,1,2,AAPL,-4067,-33.34410417169038,0.4304174174558011
2024-10-21T12:15:55.643690186Z,2024-10-21T12:15:55.643523614Z,10,2,38,A,B,0,233.77,200,130,166572,12526664,233.77,234.12,200,200,1,1,233.71,234.13,29,400,1,1,233.7,234.17,1200,1,1,1,233.66,234.18,1,30,1,1,233.58,234.41,505,600,2,2,233.53,234.43,10,105,1,2,233.5,234.5,100,63,1,4,233.45,234.75,15,1,1,1,233.4,234.79,110,2000,2,1,233.39,234.89,10,2,1,2,AAPL,-4067,-34.27522273055622,0.44243662311172816
2024-10-21T12:16:00.253510382Z,2024-10-21T12:16:00.253343668Z,10,2,38,A,A,0,234.11,200,130,166714,12533252,233.77,234.11,200,200,1,1,233.71,234.13,29,400,1,1,233.7,234.17,1200,1,1,1,233.66,234.18,1,30,1,1,233.58,234.41,505,600,2,2,233.53,234.43,10,105,1,2,233.5,234.5,100,63,1,4,233.45,234.75,15,1,1,1,233.4,234.79,110,2000,2,1,233.39,234.89,10,2,1,2,AAPL,-3977,-29.450533175355453,0.38015783440345086
2024-10-21T12:16:02.523286908Z,2024-10-21T12:16:02.523121028Z,10,2,38,C,B,0,233.77,200,130,165880,12536233,233.71,234.11,29,200,1,1,233.7,234.13,1200,400,1,1,233.66,234.17,1,1,1,1,233.58,234.18,505,30,2,1,233.53,234.41,10,600,1,2,233.5,234.43,100,105,1,2,233.45,234.5,15,63,1,4,233.4,234.75,110,1,2,1,233.39,234.79,10,2000,1,1,233.31,234.89,110,2,2,2,AAPL,-3874,-26.658742571160463,0.3441204199403811
2024-10-21T12:16:02.523299016Z,2024-10-21T12:16:02.523132984Z,10,2,38,A,B,0,233.76,200,130,166032,12536234,233.76,234.11,200,200,1,1,233.71,234.13,29,400,1,1,233.7,234.17,1200,1,1,1,233.66,234.18,1,30,1,1,233.58,234.41,505,600,2,2,233.53,234.43,10,105,1,2,233.5,234.5,100,63,1,4,233.45,234.75,15,1,1,1,233.4,234.79,110,2000,2,1,233.39,234.89,10,2,1,2,AAPL,-3864,-27.746487667811426,0.3581614160019342
2024-10-21T12:16:02.593082475Z,2024-10-21T12:16:02.592915859Z,10,2,38,A,A,2,234.17,27,130,166616,12536503,233.76,234.11,200,200,1,1,233.71,234.13,29,400,1,1,233.7,234.17,1200,28,1,2,233.66,234.18,1,30,1,1,233.58,234.41,505,600,2,2,233.53,234.43,10,105,1,2,233.5,234.5,100,63,1,4,233.45,234.75,15,1,1,1,233.4,234.79,110,2000,2,1,233.39,234.89,10,2,1,2,AAPL,-3864,-28.89872234340916,0.37303486621730564
2024-10-21T12:16:02.697524299Z,2024-10-21T12:16:02.697358278Z,10,2,38,C,A,3,234.18,30,130,166021,12536650,233.76,234.11,200,200,1,1,233.71,234.13,29,400,1,1,233.7,234.17,1200,28,1,2,233.66,234.41,1,600,1,2,233.58,234.43,505,105,2,2,233.53,234.5,10,63,1,4,233.5,234.75,100,1,1,1,233.45,234.79,15,2000,1,1,233.4,234.89,110,2,2,2,233.39,235.0,10,213,1,6,AAPL,-3651,-27.488330070772477,0.35482902699421154
2024-10-21T12:16:04.305857113Z,2024-10-21T12:16:04.305690771Z,10,2,38,A,B,0,233.77,200,130,166342,12539302,233.77,234.11,200,200,1,1,233.71,234.13,29,400,1,1,233.7,234.17,1200,28,1,2,233.66,234.41,1,600,1,2,233.58,234.43,505,105,2,2,233.53,234.5,10,63,1,4,233.5,234.75,100,1,1,1,233.45,234.79,15,2000,1,1,233.4,234.89,110,2,2,2,233.39,235.0,10,213,1,6,AAPL,-1865,-16.504424778761063,0.2130449165252755
2024-10-21T12:16:08.452361078Z,2024-10-21T12:16:08.452195034Z,10,2,38,C,B,0,233.77,200,130,166044,12544790,233.71,234.11,29,200,1,1,233.7,234.13,1200,400,1,1,233.66,234.17,1,28,1,2,233.58,234.41,505,600,2,2,233.53,234.43,10,105,1,2,233.5,234.5,100,63,1,4,233.45,234.75,15,1,1,1,233.4,234.79,110,2000,2,1,233.39,234.89,10,2,1,2,233.31,235.0,110,213,2,6,AAPL,13,0.24549356223175967,-0.003168917194888379
2024-10-21T12:16:08.452373943Z,2024-10-21T12:16:08.452206841Z,10,2,38,A,B,0,233.76,200,130,167102,12544791,233.76,234.11,200,200,1,1,233.71,234.13,29,400,1,1,233.7,234.17,1200,28,1,2,233.66,234.41,1,600,1,2,233.58,234.43,505,105,2,2,233.53,234.5,10,63,1,4,233.5,234.75,100,1,1,1,233.45,234.79,15,2000,1,1,233.4,234.89,110,2,2,2,233.39,235.0,10,213,1,6,AAPL,23,0.3976945244956772,-0.0051335807160497035
2024-10-21T12:16:09.449971056Z,2024-10-21T12:16:09.449805017Z,10,2,38,C,B,1,233.71,29,130,166039,12545654,233.76,234.11,200,200,1,1,233.7,234.13,1200,400,1,1,233.66,234.17,1,28,1,2,233.58,234.41,505,600,2,2,233.53,234.43,10,105,1,2,233.5,234.5,100,63,1,4,233.45,234.75,15,1,1,1,233.4,234.79,110,2000,2,1,233.39,234.89,10,2,1,2,233.31,235.0,110,213,2,6,AAPL,-87,-1.3220338983050848,0.01706527826831261
2024-10-21T12:16:09.450027355Z,2024-10-21T12:16:09.449860480Z,10,2,38,A,B,2,233.69,30,130,166875,12545655,233.76,234.11,200,200,1,1,233.7,234.13,1200,400,1,1,233.69,234.17,30,28,1,2,233.66,234.41,1,600,1,2,233.58,234.43,505,105,2,2,233.53,234.5,10,63,1,4,233.5,234.75,100,1,1,1,233.45,234.79,15,2000,1,1,233.4,234.89,110,2,2,2,233.39,235.0,10,213,1,6,AAPL,-77,-1.1147880041365046,0.014390075417246287
2024-10-21T12:16:09.753978514Z,2024-10-21T12:16:09.753811454Z,10,2,38,C,B,0,233.76,200,130,167060,12546012,233.7,234.11,1200,200,1,1,233.69,234.13,30,400,1,1,233.66,234.17,1,28,1,2,233.58,234.41,505,600,2,2,233.53,234.43,10,105,1,2,233.5,234.5,100,63,1,4,233.45,234.75,15,1,1,1,233.4,234.79,110,2000,2,1,233.39,234.89,10,2,1,2,233.31,235.0,110,213,2,6,AAPL,-187,-2.4856003544528136,0.03208500309026499
2024-10-21T12:16:09.753989713Z,2024-10-21T12:16:09.753823460Z,10,2,38,A,B,0,233.74,200,130,166253,12546013,233.74,234.11,200,200,1,1,233.7,234.13,1200,400,1,1,233.69,234.17,30,28,1,2,233.66,234.41,1,600,1,2,233.58,234.43,505,105,2,2,233.53,234.5,10,63,1,4,233.5,234.75,100,1,1,1,233.45,234.79,15,2000,1,1,233.4,234.89,110,2,2,2,233.39,235.0,10,213,1,6,AAPL,-177,-2.2838709677419353,0.029481009256573792
2024-10-21T12:16:09.794247866Z,2024-10-21T12:16:09.794081348Z,10,2,38,A,A,0,234.1,200,130,166518,12546087,233.74,234.1,200,200,1,1,233.7,234.13,1200,400,1,1,233.69,234.17,30,28,1,2,233.66,234.41,1,600,1,2,233.58,234.43,505,105,2,2,233.53,234.5,10,63,1,4,233.5,234.75,100,1,1,1,233.45,234.79,15,2000,1,1,233.4,234.89,110,2,2,2,233.39,235.0,10,213,1,6,AAPL,-177,-2.2264150943396226,0.028739348646345524
2024-10-21T12:16:09.813187546Z,2024-10-21T12:16:09.813020869Z,10,2,38,A,B,0,233.75,200,130,166677,12546174,233.75,234.1,200,200,1,1,233.7,234.13,1200,400,1,1,233.69,234.17,30,28,1,2,233.66,234.41,1,600,1,2,233.58,234.43,505,105,2,2,233.53,234.5,10,63,1,4,233.5,234.75,100,1,1,1,233.45,234.79,15,2000,1,1,233.4,234.89,110,2,2,2,233.39,235.0,10,213,1,6,AAPL,-177,-2.1777170198222833,0.02811073678258404
2024-10-21T12:16:10.366670967Z,2024-10-21T12:16:10.366504475Z,10,2,38,A,A,0,234.09,200,130,166492,12546733,233.75,234.09,200,200,1,1,233.7,234.13,1200,400,1,1,233.69,234.17,30,28,1,2,233.66,234.41,1,600,1,2,233.58,234.43,505,105,2,2,233.53,234.5,10,63,1,4,233.5,234.75,100,1,1,1,233.45,234.79,15,2000,1,1,233.4,234.89,110,2,2,2,233.39,235.0,10,213,1,6,AAPL,-177,-2.1359161638615434,0.027571156640396895
2024-10-21T12:16:10.387245860Z,2024-10-21T12:16:10.387079865Z,10,2,38,C,A,2,234.17,27,130,165995,12546807,233.75,234.09,200,200,1,1,233.7,234.13,1200,400,1,1,233.69,234.17,30,1,1,1,233.66,234.41,1,600,1,2,233.58,234.43,505,105,2,2,233.53,234.5,10,63,1,4,233.5,234.75,100,1,1,1,233.45,234.79,15,2000,1,1,233.4,234.89,110,2,2,2,233.39,235.0,10,213,1,6,AAPL,-177,-2.099644128113879,0.027102944452959302
2024-10-21T12:16:10.387302448Z,2024-10-21T12:16:10.387136109Z,10,2,38,A,A,2,234.16,29,130,166339,12546808,233.75,234.09,200,200,1,1,233.7,234.13,1200,400,1,1,233.69,234.16,30,29,1,1,233.66,234.17,1,1,1,1,233.58,234.41,505,600,2,2,233.53,234.43,10,105,1,2,233.5,234.5,100,63,1,4,233.45,234.75,15,1,1,1,233.4,234.79,110,2000,2,1,233.39,234.89,10,2,1,2,AAPL,-179,-2.221631205673759,0.028677596529858757
2024-10-21T12:16:12.011187719Z,2024-10-21T12:16:12.011021598Z,10,2,38,C,A,0,234.09,200,130,166121,12547958,233.75,234.13,200,400,1,1,233.7,234.16,1200,29,1,1,233.69,234.17,30,1,1,1,233.66,234.41,1,600,1,2,233.58,234.43,505,105,2,2,233.53,234.5,10,63,1,4,233.5,234.75,100,1,1,1,233.45,234.79,15,2000,1,1,233.4,234.89,110,2,2,2,233.39,235.0,10,213,1,6,AAPL,34,0.4085836909871245,-0.00527414190477926
2024-10-21T12:16:12.011200956Z,2024-10-21T12:16:12.011034600Z,10,2,38,A,A,0,234.11,200,130,166356,12547959,233.75,234.11,200,200,1,1,233.7,234.13,1200,400,1,1,233.69,234.16,30,29,1,1,233.66,234.17,1,1,1,1,233.58,234.41,505,600,2,2,233.53,234.43,10,105,1,2,233.5,234.5,100,63,1,4,233.45,234.75,15,1,1,1,233.4,234.79,110,2000,2,1,233.39,234.89,10,2,1,2,AAPL,32,0.401482748788138,-0.005182480446817958
2024-10-21T12:16:12.100747677Z,2024-10-21T12:16:12.100581387Z,10,2,38,A,A,0,234.1,200,130,166290,12548144,233.75,234.1,200,200,1,1,233.7,234.13,1200,400,1,1,233.69,234.16,30,29,1,1,233.66,234.17,1,1,1,1,233.58,234.41,505,600,2,2,233.53,234.43,10,105,1,2,233.5,234.5,100,63,1,4,233.45,234.75,15,1,1,1,233.4,234.79,110,2000,2,1,233.39,234.89,10,2,1,2,AAPL,32,0.41830065359477125,-0.005399571873734575
2024-10-21T12:16:13.573877503Z,2024-10-21T12:16:13.573710917Z,10,2,38,A,A,0,234.09,200,130,166586,12549200,233.75,234.09,200,200,1,1,233.7,234.13,1200,400,1,1,233.69,234.16,30,29,1,1,233.66,234.17,1,1,1,1,233.58,234.41,505,600,2,2,233.53,234.43,10,105,1,2,233.5,234.5,100,63,1,4,233.45,234.75,15,1,1,1,233.4,234.79,110,2000,2,1,233.39,234.89,10,2,1,2,AAPL,32,0.43500424808836025,-0.005615187742949125
2024-10-21T12:16:14.439317152Z,2024-10-21T12:16:14.439151195Z,10,2,38,C,A,0,234.09,200,130,165957,12549789,233.75,234.13,200,400,1,1,233.7,234.16,1200,29,1,1,233.69,234.17,30,1,1,1,233.66,234.41,1,600,1,2,233.58,234.43,505,105,2,2,233.53,234.5,10,63,1,4,233.5,234.75,100,1,1,1,233.45,234.79,15,2000,1,1,233.4,234.89,110,2,2,2,233.39,235.0,10,213,1,6,AAPL,245,3.2631859350026637,-0.04212235109361276
2024-10-21T12:16:14.439329197Z,2024-10-21T12:16:14.439163159Z,10,2,38,A,A,0,234.1,200,130,166038,12549790,233.75,234.1,200,200,1,1,233.7,234.13,1200,400,1,1,233.69,234.16,30,29,1,1,233.66,234.17,1,1,1,1,233.58,234.41,505,600,2,2,233.53,234.43,10,105,1,2,233.5,234.5,100,63,1,4,233.45,234.75,15,1,1,1,233.4,234.79,110,2000,2,1,233.39,234.89,10,2,1,2,AAPL,243,3.3552841210833777,-0.04331118685303556
2024-10-21T12:16:14.647379555Z,2024-10-21T12:16:14.647213365Z,10,2,38,A,A,0,234.09,200,130,166190,12550175,233.75,234.09,200,200,1,1,233.7,234.13,1200,400,1,1,233.69,234.16,30,29,1,1,233.66,234.17,1,1,1,1,233.58,234.41,505,600,2,2,233.53,234.43,10,105,1,2,233.5,234.5,100,63,1,4,233.45,234.75,15,1,1,1,233.4,234.79,110,2000,2,1,233.39,234.89,10,2,1,2,AAPL,243,3.4732662784542088,-0.04483414201236269
2024-10-21T12:16:20.281941255Z,2024-10-21T12:16:20.281774908Z,10,2,38,C,B,0,233.75,200,130,166347,12556695,233.7,234.09,1200,200,1,1,233.69,234.13,30,400,1,1,233.66,234.16,1,29,1,1,233.58,234.17,505,1,2,1,233.53,234.41,10,600,1,2,233.5,234.43,100,105,1,2,233.45,234.5,15,63,1,4,233.4,234.75,110,1,2,1,233.39,234.79,10,2000,1,1,233.31,234.89,110,2,2,2,AAPL,123,1.577765900587921,-0.02036635684630097
2024-10-21T12:16:20.281953090Z,2024-10-21T12:16:20.281786576Z,10,2,38,A,B,0,233.73,200,130,166514,12556696,233.73,234.09,200,200,1,1,233.7,234.13,1200,400,1,1,233.69,234.16,30,29,1,1,233.66,234.17,1,1,1,1,233.58,234.41,505,600,2,2,233.53,234.43,10,105,1,2,233.5,234.5,100,63,1,4,233.45,234.75,15,1,1,1,233.4,234.79,110,2000,2,1,233.39,234.89,10,2,1,2,AAPL,133,1.7714437932871605,-0.022866419165104068
2024-10-21T12:16:20.339335090Z,2024-10-21T12:16:20.339168043Z,10,2,38,A,B,0,233.74,200,130,167047,12556816,233.74,234.09,200,200,1,1,233.7,234.13,1200,400,1,1,233.69,234.16,30,29,1,1,233.66,234.17,1,1,1,1,233.58,234.41,505,600,2,2,233.53,234.43,10,105,1,2,233.5,234.5,100,63,1,4,233.45,234.75,15,1,1,1,233.4,234.79,110,2000,2,1,233.39,234.89,10,2,1,2,AAPL,133,1.8364312267657994,-0.02370529980022111
2024-10-21T12:16:20.352255989Z,2024-10-21T12:16:20.352089791Z,10,2,38,A,B,0,233.74,200,130,166198,12556912,233.74,234.09,400,200,2,1,233.7,234.13,1200,400,1,1,233.69,234.16,30,29,1,1,233.66,234.17,1,1,1,1,233.58,234.41,505,600,2,2,233.53,234.43,10,105,1,2,233.5,234.5,100,63,1,4,233.45,234.75,15,1,1,1,233.4,234.79,110,2000,2,1,233.39,234.89,10,2,1,2,AAPL,133,1.9010058231868714,-0.024538851389482457
2024-10-21T12:16:20.353221672Z,2024-10-21T12:16:20.353055730Z,10,2,38,C,B,0,233.74,200,130,165942,12556917,233.74,234.09,200,200,1,1,233.7,234.13,1200,400,1,1,233.69,234.16,30,29,1,1,233.66,234.17,1,1,1,1,233.58,234.41,505,600,2,2,233.53,234.43,10,105,1,2,233.5,234.5,100,63,1,4,233.45,234.75,15,1,1,1,233.4,234.79,110,2000,2,1,233.39,234.89,10,2,1,2,AAPL,133,1.9651715039577835,-0.025367124551793338
2024-10-21T12:16:20.448635525Z,2024-10-21T12:16:20.448469192Z,10,2,38,A,A,0,234.08,200,130,166333,12557144,233.74,234.08,200,200,1,1,233.7,234.13,1200,400,1,1,233.69,234.16,30,29,1,1,233.66,234.17,1,1,1,1,233.58,234.41,505,600,2,2,233.53,234.43,10,105,1,2,233.5,234.5,100,63,1,4,233.45,234.75,15,1,1,1,233.4,234.79,110,2000,2,1,233.39,234.89,10,2,1,2,AAPL,133,2.0289321409784327,-0.02619016926699863
2024-10-21T12:16:34.456477234Z,2024-10-21T12:16:34.456311187Z,10,2,38,C,A,2,234.16,29,130,166047,12569933,233.74,234.08,200,200,1,1,233.7,234.13,1200,400,1,1,233.69,234.17,30,1,1,1,233.66,234.41,1,600,1,2,233.58,234.43,505,105,2,2,233.53,234.5,10,63,1,4,233.5,234.75,100,1,1,1,233.45,234.79,15,2000,1,1,233.4,234.89,110,2,2,2,233.39,235.0,10,213,1,6,AAPL,113,4.442260442260443,-0.05734225929053874
2024-10-21T12:16:34.456534808Z,2024-10-21T12:16:34.456367935Z,10,2,38,A,A,2,234.15,30,130,166873,12569937,233.74,234.08,200,200,1,1,233.7,234.13,1200,400,1,1,233.69,234.15,30,30,1,1,233.66,234.17,1,1,1,1,233.58,234.41,505,600,2,2,233.53,234.43,10,105,1,2,233.5,234.5,100,63,1,4,233.45,234.75,15,1,1,1,233.4,234.79,110,2000,2,1,233.39,234.89,10,2,1,2,AAPL,111,4.768496420047732,-0.06155342796723661
2024-10-21T12:16:35.928291181Z,2024-10-21T12:16:35.928124957Z,10,2,38,C,B,2,233.69,30,130,166224,12572168,233.74,234.08,200,200,1,1,233.7,234.13,1200,400,1,1,233.66,234.15,1,30,1,1,233.58,234.17,505,1,2,1,233.53,234.41,10,600,1,2,233.5,234.43,100,105,1,2,233.45,234.5,15,63,1,4,233.4,234.75,110,1,2,1,233.39,234.79,10,2000,1,1,233.31,234.89,110,2,2,2,AAPL,1,0.034682080924855495,-0.00044768849169873014
2024-10-21T12:16:35.928342407Z,2024-10-21T12:16:35.928176126Z,10,2,38,A,B,2,233.67,28,130,166281,12572169,233.74,234.08,200,200,1,1,233.7,234.13,1200,400,1,1,233.67,234.15,28,30,1,1,233.66,234.17,1,1,1,1,233.58,234.41,505,600,2,2,233.53,234.43,10,105,1,2,233.5,234.5,100,63,1,4,233.45,234.75,15,1,1,1,233.4,234.79,110,2000,2,1,233.39,234.89,10,2,1,2,AAPL,11,0.4143126177024482,-0.005348092904599393
2024-10-21T12:16:36.290257872Z,2024-10-21T12:16:36.290091431Z,10,2,38,A,A,1,234.1,100,130,166441,12572429,233.74,234.08,200,200,1,1,233.7,234.1,1200,100,1,1,233.67,234.13,28,400,1,1,233.66,234.15,1,30,1,1,233.58,234.17,505,1,2,1,233.53,234.41,10,600,1,2,233.5,234.43,100,105,1,2,233.45,234.5,15,63,1,4,233.4,234.75,110,1,2,1,233.39,234.79,10,2000,1,1,AAPL,-1989,-17.22077922077922,0.22229187146905904
2024-10-21T12:16:37.672891891Z,2024-10-21T12:16:37.672726079Z,10,2,38,C,B,2,233.67,28,130,165812,12574327,233.74,234.08,200,200,1,1,233.7,234.1,1200,100,1,1,233.66,234.13,1,400,1,1,233.58,234.15,505,30,2,1,233.53,234.17,10,1,1,1,233.5,234.41,100,600,1,2,233.45,234.43,15,105,1,2,233.4,234.5,110,63,2,4,233.39,234.75,10,1,1,1,233.31,234.79,110,2000,2,1,AAPL,-2099,-10.831219092668244,0.1398131833369897
2024-10-21T12:16:37.673069955Z,2024-10-21T12:16:37.672903531Z,10,2,38,A,B,2,233.68,27,130,166424,12574328,233.74,234.08,200,200,1,1,233.7,234.1,1200,100,1,1,233.68,234.13,27,400,1,1,233.66,234.15,1,30,1,1,233.58,234.17,505,1,2,1,233.53,234.41,10,600,1,2,233.5,234.43,100,105,1,2,233.45,234.5,15,63,1,4,233.4,234.75,110,1,2,1,233.39,234.79,10,2000,1,1,AAPL,-2089,-8.154030926287344,0.10525509742520131
2024-10-21T12:16:41.311074051Z,2024-10-21T12:16:41.310907658Z,10,2,38,C,B,0,233.74,200,130,166393,12577924,233.7,234.08,1200,200,1,1,233.68,234.1,27,100,1,1,233.66,234.13,1,400,1,1,233.58,234.15,505,30,2,1,233.53,234.17,10,1,1,1,233.5,234.41,100,600,1,2,233.45,234.43,15,105,1,2,233.4,234.5,110,63,2,4,233.39,234.75,10,1,1,1,233.31,234.79,110,2000,2,1,AAPL,-2099,-3.905570415164554,0.05041447576852649
2024-10-21T12:16:41.311087986Z,2024-10-21T12:16:41.310921026Z,10,2,38,A,B,1,233.69,200,130,166960,12577925,233.7,234.08,1200,200,1,1,233.69,234.1,200,100,1,1,233.68,234.13,27,400,1,1,233.66,234.15,1,30,1,1,233.58,234.17,505,1,2,1,233.53,234.41,10,600,1,2,233.5,234.43,100,105,1,2,233.45,234.5,15,63,1,4,233.4,234.75,110,1,2,1,233.39,234.79,10,2000,1,1,AAPL,-2089,-3.544349137524743,0.045751704543626905
2024-10-21T12:16:42.498174235Z,2024-10-21T12:16:42.498007357Z,10,2,38,A,A,5,234.25,100,130,166878,12578938,233.7,234.08,1200,200,1,1,233.69,234.1,200,100,1,1,233.68,234.13,27,400,1,1,233.66,234.15,1,30,1,1,233.58,234.17,505,1,2,1,233.53,234.25,10,100,1,1,233.5,234.41,100,600,1,2,233.45,234.43,15,105,1,2,233.4,234.5,110,63,2,4,233.39,234.75,10,1,1,1,AAPL,-2090,-3.9359698681732582,0.050806882593694244
2024-10-21T12:16:44.366676689Z,2024-10-21T12:16:44.366509790Z,10,2,38,A,B,0,233.74,200,130,166899,12580824,233.74,234.08,200,200,1,1,233.7,234.1,1200,100,1,1,233.68,234.13,27,400,1,1,233.66,234.15,1,30,1,1,233.58,234.17,505,1,2,1,233.53,234.25,10,100,1,1,233.5,234.41,100,600,1,2,233.45,234.43,15,105,1,2,233.4,234.5,110,63,2,4,233.39,234.75,10,1,1,1,AAPL,-2090,-4.325087009688646,0.05582974343519293
2024-10-21T12:16:44.533960641Z,2024-10-21T12:16:44.533794596Z,10,2,38,A,A,0,233.9,18,130,166045,12580968,233.74,233.9,200,18,1,1,233.7,234.08,1200,200,1,1,233.68,234.1,27,100,1,1,233.66,234.13,1,400,1,1,233.58,234.15,505,30,2,1,233.53,234.17,10,1,1,1,233.5,234.25,100,100,1,1,233.45,234.41,15,600,1,2,233.4,234.43,110,105,2,2,233.39,234.5,10,63,1,4,AAPL,-2153,-4.827354260089686,0.06231318565565557
2024-10-21T12:16:44.802698042Z,2024-10-21T12:16:44.802532155Z,10,2,38,C,A,4,234.15,30,130,165887,12581165,233.74,233.9,200,18,1,1,233.7,234.08,1200,200,1,1,233.68,234.1,27,100,1,1,233.66,234.13,1,400,1,1,233.58,234.17,505,1,2,1,233.53,234.25,10,100,1,1,233.5,234.41,100,600,1,2,233.45,234.43,15,105,1,2,233.4,234.5,110,63,2,4,233.39,234.75,10,1,1,1,AAPL,-2152,-5.22183854409706,0.06740532745904854
2024-10-21T12:16:44.802744697Z,2024-10-21T12:16:44.802578420Z,10,2,38,A,A,3,234.11,27,130,166277,12581166,233.74,233.9,200,18,1,1,233.7,234.08,1200,200,1,1,233.68,234.1,27,100,1,1,233.66,234.11,1,27,1,1,233.58,234.13,505,400,2,1,233.53,234.17,10,1,1,1,233.5,234.25,100,100,1,1,233.45,234.41,15,600,1,2,233.4,234.43,110,105,2,2,233.39,234.5,10,63,1,4,AAPL,-2215,-5.74898034853541,0.07420985916669535
2024-10-21T12:16:47.612405002Z,2024-10-21T12:16:47.612239006Z,10,2,38,A,A,1,234.08,200,130,165996,12583335,233.74,233.9,200,18,1,1,233.7,234.08,1200,400,1,2,233.68,234.1,27,100,1,1,233.66,234.11,1,27,1,1,233.58,234.13,505,400,2,1,233.53,234.17,10,1,1,1,233.5,234.25,100,100,1,1,233.45,234.41,15,600,1,2,233.4,234.43,110,105,2,2,233.39,234.5,10,63,1,4,AAPL,-2215,-6.118221158272719,0.07897614933086036
2024-10-21T12:16:47.667042872Z,2024-10-21T12:16:47.666876898Z,10,2,38,C,A,1,234.08,200,130,165974,12583345,233.74,233.9,200,18,1,1,233.7,234.08,1200,200,1,1,233.68,234.1,27,100,1,1,233.66,234.11,1,27,1,1,233.58,234.13,505,400,2,1,233.53,234.17,10,1,1,1,233.5,234.25,100,100,1,1,233.45,234.41,15,600,1,2,233.4,234.43,110,105,2,2,233.39,234.5,10,63,1,4,AAPL,-2215,-6.482531552954089,0.08367879596438993
2024-10-21T12:16:47.667056416Z,2024-10-21T12:16:47.666890051Z,10,2,38,A,A,1,234.04,200,130,166365,12583346,233.74,233.9,200,18,1,1,233.7,234.04,1200,200,1,1,233.68,234.1,27,100,1,1,233.66,234.11,1,27,1,1,233.58,234.13,505,400,2,1,233.53,234.17,10,1,1,1,233.5,234.25,100,100,1,1,233.45,234.41,15,600,1,2,233.4,234.43,110,105,2,2,233.39,234.5,10,63,1,4,AAPL,-2215,-6.842009630235305,0.08831906534630728
2024-10-21T12:16:47.926963883Z,2024-10-21T12:16:47.926797838Z,10,2,38,C,B,0,233.74,200,130,166045,12583828,233.7,233.9,1200,18,1,1,233.68,234.04,27,200,1,1,233.66,234.1,1,100,1,1,233.58,234.11,505,27,2,1,233.53,234.13,10,400,1,1,233.5,234.17,100,1,1,1,233.45,234.25,15,100,1,1,233.4,234.41,110,600,2,2,233.39,234.43,10,105,1,2,233.31,234.5,110,63,2,4,AAPL,-2325,-7.486583184257603,0.09663944735609395
2024-10-21T12:16:47.926976599Z,2024-10-21T12:16:47.926810269Z,10,2,38,A,B,1,233.68,200,130,166330,12583829,233.7,233.9,1200,18,1,1,233.68,234.04,227,200,2,1,233.66,234.1,1,100,1,1,233.58,234.11,505,27,2,1,233.53,234.13,10,400,1,1,233.5,234.17,100,1,1,1,233.45,234.25,15,100,1,1,233.4,234.41,110,600,2,2,233.39,234.43,10,105,1,2,233.31,234.5,110,63,2,4,AAPL,-2325,-7.782084030652691,0.10045387615305536
2024-10-21T12:16:48.065770361Z,2024-10-21T12:16:48.065603630Z,10,2,38,C,A,3,234.11,27,130,166731,12584067,233.7,233.9,1200,18,1,1,233.68,234.04,227,200,2,1,233.66,234.1,1,100,1,1,233.58,234.13,505,400,2,1,233.53,234.17,10,1,1,1,233.5,234.25,100,100,1,1,233.45,234.41,15,600,1,2,233.4,234.43,110,105,2,2,233.39,234.5,10,63,1,4,233.31,234.75,110,1,2,1,AAPL,-2324,-8.108862526168876,0.10467204783929858
2024-10-21T12:16:48.065827712Z,2024-10-21T12:16:48.065661214Z,10,2,38,A,A,2,234.06,29,130,166498,12584068,233.7,233.9,1200,18,1,1,233.68,234.04,227,200,2,1,233.66,234.06,1,29,1,1,233.58,234.1,505,100,2,1,233.53,234.13,10,400,1,1,233.5,234.17,100,1,1,1,233.45,234.25,15,100,1,1,233.4,234.41,110,600,2,2,233.39,234.43,10,105,1,2,233.31,234.5,110,63,2,4,AAPL,-2387,-8.615106986336686,0.11120682928146225
2024-10-21T12:16:48.123133937Z,2024-10-21T12:16:48.122967378Z,10,2,38,A,A,1,234.01,200,130,166559,12584094,233.7,233.9,1200,18,1,1,233.68,234.01,227,200,2,1,233.66,234.06,1,29,1,1,233.58,234.1,505,100,2,1,233.53,234.13,10,400,1,1,233.5,234.17,100,1,1,1,233.45,234.25,15,100,1,1,233.4,234.41,110,600,2,2,233.39,234.43,10,105,1,2,233.31,234.5,110,63,2,4,AAPL,-2387,-8.893141405588484,0.11479579529722297
2024-10-21T12:16:48.228533367Z,2024-10-21T12:16:48.228366485Z,10,2,38,A,A,1,234.01,200,130,166882,12584254,233.7,233.9,1200,18,1,1,233.68,234.01,227,400,2,2,233.66,234.06,1,29,1,1,233.58,234.1,505,100,2,1,233.53,234.13,10,400,1,1,233.5,234.17,100,1,1,1,233.45,234.25,15,100,1,1,233.4,234.41,110,600,2,2,233.39,234.43,10,105,1,2,233.31,234.5,110,63,2,4,AAPL,-2387,-9.163147792706335,0.11828113265225995
2024-10-21T12:16:48.283326363Z,2024-10-21T12:16:48.283159712Z,10,2,38,C,A,1,234.01,200,130,166651,12584287,233.7,233.9,1200,18,1,1,233.68,234.01,227,200,2,1,233.66,234.06,1,29,1,1,233.58,234.1,505,100,2,1,233.53,234.13,10,400,1,1,233.5,234.17,100,1,1,1,233.45,234.25,15,100,1,1,233.4,234.41,110,600,2,2,233.39,234.43,10,105,1,2,233.31,234.5,110,63,2,4,AAPL,-2387,-9.425468904244818,0.12166726576866226
2024-10-21T12:16:48.283339638Z,2024-10-21T12:16:48.283173265Z,10,2,38,A,A,1,233.98,200,130,166373,12584288,233.7,233.9,1200,18,1,1,233.68,233.98,227,200,2,1,233.66,234.06,1,29,1,1,233.58,234.1,505,100,2,1,233.53,234.13,10,400,1,1,233.5,234.17,100,1,1,1,233.45,234.25,15,100,1,1,233.4,234.41,110,600,2,2,233.39,234.43,10,105,1,2,233.31,234.5,110,63,2,4,AAPL,-2387,-9.680428258577338,0.12495837073531395
2024-10-21T12:16:49.563943091Z,2024-10-21T12:16:49.563776410Z,10,2,38,C,A,0,233.9,18,130,166681,12585847,233.7,233.98,1200,200,1,1,233.68,234.06,227,29,2,1,233.66,234.1,1,100,1,1,233.58,234.13,505,400,2,1,233.53,234.17,10,1,1,1,233.5,234.25,100,100,1,1,233.45,234.41,15,600,1,2,233.4,234.43,110,105,2,2,233.39,234.5,10,63,1,4,233.31,234.75,110,1,2,1,AAPL,-2386,-9.973633440514469,0.12874316628850155
2024-10-21T12:16:49.564921505Z,2024-10-21T12:16:49.564755651Z,10,2,38,C,B,1,233.68,200,130,165854,12585849,233.7,233.98,1200,200,1,1,233.68,234.06,27,29,1,1,233.66,234.1,1,100,1,1,233.58,234.13,505,400,2,1,233.53,234.17,10,1,1,1,233.5,234.25,100,100,1,1,233.45,234.41,15,600,1,2,233.4,234.43,110,105,2,2,233.39,234.5,10,63,1,4,233.31,234.75,110,1,2,1,AAPL,-2386,-10.265636204286512,0.13251244060535144
2024-10-21T12:16:49.635290441Z,2024-10-21T12:16:49.635124163Z,10,2,38,C,A,0,233.98,200,130,166278,12585962,233.7,234.06,1200,29,1,1,233.68,234.1,27,100,1,1,233.66,234.13,1,400,1,1,233.58,234.17,505,1,2,1,233.53,234.25,10,100,1,1,233.5,234.41,100,600,1,2,233.45,234.43,15,105,1,2,233.4,234.5,110,63,2,4,233.39,234.75,10,1,1,1,233.31,234.79,110,2000,2,1,AAPL,-386,-1.474387831662233,0.019031916394116322
2024-10-21T12:16:49.635302899Z,2024-10-21T12:16:49.635136826Z,10,2,38,A,A,0,234.04,400,130,166073,12585963,233.7,234.04,1200,400,1,1,233.68,234.06,27,29,1,1,233.66,234.1,1,100,1,1,233.58,234.13,505,400,2,1,233.53,234.17,10,1,1,1,233.5,234.25,100,100,1,1,233.45,234.41,15,600,1,2,233.4,234.43,110,105,2,2,233.39,234.5,10,63,1,4,233.31,234.75,110,1,2,1,AAPL,-387,-1.5194963444354184,0.019614192933115098
2024-10-21T12:16:49.635707853Z,2024-10-21T12:16:49.635541646Z,10,2,38,C,A,1,234.06,29,130,166207,12585964,233.7,234.04,1200,400,1,1,233.68,234.1,27,100,1,1,233.66,234.13,1,400,1,1,233.58,234.17,505,1,2,1,233.53,234.25,10,100,1,1,233.5,234.41,100,600,1,2,233.45,234.43,15,105,1,2,233.4,234.5,110,63,2,4,233.39,234.75,10,1,1,1,233.31,234.79,110,2000,2,1,AAPL,1613,5.732733088496624,-0.07400013382302982
2024-10-21T12:16:49.635803361Z,2024-10-21T12:16:49.635636984Z,10,2,38,A,A,2,234.11,29,130,166377,12585965,233.7,234.04,1200,400,1,1,233.68,234.1,27,100,1,1,233.66,234.11,1,29,1,1,233.58,234.13,505,400,2,1,233.53,234.17,10,1,1,1,233.5,234.25,100,100,1,1,233.45,234.41,15,600,1,2,233.4,234.43,110,105,2,2,233.39,234.5,10,63,1,4,233.31,234.75,110,1,2,1,AAPL,1612,5.881480609662803,-0.07592021911258022
2024-10-21T12:16:49.669662206Z,2024-10-21T12:16:49.669495875Z,10,2,38,A,B,1,233.68,200,130,166331,12585982,233.7,234.04,1200,400,1,1,233.68,234.1,227,100,2,1,233.66,234.11,1,29,1,1,233.58,234.13,505,400,2,1,233.53,234.17,10,1,1,1,233.5,234.25,100,100,1,1,233.45,234.41,15,600,1,2,233.4,234.43,110,105,2,2,233.39,234.5,10,63,1,4,233.31,234.75,110,1,2,1,AAPL,1612,6.031805425631431,-0.07786066467787656
2024-10-21T12:16:49.706410056Z,2024-10-21T12:16:49.706243840Z,10,2,38,C,A,0,234.04,200,130,166216,12585991,233.7,234.04,1200,200,1,1,233.68,234.1,227,100,2,1,233.66,234.11,1,29,1,1,233.58,234.13,505,400,2,1,233.53,234.17,10,1,1,1,233.5,234.25,100,100,1,1,233.45,234.41,15,600,1,2,233.4,234.43,110,105,2,2,233.39,234.5,10,63,1,4,233.31,234.75,110,1,2,1,AAPL,1612,6.180191693290736,-0.07977608678017577
2024-10-21T12:16:49.706607779Z,2024-10-21T12:16:49.706441749Z,10,2,38,C,A,0,234.04,200,130,166030,12585992,233.7,234.1,1200,100,1,1,233.68,234.11,227,29,2,1,233.66,234.13,1,400,1,1,233.58,234.17,505,1,2,1,233.53,234.25,10,100,1,1,233.5,234.41,100,600,1,2,233.45,234.43,15,105,1,2,233.4,234.5,110,63,2,4,233.39,234.75,10,1,1,1,233.31,234.79,110,2000,2,1,AAPL,3612,12.709754204398449,-0.1640619748842952
2024-10-21T12:16:49.706619859Z,2024-10-21T12:16:49.706453582Z,10,2,38,A,A,0,234.09,200,130,166277,12585993,233.7,234.09,1200,200,1,1,233.68,234.1,227,100,2,1,233.66,234.11,1,29,1,1,233.58,234.13,505,400,2,1,233.53,234.17,10,1,1,1,233.5,234.25,100,100,1,1,233.45,234.41,15,600,1,2,233.4,234.43,110,105,2,2,233.39,234.5,10,63,1,4,233.31,234.75,110,1,2,1,AAPL,3611,13.005247993414283,-0.16787631258212446
2024-10-21T12:16:49.707217404Z,2024-10-21T12:16:49.707051448Z,10,2,38,C,A,2,234.11,29,130,165956,12585994,233.7,234.09,1200,200,1,1,233.68,234.1,227,100,2,1,233.66,234.13,1,400,1,1,233.58,234.17,505,1,2,1,233.53,234.25,10,100,1,1,233.5,234.41,100,600,1,2,233.45,234.43,15,105,1,2,233.4,234.5,110,63,2,4,233.39,234.75,10,1,1,1,233.31,234.79,110,2000,2,1,AAPL,5611,18.750208855472014,-0.24203428680447364
2024-10-21T12:16:49.709612912Z,2024-10-21T12:16:49.709446277Z,10,2,38,A,A,0,234.09,200,130,166635,12585999,233.7,234.09,1200,400,1,2,233.68,234.1,227,100,2,1,233.66,234.13,1,400,1,1,233.58,234.17,505,1,2,1,233.53,234.25,10,100,1,1,233.5,234.41,100,600,1,2,233.45,234.43,15,105,1,2,233.4,234.5,110,63,2,4,233.39,234.75,10,1,1,1,233.31,234.79,110,2000,2,1,AAPL,5611,17.552164355765978,-0.22656950727687122
2024-10-21T12:16:50.277429428Z,2024-10-21T12:16:50.277262708Z,10,2,38,C,B,1,233.68,27,130,166720,12586408,233.7,234.09,1200,400,1,2,233.68,234.1,200,100,1,1,233.66,234.13,1,400,1,1,233.58,234.17,505,1,2,1,233.53,234.25,10,100,1,1,233.5,234.41,100,600,1,2,233.45,234.43,15,105,1,2,233.4,234.5,110,63,2,4,233.39,234.75,10,1,1,1,233.31,234.79,110,2000,2,1,AAPL,5611,16.550337654273072,-0.21363757606124908
2024-10-21T12:16:50.277516325Z,2024-10-21T12:16:50.277350058Z,10,2,38,A,A,3,234.17,27,130,166267,12586409,233.7,234.09,1200,400,1,2,233.68,234.1,200,100,1,1,233.66,234.13,1,400,1,1,233.58,234.17,505,28,2,2,233.53,234.25,10,100,1,1,233.5,234.41,100,600,1,2,233.45,234.43,15,105,1,2,233.4,234.5,110,63,2,4,233.39,234.75,10,1,1,1,233.31,234.79,110,2000,2,1,AAPL,5611,15.700172191132157,-0.20266334142081438
2024-10-21T12:16:50.277547866Z,2024-10-21T12:16:50.277381197Z,10,2,38,A,B,1,233.69,27,130,166669,12586410,233.7,234.09,1200,400,1,2,233.69,234.1,27,100,1,1,233.68,234.13,200,400,1,1,233.66,234.17,1,28,1,2,233.58,234.25,505,100,2,1,233.53,234.41,10,600,1,2,233.5,234.43,100,105,1,2,233.45,234.5,15,63,1,4,233.4,234.75,110,1,2,1,233.39,234.79,10,2000,1,1,AAPL,5621,15.046510071605434,-0.19422564101276904
2024-10-21T12:16:50.981625530Z,2024-10-21T12:16:50.981459165Z,10,2,38,A,B,0,233.7,200,130,166365,12587468,233.7,234.09,1400,400,2,2,233.69,234.1,27,100,1,1,233.66,234.13,1,400,1,1,233.58,234.17,505,28,2,2,233.53,234.25,10,100,1,1,233.5,234.41,100,600,1,2,233.45,234.43,15,105,1,2,233.4,234.5,110,63,2,4,233.39,234.75,10,1,1,1,233.31,234.79,110,2000,2,1,AAPL,5511,14.12370296287036,-0.18231372247669314
2024-10-21T12:16:51.768939105Z,2024-10-21T12:16:51.768772781Z,10,2,38,A,B,0,233.85,141,130,166324,12588253,233.85,234.09,141,400,1,2,233.7,234.1,1400,100,2,1,233.69,234.13,27,400,1,1,233.66,234.17,1,28,1,2,233.58,234.25,505,100,2,1,233.53,234.41,10,600,1,2,233.5,234.43,100,105,1,2,233.45,234.5,15,63,1,4,233.4,234.75,110,1,2,1,233.39,234.79,10,2000,1,1,AAPL,5521,13.637710992177851,-0.17604036728764233
2024-10-21T12:16:54.799926585Z,2024-10-21T12:16:54.799759269Z,10,2,38,T,N,0,233.86,13,130,167316,12591024,233.85,234.09,141,400,1,2,233.7,234.1,1400,100,2,1,233.69,234.13,27,400,1,1,233.66,234.17,1,28,1,2,233.58,234.25,505,100,2,1,233.53,234.41,10,600,1,2,233.5,234.43,100,105,1,2,233.45,234.5,15,63,1,4,233.4,234.75,110,1,2,1,233.39,234.79,10,2000,1,1,AAPL,5310,12.16902825521925,-0.157082094261362
2024-10-21T12:16:54.862694065Z,2024-10-21T12:16:54.862528040Z,10,2,38,C,A,3,234.17,27,130,166025,12591058,233.85,234.09,141,400,1,2,233.7,234.1,1400,100,2,1,233.69,234.13,27,400,1,1,233.66,234.17,1,1,1,1,233.58,234.25,505,100,2,1,233.53,234.41,10,600,1,2,233.5,234.43,100,105,1,2,233.45,234.5,15,63,1,4,233.4,234.75,110,1,2,1,233.39,234.79,10,2000,1,1,AAPL,5310,11.802810192903072,-0.15235482278343687
2024-10-21T12:16:54.862819345Z,2024-10-21T12:16:54.862652964Z,10,2,38,A,A,3,234.16,30,130,166381,12591059,233.85,234.09,141,400,1,2,233.7,234.1,1400,100,2,1,233.69,234.13,27,400,1,1,233.66,234.16,1,30,1,1,233.58,234.17,505,1,2,1,233.53,234.25,10,100,1,1,233.5,234.41,100,600,1,2,233.45,234.43,15,105,1,2,233.4,234.5,110,63,2,4,233.39,234.75,10,1,1,1,AAPL,5309,12.078038199037088,-0.15590756263218916
2024-10-21T12:17:02.456671669Z,2024-10-21T12:17:02.456505763Z,10,2,38,C,A,0,234.09,200,130,165906,12600010,233.85,234.09,141,200,1,1,233.7,234.1,1400,100,2,1,233.69,234.13,27,400,1,1,233.66,234.16,1,30,1,1,233.58,234.17,505,1,2,1,233.53,234.25,10,100,1,1,233.5,234.41,100,600,1,2,233.45,234.43,15,105,1,2,233.4,234.5,110,63,2,4,233.39,234.75,10,1,1,1,AAPL,7609,20.520645796129596,-0.2648877091619157
2024-10-21T12:17:02.456684400Z,2024-10-21T12:17:02.456518211Z,10,2,38,A,A,0,234.08,400,130,166189,12600011,233.85,234.08,141,400,1,1,233.7,234.1,1400,100,2,1,233.69,234.13,27,400,1,1,233.66,234.16,1,30,1,1,233.58,234.17,505,1,2,1,233.53,234.25,10,100,1,1,233.5,234.41,100,600,1,2,233.45,234.43,15,105,1,2,233.4,234.5,110,63,2,4,233.39,234.75,10,1,1,1,AAPL,7609,21.06681238615665,-0.27193781948935614
2024-10-21T12:17:02.692870111Z,2024-10-21T12:17:02.692703742Z,10,2,38,A,B,1,233.7,200,130,166369,12600199,233.85,234.08,141,400,1,1,233.7,234.1,1600,100,3,1,233.69,234.13,27,400,1,1,233.66,234.16,1,30,1,1,233.58,234.17,505,1,2,1,233.53,234.25,10,100,1,1,233.5,234.41,100,600,1,2,233.45,234.43,15,105,1,2,233.4,234.5,110,63,2,4,233.39,234.75,10,1,1,1,AAPL,7610,21.0695810564663,-0.27197355845893023
2024-10-21T12:17:02.695901737Z,2024-10-21T12:17:02.695735412Z,10,2,38,A,B,1,233.73,27,130,166325,12600202,233.85,234.08,141,400,1,1,233.73,234.1,27,100,1,1,233.7,234.13,1600,400,3,1,233.69,234.16,27,30,1,1,233.66,234.17,1,1,1,1,233.58,234.25,505,100,2,1,233.53,234.41,10,600,1,2,233.5,234.43,100,105,1,2,233.45,234.5,15,63,1,4,233.4,234.75,110,1,2,1,AAPL,7720,21.848263851093936,-0.2820250696872765
2024-10-21T12:17:02.695928779Z,2024-10-21T12:17:02.695762734Z,10,2,38,C,B,3,233.69,27,130,166045,12600203,233.85,234.08,141,400,1,1,233.73,234.1,27,100,1,1,233.7,234.13,1600,400,3,1,233.66,234.16,1,30,1,1,233.58,234.17,505,1,2,1,233.53,234.25,10,100,1,1,233.5,234.41,100,600,1,2,233.45,234.43,15,105,1,2,233.4,234.5,110,63,2,4,233.39,234.75,10,1,1,1,AAPL,7710,22.370520818221387,-0.2887665461978419
2024-10-21T12:17:02.744107650Z,2024-10-21T12:17:02.743941560Z,10,2,38,C,B,2,233.7,200,130,166090,12600243,233.85,234.08,141,400,1,1,233.73,234.1,27,100,1,1,233.7,234.13,1400,400,2,1,233.66,234.16,1,30,1,1,233.58,234.17,505,1,2,1,233.53,234.25,10,100,1,1,233.5,234.41,100,600,1,2,233.45,234.43,15,105,1,2,233.4,234.5,110,63,2,4,233.39,234.75,10,1,1,1,AAPL,7710,22.920639524344704,-0.29586767182906387
2024-10-21T12:17:02.744120623Z,2024-10-21T12:17:02.743954174Z,10,2,38,A,B,1,233.77,200,130,166449,12600244,233.85,234.08,141,400,1,1,233.77,234.1,200,100,1,1,233.73,234.13,27,400,1,1,233.7,234.16,1200,30,1,1,233.66,234.17,1,1,1,1,233.58,234.25,505,100,2,1,233.53,234.41,10,600,1,2,233.5,234.43,100,105,1,2,233.45,234.5,15,63,1,4,233.4,234.75,110,1,2,1,AAPL,7820,23.719217158951395,-0.30617599264510775
2024-10-21T12:17:04.308892470Z,2024-10-21T12:17:04.308725875Z,10,2,38,C,A,3,234.16,30,130,166595,12602099,233.85,234.08,141,400,1,1,233.77,234.1,200,100,1,1,233.73,234.13,27,400,1,1,233.7,234.17,1200,1,1,1,233.66,234.25,1,100,1,1,233.58,234.41,505,600,2,2,233.53,234.43,10,105,1,2,233.5,234.5,100,63,1,4,233.45,234.75,15,1,1,1,233.4,234.79,110,2000,2,1,AAPL,9820,28.33579385317407,-0.3657683873899935
2024-10-21T12:17:04.308942951Z,2024-10-21T12:17:04.308776780Z,10,2,38,A,A,3,234.15,26,130,166171,12602100,233.85,234.08,141,400,1,1,233.77,234.1,200,100,1,1,233.73,234.13,27,400,1,1,233.7,234.15,1200,26,1,1,233.66,234.17,1,1,1,1,233.58,234.25,505,100,2,1,233.53,234.41,10,600,1,2,233.5,234.43,100,105,1,2,233.45,234.5,15,63,1,4,233.4,234.75,110,1,2,1,AAPL,9819,28.884238676249375,-0.3728479059504439
2024-10-21T12:17:06.048460890Z,2024-10-21T12:17:06.048294911Z,10,2,38,C,B,1,233.77,200,130,165979,12604816,233.85,234.08,141,400,1,1,233.73,234.1,27,100,1,1,233.7,234.13,1200,400,1,1,233.66,234.15,1,26,1,1,233.58,234.17,505,1,2,1,233.53,234.25,10,100,1,1,233.5,234.41,100,600,1,2,233.45,234.43,15,105,1,2,233.4,234.5,110,63,2,4,233.39,234.75,10,1,1,1,AAPL,9934,27.373748235768534,-0.3533499643912457
2024-10-21T12:17:06.048474822Z,2024-10-21T12:17:06.048308319Z,10,2,38,A,B,1,233.74,200,130,166503,12604817,233.85,234.08,141,400,1,1,233.74,234.1,200,100,1,1,233.73,234.13,27,400,1,1,233.7,234.15,1200,26,1,1,233.66,234.17,1,1,1,1,233.58,234.25,505,100,2,1,233.53,234.41,10,600,1,2,233.5,234.43,100,105,1,2,233.45,234.5,15,63,1,4,233.4,234.75,110,1,2,1,AAPL,10044,28.24654323880947,-0.364616309087234
2024-10-21T12:17:07.404034239Z,2024-10-21T12:17:07.403868087Z,10,2,38,A,B,1,233.74,200,130,166152,12606471,233.85,234.08,141,400,1,1,233.74,234.1,400,100,2,1,233.73,234.13,27,400,1,1,233.7,234.15,1200,26,1,1,233.66,234.17,1,1,1,1,233.58,234.25,505,100,2,1,233.53,234.41,10,600,1,2,233.5,234.43,100,105,1,2,233.45,234.5,15,63,1,4,233.4,234.75,110,1,2,1,AAPL,10044,28.812008005336892,-0.37191552706045583
2024-10-21T12:17:07.458838488Z,2024-10-21T12:17:07.458672320Z,10,2,38,C,B,1,233.74,200,130,166168,12606559,233.85,234.08,141,400,1,1,233.74,234.1,200,100,1,1,233.73,234.13,27,400,1,1,233.7,234.15,1200,26,1,1,233.66,234.17,1,1,1,1,233.58,234.25,505,100,2,1,233.53,234.41,10,600,1,2,233.5,234.43,100,105,1,2,233.45,234.5,15,63,1,4,233.4,234.75,110,1,2,1,AAPL,10044,29.373300987006083,-0.37916089416830073
2024-10-21T12:17:07.458851802Z,2024-10-21T12:17:07.458684918Z,10,2,38,A,B,1,233.77,200,130,166884,12606560,233.85,234.08,141,400,1,1,233.77,234.1,200,100,1,1,233.73,234.13,27,400,1,1,233.7,234.15,1200,26,1,1,233.66,234.17,1,1,1,1,233.58,234.25,505,100,2,1,233.53,234.41,10,600,1,2,233.5,234.43,100,105,1,2,233.45,234.5,15,63,1,4,233.4,234.75,110,1,2,1,AAPL,10044,29.93046818091517,-0.38635300415747986
2024-10-21T12:17:10.980236242Z,2024-10-21T12:17:10.980069944Z,10,2,38,C,B,1,233.77,200,130,166298,12610019,233.85,234.08,141,400,1,1,233.73,234.1,27,100,1,1,233.7,234.13,1200,400,1,1,233.66,234.15,1,26,1,1,233.58,234.17,505,1,2,1,233.53,234.25,10,100,1,1,233.5,234.41,100,600,1,2,233.45,234.43,15,105,1,2,233.4,234.5,110,63,2,4,233.39,234.75,10,1,1,1,AAPL,2198,7.910031488978857,-0.10210546692002333
2024-10-21T12:17:10.980249439Z,2024-10-21T12:17:10.980083268Z,10,2,38,A,B,1,233.74,200,130,166171,12610020,233.85,234.08,141,400,1,1,233.74,234.1,200,100,1,1,233.73,234.13,27,400,1,1,233.7,234.15,1200,26,1,1,233.66,234.17,1,1,1,1,233.58,234.25,505,100,2,1,233.53,234.41,10,600,1,2,233.5,234.43,100,105,1,2,233.45,234.5,15,63,1,4,233.4,234.75,110,1,2,1,AAPL,2308,8.634954569748798,-0.11146302886478268
2024-10-21T12:17:16.047057825Z,2024-10-21T12:17:16.046891679Z,10,2,38,A,B,1,233.74,200,130,166146,12615898,233.85,234.08,141,400,1,1,233.74,234.1,400,100,2,1,233.73,234.13,27,400,1,1,233.7,234.15,1200,26,1,1,233.66,234.17,1,1,1,1,233.58,234.25,505,100,2,1,233.53,234.41,10,600,1,2,233.5,234.43,100,105,1,2,233.45,234.5,15,63,1,4,233.4,234.75,110,1,2,1,AAPL,2409,25.708097928436914,-0.3318491647303924
2024-10-21T12:17:16.101486118Z,2024-10-21T12:17:16.101320234Z,10,2,38,C,B,1,233.74,200,130,165884,12616034,233.85,234.08,141,400,1,1,233.74,234.1,200,100,1,1,233.73,234.13,27,400,1,1,233.7,234.15,1200,26,1,1,233.66,234.17,1,1,1,1,233.58,234.25,505,100,2,1,233.53,234.41,10,600,1,2,233.5,234.43,100,105,1,2,233.45,234.5,15,63,1,4,233.4,234.75,110,1,2,1,AAPL,2409,26.303912647861694,-0.3395401505639448
2024-10-21T12:17:16.101498861Z,2024-10-21T12:17:16.101332500Z,10,2,38,A,B,1,233.77,200,130,166361,12616035,233.85,234.08,141,400,1,1,233.77,234.1,200,100,1,1,233.73,234.13,27,400,1,1,233.7,234.15,1200,26,1,1,233.66,234.17,1,1,1,1,233.58,234.25,505,100,2,1,233.53,234.41,10,600,1,2,233.5,234.43,100,105,1,2,233.45,234.5,15,63,1,4,233.4,234.75,110,1,2,1,AAPL,2409,26.860915492957744,-0.34673013908087497
2024-10-21T12:17:18.814393783Z,2024-10-21T12:17:18.814227520Z,10,2,38,A,B,0,233.9,10,130,166263,12619312,233.9,234.08,10,400,1,1,233.85,234.1,141,100,1,1,233.77,234.13,200,400,1,1,233.73,234.15,27,26,1,1,233.7,234.17,1200,1,1,1,233.66,234.25,1,100,1,1,233.58,234.41,505,600,2,2,233.53,234.43,10,105,1,2,233.5,234.5,100,63,1,4,233.45,234.75,15,1,1,1,AAPL,2424,28.317757009345797,-0.3655355614697155
2024-10-21T12:17:20.656989311Z,2024-10-21T12:17:20.656823195Z,10,2,38,C,B,2,233.77,200,130,166116,12621045,233.9,234.08,10,400,1,1,233.85,234.1,141,100,1,1,233.73,234.13,27,400,1,1,233.7,234.15,1200,26,1,1,233.66,234.17,1,1,1,1,233.58,234.25,505,100,2,1,233.53,234.41,10,600,1,2,233.5,234.43,100,105,1,2,233.45,234.5,15,63,1,4,233.4,234.75,110,1,2,1,AAPL,2314,27.493069306930693,-0.3548902027204337
2024-10-21T12:17:20.662449680Z,2024-10-21T12:17:20.662283454Z,10,2,38,A,A,0,234.05,100,130,166226,12621054,233.9,234.05,10,100,1,1,233.85,234.08,141,400,1,1,233.73,234.1,27,100,1,1,233.7,234.13,1200,400,1,1,233.66,234.15,1,26,1,1,233.58,234.17,505,1,2,1,233.53,234.25,10,100,1,1,233.5,234.41,100,600,1,2,233.45,234.43,15,105,1,2,233.4,234.5,110,63,2,4,AAPL,2251,26.7108953613808,-0.34479362648880624
2024-10-21T12:17:20.662910009Z,2024-10-21T12:17:20.662744252Z,10,2,38,C,A,0,234.05,100,130,165757,12621055,233.9,234.08,10,400,1,1,233.85,234.1,141,100,1,1,233.73,234.13,27,400,1,1,233.7,234.15,1200,26,1,1,233.66,234.17,1,1,1,1,233.58,234.25,505,100,2,1,233.53,234.41,10,600,1,2,233.5,234.43,100,105,1,2,233.45,234.5,15,63,1,4,233.4,234.75,110,1,2,1,AAPL,2252,27.125425504058654,-0.35014452728225054
2024-10-21T12:17:20.719927826Z,2024-10-21T12:17:20.719761250Z,10,2,38,C,A,0,234.08,200,130,166576,12621104,233.9,234.08,10,200,1,1,233.85,234.1,141,100,1,1,233.73,234.13,27,400,1,1,233.7,234.15,1200,26,1,1,233.66,234.17,1,1,1,1,233.58,234.25,505,100,2,1,233.53,234.41,10,600,1,2,233.5,234.43,100,105,1,2,233.45,234.5,15,63,1,4,233.4,234.75,110,1,2,1,AAPL,2252,27.50534351145038,-0.35504864246688744
2024-10-21T12:17:20.762706336Z,2024-10-21T12:17:20.762539880Z,10,2,38,A,B,2,233.77,200,130,166456,12621151,233.9,234.08,10,200,1,1,233.85,234.1,141,100,1,1,233.77,234.13,200,400,1,1,233.73,234.15,27,26,1,1,233.7,234.17,1200,1,1,1,233.66,234.25,1,100,1,1,233.58,234.41,505,600,2,2,233.53,234.43,10,105,1,2,233.5,234.5,100,63,1,4,233.45,234.75,15,1,1,1,AAPL,2267,28.72529143436391,-0.37079615908053865
2024-10-21T12:17:21.079070269Z,2024-10-21T12:17:21.078904005Z,10,2,38,A,B,2,233.77,200,130,166264,12621965,233.9,234.08,10,200,1,1,233.85,234.1,141,100,1,1,233.77,234.13,400,400,2,1,233.73,234.15,27,26,1,1,233.7,234.17,1200,1,1,1,233.66,234.25,1,100,1,1,233.58,234.41,505,600,2,2,233.53,234.43,10,105,1,2,233.5,234.5,100,63,1,4,233.45,234.75,15,1,1,1,AAPL,2267,29.753659767794044,-0.3840706990108727
2024-10-21T12:17:21.133776008Z,2024-10-21T12:17:21.133609901Z,10,2,38,C,B,2,233.77,200,130,166107,12622031,233.9,234.08,10,200,1,1,233.85,234.1,141,100,1,1,233.77,234.13,200,400,1,1,233.73,234.15,27,26,1,1,233.7,234.17,1200,1,1,1,233.66,234.25,1,100,1,1,233.58,234.41,505,600,2,2,233.53,234.43,10,105,1,2,233.5,234.5,100,63,1,4,233.45,234.75,15,1,1,1,AAPL,2267,30.773755656108595,-0.3972384553118024
2024-10-21T12:17:21.133789577Z,2024-10-21T12:17:21.133623109Z,10,2,38,A,B,2,233.8,400,130,166468,12622032,233.9,234.08,10,200,1,1,233.85,234.1,141,100,1,1,233.8,234.13,400,400,1,1,233.73,234.15,27,26,1,1,233.7,234.17,1200,1,1,1,233.66,234.25,1,100,1,1,233.58,234.41,505,600,2,2,233.53,234.43,10,105,1,2,233.5,234.5,100,63,1,4,233.45,234.75,15,1,1,1,AAPL,2267,31.785678517776667,-0.41030071131187335
2024-10-21T12:17:21.840377137Z,2024-10-21T12:17:21.840211165Z,10,2,38,C,A,0,234.08,200,130,165972,12622599,233.9,234.1,10,100,1,1,233.85,234.13,141,400,1,1,233.8,234.15,400,26,1,1,233.73,234.17,27,1,1,1,233.7,234.25,1200,100,1,1,233.66,234.41,1,600,1,2,233.58,234.43,505,105,2,2,233.53,234.5,10,63,1,4,233.5,234.75,100,1,1,1,233.45,234.79,15,2000,1,1,AAPL,4267,41.1858878349143,-0.5316419174511422
2024-10-21T12:17:21.840390874Z,2024-10-21T12:17:21.840224418Z,10,2,38,A,A,2,234.14,200,130,166456,12622600,233.9,234.1,10,100,1,1,233.85,234.13,141,400,1,1,233.8,234.14,400,200,1,1,233.73,234.15,27,26,1,1,233.7,234.17,1200,1,1,1,233.66,234.25,1,100,1,1,233.58,234.41,505,600,2,2,233.53,234.43,10,105,1,2,233.5,234.5,100,63,1,4,233.45,234.75,15,1,1,1,AAPL,4266,42.48298755186722,-0.5483853365419309
2024-10-21T12:17:22.072471402Z,2024-10-21T12:17:22.072304747Z,10,2,38,A,A,1,234.13,200,130,166655,12622909,233.9,234.1,10,100,1,1,233.85,234.13,141,600,1,2,233.8,234.15,400,26,1,1,233.73,234.17,27,1,1,1,233.7,234.25,1200,100,1,1,233.66,234.41,1,600,1,2,233.58,234.43,505,105,2,2,233.53,234.5,10,63,1,4,233.5,234.75,100,1,1,1,233.45,234.79,15,2000,1,1,AAPL,6266,48.319900497512435,-0.6237302605813637
2024-10-21T12:17:22.085874150Z,2024-10-21T12:17:22.085707892Z,10,2,38,A,A,0,234.0,50,130,166258,12622918,233.9,234.0,10,50,1,1,233.85,234.1,141,100,1,1,233.8,234.13,400,600,1,2,233.73,234.15,27,26,1,1,233.7,234.17,1200,1,1,1,233.66,234.25,1,100,1,1,233.58,234.41,505,600,2,2,233.53,234.43,10,105,1,2,233.5,234.5,100,63,1,4,233.45,234.75,15,1,1,1,AAPL,6265,49.77159880834161,-0.6424692926649588
2024-10-21T12:17:24.840534781Z,2024-10-21T12:17:24.840366131Z,10,2,38,A,A,2,234.13,200,130,168650,12624574,233.9,234.0,10,50,1,1,233.85,234.1,141,100,1,1,233.8,234.13,400,800,1,3,233.73,234.15,27,26,1,1,233.7,234.17,1200,1,1,1,233.66,234.25,1,100,1,1,233.58,234.41,505,600,2,2,233.53,234.43,10,105,1,2,233.5,234.5,100,63,1,4,233.45,234.75,15,1,1,1,AAPL,4056,34.927879440258344,-0.45086134533634525
2024-10-21T12:17:24.840961517Z,2024-10-21T12:17:24.840795392Z,10,2,38,A,A,1,234.1,28,130,166125,12624575,233.9,234.0,10,50,1,1,233.85,234.1,141,128,1,2,233.8,234.13,400,800,1,3,233.73,234.15,27,26,1,1,233.7,234.17,1200,1,1,1,233.66,234.25,1,100,1,1,233.58,234.41,505,600,2,2,233.53,234.43,10,105,1,2,233.5,234.5,100,63,1,4,233.45,234.75,15,1,1,1,AAPL,4056,36.27906976744186,-0.4683029850374158
2024-10-21T12:17:24.840987330Z,2024-10-21T12:17:24.840821231Z,10,2,38,C,A,3,234.15,26,130,166099,12624576,233.9,234.0,10,50,1,1,233.85,234.1,141,128,1,2,233.8,234.13,400,800,1,3,233.73,234.17,27,1,1,1,233.7,234.25,1200,100,1,1,233.66,234.41,1,600,1,2,233.58,234.43,505,105,2,2,233.53,234.5,10,63,1,4,233.5,234.75,100,1,1,1,233.45,234.79,15,2000,1,1,AAPL,6056,41.40854700854701,-0.5345160803314635
2024-10-21T12:17:24.896181576Z,2024-10-21T12:17:24.896015668Z,10,2,38,C,A,2,234.13,200,130,165908,12624585,233.9,234.0,10,50,1,1,233.85,234.1,141,128,1,2,233.8,234.13,400,600,1,2,233.73,234.17,27,1,1,1,233.7,234.25,1200,100,1,1,233.66,234.41,1,600,1,2,233.58,234.43,505,105,2,2,233.53,234.5,10,63,1,4,233.5,234.75,100,1,1,1,233.45,234.79,15,2000,1,1,AAPL,6056,33.994178794178794,-0.4388088091910325
2024-10-21T12:17:24.896197156Z,2024-10-21T12:17:24.896030774Z,10,2,38,A,A,1,234.04,200,130,166382,12624586,233.9,234.0,10,50,1,1,233.85,234.04,141,200,1,1,233.8,234.1,400,128,1,2,233.73,234.13,27,400,1,1,233.7,234.17,1200,1,1,1,233.66,234.25,1,100,1,1,233.58,234.41,505,600,2,2,233.53,234.43,10,105,1,2,233.5,234.5,100,63,1,4,233.45,234.75,15,1,1,1,AAPL,6055,35.18887505188875,-0.4542303684340067
2024-10-21T12:17:26.219893772Z,2024-10-21T12:17:26.219727754Z,10,2,38,C,A,2,234.1,28,130,166018,12625936,233.9,234.0,10,50,1,1,233.85,234.04,141,200,1,1,233.8,234.1,400,100,1,1,233.73,234.13,27,400,1,1,233.7,234.17,1200,1,1,1,233.66,234.25,1,100,1,1,233.58,234.41,505,600,2,2,233.53,234.43,10,105,1,2,233.5,234.5,100,63,1,4,233.45,234.75,15,1,1,1,AAPL,5955,33.742917103882476,-0.43556543497152833
2024-10-21T12:17:26.219990353Z,2024-10-21T12:17:26.219824269Z,10,2,38,A,A,2,234.09,27,130,166084,12625937,233.9,234.0,10,50,1,1,233.85,234.04,141,200,1,1,233.8,234.09,400,27,1,1,233.73,234.1,27,100,1,1,233.7,234.13,1200,400,1,1,233.66,234.17,1,1,1,1,233.58,234.25,505,100,2,1,233.53,234.41,10,600,1,2,233.5,234.43,100,105,1,2,233.45,234.5,15,63,1,4,AAPL,5892,34.3413821815154,-0.4432906325604606
2024-10-21T12:17:26.287111991Z,2024-10-21T12:17:26.286945437Z,10,2,38,A,A,1,234.03,200,130,166554,12626109,233.9,234.0,10,50,1,1,233.85,234.03,141,200,1,1,233.8,234.09,400,27,1,1,233.73,234.1,27,100,1,1,233.7,234.13,1200,400,1,1,233.66,234.17,1,1,1,1,233.58,234.25,505,100,2,1,233.53,234.41,10,600,1,2,233.5,234.43,100,105,1,2,233.45,234.5,15,63,1,4,AAPL,5892,35.2814371257485,-0.45542519221994293
2024-10-21T12:17:30.761811610Z,2024-10-21T12:17:30.761645371Z,10,2,38,C,A,1,234.03,200,130,166239,12633053,233.9,234.0,10,50,1,1,233.85,234.09,141,27,1,1,233.8,234.1,400,100,1,1,233.73,234.13,27,400,1,1,233.7,234.17,1200,1,1,1,233.66,234.25,1,100,1,1,233.58,234.41,505,600,2,2,233.53,234.43,10,105,1,2,233.5,234.5,100,63,1,4,233.45,234.75,15,1,1,1,AAPL,5893,33.96541786743516,-0.4384375530388536
2024-10-21T12:17:30.761824012Z,2024-10-21T12:17:30.761657680Z,10,2,38,A,A,1,234.08,200,130,166332,12633054,233.9,234.0,10,50,1,1,233.85,234.08,141,200,1,1,233.8,234.09,400,27,1,1,233.73,234.1,27,100,1,1,233.7,234.13,1200,400,1,1,233.66,234.17,1,1,1,1,233.58,234.25,505,100,2,1,233.53,234.41,10,600,1,2,233.5,234.43,100,105,1,2,233.45,234.5,15,63,1,4,AAPL,5830,34.55911929713136,-0.4461012597857457
2024-10-21T12:17:30.763106554Z,2024-10-21T12:17:30.762940179Z,10,2,38,A,A,1,234.08,200,130,166375,12633055,233.9,234.0,10,50,1,1,233.85,234.08,141,400,1,2,233.8,234.09,400,27,1,1,233.73,234.1,27,100,1,1,233.7,234.13,1200,400,1,1,233.66,234.17,1,1,1,1,233.58,234.25,505,100,2,1,233.53,234.41,10,600,1,2,233.5,234.43,100,105,1,2,233.45,234.5,15,63,1,4,AAPL,5830,35.500262467191604,-0.45824986664672773
2024-10-21T12:17:30.764758511Z,2024-10-21T12:17:30.764592400Z,10,2,38,C,A,2,234.09,27,130,166111,12633057,233.9,234.0,10,50,1,1,233.85,234.08,141,400,1,2,233.8,234.1,400,100,1,1,233.73,234.13,27,400,1,1,233.7,234.17,1200,1,1,1,233.66,234.25,1,100,1,1,233.58,234.41,505,600,2,2,233.53,234.43,10,105,1,2,233.5,234.5,100,63,1,4,233.45,234.75,15,1,1,1,AAPL,5831,36.669112252384444,-0.47333779053714076
2024-10-21T12:17:30.764858610Z,2024-10-21T12:17:30.764692359Z,10,2,38,A,A,4,234.15,29,130,166251,12633058,233.9,234.0,10,50,1,1,233.85,234.08,141,400,1,2,233.8,234.1,400,100,1,1,233.73,234.13,27,400,1,1,233.7,234.15,1200,29,1,1,233.66,234.17,1,1,1,1,233.58,234.25,505,100,2,1,233.53,234.41,10,600,1,2,233.5,234.43,100,105,1,2,233.45,234.5,15,63,1,4,AAPL,5768,37.178085040024946,-0.47990779018935814
2024-10-21T12:17:33.378449675Z,2024-10-21T12:17:33.378283593Z,10,2,38,C,B,2,233.8,400,130,166082,12636437,233.9,234.0,10,50,1,1,233.85,234.08,141,400,1,2,233.73,234.1,27,100,1,1,233.7,234.13,1200,400,1,1,233.66,234.15,1,29,1,1,233.58,234.17,505,1,2,1,233.53,234.25,10,100,1,1,233.5,234.41,100,600,1,2,233.45,234.43,15,105,1,2,233.4,234.5,110,63,2,4,AAPL,5558,34.48603929679421,-0.4451579174529956
2024-10-21T12:17:33.378463077Z,2024-10-21T12:17:33.378297030Z,10,2,38,A,B,2,233.77,200,130,166047,12636438,233.9,234.0,10,50,1,1,233.85,234.08,141,400,1,2,233.77,234.1,200,100,1,1,233.73,234.13,27,400,1,1,233.7,234.15,1200,29,1,1,233.66,234.17,1,1,1,1,233.58,234.25,505,100,2,1,233.53,234.41,10,600,1,2,233.5,234.43,100,105,1,2,233.45,234.5,15,63,1,4,AAPL,5573,35.445835043085765,-0.45754729832455054
2024-10-21T12:17:33.764976450Z,2024-10-21T12:17:33.764809990Z,10,2,38,A,A,2,234.09,29,130,166460,12637750,233.9,234.0,10,50,1,1,233.85,234.08,141,400,1,2,233.77,234.09,200,29,1,1,233.73,234.1,27,100,1,1,233.7,234.13,1200,400,1,1,233.66,234.15,1,29,1,1,233.58,234.17,505,1,2,1,233.53,234.25,10,100,1,1,233.5,234.41,100,600,1,2,233.45,234.43,15,105,1,2,AAPL,5468,35.46331576813944,-0.45777294566820426
2024-10-21T12:17:33.765000603Z,2024-10-21T12:17:33.764834502Z,10,2,38,C,A,5,234.15,29,130,166101,12637751,233.9,234.0,10,50,1,1,233.85,234.08,141,400,1,2,233.77,234.09,200,29,1,1,233.73,234.1,27,100,1,1,233.7,234.13,1200,400,1,1,233.66,234.17,1,1,1,1,233.58,234.25,505,100,2,1,233.53,234.41,10,600,1,2,233.5,234.43,100,105,1,2,233.45,234.5,15,63,1,4,AAPL,5531,36.70279509350493,-0.4737725804902013
2024-10-21T12:17:33.822988558Z,2024-10-21T12:17:33.822822391Z,10,2,38,C,A,1,234.08,200,130,166167,12637806,233.9,234.0,10,50,1,1,233.85,234.08,141,200,1,1,233.77,234.09,200,29,1,1,233.73,234.1,27,100,1,1,233.7,234.13,1200,400,1,1,233.66,234.17,1,1,1,1,233.58,234.25,505,100,2,1,233.53,234.41,10,600,1,2,233.5,234.43,100,105,1,2,233.45,234.5,15,63,1,4,AAPL,5531,37.52075019952115,-0.48433103251858706
2024-10-21T12:17:33.823002310Z,2024-10-21T12:17:33.822835795Z,10,2,38,A,A,1,234.03,200,130,166515,12637807,233.9,234.0,10,50,1,1,233.85,234.03,141,200,1,1,233.77,234.09,200,29,1,1,233.73,234.1,27,100,1,1,233.7,234.13,1200,400,1,1,233.66,234.17,1,1,1,1,233.58,234.25,505,100,2,1,233.53,234.41,10,600,1,2,233.5,234.43,100,105,1,2,233.45,234.5,15,63,1,4,AAPL,5531,38.32607404474361,-0.49472643579262415
2024-10-21T12:17:35.461566586Z,2024-10-21T12:17:35.461400679Z,10,2,38,C,A,1,234.03,200,130,165907,12639539,233.9,234.0,10,50,1,1,233.85,234.09,141,29,1,1,233.77,234.1,200,100,1,1,233.73,234.13,27,400,1,1,233.7,234.17,1200,1,1,1,233.66,234.25,1,100,1,1,233.58,234.41,505,600,2,2,233.53,234.43,10,105,1,2,233.5,234.5,100,63,1,4,233.45,234.75,15,1,1,1,AAPL,5532,39.36588258549121,-0.5081486499403667
2024-10-21T12:17:35.461578939Z,2024-10-21T12:17:35.461412055Z,10,2,38,A,A,1,234.08,400,130,166884,12639540,233.9,234.0,10,50,1,1,233.85,234.08,141,400,1,1,233.77,234.09,200,29,1,1,233.73,234.1,27,100,1,1,233.7,234.13,1200,400,1,1,233.66,234.17,1,1,1,1,233.58,234.25,505,100,2,1,233.53,234.41,10,600,1,2,233.5,234.43,100,105,1,2,233.45,234.5,15,63,1,4,AAPL,5469,39.69262455865045,-0.5123663501831885
2024-10-21T12:17:35.470157228Z,2024-10-21T12:17:35.469991264Z,10,2,38,C,A,2,234.09,29,130,165964,12639580,233.9,234.0,10,50,1,1,233.85,234.08,141,400,1,1,233.77,234.1,200,100,1,1,233.73,234.13,27,400,1,1,233.7,234.17,1200,1,1,1,233.66,234.25,1,100,1,1,233.58,234.41,505,600,2,2,233.53,234.43,10,105,1,2,233.5,234.5,100,63,1,4,233.45,234.75,15,1,1,1,AAPL,5470,40.70896983940462,-0.5254856923233503
2024-10-21T12:17:35.470212130Z,2024-10-21T12:17:35.470045707Z,10,2,38,A,A,4,234.15,28,130,166423,12639581,233.9,234.0,10,50,1,1,233.85,234.08,141,400,1,1,233.77,234.1,200,100,1,1,233.73,234.13,27,400,1,1,233.7,234.15,1200,28,1,1,233.66,234.17,1,1,1,1,233.58,234.25,505,100,2,1,233.53,234.41,10,600,1,2,233.5,234.43,100,105,1,2,233.45,234.5,15,63,1,4,AAPL,5407,40.986005830903785,-0.529061770282722
2024-10-21T12:17:37.663795596Z,2024-10-21T12:17:37.663629357Z,10,2,38,A,B,2,233.77,200,130,166239,12641761,233.9,234.0,10,50,1,1,233.85,234.08,141,400,1,1,233.77,234.1,400,100,2,1,233.73,234.13,27,400,1,1,233.7,234.15,1200,28,1,1,233.66,234.17,1,1,1,1,233.58,234.25,505,100,2,1,233.53,234.41,10,600,1,2,233.5,234.43,100,105,1,2,233.45,234.5,15,63,1,4,AAPL,5407,39.87224713502741,-0.5146849815383103
2024-10-21T12:17:37.718760543Z,2024-10-21T12:17:37.718594298Z,10,2,38,C,B,2,233.77,200,130,166245,12641892,233.9,234.0,10,50,1,1,233.85,234.08,141,400,1,1,233.77,234.1,200,100,1,1,233.73,234.13,27,400,1,1,233.7,234.15,1200,28,1,1,233.66,234.17,1,1,1,1,233.58,234.25,505,100,2,1,233.53,234.41,10,600,1,2,233.5,234.43,100,105,1,2,233.45,234.5,15,63,1,4,AAPL,5407,40.63403539998022,-0.5245184122390069
2024-10-21T12:17:37.718772651Z,2024-10-21T12:17:37.718605853Z,10,2,38,A,B,2,233.8,400,130,166798,12641893,233.9,234.0,10,50,1,1,233.85,234.08,141,400,1,1,233.8,234.1,400,100,1,1,233.73,234.13,27,400,1,1,233.7,234.15,1200,28,1,1,233.66,234.17,1,1,1,1,233.58,234.25,505,100,2,1,233.53,234.41,10,600,1,2,233.5,234.43,100,105,1,2,233.45,234.5,15,63,1,4,AAPL,5407,41.38416249632028,-0.5342013164762252
2024-10-21T12:17:38.521294530Z,2024-10-21T12:17:38.521127910Z,10,2,38,A,A,1,234.04,200,130,166620,12642639,233.9,234.0,10,50,1,1,233.85,234.04,141,200,1,1,233.8,234.1,400,100,1,1,233.73,234.13,27,400,1,1,233.7,234.15,1200,28,1,1,233.66,234.17,1,1,1,1,233.58,234.25,505,100,2,1,233.53,234.41,10,600,1,2,233.5,234.43,100,105,1,2,233.45,234.5,15,63,1,4,AAPL,5407,42.12289414743402,-0.5437371243008418
2024-10-21T12:17:39.973713394Z,2024-10-21T12:17:39.973547435Z,10,2,38,C,A,4,234.15,28,130,165959,12644151,233.9,234.0,10,50,1,1,233.85,234.04,141,200,1,1,233.8,234.1,400,100,1,1,233.73,234.13,27,400,1,1,233.7,234.17,1200,1,1,1,233.66,234.25,1,100,1,1,233.58,234.41,505,600,2,2,233.53,234.43,10,105,1,2,233.5,234.5,100,63,1,4,233.45,234.75,15,1,1,1,AAPL,5393,42.01382802609796,-0.5423292604687331
2024-10-21T12:17:39.973752037Z,2024-10-21T12:17:39.973585910Z,10,2,38,A,A,2,234.1,27,130,166127,12644152,233.9,234.0,10,50,1,1,233.85,234.04,141,200,1,1,233.8,234.1,400,127,1,2,233.73,234.13,27,400,1,1,233.7,234.17,1200,1,1,1,233.66,234.25,1,100,1,1,233.58,234.41,505,600,2,2,233.53,234.43,10,105,1,2,233.5,234.5,100,63,1,4,233.45,234.75,15,1,1,1,AAPL,5393,42.997180359747205,-0.5550227180502922
2024-10-21T12:17:47.136044765Z,2024-10-21T12:17:47.135873221Z,10,2,38,T,A,0,233.9,10,0,171544,12650095,233.9,234.0,10,50,1,1,233.85,234.04,141,200,1,1,233.8,234.1,400,127,1,2,233.73,234.13,27,400,1,1,233.7,234.17,1200,1,1,1,233.66,234.25,1,100,1,1,233.58,234.41,505,600,2,2,233.53,234.43,10,105,1,2,233.5,234.5,100,63,1,4,233.45,234.75,15,1,1,1,AAPL,-384,-11.906976744186046,0.1536994412430493
2024-10-21T12:17:47.136044765Z,2024-10-21T12:17:47.135873221Z,10,2,38,T,A,0,233.85,141,0,171544,12650096,233.85,234.0,141,50,1,1,233.8,234.04,400,200,1,1,233.73,234.1,27,127,1,2,233.7,234.13,1200,400,1,1,233.66,234.17,1,1,1,1,233.58,234.25,505,100,2,1,233.53,234.41,10,600,1,2,233.5,234.43,100,105,1,2,233.45,234.5,15,63,1,4,233.4,234.75,110,1,2,1,AAPL,-494,-14.852287581699347,0.19171854884178827
2024-10-21T12:17:47.136044765Z,2024-10-21T12:17:47.135873221Z,10,2,38,T,N,0,233.85,50,130,171544,12650097,233.8,234.0,400,50,1,1,233.73,234.04,27,200,1,1,233.7,234.1,1200,127,1,2,233.66,234.13,1,400,1,1,233.58,234.17,505,1,2,1,233.53,234.25,10,100,1,1,233.5,234.41,100,600,1,2,233.45,234.43,15,105,1,2,233.4,234.5,110,63,2,4,233.39,234.75,10,1,1,1,AAPL,-504,-15.698896820246594,0.20264687848511706
2024-10-21T12:17:47.136066911Z,2024-10-21T12:17:47.135900626Z,10,2,38,A,A,0,233.98,100,130,166285,12650098,233.8,233.98,400,100,1,1,233.73,234.0,27,50,1,1,233.7,234.04,1200,200,1,1,233.66,234.1,1,127,1,2,233.58,234.13,505,400,2,1,233.53,234.17,10,1,1,1,233.5,234.25,100,100,1,1,233.45,234.41,15,600,1,2,233.4,234.43,110,105,2,2,233.39,234.5,10,63,1,4,AAPL,-567,-17.565055762081784,0.22673591408106222
2024-10-21T12:17:47.136072149Z,2024-10-21T12:17:47.135905168Z,10,2,38,A,A,0,233.97,100,130,166981,12650099,233.8,233.97,400,100,1,1,233.73,233.98,27,100,1,1,233.7,234.0,1200,50,1,1,233.66,234.04,1,200,1,1,233.58,234.1,505,127,2,2,233.53,234.13,10,400,1,1,233.5,234.17,100,1,1,1,233.45,234.25,15,100,1,1,233.4,234.41,110,600,2,2,233.39,234.43,10,105,1,2,AAPL,-672,-20.210526315789473,0.2608845778993863
2024-10-21T12:17:47.136074817Z,2024-10-21T12:17:47.135906292Z,10,2,38,A,A,0,233.95,162,130,168525,12650101,233.8,233.95,400,162,1,1,233.73,233.97,27,200,1,2,233.7,233.98,1200,100,1,1,233.66,234.0,1,50,1,1,233.58,234.04,505,200,2,1,233.53,234.1,10,127,1,2,233.5,234.13,100,400,1,1,233.45,234.17,15,1,1,1,233.4,234.25,110,100,2,1,233.39,234.41,10,600,1,2,AAPL,-1272,-29.366395895681915,0.3790717608222752
2024-10-21T12:17:47.136079816Z,2024-10-21T12:17:47.135913885Z,10,2,38,A,A,0,233.92,100,130,165931,12650102,233.8,233.92,400,100,1,1,233.73,233.95,27,162,1,1,233.7,233.97,1200,200,1,2,233.66,233.98,1,100,1,1,233.58,234.0,505,50,2,1,233.53,234.04,10,200,1,1,233.5,234.1,100,127,1,2,233.45,234.13,15,400,1,1,233.4,234.17,110,1,2,1,233.39,234.25,10,100,1,1,AAPL,-1372,-31.372805226623115,0.40497119774030577
2024-10-21T12:17:47.136082565Z,2024-10-21T12:17:47.135916592Z,10,2,38,A,A,3,233.98,100,130,165973,12650103,233.8,233.92,400,100,1,1,233.73,233.95,27,162,1,1,233.7,233.97,1200,200,1,2,233.66,233.98,1,200,1,2,233.58,234.0,505,50,2,1,233.53,234.04,10,200,1,1,233.5,234.1,100,127,1,2,233.45,234.13,15,400,1,1,233.4,234.17,110,1,2,1,233.39,234.25,10,100,1,1,AAPL,-1372,-31.096522078937085,0.40140483775350655
2024-10-21T12:17:47.136093537Z,2024-10-21T12:17:47.135925594Z,10,2,38,A,A,2,233.97,100,130,167943,12650104,233.8,233.92,400,100,1,1,233.73,233.95,27,162,1,1,233.7,233.97,1200,300,1,3,233.66,233.98,1,200,1,2,233.58,234.0,505,50,2,1,233.53,234.04,10,200,1,1,233.5,234.1,100,127,1,2,233.45,234.13,15,400,1,1,233.4,234.17,110,1,2,1,233.39,234.25,10,100,1,1,AAPL,-1372,-30.84301236418134,0.39813244524407565
2024-10-21T12:17:47.136099687Z,2024-10-21T12:17:47.135933669Z,10,2,38,A,A,1,233.93,35,130,166018,12650105,233.8,233.92,400,100,1,1,233.73,233.93,27,35,1,1,233.7,233.95,1200,162,1,1,233.66,233.97,1,300,1,3,233.58,233.98,505,200,2,2,233.53,234.0,10,50,1,1,233.5,234.04,100,200,1,1,233.45,234.1,15,127,1,2,233.4,234.13,110,400,2,1,233.39,234.17,10,1,1,1,AAPL,-1373,-31.763432835820893,0.4100135562295942
2024-10-21T12:17:47.136103482Z,2024-10-21T12:17:47.135937314Z,10,2,38,C,A,4,233.98,100,130,166168,12650106,233.8,233.92,400,100,1,1,233.73,233.93,27,35,1,1,233.7,233.95,1200,162,1,1,233.66,233.97,1,300,1,3,233.58,233.98,505,100,2,1,233.53,234.0,10,50,1,1,233.5,234.04,100,200,1,1,233.45,234.1,15,127,1,2,233.4,234.13,110,400,2,1,233.39,234.17,10,1,1,1,AAPL,-1373,-32.65403195837978,0.42150972275865783
2024-10-21T12:17:47.136107460Z,2024-10-21T12:17:47.135940686Z,10,2,38,A,A,3,233.97,100,130,166774,12650107,233.8,233.92,400,100,1,1,233.73,233.93,27,35,1,1,233.7,233.95,1200,162,1,1,233.66,233.97,1,400,1,4,233.58,233.98,505,100,2,1,233.53,234.0,10,50,1,1,233.5,234.04,100,200,1,1,233.45,234.1,15,127,1,2,233.4,234.13,110,400,2,1,233.39,234.17,10,1,1,1,AAPL,-1373,-33.53737971872687,0.43291228615536054
2024-10-21T12:17:47.136114326Z,2024-10-21T12:17:47.135946914Z,10,2,38,A,A,0,233.97,35,130,167412,12650109,233.8,233.93,400,35,1,1,233.73,233.95,27,162,1,1,233.7,233.97,1200,435,1,5,233.66,233.98,1,100,1,1,233.58,234.0,505,50,2,1,233.53,234.04,10,200,1,1,233.5,234.1,100,127,1,2,233.45,234.13,15,400,1,1,233.4,234.17,110,1,2,1,233.39,234.25,10,100,1,1,AAPL,-1273,-30.783783783783786,0.39736790190882737
2024-10-21T12:17:47.136118512Z,2024-10-21T12:17:47.135952535Z,10,2,38,C,A,3,233.98,100,130,165977,12650110,233.8,233.93,400,35,1,1,233.73,233.95,27,162,1,1,233.7,233.97,1200,435,1,5,233.66,234.0,1,50,1,1,233.58,234.04,505,200,2,1,233.53,234.1,10,127,1,2,233.5,234.13,100,400,1,1,233.45,234.17,15,1,1,1,233.4,234.25,110,100,2,1,233.39,234.41,10,600,1,2,AAPL,-673,-13.766803039158386,0.177706732807296
2024-10-21T12:17:47.136124318Z,2024-10-21T12:17:47.135958456Z,10,2,38,C,B,0,233.8,400,130,165862,12650111,233.73,233.93,27,35,1,1,233.7,233.95,1200,162,1,1,233.66,233.97,1,435,1,5,233.58,234.0,505,50,2,1,233.53,234.04,10,200,1,1,233.5,234.1,100,127,1,2,233.45,234.13,15,400,1,1,233.4,234.17,110,1,2,1,233.39,234.25,10,100,1,1,233.31,234.41,110,600,2,2,AAPL,-783,-13.643756050338819,0.17611839902328638
2024-10-21T12:17:47.136134998Z,2024-10-21T12:17:47.135968023Z,10,2,38,C,A,1,233.95,162,128,166975,12650112,233.73,233.93,27,35,1,1,233.7,233.97,1200,435,1,5,233.66,234.0,1,50,1,1,233.58,234.04,505,200,2,1,233.53,234.1,10,127,1,2,233.5,234.13,100,400,1,1,233.45,234.17,15,1,1,1,233.4,234.25,110,100,2,1,233.39,234.41,10,600,1,2,233.31,234.43,110,105,2,2,AAPL,-678,-11.541752933057282,0.14898500390894115
2024-10-21T12:17:47.136176630Z,2024-10-21T12:17:47.136008874Z,10,2,38,C,A,1,233.97,100,130,167756,12650118,233.73,233.93,27,35,1,1,233.7,233.97,1200,335,1,4,233.66,234.0,1,50,1,1,233.58,234.04,505,200,2,1,233.53,234.1,10,127,1,2,233.5,234.13,100,400,1,1,233.45,234.17,15,1,1,1,233.4,234.25,110,100,2,1,233.39,234.41,10,600,1,2,233.31,234.43,110,105,2,2,AAPL,-678,-11.295046032441912,0.14580042451569578
2024-10-21T12:17:47.136220660Z,2024-10-21T12:17:47.136054541Z,10,2,38,C,A,1,233.97,100,130,166119,12650119,233.73,233.93,27,35,1,1,233.7,233.97,1200,235,1,3,233.66,234.0,1,50,1,1,233.58,234.04,505,200,2,1,233.53,234.1,10,127,1,2,233.5,234.13,100,400,1,1,233.45,234.17,15,1,1,1,233.4,234.25,110,100,2,1,233.39,234.41,10,600,1,2,233.31,234.43,110,105,2,2,AAPL,-678,-11.070546368013398,0.14290250393323028
2024-10-21T12:17:47.136384565Z,2024-10-21T12:17:47.136218636Z,10,2,38,C,A,1,233.97,100,130,165929,12650120,233.73,233.93,27,35,1,1,233.7,233.97,1200,135,1,2,233.66,234.0,1,50,1,1,233.58,234.04,505,200,2,1,233.53,234.1,10,127,1,2,233.5,234.13,100,400,1,1,233.45,234.17,15,1,1,1,233.4,234.25,110,100,2,1,233.39,234.41,10,600,1,2,233.31,234.43,110,105,2,2,AAPL,-678,-10.865384615384615,0.1402542039137576
2024-10-21T12:17:47.136391264Z,2024-10-21T12:17:47.136225295Z,10,2,38,C,A,1,233.97,100,130,165969,12650121,233.73,233.93,27,35,1,1,233.7,233.97,1200,35,1,1,233.66,234.0,1,50,1,1,233.58,234.04,505,200,2,1,233.53,234.1,10,127,1,2,233.5,234.13,100,400,1,1,233.45,234.17,15,1,1,1,233.4,234.25,110,100,2,1,233.39,234.41,10,600,1,2,233.31,234.43,110,105,2,2,AAPL,-678,-10.67716535433071,0.1378246035309996
2024-10-21T12:17:47.136731997Z,2024-10-21T12:17:47.136565013Z,10,2,38,A,A,0,233.92,100,130,166984,12650123,233.73,233.92,27,100,1,1,233.7,233.93,1200,35,1,1,233.66,233.97,1,35,1,1,233.58,234.0,505,50,2,1,233.53,234.04,10,200,1,1,233.5,234.1,100,127,1,2,233.45,234.13,15,400,1,1,233.4,234.17,110,1,2,1,233.39,234.25,10,100,1,1,233.31,234.41,110,600,2,2,AAPL,-1278,-18.14297786040223,0.23419593567195307
2024-10-21T12:17:47.137204585Z,2024-10-21T12:17:47.137037920Z,10,2,38,C,A,0,233.92,100,130,166665,12650124,233.73,233.93,27,35,1,1,233.7,233.97,1200,35,1,1,233.66,234.0,1,50,1,1,233.58,234.04,505,200,2,1,233.53,234.1,10,127,1,2,233.5,234.13,100,400,1,1,233.45,234.17,15,1,1,1,233.4,234.25,110,100,2,1,233.39,234.41,10,600,1,2,233.31,234.43,110,105,2,2,AAPL,-1173,-16.451076320939332,0.21235627587916167
2024-10-21T12:17:47.157056586Z,2024-10-21T12:17:47.156890091Z,10,2,38,A,B,0,233.8,200,130,166495,12650144,233.8,233.93,200,35,1,1,233.73,233.97,27,35,1,1,233.7,234.0,1200,50,1,1,233.66,234.04,1,200,1,1,233.58,234.1,505,127,2,2,233.53,234.13,10,400,1,1,233.5,234.17,100,1,1,1,233.45,234.25,15,100,1,1,233.4,234.41,110,600,2,2,233.39,234.43,10,105,1,2,AAPL,-1163,-16.382903793821036,0.2114762809357496
2024-10-21T12:17:47.189868393Z,2024-10-21T12:17:47.189701537Z,10,2,38,A,B,0,233.8,200,130,166856,12650170,233.8,233.93,400,35,2,1,233.73,233.97,27,35,1,1,233.7,234.0,1200,50,1,1,233.66,234.04,1,200,1,1,233.58,234.1,505,127,2,2,233.53,234.13,10,400,1,1,233.5,234.17,100,1,1,1,233.45,234.25,15,100,1,1,233.4,234.41,110,600,2,2,233.39,234.43,10,105,1,2,AAPL,-1163,-16.45237346746306,0.21237301990245078
2024-10-21T12:17:47.200204805Z,2024-10-21T12:17:47.200038724Z,10,2,38,C,B,0,233.8,200,130,166081,12650190,233.8,233.93,200,35,1,1,233.73,233.97,27,35,1,1,233.7,234.0,1200,50,1,1,233.66,234.04,1,200,1,1,233.58,234.1,505,127,2,2,233.53,234.13,10,400,1,1,233.5,234.17,100,1,1,1,233.45,234.25,15,100,1,1,233.4,234.41,110,600,2,2,233.39,234.43,10,105,1,2,AAPL,-1163,-16.519376254438782,0.2132379154289264
2024-10-21T12:17:47.200214033Z,2024-10-21T12:17:47.200048226Z,10,2,38,C,B,0,233.8,200,130,165807,12650191,233.73,233.93,27,35,1,1,233.7,233.97,1200,35,1,1,233.66,234.0,1,50,1,1,233.58,234.04,505,200,2,1,233.53,234.1,10,127,1,2,233.5,234.13,100,400,1,1,233.45,234.17,15,1,1,1,233.4,234.25,110,100,2,1,233.39,234.41,10,600,1,2,233.31,234.43,110,105,2,2,AAPL,-1273,-17.881350866706516,0.23081876247265506
2024-10-21T12:17:47.200225833Z,2024-10-21T12:17:47.200058794Z,10,2,38,A,B,2,233.69,400,130,167039,12650192,233.73,233.93,27,35,1,1,233.7,233.97,1200,35,1,1,233.69,234.0,400,50,1,1,233.66,234.04,1,200,1,1,233.58,234.1,505,127,2,2,233.53,234.13,10,400,1,1,233.5,234.17,100,1,1,1,233.45,234.25,15,100,1,1,233.4,234.41,110,600,2,2,233.39,234.43,10,105,1,2,AAPL,-1263,-17.81225209343323,0.22992681121828898
2024-10-21T12:17:47.203824313Z,2024-10-21T12:17:47.203657195Z,10,2,38,C,B,0,233.73,27,130,167118,12650207,233.7,233.93,1200,35,1,1,233.69,233.97,400,35,1,1,233.66,234.0,1,50,1,1,233.58,234.04,505,200,2,1,233.53,234.1,10,127,1,2,233.5,234.13,100,400,1,1,233.45,234.17,15,1,1,1,233.4,234.25,110,100,2,1,233.39,234.41,10,600,1,2,233.31,234.43,110,105,2,2,AAPL,-1373,-19.16177727143264,0.24734695658837347
2024-10-21T12:17:47.203896270Z,2024-10-21T12:17:47.203729908Z,10,2,38,A,B,2,233.67,28,130,166362,12650208,233.7,233.93,1200,35,1,1,233.69,233.97,400,35,1,1,233.67,234.0,28,50,1,1,233.66,234.04,1,200,1,1,233.58,234.1,505,127,2,2,233.53,234.13,10,400,1,1,233.5,234.17,100,1,1,1,233.45,234.25,15,100,1,1,233.4,234.41,110,600,2,2,233.39,234.43,10,105,1,2,AAPL,-1363,-19.09766008126664,0.24651930935983576
2024-10-21T12:17:47.207242623Z,2024-10-21T12:17:47.207076580Z,10,2,38,C,B,1,233.69,400,130,166043,12650217,233.7,233.93,1200,35,1,1,233.67,233.97,28,35,1,1,233.66,234.0,1,50,1,1,233.58,234.04,505,200,2,1,233.53,234.1,10,127,1,2,233.5,234.13,100,400,1,1,233.45,234.17,15,1,1,1,233.4,234.25,110,100,2,1,233.39,234.41,10,600,1,2,233.31,234.43,110,105,2,2,AAPL,-1473,-20.4360718171926,0.26379599851314295
2024-10-21T12:17:47.240203878Z,2024-10-21T12:17:47.240037346Z,10,2,38,A,B,1,233.68,200,130,166532,12650248,233.7,233.93,1200,35,1,1,233.68,233.97,200,35,1,1,233.67,234.0,28,50,1,1,233.66,234.04,1,200,1,1,233.58,234.1,505,127,2,2,233.53,234.13,10,400,1,1,233.5,234.17,100,1,1,1,233.45,234.25,15,100,1,1,233.4,234.41,110,600,2,2,233.39,234.43,10,105,1,2,AAPL,-1463,-20.376590330788805,0.263028190578267
2024-10-21T12:17:47.240232077Z,2024-10-21T12:17:47.240066169Z,10,2,38,C,A,1,233.97,35,130,165908,12650249,233.7,233.93,1200,35,1,1,233.68,234.0,200,50,1,1,233.67,234.04,28,200,1,1,233.66,234.1,1,127,1,2,233.58,234.13,505,400,2,1,233.53,234.17,10,1,1,1,233.5,234.25,100,100,1,1,233.45,234.41,15,600,1,2,233.4,234.43,110,105,2,2,233.39,234.5,10,63,1,4,AAPL,-1400,-19.681697612732094,0.2540582711114022
2024-10-21T12:17:47.260251805Z,2024-10-21T12:17:47.260085243Z,10,2,38,A,A,2,234.03,200,130,166562,12650278,233.7,233.93,1200,35,1,1,233.68,234.0,200,50,1,1,233.67,234.03,28,200,1,1,233.66,234.1,1,127,1,2,233.58,234.13,505,400,2,1,233.53,234.17,10,1,1,1,233.5,234.25,100,100,1,1,233.45,234.41,15,600,1,2,233.4,234.43,110,105,2,2,233.39,234.5,10,63,1,4,AAPL,-1400,-19.860764481807433,0.25636972920133766
2024-10-21T12:17:47.386630077Z,2024-10-21T12:17:47.386463721Z,10,2,38,C,A,0,233.93,35,130,166356,12650325,233.7,234.0,1200,50,1,1,233.68,234.03,200,200,1,1,233.67,234.1,28,127,1,2,233.66,234.13,1,400,1,1,233.58,234.17,505,1,2,1,233.53,234.25,10,100,1,1,233.5,234.41,100,600,1,2,233.45,234.43,15,105,1,2,233.4,234.5,110,63,2,4,233.39,234.75,10,1,1,1,AAPL,-1399,-20.184942287513117,0.2605543302693367
2024-10-21T12:17:57.664077159Z,2024-10-21T12:17:57.663911195Z,10,2,38,C,A,2,234.1,27,130,165964,12660246,233.7,234.0,1200,50,1,1,233.68,234.03,200,200,1,1,233.67,234.1,28,100,1,1,233.66,234.13,1,400,1,1,233.58,234.17,505,1,2,1,233.53,234.25,10,100,1,1,233.5,234.41,100,600,1,2,233.45,234.43,15,105,1,2,233.4,234.5,110,63,2,4,233.39,234.75,10,1,1,1,AAPL,-1014,-12.483841181902125,0.16114581017908
2024-10-21T12:17:57.664183508Z,2024-10-21T12:17:57.664016909Z,10,2,38,A,A,2,234.09,28,130,166599,12660247,233.7,234.0,1200,50,1,1,233.68,234.03,200,200,1,1,233.67,234.09,28,28,1,1,233.66,234.1,1,100,1,1,233.58,234.13,505,400,2,1,233.53,234.17,10,1,1,1,233.5,234.25,100,100,1,1,233.45,234.41,15,600,1,2,233.4,234.43,110,105,2,2,233.39,234.5,10,63,1,4,AAPL,-1077,-13.43996347587886,0.1734877728368976
2024-10-21T12:17:57.861930731Z,2024-10-21T12:17:57.861764830Z,10,2,38,C,A,1,234.03,200,130,165901,12660371,233.7,234.0,1200,50,1,1,233.68,234.09,200,28,1,1,233.67,234.1,28,100,1,1,233.66,234.13,1,400,1,1,233.58,234.17,505,1,2,1,233.53,234.25,10,100,1,1,233.5,234.41,100,600,1,2,233.45,234.43,15,105,1,2,233.4,234.5,110,63,2,4,233.39,234.75,10,1,1,1,AAPL,-1076,-13.395580454403984,0.17291486119459532
2024-10-21T12:17:57.861944318Z,2024-10-21T12:17:57.861778012Z,10,2,38,A,A,1,234.05,200,130,166306,12660372,233.7,234.0,1200,50,1,1,233.68,234.05,200,200,1,1,233.67,234.09,28,28,1,1,233.66,234.1,1,100,1,1,233.58,234.13,505,400,2,1,233.53,234.17,10,1,1,1,233.5,234.25,100,100,1,1,233.45,234.41,15,600,1,2,233.4,234.43,110,105,2,2,233.39,234.5,10,63,1,4,AAPL,-1139,-14.371134020618557,0.185507649544758
2024-10-21T12:17:57.861998569Z,2024-10-21T12:17:57.861832789Z,10,2,38,C,A,1,234.05,200,130,165780,12660373,233.7,234.0,1200,50,1,1,233.68,234.09,200,28,1,1,233.67,234.1,28,100,1,1,233.66,234.13,1,400,1,1,233.58,234.17,505,1,2,1,233.53,234.25,10,100,1,1,233.5,234.41,100,600,1,2,233.45,234.43,15,105,1,2,233.4,234.5,110,63,2,4,233.39,234.75,10,1,1,1,AAPL,-1138,-14.683870967741935,0.18954456798859312
2024-10-21T12:17:57.862047558Z,2024-10-21T12:17:57.861881332Z,10,2,38,A,A,1,234.08,400,130,166226,12660374,233.7,234.0,1200,50,1,1,233.68,234.08,200,400,1,1,233.67,234.09,28,28,1,1,233.66,234.1,1,100,1,1,233.58,234.13,505,400,2,1,233.53,234.17,10,1,1,1,233.5,234.25,100,100,1,1,233.45,234.41,15,600,1,2,233.4,234.43,110,105,2,2,233.39,234.5,10,63,1,4,AAPL,-1201,-15.689807078839435,0.20252954490789257
2024-10-21T12:17:57.862411573Z,2024-10-21T12:17:57.862245512Z,10,2,38,C,A,2,234.09,28,130,166061,12660376,233.7,234.0,1200,50,1,1,233.68,234.08,200,400,1,1,233.67,234.1,28,100,1,1,233.66,234.13,1,400,1,1,233.58,234.17,505,1,2,1,233.53,234.25,10,100,1,1,233.5,234.41,100,600,1,2,233.45,234.43,15,105,1,2,233.4,234.5,110,63,2,4,233.39,234.75,10,1,1,1,AAPL,-1200,-16.014558689717923,0.20672155285476088
2024-10-21T12:17:57.917208666Z,2024-10-21T12:17:57.917042270Z,10,2,38,A,A,1,234.06,200,130,166396,12660452,233.7,234.0,1200,50,1,1,233.68,234.06,200,200,1,1,233.67,234.1,28,100,1,1,233.66,234.13,1,400,1,1,233.58,234.17,505,1,2,1,233.53,234.25,10,100,1,1,233.5,234.41,100,600,1,2,233.45,234.43,15,105,1,2,233.4,234.5,110,63,2,4,233.39,234.75,10,1,1,1,AAPL,-1200,-16.35124905374716,0.21106767042389787
2024-10-21T12:17:58.077394143Z,2024-10-21T12:17:58.077227750Z,10,2,38,A,A,1,234.03,200,130,166393,12660553,233.7,234.0,1200,50,1,1,233.68,234.03,200,200,1,1,233.67,234.1,28,100,1,1,233.66,234.13,1,400,1,1,233.58,234.17,505,1,2,1,233.53,234.25,10,100,1,1,233.5,234.41,100,600,1,2,233.45,234.43,15,105,1,2,233.4,234.5,110,63,2,4,233.39,234.75,10,1,1,1,AAPL,-1200,-16.68681983071342,0.2153993359696792
2024-10-21T12:18:00.232519967Z,2024-10-21T12:18:00.232353557Z,10,2,38,A,A,2,234.1,29,130,166410,12662424,233.7,234.0,1200,50,1,1,233.68,234.03,200,200,1,1,233.67,234.1,28,129,1,2,233.66,234.13,1,400,1,1,233.58,234.17,505,1,2,1,233.53,234.25,10,100,1,1,233.5,234.41,100,600,1,2,233.45,234.43,15,105,1,2,233.4,234.5,110,63,2,4,233.39,234.75,10,1,1,1,AAPL,-1201,-16.217277888599046,0.20933832353187512
2024-10-21T12:18:00.862297139Z,2024-10-21T12:18:00.862130755Z,10,2,38,A,A,1,234.03,200,130,166384,12663334,233.7,234.0,1200,50,1,1,233.68,234.03,200,400,1,2,233.67,234.1,28,129,1,2,233.66,234.13,1,400,1,1,233.58,234.17,505,1,2,1,233.53,234.25,10,100,1,1,233.5,234.41,100,600,1,2,233.45,234.43,15,105,1,2,233.4,234.5,110,63,2,4,233.39,234.75,10,1,1,1,AAPL,-1201,-16.557904411764707,0.21373525042674693
2024-10-21T12:18:01.682248451Z,2024-10-21T12:18:01.682081842Z,10,2,38,C,A,1,234.03,200,130,166609,12664484,233.7,234.0,1200,50,1,1,233.68,234.03,200,200,1,1,233.67,234.1,28,129,1,2,233.66,234.13,1,400,1,1,233.58,234.17,505,1,2,1,233.53,234.25,10,100,1,1,233.5,234.41,100,600,1,2,233.45,234.43,15,105,1,2,233.4,234.5,110,63,2,4,233.39,234.75,10,1,1,1,AAPL,-1201,-16.89738492124178,0.2181173841740904
2024-10-21T12:18:01.684200005Z,2024-10-21T12:18:01.684033789Z,10,2,38,C,A,1,234.03,200,130,166216,12664487,233.7,234.0,1200,50,1,1,233.68,234.1,200,129,1,2,233.67,234.13,28,400,1,1,233.66,234.17,1,1,1,1,233.58,234.25,505,100,2,1,233.53,234.41,10,600,1,2,233.5,234.43,100,105,1,2,233.45,234.5,15,63,1,4,233.4,234.75,110,1,2,1,233.39,234.79,10,2000,1,1,AAPL,799,8.785355012282139,-0.11340445064435986
2024-10-21T12:18:01.684213363Z,2024-10-21T12:18:01.684046790Z,10,2,38,A,A,1,234.06,200,130,166573,12664488,233.7,234.0,1200,50,1,1,233.68,234.06,200,200,1,1,233.67,234.1,28,129,1,2,233.66,234.13,1,400,1,1,233.58,234.17,505,1,2,1,233.53,234.25,10,100,1,1,233.5,234.41,100,600,1,2,233.45,234.43,15,105,1,2,233.4,234.5,110,63,2,4,233.39,234.75,10,1,1,1,AAPL,798,8.949532710280373,-0.11552371408032987
2024-10-21T12:18:02.545235211Z,2024-10-21T12:18:02.545068859Z,10,2,38,A,A,1,234.05,200,130,166352,12665308,233.7,234.0,1200,50,1,1,233.68,234.05,200,200,1,1,233.67,234.1,28,129,1,2,233.66,234.13,1,400,1,1,233.58,234.17,505,1,2,1,233.53,234.25,10,100,1,1,233.5,234.41,100,600,1,2,233.45,234.43,15,105,1,2,233.4,234.5,110,63,2,4,233.39,234.75,10,1,1,1,AAPL,798,9.124256212810641,-0.11777910646816193
2024-10-21T12:18:03.624266534Z,2024-10-21T12:18:03.624100762Z,10,2,38,C,A,1,234.05,200,130,165772,12666192,233.7,234.0,1200,50,1,1,233.68,234.1,200,129,1,2,233.67,234.13,28,400,1,1,233.66,234.17,1,1,1,1,233.58,234.25,505,100,2,1,233.53,234.41,10,600,1,2,233.5,234.43,100,105,1,2,233.45,234.5,15,63,1,4,233.4,234.75,110,1,2,1,233.39,234.79,10,2000,1,1,AAPL,2798,26.443625366222474,-0.3413436114430537
2024-10-21T12:18:03.624278474Z,2024-10-21T12:18:03.624112266Z,10,2,38,A,A,1,234.07,200,130,166208,12666193,233.7,234.0,1200,50,1,1,233.68,234.07,200,200,1,1,233.67,234.1,28,129,1,2,233.66,234.13,1,400,1,1,233.58,234.17,505,1,2,1,233.53,234.25,10,100,1,1,233.5,234.41,100,600,1,2,233.45,234.43,15,105,1,2,233.4,234.5,110,63,2,4,233.39,234.75,10,1,1,1,AAPL,2797,26.934856495468278,-0.3476845955323305
2024-10-21T12:18:03.629578910Z,2024-10-21T12:18:03.629412395Z,10,2,38,C,B,2,233.67,28,130,166515,12666256,233.7,234.0,1200,50,1,1,233.68,234.07,200,200,1,1,233.66,234.1,1,129,1,2,233.58,234.13,505,400,2,1,233.53,234.17,10,1,1,1,233.5,234.25,100,100,1,1,233.45,234.41,15,600,1,2,233.4,234.43,110,105,2,2,233.39,234.5,10,63,1,4,233.31,234.75,110,1,2,1,AAPL,2687,26.10931514528637,-0.33702821759760854
2024-10-21T12:18:03.629664398Z,2024-10-21T12:18:03.629498033Z,10,2,38,A,B,1,233.68,26,130,166365,12666257,233.7,234.0,1200,50,1,1,233.68,234.07,226,200,2,1,233.66,234.1,1,129,1,2,233.58,234.13,505,400,2,1,233.53,234.17,10,1,1,1,233.5,234.25,100,100,1,1,233.45,234.41,15,600,1,2,233.4,234.43,110,105,2,2,233.39,234.5,10,63,1,4,233.31,234.75,110,1,2,1,AAPL,2687,26.33826521176253,-0.33998358553406877
2024-10-21T12:18:03.696785108Z,2024-10-21T12:18:03.696618449Z,10,2,38,A,B,1,233.69,200,130,166659,12666492,233.7,234.0,1200,50,1,1,233.69,234.07,200,200,1,1,233.68,234.1,26,129,1,2,233.66,234.13,1,400,1,1,233.58,234.17,505,1,2,1,233.53,234.25,10,100,1,1,233.5,234.41,100,600,1,2,233.45,234.43,15,105,1,2,233.4,234.5,110,63,2,4,233.39,234.75,10,1,1,1,AAPL,2697,26.90771362586605,-0.34733422583049733
2024-10-21T12:18:04.737683350Z,2024-10-21T12:18:04.737516809Z,10,2,38,A,A,1,234.04,200,130,166541,12667659,233.7,234.0,1200,50,1,1,233.69,234.04,200,200,1,1,233.68,234.1,26,129,1,2,233.66,234.13,1,400,1,1,233.58,234.17,505,1,2,1,233.53,234.25,10,100,1,1,233.5,234.41,100,600,1,2,233.45,234.43,15,105,1,2,233.4,234.5,110,63,2,4,233.39,234.75,10,1,1,1,AAPL,2697,27.378183831672203,-0.35340722062232943
2024-10-21T12:18:05.203527442Z,2024-10-21T12:18:05.203361341Z,10,2,38,C,A,1,234.04,200,130,166101,12668336,233.7,234.0,1200,50,1,1,233.69,234.1,200,129,1,2,233.68,234.13,26,400,1,1,233.66,234.17,1,1,1,1,233.58,234.25,505,100,2,1,233.53,234.41,10,600,1,2,233.5,234.43,100,105,1,2,233.45,234.5,15,63,1,4,233.4,234.75,110,1,2,1,233.39,234.79,10,2000,1,1,AAPL,4697,40.95158025844621,-0.5286173928924844
2024-10-21T12:18:05.203540356Z,2024-10-21T12:18:05.203373864Z,10,2,38,A,A,1,234.07,200,130,166492,12668337,233.7,234.0,1200,50,1,1,233.69,234.07,200,200,1,1,233.68,234.1,26,129,1,2,233.66,234.13,1,400,1,1,233.58,234.17,505,1,2,1,233.53,234.25,10,100,1,1,233.5,234.41,100,600,1,2,233.45,234.43,15,105,1,2,233.4,234.5,110,63,2,4,233.39,234.75,10,1,1,1,AAPL,4696,41.63832931477017,-0.5374821911111191
2024-10-21T12:18:08.259175673Z,2024-10-21T12:18:08.259009052Z,10,2,38,A,A,1,234.04,200,130,166621,12670951,233.7,234.0,1200,50,1,1,233.69,234.04,200,200,1,1,233.68,234.1,26,129,1,2,233.66,234.13,1,400,1,1,233.58,234.17,505,1,2,1,233.53,234.25,10,100,1,1,233.5,234.41,100,600,1,2,233.45,234.43,15,105,1,2,233.4,234.5,110,63,2,4,233.39,234.75,10,1,1,1,AAPL,5711,41.24086053858884,-0.5323515244336638
2024-10-21T12:18:08.926701808Z,2024-10-21T12:18:08.926535769Z,10,2,38,C,A,1,234.04,200,130,166039,12671724,233.7,234.0,1200,50,1,1,233.69,234.1,200,129,1,2,233.68,234.13,26,400,1,1,233.66,234.17,1,1,1,1,233.58,234.25,505,100,2,1,233.53,234.41,10,600,1,2,233.5,234.43,100,105,1,2,233.45,234.5,15,63,1,4,233.4,234.75,110,1,2,1,233.39,234.79,10,2000,1,1,AAPL,7711,44.53621346886913,-0.5748890984093615
2024-10-21T12:18:08.926714890Z,2024-10-21T12:18:08.926548505Z,10,2,38,A,A,1,234.07,200,130,166385,12671725,233.7,234.0,1200,50,1,1,233.69,234.07,200,200,1,1,233.68,234.1,26,129,1,2,233.66,234.13,1,400,1,1,233.58,234.17,505,1,2,1,233.53,234.25,10,100,1,1,233.5,234.41,100,600,1,2,233.45,234.43,15,105,1,2,233.4,234.5,110,63,2,4,233.39,234.75,10,1,1,1,AAPL,7710,46.252884171665904,-0.5970484872690912
2024-10-21T12:18:10.662605099Z,2024-10-21T12:18:10.662438649Z,10,2,38,A,A,1,234.04,200,130,166450,12673023,233.7,234.0,1200,50,1,1,233.69,234.04,200,200,1,1,233.68,234.1,26,129,1,2,233.66,234.13,1,400,1,1,233.58,234.17,505,1,2,1,233.53,234.25,10,100,1,1,233.5,234.41,100,600,1,2,233.45,234.43,15,105,1,2,233.4,234.5,110,63,2,4,233.39,234.75,10,1,1,1,AAPL,7710,47.97096439681991,-0.6192260707388701
2024-10-21T12:18:11.927426711Z,2024-10-21T12:18:11.927260518Z,10,2,38,A,A,1,234.04,200,130,166193,12675018,233.7,234.0,1200,50,1,1,233.69,234.04,200,400,1,2,233.68,234.1,26,129,1,2,233.66,234.13,1,400,1,1,233.58,234.17,505,1,2,1,233.53,234.25,10,100,1,1,233.5,234.41,100,600,1,2,233.45,234.43,15,105,1,2,233.4,234.5,110,63,2,4,233.39,234.75,10,1,1,1,AAPL,7710,49.68469505178366,-0.6413475084277132
2024-10-21T12:18:20.285893902Z,2024-10-21T12:18:20.285727761Z,10,2,38,C,A,2,234.1,29,130,166141,12682022,233.7,234.0,1200,50,1,1,233.69,234.04,200,400,1,2,233.68,234.1,26,100,1,1,233.66,234.13,1,400,1,1,233.58,234.17,505,1,2,1,233.53,234.25,10,100,1,1,233.5,234.41,100,600,1,2,233.45,234.43,15,105,1,2,233.4,234.5,110,63,2,4,233.39,234.75,10,1,1,1,AAPL,7896,35.698750743605,-0.4608120230894142
2024-10-21T12:18:20.285938798Z,2024-10-21T12:18:20.285772241Z,10,2,38,A,A,2,234.05,27,130,166557,12682023,233.7,234.0,1200,50,1,1,233.69,234.04,200,400,1,2,233.68,234.05,26,27,1,1,233.66,234.1,1,100,1,1,233.58,234.13,505,400,2,1,233.53,234.17,10,1,1,1,233.5,234.25,100,100,1,1,233.45,234.41,15,600,1,2,233.4,234.43,110,105,2,2,233.39,234.5,10,63,1,4,AAPL,7833,36.95682944090588,-0.47705174514223053
2024-10-21T12:18:20.342261946Z,2024-10-21T12:18:20.342095696Z,10,2,38,C,A,1,234.04,200,130,166250,12682048,233.7,234.0,1200,50,1,1,233.69,234.04,200,200,1,1,233.68,234.05,26,27,1,1,233.66,234.1,1,100,1,1,233.58,234.13,505,400,2,1,233.53,234.17,10,1,1,1,233.5,234.25,100,100,1,1,233.45,234.41,15,600,1,2,233.4,234.43,110,105,2,2,233.39,234.5,10,63,1,4,AAPL,7833,38.47339492457022,-0.49662810549428377
2024-10-21T12:18:20.342275574Z,2024-10-21T12:18:20.342109232Z,10,2,38,A,A,0,233.99,200,130,166342,12682049,233.7,233.99,1200,200,1,1,233.69,234.0,200,50,1,1,233.68,234.05,26,27,1,1,233.66,234.1,1,100,1,1,233.58,234.13,505,400,2,1,233.53,234.17,10,1,1,1,233.5,234.25,100,100,1,1,233.45,234.41,15,600,1,2,233.4,234.43,110,105,2,2,233.39,234.5,10,63,1,4,AAPL,7833,39.964285714285715,-0.5158730478719171
2024-10-21T12:18:30.059661118Z,2024-10-21T12:18:30.059494751Z,10,2,38,A,A,0,233.98,200,130,166367,12688662,233.7,233.98,1200,200,1,1,233.69,234.0,200,50,1,1,233.68,234.05,26,27,1,1,233.66,234.1,1,100,1,1,233.58,234.13,505,400,2,1,233.53,234.17,10,1,1,1,233.5,234.25,100,100,1,1,233.45,234.41,15,600,1,2,233.4,234.43,110,105,2,2,233.39,234.5,10,63,1,4,AAPL,-63,-2.713846153846154,0.03503128009966278
2024-10-21T12:18:30.076685634Z,2024-10-21T12:18:30.076519305Z,10,2,38,A,A,0,233.97,200,130,166329,12688696,233.7,233.97,1200,200,1,1,233.69,234.0,200,50,1,1,233.68,234.05,26,27,1,1,233.66,234.1,1,100,1,1,233.58,234.13,505,400,2,1,233.53,234.17,10,1,1,1,233.5,234.25,100,100,1,1,233.45,234.41,15,600,1,2,233.4,234.43,110,105,2,2,233.39,234.5,10,63,1,4,AAPL,-63,-2.5326633165829144,0.03269250834857259
2024-10-21T12:18:38.166025153Z,2024-10-21T12:18:38.165859345Z,10,2,38,C,A,0,233.97,200,130,165808,12695042,233.7,234.0,1200,50,1,1,233.69,234.05,200,27,1,1,233.68,234.1,26,100,1,1,233.66,234.13,1,400,1,1,233.58,234.17,505,1,2,1,233.53,234.25,10,100,1,1,233.5,234.41,100,600,1,2,233.45,234.43,15,105,1,2,233.4,234.5,110,63,2,4,233.39,234.75,10,1,1,1,AAPL,-62,-2.242894056847545,0.02895206488692855
2024-10-21T12:18:38.166038009Z,2024-10-21T12:18:38.165871291Z,10,2,38,A,A,0,233.99,200,130,166718,12695043,233.7,233.99,1200,200,1,1,233.69,234.0,200,50,1,1,233.68,234.05,26,27,1,1,233.66,234.1,1,100,1,1,233.58,234.13,505,400,2,1,233.53,234.17,10,1,1,1,233.5,234.25,100,100,1,1,233.45,234.41,15,600,1,2,233.4,234.43,110,105,2,2,233.39,234.5,10,63,1,4,AAPL,-125,-4.3478260869565215,0.056123267437594423
2024-10-21T12:18:38.170948726Z,2024-10-21T12:18:38.170782768Z,10,2,38,C,B,1,233.69,200,130,165958,12695084,233.7,233.99,1200,200,1,1,233.68,234.0,26,50,1,1,233.66,234.05,1,27,1,1,233.58,234.1,505,100,2,1,233.53,234.13,10,400,1,1,233.5,234.17,100,1,1,1,233.45,234.25,15,100,1,1,233.4,234.41,110,600,2,2,233.39,234.43,10,105,1,2,233.31,234.5,110,63,2,4,AAPL,-235,-6.682464454976304,0.08625960014223638
2024-10-21T12:18:38.170958770Z,2024-10-21T12:18:38.170792741Z,10,2,38,A,B,2,233.66,200,130,166029,12695085,233.7,233.99,1200,200,1,1,233.68,234.0,26,50,1,1,233.66,234.05,201,27,2,1,233.58,234.1,505,100,2,1,233.53,234.13,10,400,1,1,233.5,234.17,100,1,1,1,233.45,234.25,15,100,1,1,233.4,234.41,110,600,2,2,233.39,234.43,10,105,1,2,233.31,234.5,110,63,2,4,AAPL,-235,-5.831265508684864,0.07527202493801437
2024-10-21T12:18:38.189860689Z,2024-10-21T12:18:38.189694615Z,10,2,38,C,B,1,233.68,26,130,166074,12695165,233.7,233.99,1200,200,1,1,233.66,234.0,201,50,2,1,233.58,234.05,505,27,2,1,233.53,234.1,10,100,1,1,233.5,234.13,100,400,1,1,233.45,234.17,15,1,1,1,233.4,234.25,110,100,2,1,233.39,234.41,10,600,1,2,233.31,234.43,110,105,2,2,233.3,234.5,100,63,1,4,AAPL,-335,-7.60577915376677,0.0981780708291706
2024-10-21T12:18:38.189958263Z,2024-10-21T12:18:38.189791855Z,10,2,38,A,B,2,233.62,28,130,166408,12695166,233.7,233.99,1200,200,1,1,233.66,234.0,201,50,2,1,233.62,234.05,28,27,1,1,233.58,234.1,505,100,2,1,233.53,234.13,10,400,1,1,233.5,234.17,100,1,1,1,233.45,234.25,15,100,1,1,233.4,234.41,110,600,2,2,233.39,234.43,10,105,1,2,233.31,234.5,110,63,2,4,AAPL,-225,-4.728546409807355,0.06103773919219988
2024-10-21T12:18:40.408253176Z,2024-10-21T12:18:40.408086849Z,10,2,38,C,B,2,233.62,28,130,166327,12697055,233.7,233.99,1200,200,1,1,233.66,234.0,201,50,2,1,233.58,234.05,505,27,2,1,233.53,234.1,10,100,1,1,233.5,234.13,100,400,1,1,233.45,234.17,15,1,1,1,233.4,234.25,110,100,2,1,233.39,234.41,10,600,1,2,233.31,234.43,110,105,2,2,233.3,234.5,100,63,1,4,AAPL,-262,-4.386976744186047,0.05662863788298597
2024-10-21T12:18:40.408303418Z,2024-10-21T12:18:40.408137058Z,10,2,38,A,B,2,233.63,26,130,166360,12697056,233.7,233.99,1200,200,1,1,233.66,234.0,201,50,2,1,233.63,234.05,26,27,1,1,233.58,234.1,505,100,2,1,233.53,234.13,10,400,1,1,233.5,234.17,100,1,1,1,233.45,234.25,15,100,1,1,233.4,234.41,110,600,2,2,233.39,234.43,10,105,1,2,233.31,234.5,110,63,2,4,AAPL,-152,-2.435897435897436,0.031443420346447135
2024-10-21T12:18:41.180157281Z,2024-10-21T12:18:41.179991523Z,10,2,38,C,B,2,233.63,26,130,165758,12697907,233.7,233.99,1200,200,1,1,233.66,234.0,201,50,2,1,233.58,234.05,505,27,2,1,233.53,234.1,10,100,1,1,233.5,234.13,100,400,1,1,233.45,234.17,15,1,1,1,233.4,234.25,110,100,2,1,233.39,234.41,10,600,1,2,233.31,234.43,110,105,2,2,233.3,234.5,100,63,1,4,AAPL,-252,-3.9291282778171506,0.05071856894048575
2024-10-21T12:18:41.180284870Z,2024-10-21T12:18:41.180118662Z,10,2,38,A,B,1,233.68,30,130,166208,12697911,233.7,233.99,1200,200,1,1,233.68,234.0,30,50,1,1,233.66,234.05,201,27,2,1,233.58,234.1,505,100,2,1,233.53,234.13,10,400,1,1,233.5,234.17,100,1,1,1,233.45,234.25,15,100,1,1,233.4,234.41,110,600,2,2,233.39,234.43,10,105,1,2,233.31,234.5,110,63,2,4,AAPL,-142,-2.1515151515151514,0.027772513856239908
2024-10-21T12:18:41.234091711Z,2024-10-21T12:18:41.233925482Z,10,2,38,A,B,0,233.74,200,130,166229,12697993,233.74,233.99,200,200,1,1,233.7,234.0,1200,50,1,1,233.68,234.05,30,27,1,1,233.66,234.1,1,100,1,1,233.58,234.13,505,400,2,1,233.53,234.17,10,1,1,1,233.5,234.25,100,100,1,1,233.45,234.41,15,600,1,2,233.4,234.43,110,105,2,2,233.39,234.5,10,63,1,4,AAPL,-132,-2.071213035606518,0.02673594591704257
2024-10-21T12:18:44.453669428Z,2024-10-21T12:18:44.453502831Z,10,2,38,A,A,0,233.98,200,130,166597,12700269,233.74,233.98,200,200,1,1,233.7,234.0,1200,50,1,1,233.68,234.05,30,27,1,1,233.66,234.1,1,100,1,1,233.58,234.13,505,400,2,1,233.53,234.17,10,1,1,1,233.5,234.25,100,100,1,1,233.45,234.41,15,600,1,2,233.4,234.43,110,105,2,2,233.39,234.5,10,63,1,4,AAPL,-132,-2.136416184971098,0.027577611088641773
2024-10-21T12:18:44.458737649Z,2024-10-21T12:18:44.458571638Z,10,2,38,C,B,0,233.74,200,130,166011,12700368,233.7,233.98,1200,200,1,1,233.68,234.0,30,50,1,1,233.66,234.05,1,27,1,1,233.58,234.1,505,100,2,1,233.53,234.13,10,400,1,1,233.5,234.17,100,1,1,1,233.45,234.25,15,100,1,1,233.4,234.41,110,600,2,2,233.39,234.43,10,105,1,2,233.31,234.5,110,63,2,4,AAPL,-242,-3.815028901734104,0.04924573408686031
2024-10-21T12:18:44.458749682Z,2024-10-21T12:18:44.458583443Z,10,2,38,A,B,2,233.66,200,130,166239,12700369,233.7,233.98,1200,200,1,1,233.68,234.0,30,50,1,1,233.66,234.05,201,27,2,1,233.58,234.1,505,100,2,1,233.53,234.13,10,400,1,1,233.5,234.17,100,1,1,1,233.45,234.25,15,100,1,1,233.4,234.41,110,600,2,2,233.39,234.43,10,105,1,2,233.31,234.5,110,63,2,4,AAPL,-242,-3.7302504816955686,0.04815138444048564
2024-10-21T12:18:44.477985018Z,2024-10-21T12:18:44.477818456Z,10,2,38,C,B,1,233.68,30,130,166562,12700470,233.7,233.98,1200,200,1,1,233.66,234.0,201,50,2,1,233.58,234.05,505,27,2,1,233.53,234.1,10,100,1,1,233.5,234.13,100,400,1,1,233.45,234.17,15,1,1,1,233.4,234.25,110,100,2,1,233.39,234.41,10,600,1,2,233.31,234.43,110,105,2,2,233.3,234.5,100,63,1,4,AAPL,-342,-5.193389906208128,0.06703810244117911
2024-10-21T12:18:44.478091299Z,2024-10-21T12:18:44.477924999Z,10,2,38,A,B,2,233.62,28,130,166300,12700471,233.7,233.98,1200,200,1,1,233.66,234.0,201,50,2,1,233.62,234.05,28,27,1,1,233.58,234.1,505,100,2,1,233.53,234.13,10,400,1,1,233.5,234.17,100,1,1,1,233.45,234.25,15,100,1,1,233.4,234.41,110,600,2,2,233.39,234.43,10,105,1,2,233.31,234.5,110,63,2,4,AAPL,-232,-3.462686567164179,0.04469757538014983
2024-10-21T12:18:47.144655653Z,2024-10-21T12:18:47.144489374Z,10,2,38,A,A,0,233.97,200,130,166279,12703555,233.7,233.97,1200,200,1,1,233.66,234.0,201,50,2,1,233.62,234.05,28,27,1,1,233.58,234.1,505,100,2,1,233.53,234.13,10,400,1,1,233.5,234.17,100,1,1,1,233.45,234.25,15,100,1,1,233.4,234.41,110,600,2,2,233.39,234.43,10,105,1,2,233.31,234.5,110,63,2,4,AAPL,-232,-3.4104448742746616,0.044023221244820686
2024-10-21T12:18:47.206489928Z,2024-10-21T12:18:47.206323404Z,10,2,38,A,B,1,233.66,200,130,166524,12703653,233.7,233.97,1200,200,1,1,233.66,234.0,401,50,3,1,233.62,234.05,28,27,1,1,233.58,234.1,505,100,2,1,233.53,234.13,10,400,1,1,233.5,234.17,100,1,1,1,233.45,234.25,15,100,1,1,233.4,234.41,110,600,2,2,233.39,234.43,10,105,1,2,233.31,234.5,110,63,2,4,AAPL,-232,-3.3647570703408265,0.04343346701189323
2024-10-21T12:18:47.261027171Z,2024-10-21T12:18:47.260861161Z,10,2,38,C,B,1,233.66,200,130,166010,12703745,233.7,233.97,1200,200,1,1,233.66,234.0,201,50,2,1,233.62,234.05,28,27,1,1,233.58,234.1,505,100,2,1,233.53,234.13,10,400,1,1,233.5,234.17,100,1,1,1,233.45,234.25,15,100,1,1,233.4,234.41,110,600,2,2,233.39,234.43,10,105,1,2,233.31,234.5,110,63,2,4,AAPL,-232,-3.3244626407369497,0.04291333235064538
2024-10-21T12:18:47.261040389Z,2024-10-21T12:18:47.260873969Z,10,2,38,A,B,0,233.7,200,130,166420,12703746,233.7,233.97,1400,200,2,1,233.66,234.0,1,50,1,1,233.62,234.05,28,27,1,1,233.58,234.1,505,100,2,1,233.53,234.13,10,400,1,1,233.5,234.17,100,1,1,1,233.45,234.25,15,100,1,1,233.4,234.41,110,600,2,2,233.39,234.43,10,105,1,2,233.31,234.5,110,63,2,4,AAPL,-232,-3.288659793814433,0.04245117661748766
2024-10-21T12:18:47.459627907Z,2024-10-21T12:18:47.459461214Z,10,2,38,A,B,0,233.7,200,130,166693,12703881,233.7,233.97,1600,200,3,1,233.66,234.0,1,50,1,1,233.62,234.05,28,27,1,1,233.58,234.1,505,100,2,1,233.53,234.13,10,400,1,1,233.5,234.17,100,1,1,1,233.45,234.25,15,100,1,1,233.4,234.41,110,600,2,2,233.39,234.43,10,105,1,2,233.31,234.5,110,63,2,4,AAPL,-232,-3.256637168141593,0.04203781730900878
2024-10-21T12:18:47.514149868Z,2024-10-21T12:18:47.513983492Z,10,2,38,C,B,0,233.7,200,130,166376,12703892,233.7,233.97,1400,200,2,1,233.66,234.0,1,50,1,1,233.62,234.05,28,27,1,1,233.58,234.1,505,100,2,1,233.53,234.13,10,400,1,1,233.5,234.17,100,1,1,1,233.45,234.25,15,100,1,1,233.4,234.41,110,600,2,2,233.39,234.43,10,105,1,2,233.31,234.5,110,63,2,4,AAPL,-232,-3.227826086956522,0.0416659137456701
2024-10-21T12:18:47.514162028Z,2024-10-21T12:18:47.513995474Z,10,2,38,A,B,0,233.74,200,130,166554,12703893,233.74,233.97,200,200,1,1,233.7,234.0,1200,50,1,1,233.66,234.05,1,27,1,1,233.62,234.1,28,100,1,1,233.58,234.13,505,400,2,1,233.53,234.17,10,1,1,1,233.5,234.25,100,100,1,1,233.45,234.41,15,600,1,2,233.4,234.43,110,105,2,2,233.39,234.5,10,63,1,4,AAPL,-222,-3.150723814930457,0.040670650516088154
2024-10-21T12:18:48.012823351Z,2024-10-21T12:18:48.012656935Z,10,2,38,C,A,0,233.97,200,130,166416,12704330,233.74,234.0,200,50,1,1,233.7,234.05,1200,27,1,1,233.66,234.1,1,100,1,1,233.62,234.13,28,400,1,1,233.58,234.17,505,1,2,1,233.53,234.25,10,100,1,1,233.5,234.41,100,600,1,2,233.45,234.43,15,105,1,2,233.4,234.5,110,63,2,4,233.39,234.75,10,1,1,1,AAPL,-221,-3.2518392756083756,0.041975884425679705
2024-10-21T12:18:48.012837187Z,2024-10-21T12:18:48.012670562Z,10,2,38,A,A,1,234.03,200,130,166625,12704331,233.74,234.0,200,50,1,1,233.7,234.03,1200,200,1,1,233.66,234.05,1,27,1,1,233.62,234.1,28,100,1,1,233.58,234.13,505,400,2,1,233.53,234.17,10,1,1,1,233.5,234.25,100,100,1,1,233.45,234.41,15,600,1,2,233.4,234.43,110,105,2,2,233.39,234.5,10,63,1,4,AAPL,-284,-4.251732741890768,0.05488286076165181
2024-10-21T12:18:48.013001331Z,2024-10-21T12:18:48.012835297Z,10,2,38,A,A,1,234.03,200,130,166034,12704332,233.74,234.0,200,50,1,1,233.7,234.03,1200,400,1,2,233.66,234.05,1,27,1,1,233.62,234.1,28,100,1,1,233.58,234.13,505,400,2,1,233.53,234.17,10,1,1,1,233.5,234.25,100,100,1,1,233.45,234.41,15,600,1,2,233.4,234.43,110,105,2,2,233.39,234.5,10,63,1,4,AAPL,-284,-4.321739130434783,0.05578652783296886
2024-10-21T12:18:48.013375765Z,2024-10-21T12:18:48.013209412Z,10,2,38,C,A,2,234.05,27,130,166353,12704333,233.74,234.0,200,50,1,1,233.7,234.03,1200,400,1,2,233.66,234.1,1,100,1,1,233.62,234.13,28,400,1,1,233.58,234.17,505,1,2,1,233.53,234.25,10,100,1,1,233.5,234.41,100,600,1,2,233.45,234.43,15,105,1,2,233.4,234.5,110,63,2,4,233.39,234.75,10,1,1,1,AAPL,-283,-4.447033324302357,0.05740386932965462
2024-10-21T12:18:48.013479203Z,2024-10-21T12:18:48.013312876Z,10,2,38,A,A,2,234.1,28,130,166327,12704334,233.74,234.0,200,50,1,1,233.7,234.03,1200,400,1,2,233.66,234.1,1,128,1,2,233.62,234.13,28,400,1,1,233.58,234.17,505,1,2,1,233.53,234.25,10,100,1,1,233.5,234.41,100,600,1,2,233.45,234.43,15,105,1,2,233.4,234.5,110,63,2,4,233.39,234.75,10,1,1,1,AAPL,-283,-4.586709886547812,0.059206863492917684
2024-10-21T12:18:48.070451078Z,2024-10-21T12:18:48.070285169Z,10,2,38,C,A,1,234.03,200,130,165909,12704401,233.74,234.0,200,50,1,1,233.7,234.03,1200,200,1,1,233.66,234.1,1,128,1,2,233.62,234.13,28,400,1,1,233.58,234.17,505,1,2,1,233.53,234.25,10,100,1,1,233.5,234.41,100,600,1,2,233.45,234.43,15,105,1,2,233.4,234.5,110,63,2,4,233.39,234.75,10,1,1,1,AAPL,-283,-4.725558847293294,0.06099917468510835
2024-10-21T12:18:48.070465807Z,2024-10-21T12:18:48.070297042Z,10,2,38,A,A,0,233.97,200,128,168765,12704402,233.74,233.97,200,200,1,1,233.7,234.0,1200,50,1,1,233.66,234.1,1,128,1,2,233.62,234.13,28,400,1,1,233.58,234.17,505,1,2,1,233.53,234.25,10,100,1,1,233.5,234.41,100,600,1,2,233.45,234.43,15,105,1,2,233.4,234.5,110,63,2,4,233.39,234.75,10,1,1,1,AAPL,-283,-4.863587540279269,0.06278089757272647
2024-10-21T12:18:48.200074274Z,2024-10-21T12:18:48.199908254Z,10,2,38,C,B,0,233.74,200,130,166020,12704576,233.7,233.97,1200,200,1,1,233.66,234.0,1,50,1,1,233.62,234.1,28,128,1,2,233.58,234.13,505,400,2,1,233.53,234.17,10,1,1,1,233.5,234.25,100,100,1,1,233.45,234.41,15,600,1,2,233.4,234.43,110,105,2,2,233.39,234.5,10,63,1,4,233.31,234.75,110,1,2,1,AAPL,-393,-6.763494132985658,0.08730555970877563
2024-10-21T12:18:48.200087164Z,2024-10-21T12:18:48.199920865Z,10,2,38,A,B,1,233.68,200,130,166299,12704577,233.7,233.97,1200,200,1,1,233.68,234.0,200,50,1,1,233.66,234.1,1,128,1,2,233.62,234.13,28,400,1,1,233.58,234.17,505,1,2,1,233.53,234.25,10,100,1,1,233.5,234.41,100,600,1,2,233.45,234.43,15,105,1,2,233.4,234.5,110,63,2,4,233.39,234.75,10,1,1,1,AAPL,-383,-6.771710868434737,0.08741162421822234
2024-10-21T12:18:48.200108087Z,2024-10-21T12:18:48.199942139Z,10,2,38,C,B,1,233.68,200,130,165948,12704578,233.7,233.97,1200,200,1,1,233.66,234.0,1,50,1,1,233.62,234.1,28,128,1,2,233.58,234.13,505,400,2,1,233.53,234.17,10,1,1,1,233.5,234.25,100,100,1,1,233.45,234.41,15,600,1,2,233.4,234.43,110,105,2,2,233.39,234.5,10,63,1,4,233.31,234.75,110,1,2,1,AAPL,-493,-8.721253474854688,0.11257700546687345
2024-10-21T12:18:48.200195970Z,2024-10-21T12:18:48.200029266Z,10,2,38,A,B,2,233.65,200,130,166704,12704579,233.7,233.97,1200,200,1,1,233.66,234.0,1,50,1,1,233.65,234.1,200,128,1,2,233.62,234.13,28,400,1,1,233.58,234.17,505,1,2,1,233.53,234.25,10,100,1,1,233.5,234.41,100,600,1,2,233.45,234.43,15,105,1,2,233.4,234.5,110,63,2,4,233.39,234.75,10,1,1,1,AAPL,-483,-8.764112903225806,0.11313025003383323
2024-10-21T12:18:48.200668344Z,2024-10-21T12:18:48.200502296Z,10,2,38,C,B,3,233.62,28,130,166048,12704580,233.7,233.97,1200,200,1,1,233.66,234.0,1,50,1,1,233.65,234.1,200,128,1,2,233.58,234.13,505,400,2,1,233.53,234.17,10,1,1,1,233.5,234.25,100,100,1,1,233.45,234.41,15,600,1,2,233.4,234.43,110,105,2,2,233.39,234.5,10,63,1,4,233.31,234.75,110,1,2,1,AAPL,-593,-10.758028928658986,0.1388684189728363
2024-10-21T12:18:48.200720265Z,2024-10-21T12:18:48.200553666Z,10,2,38,A,B,1,233.67,27,130,166599,12704581,233.7,233.97,1200,200,1,1,233.67,234.0,27,50,1,1,233.66,234.1,1,128,1,2,233.65,234.13,200,400,1,1,233.58,234.17,505,1,2,1,233.53,234.25,10,100,1,1,233.5,234.41,100,600,1,2,233.45,234.43,15,105,1,2,233.4,234.5,110,63,2,4,233.39,234.75,10,1,1,1,AAPL,-583,-10.833251833740832,0.13983942267328478
2024-10-21T12:18:48.213389240Z,2024-10-21T12:18:48.213222660Z,10,2,38,C,B,1,233.67,27,130,166580,12704589,233.7,233.97,1200,200,1,1,233.66,234.0,1,50,1,1,233.65,234.1,200,128,1,2,233.58,234.13,505,400,2,1,233.53,234.17,10,1,1,1,233.5,234.25,100,100,1,1,233.45,234.41,15,600,1,2,233.4,234.43,110,105,2,2,233.39,234.5,10,63,1,4,233.31,234.75,110,1,2,1,AAPL,-693,-12.86693644370388,0.1660909384804803
2024-10-21T12:18:49.923109783Z,2024-10-21T12:18:49.922943623Z,10,2,38,C,A,2,234.1,28,130,166160,12706013,233.7,233.97,1200,200,1,1,233.66,234.0,1,50,1,1,233.65,234.1,200,100,1,1,233.58,234.13,505,400,2,1,233.53,234.17,10,1,1,1,233.5,234.25,100,100,1,1,233.45,234.41,15,600,1,2,233.4,234.43,110,105,2,2,233.39,234.5,10,63,1,4,233.31,234.75,110,1,2,1,AAPL,-693,-12.857142857142858,0.16596451942260065
2024-10-21T12:18:49.923258127Z,2024-10-21T12:18:49.923091366Z,10,2,38,A,A,2,234.05,28,130,166761,12706014,233.7,233.97,1200,200,1,1,233.66,234.0,1,50,1,1,233.65,234.05,200,28,1,1,233.58,234.1,505,100,2,1,233.53,234.13,10,400,1,1,233.5,234.17,100,1,1,1,233.45,234.25,15,100,1,1,233.4,234.41,110,600,2,2,233.39,234.43,10,105,1,2,233.31,234.5,110,63,2,4,AAPL,-756,-13.822073578595317,0.17842018435853096
2024-10-21T12:18:51.255092000Z,2024-10-21T12:18:51.254925630Z,10,2,38,A,B,1,233.69,200,130,166370,12707192,233.7,233.97,1200,200,1,1,233.69,234.0,200,50,1,1,233.66,234.05,1,28,1,1,233.58,234.1,505,100,2,1,233.53,234.13,10,400,1,1,233.5,234.17,100,1,1,1,233.45,234.25,15,100,1,1,233.4,234.41,110,600,2,2,233.39,234.43,10,105,1,2,233.31,234.5,110,63,2,4,AAPL,-756,-13.404255319148936,0.17302683939803046
2024-10-21T12:18:51.423495230Z,2024-10-21T12:18:51.423329256Z,10,2,38,C,A,2,234.05,28,130,165974,12707840,233.7,233.97,1200,200,1,1,233.69,234.0,200,50,1,1,233.66,234.1,1,100,1,1,233.58,234.13,505,400,2,1,233.53,234.17,10,1,1,1,233.5,234.25,100,100,1,1,233.45,234.41,15,600,1,2,233.4,234.43,110,105,2,2,233.39,234.5,10,63,1,4,233.31,234.75,110,1,2,1,AAPL,-755,-13.391736967337227,0.172865248112511
2024-10-21T12:18:51.423548073Z,2024-10-21T12:18:51.423381788Z,10,2,38,A,A,2,234.04,30,130,166285,12707841,233.7,233.97,1200,200,1,1,233.69,234.0,200,50,1,1,233.66,234.04,1,30,1,1,233.58,234.1,505,100,2,1,233.53,234.13,10,400,1,1,233.5,234.17,100,1,1,1,233.45,234.25,15,100,1,1,233.4,234.41,110,600,2,2,233.39,234.43,10,105,1,2,233.31,234.5,110,63,2,4,AAPL,-818,-14.326939115929942,0.18493716618005782
2024-10-21T12:18:51.430417250Z,2024-10-21T12:18:51.430250460Z,10,2,38,A,B,1,233.69,200,130,166790,12707856,233.7,233.97,1200,200,1,1,233.69,234.0,400,50,2,1,233.66,234.04,1,30,1,1,233.58,234.1,505,100,2,1,233.53,234.13,10,400,1,1,233.5,234.17,100,1,1,1,233.45,234.25,15,100,1,1,233.4,234.41,110,600,2,2,233.39,234.43,10,105,1,2,233.31,234.5,110,63,2,4,AAPL,-818,-14.157375729523043,0.18274838238498198
2024-10-21T12:18:53.923079620Z,2024-10-21T12:18:53.922913086Z,10,2,38,A,B,3,233.62,27,130,166534,12710377,233.7,233.97,1200,200,1,1,233.69,234.0,400,50,2,1,233.66,234.04,1,30,1,1,233.62,234.1,27,100,1,1,233.58,234.13,505,400,2,1,233.53,234.17,10,1,1,1,233.5,234.25,100,100,1,1,233.45,234.41,15,600,1,2,233.4,234.43,110,105,2,2,233.39,234.5,10,63,1,4,AAPL,-808,-14.10234034113447,0.18203796624613727
2024-10-21T12:19:00.084000089Z,2024-10-21T12:19:00.083834280Z,10,2,38,C,B,1,233.69,200,130,165809,12715313,233.7,233.97,1200,200,1,1,233.69,234.0,200,50,1,1,233.66,234.04,1,30,1,1,233.62,234.1,27,100,1,1,233.58,234.13,505,400,2,1,233.53,234.17,10,1,1,1,233.5,234.25,100,100,1,1,233.45,234.41,15,600,1,2,233.4,234.43,110,105,2,2,233.39,234.5,10,63,1,4,AAPL,-646,-11.586111749827547,0.1495576031084081
2024-10-21T12:19:00.084009808Z,2024-10-21T12:19:00.083843895Z,10,2,38,C,B,1,233.69,200,130,165913,12715314,233.7,233.97,1200,200,1,1,233.66,234.0,1,50,1,1,233.62,234.04,27,30,1,1,233.58,234.1,505,100,2,1,233.53,234.13,10,400,1,1,233.5,234.17,100,1,1,1,233.45,234.25,15,100,1,1,233.4,234.41,110,600,2,2,233.39,234.43,10,105,1,2,233.31,234.5,110,63,2,4,AAPL,-756,-13.374613003095975,0.17264420596282917
2024-10-21T12:19:00.084021335Z,2024-10-21T12:19:00.083854884Z,10,2,38,A,B,1,233.68,200,130,166451,12715315,233.7,233.97,1200,200,1,1,233.68,234.0,200,50,1,1,233.66,234.04,1,30,1,1,233.62,234.1,27,100,1,1,233.58,234.13,505,400,2,1,233.53,234.17,10,1,1,1,233.5,234.25,100,100,1,1,233.45,234.41,15,600,1,2,233.4,234.43,110,105,2,2,233.39,234.5,10,63,1,4,AAPL,-746,-13.312731229597388,0.1718454142784072
2024-10-21T12:19:00.143641105Z,2024-10-21T12:19:00.143474250Z,10,2,38,A,B,1,233.69,200,130,166855,12715619,233.7,233.97,1200,200,1,1,233.69,234.0,200,50,1,1,233.66,234.04,1,30,1,1,233.62,234.1,27,100,1,1,233.58,234.13,505,400,2,1,233.53,234.17,10,1,1,1,233.5,234.25,100,100,1,1,233.45,234.41,15,600,1,2,233.4,234.43,110,105,2,2,233.39,234.5,10,63,1,4,AAPL,-746,-13.424164524421593,0.17328383441798756
2024-10-21T12:19:00.197681940Z,2024-10-21T12:19:00.197516009Z,10,2,38,A,B,1,233.69,200,130,165931,12715801,233.7,233.97,1200,200,1,1,233.69,234.0,400,50,2,1,233.66,234.04,1,30,1,1,233.62,234.1,27,100,1,1,233.58,234.13,505,400,2,1,233.53,234.17,10,1,1,1,233.5,234.25,100,100,1,1,233.45,234.41,15,600,1,2,233.4,234.43,110,105,2,2,233.39,234.5,10,63,1,4,AAPL,-746,-13.53216620966041,0.17467795813479242
2024-10-21T12:19:00.198183165Z,2024-10-21T12:19:00.198016624Z,10,2,38,C,B,3,233.62,27,130,166541,12715804,233.7,233.97,1200,200,1,1,233.69,234.0,400,50,2,1,233.66,234.04,1,30,1,1,233.58,234.1,505,100,2,1,233.53,234.13,10,400,1,1,233.5,234.17,100,1,1,1,233.45,234.25,15,100,1,1,233.4,234.41,110,600,2,2,233.39,234.43,10,105,1,2,233.31,234.5,110,63,2,4,AAPL,-856,-15.329263329263329,0.19787551945339762
2024-10-21T12:19:00.198223152Z,2024-10-21T12:19:00.198056773Z,10,2,38,A,B,2,233.66,27,130,166379,12715805,233.7,233.97,1200,200,1,1,233.69,234.0,400,50,2,1,233.66,234.04,28,30,2,1,233.58,234.1,505,100,2,1,233.53,234.13,10,400,1,1,233.5,234.17,100,1,1,1,233.45,234.25,15,100,1,1,233.4,234.41,110,600,2,2,233.39,234.43,10,105,1,2,233.31,234.5,110,63,2,4,AAPL,-856,-15.144485944564575,0.19549034802048812
2024-10-21T12:19:00.251528734Z,2024-10-21T12:19:00.251362837Z,10,2,38,C,B,1,233.69,200,130,165897,12715921,233.7,233.97,1200,200,1,1,233.69,234.0,200,50,1,1,233.66,234.04,28,30,2,1,233.58,234.1,505,100,2,1,233.53,234.13,10,400,1,1,233.5,234.17,100,1,1,1,233.45,234.25,15,100,1,1,233.4,234.41,110,600,2,2,233.39,234.43,10,105,1,2,233.31,234.5,110,63,2,4,AAPL,-856,-14.971863117870724,0.1932620718947624
2024-10-21T12:19:00.251542039Z,2024-10-21T12:19:00.251375630Z,10,2,38,A,B,0,233.73,200,130,166409,12715922,233.73,233.97,200,200,1,1,233.7,234.0,1200,50,1,1,233.66,234.04,28,30,2,1,233.58,234.1,505,100,2,1,233.53,234.13,10,400,1,1,233.5,234.17,100,1,1,1,233.45,234.25,15,100,1,1,233.4,234.41,110,600,2,2,233.39,234.43,10,105,1,2,233.31,234.5,110,63,2,4,AAPL,-856,-14.810233756672188,0.19117570328597047
2024-10-21T12:19:02.578905341Z,2024-10-21T12:19:02.578739513Z,10,2,38,C,B,0,233.73,200,130,165828,12718269,233.7,233.97,1200,200,1,1,233.66,234.0,28,50,2,1,233.58,234.04,505,30,2,1,233.53,234.1,10,100,1,1,233.5,234.13,100,400,1,1,233.45,234.17,15,1,1,1,233.4,234.25,110,100,2,1,233.39,234.41,10,600,1,2,233.31,234.43,110,105,2,2,233.3,234.5,100,63,1,4,AAPL,-986,-17.480107194392907,0.22563936810900823
2024-10-21T12:19:02.578919174Z,2024-10-21T12:19:02.578752989Z,10,2,38,A,B,1,233.68,200,130,166185,12718270,233.7,233.97,1200,200,1,1,233.68,234.0,200,50,1,1,233.66,234.04,28,30,2,1,233.58,234.1,505,100,2,1,233.53,234.13,10,400,1,1,233.5,234.17,100,1,1,1,233.45,234.25,15,100,1,1,233.4,234.41,110,600,2,2,233.39,234.43,10,105,1,2,233.31,234.5,110,63,2,4,AAPL,-876,-15.343949044585987,0.1980650878289678
2024-10-21T12:19:02.578950637Z,2024-10-21T12:19:02.578784855Z,10,2,38,C,B,1,233.68,200,130,165782,12718271,233.7,233.97,1200,200,1,1,233.66,234.0,28,50,2,1,233.58,234.04,505,30,2,1,233.53,234.1,10,100,1,1,233.5,234.13,100,400,1,1,233.45,234.17,15,1,1,1,233.4,234.25,110,100,2,1,233.39,234.41,10,600,1,2,233.31,234.43,110,105,2,2,233.3,234.5,100,63,1,4,AAPL,-976,-16.934644303065355,0.2185983413717385
2024-10-21T12:19:02.583888440Z,2024-10-21T12:19:02.583722081Z,10,2,38,A,B,2,233.65,200,130,166359,12718279,233.7,233.97,1200,200,1,1,233.66,234.0,28,50,2,1,233.65,234.04,200,30,1,1,233.58,234.1,505,100,2,1,233.53,234.13,10,400,1,1,233.5,234.17,100,1,1,1,233.45,234.25,15,100,1,1,233.4,234.41,110,600,2,2,233.39,234.43,10,105,1,2,233.31,234.5,110,63,2,4,AAPL,-866,-14.864179104477612,0.19187204879780695
2024-10-21T12:19:05.634123171Z,2024-10-21T12:19:05.633956677Z,10,2,38,A,B,0,233.73,200,130,166494,12720933,233.73,233.97,200,200,1,1,233.7,234.0,1200,50,1,1,233.66,234.04,28,30,2,1,233.58,234.1,505,100,2,1,233.53,234.13,10,400,1,1,233.5,234.17,100,1,1,1,233.45,234.25,15,100,1,1,233.4,234.41,110,600,2,2,233.39,234.43,10,105,1,2,233.31,234.5,110,63,2,4,AAPL,-766,-13.466722478024279,0.17383318744266482
2024-10-21T12:19:06.744727908Z,2024-10-21T12:19:06.744561325Z,10,2,38,A,A,0,233.96,200,130,166583,12722330,233.73,233.96,200,200,1,1,233.7,234.0,1200,50,1,1,233.66,234.04,28,30,2,1,233.58,234.1,505,100,2,1,233.53,234.13,10,400,1,1,233.5,234.17,100,1,1,1,233.45,234.25,15,100,1,1,233.4,234.41,110,600,2,2,233.39,234.43,10,105,1,2,233.31,234.5,110,63,2,4,AAPL,-766,-13.30559482932741,0.17175329511520163
2024-10-21T12:19:07.485333806Z,2024-10-21T12:19:07.485167707Z,10,2,38,C,B,0,233.73,200,130,166099,12723226,233.7,233.96,1200,200,1,1,233.66,234.0,28,50,2,1,233.58,234.04,505,30,2,1,233.53,234.1,10,100,1,1,233.5,234.13,100,400,1,1,233.45,234.17,15,1,1,1,233.4,234.25,110,100,2,1,233.39,234.41,10,600,1,2,233.31,234.43,110,105,2,2,233.3,234.5,100,63,1,4,AAPL,-866,-15.897387620616616,0.20520906750792292
2024-10-21T12:19:07.485347068Z,2024-10-21T12:19:07.485180575Z,10,2,38,A,B,1,233.66,200,130,166493,12723227,233.7,233.96,1200,200,1,1,233.66,234.0,228,50,3,1,233.58,234.04,505,30,2,1,233.53,234.1,10,100,1,1,233.5,234.13,100,400,1,1,233.45,234.17,15,1,1,1,233.4,234.25,110,100,2,1,233.39,234.41,10,600,1,2,233.31,234.43,110,105,2,2,233.3,234.5,100,63,1,4,AAPL,-866,-15.7026291931097,0.20269505726600287
2024-10-21T12:19:07.567639201Z,2024-10-21T12:19:07.567472916Z,10,2,38,A,A,2,234.03,27,130,166285,12723377,233.7,233.96,1200,200,1,1,233.66,234.0,228,50,3,1,233.58,234.03,505,27,2,1,233.53,234.04,10,30,1,1,233.5,234.1,100,100,1,1,233.45,234.13,15,400,1,1,233.4,234.17,110,1,2,1,233.39,234.25,10,100,1,1,233.31,234.41,110,600,2,2,233.3,234.43,100,105,1,2,AAPL,-981,-17.50583390528483,0.22597145753641398
2024-10-21T12:19:07.624787875Z,2024-10-21T12:19:07.624621845Z,10,2,38,C,A,3,234.04,30,130,166030,12723449,233.7,233.96,1200,200,1,1,233.66,234.0,228,50,3,1,233.58,234.03,505,27,2,1,233.53,234.1,10,100,1,1,233.5,234.13,100,400,1,1,233.45,234.17,15,1,1,1,233.4,234.25,110,100,2,1,233.39,234.41,10,600,1,2,233.31,234.43,110,105,2,2,233.3,234.5,100,63,1,4,AAPL,-918,-16.19761799735333,0.2090845467450143
2024-10-21T12:19:08.124149233Z,2024-10-21T12:19:08.123983275Z,10,2,38,C,A,0,233.96,200,130,165958,12724349,233.7,234.0,1200,50,1,1,233.66,234.03,228,27,3,1,233.58,234.1,505,100,2,1,233.53,234.13,10,400,1,1,233.5,234.17,100,1,1,1,233.45,234.25,15,100,1,1,233.4,234.41,110,600,2,2,233.39,234.43,10,105,1,2,233.31,234.5,110,63,2,4,233.3,234.75,100,1,1,1,AAPL,-856,-13.127649977447001,0.16945632041761935
2024-10-21T12:19:08.201876654Z,2024-10-21T12:19:08.201710146Z,10,2,38,A,A,0,233.96,200,130,166508,12724487,233.7,233.96,1200,200,1,1,233.66,234.0,228,50,3,1,233.58,234.03,505,27,2,1,233.53,234.1,10,100,1,1,233.5,234.13,100,400,1,1,233.45,234.17,15,1,1,1,233.4,234.25,110,100,2,1,233.39,234.41,10,600,1,2,233.31,234.43,110,105,2,2,233.3,234.5,100,63,1,4,AAPL,-619,-8.485464429212952,0.10953335758336999
2024-10-21T12:19:10.540539563Z,2024-10-21T12:19:10.540372657Z,10,2,38,A,B,1,233.68,200,130,166906,12726299,233.7,233.96,1200,200,1,1,233.68,234.0,200,50,1,1,233.66,234.03,28,27,2,1,233.58,234.1,505,100,2,1,233.53,234.13,10,400,1,1,233.5,234.17,100,1,1,1,233.45,234.25,15,100,1,1,233.4,234.41,110,600,2,2,233.39,234.43,10,105,1,2,233.31,234.5,110,63,2,4,AAPL,-336,-4.525816911948116,0.05842083557225593
2024-10-21T12:19:10.824581833Z,2024-10-21T12:19:10.824415398Z,10,2,38,C,A,7,234.41,39,130,166435,12726899,233.7,233.96,1200,200,1,1,233.68,234.0,200,50,1,1,233.66,234.03,28,27,2,1,233.58,234.1,505,100,2,1,233.53,234.13,10,400,1,1,233.5,234.17,100,1,1,1,233.45,234.25,15,100,1,1,233.4,234.41,110,561,2,2,233.39,234.43,10,105,1,2,233.31,234.5,110,63,2,4,AAPL,-336,-4.499282639885222,0.058078321861388955
2024-10-21T12:19:10.828328587Z,2024-10-21T12:19:10.828162441Z,10,2,38,A,A,7,234.41,39,130,166146,12726909,233.7,233.96,1200,200,1,1,233.68,234.0,200,50,1,1,233.66,234.03,28,27,2,1,233.58,234.1,505,100,2,1,233.53,234.13,10,400,1,1,233.5,234.17,100,1,1,1,233.45,234.25,15,100,1,1,233.4,234.41,110,600,2,3,233.39,234.43,10,105,1,2,233.31,234.5,110,63,2,4,AAPL,-336,-4.474856486796785,0.05776302049127054
2024-10-21T12:19:14.207607166Z,2024-10-21T12:19:14.207440891Z,10,2,38,A,B,1,233.68,200,130,166275,12730136,233.7,233.96,1200,200,1,1,233.68,234.0,400,50,2,1,233.66,234.03,28,27,2,1,233.58,234.1,505,100,2,1,233.53,234.13,10,400,1,1,233.5,234.17,100,1,1,1,233.45,234.25,15,100,1,1,233.4,234.41,110,600,2,3,233.39,234.43,10,105,1,2,233.31,234.5,110,63,2,4,AAPL,-284,-3.712418300653595,0.04792120037939436
2024-10-21T12:19:21.463822961Z,2024-10-21T12:19:21.463656720Z,10,2,38,C,A,7,234.41,39,130,166241,12734671,233.7,233.96,1200,200,1,1,233.68,234.0,400,50,2,1,233.66,234.03,28,27,2,1,233.58,234.1,505,100,2,1,233.53,234.13,10,400,1,1,233.5,234.17,100,1,1,1,233.45,234.25,15,100,1,1,233.4,234.41,110,561,2,2,233.39,234.43,10,105,1,2,233.31,234.5,110,63,2,4,AAPL,-74,-0.8856036606828581,0.011431683351209834
2024-10-21T12:19:21.463929496Z,2024-10-21T12:19:21.463763491Z,10,2,38,C,A,7,234.41,61,130,166005,12734672,233.7,233.96,1200,200,1,1,233.68,234.0,400,50,2,1,233.66,234.03,28,27,2,1,233.58,234.1,505,100,2,1,233.53,234.13,10,400,1,1,233.5,234.17,100,1,1,1,233.45,234.25,15,100,1,1,233.4,234.41,110,500,2,1,233.39,234.43,10,105,1,2,233.31,234.5,110,63,2,4,AAPL,-74,-0.8838752488387525,0.011409372403570954
2024-10-21T12:19:31.377488376Z,2024-10-21T12:19:31.377322230Z,10,2,38,C,A,0,233.96,200,130,166146,12742017,233.7,234.0,1200,50,1,1,233.68,234.03,400,27,2,1,233.66,234.1,28,100,2,1,233.58,234.13,505,400,2,1,233.53,234.17,10,1,1,1,233.5,234.25,100,100,1,1,233.45,234.41,15,500,1,1,233.4,234.43,110,105,2,2,233.39,234.5,10,63,1,4,233.31,234.75,110,1,2,1,AAPL,1,0.012698412698412698,-0.000163915574738371
2024-10-21T12:19:31.377500536Z,2024-10-21T12:19:31.377334380Z,10,2,38,A,A,0,233.98,200,130,166156,12742018,233.7,233.98,1200,200,1,1,233.68,234.0,400,50,2,1,233.66,234.03,28,27,2,1,233.58,234.1,505,100,2,1,233.53,234.13,10,400,1,1,233.5,234.17,100,1,1,1,233.45,234.25,15,100,1,1,233.4,234.41,110,500,2,1,233.39,234.43,10,105,1,2,233.31,234.5,110,63,2,4,AAPL,-62,-0.772104607721046,0.009966597679453256
2024-10-21T12:19:31.411013263Z,2024-10-21T12:19:31.410847128Z,10,2,38,C,A,0,233.98,200,130,166135,12742043,233.7,234.0,1200,50,1,1,233.68,234.03,400,27,2,1,233.66,234.1,28,100,2,1,233.58,234.13,505,400,2,1,233.53,234.17,10,1,1,1,233.5,234.25,100,100,1,1,233.45,234.41,15,500,1,1,233.4,234.43,110,105,2,2,233.39,234.5,10,63,1,4,233.31,234.75,110,1,2,1,AAPL,-61,-0.8008752735229758,0.010337979546819908
2024-10-21T12:19:31.411026550Z,2024-10-21T12:19:31.410860369Z,10,2,38,A,A,1,234.03,200,130,166181,12742044,233.7,234.0,1200,50,1,1,233.68,234.03,400,227,2,2,233.66,234.1,28,100,2,1,233.58,234.13,505,400,2,1,233.53,234.17,10,1,1,1,233.5,234.25,100,100,1,1,233.45,234.41,15,500,1,1,233.4,234.43,110,105,2,2,233.39,234.5,10,63,1,4,233.31,234.75,110,1,2,1,AAPL,-61,-0.8331707317073171,0.010754860673260778
2024-10-21T12:19:31.424898662Z,2024-10-21T12:19:31.424732441Z,10,2,38,C,B,2,233.66,27,130,166221,12742086,233.7,234.0,1200,50,1,1,233.68,234.03,400,227,2,2,233.66,234.1,1,100,1,1,233.58,234.13,505,400,2,1,233.53,234.17,10,1,1,1,233.5,234.25,100,100,1,1,233.45,234.41,15,500,1,1,233.4,234.43,110,105,2,2,233.39,234.5,10,63,1,4,233.31,234.75,110,1,2,1,AAPL,-61,-0.8591549295774648,0.01109027383309084
2024-10-21T12:19:31.424956553Z,2024-10-21T12:19:31.424790390Z,10,2,38,A,B,2,233.67,30,130,166163,12742087,233.7,234.0,1200,50,1,1,233.68,234.03,400,227,2,2,233.67,234.1,30,100,1,1,233.66,234.13,1,400,1,1,233.58,234.17,505,1,2,1,233.53,234.25,10,100,1,1,233.5,234.41,100,500,1,1,233.45,234.43,15,105,1,2,233.4,234.5,110,63,2,4,233.39,234.75,10,1,1,1,AAPL,-51,-0.8003487358326068,0.01033118281322902
2024-10-21T12:19:31.428289474Z,2024-10-21T12:19:31.428123190Z,10,2,38,C,A,1,234.03,27,130,166284,12742092,233.7,234.0,1200,50,1,1,233.68,234.03,400,200,2,1,233.67,234.1,30,100,1,1,233.66,234.13,1,400,1,1,233.58,234.17,505,1,2,1,233.53,234.25,10,100,1,1,233.5,234.41,100,500,1,1,233.45,234.43,15,105,1,2,233.4,234.5,110,63,2,4,233.39,234.75,10,1,1,1,AAPL,-51,-0.8808290155440415,0.01137005055341939
2024-10-21T12:19:31.428332471Z,2024-10-21T12:19:31.428166239Z,10,2,38,A,A,2,234.09,30,130,166232,12742093,233.7,234.0,1200,50,1,1,233.68,234.03,400,200,2,1,233.67,234.09,30,30,1,1,233.66,234.1,1,100,1,1,233.58,234.13,505,400,2,1,233.53,234.17,10,1,1,1,233.5,234.25,100,100,1,1,233.45,234.41,15,500,1,1,233.4,234.43,110,105,2,2,233.39,234.5,10,63,1,4,AAPL,-114,-2.0373679935012188,0.02629906221665473
2024-10-21T12:19:31.428343415Z,2024-10-21T12:19:31.428177171Z,10,2,38,C,B,1,233.68,200,130,166244,12742094,233.7,234.0,1200,50,1,1,233.68,234.03,200,200,1,1,233.67,234.09,30,30,1,1,233.66,234.1,1,100,1,1,233.58,234.13,505,400,2,1,233.53,234.17,10,1,1,1,233.5,234.25,100,100,1,1,233.45,234.41,15,500,1,1,233.4,234.43,110,105,2,2,233.39,234.5,10,63,1,4,AAPL,-114,-2.098159509202454,0.027083780470191273
2024-10-21T12:19:31.428357645Z,2024-10-21T12:19:31.428190903Z,10,2,38,A,B,1,233.69,400,130,166742,12742095,233.7,234.0,1200,50,1,1,233.69,234.03,400,200,1,1,233.67,234.09,30,30,1,1,233.66,234.1,1,100,1,1,233.58,234.13,505,400,2,1,233.53,234.17,10,1,1,1,233.5,234.25,100,100,1,1,233.45,234.41,15,500,1,1,233.4,234.43,110,105,2,2,233.39,234.5,10,63,1,4,AAPL,-114,-2.1525054466230937,0.0277852969335925
2024-10-21T12:19:35.701715260Z,2024-10-21T12:19:35.701549120Z,10,2,38,C,B,1,233.69,200,130,166140,12745727,233.7,234.0,1200,50,1,1,233.69,234.03,200,200,1,1,233.67,234.09,30,30,1,1,233.66,234.1,1,100,1,1,233.58,234.13,505,400,2,1,233.53,234.17,10,1,1,1,233.5,234.25,100,100,1,1,233.45,234.41,15,500,1,1,233.4,234.43,110,105,2,2,233.39,234.5,10,63,1,4,AAPL,-114,-2.3210649960845733,0.02996112284851752
2024-10-21T12:19:38.701844794Z,2024-10-21T12:19:38.701678685Z,10,2,38,A,B,1,233.69,200,130,166109,12748118,233.7,234.0,1200,50,1,1,233.69,234.03,400,200,2,1,233.67,234.09,30,30,1,1,233.66,234.1,1,100,1,1,233.58,234.13,505,400,2,1,233.53,234.17,10,1,1,1,233.5,234.25,100,100,1,1,233.45,234.41,15,500,1,1,233.4,234.43,110,105,2,2,233.39,234.5,10,63,1,4,AAPL,-114,-2.3644444444444446,0.030521080016284684
2024-10-21T12:19:38.756345640Z,2024-10-21T12:19:38.756179281Z,10,2,38,C,B,1,233.69,200,130,166359,12748157,233.7,234.0,1200,50,1,1,233.69,234.03,200,200,1,1,233.67,234.09,30,30,1,1,233.66,234.1,1,100,1,1,233.58,234.13,505,400,2,1,233.53,234.17,10,1,1,1,233.5,234.25,100,100,1,1,233.45,234.41,15,500,1,1,233.4,234.43,110,105,2,2,233.39,234.5,10,63,1,4,AAPL,-114,-2.4033731553056925,0.031023585499938004
2024-10-21T12:19:38.756358436Z,2024-10-21T12:19:38.756191248Z,10,2,38,A,B,0,233.73,200,130,167188,12748158,233.73,234.0,200,50,1,1,233.7,234.03,1200,200,1,1,233.67,234.09,30,30,1,1,233.66,234.1,1,100,1,1,233.58,234.13,505,400,2,1,233.53,234.17,10,1,1,1,233.5,234.25,100,100,1,1,233.45,234.41,15,500,1,1,233.4,234.43,110,105,2,2,233.39,234.5,10,63,1,4,AAPL,-114,-2.4385026737967914,0.031477049673020875
2024-10-21T12:19:40.083493208Z,2024-10-21T12:19:40.083326842Z,10,2,38,A,A,1,234.03,200,130,166366,12749182,233.73,234.0,200,50,1,1,233.7,234.03,1200,400,1,2,233.67,234.09,30,30,1,1,233.66,234.1,1,100,1,1,233.58,234.13,505,400,2,1,233.53,234.17,10,1,1,1,233.5,234.25,100,100,1,1,233.45,234.41,15,500,1,1,233.4,234.43,110,105,2,2,233.39,234.5,10,63,1,4,AAPL,-114,-2.470363288718929,0.03188831768978118
2024-10-21T12:19:40.138138274Z,2024-10-21T12:19:40.137972145Z,10,2,38,C,A,1,234.03,200,130,166129,12749218,233.73,234.0,200,50,1,1,233.7,234.03,1200,200,1,1,233.67,234.09,30,30,1,1,233.66,234.1,1,100,1,1,233.58,234.13,505,400,2,1,233.53,234.17,10,1,1,1,233.5,234.25,100,100,1,1,233.45,234.41,15,500,1,1,233.4,234.43,110,105,2,2,233.39,234.5,10,63,1,4,AAPL,-114,-2.4993909866017052,0.03226301741759691
2024-10-21T12:19:40.138150186Z,2024-10-21T12:19:40.137983855Z,10,2,38,A,A,1,234.02,200,130,166331,12749219,233.73,234.0,200,50,1,1,233.7,234.02,1200,200,1,1,233.67,234.09,30,30,1,1,233.66,234.1,1,100,1,1,233.58,234.13,505,400,2,1,233.53,234.17,10,1,1,1,233.5,234.25,100,100,1,1,233.45,234.41,15,500,1,1,233.4,234.43,110,105,2,2,233.39,234.5,10,63,1,4,AAPL,-114,-2.5259475218658896,0.03260581850969189
2024-10-21T12:19:42.737318215Z,2024-10-21T12:19:42.737152214Z,10,2,38,C,B,0,233.73,200,130,166001,12752002,233.7,234.0,1200,50,1,1,233.67,234.02,30,200,1,1,233.66,234.09,1,30,1,1,233.58,234.1,505,100,2,1,233.53,234.13,10,400,1,1,233.5,234.17,100,1,1,1,233.45,234.25,15,100,1,1,233.4,234.41,110,500,2,1,233.39,234.43,10,105,1,2,233.31,234.5,110,63,2,4,AAPL,-224,-5.229571984435798,0.06750515342532759
2024-10-21T12:19:42.737331418Z,2024-10-21T12:19:42.737165303Z,10,2,38,A,B,1,233.68,200,130,166115,12752003,233.7,234.0,1200,50,1,1,233.68,234.02,200,200,1,1,233.67,234.09,30,30,1,1,233.66,234.1,1,100,1,1,233.58,234.13,505,400,2,1,233.53,234.17,10,1,1,1,233.5,234.25,100,100,1,1,233.45,234.41,15,500,1,1,233.4,234.43,110,105,2,2,233.39,234.5,10,63,1,4,AAPL,-214,-5.035294117647059,0.06499734643007994
2024-10-21T12:19:45.746085184Z,2024-10-21T12:19:45.745918365Z,10,2,38,A,B,1,233.68,200,130,166819,12754733,233.7,234.0,1200,50,1,1,233.68,234.02,400,200,2,1,233.67,234.09,30,30,1,1,233.66,234.1,1,100,1,1,233.58,234.13,505,400,2,1,233.53,234.17,10,1,1,1,233.5,234.25,100,100,1,1,233.45,234.41,15,500,1,1,233.4,234.43,110,105,2,2,233.39,234.5,10,63,1,4,AAPL,-214,-5.071090047393365,0.06545941287389567
2024-10-21T12:19:45.800644123Z,2024-10-21T12:19:45.800477942Z,10,2,38,C,B,1,233.68,200,130,166181,12754741,233.7,234.0,1200,50,1,1,233.68,234.02,200,200,1,1,233.67,234.09,30,30,1,1,233.66,234.1,1,100,1,1,233.58,234.13,505,400,2,1,233.53,234.17,10,1,1,1,233.5,234.25,100,100,1,1,233.45,234.41,15,500,1,1,233.4,234.43,110,105,2,2,233.39,234.5,10,63,1,4,AAPL,-214,-5.103918228279387,0.06588317057222753
2024-10-21T12:19:45.800657708Z,2024-10-21T12:19:45.800491117Z,10,2,38,A,B,0,233.72,200,130,166591,12754742,233.72,234.0,200,50,1,1,233.7,234.02,1200,200,1,1,233.67,234.09,30,30,1,1,233.66,234.1,1,100,1,1,233.58,234.13,505,400,2,1,233.53,234.17,10,1,1,1,233.5,234.25,100,100,1,1,233.45,234.41,15,500,1,1,233.4,234.43,110,105,2,2,233.39,234.5,10,63,1,4,AAPL,-214,-5.13413304252999,0.06627319401540321
2024-10-21T12:19:57.871170937Z,2024-10-21T12:19:57.871002706Z,10,2,38,A,B,0,233.73,200,130,168231,12763861,233.73,234.0,200,50,1,1,233.7,234.02,1200,200,1,1,233.67,234.09,30,30,1,1,233.66,234.1,1,100,1,1,233.58,234.13,505,400,2,1,233.53,234.17,10,1,1,1,233.5,234.25,100,100,1,1,233.45,234.41,15,500,1,1,233.4,234.43,110,105,2,2,233.39,234.5,10,63,1,4,AAPL,-100,-2.459016393442623,0.03174184797700013
2024-10-21T12:20:02.012956104Z,2024-10-21T12:20:02.012790106Z,10,2,38,C,B,0,233.73,200,130,165998,12769134,233.7,234.0,1200,50,1,1,233.67,234.02,30,200,1,1,233.66,234.09,1,30,1,1,233.58,234.1,505,100,2,1,233.53,234.13,10,400,1,1,233.5,234.17,100,1,1,1,233.45,234.25,15,100,1,1,233.4,234.41,110,500,2,1,233.39,234.43,10,105,1,2,233.31,234.5,110,63,2,4,AAPL,-210,-4.135021097046414,0.05337630582461512
2024-10-21T12:20:02.012967271Z,2024-10-21T12:20:02.012801350Z,10,2,38,A,B,0,233.71,200,130,165921,12769136,233.71,234.0,200,50,1,1,233.7,234.02,1200,200,1,1,233.67,234.09,30,30,1,1,233.66,234.1,1,100,1,1,233.58,234.13,505,400,2,1,233.53,234.17,10,1,1,1,233.5,234.25,100,100,1,1,233.45,234.41,15,500,1,1,233.4,234.43,110,105,2,2,233.39,234.5,10,63,1,4,AAPL,-200,-4.081632653061225,0.05268714902304782
2024-10-21T12:20:02.012989292Z,2024-10-21T12:20:02.012823085Z,10,2,38,A,A,1,234.02,200,130,166207,12769137,233.71,234.0,200,50,1,1,233.7,234.02,1200,400,1,2,233.67,234.09,30,30,1,1,233.66,234.1,1,100,1,1,233.58,234.13,505,400,2,1,233.53,234.17,10,1,1,1,233.5,234.25,100,100,1,1,233.45,234.41,15,500,1,1,233.4,234.43,110,105,2,2,233.39,234.5,10,63,1,4,AAPL,-200,-4.200700116686114,0.054224113696999046
2024-10-21T12:20:02.068369244Z,2024-10-21T12:20:02.068202840Z,10,2,38,A,B,0,233.72,200,130,166404,12769355,233.72,234.0,200,50,1,1,233.7,234.02,1200,400,1,2,233.67,234.09,30,30,1,1,233.66,234.1,1,100,1,1,233.58,234.13,505,400,2,1,233.53,234.17,10,1,1,1,233.5,234.25,100,100,1,1,233.45,234.41,15,500,1,1,233.4,234.43,110,105,2,2,233.39,234.5,10,63,1,4,AAPL,-200,-4.301075268817204,0.05551979144364179
2024-10-21T12:20:02.174238719Z,2024-10-21T12:20:02.174072577Z,10,2,38,C,A,1,234.02,200,130,166142,12769566,233.72,234.0,200,50,1,1,233.7,234.02,1200,200,1,1,233.67,234.09,30,30,1,1,233.66,234.1,1,100,1,1,233.58,234.13,505,400,2,1,233.53,234.17,10,1,1,1,233.5,234.25,100,100,1,1,233.45,234.41,15,500,1,1,233.4,234.43,110,105,2,2,233.39,234.5,10,63,1,4,AAPL,-200,-4.3868394815553335,0.05662686604869945
2024-10-21T12:20:02.174250737Z,2024-10-21T12:20:02.174084216Z,10,2,38,A,A,1,234.01,200,130,166521,12769567,233.72,234.0,200,50,1,1,233.7,234.01,1200,200,1,1,233.67,234.09,30,30,1,1,233.66,234.1,1,100,1,1,233.58,234.13,505,400,2,1,233.53,234.17,10,1,1,1,233.5,234.25,100,100,1,1,233.45,234.41,15,500,1,1,233.4,234.43,110,105,2,2,233.39,234.5,10,63,1,4,AAPL,-200,-4.4609665427509295,0.05758372421106343
2024-10-21T12:20:02.195927659Z,2024-10-21T12:20:02.195761354Z,10,2,38,A,A,2,234.08,27,130,166305,12769699,233.72,234.0,200,50,1,1,233.7,234.01,1200,200,1,1,233.67,234.08,30,27,1,1,233.66,234.09,1,30,1,1,233.58,234.1,505,100,2,1,233.53,234.13,10,400,1,1,233.5,234.17,100,1,1,1,233.45,234.25,15,100,1,1,233.4,234.41,110,500,2,1,233.39,234.43,10,105,1,2,AAPL,-305,-6.658270361041142,0.08594729427323969
2024-10-21T12:20:02.197265893Z,2024-10-21T12:20:02.197099790Z,10,2,38,C,A,3,234.09,30,130,166103,12769703,233.72,234.0,200,50,1,1,233.7,234.01,1200,200,1,1,233.67,234.08,30,27,1,1,233.66,234.1,1,100,1,1,233.58,234.13,505,400,2,1,233.53,234.17,10,1,1,1,233.5,234.25,100,100,1,1,233.45,234.41,15,500,1,1,233.4,234.43,110,105,2,2,233.39,234.5,10,63,1,4,AAPL,-242,-5.360759493670885,0.06919856790834031
2024-10-21T12:20:17.529825881Z,2024-10-21T12:20:17.529659579Z,10,2,38,C,A,1,234.01,200,130,166302,12783626,233.72,234.0,200,50,1,1,233.7,234.08,1200,27,1,1,233.67,234.1,30,100,1,1,233.66,234.13,1,400,1,1,233.58,234.17,505,1,2,1,233.53,234.25,10,100,1,1,233.5,234.41,100,500,1,1,233.45,234.43,15,105,1,2,233.4,234.5,110,63,2,4,233.39,234.75,10,1,1,1,AAPL,-141,-3.4814814814814814,0.044940186740770056
2024-10-21T12:20:17.529838088Z,2024-10-21T12:20:17.529671598Z,10,2,38,A,A,1,234.02,200,130,166490,12783627,233.72,234.0,200,50,1,1,233.7,234.02,1200,200,1,1,233.67,234.08,30,27,1,1,233.66,234.1,1,100,1,1,233.58,234.13,505,400,2,1,233.53,234.17,10,1,1,1,233.5,234.25,100,100,1,1,233.45,234.41,15,500,1,1,233.4,234.43,110,105,2,2,233.39,234.5,10,63,1,4,AAPL,-204,-5.082672706681767,0.06560892591141843
2024-10-21T12:20:18.175318074Z,2024-10-21T12:20:18.175151492Z,10,2,38,A,B,0,233.73,200,130,166582,12784239,233.73,234.0,200,50,1,1,233.7,234.02,1200,200,1,1,233.67,234.08,30,27,1,1,233.66,234.1,1,100,1,1,233.58,234.13,505,400,2,1,233.53,234.17,10,1,1,1,233.5,234.25,100,100,1,1,233.45,234.41,15,500,1,1,233.4,234.43,110,105,2,2,233.39,234.5,10,63,1,4,AAPL,-204,-5.082672706681767,0.06560892591141843
2024-10-21T12:20:26.003837302Z,2024-10-21T12:20:26.003671349Z,10,2,38,C,B,0,233.73,200,130,165953,12790391,233.7,234.0,1200,50,1,1,233.67,234.02,30,200,1,1,233.66,234.08,1,27,1,1,233.58,234.1,505,100,2,1,233.53,234.13,10,400,1,1,233.5,234.17,100,1,1,1,233.45,234.25,15,100,1,1,233.4,234.41,110,500,2,1,233.39,234.43,10,105,1,2,233.31,234.5,110,63,2,4,AAPL,-172,-4.16969696969697,0.05382391417772693
2024-10-21T12:20:26.003850219Z,2024-10-21T12:20:26.003684074Z,10,2,38,A,B,1,233.69,200,130,166145,12790392,233.7,234.0,1200,50,1,1,233.69,234.02,200,200,1,1,233.67,234.08,30,27,1,1,233.66,234.1,1,100,1,1,233.58,234.13,505,400,2,1,233.53,234.17,10,1,1,1,233.5,234.25,100,100,1,1,233.45,234.41,15,500,1,1,233.4,234.43,110,105,2,2,233.39,234.5,10,63,1,4,AAPL,-162,-4.01985111662531,0.05188965123386522
2024-10-21T12:20:29.006015290Z,2024-10-21T12:20:29.005849003Z,10,2,38,A,B,1,233.69,200,130,166287,12792364,233.7,234.0,1200,50,1,1,233.69,234.02,400,200,2,1,233.67,234.08,30,27,1,1,233.66,234.1,1,100,1,1,233.58,234.13,505,400,2,1,233.53,234.17,10,1,1,1,233.5,234.25,100,100,1,1,233.45,234.41,15,500,1,1,233.4,234.43,110,105,2,2,233.39,234.5,10,63,1,4,AAPL,-162,-4.084033613445379,0.05271814146364963
2024-10-21T12:20:29.035628478Z,2024-10-21T12:20:29.035461864Z,10,2,38,A,B,0,233.8,5,130,166614,12792376,233.8,234.0,5,50,1,1,233.7,234.02,1200,200,1,1,233.69,234.08,400,27,2,1,233.67,234.1,30,100,1,1,233.66,234.13,1,400,1,1,233.58,234.17,505,1,2,1,233.53,234.25,10,100,1,1,233.5,234.41,100,500,1,1,233.45,234.43,15,105,1,2,233.4,234.5,110,63,2,4,AAPL,-52,-1.1217257318952234,0.014479630045841003
2024-10-21T12:20:32.534136508Z,2024-10-21T12:20:32.533970326Z,10,2,38,C,A,2,234.08,27,130,166182,12795434,233.8,234.0,5,50,1,1,233.7,234.02,1200,200,1,1,233.69,234.1,400,100,2,1,233.67,234.13,30,400,1,1,233.66,234.17,1,1,1,1,233.58,234.25,505,100,2,1,233.53,234.41,10,500,1,1,233.5,234.43,100,105,1,2,233.45,234.5,15,63,1,4,233.4,234.75,110,1,2,1,AAPL,-51,-1.0736842105263158,0.013859493200904897
2024-10-21T12:20:32.534182863Z,2024-10-21T12:20:32.534015766Z,10,2,38,A,A,2,234.04,27,130,167097,12795435,233.8,234.0,5,50,1,1,233.7,234.02,1200,200,1,1,233.69,234.04,400,27,2,1,233.67,234.1,30,100,1,1,233.66,234.13,1,400,1,1,233.58,234.17,505,1,2,1,233.53,234.25,10,100,1,1,233.5,234.41,100,500,1,1,233.45,234.43,15,105,1,2,233.4,234.5,110,63,2,4,AAPL,-114,-2.1993569131832795,0.02839007213274069
2024-10-21T12:20:32.588752733Z,2024-10-21T12:20:32.588585911Z,10,2,38,A,A,0,233.99,200,130,166822,12795466,233.8,233.99,5,200,1,1,233.7,234.0,1200,50,1,1,233.69,234.04,400,27,2,1,233.67,234.1,30,100,1,1,233.66,234.13,1,400,1,1,233.58,234.17,505,1,2,1,233.53,234.25,10,100,1,1,233.5,234.41,100,500,1,1,233.45,234.43,15,105,1,2,233.4,234.5,110,63,2,4,AAPL,-114,-2.061482820976492,0.026610344886324157
2024-10-21T12:20:32.846479452Z,2024-10-21T12:20:32.846313500Z,10,2,38,C,A,0,233.99,200,130,165952,12795731,233.8,234.0,5,50,1,1,233.7,234.04,1200,27,1,1,233.69,234.1,400,100,2,1,233.67,234.13,30,400,1,1,233.66,234.17,1,1,1,1,233.58,234.25,505,100,2,1,233.53,234.41,10,500,1,1,233.5,234.43,100,105,1,2,233.45,234.5,15,63,1,4,233.4,234.75,110,1,2,1,AAPL,-113,-2.0427280197206246,0.026368251319201105
2024-10-21T12:20:32.846490898Z,2024-10-21T12:20:32.846324686Z,10,2,38,A,A,1,234.03,400,130,166212,12795732,233.8,234.0,5,50,1,1,233.7,234.03,1200,400,1,1,233.69,234.04,400,27,2,1,233.67,234.1,30,100,1,1,233.66,234.13,1,400,1,1,233.58,234.17,505,1,2,1,233.53,234.25,10,100,1,1,233.5,234.41,100,500,1,1,233.45,234.43,15,105,1,2,233.4,234.5,110,63,2,4,AAPL,-176,-3.0388489208633094,0.03922653005825305
2024-10-21T12:20:32.901109636Z,2024-10-21T12:20:32.900943370Z,10,2,38,A,A,0,233.98,200,130,166266,12795787,233.8,233.98,5,200,1,1,233.7,234.0,1200,50,1,1,233.69,234.04,400,27,2,1,233.67,234.1,30,100,1,1,233.66,234.13,1,400,1,1,233.58,234.17,505,1,2,1,233.53,234.25,10,100,1,1,233.5,234.41,100,500,1,1,233.45,234.43,15,105,1,2,233.4,234.5,110,63,2,4,AAPL,-176,-2.927703134996801,0.037791821185361084
2024-10-21T12:20:33.387963355Z,2024-10-21T12:20:33.387796787Z,10,2,38,A,A,0,233.97,200,130,166568,12796589,233.8,233.97,5,200,1,1,233.7,234.0,1200,50,1,1,233.69,234.04,400,27,2,1,233.67,234.1,30,100,1,1,233.66,234.13,1,400,1,1,233.58,234.17,505,1,2,1,233.53,234.25,10,100,1,1,233.5,234.41,100,500,1,1,233.45,234.43,15,105,1,2,233.4,234.5,110,63,2,4,AAPL,-176,-2.838709677419355,0.03664306235280359
2024-10-21T12:20:34.158685217Z,2024-10-21T12:20:34.158518772Z,10,2,38,A,A,0,233.97,200,130,166445,12797101,233.8,233.97,5,400,1,2,233.7,234.0,1200,50,1,1,233.69,234.04,400,27,2,1,233.67,234.1,30,100,1,1,233.66,234.13,1,400,1,1,233.58,234.17,505,1,2,1,233.53,234.25,10,100,1,1,233.5,234.41,100,500,1,1,233.45,234.43,15,105,1,2,233.4,234.5,110,63,2,4,AAPL,-176,-2.7658459926663173,0.035702512297650424
2024-10-21T12:20:53.733069722Z,2024-10-21T12:20:53.732903004Z,10,2,38,A,B,0,233.86,750,130,166718,12809362,233.86,233.97,750,400,1,2,233.8,234.0,5,50,1,1,233.7,234.04,1200,27,1,1,233.69,234.1,400,100,2,1,233.67,234.13,30,400,1,1,233.66,234.17,1,1,1,1,233.58,234.25,505,100,2,1,233.53,234.41,10,500,1,1,233.5,234.43,100,105,1,2,233.45,234.5,15,63,1,4,AAPL,15,0.23904382470119523,-0.0030856617156924428
2024-10-21T12:20:54.066491305Z,2024-10-21T12:20:54.066325257Z,10,2,38,C,A,0,233.97,200,130,166048,12809626,233.86,233.97,750,200,1,1,233.8,234.0,5,50,1,1,233.7,234.04,1200,27,1,1,233.69,234.1,400,100,2,1,233.67,234.13,30,400,1,1,233.66,234.17,1,1,1,1,233.58,234.25,505,100,2,1,233.53,234.41,10,500,1,1,233.5,234.43,100,105,1,2,233.45,234.5,15,63,1,4,AAPL,15,0.2735562310030395,-0.0035311599877149076
2024-10-21T12:20:54.066706343Z,2024-10-21T12:20:54.066539893Z,10,2,38,C,A,0,233.97,200,130,166450,12809627,233.86,234.0,750,50,1,1,233.8,234.04,5,27,1,1,233.7,234.1,1200,100,1,1,233.69,234.13,400,400,2,1,233.67,234.17,30,1,1,1,233.66,234.25,1,100,1,1,233.58,234.41,505,500,2,1,233.53,234.43,10,105,1,2,233.5,234.5,100,63,1,4,233.45,234.75,15,1,1,1,AAPL,16,0.3710144927536232,-0.004789185488008058
2024-10-21T12:20:54.088050706Z,2024-10-21T12:20:54.087884313Z,10,2,38,A,A,0,233.97,200,130,166393,12809662,233.86,233.97,750,200,1,1,233.8,234.0,5,50,1,1,233.7,234.04,1200,27,1,1,233.69,234.1,400,100,2,1,233.67,234.13,30,400,1,1,233.66,234.17,1,1,1,1,233.58,234.25,505,100,2,1,233.53,234.41,10,500,1,1,233.5,234.43,100,105,1,2,233.45,234.5,15,63,1,4,AAPL,-47,-1.1111111111111112,0.014342612789607464
2024-10-21T12:20:54.138176465Z,2024-10-21T12:20:54.138010479Z,10,2,38,C,A,0,233.97,200,130,165986,12809687,233.86,234.0,750,50,1,1,233.8,234.04,5,27,1,1,233.7,234.1,1200,100,1,1,233.69,234.13,400,400,2,1,233.67,234.17,30,1,1,1,233.66,234.25,1,100,1,1,233.58,234.41,505,500,2,1,233.53,234.43,10,105,1,2,233.5,234.5,100,63,1,4,233.45,234.75,15,1,1,1,AAPL,-46,-1.257403189066059,0.016231002355072865
2024-10-21T12:20:54.138190487Z,2024-10-21T12:20:54.138024196Z,10,2,38,A,A,1,234.03,200,130,166291,12809688,233.86,234.0,750,50,1,1,233.8,234.03,5,200,1,1,233.7,234.04,1200,27,1,1,233.69,234.1,400,100,2,1,233.67,234.13,30,400,1,1,233.66,234.17,1,1,1,1,233.58,234.25,505,100,2,1,233.53,234.41,10,500,1,1,233.5,234.43,100,105,1,2,233.45,234.5,15,63,1,4,AAPL,-109,-2.9516441005802707,0.03810085958461681
2024-10-21T12:20:54.138801017Z,2024-10-21T12:20:54.138635039Z,10,2,38,C,A,2,234.04,27,130,165978,12809691,233.86,234.0,750,50,1,1,233.8,234.03,5,200,1,1,233.7,234.1,1200,100,1,1,233.69,234.13,400,400,2,1,233.67,234.17,30,1,1,1,233.66,234.25,1,100,1,1,233.58,234.41,505,500,2,1,233.53,234.43,10,105,1,2,233.5,234.5,100,63,1,4,233.45,234.75,15,1,1,1,AAPL,-108,-3.2420262664165103,0.0418492146536539
2024-10-21T12:20:54.138845849Z,2024-10-21T12:20:54.138679423Z,10,2,38,A,A,2,234.1,29,130,166426,12809692,233.86,234.0,750,50,1,1,233.8,234.03,5,200,1,1,233.7,234.1,1200,129,1,2,233.69,234.13,400,400,2,1,233.67,234.17,30,1,1,1,233.66,234.25,1,100,1,1,233.58,234.41,505,500,2,1,233.53,234.43,10,105,1,2,233.5,234.5,100,63,1,4,233.45,234.75,15,1,1,1,AAPL,-108,-3.540983606557377,0.045708261086880184
2024-10-21T12:20:54.140867485Z,2024-10-21T12:20:54.140701289Z,10,2,38,A,A,1,234.03,200,130,166196,12809693,233.86,234.0,750,50,1,1,233.8,234.03,5,400,1,2,233.7,234.1,1200,129,1,2,233.69,234.13,400,400,2,1,233.67,234.17,30,1,1,1,233.66,234.25,1,100,1,1,233.58,234.41,505,500,2,1,233.53,234.43,10,105,1,2,233.5,234.5,100,63,1,4,233.45,234.75,15,1,1,1,AAPL,-108,-3.8230088495575223,0.04934874205840161
2024-10-21T12:20:54.260089240Z,2024-10-21T12:20:54.259923109Z,10,2,38,C,A,1,234.03,200,130,166131,12809712,233.86,234.0,750,50,1,1,233.8,234.03,5,200,1,1,233.7,234.1,1200,129,1,2,233.69,234.13,400,400,2,1,233.67,234.17,30,1,1,1,233.66,234.25,1,100,1,1,233.58,234.41,505,500,2,1,233.53,234.43,10,105,1,2,233.5,234.5,100,63,1,4,233.45,234.75,15,1,1,1,AAPL,-108,-5.294117647058824,0.06833833152695322
2024-10-21T12:20:54.260102529Z,2024-10-21T12:20:54.259936081Z,10,2,38,A,A,0,233.97,400,130,166448,12809713,233.86,233.97,750,400,1,1,233.8,234.0,5,50,1,1,233.7,234.1,1200,129,1,2,233.69,234.13,400,400,2,1,233.67,234.17,30,1,1,1,233.66,234.25,1,100,1,1,233.58,234.41,505,500,2,1,233.53,234.43,10,105,1,2,233.5,234.5,100,63,1,4,233.45,234.75,15,1,1,1,AAPL,-108,-5.60377358490566,0.07233547922003915
2024-10-21T12:20:54.368140579Z,2024-10-21T12:20:54.367974373Z,10,2,38,C,B,3,233.69,200,130,166206,12809780,233.86,233.97,750,400,1,1,233.8,234.0,5,50,1,1,233.7,234.1,1200,129,1,2,233.69,234.13,200,400,1,1,233.67,234.17,30,1,1,1,233.66,234.25,1,100,1,1,233.58,234.41,505,500,2,1,233.53,234.43,10,105,1,2,233.5,234.5,100,63,1,4,233.45,234.75,15,1,1,1,AAPL,-108,-5.8909090909090915,0.07604192526271886
2024-10-21T12:20:54.368154412Z,2024-10-21T12:20:54.367988079Z,10,2,38,A,B,2,233.71,200,130,166333,12809781,233.86,233.97,750,400,1,1,233.8,234.0,5,50,1,1,233.71,234.1,200,129,1,2,233.7,234.13,1200,400,1,1,233.67,234.17,30,1,1,1,233.66,234.25,1,100,1,1,233.58,234.41,505,500,2,1,233.53,234.43,10,105,1,2,233.5,234.5,100,63,1,4,233.45,234.75,15,1,1,1,AAPL,-108,-6.157894736842104,0.07948826982871925
2024-10-21T12:20:54.646690573Z,2024-10-21T12:20:54.646524020Z,10,2,38,A,B,2,233.71,200,130,166553,12810164,233.86,233.97,750,400,1,1,233.8,234.0,5,50,1,1,233.71,234.1,400,129,2,2,233.7,234.13,1200,400,1,1,233.67,234.17,30,1,1,1,233.66,234.25,1,100,1,1,233.58,234.41,505,500,2,1,233.53,234.43,10,105,1,2,233.5,234.5,100,63,1,4,233.45,234.75,15,1,1,1,AAPL,-108,-6.406779661016949,0.08270096391566881
2024-10-21T12:20:54.647477883Z,2024-10-21T12:20:54.647311583Z,10,2,38,C,B,4,233.67,30,130,166300,12810165,233.86,233.97,750,400,1,1,233.8,234.0,5,50,1,1,233.71,234.1,400,129,2,2,233.7,234.13,1200,400,1,1,233.66,234.17,1,1,1,1,233.58,234.25,505,100,2,1,233.53,234.41,10,500,1,1,233.5,234.43,100,105,1,2,233.45,234.5,15,63,1,4,233.4,234.75,110,1,2,1,AAPL,-218,-11.217838765008576,0.14480380596848977
2024-10-21T12:20:54.647518689Z,2024-10-21T12:20:54.647352236Z,10,2,38,A,B,2,233.73,26,130,166453,12810166,233.86,233.97,750,400,1,1,233.8,234.0,5,50,1,1,233.73,234.1,26,129,1,2,233.71,234.13,400,400,2,1,233.7,234.17,1200,1,1,1,233.66,234.25,1,100,1,1,233.58,234.41,505,500,2,1,233.53,234.43,10,105,1,2,233.5,234.5,100,63,1,4,233.45,234.75,15,1,1,1,AAPL,-203,-10.84474123539232,0.1399877319084492
2024-10-21T12:20:54.647548709Z,2024-10-21T12:20:54.647382777Z,10,2,38,C,A,2,234.1,29,130,165932,12810167,233.86,233.97,750,400,1,1,233.8,234.0,5,50,1,1,233.73,234.1,26,100,1,1,233.71,234.13,400,400,2,1,233.7,234.17,1200,1,1,1,233.66,234.25,1,100,1,1,233.58,234.41,505,500,2,1,233.53,234.43,10,105,1,2,233.5,234.5,100,63,1,4,233.45,234.75,15,1,1,1,AAPL,-203,-11.222764227642276,0.14486738557151813
2024-10-21T12:20:54.647589469Z,2024-10-21T12:20:54.647423336Z,10,2,38,A,A,2,234.04,27,130,166133,12810168,233.86,233.97,750,400,1,1,233.8,234.0,5,50,1,1,233.73,234.04,26,27,1,1,233.71,234.1,400,100,2,1,233.7,234.13,1200,400,1,1,233.66,234.17,1,1,1,1,233.58,234.25,505,100,2,1,233.53,234.41,10,500,1,1,233.5,234.43,100,105,1,2,233.45,234.5,15,63,1,4,AAPL,-266,-13.818181818181818,0.1783699481471183
2024-10-21T12:20:54.648089003Z,2024-10-21T12:20:54.647922749Z,10,2,38,C,A,0,233.97,200,130,166254,12810170,233.86,233.97,750,200,1,1,233.8,234.0,5,50,1,1,233.73,234.04,26,27,1,1,233.71,234.1,400,100,2,1,233.7,234.13,1200,400,1,1,233.66,234.17,1,1,1,1,233.58,234.25,505,100,2,1,233.53,234.41,10,500,1,1,233.5,234.43,100,105,1,2,233.45,234.5,15,63,1,4,AAPL,-266,-13.110246433203631,0.16923166935099485
2024-10-21T12:20:54.648283192Z,2024-10-21T12:20:54.648117162Z,10,2,38,C,A,0,233.97,200,130,166030,12810171,233.86,234.0,750,50,1,1,233.8,234.04,5,27,1,1,233.73,234.1,26,100,1,1,233.71,234.13,400,400,2,1,233.7,234.17,1200,1,1,1,233.66,234.25,1,100,1,1,233.58,234.41,505,500,2,1,233.53,234.43,10,105,1,2,233.5,234.5,100,63,1,4,233.45,234.75,15,1,1,1,AAPL,-265,-13.468869123252858,0.17386089709384397
2024-10-21T12:20:54.648295052Z,2024-10-21T12:20:54.648128723Z,10,2,38,A,A,1,234.03,400,130,166329,12810172,233.86,234.0,750,50,1,1,233.8,234.03,5,400,1,1,233.73,234.04,26,27,1,1,233.71,234.1,400,100,2,1,233.7,234.13,1200,400,1,1,233.66,234.17,1,1,1,1,233.58,234.25,505,100,2,1,233.53,234.41,10,500,1,1,233.5,234.43,100,105,1,2,233.45,234.5,15,63,1,4,AAPL,-328,-15.926011560693642,0.2055785553880569
2024-10-21T12:20:54.648612547Z,2024-10-21T12:20:54.648446832Z,10,2,38,C,A,2,234.04,27,130,165715,12810176,233.86,234.0,750,50,1,1,233.8,234.03,5,400,1,1,233.73,234.1,26,100,1,1,233.71,234.13,400,400,2,1,233.7,234.17,1200,1,1,1,233.66,234.25,1,100,1,1,233.58,234.41,505,500,2,1,233.53,234.43,10,105,1,2,233.5,234.5,100,63,1,4,233.45,234.75,15,1,1,1,AAPL,-327,-16.33144154370034,0.21081198812166285
2024-10-21T12:20:54.697366809Z,2024-10-21T12:20:54.697200659Z,10,2,38,C,B,3,233.71,200,130,166150,12810217,233.86,234.0,750,50,1,1,233.8,234.03,5,400,1,1,233.73,234.1,26,100,1,1,233.71,234.13,200,400,1,1,233.7,234.17,1200,1,1,1,233.66,234.25,1,100,1,1,233.58,234.41,505,500,2,1,233.53,234.43,10,105,1,2,233.5,234.5,100,63,1,4,233.45,234.75,15,1,1,1,AAPL,-327,-16.76923076923077,0.21646312533238343
2024-10-21T12:20:54.697379987Z,2024-10-21T12:20:54.697212843Z,10,2,38,A,B,2,233.77,200,130,167144,12810218,233.86,234.0,750,50,1,1,233.8,234.03,5,400,1,1,233.77,234.1,200,100,1,1,233.73,234.13,26,400,1,1,233.7,234.17,1200,1,1,1,233.66,234.25,1,100,1,1,233.58,234.41,505,500,2,1,233.53,234.43,10,105,1,2,233.5,234.5,100,63,1,4,233.45,234.75,15,1,1,1,AAPL,-327,-17.191675794085434,0.22191619420713135
2024-10-21T12:20:54.708397951Z,2024-10-21T12:20:54.708231641Z,10,2,38,A,A,0,233.99,200,130,166310,12810231,233.86,233.99,750,200,1,1,233.8,234.0,5,50,1,1,233.77,234.1,200,100,1,1,233.73,234.13,26,400,1,1,233.7,234.17,1200,1,1,1,233.66,234.25,1,100,1,1,233.58,234.41,505,500,2,1,233.53,234.43,10,105,1,2,233.5,234.5,100,63,1,4,233.45,234.75,15,1,1,1,AAPL,-327,-17.599569429494082,0.2271814286319417
2024-10-21T12:20:56.393759280Z,2024-10-21T12:20:56.393593183Z,10,2,38,A,A,2,234.05,30,130,166097,12811166,233.86,233.99,750,200,1,1,233.8,234.0,5,50,1,1,233.77,234.05,200,30,1,1,233.73,234.1,26,100,1,1,233.7,234.13,1200,400,1,1,233.66,234.17,1,1,1,1,233.58,234.25,505,100,2,1,233.53,234.41,10,500,1,1,233.5,234.43,100,105,1,2,233.45,234.5,15,63,1,4,AAPL,-390,-20.1390268123138,0.2599616371756856
2024-10-21T12:20:56.654514873Z,2024-10-21T12:20:56.654348888Z,10,2,38,C,A,0,233.99,200,130,165985,12811490,233.86,234.0,750,50,1,1,233.8,234.05,5,30,1,1,233.77,234.1,200,100,1,1,233.73,234.13,26,400,1,1,233.7,234.17,1200,1,1,1,233.66,234.25,1,100,1,1,233.58,234.41,505,500,2,1,233.53,234.43,10,105,1,2,233.5,234.5,100,63,1,4,233.45,234.75,15,1,1,1,AAPL,-389,-20.533724340175954,0.2650565316057136
2024-10-21T12:20:56.654527697Z,2024-10-21T12:20:56.654361253Z,10,2,38,A,A,1,234.03,400,130,166444,12811491,233.86,234.0,750,50,1,1,233.8,234.03,5,400,1,1,233.77,234.05,200,30,1,1,233.73,234.1,26,100,1,1,233.7,234.13,1200,400,1,1,233.66,234.17,1,1,1,1,233.58,234.25,505,100,2,1,233.53,234.41,10,500,1,1,233.5,234.43,100,105,1,2,233.45,234.5,15,63,1,4,AAPL,-452,-22.990009082652136,0.29676311847183445
2024-10-21T12:20:56.655842318Z,2024-10-21T12:20:56.655676466Z,10,2,38,C,A,2,234.05,30,130,165852,12811493,233.86,234.0,750,50,1,1,233.8,234.03,5,400,1,1,233.77,234.1,200,100,1,1,233.73,234.13,26,400,1,1,233.7,234.17,1200,1,1,1,233.66,234.25,1,100,1,1,233.58,234.41,505,500,2,1,233.53,234.43,10,105,1,2,233.5,234.5,100,63,1,4,233.45,234.75,15,1,1,1,AAPL,-451,-23.418084153983887,0.3022888619655299
2024-10-21T12:21:00.388479265Z,2024-10-21T12:21:00.388313049Z,10,2,38,A,A,2,234.1,26,130,166216,12815663,233.86,234.0,750,50,1,1,233.8,234.03,5,400,1,1,233.77,234.1,200,126,1,2,233.73,234.13,26,400,1,1,233.7,234.17,1200,1,1,1,233.66,234.25,1,100,1,1,233.58,234.41,505,500,2,1,233.53,234.43,10,105,1,2,233.5,234.5,100,63,1,4,233.45,234.75,15,1,1,1,AAPL,-451,-23.88349514563107,0.3082965506426304
2024-10-21T12:21:01.708023897Z,2024-10-21T12:21:01.707857424Z,10,2,38,A,A,0,234.0,200,130,166473,12817432,233.86,234.0,750,250,1,2,233.8,234.1,5,126,1,2,233.77,234.13,200,400,1,1,233.73,234.17,26,1,1,1,233.7,234.25,1200,100,1,1,233.66,234.41,1,500,1,1,233.58,234.43,505,105,2,2,233.53,234.5,10,63,1,4,233.5,234.75,100,1,1,1,233.45,234.79,15,2000,1,1,AAPL,1549,30.507623888182973,-0.39380313290326857
2024-10-21T12:21:01.856991707Z,2024-10-21T12:21:01.856825426Z,10,2,38,C,A,0,234.0,200,130,166281,12817610,233.86,234.0,750,50,1,1,233.8,234.1,5,126,1,2,233.77,234.13,200,400,1,1,233.73,234.17,26,1,1,1,233.7,234.25,1200,100,1,1,233.66,234.41,1,500,1,1,233.58,234.43,505,105,2,2,233.53,234.5,10,63,1,4,233.5,234.75,100,1,1,1,233.45,234.79,15,2000,1,1,AAPL,1549,19.201239589386017,-0.24785635005994056
2024-10-21T12:21:01.857003762Z,2024-10-21T12:21:01.856837629Z,10,2,38,A,A,1,234.03,400,130,166133,12817611,233.86,234.0,750,50,1,1,233.8,234.03,5,400,1,1,233.77,234.1,200,126,1,2,233.73,234.13,26,400,1,1,233.7,234.17,1200,1,1,1,233.66,234.25,1,100,1,1,233.58,234.41,505,500,2,1,233.53,234.43,10,105,1,2,233.5,234.5,100,63,1,4,233.45,234.75,15,1,1,1,AAPL,1548,19.72736049430392,-0.2546477036377204
2024-10-21T12:21:06.854114356Z,2024-10-21T12:21:06.853945458Z,10,2,38,C,B,2,233.77,200,128,168898,12822045,233.86,234.0,750,50,1,1,233.8,234.03,5,400,1,1,233.73,234.1,26,126,1,2,233.7,234.13,1200,400,1,1,233.66,234.17,1,1,1,1,233.58,234.25,505,100,2,1,233.53,234.41,10,500,1,1,233.5,234.43,100,105,1,2,233.45,234.5,15,63,1,4,233.4,234.75,110,1,2,1,AAPL,1438,18.48468809073724,-0.23860685143990146
2024-10-21T12:21:06.917672196Z,2024-10-21T12:21:06.917506080Z,10,2,38,C,A,2,234.1,26,130,166116,12822954,233.86,234.0,750,50,1,1,233.8,234.03,5,400,1,1,233.73,234.1,26,100,1,1,233.7,234.13,1200,400,1,1,233.66,234.17,1,1,1,1,233.58,234.25,505,100,2,1,233.53,234.41,10,500,1,1,233.5,234.43,100,105,1,2,233.45,234.5,15,63,1,4,233.4,234.75,110,1,2,1,AAPL,1438,18.637289390853546,-0.2405766826627844
2024-10-21T12:21:06.917723950Z,2024-10-21T12:21:06.917557816Z,10,2,38,A,A,2,234.04,29,130,166134,12822956,233.86,234.0,750,50,1,1,233.8,234.03,5,400,1,1,233.73,234.04,26,29,1,1,233.7,234.1,1200,100,1,1,233.66,234.13,1,400,1,1,233.58,234.17,505,1,2,1,233.53,234.25,10,100,1,1,233.5,234.41,100,500,1,1,233.45,234.43,15,105,1,2,233.4,234.5,110,63,2,4,AAPL,1375,17.761033369214207,-0.22926566192214295
2024-10-21T12:21:06.921436322Z,2024-10-21T12:21:06.921270364Z,10,2,38,C,A,2,234.04,29,130,165958,12822971,233.86,234.0,750,50,1,1,233.8,234.03,5,400,1,1,233.73,234.1,26,100,1,1,233.7,234.13,1200,400,1,1,233.66,234.17,1,1,1,1,233.58,234.25,505,100,2,1,233.53,234.41,10,500,1,1,233.5,234.43,100,105,1,2,233.45,234.5,15,63,1,4,233.4,234.75,110,1,2,1,AAPL,1376,17.91099384344767,-0.23120140443625178
2024-10-21T12:21:06.921907160Z,2024-10-21T12:21:06.921738635Z,10,2,38,A,B,4,233.67,30,130,168525,12822978,233.86,234.0,750,50,1,1,233.8,234.03,5,400,1,1,233.73,234.1,26,100,1,1,233.7,234.13,1200,400,1,1,233.67,234.17,30,1,1,1,233.66,234.25,1,100,1,1,233.58,234.41,505,500,2,1,233.53,234.43,10,105,1,2,233.5,234.5,100,63,1,4,233.45,234.75,15,1,1,1,AAPL,1391,18.54341343623926,-0.2393648988422257
2024-10-21T12:21:06.921927508Z,2024-10-21T12:21:06.921761416Z,10,2,38,C,B,2,233.73,26,130,166092,12822980,233.86,234.0,750,50,1,1,233.8,234.03,5,400,1,1,233.7,234.1,1200,100,1,1,233.67,234.13,30,400,1,1,233.66,234.17,1,1,1,1,233.58,234.25,505,100,2,1,233.53,234.41,10,500,1,1,233.5,234.43,100,105,1,2,233.45,234.5,15,63,1,4,233.4,234.75,110,1,2,1,AAPL,1281,17.191672401927047,-0.22191615041995846
2024-10-21T12:21:06.954339916Z,2024-10-21T12:21:06.954173708Z,10,2,38,A,B,2,233.72,200,130,166208,12823107,233.86,234.0,750,50,1,1,233.8,234.03,5,400,1,1,233.72,234.1,200,100,1,1,233.7,234.13,1200,400,1,1,233.67,234.17,30,1,1,1,233.66,234.25,1,100,1,1,233.58,234.41,505,500,2,1,233.53,234.43,10,105,1,2,233.5,234.5,100,63,1,4,233.45,234.75,15,1,1,1,AAPL,1296,17.789979409746056,-0.2296393075881695
2024-10-21T12:21:07.982871946Z,2024-10-21T12:21:07.982705400Z,10,2,38,A,B,4,233.68,29,130,166546,12824965,233.86,234.0,750,50,1,1,233.8,234.03,5,400,1,1,233.72,234.1,200,100,1,1,233.7,234.13,1200,400,1,1,233.68,234.17,29,1,1,1,233.67,234.25,30,100,1,1,233.66,234.41,1,500,1,1,233.58,234.43,505,105,2,2,233.53,234.5,10,63,1,4,233.5,234.75,100,1,1,1,AAPL,1396,19.30713442401754,-0.24922327780852604
2024-10-21T12:21:07.982898445Z,2024-10-21T12:21:07.982732401Z,10,2,38,C,B,5,233.67,30,130,166044,12824966,233.86,234.0,750,50,1,1,233.8,234.03,5,400,1,1,233.72,234.1,200,100,1,1,233.7,234.13,1200,400,1,1,233.68,234.17,29,1,1,1,233.66,234.25,1,100,1,1,233.58,234.41,505,500,2,1,233.53,234.43,10,105,1,2,233.5,234.5,100,63,1,4,233.45,234.75,15,1,1,1,AAPL,1381,19.512867956265772,-0.2518789585603132
2024-10-21T12:21:08.049635180Z,2024-10-21T12:21:08.049468728Z,10,2,38,A,B,2,233.73,200,130,166452,12825229,233.86,234.0,750,50,1,1,233.8,234.03,5,400,1,1,233.73,234.1,200,100,1,1,233.7,234.13,1200,400,1,1,233.68,234.17,29,1,1,1,233.66,234.25,1,100,1,1,233.58,234.41,505,500,2,1,233.53,234.43,10,105,1,2,233.5,234.5,100,63,1,4,233.45,234.75,15,1,1,1,AAPL,1381,19.92383828216742,-0.25718390798749674
2024-10-21T12:21:08.155903006Z,2024-10-21T12:21:08.155736487Z,10,2,38,A,B,2,233.73,200,130,166519,12825740,233.86,234.0,750,50,1,1,233.8,234.03,5,400,1,1,233.73,234.1,400,100,2,1,233.7,234.13,1200,400,1,1,233.68,234.17,29,1,1,1,233.66,234.25,1,100,1,1,233.58,234.41,505,500,2,1,233.53,234.43,10,105,1,2,233.5,234.5,100,63,1,4,233.45,234.75,15,1,1,1,AAPL,1381,20.3326083319391,-0.2624604554769741
2024-10-21T12:21:08.156442002Z,2024-10-21T12:21:08.156275244Z,10,2,38,A,B,0,233.86,100,130,166758,12825741,233.86,234.0,850,50,2,1,233.8,234.03,5,400,1,1,233.73,234.1,400,100,2,1,233.7,234.13,1200,400,1,1,233.68,234.17,29,1,1,1,233.66,234.25,1,100,1,1,233.58,234.41,505,500,2,1,233.53,234.43,10,105,1,2,233.5,234.5,100,63,1,4,233.45,234.75,15,1,1,1,AAPL,1381,20.739195728349742,-0.26770882850964134
2024-10-21T12:21:08.214759234Z,2024-10-21T12:21:08.214593412Z,10,2,38,C,B,2,233.73,200,130,165822,12825863,233.86,234.0,850,50,2,1,233.8,234.03,5,400,1,1,233.73,234.1,200,100,1,1,233.7,234.13,1200,400,1,1,233.68,234.17,29,1,1,1,233.66,234.25,1,100,1,1,233.58,234.41,505,500,2,1,233.53,234.43,10,105,1,2,233.5,234.5,100,63,1,4,233.45,234.75,15,1,1,1,AAPL,1381,21.143617906473626,-0.27292925214356584
2024-10-21T12:21:08.214770994Z,2024-10-21T12:21:08.214604801Z,10,2,38,A,B,2,233.76,400,130,166193,12825864,233.86,234.0,850,50,2,1,233.8,234.03,5,400,1,1,233.76,234.1,400,100,1,1,233.7,234.13,1200,400,1,1,233.68,234.17,29,1,1,1,233.66,234.25,1,100,1,1,233.58,234.41,505,500,2,1,233.53,234.43,10,105,1,2,233.5,234.5,100,63,1,4,233.45,234.75,15,1,1,1,AAPL,1381,21.54589211618257,-0.2781219490461565
2024-10-21T12:21:09.374399277Z,2024-10-21T12:21:09.374232780Z,10,2,38,A,A,2,234.06,26,130,166497,12827250,233.86,234.0,850,50,2,1,233.8,234.03,5,400,1,1,233.76,234.06,400,26,1,1,233.7,234.1,1200,100,1,1,233.68,234.13,29,400,1,1,233.66,234.17,1,1,1,1,233.58,234.25,505,100,2,1,233.53,234.41,10,500,1,1,233.5,234.43,100,105,1,2,233.45,234.5,15,63,1,4,AAPL,1318,20.732098967720795,-0.267617221028856
2024-10-21T12:21:13.168706863Z,2024-10-21T12:21:13.168540873Z,10,2,38,C,B,0,233.86,100,130,165990,12830353,233.86,234.0,750,50,1,1,233.8,234.03,5,400,1,1,233.76,234.06,400,26,1,1,233.7,234.1,1200,100,1,1,233.68,234.13,29,400,1,1,233.66,234.17,1,1,1,1,233.58,234.25,505,100,2,1,233.53,234.41,10,500,1,1,233.5,234.43,100,105,1,2,233.45,234.5,15,63,1,4,AAPL,1318,20.896942242355607,-0.2697450759620082
2024-10-21T12:21:16.960190551Z,2024-10-21T12:21:16.960024614Z,10,2,38,C,B,2,233.76,400,130,165937,12834954,233.86,234.0,750,50,1,1,233.8,234.03,5,400,1,1,233.7,234.06,1200,26,1,1,233.68,234.1,29,100,1,1,233.66,234.13,1,400,1,1,233.58,234.17,505,1,2,1,233.53,234.25,10,100,1,1,233.5,234.41,100,500,1,1,233.45,234.43,15,105,1,2,233.4,234.5,110,63,2,4,AAPL,1659,13.304945579530266,-0.17174491437060188
2024-10-21T12:21:16.960203958Z,2024-10-21T12:21:16.960037598Z,10,2,38,A,B,2,233.73,200,130,166360,12834955,233.86,234.0,750,50,1,1,233.8,234.03,5,400,1,1,233.73,234.06,200,26,1,1,233.7,234.1,1200,100,1,1,233.68,234.13,29,400,1,1,233.66,234.17,1,1,1,1,233.58,234.25,505,100,2,1,233.53,234.41,10,500,1,1,233.5,234.43,100,105,1,2,233.45,234.5,15,63,1,4,AAPL,1674,13.858137347130763,-0.17888570815958507
2024-10-21T12:21:17.838076240Z,2024-10-21T12:21:17.837910042Z,10,2,38,C,A,1,234.03,400,130,166198,12836232,233.86,234.0,750,50,1,1,233.8,234.06,5,26,1,1,233.73,234.1,200,100,1,1,233.7,234.13,1200,400,1,1,233.68,234.17,29,1,1,1,233.66,234.25,1,100,1,1,233.58,234.41,505,500,2,1,233.53,234.43,10,105,1,2,233.5,234.5,100,63,1,4,233.45,234.75,15,1,1,1,AAPL,1675,14.453198274244981,-0.18656696377702675
2024-10-21T12:21:17.838088673Z,2024-10-21T12:21:17.837922361Z,10,2,38,A,A,1,234.05,400,130,166312,12836233,233.86,234.0,750,50,1,1,233.8,234.05,5,400,1,1,233.73,234.06,200,26,1,1,233.7,234.1,1200,100,1,1,233.68,234.13,29,400,1,1,233.66,234.17,1,1,1,1,233.58,234.25,505,100,2,1,233.53,234.41,10,500,1,1,233.5,234.43,100,105,1,2,233.45,234.5,15,63,1,4,AAPL,1612,14.305047143649473,-0.18465457690660017
2024-10-21T12:21:17.892937930Z,2024-10-21T12:21:17.892771425Z,10,2,38,A,B,2,233.74,200,130,166505,12836353,233.86,234.0,750,50,1,1,233.8,234.05,5,400,1,1,233.74,234.06,200,26,1,1,233.7,234.1,1200,100,1,1,233.68,234.13,29,400,1,1,233.66,234.17,1,1,1,1,233.58,234.25,505,100,2,1,233.53,234.41,10,500,1,1,233.5,234.43,100,105,1,2,233.45,234.5,15,63,1,4,AAPL,1612,14.689265536723164,-0.18961420298125123
2024-10-21T12:21:18.021459648Z,2024-10-21T12:21:18.021293469Z,10,2,38,C,B,4,233.68,29,130,166179,12836833,233.86,234.0,750,50,1,1,233.8,234.05,5,400,1,1,233.74,234.06,200,26,1,1,233.7,234.1,1200,100,1,1,233.66,234.13,1,400,1,1,233.58,234.17,505,1,2,1,233.53,234.25,10,100,1,1,233.5,234.41,100,500,1,1,233.45,234.43,15,105,1,2,233.4,234.5,110,63,2,4,AAPL,1502,13.799293286219083,-0.1781261283370232
2024-10-21T12:21:18.047995053Z,2024-10-21T12:21:18.047828600Z,10,2,38,A,B,2,233.74,200,130,166453,12836959,233.86,234.0,750,50,1,1,233.8,234.05,5,400,1,1,233.74,234.06,400,26,2,1,233.7,234.1,1200,100,1,1,233.66,234.13,1,400,1,1,233.58,234.17,505,1,2,1,233.53,234.25,10,100,1,1,233.5,234.41,100,500,1,1,233.45,234.43,15,105,1,2,233.4,234.5,110,63,2,4,AAPL,1502,13.905023144179667,-0.17949092650874918
2024-10-21T12:21:18.102567260Z,2024-10-21T12:21:18.102401275Z,10,2,38,C,B,2,233.74,200,130,165985,12837042,233.86,234.0,750,50,1,1,233.8,234.05,5,400,1,1,233.74,234.06,200,26,1,1,233.7,234.1,1200,100,1,1,233.66,234.13,1,400,1,1,233.58,234.17,505,1,2,1,233.53,234.25,10,100,1,1,233.5,234.41,100,500,1,1,233.45,234.43,15,105,1,2,233.4,234.5,110,63,2,4,AAPL,1502,14.004662004662004,-0.18077709994397545
2024-10-21T12:21:18.102579613Z,2024-10-21T12:21:18.102413183Z,10,2,38,A,B,2,233.77,400,130,166430,12837043,233.86,234.0,750,50,1,1,233.8,234.05,5,400,1,1,233.77,234.06,400,26,1,1,233.7,234.1,1200,100,1,1,233.66,234.13,1,400,1,1,233.58,234.17,505,1,2,1,233.53,234.25,10,100,1,1,233.5,234.41,100,500,1,1,233.45,234.43,15,105,1,2,233.4,234.5,110,63,2,4,AAPL,1502,14.098721475966986,-0.18199125266248578
2024-10-21T12:21:18.740047899Z,2024-10-21T12:21:18.739881846Z,10,2,38,C,A,1,234.05,200,130,166053,12837434,233.86,234.0,750,50,1,1,233.8,234.05,5,200,1,1,233.77,234.06,400,26,1,1,233.7,234.1,1200,100,1,1,233.66,234.13,1,400,1,1,233.58,234.17,505,1,2,1,233.53,234.25,10,100,1,1,233.5,234.41,100,500,1,1,233.45,234.43,15,105,1,2,233.4,234.5,110,63,2,4,AAPL,1502,14.18765743073048,-0.18313926922850793
2024-10-21T12:21:21.742938480Z,2024-10-21T12:21:21.742772097Z,10,2,38,A,A,1,234.05,200,130,166383,12841885,233.86,234.0,750,50,1,1,233.8,234.05,5,400,1,2,233.77,234.06,400,26,1,1,233.7,234.1,1200,100,1,1,233.66,234.13,1,400,1,1,233.58,234.17,505,1,2,1,233.53,234.25,10,100,1,1,233.5,234.41,100,500,1,1,233.45,234.43,15,105,1,2,233.4,234.5,110,63,2,4,AAPL,-498,-6.427236315086783,0.08296502559713391
2024-10-21T12:21:26.102361829Z,2024-10-21T12:21:26.102195386Z,10,2,38,A,B,2,233.78,400,130,166443,12846472,233.86,234.0,750,50,1,1,233.8,234.05,5,400,1,2,233.78,234.06,400,26,1,1,233.7,234.1,1200,100,1,1,233.66,234.13,1,400,1,1,233.58,234.17,505,1,2,1,233.53,234.25,10,100,1,1,233.5,234.41,100,500,1,1,233.45,234.43,15,105,1,2,233.4,234.5,110,63,2,4,AAPL,-497,-10.558421851289834,0.13629182065414244
2024-10-21T12:21:26.482529203Z,2024-10-21T12:21:26.482363138Z,10,2,38,C,B,2,233.78,200,130,166065,12846917,233.86,234.0,750,50,1,1,233.8,234.05,5,400,1,2,233.78,234.06,200,26,1,1,233.7,234.1,1200,100,1,1,233.66,234.13,1,400,1,1,233.58,234.17,505,1,2,1,233.53,234.25,10,100,1,1,233.5,234.41,100,500,1,1,233.45,234.43,15,105,1,2,233.4,234.5,110,63,2,4,AAPL,-497,-10.262014951940193,0.1324656962071564
2024-10-21T12:21:26.509714476Z,2024-10-21T12:21:26.509547941Z,10,2,38,A,B,2,233.78,200,130,166535,12846932,233.86,234.0,750,50,1,1,233.8,234.05,5,400,1,2,233.78,234.06,400,26,2,1,233.7,234.1,1200,100,1,1,233.66,234.13,1,400,1,1,233.58,234.17,505,1,2,1,233.53,234.25,10,100,1,1,233.5,234.41,100,500,1,1,233.45,234.43,15,105,1,2,233.4,234.5,110,63,2,4,AAPL,-497,-10.0,0.12908351510646718
2024-10-21T12:21:26.750930428Z,2024-10-21T12:21:26.750764565Z,10,2,38,C,B,2,233.78,200,130,165863,12847141,233.86,234.0,750,50,1,1,233.8,234.05,5,400,1,2,233.78,234.06,200,26,1,1,233.7,234.1,1200,100,1,1,233.66,234.13,1,400,1,1,233.58,234.17,505,1,2,1,233.53,234.25,10,100,1,1,233.5,234.41,100,500,1,1,233.45,234.43,15,105,1,2,233.4,234.5,110,63,2,4,AAPL,-497,-9.766719492868463,0.12607224831983135
2024-10-21T12:21:26.750938918Z,2024-10-21T12:21:26.750773173Z,10,2,38,C,B,2,233.78,200,130,165745,12847142,233.86,234.0,750,50,1,1,233.8,234.05,5,400,1,2,233.7,234.06,1200,26,1,1,233.66,234.1,1,100,1,1,233.58,234.13,505,400,2,1,233.53,234.17,10,1,1,1,233.5,234.25,100,100,1,1,233.45,234.41,15,500,1,1,233.4,234.43,110,105,2,2,233.39,234.5,10,63,1,4,AAPL,-507,-10.052044609665428,0.12975532522226293
2024-10-21T12:21:26.750951960Z,2024-10-21T12:21:26.750785721Z,10,2,38,A,B,2,233.75,400,130,166239,12847143,233.86,234.0,750,50,1,1,233.8,234.05,5,400,1,2,233.75,234.06,400,26,1,1,233.7,234.1,1200,100,1,1,233.66,234.13,1,400,1,1,233.58,234.17,505,1,2,1,233.53,234.25,10,100,1,1,233.5,234.41,100,500,1,1,233.45,234.43,15,105,1,2,233.4,234.5,110,63,2,4,AAPL,-397,-7.704204645692443,0.09944858167655551
2024-10-21T12:21:26.804985162Z,2024-10-21T12:21:26.804818995Z,10,2,38,C,A,1,234.05,200,130,166167,12847412,233.86,234.0,750,50,1,1,233.8,234.05,5,200,1,1,233.75,234.06,400,26,1,1,233.7,234.1,1200,100,1,1,233.66,234.13,1,400,1,1,233.58,234.17,505,1,2,1,233.53,234.25,10,100,1,1,233.5,234.41,100,500,1,1,233.45,234.43,15,105,1,2,233.4,234.5,110,63,2,4,AAPL,-397,-7.553441522104085,0.0975024782824339
2024-10-21T12:21:26.804997390Z,2024-10-21T12:21:26.804831024Z,10,2,38,A,A,1,234.04,400,130,166366,12847413,233.86,234.0,750,50,1,1,233.8,234.04,5,400,1,1,233.75,234.06,400,26,1,1,233.7,234.1,1200,100,1,1,233.66,234.13,1,400,1,1,233.58,234.17,505,1,2,1,233.53,234.25,10,100,1,1,233.5,234.41,100,500,1,1,233.45,234.43,15,105,1,2,233.4,234.5,110,63,2,4,AAPL,-397,-7.416599946623966,0.09573607912486584
2024-10-21T12:21:26.876365981Z,2024-10-21T12:21:26.876199312Z,10,2,38,A,B,2,233.76,400,130,166669,12847641,233.86,234.0,750,50,1,1,233.8,234.04,5,400,1,1,233.76,234.06,400,26,1,1,233.7,234.1,1200,100,1,1,233.66,234.13,1,400,1,1,233.58,234.17,505,1,2,1,233.53,234.25,10,100,1,1,233.5,234.41,100,500,1,1,233.45,234.43,15,105,1,2,233.4,234.5,110,63,2,4,AAPL,-287,-5.274350223155684,0.06808316667075154
2024-10-21T12:21:28.271511190Z,2024-10-21T12:21:28.271344736Z,10,2,38,A,B,2,233.77,400,130,166454,12849143,233.86,234.0,750,50,1,1,233.8,234.04,5,400,1,1,233.77,234.06,400,26,1,1,233.7,234.1,1200,100,1,1,233.66,234.13,1,400,1,1,233.58,234.17,505,1,2,1,233.53,234.25,10,100,1,1,233.5,234.41,100,500,1,1,233.45,234.43,15,105,1,2,233.4,234.5,110,63,2,4,AAPL,-230,-3.2583923621804747,0.042060473970632055
2024-10-21T12:21:29.830338711Z,2024-10-21T12:21:29.830172186Z,10,2,38,A,B,4,233.69,29,130,166525,12850583,233.86,234.0,750,50,1,1,233.8,234.04,5,400,1,1,233.77,234.06,400,26,1,1,233.7,234.1,1200,100,1,1,233.69,234.13,29,400,1,1,233.66,234.17,1,1,1,1,233.58,234.25,505,100,2,1,233.53,234.41,10,500,1,1,233.5,234.43,100,105,1,2,233.45,234.5,15,63,1,4,AAPL,-152,-2.153372343701879,0.027796487145809012
2024-10-21T12:21:43.255727052Z,2024-10-21T12:21:43.255561253Z,10,2,38,C,A,1,234.04,400,130,165799,12858522,233.86,234.0,750,50,1,1,233.8,234.06,5,26,1,1,233.77,234.1,400,100,1,1,233.7,234.13,1200,400,1,1,233.69,234.17,29,1,1,1,233.66,234.25,1,100,1,1,233.58,234.41,505,500,2,1,233.53,234.43,10,105,1,2,233.5,234.5,100,63,1,4,233.45,234.75,15,1,1,1,AAPL,116,1.6148491879350348,-0.020845040954547832
2024-10-21T12:21:43.255741694Z,2024-10-21T12:21:43.255575289Z,10,2,38,A,A,1,234.06,400,130,166405,12858523,233.86,234.0,750,50,1,1,233.8,234.06,5,426,1,2,233.77,234.1,400,100,1,1,233.7,234.13,1200,400,1,1,233.69,234.17,29,1,1,1,233.66,234.25,1,100,1,1,233.58,234.41,505,500,2,1,233.53,234.43,10,105,1,2,233.5,234.5,100,63,1,4,233.45,234.75,15,1,1,1,AAPL,116,1.7333333333333334,-0.022374475951787647
2024-10-21T12:21:43.311094812Z,2024-10-21T12:21:43.310928524Z,10,2,38,A,A,1,234.05,200,130,166288,12858622,233.86,234.0,750,50,1,1,233.8,234.05,5,200,1,1,233.77,234.06,400,26,1,1,233.7,234.1,1200,100,1,1,233.69,234.13,29,400,1,1,233.66,234.17,1,1,1,1,233.58,234.25,505,100,2,1,233.53,234.41,10,500,1,1,233.5,234.43,100,105,1,2,233.45,234.5,15,63,1,4,AAPL,53,0.8162816281628162,-0.01053685018800865
2024-10-21T12:21:45.092291237Z,2024-10-21T12:21:45.092124924Z,10,2,38,A,B,2,233.78,400,130,166313,12859898,233.86,234.0,750,50,1,1,233.8,234.05,5,200,1,1,233.78,234.06,400,26,1,1,233.7,234.1,1200,100,1,1,233.69,234.13,29,400,1,1,233.66,234.17,1,1,1,1,233.58,234.25,505,100,2,1,233.53,234.41,10,500,1,1,233.5,234.43,100,105,1,2,233.45,234.5,15,63,1,4,AAPL,53,0.8386075949367088,-0.010825041614941076
2024-10-21T12:21:45.108399049Z,2024-10-21T12:21:45.108232814Z,10,2,38,C,B,4,233.69,29,130,166235,12859978,233.86,234.0,750,50,1,1,233.8,234.05,5,200,1,1,233.78,234.06,400,26,1,1,233.7,234.1,1200,100,1,1,233.66,234.13,1,400,1,1,233.58,234.17,505,1,2,1,233.53,234.25,10,100,1,1,233.5,234.41,100,500,1,1,233.45,234.43,15,105,1,2,233.4,234.5,110,63,2,4,AAPL,-57,-0.8815853069115515,0.011379813028235675
2024-10-21T12:21:45.108462494Z,2024-10-21T12:21:45.108296167Z,10,2,38,A,B,3,233.7,29,130,166327,12859979,233.86,234.0,750,50,1,1,233.8,234.05,5,200,1,1,233.78,234.06,400,26,1,1,233.7,234.1,1229,100,2,1,233.66,234.13,1,400,1,1,233.58,234.17,505,1,2,1,233.53,234.25,10,100,1,1,233.5,234.41,100,500,1,1,233.45,234.43,15,105,1,2,233.4,234.5,110,63,2,4,AAPL,-57,-0.864406779661017,0.011158066560050552
2024-10-21T12:21:48.360796158Z,2024-10-21T12:21:48.360630060Z,10,2,38,C,A,1,234.05,200,130,166098,12862379,233.86,234.0,750,50,1,1,233.8,234.06,5,26,1,1,233.78,234.1,400,100,1,1,233.7,234.13,1229,400,2,1,233.66,234.17,1,1,1,1,233.58,234.25,505,100,2,1,233.53,234.41,10,500,1,1,233.5,234.43,100,105,1,2,233.45,234.5,15,63,1,4,233.4,234.75,110,1,2,1,AAPL,-156,-3.4522821576763487,0.04456327160522021
2024-10-21T12:21:48.360808085Z,2024-10-21T12:21:48.360641832Z,10,2,38,A,A,2,234.07,200,130,166253,12862380,233.86,234.0,750,50,1,1,233.8,234.06,5,26,1,1,233.78,234.07,400,200,1,1,233.7,234.1,1229,100,2,1,233.66,234.13,1,400,1,1,233.58,234.17,505,1,2,1,233.53,234.25,10,100,1,1,233.5,234.41,100,500,1,1,233.45,234.43,15,105,1,2,233.4,234.5,110,63,2,4,AAPL,-219,-4.399553571428571,0.05679098398992116
2024-10-21T12:21:48.415690677Z,2024-10-21T12:21:48.415524174Z,10,2,38,A,B,2,233.79,400,130,166503,12862494,233.86,234.0,750,50,1,1,233.8,234.06,5,26,1,1,233.79,234.07,400,200,1,1,233.7,234.1,1229,100,2,1,233.66,234.13,1,400,1,1,233.58,234.17,505,1,2,1,233.53,234.25,10,100,1,1,233.5,234.41,100,500,1,1,233.45,234.43,15,105,1,2,233.4,234.5,110,63,2,4,AAPL,-219,-4.097287184284378,0.05288922321481068
2024-10-21T12:21:48.426415426Z,2024-10-21T12:21:48.426249325Z,10,2,38,C,B,3,233.7,29,130,166101,12862632,233.86,234.0,750,50,1,1,233.8,234.06,5,26,1,1,233.79,234.07,400,200,1,1,233.7,234.1,1200,100,1,1,233.66,234.13,1,400,1,1,233.58,234.17,505,1,2,1,233.53,234.25,10,100,1,1,233.5,234.41,100,500,1,1,233.45,234.43,15,105,1,2,233.4,234.5,110,63,2,4,AAPL,-219,-3.8792270531400965,0.05007442639154258
2024-10-21T12:21:48.426524915Z,2024-10-21T12:21:48.426358775Z,10,2,38,A,B,3,233.71,26,130,166140,12862634,233.86,234.0,750,50,1,1,233.8,234.06,5,26,1,1,233.79,234.07,400,200,1,1,233.71,234.1,26,100,1,1,233.7,234.13,1200,400,1,1,233.66,234.17,1,1,1,1,233.58,234.25,505,100,2,1,233.53,234.41,10,500,1,1,233.5,234.43,100,105,1,2,233.45,234.5,15,63,1,4,AAPL,-204,-3.709090909090909,0.04787824923948964
2024-10-21T12:21:48.440507069Z,2024-10-21T12:21:48.440341021Z,10,2,38,C,A,1,234.06,26,130,166048,12862704,233.86,234.0,750,50,1,1,233.8,234.07,5,200,1,1,233.79,234.1,400,100,1,1,233.71,234.13,26,400,1,1,233.7,234.17,1200,1,1,1,233.66,234.25,1,100,1,1,233.58,234.41,505,500,2,1,233.53,234.43,10,105,1,2,233.5,234.5,100,63,1,4,233.45,234.75,15,1,1,1,AAPL,-203,-3.950598802395209,0.05099571801885732
2024-10-21T12:21:48.582611366Z,2024-10-21T12:21:48.582445356Z,10,2,38,C,B,2,233.79,400,130,166010,12862943,233.86,234.0,750,50,1,1,233.8,234.07,5,200,1,1,233.71,234.1,26,100,1,1,233.7,234.13,1200,400,1,1,233.66,234.17,1,1,1,1,233.58,234.25,505,100,2,1,233.53,234.41,10,500,1,1,233.5,234.43,100,105,1,2,233.45,234.5,15,63,1,4,233.4,234.75,110,1,2,1,AAPL,-313,-6.0566689702833445,0.07818161205204412
2024-10-21T12:21:48.582623644Z,2024-10-21T12:21:48.582457462Z,10,2,38,A,B,2,233.76,200,130,166182,12862944,233.86,234.0,750,50,1,1,233.8,234.07,5,200,1,1,233.76,234.1,200,100,1,1,233.71,234.13,26,400,1,1,233.7,234.17,1200,1,1,1,233.66,234.25,1,100,1,1,233.58,234.41,505,500,2,1,233.53,234.43,10,105,1,2,233.5,234.5,100,63,1,4,233.45,234.75,15,1,1,1,AAPL,-298,-6.110731373889268,0.07887946856129983
2024-10-21T12:21:48.969029036Z,2024-10-21T12:21:48.968862759Z,10,2,38,A,A,1,234.07,200,130,166277,12863250,233.86,234.0,750,50,1,1,233.8,234.07,5,400,1,2,233.76,234.1,200,100,1,1,233.71,234.13,26,400,1,1,233.7,234.17,1200,1,1,1,233.66,234.25,1,100,1,1,233.58,234.41,505,500,2,1,233.53,234.43,10,105,1,2,233.5,234.5,100,63,1,4,233.45,234.75,15,1,1,1,AAPL,-298,-6.447599729546991,0.08322788370894327
2024-10-21T12:21:49.023322916Z,2024-10-21T12:21:49.023156980Z,10,2,38,C,A,1,234.07,200,130,165936,12863318,233.86,234.0,750,50,1,1,233.8,234.07,5,200,1,1,233.76,234.1,200,100,1,1,233.71,234.13,26,400,1,1,233.7,234.17,1200,1,1,1,233.66,234.25,1,100,1,1,233.58,234.41,505,500,2,1,233.53,234.43,10,105,1,2,233.5,234.5,100,63,1,4,233.45,234.75,15,1,1,1,AAPL,-298,-6.777257525083613,0.08748322241195489
2024-10-21T12:21:49.023336867Z,2024-10-21T12:21:49.023170310Z,10,2,38,A,A,1,234.03,200,130,166557,12863319,233.86,234.0,750,50,1,1,233.8,234.03,5,200,1,1,233.76,234.1,200,100,1,1,233.71,234.13,26,400,1,1,233.7,234.17,1200,1,1,1,233.66,234.25,1,100,1,1,233.58,234.41,505,500,2,1,233.53,234.43,10,105,1,2,233.5,234.5,100,63,1,4,233.45,234.75,15,1,1,1,AAPL,-298,-7.099933818663137,0.09164844143363203
2024-10-21T12:21:53.593514833Z,2024-10-21T12:21:53.593348279Z,10,2,38,A,B,2,233.76,200,130,166554,12866345,233.86,234.0,750,50,1,1,233.8,234.03,5,200,1,1,233.76,234.1,400,100,2,1,233.71,234.13,26,400,1,1,233.7,234.17,1200,1,1,1,233.66,234.25,1,100,1,1,233.58,234.41,505,500,2,1,233.53,234.43,10,105,1,2,233.5,234.5,100,63,1,4,233.45,234.75,15,1,1,1,AAPL,-313,-7.77639751552795,0.1003804726169546
2024-10-21T12:21:53.648061859Z,2024-10-21T12:21:53.647894830Z,10,2,38,C,B,2,233.76,200,130,167029,12866372,233.86,234.0,750,50,1,1,233.8,234.03,5,200,1,1,233.76,234.1,200,100,1,1,233.71,234.13,26,400,1,1,233.7,234.17,1200,1,1,1,233.66,234.25,1,100,1,1,233.58,234.41,505,500,2,1,233.53,234.43,10,105,1,2,233.5,234.5,100,63,1,4,233.45,234.75,15,1,1,1,AAPL,-313,-8.11877133105802,0.10479995417585805
2024-10-21T12:21:53.648074342Z,2024-10-21T12:21:53.647907823Z,10,2,38,A,B,2,233.79,400,130,166519,12866373,233.86,234.0,750,50,1,1,233.8,234.03,5,200,1,1,233.79,234.1,400,100,1,1,233.71,234.13,26,400,1,1,233.7,234.17,1200,1,1,1,233.66,234.25,1,100,1,1,233.58,234.41,505,500,2,1,233.53,234.43,10,105,1,2,233.5,234.5,100,63,1,4,233.45,234.75,15,1,1,1,AAPL,-313,-8.453747467927077,0.10912394389824234
2024-10-21T12:21:55.660797064Z,2024-10-21T12:21:55.660629861Z,10,2,38,T,N,0,233.92,46,130,167203,12867692,233.86,234.0,750,50,1,1,233.8,234.03,5,200,1,1,233.79,234.1,400,100,1,1,233.71,234.13,26,400,1,1,233.7,234.17,1200,1,1,1,233.66,234.25,1,100,1,1,233.58,234.41,505,500,2,1,233.53,234.43,10,105,1,2,233.5,234.5,100,63,1,4,233.45,234.75,15,1,1,1,AAPL,-313,-8.781563126252504,0.11335550364660103
2024-10-21T12:22:01.338070399Z,2024-10-21T12:22:01.337904135Z,10,2,38,A,A,1,234.02,200,130,166264,12872899,233.86,234.0,750,50,1,1,233.8,234.02,5,200,1,1,233.79,234.1,400,100,1,1,233.71,234.13,26,400,1,1,233.7,234.17,1200,1,1,1,233.66,234.25,1,100,1,1,233.58,234.41,505,500,2,1,233.53,234.43,10,105,1,2,233.5,234.5,100,63,1,4,233.45,234.75,15,1,1,1,AAPL,-313,-9.102445472571052,0.11749756576644192
2024-10-21T12:22:03.706527389Z,2024-10-21T12:22:03.706361217Z,10,2,38,C,B,0,233.86,750,130,166172,12876552,233.8,234.0,5,50,1,1,233.79,234.02,400,200,1,1,233.71,234.1,26,100,1,1,233.7,234.13,1200,400,1,1,233.66,234.17,1,1,1,1,233.58,234.25,505,100,2,1,233.53,234.41,10,500,1,1,233.5,234.43,100,105,1,2,233.45,234.5,15,63,1,4,233.4,234.75,110,1,2,1,AAPL,-361,-9.537648612945839,0.12311532088093699
2024-10-21T12:22:03.777683119Z,2024-10-21T12:22:03.777516702Z,10,2,38,C,B,1,233.79,400,130,166417,12876583,233.8,234.0,5,50,1,1,233.71,234.02,26,200,1,1,233.7,234.1,1200,100,1,1,233.66,234.13,1,400,1,1,233.58,234.17,505,1,2,1,233.53,234.25,10,100,1,1,233.5,234.41,100,500,1,1,233.45,234.43,15,105,1,2,233.4,234.5,110,63,2,4,233.39,234.75,10,1,1,1,AAPL,-371,-10.217704918032787,0.13189372671403093
2024-10-21T12:22:03.777696253Z,2024-10-21T12:22:03.777529729Z,10,2,38,A,B,1,233.72,200,130,166524,12876584,233.8,234.0,5,50,1,1,233.72,234.02,200,200,1,1,233.71,234.1,26,100,1,1,233.7,234.13,1200,400,1,1,233.66,234.17,1,1,1,1,233.58,234.25,505,100,2,1,233.53,234.41,10,500,1,1,233.5,234.43,100,105,1,2,233.45,234.5,15,63,1,4,233.4,234.75,110,1,2,1,AAPL,-261,-7.0195599022004895,0.09061094666764481
2024-10-21T12:22:03.782147350Z,2024-10-21T12:22:03.781981187Z,10,2,38,A,A,1,234.02,200,130,166163,12876586,233.8,234.0,5,50,1,1,233.72,234.02,200,400,1,2,233.71,234.1,26,100,1,1,233.7,234.13,1200,400,1,1,233.66,234.17,1,1,1,1,233.58,234.25,505,100,2,1,233.53,234.41,10,500,1,1,233.5,234.43,100,105,1,2,233.45,234.5,15,63,1,4,233.4,234.75,110,1,2,1,AAPL,-261,-6.872352604464797,0.08871074312354006
2024-10-21T12:22:09.127475230Z,2024-10-21T12:22:09.127308929Z,10,2,38,A,A,2,234.08,28,130,166301,12879884,233.8,234.0,5,50,1,1,233.72,234.02,200,400,1,2,233.71,234.08,26,28,1,1,233.7,234.1,1200,100,1,1,233.66,234.13,1,400,1,1,233.58,234.17,505,1,2,1,233.53,234.25,10,100,1,1,233.5,234.41,100,500,1,1,233.45,234.43,15,105,1,2,233.4,234.5,110,63,2,4,AAPL,-73,-2.4455611390284755,0.03156816282335713
2024-10-21T12:22:16.157521352Z,2024-10-21T12:22:16.157355560Z,10,2,38,C,B,2,233.71,26,130,165792,12885019,233.8,234.0,5,50,1,1,233.72,234.02,200,400,1,2,233.7,234.08,1200,28,1,1,233.66,234.1,1,100,1,1,233.58,234.13,505,400,2,1,233.53,234.17,10,1,1,1,233.5,234.25,100,100,1,1,233.45,234.41,15,500,1,1,233.4,234.43,110,105,2,2,233.39,234.5,10,63,1,4,AAPL,-83,-1.9174917491749175,0.024751657517114663
2024-10-21T12:22:16.158550111Z,2024-10-21T12:22:16.158383793Z,10,2,38,A,B,1,233.72,28,130,166318,12885021,233.8,234.0,5,50,1,1,233.72,234.02,228,400,2,2,233.7,234.08,1200,28,1,1,233.66,234.1,1,100,1,1,233.58,234.13,505,400,2,1,233.53,234.17,10,1,1,1,233.5,234.25,100,100,1,1,233.45,234.41,15,500,1,1,233.4,234.43,110,105,2,2,233.39,234.5,10,63,1,4,AAPL,-83,-1.9558173784977908,0.025246378212281064
2024-10-21T12:22:20.068588488Z,2024-10-21T12:22:20.068422134Z,10,2,38,A,B,1,233.73,200,130,166354,12888188,233.8,234.0,5,50,1,1,233.73,234.02,200,400,1,2,233.72,234.08,28,28,1,1,233.7,234.1,1200,100,1,1,233.66,234.13,1,400,1,1,233.58,234.17,505,1,2,1,233.53,234.25,10,100,1,1,233.5,234.41,100,500,1,1,233.45,234.43,15,105,1,2,233.4,234.5,110,63,2,4,AAPL,27,0.5704225352112676,-0.0073632145941012975
2024-10-21T12:22:20.078936626Z,2024-10-21T12:22:20.078770275Z,10,2,38,A,B,1,233.73,29,130,166351,12888325,233.8,234.0,5,50,1,1,233.73,234.02,229,400,2,2,233.72,234.08,28,28,1,1,233.7,234.1,1200,100,1,1,233.66,234.13,1,400,1,1,233.58,234.17,505,1,2,1,233.53,234.25,10,100,1,1,233.5,234.41,100,500,1,1,233.45,234.43,15,105,1,2,233.4,234.5,110,63,2,4,AAPL,27,0.526829268292683,-0.006800497381218759
2024-10-21T12:22:20.079017156Z,2024-10-21T12:22:20.078850920Z,10,2,38,C,B,2,233.72,28,130,166236,12888328,233.8,234.0,5,50,1,1,233.73,234.02,229,400,2,2,233.7,234.08,1200,28,1,1,233.66,234.1,1,100,1,1,233.58,234.13,505,400,2,1,233.53,234.17,10,1,1,1,233.5,234.25,100,100,1,1,233.45,234.41,15,500,1,1,233.4,234.43,110,105,2,2,233.39,234.5,10,63,1,4,AAPL,17,0.3406193078324226,-0.004396833756814092
2024-10-21T12:22:20.140405333Z,2024-10-21T12:22:20.140239259Z,10,2,38,C,A,2,234.08,28,130,166074,12888403,233.8,234.0,5,50,1,1,233.73,234.02,229,400,2,2,233.7,234.1,1200,100,1,1,233.66,234.13,1,400,1,1,233.58,234.17,505,1,2,1,233.53,234.25,10,100,1,1,233.5,234.41,100,500,1,1,233.45,234.43,15,105,1,2,233.4,234.5,110,63,2,4,233.39,234.75,10,1,1,1,AAPL,18,0.38954012623985573,-0.005028320877005755
2024-10-21T12:22:20.140457549Z,2024-10-21T12:22:20.140291372Z,10,2,38,A,A,2,234.04,30,130,166177,12888404,233.8,234.0,5,50,1,1,233.73,234.02,229,400,2,2,233.7,234.04,1200,30,1,1,233.66,234.1,1,100,1,1,233.58,234.13,505,400,2,1,233.53,234.17,10,1,1,1,233.5,234.25,100,100,1,1,233.45,234.41,15,500,1,1,233.4,234.43,110,105,2,2,233.39,234.5,10,63,1,4,AAPL,-45,-0.9898477157360407,0.012777302256731524
2024-10-21T12:22:20.142691051Z,2024-10-21T12:22:20.142525001Z,10,2,38,C,A,1,234.02,200,130,166050,12888407,233.8,234.0,5,50,1,1,233.73,234.02,229,200,2,1,233.7,234.04,1200,30,1,1,233.66,234.1,1,100,1,1,233.58,234.13,505,400,2,1,233.53,234.17,10,1,1,1,233.5,234.25,100,100,1,1,233.45,234.41,15,500,1,1,233.4,234.43,110,105,2,2,233.39,234.5,10,63,1,4,AAPL,-45,-1.00398406374502,0.012959779205908259
2024-10-21T12:22:20.142701567Z,2024-10-21T12:22:20.142535602Z,10,2,38,C,A,1,234.02,200,130,165965,12888408,233.8,234.0,5,50,1,1,233.73,234.04,229,30,2,1,233.7,234.1,1200,100,1,1,233.66,234.13,1,400,1,1,233.58,234.17,505,1,2,1,233.53,234.25,10,100,1,1,233.5,234.41,100,500,1,1,233.45,234.43,15,105,1,2,233.4,234.5,110,63,2,4,233.39,234.75,10,1,1,1,AAPL,-44,-1.0426540284360188,0.013458944703043969
2024-10-21T12:22:20.142712784Z,2024-10-21T12:22:20.142546696Z,10,2,38,A,A,1,234.03,200,130,166088,12888409,233.8,234.0,5,50,1,1,233.73,234.03,229,200,2,1,233.7,234.04,1200,30,1,1,233.66,234.1,1,100,1,1,233.58,234.13,505,400,2,1,233.53,234.17,10,1,1,1,233.5,234.25,100,100,1,1,233.45,234.41,15,500,1,1,233.4,234.43,110,105,2,2,233.39,234.5,10,63,1,4,AAPL,-107,-2.5571321882001494,0.03300836114447675
2024-10-21T12:22:20.146400458Z,2024-10-21T12:22:20.146234448Z,10,2,38,C,A,2,234.04,30,130,166010,12888412,233.8,234.0,5,50,1,1,233.73,234.03,229,200,2,1,233.7,234.1,1200,100,1,1,233.66,234.13,1,400,1,1,233.58,234.17,505,1,2,1,233.53,234.25,10,100,1,1,233.5,234.41,100,500,1,1,233.45,234.43,15,105,1,2,233.4,234.5,110,63,2,4,233.39,234.75,10,1,1,1,AAPL,-106,-2.66962962962963,0.03446051766249687
2024-10-21T12:22:20.260912200Z,2024-10-21T12:22:20.260745295Z,10,2,38,A,A,1,234.02,200,130,166905,12888534,233.8,234.0,5,50,1,1,233.73,234.02,229,200,2,1,233.7,234.1,1200,100,1,1,233.66,234.13,1,400,1,1,233.58,234.17,505,1,2,1,233.53,234.25,10,100,1,1,233.5,234.41,100,500,1,1,233.45,234.43,15,105,1,2,233.4,234.5,110,63,2,4,233.39,234.75,10,1,1,1,AAPL,-106,-2.80382072005878,0.036192703427353326
2024-10-21T12:22:20.322389944Z,2024-10-21T12:22:20.322223273Z,10,2,38,A,A,1,234.02,200,130,166671,12888684,233.8,234.0,5,50,1,1,233.73,234.02,229,400,2,2,233.7,234.1,1200,100,1,1,233.66,234.13,1,400,1,1,233.58,234.17,505,1,2,1,233.53,234.25,10,100,1,1,233.5,234.41,100,500,1,1,233.45,234.43,15,105,1,2,233.4,234.5,110,63,2,4,233.39,234.75,10,1,1,1,AAPL,-106,-2.9358600583090375,0.03789711361872083
2024-10-21T12:22:21.536173766Z,2024-10-21T12:22:21.536007375Z,10,2,38,A,A,2,234.04,26,130,166391,12890037,233.8,234.0,5,50,1,1,233.73,234.02,229,400,2,2,233.7,234.04,1200,26,1,1,233.66,234.1,1,100,1,1,233.58,234.13,505,400,2,1,233.53,234.17,10,1,1,1,233.5,234.25,100,100,1,1,233.45,234.41,15,500,1,1,233.4,234.43,110,105,2,2,233.39,234.5,10,63,1,4,AAPL,-169,-4.49405178446466,0.05801080014091898
2024-10-21T12:22:21.539463374Z,2024-10-21T12:22:21.539297131Z,10,2,38,C,A,2,234.04,26,130,166243,12890041,233.8,234.0,5,50,1,1,233.73,234.02,229,400,2,2,233.7,234.1,1200,100,1,1,233.66,234.13,1,400,1,1,233.58,234.17,505,1,2,1,233.53,234.25,10,100,1,1,233.5,234.41,100,500,1,1,233.45,234.43,15,105,1,2,233.4,234.5,110,63,2,4,233.39,234.75,10,1,1,1,AAPL,-168,-4.666666666666667,0.060238973716351354
2024-10-21T12:22:21.583448421Z,2024-10-21T12:22:21.583281944Z,10,2,38,A,B,1,233.74,200,130,166477,12890469,233.8,234.0,5,50,1,1,233.74,234.02,200,400,1,2,233.73,234.1,29,100,1,1,233.7,234.13,1200,400,1,1,233.66,234.17,1,1,1,1,233.58,234.25,505,100,2,1,233.53,234.41,10,500,1,1,233.5,234.43,100,105,1,2,233.45,234.5,15,63,1,4,233.4,234.75,110,1,2,1,AAPL,-58,-1.5705996131528046,0.020273851889062156
2024-10-21T12:22:22.095429909Z,2024-10-21T12:22:22.095263170Z,10,2,38,A,A,2,234.09,27,130,166739,12891303,233.8,234.0,5,50,1,1,233.74,234.02,200,400,1,2,233.73,234.09,29,27,1,1,233.7,234.1,1200,100,1,1,233.66,234.13,1,400,1,1,233.58,234.17,505,1,2,1,233.53,234.25,10,100,1,1,233.5,234.41,100,500,1,1,233.45,234.43,15,105,1,2,233.4,234.5,110,63,2,4,AAPL,-121,-3.0881670533642693,0.03986314584842409
2024-10-21T12:22:22.945563810Z,2024-10-21T12:22:22.945397458Z,10,2,38,C,A,1,234.02,200,130,166352,12893143,233.8,234.0,5,50,1,1,233.74,234.02,200,200,1,1,233.73,234.09,29,27,1,1,233.7,234.1,1200,100,1,1,233.66,234.13,1,400,1,1,233.58,234.17,505,1,2,1,233.53,234.25,10,100,1,1,233.5,234.41,100,500,1,1,233.45,234.43,15,105,1,2,233.4,234.5,110,63,2,4,AAPL,-121,-2.934106483921982,0.037874477864132644
2024-10-21T12:22:22.945572707Z,2024-10-21T12:22:22.945406901Z,10,2,38,C,A,1,234.02,200,130,165806,12893145,233.8,234.0,5,50,1,1,233.74,234.09,200,27,1,1,233.73,234.1,29,100,1,1,233.7,234.13,1200,400,1,1,233.66,234.17,1,1,1,1,233.58,234.25,505,100,2,1,233.53,234.41,10,500,1,1,233.5,234.43,100,105,1,2,233.45,234.5,15,63,1,4,233.4,234.75,110,1,2,1,AAPL,-120,-2.8685258964143423,0.037027940588309306
2024-10-21T12:22:22.945862943Z,2024-10-21T12:22:22.945697032Z,10,2,38,A,A,1,234.03,200,130,165911,12893175,233.8,234.0,5,50,1,1,233.74,234.03,200,200,1,1,233.73,234.09,29,27,1,1,233.7,234.1,1200,100,1,1,233.66,234.13,1,400,1,1,233.58,234.17,505,1,2,1,233.53,234.25,10,100,1,1,233.5,234.41,100,500,1,1,233.45,234.43,15,105,1,2,233.4,234.5,110,63,2,4,AAPL,-183,-4.195323246217332,0.054154707162960794
2024-10-21T12:22:22.986462573Z,2024-10-21T12:22:22.986296201Z,10,2,38,A,A,1,234.03,200,130,166372,12894197,233.8,234.0,5,50,1,1,233.74,234.03,200,400,1,2,233.73,234.09,29,27,1,1,233.7,234.1,1200,100,1,1,233.66,234.13,1,400,1,1,233.58,234.17,505,1,2,1,233.53,234.25,10,100,1,1,233.5,234.41,100,500,1,1,233.45,234.43,15,105,1,2,233.4,234.5,110,63,2,4,AAPL,-183,-4.042480883602379,0.05218176422060925
2024-10-21T12:22:23.024730389Z,2024-10-21T12:22:23.024563308Z,10,2,38,C,A,1,234.03,200,128,167081,12894812,233.8,234.0,5,50,1,1,233.74,234.03,200,200,1,1,233.73,234.09,29,27,1,1,233.7,234.1,1200,100,1,1,233.66,234.13,1,400,1,1,233.58,234.17,505,1,2,1,233.53,234.25,10,100,1,1,233.5,234.41,100,500,1,1,233.45,234.43,15,105,1,2,233.4,234.5,110,63,2,4,AAPL,-183,-3.9105658884052237,0.0504789590930791
2024-10-21T12:22:23.029069095Z,2024-10-21T12:22:23.028903196Z,10,2,38,C,A,1,234.03,200,130,165899,12894909,233.8,234.0,5,50,1,1,233.74,234.09,200,27,1,1,233.73,234.1,29,100,1,1,233.7,234.13,1200,400,1,1,233.66,234.17,1,1,1,1,233.58,234.25,505,100,2,1,233.53,234.41,10,500,1,1,233.5,234.43,100,105,1,2,233.45,234.5,15,63,1,4,233.4,234.75,110,1,2,1,AAPL,-182,-3.863532979529947,0.04987184177274881
2024-10-21T12:22:23.029082382Z,2024-10-21T12:22:23.028915916Z,10,2,38,A,A,1,234.08,200,130,166466,12894910,233.8,234.0,5,50,1,1,233.74,234.08,200,200,1,1,233.73,234.09,29,27,1,1,233.7,234.1,1200,100,1,1,233.66,234.13,1,400,1,1,233.58,234.17,505,1,2,1,233.53,234.25,10,100,1,1,233.5,234.41,100,500,1,1,233.45,234.43,15,105,1,2,233.4,234.5,110,63,2,4,AAPL,-245,-5.055140519388118,0.06525353075997505
2024-10-21T12:22:23.079970068Z,2024-10-21T12:22:23.079803882Z,10,2,38,A,B,0,233.88,3,130,166186,12895304,233.88,234.0,3,50,1,1,233.8,234.08,5,200,1,1,233.74,234.09,200,27,1,1,233.73,234.1,29,100,1,1,233.7,234.13,1200,400,1,1,233.66,234.17,1,1,1,1,233.58,234.25,505,100,2,1,233.53,234.41,10,500,1,1,233.5,234.43,100,105,1,2,233.45,234.5,15,63,1,4,AAPL,-230,-4.7767393561786085,0.06165983068429377
2024-10-21T12:22:23.080018858Z,2024-10-21T12:22:23.079851405Z,10,2,38,T,N,0,233.92,17,130,167453,12895307,233.88,234.0,3,50,1,1,233.8,234.08,5,200,1,1,233.74,234.09,200,27,1,1,233.73,234.1,29,100,1,1,233.7,234.13,1200,400,1,1,233.66,234.17,1,1,1,1,233.58,234.25,505,100,2,1,233.53,234.41,10,500,1,1,233.5,234.43,100,105,1,2,233.45,234.5,15,63,1,4,AAPL,-230,-4.806201550387597,0.06204013904341834
2024-10-21T12:22:23.080043588Z,2024-10-21T12:22:23.079869699Z,10,2,38,T,N,0,233.98,13,0,173889,12895310,233.88,234.0,3,50,1,1,233.8,234.08,5,200,1,1,233.74,234.09,200,27,1,1,233.73,234.1,29,100,1,1,233.7,234.13,1200,400,1,1,233.66,234.17,1,1,1,1,233.58,234.25,505,100,2,1,233.53,234.41,10,500,1,1,233.5,234.43,100,105,1,2,233.45,234.5,15,63,1,4,AAPL,-230,-4.834154351395731,0.06240096362453849
2024-10-21T12:22:23.080043588Z,2024-10-21T12:22:23.079869699Z,10,2,38,T,N,0,233.98,21,0,173889,12895311,233.88,234.0,3,50,1,1,233.8,234.08,5,200,1,1,233.74,234.09,200,27,1,1,233.73,234.1,29,100,1,1,233.7,234.13,1200,400,1,1,233.66,234.17,1,1,1,1,233.58,234.25,505,100,2,1,233.53,234.41,10,500,1,1,233.5,234.43,100,105,1,2,233.45,234.5,15,63,1,4,AAPL,-230,-4.860710854947166,0.06274376430727414
2024-10-21T12:22:23.080043588Z,2024-10-21T12:22:23.079869699Z,10,2,38,T,N,0,233.98,18,0,173889,12895312,233.88,234.0,3,50,1,1,233.8,234.08,5,200,1,1,233.74,234.09,200,27,1,1,233.73,234.1,29,100,1,1,233.7,234.13,1200,400,1,1,233.66,234.17,1,1,1,1,233.58,234.25,505,100,2,1,233.53,234.41,10,500,1,1,233.5,234.43,100,105,1,2,233.45,234.5,15,63,1,4,AAPL,-230,-4.885973133395814,0.06306985867744913
2024-10-21T12:22:23.080043588Z,2024-10-21T12:22:23.079869699Z,10,2,38,T,B,0,234.0,48,128,173889,12895313,233.88,234.0,3,50,1,1,233.8,234.08,5,200,1,1,233.74,234.09,200,27,1,1,233.73,234.1,29,100,1,1,233.7,234.13,1200,400,1,1,233.66,234.17,1,1,1,1,233.58,234.25,505,100,2,1,233.53,234.41,10,500,1,1,233.5,234.43,100,105,1,2,233.45,234.5,15,63,1,4,AAPL,-230,-4.910033546813053,0.06338043895133033
2024-10-21T12:22:23.080043588Z,2024-10-21T12:22:23.079869699Z,10,2,38,C,A,0,234.0,48,128,173889,12895313,233.88,234.0,3,2,1,1,233.8,234.08,5,200,1,1,233.74,234.09,200,27,1,1,233.73,234.1,29,100,1,1,233.7,234.13,1200,400,1,1,233.66,234.17,1,1,1,1,233.58,234.25,505,100,2,1,233.53,234.41,10,500,1,1,233.5,234.43,100,105,1,2,233.45,234.5,15,63,1,4,AAPL,-230,-4.932975871313673,0.06367658654045566
2024-10-21T12:22:23.080121046Z,2024-10-21T12:22:23.079955251Z,10,2,38,C,A,1,234.08,200,130,165795,12895319,233.88,234.0,3,2,1,1,233.8,234.09,5,27,1,1,233.74,234.1,200,100,1,1,233.73,234.13,29,400,1,1,233.7,234.17,1200,1,1,1,233.66,234.25,1,100,1,1,233.58,234.41,505,500,2,1,233.53,234.43,10,105,1,2,233.5,234.5,100,63,1,4,233.45,234.75,15,1,1,1,AAPL,-229,-5.024014230655203,0.0648517416837887
2024-10-21T12:22:23.084076713Z,2024-10-21T12:22:23.083910618Z,10,2,38,C,B,0,233.88,3,130,166095,12895336,233.8,234.0,5,2,1,1,233.74,234.09,200,27,1,1,233.73,234.1,29,100,1,1,233.7,234.13,1200,400,1,1,233.66,234.17,1,1,1,1,233.58,234.25,505,100,2,1,233.53,234.41,10,500,1,1,233.5,234.43,100,105,1,2,233.45,234.5,15,63,1,4,233.4,234.75,110,1,2,1,AAPL,-339,-7.394948335246842,0.095456592514438
2024-10-21T12:22:23.088319645Z,2024-10-21T12:22:23.088151194Z,10,2,38,A,B,0,233.91,100,128,168451,12895372,233.91,234.0,100,2,1,1,233.8,234.09,5,27,1,1,233.74,234.1,200,100,1,1,233.73,234.13,29,400,1,1,233.7,234.17,1200,1,1,1,233.66,234.25,1,100,1,1,233.58,234.41,505,500,2,1,233.53,234.43,10,105,1,2,233.5,234.5,100,63,1,4,233.45,234.75,15,1,1,1,AAPL,-324,-7.220571428571429,0.09320567410773252
2024-10-21T12:22:23.116317544Z,2024-10-21T12:22:23.116151189Z,10,2,38,A,A,1,234.08,200,130,166355,12895511,233.91,234.0,100,2,1,1,233.8,234.08,5,200,1,1,233.74,234.09,200,27,1,1,233.73,234.1,29,100,1,1,233.7,234.13,1200,400,1,1,233.66,234.17,1,1,1,1,233.58,234.25,505,100,2,1,233.53,234.41,10,500,1,1,233.5,234.43,100,105,1,2,233.45,234.5,15,63,1,4,AAPL,-387,-8.652878703186138,0.1116943998797156
2024-10-21T12:22:23.242021318Z,2024-10-21T12:22:23.241854315Z,10,2,38,A,A,1,234.07,200,130,167003,12895969,233.91,234.0,100,2,1,1,233.8,234.07,5,200,1,1,233.74,234.09,200,27,1,1,233.73,234.1,29,100,1,1,233.7,234.13,1200,400,1,1,233.66,234.17,1,1,1,1,233.58,234.25,505,100,2,1,233.53,234.41,10,500,1,1,233.5,234.43,100,105,1,2,233.45,234.5,15,63,1,4,AAPL,-387,-8.679978118161925,0.11204420865395594
2024-10-21T12:22:26.043193578Z,2024-10-21T12:22:26.043027067Z,10,2,38,A,A,1,234.07,200,130,166511,12901196,233.91,234.0,100,2,1,1,233.8,234.07,5,400,1,2,233.74,234.09,200,27,1,1,233.73,234.1,29,100,1,1,233.7,234.13,1200,400,1,1,233.66,234.17,1,1,1,1,233.58,234.25,505,100,2,1,233.53,234.41,10,500,1,1,233.5,234.43,100,105,1,2,233.45,234.5,15,63,1,4,AAPL,-377,-8.451917404129793,0.10910032079146009
2024-10-21T12:22:26.221605392Z,2024-10-21T12:22:26.221438925Z,10,2,38,A,B,2,233.78,200,130,166467,12901441,233.91,234.0,100,2,1,1,233.8,234.07,5,400,1,2,233.78,234.09,200,27,1,1,233.73,234.1,29,100,1,1,233.7,234.13,1200,400,1,1,233.66,234.17,1,1,1,1,233.58,234.25,505,100,2,1,233.53,234.41,10,500,1,1,233.5,234.43,100,105,1,2,233.45,234.5,15,63,1,4,AAPL,-377,-8.47923875432526,0.10945299438352867
2024-10-21T12:22:29.394326484Z,2024-10-21T12:22:29.394160247Z,10,2,38,A,B,2,233.79,200,130,166237,12905660,233.91,234.0,100,2,1,1,233.8,234.07,5,400,1,2,233.79,234.09,200,27,1,1,233.73,234.1,29,100,1,1,233.7,234.13,1200,400,1,1,233.66,234.17,1,1,1,1,233.58,234.25,505,100,2,1,233.53,234.41,10,500,1,1,233.5,234.43,100,105,1,2,233.45,234.5,15,63,1,4,AAPL,-314,-7.261191817373258,0.09373001636488568
2024-10-21T12:22:36.707629405Z,2024-10-21T12:22:36.707463498Z,10,2,38,C,A,2,234.09,27,130,165907,12912830,233.91,234.0,100,2,1,1,233.8,234.07,5,400,1,2,233.79,234.1,200,100,1,1,233.73,234.13,29,400,1,1,233.7,234.17,1200,1,1,1,233.66,234.25,1,100,1,1,233.58,234.41,505,500,2,1,233.53,234.43,10,105,1,2,233.5,234.5,100,63,1,4,233.45,234.75,15,1,1,1,AAPL,-303,-7.100832562442184,0.09166004273424996
2024-10-21T12:22:36.707672458Z,2024-10-21T12:22:36.707506060Z,10,2,38,A,A,2,234.08,26,130,166398,12912831,233.91,234.0,100,2,1,1,233.8,234.07,5,400,1,2,233.79,234.08,200,26,1,1,233.73,234.1,29,100,1,1,233.7,234.13,1200,400,1,1,233.66,234.17,1,1,1,1,233.58,234.25,505,100,2,1,233.53,234.41,10,500,1,1,233.5,234.43,100,105,1,2,233.45,234.5,15,63,1,4,AAPL,-366,-8.59620596205962,0.11096284821618263
2024-10-21T12:22:40.428593628Z,2024-10-21T12:22:40.428425309Z,10,2,38,T,N,0,233.92,100,0,168319,12916971,233.91,234.0,100,2,1,1,233.8,234.07,5,400,1,2,233.79,234.08,200,26,1,1,233.73,234.1,29,100,1,1,233.7,234.13,1200,400,1,1,233.66,234.17,1,1,1,1,233.58,234.25,505,100,2,1,233.53,234.41,10,500,1,1,233.5,234.43,100,105,1,2,233.45,234.5,15,63,1,4,AAPL,-343,-7.351810790835181,0.09489975792786616
2024-10-21T12:22:40.428593628Z,2024-10-21T12:22:40.428425309Z,10,2,38,T,N,0,233.92,40,130,168319,12916972,233.91,234.0,100,2,1,1,233.8,234.07,5,400,1,2,233.79,234.08,200,26,1,1,233.73,234.1,29,100,1,1,233.7,234.13,1200,400,1,1,233.66,234.17,1,1,1,1,233.58,234.25,505,100,2,1,233.53,234.41,10,500,1,1,233.5,234.43,100,105,1,2,233.45,234.5,15,63,1,4,AAPL,-343,-7.392241379310345,0.09542165017568587
2024-10-21T12:23:09.008779869Z,2024-10-21T12:23:09.008613373Z,10,2,38,A,B,0,233.93,4,130,166496,12947436,233.93,234.0,4,2,1,1,233.91,234.07,100,400,1,2,233.8,234.08,5,26,1,1,233.79,234.1,200,100,1,1,233.73,234.13,29,400,1,1,233.7,234.17,1200,1,1,1,233.66,234.25,1,100,1,1,233.58,234.41,505,500,2,1,233.53,234.43,10,105,1,2,233.5,234.5,100,63,1,4,AAPL,100,1.2269938650306749,-0.015838468111222966
2024-10-21T12:23:09.008787962Z,2024-10-21T12:23:09.008621599Z,10,2,38,A,B,1,233.92,100,130,166363,12947438,233.93,234.0,4,2,1,1,233.92,234.07,100,400,1,2,233.91,234.08,100,26,1,1,233.8,234.1,5,100,1,1,233.79,234.13,200,400,1,1,233.73,234.17,29,1,1,1,233.7,234.25,1200,100,1,1,233.66,234.41,1,500,1,1,233.58,234.43,505,105,2,2,233.53,234.5,10,63,1,4,AAPL,110,1.8644067796610169,-0.02406641807069727
2024-10-21T12:23:09.009139279Z,2024-10-21T12:23:09.008973422Z,10,2,38,C,B,1,233.92,100,130,165857,12947440,233.93,234.0,4,2,1,1,233.91,234.07,100,400,1,2,233.8,234.08,5,26,1,1,233.79,234.1,200,100,1,1,233.73,234.13,29,400,1,1,233.7,234.17,1200,1,1,1,233.66,234.25,1,100,1,1,233.58,234.41,505,500,2,1,233.53,234.43,10,105,1,2,233.5,234.5,100,63,1,4,AAPL,10,0.15037593984962405,-0.0019411054903228145
