ts_recv,ts_event,rtype,publisher_id,instrument_id,action,side,depth,price,size,flags,ts_in_delta,sequence,bid_px_00,ask_px_00,bid_sz_00,ask_sz_00,bid_ct_00,ask_ct_00,bid_px_01,ask_px_01,bid_sz_01,ask_sz_01,bid_ct_01,ask_ct_01,bid_px_02,ask_px_02,bid_sz_02,ask_sz_02,bid_ct_02,ask_ct_02,bid_px_03,ask_px_03,bid_sz_03,ask_sz_03,bid_ct_03,ask_ct_03,bid_px_04,ask_px_04,bid_sz_04,ask_sz_04,bid_ct_04,ask_ct_04,bid_px_05,ask_px_05,bid_sz_05,ask_sz_05,bid_ct_05,ask_ct_05,bid_px_06,ask_px_06,bid_sz_06,ask_sz_06,bid_ct_06,ask_ct_06,bid_px_07,ask_px_07,bid_sz_07,ask_sz_07,bid_ct_07,ask_ct_07,bid_px_08,ask_px_08,bid_sz_08,ask_sz_08,bid_ct_08,ask_ct_08,bid_px_09,ask_px_09,bid_sz_09,ask_sz_09,bid_ct_09,ask_ct_09,symbol,ofi_best_level,multi_level_ofi,integrated_ofi
2024-10-21T12:23:09.009232105Z,2024-10-21T12:23:09.009065871Z,10,2,38,A,B,0,233.95,723,130,166234,12947441,233.95,234.0,723,2,1,1,233.93,234.07,4,400,1,2,233.91,234.08,100,26,1,1,233.8,234.1,5,100,1,1,233.79,234.13,200,400,1,1,233.73,234.17,29,1,1,1,233.7,234.25,1200,100,1,1,233.66,234.41,1,500,1,1,233.58,234.43,505,105,2,2,233.53,234.5,10,63,1,4,AAPL,20,0.3389830508474576,-0.004375712376490412
2024-10-21T12:23:09.047215822Z,2024-10-21T12:23:09.047049975Z,10,2,38,C,B,1,233.93,4,130,165847,12947464,233.95,234.0,723,2,1,1,233.91,234.07,100,400,1,2,233.8,234.08,5,26,1,1,233.79,234.1,200,100,1,1,233.73,234.13,29,400,1,1,233.7,234.17,1200,1,1,1,233.66,234.25,1,100,1,1,233.58,234.41,505,500,2,1,233.53,234.43,10,105,1,2,233.5,234.5,100,63,1,4,AAPL,-80,-1.2598425196850394,0.016262490092153345
2024-10-21T12:23:09.047694600Z,2024-10-21T12:23:09.047528450Z,10,2,38,C,B,1,233.91,100,130,166150,12947466,233.95,234.0,723,2,1,1,233.8,234.07,5,400,1,2,233.79,234.08,200,26,1,1,233.73,234.1,29,100,1,1,233.7,234.13,1200,400,1,1,233.66,234.17,1,1,1,1,233.58,234.25,505,100,2,1,233.53,234.41,10,500,1,1,233.5,234.43,100,105,1,2,233.45,234.5,15,63,1,4,AAPL,-95,-1.5988779803646564,0.020638878993179885
2024-10-21T12:23:09.079945758Z,2024-10-21T12:23:09.079779485Z,10,2,38,C,A,1,234.07,200,130,166273,12947479,233.95,234.0,723,2,1,1,233.8,234.07,5,200,1,1,233.79,234.08,200,26,1,1,233.73,234.1,29,100,1,1,233.7,234.13,1200,400,1,1,233.66,234.17,1,1,1,1,233.58,234.25,505,100,2,1,233.53,234.41,10,500,1,1,233.5,234.43,100,105,1,2,233.45,234.5,15,63,1,4,AAPL,-95,-1.6814159292035398,0.021704307849759966
2024-10-21T12:23:09.081865026Z,2024-10-21T12:23:09.081699019Z,10,2,38,A,B,2,233.79,200,130,166007,12947480,233.95,234.0,723,2,1,1,233.8,234.07,5,200,1,1,233.79,234.08,400,26,2,1,233.73,234.1,29,100,1,1,233.7,234.13,1200,400,1,1,233.66,234.17,1,1,1,1,233.58,234.25,505,100,2,1,233.53,234.41,10,500,1,1,233.5,234.43,100,105,1,2,233.45,234.5,15,63,1,4,AAPL,-95,-1.7491369390103568,0.022578474449002316
2024-10-21T12:23:09.087941406Z,2024-10-21T12:23:09.087775155Z,10,2,38,C,B,2,233.79,200,130,166251,12947484,233.95,234.0,723,2,1,1,233.8,234.07,5,200,1,1,233.79,234.08,200,26,1,1,233.73,234.1,29,100,1,1,233.7,234.13,1200,400,1,1,233.66,234.17,1,1,1,1,233.58,234.25,505,100,2,1,233.53,234.41,10,500,1,1,233.5,234.43,100,105,1,2,233.45,234.5,15,63,1,4,AAPL,-95,-1.805702217529039,0.0233086389474191
2024-10-21T12:23:09.087951571Z,2024-10-21T12:23:09.087785825Z,10,2,38,C,B,2,233.79,200,130,165746,12947485,233.95,234.0,723,2,1,1,233.8,234.07,5,200,1,1,233.73,234.08,29,26,1,1,233.7,234.1,1200,100,1,1,233.66,234.13,1,400,1,1,233.58,234.17,505,1,2,1,233.53,234.25,10,100,1,1,233.5,234.41,100,500,1,1,233.45,234.43,15,105,1,2,233.4,234.5,110,63,2,4,AAPL,-205,-3.6607142857142856,0.04725378678004601
2024-10-21T12:23:09.087963244Z,2024-10-21T12:23:09.087797026Z,10,2,38,A,B,2,233.78,200,130,166218,12947486,233.95,234.0,723,2,1,1,233.8,234.07,5,200,1,1,233.78,234.08,200,26,1,1,233.73,234.1,29,100,1,1,233.7,234.13,1200,400,1,1,233.66,234.17,1,1,1,1,233.58,234.25,505,100,2,1,233.53,234.41,10,500,1,1,233.5,234.43,100,105,1,2,233.45,234.5,15,63,1,4,AAPL,-190,-3.4891485809682807,0.04503915635601276
2024-10-21T12:23:09.133495750Z,2024-10-21T12:23:09.133329159Z,10,2,38,A,B,2,233.79,200,130,166591,12947507,233.95,234.0,723,2,1,1,233.8,234.07,5,200,1,1,233.79,234.08,200,26,1,1,233.73,234.1,29,100,1,1,233.7,234.13,1200,400,1,1,233.66,234.17,1,1,1,1,233.58,234.25,505,100,2,1,233.53,234.41,10,500,1,1,233.5,234.43,100,105,1,2,233.45,234.5,15,63,1,4,AAPL,-190,-3.573667711598746,0.04613015900356507
2024-10-21T12:23:09.155801329Z,2024-10-21T12:23:09.155634175Z,10,2,38,C,B,3,233.73,29,130,167154,12947520,233.95,234.0,723,2,1,1,233.8,234.07,5,200,1,1,233.79,234.08,200,26,1,1,233.7,234.1,1200,100,1,1,233.66,234.13,1,400,1,1,233.58,234.17,505,1,2,1,233.53,234.25,10,100,1,1,233.5,234.41,100,500,1,1,233.45,234.43,15,105,1,2,233.4,234.5,110,63,2,4,AAPL,-300,-5.383022774327122,0.06948595016083119
2024-10-21T12:23:09.155898909Z,2024-10-21T12:23:09.155732424Z,10,2,38,A,B,3,233.77,26,130,166485,12947521,233.95,234.0,723,2,1,1,233.8,234.07,5,200,1,1,233.79,234.08,200,26,1,1,233.77,234.1,26,100,1,1,233.7,234.13,1200,400,1,1,233.66,234.17,1,1,1,1,233.58,234.25,505,100,2,1,233.53,234.41,10,500,1,1,233.5,234.43,100,105,1,2,233.45,234.5,15,63,1,4,AAPL,-285,-5.225933202357564,0.0674581827471911
2024-10-21T12:23:09.242988929Z,2024-10-21T12:23:09.242822823Z,10,2,38,C,A,2,234.08,26,130,166106,12947586,233.95,234.0,723,2,1,1,233.8,234.07,5,200,1,1,233.79,234.1,200,100,1,1,233.77,234.13,26,400,1,1,233.7,234.17,1200,1,1,1,233.66,234.25,1,100,1,1,233.58,234.41,505,500,2,1,233.53,234.43,10,105,1,2,233.5,234.5,100,63,1,4,233.45,234.75,15,1,1,1,AAPL,-284,-5.521710952689566,0.07127618591750488
2024-10-21T12:23:09.243042523Z,2024-10-21T12:23:09.242876186Z,10,2,38,A,A,4,234.14,29,130,166337,12947587,233.95,234.0,723,2,1,1,233.8,234.07,5,200,1,1,233.79,234.1,200,100,1,1,233.77,234.13,26,400,1,1,233.7,234.14,1200,29,1,1,233.66,234.17,1,1,1,1,233.58,234.25,505,100,2,1,233.53,234.41,10,500,1,1,233.5,234.43,100,105,1,2,233.45,234.5,15,63,1,4,AAPL,-347,-6.850092535471931,0.0884234023283289
2024-10-21T12:23:09.312801998Z,2024-10-21T12:23:09.312635376Z,10,2,38,A,B,1,233.81,200,130,166622,12947706,233.95,234.0,723,2,1,1,233.81,234.07,200,200,1,1,233.8,234.1,5,100,1,1,233.77,234.13,26,400,1,1,233.7,234.14,1200,29,1,1,233.66,234.17,1,1,1,1,233.58,234.25,505,100,2,1,233.53,234.41,10,500,1,1,233.5,234.43,100,105,1,2,233.45,234.5,15,63,1,4,AAPL,-347,-6.94408475573867,0.0896366869467981
2024-10-21T12:23:09.319634626Z,2024-10-21T12:23:09.319468618Z,10,2,38,A,A,1,234.07,200,130,166008,12947710,233.95,234.0,723,2,1,1,233.81,234.07,200,400,1,2,233.8,234.1,5,100,1,1,233.77,234.13,26,400,1,1,233.7,234.14,1200,29,1,1,233.66,234.17,1,1,1,1,233.58,234.25,505,100,2,1,233.53,234.41,10,500,1,1,233.5,234.43,100,105,1,2,233.45,234.5,15,63,1,4,AAPL,-347,-7.029825548677546,0.0907434592408547
2024-10-21T12:23:09.729631282Z,2024-10-21T12:23:09.729465211Z,10,2,38,C,A,1,234.07,200,130,166071,12947991,233.95,234.0,723,2,1,1,233.81,234.07,200,200,1,1,233.8,234.1,5,100,1,1,233.77,234.13,26,400,1,1,233.7,234.14,1200,29,1,1,233.66,234.17,1,1,1,1,233.58,234.25,505,100,2,1,233.53,234.41,10,500,1,1,233.5,234.43,100,105,1,2,233.45,234.5,15,63,1,4,AAPL,-347,-7.108355795148248,0.09175715526651625
2024-10-21T12:23:09.784241575Z,2024-10-21T12:23:09.784075201Z,10,2,38,A,B,1,233.82,200,130,166374,12948038,233.95,234.0,723,2,1,1,233.82,234.07,200,200,1,1,233.8,234.1,5,100,1,1,233.77,234.13,26,400,1,1,233.7,234.14,1200,29,1,1,233.66,234.17,1,1,1,1,233.58,234.25,505,100,2,1,233.53,234.41,10,500,1,1,233.5,234.43,100,105,1,2,233.45,234.5,15,63,1,4,AAPL,-347,-7.18054837040869,0.09268904240443686
2024-10-21T12:23:11.099239175Z,2024-10-21T12:23:11.099071185Z,10,2,38,T,A,0,233.95,200,130,167990,12949099,233.95,234.0,723,2,1,1,233.82,234.07,200,200,1,1,233.8,234.1,5,100,1,1,233.77,234.13,26,400,1,1,233.7,234.14,1200,29,1,1,233.66,234.17,1,1,1,1,233.58,234.25,505,100,2,1,233.53,234.41,10,500,1,1,233.5,234.43,100,105,1,2,233.45,234.5,15,63,1,4,AAPL,-347,-7.247140726006962,0.09354863993842132
2024-10-21T12:23:11.099239175Z,2024-10-21T12:23:11.099071185Z,10,2,38,C,B,0,233.95,200,130,167990,12949099,233.95,234.0,523,2,1,1,233.82,234.07,200,200,1,1,233.8,234.1,5,100,1,1,233.77,234.13,26,400,1,1,233.7,234.14,1200,29,1,1,233.66,234.17,1,1,1,1,233.58,234.25,505,100,2,1,233.53,234.41,10,500,1,1,233.5,234.43,100,105,1,2,233.45,234.5,15,63,1,4,AAPL,-347,-7.308760172331259,0.09434404541146678
2024-10-21T12:23:11.099304941Z,2024-10-21T12:23:11.099138993Z,10,2,38,C,B,1,233.82,200,130,165948,12949100,233.95,234.0,523,2,1,1,233.8,234.07,5,200,1,1,233.77,234.1,26,100,1,1,233.7,234.13,1200,400,1,1,233.66,234.14,1,29,1,1,233.58,234.17,505,1,2,1,233.53,234.25,10,100,1,1,233.5,234.41,100,500,1,1,233.45,234.43,15,105,1,2,233.4,234.5,110,63,2,4,AAPL,-457,-9.293545534924846,0.11996435254501119
2024-10-21T12:23:11.172041039Z,2024-10-21T12:23:11.171874633Z,10,2,38,A,A,1,234.07,200,130,166406,12949158,233.95,234.0,523,2,1,1,233.8,234.07,5,400,1,2,233.77,234.1,26,100,1,1,233.7,234.13,1200,400,1,1,233.66,234.14,1,29,1,1,233.58,234.17,505,1,2,1,233.53,234.25,10,100,1,1,233.5,234.41,100,500,1,1,233.45,234.43,15,105,1,2,233.4,234.5,110,63,2,4,AAPL,-457,-9.008624229979466,0.11628648818790407
2024-10-21T12:23:11.208329414Z,2024-10-21T12:23:11.208162821Z,10,2,38,A,B,1,233.82,200,130,166593,12949167,233.95,234.0,523,2,1,1,233.82,234.07,200,400,1,2,233.8,234.1,5,100,1,1,233.77,234.13,26,400,1,1,233.7,234.14,1200,29,1,1,233.66,234.17,1,1,1,1,233.58,234.25,505,100,2,1,233.53,234.41,10,500,1,1,233.5,234.43,100,105,1,2,233.45,234.5,15,63,1,4,AAPL,-442,-8.794269797055312,0.11351952581985375
2024-10-21T12:23:12.139769418Z,2024-10-21T12:23:12.139603042Z,10,2,38,A,B,1,233.84,200,130,166376,12950444,233.95,234.0,523,2,1,1,233.84,234.07,200,400,1,2,233.8,234.1,5,100,1,1,233.77,234.13,26,400,1,1,233.7,234.14,1200,29,1,1,233.66,234.17,1,1,1,1,233.58,234.25,505,100,2,1,233.53,234.41,10,500,1,1,233.5,234.43,100,105,1,2,233.45,234.5,15,63,1,4,AAPL,-442,-8.870706291007332,0.11450619495202784
2024-10-21T12:23:12.190290255Z,2024-10-21T12:23:12.190123660Z,10,2,38,C,A,4,234.14,29,130,166595,12950624,233.95,234.0,523,2,1,1,233.84,234.07,200,400,1,2,233.8,234.1,5,100,1,1,233.77,234.13,26,400,1,1,233.7,234.17,1200,1,1,1,233.66,234.25,1,100,1,1,233.58,234.41,505,500,2,1,233.53,234.43,10,105,1,2,233.5,234.5,100,63,1,4,233.45,234.75,15,1,1,1,AAPL,-441,-9.13463751438435,0.1179131119580134
2024-10-21T12:23:12.190410859Z,2024-10-21T12:23:12.190244811Z,10,2,38,A,A,2,234.09,28,130,166048,12950625,233.95,234.0,523,2,1,1,233.84,234.07,200,400,1,2,233.8,234.09,5,28,1,1,233.77,234.1,26,100,1,1,233.7,234.13,1200,400,1,1,233.66,234.17,1,1,1,1,233.58,234.25,505,100,2,1,233.53,234.41,10,500,1,1,233.5,234.43,100,105,1,2,233.45,234.5,15,63,1,4,AAPL,-504,-10.511731843575419,0.13568912962252996
2024-10-21T12:23:12.195419708Z,2024-10-21T12:23:12.195254017Z,10,2,38,C,A,2,234.09,28,130,165691,12950641,233.95,234.0,523,2,1,1,233.84,234.07,200,400,1,2,233.8,234.1,5,100,1,1,233.77,234.13,26,400,1,1,233.7,234.17,1200,1,1,1,233.66,234.25,1,100,1,1,233.58,234.41,505,500,2,1,233.53,234.43,10,105,1,2,233.5,234.5,100,63,1,4,233.45,234.75,15,1,1,1,AAPL,-503,-10.801184746390225,0.13942548943784053
2024-10-21T12:23:13.923669862Z,2024-10-21T12:23:13.923503589Z,10,2,38,A,A,4,234.14,27,130,166273,12952557,233.95,234.0,523,2,1,1,233.84,234.07,200,400,1,2,233.8,234.1,5,100,1,1,233.77,234.13,26,400,1,1,233.7,234.14,1200,27,1,1,233.66,234.17,1,1,1,1,233.58,234.25,505,100,2,1,233.53,234.41,10,500,1,1,233.5,234.43,100,105,1,2,233.45,234.5,15,63,1,4,AAPL,-566,-12.220223101835192,0.15774293533701422
2024-10-21T12:23:14.014291143Z,2024-10-21T12:23:14.014125157Z,10,2,38,C,B,1,233.84,200,130,165986,12953020,233.95,234.0,523,2,1,1,233.8,234.07,5,400,1,2,233.77,234.1,26,100,1,1,233.7,234.13,1200,400,1,1,233.66,234.14,1,27,1,1,233.58,234.17,505,1,2,1,233.53,234.25,10,100,1,1,233.5,234.41,100,500,1,1,233.45,234.43,15,105,1,2,233.4,234.5,110,63,2,4,AAPL,-676,-14.197831978319783,0.18327060586525246
2024-10-21T12:23:14.014304377Z,2024-10-21T12:23:14.014138266Z,10,2,38,A,B,1,233.8,400,130,166111,12953021,233.95,234.0,523,2,1,1,233.8,234.07,405,400,2,2,233.77,234.1,26,100,1,1,233.7,234.13,1200,400,1,1,233.66,234.14,1,27,1,1,233.58,234.17,505,1,2,1,233.53,234.25,10,100,1,1,233.5,234.41,100,500,1,1,233.45,234.43,15,105,1,2,233.4,234.5,110,63,2,4,AAPL,-676,-13.84448,0.1787094143221183
2024-10-21T12:23:24.180223668Z,2024-10-21T12:23:24.180057341Z,10,2,38,A,B,1,233.84,200,130,166327,12963680,233.95,234.0,523,2,1,1,233.84,234.07,200,400,1,2,233.8,234.1,5,100,1,1,233.77,234.13,26,400,1,1,233.7,234.14,1200,27,1,1,233.66,234.17,1,1,1,1,233.58,234.25,505,100,2,1,233.53,234.41,10,500,1,1,233.5,234.43,100,105,1,2,233.45,234.5,15,63,1,4,AAPL,-661,-13.620355916328442,0.1758163418680842
2024-10-21T12:23:24.244554625Z,2024-10-21T12:23:24.244388472Z,10,2,38,C,B,3,233.77,26,130,166153,12963842,233.95,234.0,523,2,1,1,233.84,234.07,200,400,1,2,233.8,234.1,5,100,1,1,233.7,234.13,1200,400,1,1,233.66,234.14,1,27,1,1,233.58,234.17,505,1,2,1,233.53,234.25,10,100,1,1,233.5,234.41,100,500,1,1,233.45,234.43,15,105,1,2,233.4,234.5,110,63,2,4,AAPL,-771,-15.529620853080567,0.20046180479863332
2024-10-21T12:23:24.244894113Z,2024-10-21T12:23:24.244727755Z,10,2,38,A,B,3,233.78,29,130,166358,12963846,233.95,234.0,523,2,1,1,233.84,234.07,200,400,1,2,233.8,234.1,5,100,1,1,233.78,234.13,29,400,1,1,233.7,234.14,1200,27,1,1,233.66,234.17,1,1,1,1,233.58,234.25,505,100,2,1,233.53,234.41,10,500,1,1,233.5,234.43,100,105,1,2,233.45,234.5,15,63,1,4,AAPL,-756,-15.321366531557615,0.1977735848128038
2024-10-21T12:23:24.253991498Z,2024-10-21T12:23:24.253824768Z,10,2,38,A,B,1,233.85,200,130,166730,12963873,233.95,234.0,523,2,1,1,233.85,234.07,200,400,1,2,233.8,234.1,5,100,1,1,233.78,234.13,29,400,1,1,233.7,234.14,1200,27,1,1,233.66,234.17,1,1,1,1,233.58,234.25,505,100,2,1,233.53,234.41,10,500,1,1,233.5,234.43,100,105,1,2,233.45,234.5,15,63,1,4,AAPL,-756,-15.411098527746319,0.19893187696135958
2024-10-21T12:23:24.273314409Z,2024-10-21T12:23:24.273148439Z,10,2,38,C,A,4,234.14,27,130,165970,12963906,233.95,234.0,523,2,1,1,233.85,234.07,200,400,1,2,233.8,234.1,5,100,1,1,233.78,234.13,29,400,1,1,233.7,234.17,1200,1,1,1,233.66,234.25,1,100,1,1,233.58,234.41,505,500,2,1,233.53,234.43,10,105,1,2,233.5,234.5,100,63,1,4,233.45,234.75,15,1,1,1,AAPL,-755,-15.746899661781287,0.20326651603715673
2024-10-21T12:23:24.273365393Z,2024-10-21T12:23:24.273199301Z,10,2,38,A,A,2,234.09,30,130,166092,12963907,233.95,234.0,523,2,1,1,233.85,234.07,200,400,1,2,233.8,234.09,5,30,1,1,233.78,234.1,29,100,1,1,233.7,234.13,1200,400,1,1,233.66,234.17,1,1,1,1,233.58,234.25,505,100,2,1,233.53,234.41,10,500,1,1,233.5,234.43,100,105,1,2,233.45,234.5,15,63,1,4,AAPL,-818,-17.145063430777718,0.22131450543681333
2024-10-21T12:23:24.281190133Z,2024-10-21T12:23:24.281024032Z,10,2,38,C,A,2,234.09,30,130,166101,12963913,233.95,234.0,523,2,1,1,233.85,234.07,200,400,1,2,233.8,234.1,5,100,1,1,233.78,234.13,29,400,1,1,233.7,234.17,1200,1,1,1,233.66,234.25,1,100,1,1,233.58,234.41,505,500,2,1,233.53,234.43,10,105,1,2,233.5,234.5,100,63,1,4,233.45,234.75,15,1,1,1,AAPL,-817,-17.497528830313016,0.2258642527093555
2024-10-21T12:23:25.923153392Z,2024-10-21T12:23:25.922987113Z,10,2,38,A,A,4,234.15,29,130,166279,12965330,233.95,234.0,523,2,1,1,233.85,234.07,200,400,1,2,233.8,234.1,5,100,1,1,233.78,234.13,29,400,1,1,233.7,234.15,1200,29,1,1,233.66,234.17,1,1,1,1,233.58,234.25,505,100,2,1,233.53,234.41,10,500,1,1,233.5,234.43,100,105,1,2,233.45,234.5,15,63,1,4,AAPL,-880,-18.9247311827957,0.24428708235202393
2024-10-21T12:23:26.667650199Z,2024-10-21T12:23:26.667483730Z,10,2,38,C,A,4,234.15,29,130,166469,12965993,233.95,234.0,523,2,1,1,233.85,234.07,200,400,1,2,233.8,234.1,5,100,1,1,233.78,234.13,29,400,1,1,233.7,234.17,1200,1,1,1,233.66,234.25,1,100,1,1,233.58,234.41,505,500,2,1,233.53,234.43,10,105,1,2,233.5,234.5,100,63,1,4,233.45,234.75,15,1,1,1,AAPL,-879,-19.292826552462525,0.24903858677312474
2024-10-21T12:23:26.667733223Z,2024-10-21T12:23:26.667566801Z,10,2,38,A,A,2,234.09,26,130,166422,12965994,233.95,234.0,523,2,1,1,233.85,234.07,200,400,1,2,233.8,234.09,5,26,1,1,233.78,234.1,29,100,1,1,233.7,234.13,1200,400,1,1,233.66,234.17,1,1,1,1,233.58,234.25,505,100,2,1,233.53,234.41,10,500,1,1,233.5,234.43,100,105,1,2,233.45,234.5,15,63,1,4,AAPL,-942,-20.74672260094389,0.26780598802686245
2024-10-21T12:23:26.671836031Z,2024-10-21T12:23:26.671669972Z,10,2,38,C,A,2,234.09,26,130,166059,12965998,233.95,234.0,523,2,1,1,233.85,234.07,200,400,1,2,233.8,234.1,5,100,1,1,233.78,234.13,29,400,1,1,233.7,234.17,1200,1,1,1,233.66,234.25,1,100,1,1,233.58,234.41,505,500,2,1,233.53,234.43,10,105,1,2,233.5,234.5,100,63,1,4,233.45,234.75,15,1,1,1,AAPL,-941,-21.129503916449085,0.2727470637991113
2024-10-21T12:23:29.923208530Z,2024-10-21T12:23:29.923042073Z,10,2,38,A,A,4,234.15,26,130,166457,12968315,233.95,234.0,523,2,1,1,233.85,234.07,200,400,1,2,233.8,234.1,5,100,1,1,233.78,234.13,29,400,1,1,233.7,234.15,1200,26,1,1,233.66,234.17,1,1,1,1,233.58,234.25,505,100,2,1,233.53,234.41,10,500,1,1,233.5,234.43,100,105,1,2,233.45,234.5,15,63,1,4,AAPL,-657,-15.96759493670886,0.2061153282226607
2024-10-21T12:23:31.049437219Z,2024-10-21T12:23:31.049271170Z,10,2,38,C,B,1,233.85,200,130,166049,12969394,233.95,234.0,523,2,1,1,233.8,234.07,5,400,1,2,233.78,234.1,29,100,1,1,233.7,234.13,1200,400,1,1,233.66,234.15,1,26,1,1,233.58,234.17,505,1,2,1,233.53,234.25,10,100,1,1,233.5,234.41,100,500,1,1,233.45,234.43,15,105,1,2,233.4,234.5,110,63,2,4,AAPL,-767,-17.853817504655492,0.23046335215703054
2024-10-21T12:23:31.049449290Z,2024-10-21T12:23:31.049283153Z,10,2,38,A,B,1,233.83,200,130,166137,12969395,233.95,234.0,523,2,1,1,233.83,234.07,200,400,1,2,233.8,234.1,5,100,1,1,233.78,234.13,29,400,1,1,233.7,234.15,1200,26,1,1,233.66,234.17,1,1,1,1,233.58,234.25,505,100,2,1,233.53,234.41,10,500,1,1,233.5,234.43,100,105,1,2,233.45,234.5,15,63,1,4,AAPL,-752,-17.566936208445643,0.22676018754372385
2024-10-21T12:23:31.105367441Z,2024-10-21T12:23:31.105200821Z,10,2,38,A,B,1,233.84,200,130,166620,12969432,233.95,234.0,523,2,1,1,233.84,234.07,200,400,1,2,233.8,234.1,5,100,1,1,233.78,234.13,29,400,1,1,233.7,234.15,1200,26,1,1,233.66,234.17,1,1,1,1,233.58,234.25,505,100,2,1,233.53,234.41,10,500,1,1,233.5,234.43,100,105,1,2,233.45,234.5,15,63,1,4,AAPL,-642,-15.603037974683543,0.20140949881118442
2024-10-21T12:23:33.817991958Z,2024-10-21T12:23:33.817825903Z,10,2,38,C,B,1,233.84,200,130,166055,12972883,233.95,234.0,523,2,1,1,233.8,234.07,5,400,1,2,233.78,234.1,29,100,1,1,233.7,234.13,1200,400,1,1,233.66,234.15,1,26,1,1,233.58,234.17,505,1,2,1,233.53,234.25,10,100,1,1,233.5,234.41,100,500,1,1,233.45,234.43,15,105,1,2,233.4,234.5,110,63,2,4,AAPL,-706,-15.698069046225863,0.20263619328708612
2024-10-21T12:23:33.818003417Z,2024-10-21T12:23:33.817837243Z,10,2,38,A,B,1,233.8,400,130,166174,12972884,233.95,234.0,523,2,1,1,233.8,234.07,405,400,2,2,233.78,234.1,29,100,1,1,233.7,234.13,1200,400,1,1,233.66,234.15,1,26,1,1,233.58,234.17,505,1,2,1,233.53,234.25,10,100,1,1,233.5,234.41,100,500,1,1,233.45,234.43,15,105,1,2,233.4,234.5,110,63,2,4,AAPL,-706,-15.005313496280554,0.1936938611374407
2024-10-21T12:23:34.381839108Z,2024-10-21T12:23:34.381673108Z,10,2,38,C,A,4,234.15,26,130,166000,12973267,233.95,234.0,523,2,1,1,233.8,234.07,405,400,2,2,233.78,234.1,29,100,1,1,233.7,234.13,1200,400,1,1,233.66,234.17,1,1,1,1,233.58,234.25,505,100,2,1,233.53,234.41,10,500,1,1,233.5,234.43,100,105,1,2,233.45,234.5,15,63,1,4,233.4,234.75,110,1,2,1,AAPL,-532,-12.206500956022944,0.1575658050553894
2024-10-21T12:23:34.381954269Z,2024-10-21T12:23:34.381786514Z,10,2,38,A,A,4,234.14,27,130,167755,12973268,233.95,234.0,523,2,1,1,233.8,234.07,405,400,2,2,233.78,234.1,29,100,1,1,233.7,234.13,1200,400,1,1,233.66,234.14,1,27,1,1,233.58,234.17,505,1,2,1,233.53,234.25,10,100,1,1,233.5,234.41,100,500,1,1,233.45,234.43,15,105,1,2,233.4,234.5,110,63,2,4,AAPL,-595,-12.979334098737082,0.16754180692062126
2024-10-21T12:23:35.765246828Z,2024-10-21T12:23:35.765078516Z,10,2,38,T,A,0,233.95,100,130,168312,12974800,233.95,234.0,523,2,1,1,233.8,234.07,405,400,2,2,233.78,234.1,29,100,1,1,233.7,234.13,1200,400,1,1,233.66,234.14,1,27,1,1,233.58,234.17,505,1,2,1,233.53,234.25,10,100,1,1,233.5,234.41,100,500,1,1,233.45,234.43,15,105,1,2,233.4,234.5,110,63,2,4,AAPL,-595,-12.428198433420366,0.16042755402265896
2024-10-21T12:23:35.765246828Z,2024-10-21T12:23:35.765078516Z,10,2,38,C,B,0,233.95,100,130,168312,12974800,233.95,234.0,423,2,1,1,233.8,234.07,405,400,2,2,233.78,234.1,29,100,1,1,233.7,234.13,1200,400,1,1,233.66,234.14,1,27,1,1,233.58,234.17,505,1,2,1,233.53,234.25,10,100,1,1,233.5,234.41,100,500,1,1,233.45,234.43,15,105,1,2,233.4,234.5,110,63,2,4,AAPL,-595,-11.968390804597702,0.15449219552253904
2024-10-21T12:23:35.765460271Z,2024-10-21T12:23:35.765293055Z,10,2,38,T,A,0,233.95,423,130,167216,12974807,233.95,234.0,423,2,1,1,233.8,234.07,405,400,2,2,233.78,234.1,29,100,1,1,233.7,234.13,1200,400,1,1,233.66,234.14,1,27,1,1,233.58,234.17,505,1,2,1,233.53,234.25,10,100,1,1,233.5,234.41,100,500,1,1,233.45,234.43,15,105,1,2,233.4,234.5,110,63,2,4,AAPL,-595,-11.578947368421053,0.14946512275485674
2024-10-21T12:23:35.765460271Z,2024-10-21T12:23:35.765293055Z,10,2,38,C,B,0,233.95,423,130,167216,12974807,233.8,234.0,405,2,2,1,233.78,234.07,29,400,1,2,233.7,234.1,1200,100,1,1,233.66,234.13,1,400,1,1,233.58,234.14,505,27,2,1,233.53,234.17,10,1,1,1,233.5,234.25,100,100,1,1,233.45,234.41,15,500,1,1,233.4,234.43,110,105,2,2,233.39,234.5,10,63,1,4,AAPL,-605,-11.923736075407026,0.15391577658153305
2024-10-21T12:23:35.765484464Z,2024-10-21T12:23:35.765317844Z,10,2,38,A,A,0,233.98,24,130,166620,12974809,233.8,233.98,405,124,2,2,233.78,234.0,29,2,1,1,233.7,234.07,1200,400,1,2,233.66,234.1,1,100,1,1,233.58,234.13,505,400,2,1,233.53,234.14,10,27,1,1,233.5,234.17,100,1,1,1,233.45,234.25,15,100,1,1,233.4,234.41,110,500,2,1,233.39,234.43,10,105,1,2,AAPL,-710,-13.915884034299713,0.17963112269613726
2024-10-21T12:23:35.765485889Z,2024-10-21T12:23:35.765319866Z,10,2,38,A,A,1,233.99,100,130,166023,12974810,233.8,233.98,405,124,2,2,233.78,233.99,29,100,1,1,233.7,234.0,1200,2,1,1,233.66,234.07,1,400,1,2,233.58,234.1,505,100,2,1,233.53,234.13,10,400,1,1,233.5,234.14,100,27,1,1,233.45,234.17,15,1,1,1,233.4,234.25,110,100,2,1,233.39,234.41,10,500,1,1,AAPL,-1210,-20.44609665427509,0.2639254026340407
2024-10-21T12:23:35.765493677Z,2024-10-21T12:23:35.765327695Z,10,2,38,A,A,1,233.99,100,130,165982,12974811,233.8,233.98,405,124,2,2,233.78,233.99,29,200,1,2,233.7,234.0,1200,2,1,1,233.66,234.07,1,400,1,2,233.58,234.1,505,100,2,1,233.53,234.13,10,400,1,1,233.5,234.14,100,27,1,1,233.45,234.17,15,1,1,1,233.4,234.25,110,100,2,1,233.39,234.41,10,500,1,1,AAPL,-1210,-18.13779187085615,0.23412899309596177
2024-10-21T12:23:35.765497059Z,2024-10-21T12:23:35.765330068Z,10,2,38,A,A,1,233.99,100,130,166991,12974812,233.8,233.98,405,124,2,2,233.78,233.99,29,300,1,3,233.7,234.0,1200,2,1,1,233.66,234.07,1,400,1,2,233.58,234.1,505,100,2,1,233.53,234.13,10,400,1,1,233.5,234.14,100,27,1,1,233.45,234.17,15,1,1,1,233.4,234.25,110,100,2,1,233.39,234.41,10,500,1,1,AAPL,-1210,-16.4212113596381,0.21197076846083351
2024-10-21T12:23:35.765503864Z,2024-10-21T12:23:35.765336405Z,10,2,38,A,A,1,233.99,38,130,167459,12974813,233.8,233.98,405,124,2,2,233.78,233.99,29,338,1,4,233.7,234.0,1200,2,1,1,233.66,234.07,1,400,1,2,233.58,234.1,505,100,2,1,233.53,234.13,10,400,1,1,233.5,234.14,100,27,1,1,233.45,234.17,15,1,1,1,233.4,234.25,110,100,2,1,233.39,234.41,10,500,1,1,AAPL,-1210,-15.094675874359545,0.19484738212551161
2024-10-21T12:23:35.765520554Z,2024-10-21T12:23:35.765353728Z,10,2,38,C,A,1,233.99,100,130,166826,12974817,233.8,233.98,405,124,2,2,233.78,233.99,29,238,1,3,233.7,234.0,1200,2,1,1,233.66,234.07,1,400,1,2,233.58,234.1,505,100,2,1,233.53,234.13,10,400,1,1,233.5,234.14,100,27,1,1,233.45,234.17,15,1,1,1,233.4,234.25,110,100,2,1,233.39,234.41,10,500,1,1,AAPL,-1210,-14.038807761552311,0.18121786537651266
2024-10-21T12:23:35.765523939Z,2024-10-21T12:23:35.765358258Z,10,2,38,C,N,0,233.8,400,130,165681,12974819,233.8,233.98,5,24,1,1,233.78,233.99,29,238,1,3,233.7,234.0,1200,2,1,1,233.66,234.07,1,400,1,2,233.58,234.1,505,100,2,1,233.53,234.13,10,400,1,1,233.5,234.14,100,27,1,1,233.45,234.17,15,1,1,1,233.4,234.25,110,100,2,1,233.39,234.41,10,500,1,1,AAPL,-1210,-13.178435287711018,0.17011187505408454
2024-10-21T12:23:35.765545765Z,2024-10-21T12:23:35.765377342Z,10,2,38,C,A,1,233.99,100,128,168423,12974821,233.8,233.98,5,24,1,1,233.78,233.99,29,138,1,2,233.7,234.0,1200,2,1,1,233.66,234.07,1,400,1,2,233.58,234.1,505,100,2,1,233.53,234.13,10,400,1,1,233.5,234.14,100,27,1,1,233.45,234.17,15,1,1,1,233.4,234.25,110,100,2,1,233.39,234.41,10,500,1,1,AAPL,-1210,-12.463864429307193,0.16088794323454342
2024-10-21T12:23:35.765878037Z,2024-10-21T12:23:35.765712149Z,10,2,38,C,A,1,233.99,100,130,165888,12974836,233.8,233.98,5,24,1,1,233.78,233.99,29,38,1,1,233.7,234.0,1200,2,1,1,233.66,234.07,1,400,1,2,233.58,234.1,505,100,2,1,233.53,234.13,10,400,1,1,233.5,234.14,100,27,1,1,233.45,234.17,15,1,1,1,233.4,234.25,110,100,2,1,233.39,234.41,10,500,1,1,AAPL,-1210,-11.86092816664114,0.15310503001753437
2024-10-21T12:23:35.833393604Z,2024-10-21T12:23:35.833227941Z,10,2,38,C,B,1,233.78,29,130,165663,12975154,233.8,233.98,5,24,1,1,233.7,233.99,1200,38,1,1,233.66,234.0,1,2,1,1,233.58,234.07,505,400,2,2,233.53,234.1,10,100,1,1,233.5,234.13,100,400,1,1,233.45,234.14,15,27,1,1,233.4,234.17,110,1,2,1,233.39,234.25,10,100,1,1,233.31,234.41,110,500,2,1,AAPL,-1320,-12.203389830508474,0.15752564555365484
2024-10-21T12:23:35.833436011Z,2024-10-21T12:23:35.833269631Z,10,2,38,A,B,1,233.71,30,130,166380,12975155,233.8,233.98,5,24,1,1,233.71,233.99,30,38,1,1,233.7,234.0,1200,2,1,1,233.66,234.07,1,400,1,2,233.58,234.1,505,100,2,1,233.53,234.13,10,400,1,1,233.5,234.14,100,27,1,1,233.45,234.17,15,1,1,1,233.4,234.25,110,100,2,1,233.39,234.41,10,500,1,1,AAPL,-1310,-11.645966793044842,0.1503302330459419
2024-10-21T12:23:35.833941747Z,2024-10-21T12:23:35.833775320Z,10,2,38,A,B,0,233.91,100,130,166427,12975156,233.91,233.98,100,24,1,1,233.8,233.99,5,38,1,1,233.71,234.0,30,2,1,1,233.7,234.07,1200,400,1,2,233.66,234.1,1,100,1,1,233.58,234.13,505,400,2,1,233.53,234.14,10,27,1,1,233.5,234.17,100,1,1,1,233.45,234.25,15,100,1,1,233.4,234.41,110,500,2,1,AAPL,-1200,-10.170722847802399,0.13128726563679918
2024-10-21T12:23:35.833961308Z,2024-10-21T12:23:35.833795471Z,10,2,38,C,A,0,233.98,24,130,165837,12975157,233.91,233.99,100,38,1,1,233.8,234.0,5,2,1,1,233.71,234.07,30,400,1,2,233.7,234.1,1200,100,1,1,233.66,234.13,1,400,1,1,233.58,234.14,505,27,2,1,233.53,234.17,10,1,1,1,233.5,234.25,100,100,1,1,233.45,234.41,15,500,1,1,233.4,234.43,110,105,2,2,AAPL,-1095,-9.303752655180553,0.1200961096411833
2024-10-21T12:23:35.836968752Z,2024-10-21T12:23:35.836802755Z,10,2,38,C,B,2,233.71,30,130,165997,12975162,233.91,233.99,100,38,1,1,233.8,234.0,5,2,1,1,233.7,234.07,1200,400,1,2,233.66,234.1,1,100,1,1,233.58,234.13,505,400,2,1,233.53,234.14,10,27,1,1,233.5,234.17,100,1,1,1,233.45,234.25,15,100,1,1,233.4,234.41,110,500,2,1,233.39,234.43,10,105,1,2,AAPL,-1105,-9.520316684130865,0.1228915942514358
2024-10-21T12:23:35.873928834Z,2024-10-21T12:23:35.873762810Z,10,2,38,C,A,0,233.99,38,130,166024,12975242,233.91,234.0,100,2,1,1,233.8,234.07,5,400,1,2,233.7,234.1,1200,100,1,1,233.66,234.13,1,400,1,1,233.58,234.14,505,27,2,1,233.53,234.17,10,1,1,1,233.5,234.25,100,100,1,1,233.45,234.41,15,500,1,1,233.4,234.43,110,105,2,2,233.39,234.5,10,63,1,4,AAPL,-1042,-9.142461325329023,0.11801410445984009
2024-10-21T12:23:35.901252464Z,2024-10-21T12:23:35.901086187Z,10,2,38,A,B,3,233.68,400,130,166277,12975273,233.91,234.0,100,2,1,1,233.8,234.07,5,400,1,2,233.7,234.1,1200,100,1,1,233.68,234.13,400,400,1,1,233.66,234.14,1,27,1,1,233.58,234.17,505,1,2,1,233.53,234.25,10,100,1,1,233.5,234.41,100,500,1,1,233.45,234.43,15,105,1,2,233.4,234.5,110,63,2,4,AAPL,-932,-8.228183361629881,0.10621228312597326
2024-10-21T12:23:35.969287724Z,2024-10-21T12:23:35.969121189Z,10,2,38,A,B,3,233.69,400,130,166535,12975451,233.91,234.0,100,2,1,1,233.8,234.07,5,400,1,2,233.7,234.1,1200,100,1,1,233.69,234.13,400,400,1,1,233.66,234.14,1,27,1,1,233.58,234.17,505,1,2,1,233.53,234.25,10,100,1,1,233.5,234.41,100,500,1,1,233.45,234.43,15,105,1,2,233.4,234.5,110,63,2,4,AAPL,-932,-8.27708703374778,0.10684354891583252
2024-10-21T12:23:36.000313609Z,2024-10-21T12:23:36.000147454Z,10,2,38,A,B,2,233.73,400,130,166155,12975478,233.91,234.0,100,2,1,1,233.8,234.07,5,400,1,2,233.73,234.1,400,100,1,1,233.7,234.13,1200,400,1,1,233.66,234.14,1,27,1,1,233.58,234.17,505,1,2,1,233.53,234.25,10,100,1,1,233.5,234.41,100,500,1,1,233.45,234.43,15,105,1,2,233.4,234.5,110,63,2,4,AAPL,-932,-8.324147696329376,0.10745102449075969
2024-10-21T12:23:36.364494386Z,2024-10-21T12:23:36.364328399Z,10,2,38,A,B,3,233.71,27,130,165987,12975884,233.91,234.0,100,2,1,1,233.8,234.07,5,400,1,2,233.73,234.1,400,100,1,1,233.71,234.13,27,400,1,1,233.7,234.14,1200,27,1,1,233.66,234.17,1,1,1,1,233.58,234.25,505,100,2,1,233.53,234.41,10,500,1,1,233.5,234.43,100,105,1,2,233.45,234.5,15,63,1,4,AAPL,-917,-8.319256939194297,0.10738789287850688
2024-10-21T12:23:36.418044070Z,2024-10-21T12:23:36.417876919Z,10,2,38,A,B,2,233.79,400,130,167151,12975910,233.91,234.0,100,2,1,1,233.8,234.07,5,400,1,2,233.79,234.1,400,100,1,1,233.71,234.13,27,400,1,1,233.7,234.14,1200,27,1,1,233.66,234.17,1,1,1,1,233.58,234.25,505,100,2,1,233.53,234.41,10,500,1,1,233.5,234.43,100,105,1,2,233.45,234.5,15,63,1,4,AAPL,-917,-8.446181857127558,0.1090262843346494
2024-10-21T12:23:37.809565585Z,2024-10-21T12:23:37.809399308Z,10,2,38,C,A,1,234.07,200,130,166277,12978420,233.91,234.0,100,2,1,1,233.8,234.07,5,200,1,1,233.79,234.1,400,100,1,1,233.71,234.13,27,400,1,1,233.7,234.14,1200,27,1,1,233.66,234.17,1,1,1,1,233.58,234.25,505,100,2,1,233.53,234.41,10,500,1,1,233.5,234.43,100,105,1,2,233.45,234.5,15,63,1,4,AAPL,-917,-8.57100371747212,0.11063752878418988
2024-10-21T12:23:37.809578123Z,2024-10-21T12:23:37.809411756Z,10,2,38,A,A,1,234.02,200,130,166367,12978421,233.91,234.0,100,2,1,1,233.8,234.02,5,200,1,1,233.79,234.1,400,100,1,1,233.71,234.13,27,400,1,1,233.7,234.14,1200,27,1,1,233.66,234.17,1,1,1,1,233.58,234.25,505,100,2,1,233.53,234.41,10,500,1,1,233.5,234.43,100,105,1,2,233.45,234.5,15,63,1,4,AAPL,-917,-8.693774360054778,0.1122222953938348
2024-10-21T12:23:37.892570179Z,2024-10-21T12:23:37.892403782Z,10,2,38,A,A,1,234.01,200,130,166397,12978809,233.91,234.0,100,2,1,1,233.8,234.01,5,200,1,1,233.79,234.1,400,100,1,1,233.71,234.13,27,400,1,1,233.7,234.14,1200,27,1,1,233.66,234.17,1,1,1,1,233.58,234.25,505,100,2,1,233.53,234.41,10,500,1,1,233.5,234.43,100,105,1,2,233.45,234.5,15,63,1,4,AAPL,-917,-8.814543934803051,0.11378123151647683
2024-10-21T12:23:39.411896692Z,2024-10-21T12:23:39.411730598Z,10,2,38,C,A,4,234.14,27,130,166094,12981148,233.91,234.0,100,2,1,1,233.8,234.01,5,200,1,1,233.79,234.1,400,100,1,1,233.71,234.13,27,400,1,1,233.7,234.17,1200,1,1,1,233.66,234.25,1,100,1,1,233.58,234.41,505,500,2,1,233.53,234.43,10,105,1,2,233.5,234.5,100,63,1,4,233.45,234.75,15,1,1,1,AAPL,-916,-8.98132888286221,0.1159341502527094
2024-10-21T12:23:39.411955539Z,2024-10-21T12:23:39.411789045Z,10,2,38,A,A,2,234.08,30,130,166494,12981149,233.91,234.0,100,2,1,1,233.8,234.01,5,200,1,1,233.79,234.08,400,30,1,1,233.71,234.1,27,100,1,1,233.7,234.13,1200,400,1,1,233.66,234.17,1,1,1,1,233.58,234.25,505,100,2,1,233.53,234.41,10,500,1,1,233.5,234.43,100,105,1,2,233.45,234.5,15,63,1,4,AAPL,-979,-9.724159337816866,0.12552286687807773
2024-10-21T12:23:40.838628426Z,2024-10-21T12:23:40.838462060Z,10,2,38,C,B,3,233.71,27,130,166366,12982424,233.91,234.0,100,2,1,1,233.8,234.01,5,200,1,1,233.79,234.08,400,30,1,1,233.7,234.1,1200,100,1,1,233.66,234.13,1,400,1,1,233.58,234.17,505,1,2,1,233.53,234.25,10,100,1,1,233.5,234.41,100,500,1,1,233.45,234.43,15,105,1,2,233.4,234.5,110,63,2,4,AAPL,-1089,-10.847936572474081,0.1400289784426956
2024-10-21T12:23:40.838662378Z,2024-10-21T12:23:40.838495937Z,10,2,38,A,B,3,233.77,28,130,166441,12982425,233.91,234.0,100,2,1,1,233.8,234.01,5,200,1,1,233.79,234.08,400,30,1,1,233.77,234.1,28,100,1,1,233.7,234.13,1200,400,1,1,233.66,234.17,1,1,1,1,233.58,234.25,505,100,2,1,233.53,234.41,10,500,1,1,233.5,234.43,100,105,1,2,233.45,234.5,15,63,1,4,AAPL,-1074,-10.83098023396531,0.13981010006489084
2024-10-21T12:23:40.884021980Z,2024-10-21T12:23:40.883854903Z,10,2,38,A,B,1,233.82,200,130,167077,12982474,233.91,234.0,100,2,1,1,233.82,234.01,200,200,1,1,233.8,234.08,5,30,1,1,233.77,234.1,28,100,1,1,233.7,234.13,1200,400,1,1,233.66,234.17,1,1,1,1,233.58,234.25,505,100,2,1,233.53,234.41,10,500,1,1,233.5,234.43,100,105,1,2,233.45,234.5,15,63,1,4,AAPL,-1074,-10.961376826095657,0.1414933051118998
2024-10-21T12:23:53.580666026Z,2024-10-21T12:23:53.580500087Z,10,2,38,A,A,0,233.97,4,130,165939,12991980,233.91,233.97,100,4,1,1,233.82,234.0,200,2,1,1,233.8,234.01,5,200,1,1,233.77,234.08,28,30,1,1,233.7,234.1,1200,100,1,1,233.66,234.13,1,400,1,1,233.58,234.17,505,1,2,1,233.53,234.25,10,100,1,1,233.5,234.41,100,500,1,1,233.45,234.43,15,105,1,2,AAPL,-756,-6.214618973561431,0.08022048621546544
2024-10-21T12:23:53.580697675Z,2024-10-21T12:23:53.580531557Z,10,2,38,C,B,1,233.82,200,130,166118,12991981,233.91,233.97,100,4,1,1,233.8,234.0,5,2,1,1,233.77,234.01,28,200,1,1,233.7,234.08,1200,30,1,1,233.66,234.1,1,100,1,1,233.58,234.13,505,400,2,1,233.53,234.17,10,1,1,1,233.5,234.25,100,100,1,1,233.45,234.41,15,500,1,1,233.4,234.43,110,105,2,2,AAPL,-866,-7.140718238038407,0.09217490105508565
2024-10-21T12:23:53.584756226Z,2024-10-21T12:23:53.584590487Z,10,2,38,C,A,0,233.97,4,130,165739,12991991,233.91,234.0,100,2,1,1,233.8,234.01,5,200,1,1,233.77,234.08,28,30,1,1,233.7,234.1,1200,100,1,1,233.66,234.13,1,400,1,1,233.58,234.17,505,1,2,1,233.53,234.25,10,100,1,1,233.5,234.41,100,500,1,1,233.45,234.43,15,105,1,2,233.4,234.5,110,63,2,4,AAPL,-803,-6.670287539936102,0.08610241624258216
2024-10-21T12:23:53.687484901Z,2024-10-21T12:23:53.687318686Z,10,2,38,A,B,1,233.82,200,130,166215,12992039,233.91,234.0,100,2,1,1,233.82,234.01,200,200,1,1,233.8,234.08,5,30,1,1,233.77,234.1,28,100,1,1,233.7,234.13,1200,400,1,1,233.66,234.17,1,1,1,1,233.58,234.25,505,100,2,1,233.53,234.41,10,500,1,1,233.5,234.43,100,105,1,2,233.45,234.5,15,63,1,4,AAPL,-788,-6.658217152513731,0.08594660743886451
2024-10-21T12:23:56.151884878Z,2024-10-21T12:23:56.151717030Z,10,2,38,T,A,0,233.91,100,130,167848,12994141,233.91,234.0,100,2,1,1,233.82,234.01,200,200,1,1,233.8,234.08,5,30,1,1,233.77,234.1,28,100,1,1,233.7,234.13,1200,400,1,1,233.66,234.17,1,1,1,1,233.58,234.25,505,100,2,1,233.53,234.41,10,500,1,1,233.5,234.43,100,105,1,2,233.45,234.5,15,63,1,4,AAPL,-279,-5.666892349356805,0.07315023841849223
2024-10-21T12:23:56.151884878Z,2024-10-21T12:23:56.151717030Z,10,2,38,C,B,0,233.91,100,130,167848,12994141,233.82,234.0,200,2,1,1,233.8,234.01,5,200,1,1,233.77,234.08,28,30,1,1,233.7,234.1,1200,100,1,1,233.66,234.13,1,400,1,1,233.58,234.17,505,1,2,1,233.53,234.25,10,100,1,1,233.5,234.41,100,500,1,1,233.45,234.43,15,105,1,2,233.4,234.5,110,63,2,4,AAPL,-389,-7.544242424242424,0.09738373309365475
2024-10-21T12:23:56.151905940Z,2024-10-21T12:23:56.151739820Z,10,2,38,A,A,0,233.95,100,130,166120,12994142,233.82,233.95,200,100,1,1,233.8,234.0,5,2,1,1,233.77,234.01,28,200,1,1,233.7,234.08,1200,30,1,1,233.66,234.1,1,100,1,1,233.58,234.13,505,400,2,1,233.53,234.17,10,1,1,1,233.5,234.25,100,100,1,1,233.45,234.41,15,500,1,1,233.4,234.43,110,105,2,2,AAPL,-494,-9.005898123324396,0.1162512986449449
2024-10-21T12:23:56.151909152Z,2024-10-21T12:23:56.151743006Z,10,2,38,A,A,1,233.98,100,130,166146,12994143,233.82,233.95,200,100,1,1,233.8,233.98,5,100,1,1,233.77,234.0,28,2,1,1,233.7,234.01,1200,200,1,1,233.66,234.08,1,30,1,1,233.58,234.1,505,100,2,1,233.53,234.13,10,400,1,1,233.5,234.17,100,1,1,1,233.45,234.25,15,100,1,1,233.4,234.41,110,500,2,1,AAPL,-994,-14.458181818181819,0.1866312931139322
2024-10-21T12:23:56.151910443Z,2024-10-21T12:23:56.151744249Z,10,2,38,A,A,1,233.96,25,130,166194,12994144,233.82,233.95,200,100,1,1,233.8,233.96,5,25,1,1,233.77,233.98,28,100,1,1,233.7,234.0,1200,2,1,1,233.66,234.01,1,200,1,1,233.58,234.08,505,30,2,1,233.53,234.1,10,100,1,1,233.5,234.13,100,400,1,1,233.45,234.17,15,1,1,1,233.4,234.25,110,100,2,1,AAPL,-1094,-15.483054003724394,0.1998607035384005
2024-10-21T12:23:56.151917914Z,2024-10-21T12:23:56.151751835Z,10,2,38,A,A,2,233.98,100,130,166079,12994145,233.82,233.95,200,100,1,1,233.8,233.96,5,25,1,1,233.77,233.98,28,200,1,2,233.7,234.0,1200,2,1,1,233.66,234.01,1,200,1,1,233.58,234.08,505,30,2,1,233.53,234.1,10,100,1,1,233.5,234.13,100,400,1,1,233.45,234.17,15,1,1,1,233.4,234.25,110,100,2,1,AAPL,-1094,-15.115716753022452,0.19511898518338527
2024-10-21T12:23:56.151922395Z,2024-10-21T12:23:56.151753407Z,10,2,38,C,B,0,233.82,200,130,168988,12994147,233.8,233.95,5,100,1,1,233.77,233.96,28,25,1,1,233.7,233.98,1200,300,1,3,233.66,234.0,1,2,1,1,233.58,234.01,505,200,2,1,233.53,234.08,10,30,1,1,233.5,234.1,100,100,1,1,233.45,234.13,15,400,1,1,233.4,234.17,110,1,2,1,233.39,234.25,10,100,1,1,AAPL,-1104,-15.430282861896838,0.1991795150900722
2024-10-21T12:23:56.151926634Z,2024-10-21T12:23:56.151760470Z,10,2,38,A,A,1,233.96,30,130,166164,12994148,233.8,233.95,5,100,1,1,233.77,233.96,28,55,1,2,233.7,233.98,1200,300,1,3,233.66,234.0,1,2,1,1,233.58,234.01,505,200,2,1,233.53,234.08,10,30,1,1,233.5,234.1,100,100,1,1,233.45,234.13,15,400,1,1,233.4,234.17,110,1,2,1,233.39,234.25,10,100,1,1,AAPL,-1104,-15.59422150882825,0.2012956927708427
2024-10-21T12:23:56.151940792Z,2024-10-21T12:23:56.151774406Z,10,2,38,C,A,2,233.98,100,130,166386,12994150,233.8,233.95,5,100,1,1,233.77,233.96,28,55,1,2,233.7,233.98,1200,200,1,2,233.66,233.99,1,30,1,1,233.58,234.0,505,2,2,1,233.53,234.01,10,200,1,1,233.5,234.08,100,30,1,1,233.45,234.1,15,100,1,1,233.4,234.13,110,400,2,1,233.39,234.17,10,1,1,1,AAPL,-1105,-16.26039667306462,0.20989491595846854
2024-10-21T12:23:56.151962295Z,2024-10-21T12:23:56.151794726Z,10,2,38,C,A,0,233.95,100,130,167569,12994152,233.8,233.96,5,55,1,2,233.77,233.98,28,200,1,2,233.7,233.99,1200,30,1,1,233.66,234.0,1,2,1,1,233.58,234.01,505,200,2,1,233.53,234.08,10,30,1,1,233.5,234.1,100,100,1,1,233.45,234.13,15,400,1,1,233.4,234.17,110,1,2,1,233.39,234.25,10,100,1,1,AAPL,-1005,-14.907292954264523,0.19242857752583362
2024-10-21T12:23:56.151983196Z,2024-10-21T12:23:56.151815406Z,10,2,38,C,A,0,233.96,25,128,167790,12994153,233.8,233.96,5,30,1,1,233.77,233.98,28,200,1,2,233.7,233.99,1200,30,1,1,233.66,234.0,1,2,1,1,233.58,234.01,505,200,2,1,233.53,234.08,10,30,1,1,233.5,234.1,100,100,1,1,233.45,234.13,15,400,1,1,233.4,234.17,110,1,2,1,233.39,234.25,10,100,1,1,AAPL,-1005,-15.017931858936043,0.19385674339808653
2024-10-21T12:23:56.151984267Z,2024-10-21T12:23:56.151818053Z,10,2,38,C,A,1,233.98,100,130,166214,12994155,233.8,233.96,5,30,1,1,233.77,233.98,28,100,1,1,233.7,233.99,1200,30,1,1,233.66,234.0,1,2,1,1,233.58,234.01,505,200,2,1,233.53,234.08,10,30,1,1,233.5,234.1,100,100,1,1,233.45,234.13,15,400,1,1,233.4,234.17,110,1,2,1,233.39,234.25,10,100,1,1,AAPL,-1005,-15.121527777777777,0.19519399593356407
2024-10-21T12:23:56.152075526Z,2024-10-21T12:23:56.151908869Z,10,2,38,A,A,0,233.95,100,130,166657,12994157,233.8,233.95,5,100,1,1,233.77,233.96,28,30,1,1,233.7,233.98,1200,100,1,1,233.66,233.99,1,30,1,1,233.58,234.0,505,2,2,1,233.53,234.01,10,200,1,1,233.5,234.08,100,30,1,1,233.45,234.1,15,100,1,1,233.4,234.13,110,400,2,1,233.39,234.17,10,1,1,1,AAPL,-1006,-15.66887799250072,0.20225938490463577
2024-10-21T12:23:56.152225403Z,2024-10-21T12:23:56.152059304Z,10,2,38,C,A,2,233.98,100,130,166099,12994158,233.8,233.95,5,100,1,1,233.77,233.96,28,30,1,1,233.7,233.99,1200,30,1,1,233.66,234.0,1,2,1,1,233.58,234.01,505,200,2,1,233.53,234.08,10,30,1,1,233.5,234.1,100,100,1,1,233.45,234.13,15,400,1,1,233.4,234.17,110,1,2,1,233.39,234.25,10,100,1,1,AAPL,-906,-14.183953033268102,0.1830914515639284
2024-10-21T12:23:56.152267246Z,2024-10-21T12:23:56.152100943Z,10,2,38,A,A,0,233.95,7,130,166303,12994159,233.8,233.95,5,107,1,2,233.77,233.96,28,30,1,1,233.7,233.99,1200,30,1,1,233.66,234.0,1,2,1,1,233.58,234.01,505,200,2,1,233.53,234.08,10,30,1,1,233.5,234.1,100,100,1,1,233.45,234.13,15,400,1,1,233.4,234.17,110,1,2,1,233.39,234.25,10,100,1,1,AAPL,-906,-14.252237591537835,0.18397289264482333
2024-10-21T12:23:56.152492907Z,2024-10-21T12:23:56.152326897Z,10,2,38,C,A,0,233.95,100,130,166010,12994160,233.8,233.95,5,7,1,1,233.77,233.96,28,30,1,1,233.7,233.99,1200,30,1,1,233.66,234.0,1,2,1,1,233.58,234.01,505,200,2,1,233.53,234.08,10,30,1,1,233.5,234.1,100,100,1,1,233.45,234.13,15,400,1,1,233.4,234.17,110,1,2,1,233.39,234.25,10,100,1,1,AAPL,-906,-14.316565709770872,0.18480326260699384
2024-10-21T12:23:56.156361100Z,2024-10-21T12:23:56.156195112Z,10,2,38,C,A,0,233.95,7,130,165988,12994163,233.8,233.96,5,30,1,1,233.77,233.99,28,30,1,1,233.7,234.0,1200,2,1,1,233.66,234.01,1,200,1,1,233.58,234.08,505,30,2,1,233.53,234.1,10,100,1,1,233.5,234.13,100,400,1,1,233.45,234.17,15,1,1,1,233.4,234.25,110,100,2,1,233.39,234.41,10,500,1,1,AAPL,-406,-5.844439284885071,0.07544207667192922
2024-10-21T12:23:56.223030277Z,2024-10-21T12:23:56.222863616Z,10,2,38,A,B,2,233.73,400,130,166661,12994197,233.8,233.96,5,30,1,1,233.77,233.99,28,30,1,1,233.73,234.0,400,2,1,1,233.7,234.01,1200,200,1,1,233.66,234.08,1,30,1,1,233.58,234.1,505,100,2,1,233.53,234.13,10,400,1,1,233.5,234.17,100,1,1,1,233.45,234.25,15,100,1,1,233.4,234.41,110,500,2,1,AAPL,-296,-3.852755745373195,0.04973272544594091
2024-10-21T12:23:56.223543885Z,2024-10-21T12:23:56.223377764Z,10,2,38,C,B,1,233.77,28,130,166121,12994198,233.8,233.96,5,30,1,1,233.73,233.99,400,30,1,1,233.7,234.0,1200,2,1,1,233.66,234.01,1,200,1,1,233.58,234.08,505,30,2,1,233.53,234.1,10,100,1,1,233.5,234.13,100,400,1,1,233.45,234.17,15,1,1,1,233.4,234.25,110,100,2,1,233.39,234.41,10,500,1,1,AAPL,-306,-3.72139303482587,0.0480370494028047
2024-10-21T12:23:56.223614225Z,2024-10-21T12:23:56.223447893Z,10,2,38,A,B,2,233.71,29,130,166332,12994199,233.8,233.96,5,30,1,1,233.73,233.99,400,30,1,1,233.71,234.0,29,2,1,1,233.7,234.01,1200,200,1,1,233.66,234.08,1,30,1,1,233.58,234.1,505,100,2,1,233.53,234.13,10,400,1,1,233.5,234.17,100,1,1,1,233.45,234.25,15,100,1,1,233.4,234.41,110,500,2,1,AAPL,-196,-2.2077190657611396,0.028498013737601365
2024-10-21T12:23:56.253930823Z,2024-10-21T12:23:56.253764723Z,10,2,38,C,A,1,233.99,30,130,166100,12994211,233.8,233.96,5,30,1,1,233.73,234.0,400,2,1,1,233.71,234.01,29,200,1,1,233.7,234.08,1200,30,1,1,233.66,234.1,1,100,1,1,233.58,234.13,505,400,2,1,233.53,234.17,10,1,1,1,233.5,234.25,100,100,1,1,233.45,234.41,15,500,1,1,233.4,234.43,110,105,2,2,AAPL,-91,-1.0188739603326935,0.013151983225019129
2024-10-21T12:23:56.403930641Z,2024-10-21T12:23:56.403764720Z,10,2,38,C,A,0,233.96,30,130,165921,12994800,233.8,234.0,5,2,1,1,233.73,234.01,400,200,1,1,233.71,234.08,29,30,1,1,233.7,234.1,1200,100,1,1,233.66,234.13,1,400,1,1,233.58,234.17,505,1,2,1,233.53,234.25,10,100,1,1,233.5,234.41,100,500,1,1,233.45,234.43,15,105,1,2,233.4,234.5,110,63,2,4,AAPL,-43,-0.47423979832991964,0.006121654017180812
2024-10-21T12:23:59.005077193Z,2024-10-21T12:23:59.004911131Z,10,2,38,C,B,1,233.73,400,130,166062,12997239,233.8,234.0,5,2,1,1,233.71,234.01,29,200,1,1,233.7,234.08,1200,30,1,1,233.66,234.1,1,100,1,1,233.58,234.13,505,400,2,1,233.53,234.17,10,1,1,1,233.5,234.25,100,100,1,1,233.45,234.41,15,500,1,1,233.4,234.43,110,105,2,2,233.39,234.5,10,63,1,4,AAPL,-53,-0.5553372626064178,0.007168488592683967
2024-10-21T12:23:59.005089751Z,2024-10-21T12:23:59.004923443Z,10,2,38,A,B,3,233.68,400,130,166308,12997240,233.8,234.0,5,2,1,1,233.71,234.01,29,200,1,1,233.7,234.08,1200,30,1,1,233.68,234.1,400,100,1,1,233.66,234.13,1,400,1,1,233.58,234.17,505,1,2,1,233.53,234.25,10,100,1,1,233.5,234.41,100,500,1,1,233.45,234.43,15,105,1,2,233.4,234.5,110,63,2,4,AAPL,57,0.5989492119089317,-0.00773144696434532
2024-10-21T12:23:59.008446995Z,2024-10-21T12:23:59.008280403Z,10,2,38,A,A,2,234.03,29,130,166592,12997243,233.8,234.0,5,2,1,1,233.71,234.01,29,200,1,1,233.7,234.03,1200,29,1,1,233.68,234.08,400,30,1,1,233.66,234.1,1,100,1,1,233.58,234.13,505,400,2,1,233.53,234.17,10,1,1,1,233.5,234.25,100,100,1,1,233.45,234.41,15,500,1,1,233.4,234.43,110,105,2,2,AAPL,-48,-0.5024630541871921,0.006485969724561403
2024-10-21T12:23:59.008489006Z,2024-10-21T12:23:59.008322912Z,10,2,38,C,A,3,234.08,30,130,166094,12997244,233.8,234.0,5,2,1,1,233.71,234.01,29,200,1,1,233.7,234.03,1200,29,1,1,233.68,234.1,400,100,1,1,233.66,234.13,1,400,1,1,233.58,234.17,505,1,2,1,233.53,234.25,10,100,1,1,233.5,234.41,100,500,1,1,233.45,234.43,15,105,1,2,233.4,234.5,110,63,2,4,AAPL,15,0.15744489428699954,-0.0020323540390132034
2024-10-21T12:23:59.012113870Z,2024-10-21T12:23:59.011947596Z,10,2,38,C,A,1,234.01,200,130,166274,12997249,233.8,234.0,5,2,1,1,233.71,234.03,29,29,1,1,233.7,234.1,1200,100,1,1,233.68,234.13,400,400,1,1,233.66,234.17,1,1,1,1,233.58,234.25,505,100,2,1,233.53,234.41,10,500,1,1,233.5,234.43,100,105,1,2,233.45,234.5,15,63,1,4,233.4,234.75,110,1,2,1,AAPL,16,0.16991150442477876,-0.0021932774248178493
2024-10-21T12:23:59.012126464Z,2024-10-21T12:23:59.011960403Z,10,2,38,A,A,2,234.04,200,130,166061,12997250,233.8,234.0,5,2,1,1,233.71,234.03,29,29,1,1,233.7,234.04,1200,200,1,1,233.68,234.1,400,100,1,1,233.66,234.13,1,400,1,1,233.58,234.17,505,1,2,1,233.53,234.25,10,100,1,1,233.5,234.41,100,500,1,1,233.45,234.43,15,105,1,2,233.4,234.5,110,63,2,4,AAPL,-47,-0.5002157342154466,0.006456960528409218
2024-10-21T12:23:59.013684039Z,2024-10-21T12:23:59.013517894Z,10,2,38,C,A,2,234.04,200,130,166145,12997253,233.8,234.0,5,2,1,1,233.71,234.03,29,29,1,1,233.7,234.1,1200,100,1,1,233.68,234.13,400,400,1,1,233.66,234.17,1,1,1,1,233.58,234.25,505,100,2,1,233.53,234.41,10,500,1,1,233.5,234.43,100,105,1,2,233.45,234.5,15,63,1,4,233.4,234.75,110,1,2,1,AAPL,-46,-0.49490373725934317,0.006388391404476349
2024-10-21T12:23:59.013696792Z,2024-10-21T12:23:59.013530559Z,10,2,38,A,A,2,234.07,400,130,166233,12997254,233.8,234.0,5,2,1,1,233.71,234.03,29,29,1,1,233.7,234.07,1200,400,1,1,233.68,234.1,400,100,1,1,233.66,234.13,1,400,1,1,233.58,234.17,505,1,2,1,233.53,234.25,10,100,1,1,233.5,234.41,100,500,1,1,233.45,234.43,15,105,1,2,233.4,234.5,110,63,2,4,AAPL,-109,-1.174796186265027,0.015164682125676163
2024-10-21T12:23:59.014404565Z,2024-10-21T12:23:59.014238552Z,10,2,38,C,A,1,234.03,29,130,166013,12997255,233.8,234.0,5,2,1,1,233.71,234.07,29,400,1,1,233.7,234.1,1200,100,1,1,233.68,234.13,400,400,1,1,233.66,234.17,1,1,1,1,233.58,234.25,505,100,2,1,233.53,234.41,10,500,1,1,233.5,234.43,100,105,1,2,233.45,234.5,15,63,1,4,233.4,234.75,110,1,2,1,AAPL,-108,-1.1758301578660861,0.015178028994554662
2024-10-21T12:23:59.017362837Z,2024-10-21T12:23:59.017196811Z,10,2,38,C,B,1,233.71,29,130,166026,12997256,233.8,234.0,5,2,1,1,233.7,234.07,1200,400,1,1,233.68,234.1,400,100,1,1,233.66,234.13,1,400,1,1,233.58,234.17,505,1,2,1,233.53,234.25,10,100,1,1,233.5,234.41,100,500,1,1,233.45,234.43,15,105,1,2,233.4,234.5,110,63,2,4,233.39,234.75,10,1,1,1,AAPL,-118,-1.3148525614893327,0.016972579048378535
2024-10-21T12:23:59.017449096Z,2024-10-21T12:23:59.017282783Z,10,2,38,A,B,4,233.61,27,130,166313,12997257,233.8,234.0,5,2,1,1,233.7,234.07,1200,400,1,1,233.68,234.1,400,100,1,1,233.66,234.13,1,400,1,1,233.61,234.17,27,1,1,1,233.58,234.25,505,100,2,1,233.53,234.41,10,500,1,1,233.5,234.43,100,105,1,2,233.45,234.5,15,63,1,4,233.4,234.75,110,1,2,1,AAPL,-8,-0.08995983935742971,0.0011612332282670138
2024-10-21T12:23:59.074684910Z,2024-10-21T12:23:59.074518650Z,10,2,38,A,A,1,234.02,200,130,166260,12997280,233.8,234.0,5,2,1,1,233.7,234.02,1200,200,1,1,233.68,234.1,400,100,1,1,233.66,234.13,1,400,1,1,233.61,234.17,27,1,1,1,233.58,234.25,505,100,2,1,233.53,234.41,10,500,1,1,233.5,234.43,100,105,1,2,233.45,234.5,15,63,1,4,233.4,234.75,110,1,2,1,AAPL,-8,-0.0907531987864398,0.001171474190650962
2024-10-21T12:24:00.591711571Z,2024-10-21T12:24:00.591545399Z,10,2,38,A,B,3,233.66,27,130,166172,12999539,233.8,234.0,5,2,1,1,233.7,234.02,1200,200,1,1,233.68,234.1,400,100,1,1,233.66,234.13,28,400,2,1,233.61,234.17,27,1,1,1,233.58,234.25,505,100,2,1,233.53,234.41,10,500,1,1,233.5,234.43,100,105,1,2,233.45,234.5,15,63,1,4,233.4,234.75,110,1,2,1,AAPL,54,0.5969992103185049,-0.0077062756583697704
2024-10-21T12:24:00.591743978Z,2024-10-21T12:24:00.591577923Z,10,2,38,C,B,4,233.61,27,130,166055,12999540,233.8,234.0,5,2,1,1,233.7,234.02,1200,200,1,1,233.68,234.1,400,100,1,1,233.66,234.13,28,400,2,1,233.58,234.17,505,1,2,1,233.53,234.25,10,100,1,1,233.5,234.41,100,500,1,1,233.45,234.43,15,105,1,2,233.4,234.5,110,63,2,4,233.39,234.75,10,1,1,1,AAPL,44,0.49730582205283214,-0.006419398359349083
2024-10-21T12:24:00.591786574Z,2024-10-21T12:24:00.591620074Z,10,2,38,A,A,2,234.08,26,130,166500,12999541,233.8,234.0,5,2,1,1,233.7,234.02,1200,200,1,1,233.68,234.08,400,26,1,1,233.66,234.1,28,100,2,1,233.58,234.13,505,400,2,1,233.53,234.17,10,1,1,1,233.5,234.25,100,100,1,1,233.45,234.41,15,500,1,1,233.4,234.43,110,105,2,2,233.39,234.5,10,63,1,4,AAPL,-19,-0.21765165321530852,0.002809524046576583
2024-10-21T12:24:00.639172304Z,2024-10-21T12:24:00.639005885Z,10,2,38,A,B,1,233.72,400,130,166419,12999658,233.8,234.0,5,2,1,1,233.72,234.02,400,200,1,1,233.7,234.08,1200,26,1,1,233.66,234.1,28,100,2,1,233.58,234.13,505,400,2,1,233.53,234.17,10,1,1,1,233.5,234.25,100,100,1,1,233.45,234.41,15,500,1,1,233.4,234.43,110,105,2,2,233.39,234.5,10,63,1,4,AAPL,-19,-0.22050290135396516,0.0028463289597944405
2024-10-21T12:24:00.649223162Z,2024-10-21T12:24:00.649056842Z,10,2,38,A,A,1,234.01,200,130,166320,12999723,233.8,234.0,5,2,1,1,233.72,234.01,400,200,1,1,233.7,234.08,1200,26,1,1,233.66,234.1,28,100,2,1,233.58,234.13,505,400,2,1,233.53,234.17,10,1,1,1,233.5,234.25,100,100,1,1,233.45,234.41,15,500,1,1,233.4,234.43,110,105,2,2,233.39,234.5,10,63,1,4,AAPL,-19,-0.22330097087378642,0.00288244742470752
2024-10-21T12:24:02.009559726Z,2024-10-21T12:24:02.009392935Z,10,2,38,A,A,1,234.01,200,130,166791,13001036,233.8,234.0,5,2,1,1,233.72,234.01,400,400,1,2,233.7,234.08,1200,26,1,1,233.66,234.1,28,100,2,1,233.58,234.13,505,400,2,1,233.53,234.17,10,1,1,1,233.5,234.25,100,100,1,1,233.45,234.41,15,500,1,1,233.4,234.43,110,105,2,2,233.39,234.5,10,63,1,4,AAPL,76,0.8832540940306391,-0.0114013543189653
2024-10-21T12:24:03.014397743Z,2024-10-21T12:24:03.014231244Z,10,2,38,A,B,1,233.73,400,130,166499,13002474,233.8,234.0,5,2,1,1,233.73,234.01,400,400,1,2,233.7,234.08,1200,26,1,1,233.66,234.1,28,100,2,1,233.58,234.13,505,400,2,1,233.53,234.17,10,1,1,1,233.5,234.25,100,100,1,1,233.45,234.41,15,500,1,1,233.4,234.43,110,105,2,2,233.39,234.5,10,63,1,4,AAPL,76,0.8947024198822761,-0.011549133333266652
2024-10-21T12:24:12.705919587Z,2024-10-21T12:24:12.705753370Z,10,2,38,C,A,2,234.08,26,130,166217,13011148,233.8,234.0,5,2,1,1,233.73,234.01,400,400,1,2,233.7,234.1,1200,100,1,1,233.66,234.13,28,400,2,1,233.58,234.17,505,1,2,1,233.53,234.25,10,100,1,1,233.5,234.41,100,500,1,1,233.45,234.43,15,105,1,2,233.4,234.5,110,63,2,4,233.39,234.75,10,1,1,1,AAPL,77,0.925287356321839,-0.011943934443759319
2024-10-21T12:24:12.705959304Z,2024-10-21T12:24:12.705792927Z,10,2,38,A,A,2,234.03,27,130,166377,13011149,233.8,234.0,5,2,1,1,233.73,234.01,400,400,1,2,233.7,234.03,1200,27,1,1,233.66,234.1,28,100,2,1,233.58,234.13,505,400,2,1,233.53,234.17,10,1,1,1,233.5,234.25,100,100,1,1,233.45,234.41,15,500,1,1,233.4,234.43,110,105,2,2,233.39,234.5,10,63,1,4,AAPL,14,0.17026782248673825,-0.002197876903611215
2024-10-21T12:24:12.758818645Z,2024-10-21T12:24:12.758652350Z,10,2,38,C,A,1,234.01,200,130,166295,13011180,233.8,234.0,5,2,1,1,233.73,234.01,400,200,1,1,233.7,234.03,1200,27,1,1,233.66,234.1,28,100,2,1,233.58,234.13,505,400,2,1,233.53,234.17,10,1,1,1,233.5,234.25,100,100,1,1,233.45,234.41,15,500,1,1,233.4,234.43,110,105,2,2,233.39,234.5,10,63,1,4,AAPL,14,0.1722635221738016,-0.002223638096681516
2024-10-21T12:24:12.758831773Z,2024-10-21T12:24:12.758665302Z,10,2,38,A,A,0,233.96,200,130,166471,13011181,233.8,233.96,5,200,1,1,233.73,234.0,400,2,1,1,233.7,234.03,1200,27,1,1,233.66,234.1,28,100,2,1,233.58,234.13,505,400,2,1,233.53,234.17,10,1,1,1,233.5,234.25,100,100,1,1,233.45,234.41,15,500,1,1,233.4,234.43,110,105,2,2,233.39,234.5,10,63,1,4,AAPL,14,0.17422222222222222,-0.0022489216854104507
2024-10-21T12:24:12.829962896Z,2024-10-21T12:24:12.829796906Z,10,2,38,C,B,1,233.73,400,130,165990,13011209,233.8,233.96,5,200,1,1,233.7,234.0,1200,2,1,1,233.66,234.03,28,27,2,1,233.58,234.1,505,100,2,1,233.53,234.13,10,400,1,1,233.5,234.17,100,1,1,1,233.45,234.25,15,100,1,1,233.4,234.41,110,500,2,1,233.39,234.43,10,105,1,2,233.31,234.5,110,63,2,4,AAPL,-96,-1.1928429423459244,0.015397635996795288
2024-10-21T12:24:12.829976396Z,2024-10-21T12:24:12.829810064Z,10,2,38,A,B,2,233.68,400,130,166332,13011211,233.8,233.96,5,200,1,1,233.7,234.0,1200,2,1,1,233.68,234.03,400,27,1,1,233.66,234.1,28,100,2,1,233.58,234.13,505,400,2,1,233.53,234.17,10,1,1,1,233.5,234.25,100,100,1,1,233.45,234.41,15,500,1,1,233.4,234.43,110,105,2,2,233.39,234.5,10,63,1,4,AAPL,-86,-1.0801625415589213,0.013943117775076102
2024-10-21T12:24:12.887926720Z,2024-10-21T12:24:12.887759925Z,10,2,38,A,B,1,233.71,200,130,166795,13011280,233.8,233.96,5,200,1,1,233.71,234.0,200,2,1,1,233.7,234.03,1200,27,1,1,233.66,234.1,28,100,2,1,233.58,234.13,505,400,2,1,233.53,234.17,10,1,1,1,233.5,234.25,100,100,1,1,233.45,234.41,15,500,1,1,233.4,234.43,110,105,2,2,233.39,234.5,10,63,1,4,AAPL,-86,-1.0915303880888456,0.01408985793400345
2024-10-21T12:24:12.974238049Z,2024-10-21T12:24:12.974071654Z,10,2,38,A,A,0,233.96,200,130,166395,13011303,233.8,233.96,5,400,1,2,233.71,234.0,200,2,1,1,233.7,234.03,1200,27,1,1,233.66,234.1,28,100,2,1,233.58,234.13,505,400,2,1,233.53,234.17,10,1,1,1,233.5,234.25,100,100,1,1,233.45,234.41,15,500,1,1,233.4,234.43,110,105,2,2,233.39,234.5,10,63,1,4,AAPL,-86,-1.102697471876134,0.014234006576878611
2024-10-21T12:24:12.981903881Z,2024-10-21T12:24:12.981737142Z,10,2,38,A,A,0,233.94,6,130,166739,13011309,233.8,233.94,5,6,1,1,233.71,233.96,200,400,1,2,233.7,234.0,1200,2,1,1,233.66,234.03,28,27,2,1,233.58,234.1,505,100,2,1,233.53,234.13,10,400,1,1,233.5,234.17,100,1,1,1,233.45,234.25,15,100,1,1,233.4,234.41,110,500,2,1,233.39,234.43,10,105,1,2,AAPL,-191,-2.460987831066571,0.03176729598683136
2024-10-21T12:24:12.981949530Z,2024-10-21T12:24:12.981783591Z,10,2,38,C,B,1,233.71,200,130,165939,13011310,233.8,233.94,5,6,1,1,233.7,233.96,1200,400,1,2,233.66,234.0,28,2,2,1,233.58,234.03,505,27,2,1,233.53,234.1,10,100,1,1,233.5,234.13,100,400,1,1,233.45,234.17,15,1,1,1,233.4,234.25,110,100,2,1,233.39,234.41,10,500,1,1,233.31,234.43,110,105,2,2,AAPL,-301,-3.8513434919157845,0.04971449558189052
2024-10-21T12:24:12.985997932Z,2024-10-21T12:24:12.985831565Z,10,2,38,C,A,0,233.94,6,130,166367,13011317,233.8,233.96,5,400,1,2,233.7,234.0,1200,2,1,1,233.66,234.03,28,27,2,1,233.58,234.1,505,100,2,1,233.53,234.13,10,400,1,1,233.5,234.17,100,1,1,1,233.45,234.25,15,100,1,1,233.4,234.41,110,500,2,1,233.39,234.43,10,105,1,2,233.31,234.5,110,63,2,4,AAPL,-238,-3.03945267958951,0.039234323588118465
2024-10-21T12:24:13.052769828Z,2024-10-21T12:24:13.052603423Z,10,2,38,A,B,3,233.62,400,130,166405,13011374,233.8,233.96,5,400,1,2,233.7,234.0,1200,2,1,1,233.66,234.03,28,27,2,1,233.62,234.1,400,100,1,1,233.58,234.13,505,400,2,1,233.53,234.17,10,1,1,1,233.5,234.25,100,100,1,1,233.45,234.41,15,500,1,1,233.4,234.43,110,105,2,2,233.39,234.5,10,63,1,4,AAPL,-228,-2.9392740020355084,0.03794118200437968
2024-10-21T12:24:13.053294920Z,2024-10-21T12:24:13.053128647Z,10,2,38,A,B,5,233.55,27,130,166273,13011375,233.8,233.96,5,400,1,2,233.7,234.0,1200,2,1,1,233.66,234.03,28,27,2,1,233.62,234.1,400,100,1,1,233.58,234.13,505,400,2,1,233.55,234.17,27,1,1,1,233.53,234.25,10,100,1,1,233.5,234.41,100,500,1,1,233.45,234.43,15,105,1,2,233.4,234.5,110,63,2,4,AAPL,-118,-1.518189884649512,0.019597328690964096
2024-10-21T12:24:13.053320162Z,2024-10-21T12:24:13.053154026Z,10,2,38,C,B,2,233.66,27,130,166136,13011376,233.8,233.96,5,400,1,2,233.7,234.0,1200,2,1,1,233.66,234.03,1,27,1,1,233.62,234.1,400,100,1,1,233.58,234.13,505,400,2,1,233.55,234.17,27,1,1,1,233.53,234.25,10,100,1,1,233.5,234.41,100,500,1,1,233.45,234.43,15,105,1,2,233.4,234.5,110,63,2,4,AAPL,-118,-1.5152900206768962,0.01955989622747251
2024-10-21T12:24:13.185024995Z,2024-10-21T12:24:13.184858615Z,10,2,38,A,B,3,233.63,200,130,166380,13011463,233.8,233.96,5,400,1,2,233.7,234.0,1200,2,1,1,233.66,234.03,1,27,1,1,233.63,234.1,200,100,1,1,233.58,234.13,505,400,2,1,233.55,234.17,27,1,1,1,233.53,234.25,10,100,1,1,233.5,234.41,100,500,1,1,233.45,234.43,15,105,1,2,233.4,234.5,110,63,2,4,AAPL,-118,-1.512497329630421,0.01952384718978397
2024-10-21T12:24:13.203151981Z,2024-10-21T12:24:13.202985661Z,10,2,38,A,B,2,233.68,200,130,166320,13011562,233.8,233.96,5,400,1,2,233.7,234.0,1200,2,1,1,233.68,234.03,200,27,1,1,233.66,234.1,1,100,1,1,233.58,234.13,505,400,2,1,233.55,234.17,27,1,1,1,233.53,234.25,10,100,1,1,233.5,234.41,100,500,1,1,233.45,234.43,15,105,1,2,233.4,234.5,110,63,2,4,AAPL,-118,-1.5098059779758781,0.019489106276588373
2024-10-21T12:24:13.538567140Z,2024-10-21T12:24:13.538400660Z,10,2,38,A,B,2,233.68,200,130,166480,13011788,233.8,233.96,5,400,1,2,233.7,234.0,1200,2,1,1,233.68,234.03,400,27,2,1,233.66,234.1,1,100,1,1,233.58,234.13,505,400,2,1,233.55,234.17,27,1,1,1,233.53,234.25,10,100,1,1,233.5,234.41,100,500,1,1,233.45,234.43,15,105,1,2,233.4,234.5,110,63,2,4,AAPL,-118,-1.507210548001648,0.01945560355415974
2024-10-21T12:24:13.589336955Z,2024-10-21T12:24:13.589170912Z,10,2,38,C,B,2,233.68,200,130,166043,13011843,233.8,233.96,5,400,1,2,233.7,234.0,1200,2,1,1,233.68,234.03,200,27,1,1,233.66,234.1,1,100,1,1,233.58,234.13,505,400,2,1,233.55,234.17,27,1,1,1,233.53,234.25,10,100,1,1,233.5,234.41,100,500,1,1,233.45,234.43,15,105,1,2,233.4,234.5,110,63,2,4,AAPL,34,0.4352928624773285,-0.005618913278932957
2024-10-21T12:24:13.589349547Z,2024-10-21T12:24:13.589183060Z,10,2,38,A,B,1,233.71,200,130,166487,13011844,233.8,233.96,5,400,1,2,233.71,234.0,200,2,1,1,233.7,234.03,1200,27,1,1,233.66,234.1,1,100,1,1,233.58,234.13,505,400,2,1,233.55,234.17,27,1,1,1,233.53,234.25,10,100,1,1,233.5,234.41,100,500,1,1,233.45,234.43,15,105,1,2,233.4,234.5,110,63,2,4,AAPL,34,0.43452755080662053,-0.005609034366872259
2024-10-21T12:24:13.923159059Z,2024-10-21T12:24:13.922992508Z,10,2,38,C,B,5,233.55,27,130,166551,13011979,233.8,233.96,5,400,1,2,233.71,234.0,200,2,1,1,233.7,234.03,1200,27,1,1,233.66,234.1,1,100,1,1,233.58,234.13,505,400,2,1,233.53,234.17,10,1,1,1,233.5,234.25,100,100,1,1,233.45,234.41,15,500,1,1,233.4,234.43,110,105,2,2,233.39,234.5,10,63,1,4,AAPL,9,0.11508227649093387,-0.0014855224775904095
2024-10-21T12:24:13.923293151Z,2024-10-21T12:24:13.923126726Z,10,2,38,A,B,3,233.66,30,130,166425,13011980,233.8,233.96,5,400,1,2,233.71,234.0,200,2,1,1,233.7,234.03,1200,27,1,1,233.66,234.1,31,100,2,1,233.58,234.13,505,400,2,1,233.53,234.17,10,1,1,1,233.5,234.25,100,100,1,1,233.45,234.41,15,500,1,1,233.4,234.43,110,105,2,2,233.39,234.5,10,63,1,4,AAPL,9,0.11608071562304972,-0.001498410680869746
2024-10-21T12:24:15.709004892Z,2024-10-21T12:24:15.708838775Z,10,2,38,C,A,2,234.03,27,130,166117,13013886,233.8,233.96,5,400,1,2,233.71,234.0,200,2,1,1,233.7,234.1,1200,100,1,1,233.66,234.13,31,400,2,1,233.58,234.17,505,1,2,1,233.53,234.25,10,100,1,1,233.5,234.41,100,500,1,1,233.45,234.43,15,105,1,2,233.4,234.5,110,63,2,4,233.39,234.75,10,1,1,1,AAPL,10,0.13090909090909092,-0.001689820561393752
2024-10-21T12:24:15.709139884Z,2024-10-21T12:24:15.708973640Z,10,2,38,A,A,1,233.98,29,130,166244,13013888,233.8,233.96,5,400,1,2,233.71,233.98,200,29,1,1,233.7,234.0,1200,2,1,1,233.66,234.1,31,100,2,1,233.58,234.13,505,400,2,1,233.53,234.17,10,1,1,1,233.5,234.25,100,100,1,1,233.45,234.41,15,500,1,1,233.4,234.43,110,105,2,2,233.39,234.5,10,63,1,4,AAPL,-53,-0.6995256753969891,0.009029723308746889
2024-10-21T12:24:15.716746619Z,2024-10-21T12:24:15.716580295Z,10,2,38,C,A,1,233.98,29,130,166324,13013896,233.8,233.96,5,400,1,2,233.71,234.0,200,2,1,1,233.7,234.1,1200,100,1,1,233.66,234.13,31,400,2,1,233.58,234.17,505,1,2,1,233.53,234.25,10,100,1,1,233.5,234.41,100,500,1,1,233.45,234.43,15,105,1,2,233.4,234.5,110,63,2,4,233.39,234.75,10,1,1,1,AAPL,-52,-0.6962612009475744,0.00898758432505632
2024-10-21T12:24:17.552123107Z,2024-10-21T12:24:17.551956961Z,10,2,38,A,A,2,234.03,27,130,166146,13015292,233.8,233.96,5,400,1,2,233.71,234.0,200,2,1,1,233.7,234.03,1200,27,1,1,233.66,234.1,31,100,2,1,233.58,234.13,505,400,2,1,233.53,234.17,10,1,1,1,233.5,234.25,100,100,1,1,233.45,234.41,15,500,1,1,233.4,234.43,110,105,2,2,233.39,234.5,10,63,1,4,AAPL,-366,-6.772077375946173,0.08741635522601124
2024-10-21T12:24:18.858293636Z,2024-10-21T12:24:18.858127605Z,10,2,38,A,B,0,233.8,100,130,166031,13016509,233.8,233.96,105,400,2,2,233.71,234.0,200,2,1,1,233.7,234.03,1200,27,1,1,233.66,234.1,31,100,2,1,233.58,234.13,505,400,2,1,233.53,234.17,10,1,1,1,233.5,234.25,100,100,1,1,233.45,234.41,15,500,1,1,233.4,234.43,110,105,2,2,233.39,234.5,10,63,1,4,AAPL,-366,-6.8212880513563885,0.08805158392228264
2024-10-21T12:24:25.049504145Z,2024-10-21T12:24:25.049338154Z,10,2,38,C,A,2,234.03,27,130,165991,13021095,233.8,233.96,105,400,2,2,233.71,234.0,200,2,1,1,233.7,234.1,1200,100,1,1,233.66,234.13,31,400,2,1,233.58,234.17,505,1,2,1,233.53,234.25,10,100,1,1,233.5,234.41,100,500,1,1,233.45,234.43,15,105,1,2,233.4,234.5,110,63,2,4,233.39,234.75,10,1,1,1,AAPL,-327,-6.290701816886355,0.08120259030103304
2024-10-21T12:24:25.049548880Z,2024-10-21T12:24:25.049382422Z,10,2,38,A,A,1,233.98,28,130,166458,13021096,233.8,233.96,105,400,2,2,233.71,233.98,200,28,1,1,233.7,234.0,1200,2,1,1,233.66,234.1,31,100,2,1,233.58,234.13,505,400,2,1,233.53,234.17,10,1,1,1,233.5,234.25,100,100,1,1,233.45,234.41,15,500,1,1,233.4,234.43,110,105,2,2,233.39,234.5,10,63,1,4,AAPL,-390,-7.583333333333333,0.09788833228907093
2024-10-21T12:24:25.060245863Z,2024-10-21T12:24:25.060079940Z,10,2,38,C,A,1,233.98,28,130,165923,13021116,233.8,233.96,105,400,2,2,233.71,234.0,200,2,1,1,233.7,234.1,1200,100,1,1,233.66,234.13,31,400,2,1,233.58,234.17,505,1,2,1,233.53,234.25,10,100,1,1,233.5,234.41,100,500,1,1,233.45,234.43,15,105,1,2,233.4,234.5,110,63,2,4,233.39,234.75,10,1,1,1,AAPL,-389,-7.804219993081978,0.10073961493711908
2024-10-21T12:24:25.923090996Z,2024-10-21T12:24:25.922924503Z,10,2,38,A,A,2,234.03,26,130,166493,13021866,233.8,233.96,105,400,2,2,233.71,234.0,200,2,1,1,233.7,234.03,1200,26,1,1,233.66,234.1,31,100,2,1,233.58,234.13,505,400,2,1,233.53,234.17,10,1,1,1,233.5,234.25,100,100,1,1,233.45,234.41,15,500,1,1,233.4,234.43,110,105,2,2,233.39,234.5,10,63,1,4,AAPL,-452,-9.149797570850202,0.11810880329579587
2024-10-21T12:24:33.385339105Z,2024-10-21T12:24:33.385173258Z,10,2,38,C,A,2,234.03,26,130,165847,13026898,233.8,233.96,105,400,2,2,233.71,234.0,200,2,1,1,233.7,234.1,1200,100,1,1,233.66,234.13,31,400,2,1,233.58,234.17,505,1,2,1,233.53,234.25,10,100,1,1,233.5,234.41,100,500,1,1,233.45,234.43,15,105,1,2,233.4,234.5,110,63,2,4,233.39,234.75,10,1,1,1,AAPL,-257,-7.105990783410139,0.09172662686367392
2024-10-21T12:24:33.385363270Z,2024-10-21T12:24:33.385196713Z,10,2,38,A,A,1,233.98,29,130,166557,13026899,233.8,233.96,105,400,2,2,233.71,233.98,200,29,1,1,233.7,234.0,1200,2,1,1,233.66,234.1,31,100,2,1,233.58,234.13,505,400,2,1,233.53,234.17,10,1,1,1,233.5,234.25,100,100,1,1,233.45,234.41,15,500,1,1,233.4,234.43,110,105,2,2,233.39,234.5,10,63,1,4,AAPL,-320,-8.842832469775475,0.1141463898696221
2024-10-21T12:24:33.391357628Z,2024-10-21T12:24:33.391191505Z,10,2,38,C,A,1,233.98,29,130,166123,13026904,233.8,233.96,105,400,2,2,233.71,234.0,200,2,1,1,233.7,234.1,1200,100,1,1,233.66,234.13,31,400,2,1,233.58,234.17,505,1,2,1,233.53,234.25,10,100,1,1,233.5,234.41,100,500,1,1,233.45,234.43,15,105,1,2,233.4,234.5,110,63,2,4,233.39,234.75,10,1,1,1,AAPL,-319,-9.278015397775876,0.11976388407568374
2024-10-21T12:24:33.923269202Z,2024-10-21T12:24:33.923102791Z,10,2,38,A,A,2,234.03,26,130,166411,13027549,233.8,233.96,105,400,2,2,233.71,234.0,200,2,1,1,233.7,234.03,1200,26,1,1,233.66,234.1,31,100,2,1,233.58,234.13,505,400,2,1,233.53,234.17,10,1,1,1,233.5,234.25,100,100,1,1,233.45,234.41,15,500,1,1,233.4,234.43,110,105,2,2,233.39,234.5,10,63,1,4,AAPL,-372,-16.024615384615384,0.20685136820753264
2024-10-21T12:24:37.923110609Z,2024-10-21T12:24:37.922944460Z,10,2,38,C,A,2,234.03,26,130,166149,13030243,233.8,233.96,105,400,2,2,233.71,234.0,200,2,1,1,233.7,234.1,1200,100,1,1,233.66,234.13,31,400,2,1,233.58,234.17,505,1,2,1,233.53,234.25,10,100,1,1,233.5,234.41,100,500,1,1,233.45,234.43,15,105,1,2,233.4,234.5,110,63,2,4,233.39,234.75,10,1,1,1,AAPL,-247,-11.761904761904763,0.15182680110141616
2024-10-21T12:24:37.923194567Z,2024-10-21T12:24:37.923028006Z,10,2,38,A,A,1,233.98,27,130,166561,13030244,233.8,233.96,105,400,2,2,233.71,233.98,200,27,1,1,233.7,234.0,1200,2,1,1,233.66,234.1,31,100,2,1,233.58,234.13,505,400,2,1,233.53,234.17,10,1,1,1,233.5,234.25,100,100,1,1,233.45,234.41,15,500,1,1,233.4,234.43,110,105,2,2,233.39,234.5,10,63,1,4,AAPL,-310,-13.83367139959432,0.1785698931087436
2024-10-21T12:24:40.307842089Z,2024-10-21T12:24:40.307674730Z,10,2,38,T,N,0,233.84,127,130,167359,13031847,233.8,233.96,105,400,2,2,233.71,233.98,200,27,1,1,233.7,234.0,1200,2,1,1,233.66,234.1,31,100,2,1,233.58,234.13,505,400,2,1,233.53,234.17,10,1,1,1,233.5,234.25,100,100,1,1,233.45,234.41,15,500,1,1,233.4,234.43,110,105,2,2,233.39,234.5,10,63,1,4,AAPL,-310,-13.83367139959432,0.1785698931087436
2024-10-21T12:24:40.308161486Z,2024-10-21T12:24:40.307995193Z,10,2,38,A,B,0,233.8,2,130,166293,13031848,233.8,233.96,107,400,3,2,233.71,233.98,200,27,1,1,233.7,234.0,1200,2,1,1,233.66,234.1,31,100,2,1,233.58,234.13,505,400,2,1,233.53,234.17,10,1,1,1,233.5,234.25,100,100,1,1,233.45,234.41,15,500,1,1,233.4,234.43,110,105,2,2,233.39,234.5,10,63,1,4,AAPL,-310,-13.14487632508834,0.16967868416821835
2024-10-21T12:24:40.308163000Z,2024-10-21T12:24:40.307996031Z,10,2,38,A,B,1,233.79,100,130,166969,13031849,233.8,233.96,107,400,3,2,233.79,233.98,100,27,1,1,233.71,234.0,200,2,1,1,233.7,234.1,1200,100,1,1,233.66,234.13,31,400,2,1,233.58,234.17,505,1,2,1,233.53,234.25,10,100,1,1,233.5,234.41,100,500,1,1,233.45,234.43,15,105,1,2,233.4,234.5,110,63,2,4,AAPL,-200,-7.036535859269283,0.09083007828871845
2024-10-21T12:24:40.308173860Z,2024-10-21T12:24:40.308007727Z,10,2,38,C,B,0,233.8,2,130,166133,13031850,233.8,233.96,105,400,2,2,233.79,233.98,100,27,1,1,233.71,234.0,200,2,1,1,233.7,234.1,1200,100,1,1,233.66,234.13,31,400,2,1,233.58,234.17,505,1,2,1,233.53,234.25,10,100,1,1,233.5,234.41,100,500,1,1,233.45,234.43,15,105,1,2,233.4,234.5,110,63,2,4,AAPL,-200,-6.140350877192983,0.07926180752151495
2024-10-21T12:24:40.308191984Z,2024-10-21T12:24:40.308025276Z,10,2,38,C,A,0,233.96,200,130,166708,13031851,233.8,233.96,105,200,2,1,233.79,233.98,100,27,1,1,233.71,234.0,200,2,1,1,233.7,234.1,1200,100,1,1,233.66,234.13,31,400,2,1,233.58,234.17,505,1,2,1,233.53,234.25,10,100,1,1,233.5,234.41,100,500,1,1,233.45,234.43,15,105,1,2,233.4,234.5,110,63,2,4,AAPL,-200,-5.529953917050691,0.07138258899896803
2024-10-21T12:24:40.308202091Z,2024-10-21T12:24:40.308036005Z,10,2,38,C,A,0,233.96,200,130,166086,13031852,233.8,233.98,105,27,2,1,233.79,234.0,100,2,1,1,233.71,234.1,200,100,1,1,233.7,234.13,1200,400,1,1,233.66,234.17,31,1,2,1,233.58,234.25,505,100,2,1,233.53,234.41,10,500,1,1,233.5,234.43,100,105,1,2,233.45,234.5,15,63,1,4,233.4,234.75,110,1,2,1,AAPL,-199,-5.3244147157190636,0.06872941673896178
2024-10-21T12:24:40.308571346Z,2024-10-21T12:24:40.308405475Z,10,2,38,C,B,1,233.79,100,130,165871,13031857,233.8,233.98,105,27,2,1,233.71,234.0,200,2,1,1,233.7,234.1,1200,100,1,1,233.66,234.13,31,400,2,1,233.58,234.17,505,1,2,1,233.53,234.25,10,100,1,1,233.5,234.41,100,500,1,1,233.45,234.43,15,105,1,2,233.4,234.5,110,63,2,4,233.39,234.75,10,1,1,1,AAPL,-209,-5.887323943661972,0.07599564692183561
2024-10-21T12:24:40.309914708Z,2024-10-21T12:24:40.309748359Z,10,2,38,A,B,1,233.79,100,130,166349,13031868,233.8,233.98,105,27,2,1,233.79,234.0,100,2,1,1,233.71,234.1,200,100,1,1,233.7,234.13,1200,400,1,1,233.66,234.17,31,1,2,1,233.58,234.25,505,100,2,1,233.53,234.41,10,500,1,1,233.5,234.43,100,105,1,2,233.45,234.5,15,63,1,4,233.4,234.75,110,1,2,1,AAPL,-99,-2.7040971168437022,0.03490543610314484
2024-10-21T12:24:40.310359600Z,2024-10-21T12:24:40.310193512Z,10,2,38,C,B,1,233.79,100,130,166088,13031873,233.8,233.98,105,27,2,1,233.71,234.0,200,2,1,1,233.7,234.1,1200,100,1,1,233.66,234.13,31,400,2,1,233.58,234.17,505,1,2,1,233.53,234.25,10,100,1,1,233.5,234.41,100,500,1,1,233.45,234.43,15,105,1,2,233.4,234.5,110,63,2,4,233.39,234.75,10,1,1,1,AAPL,-109,-3.1166290443942817,0.04023054323333236
2024-10-21T12:24:40.353976280Z,2024-10-21T12:24:40.353810051Z,10,2,38,A,A,0,233.96,200,130,166229,13031906,233.8,233.96,105,200,2,1,233.71,233.98,200,27,1,1,233.7,234.0,1200,2,1,1,233.66,234.1,31,100,2,1,233.58,234.13,505,400,2,1,233.53,234.17,10,1,1,1,233.5,234.25,100,100,1,1,233.45,234.41,15,500,1,1,233.4,234.43,110,105,2,2,233.39,234.5,10,63,1,4,AAPL,-172,-4.907275320970043,0.06334483480260301
2024-10-21T12:24:40.377414086Z,2024-10-21T12:24:40.377247665Z,10,2,38,C,A,0,233.96,200,130,166421,13031918,233.8,233.98,105,27,2,1,233.71,234.0,200,2,1,1,233.7,234.1,1200,100,1,1,233.66,234.13,31,400,2,1,233.58,234.17,505,1,2,1,233.53,234.25,10,100,1,1,233.5,234.41,100,500,1,1,233.45,234.43,15,105,1,2,233.4,234.5,110,63,2,4,233.39,234.75,10,1,1,1,AAPL,-171,-5.0828025477707,0.0656106019458349
2024-10-21T12:24:40.379975554Z,2024-10-21T12:24:40.379809120Z,10,2,38,C,A,0,233.98,27,130,166434,13031919,233.8,234.0,105,2,2,1,233.71,234.1,200,100,1,1,233.7,234.13,1200,400,1,1,233.66,234.17,31,1,2,1,233.58,234.25,505,100,2,1,233.53,234.41,10,500,1,1,233.5,234.43,100,105,1,2,233.45,234.5,15,63,1,4,233.4,234.75,110,1,2,1,233.39,234.79,10,2000,1,1,AAPL,1829,23.510371019573473,-0.303480133266376
2024-10-21T12:24:40.416037866Z,2024-10-21T12:24:40.415871461Z,10,2,38,A,A,1,234.02,200,130,166405,13031935,233.8,234.0,105,2,2,1,233.71,234.02,200,200,1,1,233.7,234.1,1200,100,1,1,233.66,234.13,31,400,2,1,233.58,234.17,505,1,2,1,233.53,234.25,10,100,1,1,233.5,234.41,100,500,1,1,233.45,234.43,15,105,1,2,233.4,234.5,110,63,2,4,233.39,234.75,10,1,1,1,AAPL,1828,24.486895748398368,-0.3160854577248868
2024-10-21T12:24:40.464995283Z,2024-10-21T12:24:40.464828695Z,10,2,38,A,A,1,234.02,200,130,166588,13031977,233.8,234.0,105,2,2,1,233.71,234.02,200,400,1,2,233.7,234.1,1200,100,1,1,233.66,234.13,31,400,2,1,233.58,234.17,505,1,2,1,233.53,234.25,10,100,1,1,233.5,234.41,100,500,1,1,233.45,234.43,15,105,1,2,233.4,234.5,110,63,2,4,233.39,234.75,10,1,1,1,AAPL,1828,25.469956458635707,-0.32877515092893633
2024-10-21T12:24:40.657004232Z,2024-10-21T12:24:40.656837789Z,10,2,38,C,B,1,233.71,200,130,166443,13032132,233.8,234.0,105,2,2,1,233.7,234.02,1200,400,1,2,233.66,234.1,31,100,2,1,233.58,234.13,505,400,2,1,233.53,234.17,10,1,1,1,233.5,234.25,100,100,1,1,233.45,234.41,15,500,1,1,233.4,234.43,110,105,2,2,233.39,234.5,10,63,1,4,233.31,234.75,110,1,2,1,AAPL,1718,24.156355455568054,-0.311818727436601
2024-10-21T12:24:40.763757375Z,2024-10-21T12:24:40.763590881Z,10,2,38,A,B,1,233.71,200,130,166494,13032319,233.8,234.0,105,2,2,1,233.71,234.02,200,400,1,2,233.7,234.1,1200,100,1,1,233.66,234.13,31,400,2,1,233.58,234.17,505,1,2,1,233.53,234.25,10,100,1,1,233.5,234.41,100,500,1,1,233.45,234.43,15,105,1,2,233.4,234.5,110,63,2,4,233.39,234.75,10,1,1,1,AAPL,1728,25.190916736753575,-0.3251732081134487
2024-10-21T12:24:43.066523534Z,2024-10-21T12:24:43.066357159Z,10,2,38,A,B,0,233.88,1,130,166375,13033852,233.88,234.0,1,2,1,1,233.8,234.02,105,400,2,2,233.71,234.1,200,100,1,1,233.7,234.13,1200,400,1,1,233.66,234.17,31,1,2,1,233.58,234.25,505,100,2,1,233.53,234.41,10,500,1,1,233.5,234.43,100,105,1,2,233.45,234.5,15,63,1,4,233.4,234.75,110,1,2,1,AAPL,1838,26.985318107667208,-0.3483359717603883
2024-10-21T12:24:43.129607008Z,2024-10-21T12:24:43.129440388Z,10,2,38,A,A,2,234.09,27,130,166620,13033910,233.88,234.0,1,2,1,1,233.8,234.02,105,400,2,2,233.71,234.09,200,27,1,1,233.7,234.1,1200,100,1,1,233.66,234.13,31,400,2,1,233.58,234.17,505,1,2,1,233.53,234.25,10,100,1,1,233.5,234.41,100,500,1,1,233.45,234.43,15,105,1,2,233.4,234.5,110,63,2,4,AAPL,1775,25.81147753830174,-0.3331836250735611
2024-10-21T12:24:55.150110202Z,2024-10-21T12:24:55.149943017Z,10,2,38,T,A,0,233.88,1,130,167185,13042533,233.88,234.0,1,2,1,1,233.8,234.02,105,400,2,2,233.71,234.09,200,27,1,1,233.7,234.1,1200,100,1,1,233.66,234.13,31,400,2,1,233.58,234.17,505,1,2,1,233.53,234.25,10,100,1,1,233.5,234.41,100,500,1,1,233.45,234.43,15,105,1,2,233.4,234.5,110,63,2,4,AAPL,2023,23.038503253796094,-0.29738909827917814
2024-10-21T12:24:55.150110202Z,2024-10-21T12:24:55.149943017Z,10,2,38,C,B,0,233.88,1,130,167185,13042533,233.8,234.0,105,2,2,1,233.71,234.02,200,400,1,2,233.7,234.09,1200,27,1,1,233.66,234.1,31,100,2,1,233.58,234.13,505,400,2,1,233.53,234.17,10,1,1,1,233.5,234.25,100,100,1,1,233.45,234.41,15,500,1,1,233.4,234.43,110,105,2,2,233.39,234.5,10,63,1,4,AAPL,2013,23.55011964902951,-0.3039932225474611
2024-10-21T12:24:55.150138721Z,2024-10-21T12:24:55.149972348Z,10,2,38,A,A,0,233.94,38,130,166373,13042534,233.8,233.94,105,38,2,1,233.71,234.0,200,2,1,1,233.7,234.02,1200,400,1,2,233.66,234.09,31,27,2,1,233.58,234.1,505,100,2,1,233.53,234.13,10,400,1,1,233.5,234.17,100,1,1,1,233.45,234.25,15,100,1,1,233.4,234.41,110,500,2,1,233.39,234.43,10,105,1,2,AAPL,1908,22.643962848297214,-0.2922962320398455
2024-10-21T12:24:55.150156298Z,2024-10-21T12:24:55.149990092Z,10,2,38,A,A,0,233.94,26,130,166206,13042535,233.8,233.94,105,64,2,2,233.71,234.0,200,2,1,1,233.7,234.02,1200,400,1,2,233.66,234.09,31,27,2,1,233.58,234.1,505,100,2,1,233.53,234.13,10,400,1,1,233.5,234.17,100,1,1,1,233.45,234.25,15,100,1,1,233.4,234.41,110,500,2,1,233.39,234.43,10,105,1,2,AAPL,1908,22.947632172387873,-0.2962161024182082
2024-10-21T12:24:55.150170265Z,2024-10-21T12:24:55.150004189Z,10,2,38,A,A,1,233.98,26,130,166076,13042536,233.8,233.94,105,64,2,2,233.71,233.98,200,26,1,1,233.7,234.0,1200,2,1,1,233.66,234.02,31,400,2,2,233.58,234.09,505,27,2,1,233.53,234.1,10,100,1,1,233.5,234.13,100,400,1,1,233.45,234.17,15,1,1,1,233.4,234.25,110,100,2,1,233.39,234.41,10,500,1,1,AAPL,1408,15.640968673628084,-0.20189912160620505
2024-10-21T12:24:55.250218188Z,2024-10-21T12:24:55.250051974Z,10,2,38,C,A,0,233.94,38,130,166214,13042633,233.8,233.94,105,26,2,1,233.71,233.98,200,26,1,1,233.7,234.0,1200,2,1,1,233.66,234.02,31,400,2,2,233.58,234.09,505,27,2,1,233.53,234.1,10,100,1,1,233.5,234.13,100,400,1,1,233.45,234.17,15,1,1,1,233.4,234.25,110,100,2,1,233.39,234.41,10,500,1,1,AAPL,1408,14.61105567750948,-0.1886046426269228
2024-10-21T12:24:55.250245636Z,2024-10-21T12:24:55.250079517Z,10,2,38,C,A,1,233.98,26,130,166119,13042634,233.8,233.94,105,26,2,1,233.71,234.0,200,2,1,1,233.7,234.02,1200,400,1,2,233.66,234.09,31,27,2,1,233.58,234.1,505,100,2,1,233.53,234.13,10,400,1,1,233.5,234.17,100,1,1,1,233.45,234.25,15,100,1,1,233.4,234.41,110,500,2,1,233.39,234.43,10,105,1,2,AAPL,1513,15.938743659773703,-0.20574290579845067
2024-10-21T12:24:55.403930872Z,2024-10-21T12:24:55.403764807Z,10,2,38,C,A,0,233.94,26,130,166065,13042985,233.8,234.0,105,2,2,1,233.71,234.02,200,400,1,2,233.7,234.09,1200,27,1,1,233.66,234.1,31,100,2,1,233.58,234.13,505,400,2,1,233.53,234.17,10,1,1,1,233.5,234.25,100,100,1,1,233.45,234.41,15,500,1,1,233.4,234.43,110,105,2,2,233.39,234.5,10,63,1,4,AAPL,1576,16.975572225427968,-0.21912665338019555
2024-10-21T12:24:58.867150506Z,2024-10-21T12:24:58.866984470Z,10,2,38,A,A,0,233.95,200,130,166036,13044827,233.8,233.95,105,200,2,1,233.71,234.0,200,2,1,1,233.7,234.02,1200,400,1,2,233.66,234.09,31,27,2,1,233.58,234.1,505,100,2,1,233.53,234.13,10,400,1,1,233.5,234.17,100,1,1,1,233.45,234.25,15,100,1,1,233.4,234.41,110,500,2,1,233.39,234.43,10,105,1,2,AAPL,1533,15.8282982791587,-0.20431723800274504
2024-10-21T12:25:00.039367879Z,2024-10-21T12:25:00.039201756Z,10,2,38,C,A,3,234.09,27,130,166123,13045779,233.8,233.95,105,200,2,1,233.71,234.0,200,2,1,1,233.7,234.02,1200,400,1,2,233.66,234.1,31,100,2,1,233.58,234.13,505,400,2,1,233.53,234.17,10,1,1,1,233.5,234.25,100,100,1,1,233.45,234.41,15,500,1,1,233.4,234.43,110,105,2,2,233.39,234.5,10,63,1,4,AAPL,1596,16.85385630775033,-0.21755550153037168
2024-10-21T12:25:00.039422307Z,2024-10-21T12:25:00.039255807Z,10,2,38,C,B,3,233.66,30,130,166500,13045782,233.8,233.95,105,200,2,1,233.71,234.0,200,2,1,1,233.7,234.02,1200,400,1,2,233.66,234.1,1,100,1,1,233.58,234.13,505,400,2,1,233.53,234.17,10,1,1,1,233.5,234.25,100,100,1,1,233.45,234.41,15,500,1,1,233.4,234.43,110,105,2,2,233.39,234.5,10,63,1,4,AAPL,1596,17.21875,-0.2222656775739482
2024-10-21T12:25:00.940467712Z,2024-10-21T12:25:00.940301280Z,10,2,38,A,B,0,233.81,1,130,166432,13048050,233.81,233.95,1,200,1,1,233.8,234.0,105,2,2,1,233.71,234.02,200,400,1,2,233.7,234.1,1200,100,1,1,233.66,234.13,1,400,1,1,233.58,234.17,505,1,2,1,233.53,234.25,10,100,1,1,233.5,234.41,100,500,1,1,233.45,234.43,15,105,1,2,233.4,234.5,110,63,2,4,AAPL,-332,-3.870108243130724,0.0499567175865828
2024-10-21T12:25:03.426126208Z,2024-10-21T12:25:03.425959742Z,10,2,38,A,A,1,233.97,7,130,166466,13052492,233.81,233.95,1,200,1,1,233.8,233.97,105,7,2,1,233.71,234.0,200,2,1,1,233.7,234.02,1200,400,1,2,233.66,234.1,1,100,1,1,233.58,234.13,505,400,2,1,233.53,234.17,10,1,1,1,233.5,234.25,100,100,1,1,233.45,234.41,15,500,1,1,233.4,234.43,110,105,2,2,AAPL,-484,-5.393913416202315,0.06962653039433274
2024-10-21T12:25:07.929188046Z,2024-10-21T12:25:07.929021771Z,10,2,38,C,A,3,234.02,200,130,166275,13057385,233.81,233.95,1,200,1,1,233.8,233.97,105,7,2,1,233.71,234.0,200,2,1,1,233.7,234.02,1200,200,1,1,233.66,234.1,1,100,1,1,233.58,234.13,505,400,2,1,233.53,234.17,10,1,1,1,233.5,234.25,100,100,1,1,233.45,234.41,15,500,1,1,233.4,234.43,110,105,2,2,AAPL,-484,-5.318681318681318,0.06865540803464848
2024-10-21T12:25:07.929203389Z,2024-10-21T12:25:07.929036599Z,10,2,38,A,A,3,234.01,400,130,166790,13057386,233.81,233.95,1,200,1,1,233.8,233.97,105,7,2,1,233.71,234.0,200,2,1,1,233.7,234.01,1200,400,1,1,233.66,234.1,1,100,1,1,233.58,234.13,505,400,2,1,233.53,234.17,10,1,1,1,233.5,234.25,100,100,1,1,233.45,234.41,15,500,1,1,233.4,234.43,110,105,2,2,AAPL,-484,-5.255157437567862,0.06783541944791545
2024-10-21T12:25:08.719128994Z,2024-10-21T12:25:08.718962947Z,10,2,38,C,A,1,233.97,7,130,166047,13057965,233.81,233.95,1,200,1,1,233.8,234.0,105,2,2,1,233.71,234.01,200,400,1,1,233.7,234.1,1200,100,1,1,233.66,234.13,1,400,1,1,233.58,234.17,505,1,2,1,233.53,234.25,10,100,1,1,233.5,234.41,100,500,1,1,233.45,234.43,15,105,1,2,233.4,234.5,110,63,2,4,AAPL,-421,-4.5885558583106265,0.05923069194531082
2024-10-21T12:25:08.828580021Z,2024-10-21T12:25:08.828413687Z,10,2,38,A,B,0,233.85,100,130,166334,13058052,233.85,233.95,100,200,1,1,233.81,234.0,1,2,1,1,233.8,234.01,105,400,2,1,233.71,234.1,200,100,1,1,233.7,234.13,1200,400,1,1,233.66,234.17,1,1,1,1,233.58,234.25,505,100,2,1,233.53,234.41,10,500,1,1,233.5,234.43,100,105,1,2,233.45,234.5,15,63,1,4,AAPL,-406,-4.579960185799602,0.05911973598306812
2024-10-21T12:25:09.010032581Z,2024-10-21T12:25:09.009866477Z,10,2,38,C,B,3,233.71,200,130,166104,13058226,233.85,233.95,100,200,1,1,233.81,234.0,1,2,1,1,233.8,234.01,105,400,2,1,233.7,234.1,1200,100,1,1,233.66,234.13,1,400,1,1,233.58,234.17,505,1,2,1,233.53,234.25,10,100,1,1,233.5,234.41,100,500,1,1,233.45,234.43,15,105,1,2,233.4,234.5,110,63,2,4,AAPL,-516,-5.8286790084719176,0.07523863748408328
2024-10-21T12:25:09.010056790Z,2024-10-21T12:25:09.009890544Z,10,2,38,A,B,4,233.69,200,130,166246,13058227,233.85,233.95,100,200,1,1,233.81,234.0,1,2,1,1,233.8,234.01,105,400,2,1,233.7,234.1,1200,100,1,1,233.69,234.13,200,400,1,1,233.66,234.17,1,1,1,1,233.58,234.25,505,100,2,1,233.53,234.41,10,500,1,1,233.5,234.43,100,105,1,2,233.45,234.5,15,63,1,4,AAPL,-501,-5.83093415007657,0.07526774764462242
2024-10-21T12:25:09.088943398Z,2024-10-21T12:25:09.088777165Z,10,2,38,A,B,4,233.69,200,130,166233,13058312,233.85,233.95,100,200,1,1,233.81,234.0,1,2,1,1,233.8,234.01,105,400,2,1,233.7,234.1,1200,100,1,1,233.69,234.13,400,400,2,1,233.66,234.17,1,1,1,1,233.58,234.25,505,100,2,1,233.53,234.41,10,500,1,1,233.5,234.43,100,105,1,2,233.45,234.5,15,63,1,4,AAPL,-501,-5.994615614717319,0.0773806055259827
2024-10-21T12:25:09.146843023Z,2024-10-21T12:25:09.146677151Z,10,2,38,C,B,4,233.69,200,130,165872,13058371,233.85,233.95,100,200,1,1,233.81,234.0,1,2,1,1,233.8,234.01,105,400,2,1,233.7,234.1,1200,100,1,1,233.69,234.13,200,400,1,1,233.66,234.17,1,1,1,1,233.58,234.25,505,100,2,1,233.53,234.41,10,500,1,1,233.5,234.43,100,105,1,2,233.45,234.5,15,63,1,4,AAPL,-501,-6.150833089739843,0.07939711560567912
2024-10-21T12:25:09.146855993Z,2024-10-21T12:25:09.146689798Z,10,2,38,A,B,3,233.72,400,130,166195,13058372,233.85,233.95,100,200,1,1,233.81,234.0,1,2,1,1,233.8,234.01,105,400,2,1,233.72,234.1,400,100,1,1,233.7,234.13,1200,400,1,1,233.66,234.17,1,1,1,1,233.58,234.25,505,100,2,1,233.53,234.41,10,500,1,1,233.5,234.43,100,105,1,2,233.45,234.5,15,63,1,4,AAPL,-501,-6.30008573878251,0.08132372126341705
2024-10-21T12:25:09.325402278Z,2024-10-21T12:25:09.325236301Z,10,2,38,C,B,3,233.72,400,130,165977,13058695,233.85,233.95,100,200,1,1,233.81,234.0,1,2,1,1,233.8,234.01,105,400,2,1,233.7,234.1,1200,100,1,1,233.66,234.13,1,400,1,1,233.58,234.17,505,1,2,1,233.53,234.25,10,100,1,1,233.5,234.41,100,500,1,1,233.45,234.43,15,105,1,2,233.4,234.5,110,63,2,4,AAPL,-611,-7.654139433551198,0.09880232231978123
2024-10-21T12:25:09.325415366Z,2024-10-21T12:25:09.325248668Z,10,2,38,A,B,4,233.69,200,130,166698,13058696,233.85,233.95,100,200,1,1,233.81,234.0,1,2,1,1,233.8,234.01,105,400,2,1,233.7,234.1,1200,100,1,1,233.69,234.13,200,400,1,1,233.66,234.17,1,1,1,1,233.58,234.25,505,100,2,1,233.53,234.41,10,500,1,1,233.5,234.43,100,105,1,2,233.45,234.5,15,63,1,4,AAPL,-596,-7.6288,0.09847523200442168
2024-10-21T12:25:09.630196737Z,2024-10-21T12:25:09.630030450Z,10,2,38,A,B,4,233.69,200,130,166287,13059010,233.85,233.95,100,200,1,1,233.81,234.0,1,2,1,1,233.8,234.01,105,400,2,1,233.7,234.1,1200,100,1,1,233.69,234.13,400,400,2,1,233.66,234.17,1,1,1,1,233.58,234.25,505,100,2,1,233.53,234.41,10,500,1,1,233.5,234.43,100,105,1,2,233.45,234.5,15,63,1,4,AAPL,-596,-7.784743991640543,0.10048821186449115
2024-10-21T12:25:09.684458949Z,2024-10-21T12:25:09.684292780Z,10,2,38,C,B,4,233.69,200,130,166169,13059061,233.85,233.95,100,200,1,1,233.81,234.0,1,2,1,1,233.8,234.01,105,400,2,1,233.7,234.1,1200,100,1,1,233.69,234.13,200,400,1,1,233.66,234.17,1,1,1,1,233.58,234.25,505,100,2,1,233.53,234.41,10,500,1,1,233.5,234.43,100,105,1,2,233.45,234.5,15,63,1,4,AAPL,-596,-7.934459805427547,0.10242079621555633
2024-10-21T12:25:09.684472400Z,2024-10-21T12:25:09.684305729Z,10,2,38,A,B,3,233.72,400,130,166671,13059062,233.85,233.95,100,200,1,1,233.81,234.0,1,2,1,1,233.8,234.01,105,400,2,1,233.72,234.1,400,100,1,1,233.7,234.13,1200,400,1,1,233.66,234.17,1,1,1,1,233.58,234.25,505,100,2,1,233.53,234.41,10,500,1,1,233.5,234.43,100,105,1,2,233.45,234.5,15,63,1,4,AAPL,-596,-8.078313253012048,0.10427770708299548
2024-10-21T12:25:10.726294001Z,2024-10-21T12:25:10.726127491Z,10,2,38,A,A,1,233.98,7,130,166510,13060271,233.85,233.95,100,200,1,1,233.81,233.98,1,7,1,1,233.8,234.0,105,2,2,1,233.72,234.01,400,400,1,1,233.7,234.1,1200,100,1,1,233.66,234.13,1,400,1,1,233.58,234.17,505,1,2,1,233.53,234.25,10,100,1,1,233.5,234.41,100,500,1,1,233.45,234.43,15,105,1,2,AAPL,-701,-9.565302144249513,0.12347228238351549
2024-10-21T12:25:16.348450351Z,2024-10-21T12:25:16.348283664Z,10,2,38,A,B,3,233.77,200,130,166687,13064852,233.85,233.95,100,200,1,1,233.81,233.98,1,7,1,1,233.8,234.0,105,2,2,1,233.77,234.01,200,400,1,1,233.7,234.1,1200,100,1,1,233.66,234.13,1,400,1,1,233.58,234.17,505,1,2,1,233.53,234.25,10,100,1,1,233.5,234.41,100,500,1,1,233.45,234.43,15,105,1,2,AAPL,-254,-4.2,0.054215076344716215
2024-10-21T12:25:25.279574162Z,2024-10-21T12:25:25.279408267Z,10,2,38,C,B,3,233.77,200,130,165895,13072236,233.85,233.95,100,200,1,1,233.81,233.98,1,7,1,1,233.8,234.0,105,2,2,1,233.7,234.01,1200,400,1,1,233.66,234.1,1,100,1,1,233.58,234.13,505,400,2,1,233.53,234.17,10,1,1,1,233.5,234.25,100,100,1,1,233.45,234.41,15,500,1,1,233.4,234.43,110,105,2,2,AAPL,-327,-5.27920227920228,0.06814579871575034
2024-10-21T12:25:25.279586508Z,2024-10-21T12:25:25.279420038Z,10,2,38,A,B,3,233.75,200,130,166470,13072237,233.85,233.95,100,200,1,1,233.81,233.98,1,7,1,1,233.8,234.0,105,2,2,1,233.75,234.01,200,400,1,1,233.7,234.1,1200,100,1,1,233.66,234.13,1,400,1,1,233.58,234.17,505,1,2,1,233.53,234.25,10,100,1,1,233.5,234.41,100,500,1,1,233.45,234.43,15,105,1,2,AAPL,-312,-5.045822102425876,0.06513324535830366
2024-10-21T12:25:25.341710080Z,2024-10-21T12:25:25.341543400Z,10,2,38,A,A,2,234.0,400,130,166680,13072382,233.85,233.95,100,200,1,1,233.81,233.98,1,7,1,1,233.8,234.0,105,402,2,2,233.75,234.1,200,100,1,1,233.7,234.13,1200,400,1,1,233.66,234.17,1,1,1,1,233.58,234.25,505,100,2,1,233.53,234.41,10,500,1,1,233.5,234.43,100,105,1,2,233.45,234.5,15,63,1,4,AAPL,-249,-4.106770833333334,0.05301164149033823
2024-10-21T12:25:26.789385215Z,2024-10-21T12:25:26.789218710Z,10,2,38,A,A,2,233.99,400,130,166505,13074488,233.85,233.95,100,200,1,1,233.81,233.98,1,7,1,1,233.8,233.99,105,400,2,1,233.75,234.0,200,2,1,1,233.7,234.1,1200,100,1,1,233.66,234.13,1,400,1,1,233.58,234.17,505,1,2,1,233.53,234.25,10,100,1,1,233.5,234.41,100,500,1,1,233.45,234.43,15,105,1,2,AAPL,-354,-5.841584158415841,0.07540522169585706
2024-10-21T12:25:34.806070616Z,2024-10-21T12:25:34.805904261Z,10,2,38,A,B,0,233.86,4,130,166355,13082761,233.86,233.95,4,200,1,1,233.85,233.98,100,7,1,1,233.81,233.99,1,400,1,1,233.8,234.0,105,2,2,1,233.75,234.1,200,100,1,1,233.7,234.13,1200,400,1,1,233.66,234.17,1,1,1,1,233.58,234.25,505,100,2,1,233.53,234.41,10,500,1,1,233.5,234.43,100,105,1,2,AAPL,-37,-0.5174825174825175,0.006679846236278721
2024-10-21T12:25:34.806829112Z,2024-10-21T12:25:34.806661445Z,10,2,38,C,B,0,233.86,4,130,167667,13082762,233.85,233.95,100,200,1,1,233.81,233.98,1,7,1,1,233.8,233.99,105,400,2,1,233.75,234.0,200,2,1,1,233.7,234.1,1200,100,1,1,233.66,234.13,1,400,1,1,233.58,234.17,505,1,2,1,233.53,234.25,10,100,1,1,233.5,234.41,100,500,1,1,233.45,234.43,15,105,1,2,AAPL,-52,-0.7443762781186094,0.009608670654141933
2024-10-21T12:25:34.807157514Z,2024-10-21T12:25:34.806990464Z,10,2,38,T,N,0,233.93,100,130,167050,13082763,233.85,233.95,100,200,1,1,233.81,233.98,1,7,1,1,233.8,233.99,105,400,2,1,233.75,234.0,200,2,1,1,233.7,234.1,1200,100,1,1,233.66,234.13,1,400,1,1,233.58,234.17,505,1,2,1,233.53,234.25,10,100,1,1,233.5,234.41,100,500,1,1,233.45,234.43,15,105,1,2,AAPL,-52,-0.7577413479052824,0.009781191672912632
2024-10-21T12:25:35.054650784Z,2024-10-21T12:25:35.054480586Z,10,2,38,T,N,0,233.91,101,0,170198,13083003,233.85,233.95,100,200,1,1,233.81,233.98,1,7,1,1,233.8,233.99,105,400,2,1,233.75,234.0,200,2,1,1,233.7,234.1,1200,100,1,1,233.66,234.13,1,400,1,1,233.58,234.17,505,1,2,1,233.53,234.25,10,100,1,1,233.5,234.41,100,500,1,1,233.45,234.43,15,105,1,2,AAPL,-52,-0.7684729064039408,0.009919718402270385
2024-10-21T12:25:35.054650784Z,2024-10-21T12:25:35.054480586Z,10,2,38,T,N,0,233.93,50,0,170198,13083004,233.85,233.95,100,200,1,1,233.81,233.98,1,7,1,1,233.8,233.99,105,400,2,1,233.75,234.0,200,2,1,1,233.7,234.1,1200,100,1,1,233.66,234.13,1,400,1,1,233.58,234.17,505,1,2,1,233.53,234.25,10,100,1,1,233.5,234.41,100,500,1,1,233.45,234.43,15,105,1,2,AAPL,-52,-0.7772795216741405,0.01003339728779715
2024-10-21T12:25:35.054650784Z,2024-10-21T12:25:35.054480586Z,10,2,38,T,B,0,233.95,79,130,170198,13083005,233.85,233.95,100,200,1,1,233.81,233.98,1,7,1,1,233.8,233.99,105,400,2,1,233.75,234.0,200,2,1,1,233.7,234.1,1200,100,1,1,233.66,234.13,1,400,1,1,233.58,234.17,505,1,2,1,233.53,234.25,10,100,1,1,233.5,234.41,100,500,1,1,233.45,234.43,15,105,1,2,AAPL,-52,-0.7846364883401922,0.010128363599574655
2024-10-21T12:25:35.054650784Z,2024-10-21T12:25:35.054480586Z,10,2,38,C,A,0,233.95,79,130,170198,13083005,233.85,233.95,100,121,1,1,233.81,233.98,1,7,1,1,233.8,233.99,105,400,2,1,233.75,234.0,200,2,1,1,233.7,234.1,1200,100,1,1,233.66,234.13,1,400,1,1,233.58,234.17,505,1,2,1,233.53,234.25,10,100,1,1,233.5,234.41,100,500,1,1,233.45,234.43,15,105,1,2,AAPL,-52,-0.7908745247148289,0.010208886365834667
2024-10-21T12:25:35.054724289Z,2024-10-21T12:25:35.054558163Z,10,2,38,C,A,2,233.99,400,130,166126,13083006,233.85,233.95,100,121,1,1,233.81,233.98,1,7,1,1,233.8,234.0,105,2,2,1,233.75,234.1,200,100,1,1,233.7,234.13,1200,400,1,1,233.66,234.17,1,1,1,1,233.58,234.25,505,100,2,1,233.53,234.41,10,500,1,1,233.5,234.43,100,105,1,2,233.45,234.5,15,63,1,4,AAPL,11,0.17270531400966183,-0.002229340900993334
2024-10-21T12:25:35.065068431Z,2024-10-21T12:25:35.064902310Z,10,2,38,A,A,2,234.0,200,130,166121,13083015,233.85,233.95,100,121,1,1,233.81,233.98,1,7,1,1,233.8,234.0,105,202,2,2,233.75,234.1,200,100,1,1,233.7,234.13,1200,400,1,1,233.66,234.17,1,1,1,1,233.58,234.25,505,100,2,1,233.53,234.41,10,500,1,1,233.5,234.43,100,105,1,2,233.45,234.5,15,63,1,4,AAPL,11,0.17762399077277968,-0.002292832909618909
2024-10-21T12:25:35.147837274Z,2024-10-21T12:25:35.147671307Z,10,2,38,A,A,2,234.0,200,130,165967,13083092,233.85,233.95,100,121,1,1,233.81,233.98,1,7,1,1,233.8,234.0,105,402,2,3,233.75,234.1,200,100,1,1,233.7,234.13,1200,400,1,1,233.66,234.17,1,1,1,1,233.58,234.25,505,100,2,1,233.53,234.41,10,500,1,1,233.5,234.43,100,105,1,2,233.45,234.5,15,63,1,4,AAPL,11,0.18211920529801326,-0.002350858718826389
2024-10-21T12:25:37.149278847Z,2024-10-21T12:25:37.149112390Z,10,2,38,C,A,1,233.98,7,130,166457,13084951,233.85,233.95,100,121,1,1,233.81,234.0,1,402,1,3,233.8,234.1,105,100,2,1,233.75,234.13,200,400,1,1,233.7,234.17,1200,1,1,1,233.66,234.25,1,100,1,1,233.58,234.41,505,500,2,1,233.53,234.43,10,105,1,2,233.5,234.5,100,63,1,4,233.45,234.59,15,60,1,1,AAPL,71,1.2054329371816639,-0.01556015207565224
2024-10-21T12:25:39.151956133Z,2024-10-21T12:25:39.151789847Z,10,2,38,A,A,8,234.44,7,130,166286,13087130,233.85,233.95,100,121,1,1,233.81,234.0,1,402,1,3,233.8,234.1,105,100,2,1,233.75,234.13,200,400,1,1,233.7,234.17,1200,1,1,1,233.66,234.25,1,100,1,1,233.58,234.41,505,500,2,1,233.53,234.43,10,105,1,2,233.5,234.44,100,7,1,1,233.45,234.5,15,63,1,4,AAPL,8,0.13875338753387534,-0.0017910774995802492
2024-10-21T12:25:43.597553367Z,2024-10-21T12:25:43.597387033Z,10,2,38,A,B,3,233.76,200,130,166334,13091002,233.85,233.95,100,121,1,1,233.81,234.0,1,402,1,3,233.8,234.1,105,100,2,1,233.76,234.13,200,400,1,1,233.7,234.17,1200,1,1,1,233.66,234.25,1,100,1,1,233.58,234.41,505,500,2,1,233.53,234.43,10,105,1,2,233.5,234.44,100,7,1,1,233.45,234.5,15,63,1,4,AAPL,8,0.14144565782631305,-0.0018258302708767068
2024-10-21T12:25:45.063614991Z,2024-10-21T12:25:45.063448661Z,10,2,38,A,B,3,233.77,200,130,166330,13092718,233.85,233.95,100,121,1,1,233.81,234.0,1,402,1,3,233.8,234.1,105,100,2,1,233.77,234.13,200,400,1,1,233.7,234.17,1200,1,1,1,233.66,234.25,1,100,1,1,233.58,234.41,505,500,2,1,233.53,234.43,10,105,1,2,233.5,234.44,100,7,1,1,233.45,234.5,15,63,1,4,AAPL,8,0.14392803598200898,-0.0018578736806927807
2024-10-21T12:25:52.757457183Z,2024-10-21T12:25:52.757291105Z,10,2,38,C,B,3,233.77,200,130,166078,13098338,233.85,233.95,100,121,1,1,233.81,234.0,1,402,1,3,233.8,234.1,105,100,2,1,233.7,234.13,1200,400,1,1,233.66,234.17,1,1,1,1,233.58,234.25,505,100,2,1,233.53,234.41,10,500,1,1,233.5,234.43,100,105,1,2,233.45,234.44,15,7,1,1,233.4,234.5,110,63,2,4,AAPL,35,0.639853747714808,-0.008259457090907406
2024-10-21T12:25:52.757470818Z,2024-10-21T12:25:52.757304269Z,10,2,38,A,B,3,233.75,200,130,166549,13098339,233.85,233.95,100,121,1,1,233.81,234.0,1,402,1,3,233.8,234.1,105,100,2,1,233.75,234.13,200,400,1,1,233.7,234.17,1200,1,1,1,233.66,234.25,1,100,1,1,233.58,234.41,505,500,2,1,233.53,234.43,10,105,1,2,233.5,234.44,100,7,1,1,233.45,234.5,15,63,1,4,AAPL,50,0.9307737056428156,-0.012014754169304684
2024-10-21T12:25:54.873403967Z,2024-10-21T12:25:54.873237392Z,10,2,38,A,B,1,233.81,1,130,166575,13100599,233.85,233.95,100,121,1,1,233.81,234.0,2,402,2,3,233.8,234.1,105,100,2,1,233.75,234.13,200,400,1,1,233.7,234.17,1200,1,1,1,233.66,234.25,1,100,1,1,233.58,234.41,505,500,2,1,233.53,234.43,10,105,1,2,233.5,234.44,100,7,1,1,233.45,234.5,15,63,1,4,AAPL,-35,-0.7248520710059172,0.009356645325764633
2024-10-21T12:26:00.405862083Z,2024-10-21T12:26:00.405695962Z,10,2,38,C,A,8,234.44,7,130,166121,13106337,233.85,233.95,100,121,1,1,233.81,234.0,2,402,2,3,233.8,234.1,105,100,2,1,233.75,234.13,200,400,1,1,233.7,234.17,1200,1,1,1,233.66,234.25,1,100,1,1,233.58,234.41,505,500,2,1,233.53,234.43,10,105,1,2,233.5,234.5,100,63,1,4,233.45,234.59,15,60,1,1,AAPL,-35,-0.75,0.009681263632985038
2024-10-21T12:26:01.715446829Z,2024-10-21T12:26:01.715279752Z,10,2,38,A,B,3,233.76,200,130,167077,13108880,233.85,233.95,100,121,1,1,233.81,234.0,2,402,2,3,233.8,234.1,105,100,2,1,233.76,234.13,200,400,1,1,233.7,234.17,1200,1,1,1,233.66,234.25,1,100,1,1,233.58,234.41,505,500,2,1,233.53,234.43,10,105,1,2,233.5,234.5,100,63,1,4,233.45,234.59,15,60,1,1,AAPL,-35,-0.7716535433070867,0.009960775181443926
2024-10-21T12:26:02.222090992Z,2024-10-21T12:26:02.221924482Z,10,2,38,A,B,3,233.77,200,130,166510,13109908,233.85,233.95,100,121,1,1,233.81,234.0,2,402,2,3,233.8,234.1,105,100,2,1,233.77,234.13,200,400,1,1,233.7,234.17,1200,1,1,1,233.66,234.25,1,100,1,1,233.58,234.41,505,500,2,1,233.53,234.43,10,105,1,2,233.5,234.5,100,63,1,4,233.45,234.59,15,60,1,1,AAPL,-35,-0.7887323943661971,0.010181234994312904
2024-10-21T12:26:02.408702630Z,2024-10-21T12:26:02.408536304Z,10,2,38,A,A,2,234.07,7,130,166326,13110618,233.85,233.95,100,121,1,1,233.81,234.0,2,402,2,3,233.8,234.07,105,7,2,1,233.77,234.1,200,100,1,1,233.7,234.13,1200,400,1,1,233.66,234.17,1,1,1,1,233.58,234.25,505,100,2,1,233.53,234.41,10,500,1,1,233.5,234.43,100,105,1,2,233.45,234.5,15,63,1,4,AAPL,-98,-2.238578680203046,0.028896360488300524
2024-10-21T12:26:05.174048295Z,2024-10-21T12:26:05.173881544Z,10,2,38,A,B,0,233.86,100,130,166751,13112718,233.86,233.95,100,121,1,1,233.85,234.0,100,402,1,3,233.81,234.07,2,7,2,1,233.8,234.1,105,100,2,1,233.77,234.13,200,400,1,1,233.7,234.17,1200,1,1,1,233.66,234.25,1,100,1,1,233.58,234.41,505,500,2,1,233.53,234.43,10,105,1,2,233.5,234.5,100,63,1,4,AAPL,2,0.04025157232704402,-0.0005195814444537044
2024-10-21T12:26:05.247381714Z,2024-10-21T12:26:05.247215441Z,10,2,38,C,A,1,234.0,200,130,166273,13112835,233.86,233.95,100,121,1,1,233.85,234.0,100,202,1,2,233.81,234.07,2,7,2,1,233.8,234.1,105,100,2,1,233.77,234.13,200,400,1,1,233.7,234.17,1200,1,1,1,233.66,234.25,1,100,1,1,233.58,234.41,505,500,2,1,233.53,234.43,10,105,1,2,233.5,234.5,100,63,1,4,AAPL,2,0.037578288100208766,-0.0004850737519658474
2024-10-21T12:26:05.247392056Z,2024-10-21T12:26:05.247226039Z,10,2,38,C,A,1,234.0,200,130,166017,13112836,233.86,233.95,100,121,1,1,233.85,234.0,100,2,1,1,233.81,234.07,2,7,2,1,233.8,234.1,105,100,2,1,233.77,234.13,200,400,1,1,233.7,234.17,1200,1,1,1,233.66,234.25,1,100,1,1,233.58,234.41,505,500,2,1,233.53,234.43,10,105,1,2,233.5,234.5,100,63,1,4,AAPL,2,0.03568242640499554,-0.00046060130278846454
2024-10-21T12:26:05.247404052Z,2024-10-21T12:26:05.247237168Z,10,2,38,A,A,2,234.01,200,130,166884,13112837,233.86,233.95,100,121,1,1,233.85,234.0,100,2,1,1,233.81,234.01,2,200,2,1,233.8,234.07,105,7,2,1,233.77,234.1,200,100,1,1,233.7,234.13,1200,400,1,1,233.66,234.17,1,1,1,1,233.58,234.25,505,100,2,1,233.53,234.41,10,500,1,1,233.5,234.43,100,105,1,2,AAPL,-103,-1.7088989441930618,0.02205906826781709
2024-10-21T12:26:08.272617784Z,2024-10-21T12:26:08.272451351Z,10,2,38,A,B,4,233.78,200,130,166433,13116250,233.86,233.95,100,121,1,1,233.85,234.0,100,2,1,1,233.81,234.01,2,200,2,1,233.8,234.07,105,7,2,1,233.78,234.1,200,100,1,1,233.7,234.13,1200,400,1,1,233.66,234.17,1,1,1,1,233.58,234.25,505,100,2,1,233.53,234.41,10,500,1,1,233.5,234.43,100,105,1,2,AAPL,-103,-1.6146309601567603,0.020842223993676478
2024-10-21T12:26:09.611069894Z,2024-10-21T12:26:09.610903498Z,10,2,38,C,B,1,233.85,100,130,166396,13117941,233.86,233.95,100,121,1,1,233.81,234.0,2,2,2,1,233.8,234.01,105,200,2,1,233.78,234.07,200,7,1,1,233.7,234.1,1200,100,1,1,233.66,234.13,1,400,1,1,233.58,234.17,505,1,2,1,233.53,234.25,10,100,1,1,233.5,234.41,100,500,1,1,233.45,234.43,15,105,1,2,AAPL,-118,-1.858267716535433,0.023987172885926184
2024-10-21T12:26:11.689942070Z,2024-10-21T12:26:11.689776041Z,10,2,38,C,A,2,234.01,200,130,166029,13119493,233.86,233.95,100,121,1,1,233.81,234.0,2,2,2,1,233.8,234.07,105,7,2,1,233.78,234.1,200,100,1,1,233.7,234.13,1200,400,1,1,233.66,234.17,1,1,1,1,233.58,234.25,505,100,2,1,233.53,234.41,10,500,1,1,233.5,234.43,100,105,1,2,233.45,234.5,15,63,1,4,AAPL,-55,-0.8906882591093117,0.011497317134988978
2024-10-21T12:26:11.689954364Z,2024-10-21T12:26:11.689788127Z,10,2,38,A,A,2,234.03,200,130,166237,13119494,233.86,233.95,100,121,1,1,233.81,234.0,2,2,2,1,233.8,234.03,105,200,2,1,233.78,234.07,200,7,1,1,233.7,234.1,1200,100,1,1,233.66,234.13,1,400,1,1,233.58,234.17,505,1,2,1,233.53,234.25,10,100,1,1,233.5,234.41,100,500,1,1,233.45,234.43,15,105,1,2,AAPL,-160,-2.5959978366684693,0.03351005259659504
2024-10-21T12:26:11.691953516Z,2024-10-21T12:26:11.691787041Z,10,2,38,A,A,2,234.03,200,130,166475,13119500,233.86,233.95,100,121,1,1,233.81,234.0,2,2,2,1,233.8,234.03,105,400,2,2,233.78,234.07,200,7,1,1,233.7,234.1,1200,100,1,1,233.66,234.13,1,400,1,1,233.58,234.17,505,1,2,1,233.53,234.25,10,100,1,1,233.5,234.41,100,500,1,1,233.45,234.43,15,105,1,2,AAPL,-160,-2.600304723209751,0.033565647401986386
2024-10-21T12:26:11.746463267Z,2024-10-21T12:26:11.746296162Z,10,2,38,C,A,2,234.03,200,130,167105,13119630,233.86,233.95,100,121,1,1,233.81,234.0,2,2,2,1,233.8,234.03,105,200,2,1,233.78,234.07,200,7,1,1,233.7,234.1,1200,100,1,1,233.66,234.13,1,400,1,1,233.58,234.17,505,1,2,1,233.53,234.25,10,100,1,1,233.5,234.41,100,500,1,1,233.45,234.43,15,105,1,2,AAPL,-160,-2.6041168022977503,0.03361485505884067
2024-10-21T12:26:11.746474261Z,2024-10-21T12:26:11.746308007Z,10,2,38,A,A,2,234.02,200,130,166254,13119632,233.86,233.95,100,121,1,1,233.81,234.0,2,2,2,1,233.8,234.02,105,200,2,1,233.78,234.07,200,7,1,1,233.7,234.1,1200,100,1,1,233.66,234.13,1,400,1,1,233.58,234.17,505,1,2,1,233.53,234.25,10,100,1,1,233.5,234.41,100,500,1,1,233.45,234.43,15,105,1,2,AAPL,-160,-2.6075147125396105,0.03365871647864423
2024-10-21T12:26:13.045453100Z,2024-10-21T12:26:13.045285946Z,10,2,38,A,B,3,233.79,200,130,167154,13120862,233.86,233.95,100,121,1,1,233.81,234.0,2,2,2,1,233.8,234.02,105,200,2,1,233.79,234.07,200,7,1,1,233.7,234.1,1200,100,1,1,233.66,234.13,1,400,1,1,233.58,234.17,505,1,2,1,233.53,234.25,10,100,1,1,233.5,234.41,100,500,1,1,233.45,234.43,15,105,1,2,AAPL,-65,-1.0635226179018287,0.013728323791400023
2024-10-21T12:26:20.829403397Z,2024-10-21T12:26:20.829236958Z,10,2,38,A,A,1,234.0,15,130,166439,13126283,233.86,233.95,100,121,1,1,233.81,234.0,2,17,2,2,233.8,234.02,105,200,2,1,233.79,234.07,200,7,1,1,233.7,234.1,1200,100,1,1,233.66,234.13,1,400,1,1,233.58,234.17,505,1,2,1,233.53,234.25,10,100,1,1,233.5,234.41,100,500,1,1,233.45,234.43,15,105,1,2,AAPL,-125,-1.9559902200488997,0.025248609311778417
2024-10-21T12:26:22.496516455Z,2024-10-21T12:26:22.496350258Z,10,2,38,C,A,3,234.07,7,130,166197,13127351,233.86,233.95,100,121,1,1,233.81,234.0,2,17,2,2,233.8,234.02,105,200,2,1,233.79,234.1,200,100,1,1,233.7,234.13,1200,400,1,1,233.66,234.17,1,1,1,1,233.58,234.25,505,100,2,1,233.53,234.41,10,500,1,1,233.5,234.43,100,105,1,2,233.45,234.5,15,63,1,4,AAPL,1,0.014775725593667546,-0.00019073025978791984
2024-10-21T12:26:23.489058780Z,2024-10-21T12:26:23.488892465Z,10,2,38,C,B,3,233.79,200,130,166315,13128004,233.86,233.95,100,121,1,1,233.81,234.0,2,17,2,2,233.8,234.02,105,200,2,1,233.7,234.1,1200,100,1,1,233.66,234.13,1,400,1,1,233.58,234.17,505,1,2,1,233.53,234.25,10,100,1,1,233.5,234.41,100,500,1,1,233.45,234.43,15,105,1,2,233.4,234.5,110,63,2,4,AAPL,-109,-1.5812379110251449,0.020411174777473288
2024-10-21T12:26:23.498527505Z,2024-10-21T12:26:23.498360877Z,10,2,38,A,B,3,233.78,200,130,166628,13128006,233.86,233.95,100,121,1,1,233.81,234.0,2,17,2,2,233.8,234.02,105,200,2,1,233.78,234.1,200,100,1,1,233.7,234.13,1200,400,1,1,233.66,234.17,1,1,1,1,233.58,234.25,505,100,2,1,233.53,234.41,10,500,1,1,233.5,234.43,100,105,1,2,233.45,234.5,15,63,1,4,AAPL,-94,-1.401677539608574,0.018093346385845914
2024-10-21T12:26:24.504603959Z,2024-10-21T12:26:24.504437465Z,10,2,38,A,A,7,234.41,7,130,166494,13128603,233.86,233.95,100,121,1,1,233.81,234.0,2,17,2,2,233.8,234.02,105,200,2,1,233.78,234.1,200,100,1,1,233.7,234.13,1200,400,1,1,233.66,234.17,1,1,1,1,233.58,234.25,505,100,2,1,233.53,234.41,10,507,1,2,233.5,234.43,100,105,1,2,233.45,234.5,15,63,1,4,AAPL,-94,-1.4370503597122304,0.018549951181666777
2024-10-21T12:26:25.077623504Z,2024-10-21T12:26:25.077457400Z,10,2,38,C,B,3,233.78,200,130,166104,13129240,233.86,233.95,100,121,1,1,233.81,234.0,2,17,2,2,233.8,234.02,105,200,2,1,233.7,234.1,1200,100,1,1,233.66,234.13,1,400,1,1,233.58,234.17,505,1,2,1,233.53,234.25,10,100,1,1,233.5,234.41,100,507,1,2,233.45,234.43,15,105,1,2,233.4,234.5,110,63,2,4,AAPL,-204,-3.063829787234043,0.03954899186240697
2024-10-21T12:26:25.077635518Z,2024-10-21T12:26:25.077469095Z,10,2,38,A,B,3,233.76,200,130,166423,13129241,233.86,233.95,100,121,1,1,233.81,234.0,2,17,2,2,233.8,234.02,105,200,2,1,233.76,234.1,200,100,1,1,233.7,234.13,1200,400,1,1,233.66,234.17,1,1,1,1,233.58,234.25,505,100,2,1,233.53,234.41,10,507,1,2,233.5,234.43,100,105,1,2,233.45,234.5,15,63,1,4,AAPL,-189,-2.901818181818182,0.037457689110894844
2024-10-21T12:26:25.077648690Z,2024-10-21T12:26:25.077482593Z,10,2,38,A,A,2,234.02,200,130,166097,13129242,233.86,233.95,100,121,1,1,233.81,234.0,2,17,2,2,233.8,234.02,105,400,2,2,233.76,234.1,200,100,1,1,233.7,234.13,1200,400,1,1,233.66,234.17,1,1,1,1,233.58,234.25,505,100,2,1,233.53,234.41,10,507,1,2,233.5,234.43,100,105,1,2,233.45,234.5,15,63,1,4,AAPL,-189,-2.9612220916568743,0.03822449566019945
2024-10-21T12:26:25.129478069Z,2024-10-21T12:26:25.129312037Z,10,2,38,C,A,2,234.02,200,130,166032,13129411,233.86,233.95,100,121,1,1,233.81,234.0,2,17,2,2,233.8,234.02,105,200,2,1,233.76,234.1,200,100,1,1,233.7,234.13,1200,400,1,1,233.66,234.17,1,1,1,1,233.58,234.25,505,100,2,1,233.53,234.41,10,507,1,2,233.5,234.43,100,105,1,2,233.45,234.5,15,63,1,4,AAPL,-189,-3.017103762827822,0.038945835914676416
2024-10-21T12:26:25.129491036Z,2024-10-21T12:26:25.129324093Z,10,2,38,A,A,1,234.0,200,130,166943,13129412,233.86,233.95,100,121,1,1,233.81,234.0,2,217,2,3,233.8,234.1,105,100,2,1,233.76,234.13,200,400,1,1,233.7,234.17,1200,1,1,1,233.66,234.25,1,100,1,1,233.58,234.41,505,507,2,2,233.53,234.43,10,105,1,2,233.5,234.5,100,63,1,4,233.45,234.59,15,60,1,1,AAPL,-129,-2.097560975609756,0.027076054388185798
2024-10-21T12:26:25.268804920Z,2024-10-21T12:26:25.268638479Z,10,2,38,A,B,3,233.77,200,130,166441,13129838,233.86,233.95,100,121,1,1,233.81,234.0,2,217,2,3,233.8,234.1,105,100,2,1,233.77,234.13,200,400,1,1,233.7,234.17,1200,1,1,1,233.66,234.25,1,100,1,1,233.58,234.41,505,507,2,2,233.53,234.43,10,105,1,2,233.5,234.5,100,63,1,4,233.45,234.59,15,60,1,1,AAPL,-124,-2.257786296118831,0.02914429914622297
2024-10-21T12:26:25.384254820Z,2024-10-21T12:26:25.384088744Z,10,2,38,C,A,1,234.0,200,130,166076,13130001,233.86,233.95,100,121,1,1,233.81,234.0,2,17,2,2,233.8,234.1,105,100,2,1,233.77,234.13,200,400,1,1,233.7,234.17,1200,1,1,1,233.66,234.25,1,100,1,1,233.58,234.41,505,507,2,2,233.53,234.43,10,105,1,2,233.5,234.5,100,63,1,4,233.45,234.59,15,60,1,1,AAPL,-124,-2.294172062904718,0.029613979413879613
2024-10-21T12:26:25.384266211Z,2024-10-21T12:26:25.384100277Z,10,2,38,A,A,2,234.02,200,130,165934,13130002,233.86,233.95,100,121,1,1,233.81,234.0,2,17,2,2,233.8,234.02,105,200,2,1,233.77,234.1,200,100,1,1,233.7,234.13,1200,400,1,1,233.66,234.17,1,1,1,1,233.58,234.25,505,100,2,1,233.53,234.41,10,507,1,2,233.5,234.43,100,105,1,2,233.45,234.5,15,63,1,4,AAPL,-187,-3.5062499999999996,0.045259907484205046
2024-10-21T12:26:25.439053026Z,2024-10-21T12:26:25.438886764Z,10,2,38,A,B,3,233.78,200,130,166262,13130072,233.86,233.95,100,121,1,1,233.81,234.0,2,17,2,2,233.8,234.02,105,200,2,1,233.78,234.1,200,100,1,1,233.7,234.13,1200,400,1,1,233.66,234.17,1,1,1,1,233.58,234.25,505,100,2,1,233.53,234.41,10,507,1,2,233.5,234.43,100,105,1,2,233.45,234.5,15,63,1,4,AAPL,-187,-3.5496117342536673,0.045819635992062645
2024-10-21T12:26:25.519068296Z,2024-10-21T12:26:25.518902005Z,10,2,38,A,A,2,234.01,200,130,166291,13130195,233.86,233.95,100,121,1,1,233.81,234.0,2,17,2,2,233.8,234.01,105,200,2,1,233.78,234.1,200,100,1,1,233.7,234.13,1200,400,1,1,233.66,234.17,1,1,1,1,233.58,234.25,505,100,2,1,233.53,234.41,10,507,1,2,233.5,234.43,100,105,1,2,233.45,234.5,15,63,1,4,AAPL,-187,-3.590150250417362,0.046342921408423644
2024-10-21T12:26:31.593057846Z,2024-10-21T12:26:31.592891536Z,10,2,38,C,A,7,234.41,7,130,166310,13135066,233.86,233.95,100,121,1,1,233.81,234.0,2,17,2,2,233.8,234.01,105,200,2,1,233.78,234.1,200,100,1,1,233.7,234.13,1200,400,1,1,233.66,234.17,1,1,1,1,233.58,234.25,505,100,2,1,233.53,234.41,10,500,1,1,233.5,234.43,100,105,1,2,233.45,234.5,15,63,1,4,AAPL,-172,-3.5216379711493717,0.045458540824836836
2024-10-21T12:26:32.717599837Z,2024-10-21T12:26:32.717433050Z,10,2,38,A,A,0,233.95,10,130,166787,13137148,233.86,233.95,100,131,1,2,233.81,234.0,2,17,2,2,233.8,234.01,105,200,2,1,233.78,234.1,200,100,1,1,233.7,234.13,1200,400,1,1,233.66,234.17,1,1,1,1,233.58,234.25,505,100,2,1,233.53,234.41,10,500,1,1,233.5,234.43,100,105,1,2,233.45,234.5,15,63,1,4,AAPL,-130,-2.80407429598562,0.03619597667455161
2024-10-21T12:26:32.717638955Z,2024-10-21T12:26:32.717472823Z,10,2,38,C,B,3,233.78,200,130,166132,13137150,233.86,233.95,100,131,1,2,233.81,234.0,2,17,2,2,233.8,234.01,105,200,2,1,233.7,234.1,1200,100,1,1,233.66,234.13,1,400,1,1,233.58,234.17,505,1,2,1,233.53,234.25,10,100,1,1,233.5,234.41,100,500,1,1,233.45,234.43,15,105,1,2,233.4,234.5,110,63,2,4,AAPL,-240,-4.95114006514658,0.06391105633935834
2024-10-21T12:26:32.721694410Z,2024-10-21T12:26:32.721528057Z,10,2,38,C,A,0,233.95,10,130,166353,13137153,233.86,233.95,100,121,1,1,233.81,234.0,2,17,2,2,233.8,234.01,105,200,2,1,233.7,234.1,1200,100,1,1,233.66,234.13,1,400,1,1,233.58,234.17,505,1,2,1,233.53,234.25,10,100,1,1,233.5,234.41,100,500,1,1,233.45,234.43,15,105,1,2,233.4,234.5,110,63,2,4,AAPL,-240,-4.764267990074441,0.06149884590680322
2024-10-21T12:26:32.820850700Z,2024-10-21T12:26:32.820683999Z,10,2,38,A,B,3,233.78,200,130,166701,13137257,233.86,233.95,100,121,1,1,233.81,234.0,2,17,2,2,233.8,234.01,105,200,2,1,233.78,234.1,200,100,1,1,233.7,234.13,1200,400,1,1,233.66,234.17,1,1,1,1,233.58,234.25,505,100,2,1,233.53,234.41,10,500,1,1,233.5,234.43,100,105,1,2,233.45,234.5,15,63,1,4,AAPL,-225,-4.51505016722408,0.058281854646732675
2024-10-21T12:26:33.596226968Z,2024-10-21T12:26:33.596060481Z,10,2,38,A,A,7,234.41,7,130,166487,13137944,233.86,233.95,100,121,1,1,233.81,234.0,2,17,2,2,233.8,234.01,105,200,2,1,233.78,234.1,200,100,1,1,233.7,234.13,1200,400,1,1,233.66,234.17,1,1,1,1,233.58,234.25,505,100,2,1,233.53,234.41,10,507,1,2,233.5,234.43,100,105,1,2,233.45,234.5,15,63,1,4,AAPL,-225,-4.607508532423208,0.05947533972482276
2024-10-21T12:26:33.705462618Z,2024-10-21T12:26:33.705296257Z,10,2,38,C,B,3,233.78,200,130,166361,13138040,233.86,233.95,100,121,1,1,233.81,234.0,2,17,2,2,233.8,234.01,105,200,2,1,233.7,234.1,1200,100,1,1,233.66,234.13,1,400,1,1,233.58,234.17,505,1,2,1,233.53,234.25,10,100,1,1,233.5,234.41,100,507,1,2,233.45,234.43,15,105,1,2,233.4,234.5,110,63,2,4,AAPL,-335,-6.627697841726619,0.08555265344736179
2024-10-21T12:26:33.705475821Z,2024-10-21T12:26:33.705309399Z,10,2,38,A,B,3,233.73,400,130,166422,13138041,233.86,233.95,100,121,1,1,233.81,234.0,2,17,2,2,233.8,234.01,105,200,2,1,233.73,234.1,400,100,1,1,233.7,234.13,1200,400,1,1,233.66,234.17,1,1,1,1,233.58,234.25,505,100,2,1,233.53,234.41,10,507,1,2,233.5,234.43,100,105,1,2,233.45,234.5,15,63,1,4,AAPL,-320,-6.394439617723719,0.08254167429918319
2024-10-21T12:26:40.656300037Z,2024-10-21T12:26:40.656134264Z,10,2,38,C,A,2,234.01,200,130,165773,13145962,233.86,233.95,100,121,1,1,233.81,234.0,2,17,2,2,233.8,234.1,105,100,2,1,233.73,234.13,400,400,1,1,233.7,234.17,1200,1,1,1,233.66,234.25,1,100,1,1,233.58,234.41,505,507,2,2,233.53,234.43,10,105,1,2,233.5,234.5,100,63,1,4,233.45,234.59,15,60,1,1,AAPL,-260,-5.250315523769457,0.06777291832262138
2024-10-21T12:26:40.656313085Z,2024-10-21T12:26:40.656147028Z,10,2,38,A,A,2,234.03,400,130,166057,13145963,233.86,233.95,100,121,1,1,233.81,234.0,2,17,2,2,233.8,234.03,105,400,2,1,233.73,234.1,400,100,1,1,233.7,234.13,1200,400,1,1,233.66,234.17,1,1,1,1,233.58,234.25,505,100,2,1,233.53,234.41,10,507,1,2,233.5,234.43,100,105,1,2,233.45,234.5,15,63,1,4,AAPL,-323,-6.5784114052953155,0.08491644680119938
2024-10-21T12:26:40.707673608Z,2024-10-21T12:26:40.707506986Z,10,2,38,A,B,3,233.74,400,130,166622,13146198,233.86,233.95,100,121,1,1,233.81,234.0,2,17,2,2,233.8,234.03,105,400,2,1,233.74,234.1,400,100,1,1,233.7,234.13,1200,400,1,1,233.66,234.17,1,1,1,1,233.58,234.25,505,100,2,1,233.53,234.41,10,507,1,2,233.5,234.43,100,105,1,2,233.45,234.5,15,63,1,4,AAPL,-323,-6.630872483221477,0.08559363283569771
2024-10-21T12:26:40.896702274Z,2024-10-21T12:26:40.896535785Z,10,2,38,A,A,2,234.02,400,130,166489,13146521,233.86,233.95,100,121,1,1,233.81,234.0,2,17,2,2,233.8,234.02,105,400,2,1,233.74,234.1,400,100,1,1,233.7,234.13,1200,400,1,1,233.66,234.17,1,1,1,1,233.58,234.25,505,100,2,1,233.53,234.41,10,507,1,2,233.5,234.43,100,105,1,2,233.45,234.5,15,63,1,4,AAPL,-323,-6.74267362505018,0.08703680127371428
2024-10-21T12:26:42.392700431Z,2024-10-21T12:26:42.392534365Z,10,2,38,C,A,7,234.41,7,130,166066,13148175,233.86,233.95,100,121,1,1,233.81,234.0,2,17,2,2,233.8,234.02,105,400,2,1,233.74,234.1,400,100,1,1,233.7,234.13,1200,400,1,1,233.66,234.17,1,1,1,1,233.58,234.25,505,100,2,1,233.53,234.41,10,500,1,1,233.5,234.43,100,105,1,2,233.45,234.5,15,63,1,4,AAPL,-323,-6.789412222654729,0.08764011952070845
2024-10-21T12:26:43.555781301Z,2024-10-21T12:26:43.555613825Z,10,2,38,T,A,0,233.86,100,130,167476,13148963,233.86,233.95,100,121,1,1,233.81,234.0,2,17,2,2,233.8,234.02,105,400,2,1,233.74,234.1,400,100,1,1,233.7,234.13,1200,400,1,1,233.66,234.17,1,1,1,1,233.58,234.25,505,100,2,1,233.53,234.41,10,500,1,1,233.5,234.43,100,105,1,2,233.45,234.5,15,63,1,4,AAPL,-291,-6.276962899050906,0.08102524352023716
2024-10-21T12:26:43.555781301Z,2024-10-21T12:26:43.555613825Z,10,2,38,C,B,0,233.86,100,130,167476,13148963,233.81,233.95,2,121,2,1,233.8,234.0,105,17,2,2,233.74,234.02,400,400,1,1,233.7,234.1,1200,100,1,1,233.66,234.13,1,400,1,1,233.58,234.17,505,1,2,1,233.53,234.25,10,100,1,1,233.5,234.41,100,500,1,1,233.45,234.43,15,105,1,2,233.4,234.5,110,63,2,4,AAPL,-401,-8.37093536732236,0.10805497619430163
2024-10-21T12:26:43.555792717Z,2024-10-21T12:26:43.555625145Z,10,2,38,A,B,0,233.86,100,130,167572,13148964,233.86,233.95,100,121,1,1,233.81,234.0,2,17,2,2,233.8,234.02,105,400,2,1,233.74,234.1,400,100,1,1,233.7,234.13,1200,400,1,1,233.66,234.17,1,1,1,1,233.58,234.25,505,100,2,1,233.53,234.41,10,500,1,1,233.5,234.43,100,105,1,2,233.45,234.5,15,63,1,4,AAPL,-386,-8.113662903853639,0.10473401280183736
2024-10-21T12:26:43.555803052Z,2024-10-21T12:26:43.555636531Z,10,2,38,A,A,0,233.9,100,130,166521,13148965,233.86,233.9,100,100,1,1,233.81,233.95,2,121,2,1,233.8,234.0,105,17,2,2,233.74,234.02,400,400,1,1,233.7,234.1,1200,100,1,1,233.66,234.13,1,400,1,1,233.58,234.17,505,1,2,1,233.53,234.25,10,100,1,1,233.5,234.41,100,500,1,1,233.45,234.43,15,105,1,2,AAPL,-491,-10.225362588322795,0.131992574613887
2024-10-21T12:26:43.555807607Z,2024-10-21T12:26:43.555641373Z,10,2,38,A,A,1,233.91,200,130,166234,13148967,233.86,233.9,100,100,1,1,233.81,233.91,2,200,2,1,233.8,233.93,105,100,2,1,233.74,233.95,400,121,1,1,233.7,234.0,1200,17,1,2,233.66,234.02,1,400,1,1,233.58,234.1,505,100,2,1,233.53,234.13,10,400,1,1,233.5,234.17,100,1,1,1,233.45,234.25,15,100,1,1,AAPL,-591,-12.224679029957205,0.15780045402351933
2024-10-21T12:26:43.555814614Z,2024-10-21T12:26:43.555648065Z,10,2,38,A,A,2,233.93,100,130,166549,13148968,233.86,233.9,100,100,1,1,233.81,233.91,2,200,2,1,233.8,233.93,105,200,2,2,233.74,233.95,400,121,1,1,233.7,234.0,1200,17,1,2,233.66,234.02,1,400,1,1,233.58,234.1,505,100,2,1,233.53,234.13,10,400,1,1,233.5,234.17,100,1,1,1,233.45,234.25,15,100,1,1,AAPL,-591,-12.147995889003084,0.15681060108514308
2024-10-21T12:26:43.555816268Z,2024-10-21T12:26:43.555650058Z,10,2,38,A,A,2,233.93,100,130,166210,13148969,233.86,233.9,100,100,1,1,233.81,233.91,2,200,2,1,233.8,233.93,105,300,2,3,233.74,233.95,400,121,1,1,233.7,234.0,1200,17,1,2,233.66,234.02,1,400,1,1,233.58,234.1,505,100,2,1,233.53,234.13,10,400,1,1,233.5,234.17,100,1,1,1,233.45,234.25,15,100,1,1,AAPL,-591,-12.0771259063942,0.15589578643807417
2024-10-21T12:26:43.555819727Z,2024-10-21T12:26:43.555653371Z,10,2,38,C,A,1,233.91,200,130,166356,13148970,233.86,233.9,100,100,1,1,233.81,233.93,2,300,2,3,233.8,233.95,105,121,2,1,233.74,234.0,400,17,1,2,233.7,234.02,1200,400,1,1,233.66,234.1,1,100,1,1,233.58,234.13,505,400,2,1,233.53,234.17,10,1,1,1,233.5,234.25,100,100,1,1,233.45,234.41,15,500,1,1,AAPL,-91,-1.641025641025641,0.02118293581234333
2024-10-21T12:26:43.555829005Z,2024-10-21T12:26:43.555663089Z,10,2,38,A,A,1,233.91,23,130,165916,13148971,233.86,233.9,100,100,1,1,233.81,233.91,2,23,2,1,233.8,233.93,105,300,2,3,233.74,233.95,400,121,1,1,233.7,234.0,1200,17,1,2,233.66,234.02,1,400,1,1,233.58,234.1,505,100,2,1,233.53,234.13,10,400,1,1,233.5,234.17,100,1,1,1,233.45,234.25,15,100,1,1,AAPL,-191,-3.4405021834061134,0.044411211556553636
2024-10-21T12:26:43.555844094Z,2024-10-21T12:26:43.555678324Z,10,2,38,C,A,0,233.9,100,130,165770,13148972,233.86,233.91,100,23,1,1,233.81,233.93,2,300,2,3,233.8,233.95,105,121,2,1,233.74,234.0,400,17,1,2,233.7,234.02,1200,400,1,1,233.66,234.1,1,100,1,1,233.58,234.13,505,400,2,1,233.53,234.17,10,1,1,1,233.5,234.25,100,100,1,1,233.45,234.41,15,500,1,1,AAPL,309,5.027997128499641,-0.0649031543291957
2024-10-21T12:26:43.555858526Z,2024-10-21T12:26:43.555692383Z,10,2,38,C,A,1,233.93,100,130,166143,13148974,233.86,233.91,100,23,1,1,233.81,233.93,2,200,2,2,233.8,233.95,105,121,2,1,233.74,234.0,400,17,1,2,233.7,234.02,1200,400,1,1,233.66,234.1,1,100,1,1,233.58,234.13,505,400,2,1,233.53,234.17,10,1,1,1,233.5,234.25,100,100,1,1,233.45,234.41,15,500,1,1,AAPL,309,4.608010225820196,-0.059481815759541645
2024-10-21T12:26:43.555866497Z,2024-10-21T12:26:43.555700148Z,10,2,38,C,A,1,233.93,100,130,166349,13148976,233.86,233.91,100,23,1,1,233.81,233.93,2,100,2,1,233.8,233.94,105,23,2,1,233.74,233.95,400,121,1,1,233.7,234.0,1200,17,1,2,233.66,234.02,1,400,1,1,233.58,234.1,505,100,2,1,233.53,234.13,10,400,1,1,233.5,234.17,100,1,1,1,233.45,234.25,15,100,1,1,AAPL,209,3.1291328758577666,-0.04039194708509291
2024-10-21T12:26:43.555879570Z,2024-10-21T12:26:43.555711164Z,10,2,38,T,A,0,233.86,50,130,168406,13148979,233.86,233.91,100,23,1,1,233.81,233.93,2,100,2,1,233.8,233.94,105,23,2,1,233.74,233.95,400,121,1,1,233.7,234.0,1200,17,1,2,233.66,234.02,1,400,1,1,233.58,234.1,505,100,2,1,233.53,234.13,10,400,1,1,233.5,234.17,100,1,1,1,233.45,234.25,15,100,1,1,AAPL,209,3.1409423233143783,-0.04054438758400936
2024-10-21T12:26:43.555879570Z,2024-10-21T12:26:43.555711164Z,10,2,38,C,B,0,233.86,50,130,168406,13148979,233.86,233.91,50,23,1,1,233.81,233.93,2,100,2,1,233.8,233.94,105,23,2,1,233.74,233.95,400,121,1,1,233.7,234.0,1200,17,1,2,233.66,234.02,1,400,1,1,233.58,234.1,505,100,2,1,233.53,234.13,10,400,1,1,233.5,234.17,100,1,1,1,233.45,234.25,15,100,1,1,AAPL,209,3.1522127406231393,-0.04068987009230253
2024-10-21T12:26:43.555892512Z,2024-10-21T12:26:43.555724858Z,10,2,38,A,B,0,233.86,100,130,167654,13148980,233.86,233.91,150,23,2,1,233.81,233.93,2,100,2,1,233.8,233.94,105,23,2,1,233.74,233.95,400,121,1,1,233.7,234.0,1200,17,1,2,233.66,234.02,1,400,1,1,233.58,234.1,505,100,2,1,233.53,234.13,10,400,1,1,233.5,234.17,100,1,1,1,233.45,234.25,15,100,1,1,AAPL,209,3.1629802095459834,-0.04082886036603857
2024-10-21T12:26:43.555904815Z,2024-10-21T12:26:43.555737821Z,10,2,38,T,A,0,233.86,50,130,166994,13148981,233.86,233.91,150,23,2,1,233.81,233.93,2,100,2,1,233.8,233.94,105,23,2,1,233.74,233.95,400,121,1,1,233.7,234.0,1200,17,1,2,233.66,234.02,1,400,1,1,233.58,234.1,505,100,2,1,233.53,234.13,10,400,1,1,233.5,234.17,100,1,1,1,233.45,234.25,15,100,1,1,AAPL,209,3.173277661795407,-0.040961783499338225
2024-10-21T12:26:43.555904815Z,2024-10-21T12:26:43.555737821Z,10,2,38,C,B,0,233.86,50,130,166994,13148981,233.86,233.91,100,23,1,1,233.81,233.93,2,100,2,1,233.8,233.94,105,23,2,1,233.74,233.95,400,121,1,1,233.7,234.0,1200,17,1,2,233.66,234.02,1,400,1,1,233.58,234.1,505,100,2,1,233.53,234.13,10,400,1,1,233.5,234.17,100,1,1,1,233.45,234.25,15,100,1,1,AAPL,209,3.183135215453195,-0.041089028266988015
2024-10-21T12:26:43.555933449Z,2024-10-21T12:26:43.555767270Z,10,2,38,C,B,3,233.74,200,130,166179,13148982,233.86,233.91,100,23,1,1,233.81,233.93,2,100,2,1,233.8,233.94,105,23,2,1,233.74,233.95,200,121,1,1,233.7,234.0,1200,17,1,2,233.66,234.02,1,400,1,1,233.58,234.1,505,100,2,1,233.53,234.13,10,400,1,1,233.5,234.17,100,1,1,1,233.45,234.25,15,100,1,1,AAPL,209,3.1925804691762143,-0.041210950922152
2024-10-21T12:26:43.555956286Z,2024-10-21T12:26:43.555789284Z,10,2,38,C,B,3,233.74,200,130,167002,13148983,233.86,233.91,100,23,1,1,233.81,233.93,2,100,2,1,233.8,233.94,105,23,2,1,233.7,233.95,1200,121,1,1,233.66,234.0,1,17,1,2,233.58,234.02,505,400,2,1,233.53,234.1,10,100,1,1,233.5,234.13,100,400,1,1,233.45,234.17,15,1,1,1,233.4,234.25,110,100,2,1,AAPL,99,1.4913294797687862,-0.019250605143045395
2024-10-21T12:26:43.556155095Z,2024-10-21T12:26:43.555989102Z,10,2,38,C,A,1,233.93,100,130,165993,13148984,233.86,233.91,100,23,1,1,233.81,233.94,2,23,2,1,233.8,233.95,105,121,2,1,233.7,234.0,1200,17,1,2,233.66,234.02,1,400,1,1,233.58,234.1,505,100,2,1,233.53,234.13,10,400,1,1,233.5,234.17,100,1,1,1,233.45,234.25,15,100,1,1,233.4,234.41,110,500,2,1,AAPL,599,8.34182623832885,-0.10767922532508462
2024-10-21T12:26:43.556502258Z,2024-10-21T12:26:43.556335122Z,10,2,38,T,A,0,233.86,5,130,167136,13148985,233.86,233.91,100,23,1,1,233.81,233.94,2,23,2,1,233.8,233.95,105,121,2,1,233.7,234.0,1200,17,1,2,233.66,234.02,1,400,1,1,233.58,234.1,505,100,2,1,233.53,234.13,10,400,1,1,233.5,234.17,100,1,1,1,233.45,234.25,15,100,1,1,233.4,234.41,110,500,2,1,AAPL,599,7.7803434839082115,-0.10043140856385692
2024-10-21T12:26:43.556502258Z,2024-10-21T12:26:43.556335122Z,10,2,38,C,B,0,233.86,5,130,167136,13148985,233.86,233.91,95,23,1,1,233.81,233.94,2,23,2,1,233.8,233.95,105,121,2,1,233.7,234.0,1200,17,1,2,233.66,234.02,1,400,1,1,233.58,234.1,505,100,2,1,233.53,234.13,10,400,1,1,233.5,234.17,100,1,1,1,233.45,234.25,15,100,1,1,233.4,234.41,110,500,2,1,AAPL,599,7.309722774903833,-0.09435647102383861
2024-10-21T12:26:43.556510636Z,2024-10-21T12:26:43.556344203Z,10,2,38,A,B,0,233.86,100,130,166433,13148986,233.86,233.91,195,23,2,1,233.81,233.94,2,23,2,1,233.8,233.95,105,121,2,1,233.7,234.0,1200,17,1,2,233.66,234.02,1,400,1,1,233.58,234.1,505,100,2,1,233.53,234.13,10,400,1,1,233.5,234.17,100,1,1,1,233.45,234.25,15,100,1,1,233.4,234.41,110,500,2,1,AAPL,599,6.909559455147871,-0.08919102223076135
2024-10-21T12:26:43.603087151Z,2024-10-21T12:26:43.602920183Z,10,2,38,A,B,3,233.74,200,130,166968,13149063,233.86,233.91,195,23,2,1,233.81,233.94,2,23,2,1,233.8,233.95,105,121,2,1,233.74,234.0,200,17,1,2,233.7,234.02,1200,400,1,1,233.66,234.1,1,100,1,1,233.58,234.13,505,400,2,1,233.53,234.17,10,1,1,1,233.5,234.25,100,100,1,1,233.45,234.41,15,500,1,1,AAPL,614,6.803324099722992,-0.08781969892007849
2024-10-21T12:26:43.633097364Z,2024-10-21T12:26:43.632931005Z,10,2,38,A,B,3,233.74,200,130,166359,13149078,233.86,233.91,195,23,2,1,233.81,233.94,2,23,2,1,233.8,233.95,105,121,2,1,233.74,234.0,400,17,2,2,233.7,234.02,1200,400,1,1,233.66,234.1,1,100,1,1,233.58,234.13,505,400,2,1,233.53,234.17,10,1,1,1,233.5,234.25,100,100,1,1,233.45,234.41,15,500,1,1,AAPL,614,6.555398191524131,-0.08461938414845128
2024-10-21T12:26:43.663930696Z,2024-10-21T12:26:43.663764676Z,10,2,38,C,A,1,233.94,23,130,166020,13149095,233.86,233.91,195,23,2,1,233.81,233.95,2,121,2,1,233.8,234.0,105,17,2,2,233.74,234.02,400,400,2,1,233.7,234.1,1200,100,1,1,233.66,234.13,1,400,1,1,233.58,234.17,505,1,2,1,233.53,234.25,10,100,1,1,233.5,234.41,100,500,1,1,233.45,234.43,15,105,1,2,AAPL,719,7.73201419507474,-0.09980755711533489
2024-10-21T12:26:43.813930819Z,2024-10-21T12:26:43.813764689Z,10,2,38,C,A,0,233.91,23,130,166130,13149215,233.86,233.95,195,121,2,1,233.81,234.0,2,17,2,2,233.8,234.02,105,400,2,1,233.74,234.1,400,100,2,1,233.7,234.13,1200,400,1,1,233.66,234.17,1,1,1,1,233.58,234.25,505,100,2,1,233.53,234.41,10,500,1,1,233.5,234.43,100,105,1,2,233.45,234.5,15,63,1,4,AAPL,782,8.506345312999892,-0.10980289537114478
2024-10-21T12:26:44.395306900Z,2024-10-21T12:26:44.395140599Z,10,2,38,A,A,1,233.97,7,130,166301,13149756,233.86,233.95,195,121,2,1,233.81,233.97,2,7,2,1,233.8,234.0,105,17,2,2,233.74,234.02,400,400,2,1,233.7,234.1,1200,100,1,1,233.66,234.13,1,400,1,1,233.58,234.17,505,1,2,1,233.53,234.25,10,100,1,1,233.5,234.41,100,500,1,1,233.45,234.43,15,105,1,2,AAPL,677,7.4137095925028955,-0.09569876941788082
2024-10-21T12:26:47.317000869Z,2024-10-21T12:26:47.316834945Z,10,2,38,C,A,3,234.02,400,130,165924,13152409,233.86,233.95,195,121,2,1,233.81,233.97,2,7,2,1,233.8,234.0,105,17,2,2,233.74,234.1,400,100,2,1,233.7,234.13,1200,400,1,1,233.66,234.17,1,1,1,1,233.58,234.25,505,100,2,1,233.53,234.41,10,500,1,1,233.5,234.43,100,105,1,2,233.45,234.5,15,63,1,4,AAPL,838,8.155717761557177,-0.10527687168780486
2024-10-21T12:26:47.317013569Z,2024-10-21T12:26:47.316847348Z,10,2,38,A,A,3,234.04,400,130,166221,13152410,233.86,233.95,195,121,2,1,233.81,233.97,2,7,2,1,233.8,234.0,105,17,2,2,233.74,234.04,400,400,2,1,233.7,234.1,1200,100,1,1,233.66,234.13,1,400,1,1,233.58,234.17,505,1,2,1,233.53,234.25,10,100,1,1,233.5,234.41,100,500,1,1,233.45,234.43,15,105,1,2,AAPL,733,7.203519597760256,-0.09298556308172183
2024-10-21T12:26:47.371614290Z,2024-10-21T12:26:47.371448271Z,10,2,38,C,B,3,233.74,200,130,166019,13152673,233.86,233.95,195,121,2,1,233.81,233.97,2,7,2,1,233.8,234.0,105,17,2,2,233.74,234.04,200,400,1,1,233.7,234.1,1200,100,1,1,233.66,234.13,1,400,1,1,233.58,234.17,505,1,2,1,233.53,234.25,10,100,1,1,233.5,234.41,100,500,1,1,233.45,234.43,15,105,1,2,AAPL,733,7.271333558787059,-0.0938609295279851
2024-10-21T12:26:47.371627679Z,2024-10-21T12:26:47.371461367Z,10,2,38,A,B,3,233.76,400,130,166312,13152674,233.86,233.95,195,121,2,1,233.81,233.97,2,7,2,1,233.8,234.0,105,17,2,2,233.76,234.04,400,400,1,1,233.7,234.1,1200,100,1,1,233.66,234.13,1,400,1,1,233.58,234.17,505,1,2,1,233.53,234.25,10,100,1,1,233.5,234.41,100,500,1,1,233.45,234.43,15,105,1,2,AAPL,733,7.3373373373373365,-0.09471292950254298
2024-10-21T12:26:53.381817361Z,2024-10-21T12:26:53.381650546Z,10,2,38,A,B,3,233.77,400,130,166815,13157627,233.86,233.95,195,121,2,1,233.81,233.97,2,7,2,1,233.8,234.0,105,17,2,2,233.77,234.04,400,400,1,1,233.7,234.1,1200,100,1,1,233.66,234.13,1,400,1,1,233.58,234.17,505,1,2,1,233.53,234.25,10,100,1,1,233.5,234.41,100,500,1,1,233.45,234.43,15,105,1,2,AAPL,828,7.9587387176180995,-0.10273419694840812
2024-10-21T12:26:54.545889324Z,2024-10-21T12:26:54.545723322Z,10,2,38,C,B,3,233.77,400,130,166002,13158660,233.86,233.95,195,121,2,1,233.81,233.97,2,7,2,1,233.8,234.0,105,17,2,2,233.7,234.04,1200,400,1,1,233.66,234.1,1,100,1,1,233.58,234.13,505,400,2,1,233.53,234.17,10,1,1,1,233.5,234.25,100,100,1,1,233.45,234.41,15,500,1,1,233.4,234.43,110,105,2,2,AAPL,813,7.534038255910657,-0.0972520141019545
2024-10-21T12:26:54.545901500Z,2024-10-21T12:26:54.545735230Z,10,2,38,A,B,3,233.76,400,130,166270,13158661,233.86,233.95,195,121,2,1,233.81,233.97,2,7,2,1,233.8,234.0,105,17,2,2,233.76,234.04,400,400,1,1,233.7,234.1,1200,100,1,1,233.66,234.13,1,400,1,1,233.58,234.17,505,1,2,1,233.53,234.25,10,100,1,1,233.5,234.41,100,500,1,1,233.45,234.43,15,105,1,2,AAPL,828,7.759165983366522,-0.10015804194274786
2024-10-21T12:27:04.677969002Z,2024-10-21T12:27:04.677802802Z,10,2,38,A,B,3,233.77,400,130,166200,13168438,233.86,233.95,195,121,2,1,233.81,233.97,2,7,2,1,233.8,234.0,105,17,2,2,233.77,234.04,400,400,1,1,233.7,234.1,1200,100,1,1,233.66,234.13,1,400,1,1,233.58,234.17,505,1,2,1,233.53,234.25,10,100,1,1,233.5,234.41,100,500,1,1,233.45,234.43,15,105,1,2,AAPL,-137,-2.1638696939782824,0.027931990633107213
2024-10-21T12:27:04.858352610Z,2024-10-21T12:27:04.858186427Z,10,2,38,C,B,3,233.77,200,130,166183,13168809,233.86,233.95,195,121,2,1,233.81,233.97,2,7,2,1,233.8,234.0,105,17,2,2,233.77,234.04,200,400,1,1,233.7,234.1,1200,100,1,1,233.66,234.13,1,400,1,1,233.58,234.17,505,1,2,1,233.53,234.25,10,100,1,1,233.5,234.41,100,500,1,1,233.45,234.43,15,105,1,2,AAPL,-137,-2.176522506619594,0.02809531758627962
2024-10-21T12:27:08.140351417Z,2024-10-21T12:27:08.140184917Z,10,2,38,A,B,0,233.86,100,130,166500,13171896,233.86,233.95,295,121,3,1,233.81,233.97,2,7,2,1,233.8,234.0,105,17,2,2,233.77,234.04,200,400,1,1,233.7,234.1,1200,100,1,1,233.66,234.13,1,400,1,1,233.58,234.17,505,1,2,1,233.53,234.25,10,100,1,1,233.5,234.41,100,500,1,1,233.45,234.43,15,105,1,2,AAPL,-95,-1.3987730061349692,0.01805585364679418
2024-10-21T12:27:08.267404175Z,2024-10-21T12:27:08.267237597Z,10,2,38,A,A,2,233.99,200,130,166578,13172040,233.86,233.95,295,121,3,1,233.81,233.97,2,7,2,1,233.8,233.99,105,200,2,1,233.77,234.0,200,17,1,2,233.7,234.1,1200,100,1,1,233.66,234.13,1,400,1,1,233.58,234.17,505,1,2,1,233.53,234.25,10,100,1,1,233.5,234.41,100,500,1,1,233.45,234.43,15,105,1,2,AAPL,-95,-1.4224598930481283,0.018361612309262174
2024-10-21T12:27:08.904013328Z,2024-10-21T12:27:08.903847050Z,10,2,38,A,B,3,233.77,200,130,166278,13172666,233.86,233.95,295,121,3,1,233.81,233.97,2,7,2,1,233.8,233.99,105,200,2,1,233.77,234.0,400,17,2,2,233.7,234.1,1200,100,1,1,233.66,234.13,1,400,1,1,233.58,234.17,505,1,2,1,233.53,234.25,10,100,1,1,233.5,234.41,100,500,1,1,233.45,234.43,15,105,1,2,AAPL,-95,-1.4407582938388626,0.01859781449875167
2024-10-21T12:27:15.211190007Z,2024-10-21T12:27:15.211023662Z,10,2,38,C,A,1,233.97,7,130,166345,13177973,233.86,233.95,295,121,3,1,233.81,233.99,2,200,2,1,233.8,234.0,105,17,2,2,233.77,234.1,400,100,2,1,233.7,234.13,1200,400,1,1,233.66,234.17,1,1,1,1,233.58,234.25,505,100,2,1,233.53,234.41,10,500,1,1,233.5,234.43,100,105,1,2,233.45,234.5,15,63,1,4,AAPL,63,1.1150442477876106,-0.014393383100367136
2024-10-21T12:27:16.357351976Z,2024-10-21T12:27:16.357185731Z,10,2,38,C,A,0,233.95,121,130,166245,13178747,233.86,233.99,295,200,3,1,233.81,234.0,2,17,2,2,233.8,234.1,105,100,2,1,233.77,234.13,400,400,2,1,233.7,234.17,1200,1,1,1,233.66,234.25,1,100,1,1,233.58,234.41,505,500,2,1,233.53,234.43,10,105,1,2,233.5,234.5,100,63,1,4,233.45,234.59,15,60,1,1,AAPL,123,2.2868525896414345,-0.02951949708012437
2024-10-21T12:27:16.384048756Z,2024-10-21T12:27:16.383880298Z,10,2,38,T,N,0,233.87,50,0,168458,13178752,233.86,233.99,295,200,3,1,233.81,234.0,2,17,2,2,233.8,234.1,105,100,2,1,233.77,234.13,400,400,2,1,233.7,234.17,1200,1,1,1,233.66,234.25,1,100,1,1,233.58,234.41,505,500,2,1,233.53,234.43,10,105,1,2,233.5,234.5,100,63,1,4,233.45,234.59,15,60,1,1,AAPL,123,2.3768115942028984,-0.030680719532551616
2024-10-21T12:27:16.384048756Z,2024-10-21T12:27:16.383880298Z,10,2,38,T,N,0,233.87,71,130,168458,13178753,233.86,233.99,295,200,3,1,233.81,234.0,2,17,2,2,233.8,234.1,105,100,2,1,233.77,234.13,400,400,2,1,233.7,234.17,1200,1,1,1,233.66,234.25,1,100,1,1,233.58,234.41,505,500,2,1,233.53,234.43,10,105,1,2,233.5,234.5,100,63,1,4,233.45,234.59,15,60,1,1,AAPL,123,2.4518272425249172,-0.03164904788989129
2024-10-21T12:27:17.218399628Z,2024-10-21T12:27:17.218233083Z,10,2,38,A,A,0,233.98,7,130,166545,13179063,233.86,233.98,295,7,3,1,233.81,233.99,2,200,2,1,233.8,234.0,105,17,2,2,233.77,234.1,400,100,2,1,233.7,234.13,1200,400,1,1,233.66,234.17,1,1,1,1,233.58,234.25,505,100,2,1,233.53,234.41,10,500,1,1,233.5,234.43,100,105,1,2,233.45,234.5,15,63,1,4,AAPL,60,1.2232415902140674,-0.01579003242892565
2024-10-21T12:27:21.556157771Z,2024-10-21T12:27:21.555991612Z,10,2,38,C,B,3,233.77,200,130,166159,13183172,233.86,233.98,295,7,3,1,233.81,233.99,2,200,2,1,233.8,234.0,105,17,2,2,233.77,234.1,200,100,1,1,233.7,234.13,1200,400,1,1,233.66,234.17,1,1,1,1,233.58,234.25,505,100,2,1,233.53,234.41,10,500,1,1,233.5,234.43,100,105,1,2,233.45,234.5,15,63,1,4,AAPL,60,1.246458923512748,-0.016089729928284863
2024-10-21T12:27:21.556172659Z,2024-10-21T12:27:21.556005910Z,10,2,38,A,B,1,233.81,200,130,166749,13183173,233.86,233.98,295,7,3,1,233.81,233.99,202,200,3,1,233.8,234.0,105,17,2,2,233.7,234.1,1200,100,1,1,233.66,234.13,1,400,1,1,233.58,234.17,505,1,2,1,233.53,234.25,10,100,1,1,233.5,234.41,100,500,1,1,233.45,234.43,15,105,1,2,233.4,234.5,110,63,2,4,AAPL,-50,-0.974025974025974,0.012573069653227322
2024-10-21T12:27:21.983295309Z,2024-10-21T12:27:21.983129451Z,10,2,38,C,B,1,233.81,200,130,165858,13183374,233.86,233.98,295,7,3,1,233.81,233.99,2,200,2,1,233.8,234.0,105,17,2,2,233.7,234.1,1200,100,1,1,233.66,234.13,1,400,1,1,233.58,234.17,505,1,2,1,233.53,234.25,10,100,1,1,233.5,234.41,100,500,1,1,233.45,234.43,15,105,1,2,233.4,234.5,110,63,2,4,AAPL,-50,-0.9252669039145908,0.011943670436897319
2024-10-21T12:27:21.983308878Z,2024-10-21T12:27:21.983142748Z,10,2,38,A,B,3,233.77,400,130,166130,13183375,233.86,233.98,295,7,3,1,233.81,233.99,2,200,2,1,233.8,234.0,105,17,2,2,233.77,234.1,400,100,1,1,233.7,234.13,1200,400,1,1,233.66,234.17,1,1,1,1,233.58,234.25,505,100,2,1,233.53,234.41,10,500,1,1,233.5,234.43,100,105,1,2,233.45,234.5,15,63,1,4,AAPL,-35,-0.6608226567768037,0.008530131139874433
2024-10-21T12:27:22.989069356Z,2024-10-21T12:27:22.988903196Z,10,2,38,C,A,0,233.98,7,130,166160,13184098,233.86,233.99,295,200,3,1,233.81,234.0,2,17,2,2,233.8,234.1,105,100,2,1,233.77,234.13,400,400,1,1,233.7,234.17,1200,1,1,1,233.66,234.25,1,100,1,1,233.58,234.41,505,500,2,1,233.53,234.43,10,105,1,2,233.5,234.5,100,63,1,4,233.45,234.59,15,60,1,1,AAPL,25,0.4813863928112966,-0.006213904770850475
2024-10-21T12:27:23.025873698Z,2024-10-21T12:27:23.025707565Z,10,2,38,C,B,3,233.77,400,130,166133,13184133,233.86,233.99,295,200,3,1,233.81,234.0,2,17,2,2,233.8,234.1,105,100,2,1,233.7,234.13,1200,400,1,1,233.66,234.17,1,1,1,1,233.58,234.25,505,100,2,1,233.53,234.41,10,500,1,1,233.5,234.43,100,105,1,2,233.45,234.5,15,63,1,4,233.4,234.59,110,60,2,1,AAPL,-85,-1.5740740740740742,0.020318701451943907
2024-10-21T12:27:23.025886464Z,2024-10-21T12:27:23.025720316Z,10,2,38,A,B,3,233.74,200,130,166148,13184134,233.86,233.99,295,200,3,1,233.81,234.0,2,17,2,2,233.8,234.1,105,100,2,1,233.74,234.13,200,400,1,1,233.7,234.17,1200,1,1,1,233.66,234.25,1,100,1,1,233.58,234.41,505,500,2,1,233.53,234.43,10,105,1,2,233.5,234.5,100,63,1,4,233.45,234.59,15,60,1,1,AAPL,-70,-1.3200221852468108,0.017039310369017853
2024-10-21T12:27:24.992972792Z,2024-10-21T12:27:24.992239712Z,10,2,38,A,A,0,233.99,7,130,733080,13186020,233.86,233.99,295,207,3,2,233.81,234.0,2,17,2,2,233.8,234.1,105,100,2,1,233.74,234.13,200,400,1,1,233.7,234.17,1200,1,1,1,233.66,234.25,1,100,1,1,233.58,234.41,505,500,2,1,233.53,234.43,10,105,1,2,233.5,234.5,100,63,1,4,233.45,234.59,15,60,1,1,AAPL,-70,-1.3675213675213675,0.01765244651028611
2024-10-21T12:27:25.038852343Z,2024-10-21T12:27:25.038119028Z,10,2,38,A,B,3,233.77,200,130,733315,13186052,233.86,233.99,295,207,3,2,233.81,234.0,2,17,2,2,233.8,234.1,105,100,2,1,233.77,234.13,200,400,1,1,233.7,234.17,1200,1,1,1,233.66,234.25,1,100,1,1,233.58,234.41,505,500,2,1,233.53,234.43,10,105,1,2,233.5,234.5,100,63,1,4,233.45,234.59,15,60,1,1,AAPL,-70,-1.389375364856976,0.01793454558980688
2024-10-21T12:27:26.131472457Z,2024-10-21T12:27:26.130738899Z,10,2,38,A,B,3,233.77,200,130,733558,13186986,233.86,233.99,295,207,3,2,233.81,234.0,2,17,2,2,233.8,234.1,105,100,2,1,233.77,234.13,400,400,2,1,233.7,234.17,1200,1,1,1,233.66,234.25,1,100,1,1,233.58,234.41,505,500,2,1,233.53,234.43,10,105,1,2,233.5,234.5,100,63,1,4,233.45,234.59,15,60,1,1,AAPL,-70,-1.4093959731543624,0.018192978639166513
2024-10-21T12:27:28.579136710Z,2024-10-21T12:27:28.578403729Z,10,2,38,C,A,0,233.99,7,130,732981,13188280,233.86,233.99,295,200,3,1,233.81,234.0,2,17,2,2,233.8,234.1,105,100,2,1,233.77,234.13,400,400,2,1,233.7,234.17,1200,1,1,1,233.66,234.25,1,100,1,1,233.58,234.41,505,500,2,1,233.53,234.43,10,105,1,2,233.5,234.5,100,63,1,4,233.45,234.59,15,60,1,1,AAPL,-70,-1.4664202094886014,0.018929067526395064
2024-10-21T12:27:29.136296936Z,2024-10-21T12:27:29.135563917Z,10,2,38,C,A,0,233.99,200,130,733019,13188524,233.86,234.0,295,17,3,2,233.81,234.1,2,100,2,1,233.8,234.13,105,400,2,1,233.77,234.17,400,1,2,1,233.7,234.25,1200,100,1,1,233.66,234.41,1,500,1,1,233.58,234.43,505,105,2,2,233.53,234.5,10,63,1,4,233.5,234.59,100,60,1,1,233.45,234.75,15,1,1,1,AAPL,-69,-1.5444371296905859,0.019936137356140356
2024-10-21T12:27:29.136314635Z,2024-10-21T12:27:29.135580379Z,10,2,38,A,A,1,234.05,400,130,734256,13188525,233.86,234.0,295,17,3,2,233.81,234.05,2,400,2,1,233.8,234.1,105,100,2,1,233.77,234.13,400,400,2,1,233.7,234.17,1200,1,1,1,233.66,234.25,1,100,1,1,233.58,234.41,505,500,2,1,233.53,234.43,10,105,1,2,233.5,234.5,100,63,1,4,233.45,234.59,15,60,1,1,AAPL,-129,-2.9134253450439145,0.037607518453854044
2024-10-21T12:27:30.582343028Z,2024-10-21T12:27:30.581609917Z,10,2,38,A,A,6,234.41,7,130,733111,13189750,233.86,234.0,295,17,3,2,233.81,234.05,2,400,2,1,233.8,234.1,105,100,2,1,233.77,234.13,400,400,2,1,233.7,234.17,1200,1,1,1,233.66,234.25,1,100,1,1,233.58,234.41,505,507,2,2,233.53,234.43,10,105,1,2,233.5,234.5,100,63,1,4,233.45,234.59,15,60,1,1,AAPL,-129,-2.9370880766926306,0.03791296531167778
2024-10-21T12:27:37.149919392Z,2024-10-21T12:27:37.149186319Z,10,2,38,C,B,3,233.77,200,130,733073,13194254,233.86,234.0,295,17,3,2,233.81,234.05,2,400,2,1,233.8,234.1,105,100,2,1,233.77,234.13,200,400,1,1,233.7,234.17,1200,1,1,1,233.66,234.25,1,100,1,1,233.58,234.41,505,507,2,2,233.53,234.43,10,105,1,2,233.5,234.5,100,63,1,4,233.45,234.59,15,60,1,1,AAPL,-252,-5.596113809854268,0.0722366041511833
2024-10-21T12:27:37.149931822Z,2024-10-21T12:27:37.149198552Z,10,2,38,A,B,3,233.78,400,130,733270,13194255,233.86,234.0,295,17,3,2,233.81,234.05,2,400,2,1,233.8,234.1,105,100,2,1,233.78,234.13,400,400,1,1,233.7,234.17,1200,1,1,1,233.66,234.25,1,100,1,1,233.58,234.41,505,507,2,2,233.53,234.43,10,105,1,2,233.5,234.5,100,63,1,4,233.45,234.59,15,60,1,1,AAPL,-252,-5.651715039577836,0.07295432436887933
2024-10-21T12:27:37.282093181Z,2024-10-21T12:27:37.281359883Z,10,2,38,A,A,1,234.02,200,130,733298,13194447,233.86,234.0,295,17,3,2,233.81,234.02,2,200,2,1,233.8,234.1,105,100,2,1,233.78,234.13,400,400,1,1,233.7,234.17,1200,1,1,1,233.66,234.25,1,100,1,1,233.58,234.41,505,507,2,2,233.53,234.43,10,105,1,2,233.5,234.5,100,63,1,4,233.45,234.59,15,60,1,1,AAPL,-189,-4.247191011235955,0.0548242345058928
2024-10-21T12:27:37.731855277Z,2024-10-21T12:27:37.731121489Z,10,2,38,A,B,3,233.79,400,130,733788,13195199,233.86,234.0,295,17,3,2,233.81,234.02,2,200,2,1,233.8,234.1,105,100,2,1,233.79,234.13,400,400,1,1,233.7,234.17,1200,1,1,1,233.66,234.25,1,100,1,1,233.58,234.41,505,507,2,2,233.53,234.43,10,105,1,2,233.5,234.5,100,63,1,4,233.45,234.59,15,60,1,1,AAPL,-189,-4.2846347607052895,0.05530757158591956
2024-10-21T12:27:37.764573144Z,2024-10-21T12:27:37.763839849Z,10,2,38,C,B,3,233.79,200,130,733295,13195270,233.86,234.0,295,17,3,2,233.81,234.02,2,200,2,1,233.8,234.1,105,100,2,1,233.79,234.13,200,400,1,1,233.7,234.17,1200,1,1,1,233.66,234.25,1,100,1,1,233.58,234.41,505,507,2,2,233.53,234.43,10,105,1,2,233.5,234.5,100,63,1,4,233.45,234.59,15,60,1,1,AAPL,-189,-4.31870114251353,0.05574731241699623
2024-10-21T12:27:37.767686766Z,2024-10-21T12:27:37.766952915Z,10,2,38,A,A,1,234.02,200,130,733851,13195276,233.86,234.0,295,17,3,2,233.81,234.02,2,400,2,2,233.8,234.1,105,100,2,1,233.79,234.13,200,400,1,1,233.7,234.17,1200,1,1,1,233.66,234.25,1,100,1,1,233.58,234.41,505,507,2,2,233.53,234.43,10,105,1,2,233.5,234.5,100,63,1,4,233.45,234.59,15,60,1,1,AAPL,-189,-4.349827387802071,0.05614910093238733
2024-10-21T12:27:39.526116351Z,2024-10-21T12:27:39.525383410Z,10,2,38,C,A,1,234.02,200,130,732941,13197083,233.86,234.0,295,17,3,2,233.81,234.02,2,200,2,1,233.8,234.1,105,100,2,1,233.79,234.13,200,400,1,1,233.7,234.17,1200,1,1,1,233.66,234.25,1,100,1,1,233.58,234.41,505,507,2,2,233.53,234.43,10,105,1,2,233.5,234.5,100,63,1,4,233.45,234.59,15,60,1,1,AAPL,-189,-4.378378378378379,0.056517647154723474
2024-10-21T12:27:39.526127909Z,2024-10-21T12:27:39.525394818Z,10,2,38,C,A,1,234.02,200,130,733091,13197084,233.86,234.0,295,17,3,2,233.81,234.1,2,100,2,1,233.8,234.13,105,400,2,1,233.79,234.17,200,1,1,1,233.7,234.25,1200,100,1,1,233.66,234.41,1,507,1,2,233.58,234.43,505,105,2,2,233.53,234.5,10,63,1,4,233.5,234.59,100,60,1,1,233.45,234.75,15,1,1,1,AAPL,-188,-4.522689994532532,0.0583804722231108
2024-10-21T12:27:39.527631797Z,2024-10-21T12:27:39.526899044Z,10,2,38,C,A,5,234.41,7,130,732753,13197088,233.86,234.0,295,17,3,2,233.81,234.1,2,100,2,1,233.8,234.13,105,400,2,1,233.79,234.17,200,1,1,1,233.7,234.25,1200,100,1,1,233.66,234.41,1,500,1,1,233.58,234.43,505,105,2,2,233.53,234.5,10,63,1,4,233.5,234.59,100,60,1,1,233.45,234.75,15,1,1,1,AAPL,-188,-4.687262872628726,0.06050483678269529
2024-10-21T12:27:39.593636447Z,2024-10-21T12:27:39.592903496Z,10,2,38,A,B,1,233.84,100,130,732951,13197554,233.86,234.0,295,17,3,2,233.84,234.1,100,100,1,1,233.81,234.13,2,400,2,1,233.8,234.17,105,1,2,1,233.79,234.25,200,100,1,1,233.7,234.41,1200,500,1,1,233.66,234.43,1,105,1,2,233.58,234.5,505,63,2,4,233.53,234.59,10,60,1,1,233.5,234.75,100,1,1,1,AAPL,-88,-2.170606372045221,0.02801895004160932
2024-10-21T12:27:39.593996622Z,2024-10-21T12:27:39.593262886Z,10,2,38,C,B,1,233.84,100,130,733736,13197558,233.86,234.0,295,17,3,2,233.81,234.1,2,100,2,1,233.8,234.13,105,400,2,1,233.79,234.17,200,1,1,1,233.7,234.25,1200,100,1,1,233.66,234.41,1,500,1,1,233.58,234.43,505,105,2,2,233.53,234.5,10,63,1,4,233.5,234.59,100,60,1,1,233.45,234.75,15,1,1,1,AAPL,-103,-2.6248725790010194,0.03388277792040295
2024-10-21T12:27:39.712483751Z,2024-10-21T12:27:39.711750527Z,10,2,38,A,A,1,234.02,400,130,733224,13197970,233.86,234.0,295,17,3,2,233.81,234.02,2,400,2,1,233.8,234.1,105,100,2,1,233.79,234.13,200,400,1,1,233.7,234.17,1200,1,1,1,233.66,234.25,1,100,1,1,233.58,234.41,505,500,2,1,233.53,234.43,10,105,1,2,233.5,234.5,100,63,1,4,233.45,234.59,15,60,1,1,AAPL,-163,-4.161021109474718,0.053711923124320854
2024-10-21T12:27:40.732061815Z,2024-10-21T12:27:40.731328339Z,10,2,38,A,A,1,234.01,400,130,733476,13198996,233.86,234.0,295,17,3,2,233.81,234.01,2,400,2,1,233.8,234.1,105,100,2,1,233.79,234.13,200,400,1,1,233.7,234.17,1200,1,1,1,233.66,234.25,1,100,1,1,233.58,234.41,505,500,2,1,233.53,234.43,10,105,1,2,233.5,234.5,100,63,1,4,233.45,234.59,15,60,1,1,AAPL,-163,-4.167613636363636,0.053797021778746394
2024-10-21T12:27:40.758541085Z,2024-10-21T12:27:40.757807867Z,10,2,38,C,A,1,234.01,400,130,733218,13199068,233.86,234.0,295,17,3,2,233.81,234.1,2,100,2,1,233.8,234.13,105,400,2,1,233.79,234.17,200,1,1,1,233.7,234.25,1200,100,1,1,233.66,234.41,1,500,1,1,233.58,234.43,505,105,2,2,233.53,234.5,10,63,1,4,233.5,234.59,100,60,1,1,233.45,234.75,15,1,1,1,AAPL,-162,-4.2631578947368425,0.05503034065065181
2024-10-21T12:27:40.758553589Z,2024-10-21T12:27:40.757820402Z,10,2,38,A,A,1,234.02,200,130,733187,13199069,233.86,234.0,295,17,3,2,233.81,234.02,2,200,2,1,233.8,234.1,105,100,2,1,233.79,234.13,200,400,1,1,233.7,234.17,1200,1,1,1,233.66,234.25,1,100,1,1,233.58,234.41,505,500,2,1,233.53,234.43,10,105,1,2,233.5,234.5,100,63,1,4,233.45,234.59,15,60,1,1,AAPL,-222,-5.844757149341806,0.0754461797780695
2024-10-21T12:27:41.106714797Z,2024-10-21T12:27:41.105981707Z,10,2,38,C,A,1,234.02,200,130,733090,13199310,233.86,234.0,295,17,3,2,233.81,234.1,2,100,2,1,233.8,234.13,105,400,2,1,233.79,234.17,200,1,1,1,233.7,234.25,1200,100,1,1,233.66,234.41,1,500,1,1,233.58,234.43,505,105,2,2,233.53,234.5,10,63,1,4,233.5,234.59,100,60,1,1,233.45,234.75,15,1,1,1,AAPL,-221,-5.9756647138350605,0.07713598063595109
2024-10-21T12:27:41.176308255Z,2024-10-21T12:27:41.175574942Z,10,2,38,A,A,1,234.06,200,130,733313,13199399,233.86,234.0,295,17,3,2,233.81,234.06,2,200,2,1,233.8,234.1,105,100,2,1,233.79,234.13,200,400,1,1,233.7,234.17,1200,1,1,1,233.66,234.25,1,100,1,1,233.58,234.41,505,500,2,1,233.53,234.43,10,105,1,2,233.5,234.5,100,63,1,4,233.45,234.59,15,60,1,1,AAPL,-281,-7.594594594594595,0.09803369660788452
2024-10-21T12:27:41.223548018Z,2024-10-21T12:27:41.222814573Z,10,2,38,A,A,1,234.06,200,130,733445,13199432,233.86,234.0,295,17,3,2,233.81,234.06,2,400,2,2,233.8,234.1,105,100,2,1,233.79,234.13,200,400,1,1,233.7,234.17,1200,1,1,1,233.66,234.25,1,100,1,1,233.58,234.41,505,500,2,1,233.53,234.43,10,105,1,2,233.5,234.5,100,63,1,4,233.45,234.59,15,60,1,1,AAPL,-281,-7.591388771633601,0.09799231471822313
2024-10-21T12:27:41.320586998Z,2024-10-21T12:27:41.319854032Z,10,2,38,C,A,1,234.06,200,130,732966,13199474,233.86,234.0,295,17,3,2,233.81,234.06,2,200,2,1,233.8,234.1,105,100,2,1,233.79,234.13,200,400,1,1,233.7,234.17,1200,1,1,1,233.66,234.25,1,100,1,1,233.58,234.41,505,500,2,1,233.53,234.43,10,105,1,2,233.5,234.5,100,63,1,4,233.45,234.59,15,60,1,1,AAPL,-281,-7.588379705400982,0.09795347263357365
2024-10-21T12:27:41.320600607Z,2024-10-21T12:27:41.319866876Z,10,2,38,A,A,1,234.04,200,130,733731,13199475,233.86,234.0,295,17,3,2,233.81,234.04,2,200,2,1,233.8,234.1,105,100,2,1,233.79,234.13,200,400,1,1,233.7,234.17,1200,1,1,1,233.66,234.25,1,100,1,1,233.58,234.41,505,500,2,1,233.53,234.43,10,105,1,2,233.5,234.5,100,63,1,4,233.45,234.59,15,60,1,1,AAPL,-281,-7.585549821357681,0.09791694349560835
2024-10-21T12:27:41.530250934Z,2024-10-21T12:27:41.529517717Z,10,2,38,A,A,6,234.38,7,130,733217,13199682,233.86,234.0,295,17,3,2,233.81,234.04,2,200,2,1,233.8,234.1,105,100,2,1,233.79,234.13,200,400,1,1,233.7,234.17,1200,1,1,1,233.66,234.25,1,100,1,1,233.58,234.38,505,7,2,1,233.53,234.41,10,500,1,1,233.5,234.43,100,105,1,2,233.45,234.5,15,63,1,4,AAPL,-344,-9.272237196765499,0.11968929702594261
2024-10-21T12:27:46.418013842Z,2024-10-21T12:27:46.417280824Z,10,2,38,C,B,3,233.79,200,130,733018,13203166,233.86,234.0,295,17,3,2,233.81,234.04,2,200,2,1,233.8,234.1,105,100,2,1,233.7,234.13,1200,400,1,1,233.66,234.17,1,1,1,1,233.58,234.25,505,100,2,1,233.53,234.38,10,7,1,1,233.5,234.41,100,500,1,1,233.45,234.43,15,105,1,2,233.4,234.5,110,63,2,4,AAPL,-324,-9.778293673824724,0.1262216519160626
2024-10-21T12:27:46.418026002Z,2024-10-21T12:27:46.417292639Z,10,2,38,A,B,3,233.77,400,130,733363,13203167,233.86,234.0,295,17,3,2,233.81,234.04,2,200,2,1,233.8,234.1,105,100,2,1,233.77,234.13,400,400,1,1,233.7,234.17,1200,1,1,1,233.66,234.25,1,100,1,1,233.58,234.38,505,7,2,1,233.53,234.41,10,500,1,1,233.5,234.43,100,105,1,2,233.45,234.5,15,63,1,4,AAPL,-309,-9.264852859522486,0.11959397740513666
2024-10-21T12:27:46.473030357Z,2024-10-21T12:27:46.472297071Z,10,2,38,A,A,1,234.03,200,130,733286,13203213,233.86,234.0,295,17,3,2,233.81,234.03,2,200,2,1,233.8,234.1,105,100,2,1,233.77,234.13,400,400,1,1,233.7,234.17,1200,1,1,1,233.66,234.25,1,100,1,1,233.58,234.38,505,7,2,1,233.53,234.41,10,500,1,1,233.5,234.43,100,105,1,2,233.45,234.5,15,63,1,4,AAPL,-309,-9.20915380521554,0.11887499443333197
2024-10-21T12:27:47.209450267Z,2024-10-21T12:27:47.208717142Z,10,2,38,C,A,1,234.03,200,130,733125,13204087,233.86,234.0,295,17,3,2,233.81,234.1,2,100,2,1,233.8,234.13,105,400,2,1,233.77,234.17,400,1,1,1,233.7,234.25,1200,100,1,1,233.66,234.38,1,7,1,1,233.58,234.41,505,500,2,1,233.53,234.43,10,105,1,2,233.5,234.5,100,63,1,4,233.45,234.59,15,60,1,1,AAPL,-249,-7.3909928352098255,0.09540553352955983
2024-10-21T12:27:47.310139513Z,2024-10-21T12:27:47.309406274Z,10,2,38,A,A,1,234.03,200,130,733239,13204445,233.86,234.0,295,17,3,2,233.81,234.03,2,200,2,1,233.8,234.1,105,100,2,1,233.77,234.13,400,400,1,1,233.7,234.17,1200,1,1,1,233.66,234.25,1,100,1,1,233.58,234.38,505,7,2,1,233.53,234.41,10,500,1,1,233.5,234.43,100,105,1,2,233.45,234.5,15,63,1,4,AAPL,-312,-9.21259842519685,0.11891945879887134
2024-10-21T12:27:47.985465401Z,2024-10-21T12:27:47.985298442Z,10,2,38,A,B,3,233.78,400,130,166959,13205236,233.86,234.0,295,17,3,2,233.81,234.03,2,200,2,1,233.8,234.1,105,100,2,1,233.78,234.13,400,400,1,1,233.7,234.17,1200,1,1,1,233.66,234.25,1,100,1,1,233.58,234.38,505,7,2,1,233.53,234.41,10,500,1,1,233.5,234.43,100,105,1,2,233.45,234.5,15,63,1,4,AAPL,-312,-9.16777251184834,0.11834083015258298
2024-10-21T12:27:50.060871934Z,2024-10-21T12:27:50.060705561Z,10,2,38,C,A,1,234.03,200,130,166373,13206376,233.86,234.0,295,17,3,2,233.81,234.1,2,100,2,1,233.8,234.13,105,400,2,1,233.78,234.17,400,1,1,1,233.7,234.25,1200,100,1,1,233.66,234.38,1,7,1,1,233.58,234.41,505,500,2,1,233.53,234.43,10,105,1,2,233.5,234.5,100,63,1,4,233.45,234.59,15,60,1,1,AAPL,-193,-5.54432887568103,0.07156814601791944
2024-10-21T12:27:50.061591231Z,2024-10-21T12:27:50.061424726Z,10,2,38,A,B,0,233.87,4,130,166505,13206379,233.87,234.0,4,17,1,2,233.86,234.1,295,100,3,1,233.81,234.13,2,400,2,1,233.8,234.17,105,1,2,1,233.78,234.25,400,100,1,1,233.7,234.38,1200,7,1,1,233.66,234.41,1,500,1,1,233.58,234.43,505,105,2,2,233.53,234.5,10,63,1,4,233.5,234.59,100,60,1,1,AAPL,-93,-2.5608077099586963,0.033055806071321095
2024-10-21T12:27:50.061891362Z,2024-10-21T12:27:50.061724093Z,10,2,38,A,B,0,233.87,100,128,167269,13206382,233.87,234.0,104,17,2,2,233.86,234.1,295,100,3,1,233.81,234.13,2,400,2,1,233.8,234.17,105,1,2,1,233.78,234.25,400,100,1,1,233.7,234.38,1200,7,1,1,233.66,234.41,1,500,1,1,233.58,234.43,505,105,2,2,233.53,234.5,10,63,1,4,233.5,234.59,100,60,1,1,AAPL,-93,-2.4651560495938436,0.031821100816754586
2024-10-21T12:27:50.062283396Z,2024-10-21T12:27:50.062117451Z,10,2,38,C,B,0,233.87,100,130,165945,13206387,233.87,234.0,4,17,1,2,233.86,234.1,295,100,3,1,233.81,234.13,2,400,2,1,233.8,234.17,105,1,2,1,233.78,234.25,400,100,1,1,233.7,234.38,1200,7,1,1,233.66,234.41,1,500,1,1,233.58,234.43,505,105,2,2,233.53,234.5,10,63,1,4,233.5,234.59,100,60,1,1,AAPL,-93,-2.381752701080432,0.030744501076978497
2024-10-21T12:27:50.063258837Z,2024-10-21T12:27:50.063092822Z,10,2,38,C,A,5,234.38,7,130,166015,13206393,233.87,234.0,4,17,1,2,233.86,234.1,295,100,3,1,233.81,234.13,2,400,2,1,233.8,234.17,105,1,2,1,233.78,234.25,400,100,1,1,233.7,234.41,1200,500,1,1,233.66,234.43,1,105,1,2,233.58,234.5,505,63,2,4,233.53,234.59,10,60,1,1,233.5,234.75,100,1,1,1,AAPL,-92,-2.3353846153846156,0.030145965527941108
2024-10-21T12:27:50.065683975Z,2024-10-21T12:27:50.065517946Z,10,2,38,C,B,0,233.87,4,130,166029,13206394,233.86,234.0,295,17,3,2,233.81,234.1,2,100,2,1,233.8,234.13,105,400,2,1,233.78,234.17,400,1,1,1,233.7,234.25,1200,100,1,1,233.66,234.41,1,500,1,1,233.58,234.43,505,105,2,2,233.53,234.5,10,63,1,4,233.5,234.59,100,60,1,1,233.45,234.75,15,1,1,1,AAPL,-107,-2.7813455657492354,0.03590258623526969
2024-10-21T12:27:50.072777187Z,2024-10-21T12:27:50.072608485Z,10,2,38,T,N,0,233.92,250,0,168702,13206395,233.86,234.0,295,17,3,2,233.81,234.1,2,100,2,1,233.8,234.13,105,400,2,1,233.78,234.17,400,1,1,1,233.7,234.25,1200,100,1,1,233.66,234.41,1,500,1,1,233.58,234.43,505,105,2,2,233.53,234.5,10,63,1,4,233.5,234.59,100,60,1,1,233.45,234.75,15,1,1,1,AAPL,-107,-2.845744680851064,0.03673387264997869
2024-10-21T12:27:50.072777187Z,2024-10-21T12:27:50.072608485Z,10,2,38,T,N,0,233.87,73,130,168702,13206396,233.86,234.0,295,17,3,2,233.81,234.1,2,100,2,1,233.8,234.13,105,400,2,1,233.78,234.17,400,1,1,1,233.7,234.25,1200,100,1,1,233.66,234.41,1,500,1,1,233.58,234.43,505,105,2,2,233.53,234.5,10,63,1,4,233.5,234.59,100,60,1,1,233.45,234.75,15,1,1,1,AAPL,-107,-2.909365558912387,0.03755511330741024
2024-10-21T12:27:50.167562575Z,2024-10-21T12:27:50.167395987Z,10,2,38,A,A,1,234.06,200,130,166588,13206479,233.86,234.0,295,17,3,2,233.81,234.06,2,200,2,1,233.8,234.1,105,100,2,1,233.78,234.13,400,400,1,1,233.7,234.17,1200,1,1,1,233.66,234.25,1,100,1,1,233.58,234.41,505,500,2,1,233.53,234.43,10,105,1,2,233.5,234.5,100,63,1,4,233.45,234.59,15,60,1,1,AAPL,-167,-4.5383767903048104,0.058582962897015096
2024-10-21T12:27:51.736371710Z,2024-10-21T12:27:51.736205355Z,10,2,38,A,A,1,234.06,200,130,166355,13207413,233.86,234.0,295,17,3,2,233.81,234.06,2,400,2,2,233.8,234.1,105,100,2,1,233.78,234.13,400,400,1,1,233.7,234.17,1200,1,1,1,233.66,234.25,1,100,1,1,233.58,234.41,505,500,2,1,233.53,234.43,10,105,1,2,233.5,234.5,100,63,1,4,233.45,234.59,15,60,1,1,AAPL,-167,-4.5383767903048104,0.058582962897015096
2024-10-21T12:27:51.790967984Z,2024-10-21T12:27:51.790801843Z,10,2,38,C,A,1,234.06,200,130,166141,13207602,233.86,234.0,295,17,3,2,233.81,234.06,2,200,2,1,233.8,234.1,105,100,2,1,233.78,234.13,400,400,1,1,233.7,234.17,1200,1,1,1,233.66,234.25,1,100,1,1,233.58,234.41,505,500,2,1,233.53,234.43,10,105,1,2,233.5,234.5,100,63,1,4,233.45,234.59,15,60,1,1,AAPL,-167,-4.536097212294496,0.05855353730276202
2024-10-21T12:27:51.790980861Z,2024-10-21T12:27:51.790814229Z,10,2,38,A,A,1,234.05,200,130,166632,13207603,233.86,234.0,295,17,3,2,233.81,234.05,2,200,2,1,233.8,234.1,105,100,2,1,233.78,234.13,400,400,1,1,233.7,234.17,1200,1,1,1,233.66,234.25,1,100,1,1,233.58,234.41,505,500,2,1,233.53,234.43,10,105,1,2,233.5,234.5,100,63,1,4,233.45,234.59,15,60,1,1,AAPL,-167,-4.53393665158371,0.05852564802564711
2024-10-21T12:27:52.065722099Z,2024-10-21T12:27:52.065555514Z,10,2,38,A,A,6,234.41,7,130,166585,13207879,233.86,234.0,295,17,3,2,233.81,234.05,2,200,2,1,233.8,234.1,105,100,2,1,233.78,234.13,400,400,1,1,233.7,234.17,1200,1,1,1,233.66,234.25,1,100,1,1,233.58,234.41,505,507,2,2,233.53,234.43,10,105,1,2,233.5,234.5,100,63,1,4,233.45,234.59,15,60,1,1,AAPL,-167,-4.531886024423338,0.05849917780944375
2024-10-21T12:27:52.393306163Z,2024-10-21T12:27:52.393140055Z,10,2,38,A,B,0,233.91,100,130,166108,13208151,233.91,234.0,100,17,1,2,233.86,234.05,295,200,3,1,233.81,234.1,2,100,2,1,233.8,234.13,105,400,2,1,233.78,234.17,400,1,1,1,233.7,234.25,1200,100,1,1,233.66,234.41,1,507,1,2,233.58,234.43,505,105,2,2,233.53,234.5,10,63,1,4,233.5,234.59,100,60,1,1,AAPL,-67,-1.7676962676962675,0.022818044787481683
2024-10-21T12:27:52.393974163Z,2024-10-21T12:27:52.393807534Z,10,2,38,C,B,0,233.91,100,130,166629,13208153,233.86,234.0,295,17,3,2,233.81,234.05,2,200,2,1,233.8,234.1,105,100,2,1,233.78,234.13,400,400,1,1,233.7,234.17,1200,1,1,1,233.66,234.25,1,100,1,1,233.58,234.41,505,507,2,2,233.53,234.43,10,105,1,2,233.5,234.5,100,63,1,4,233.45,234.59,15,60,1,1,AAPL,-82,-2.163996229971725,0.027933624004189316
2024-10-21T12:27:53.197081371Z,2024-10-21T12:27:53.196914522Z,10,2,38,A,B,1,233.81,200,130,166849,13208530,233.86,234.0,295,17,3,2,233.81,234.05,202,200,3,1,233.8,234.1,105,100,2,1,233.7,234.13,1200,400,1,1,233.66,234.17,1,1,1,1,233.58,234.25,505,100,2,1,233.53,234.41,10,507,1,2,233.5,234.43,100,105,1,2,233.45,234.5,15,63,1,4,233.4,234.59,110,60,2,1,AAPL,-192,-4.924545183417835,0.06356776025761963
2024-10-21T12:27:55.777527005Z,2024-10-21T12:27:55.777360755Z,10,2,38,A,B,1,233.82,200,130,166250,13210010,233.86,234.0,295,17,3,2,233.82,234.05,200,200,1,1,233.81,234.1,2,100,2,1,233.8,234.13,105,400,2,1,233.7,234.17,1200,1,1,1,233.66,234.25,1,100,1,1,233.58,234.41,505,507,2,2,233.53,234.43,10,105,1,2,233.5,234.5,100,63,1,4,233.45,234.59,15,60,1,1,AAPL,-177,-4.543757292882147,0.058652416315587305
2024-10-21T12:27:57.069810253Z,2024-10-21T12:27:57.069644133Z,10,2,38,C,A,6,234.41,7,130,166120,13211098,233.86,234.0,295,17,3,2,233.82,234.05,200,200,1,1,233.81,234.1,2,100,2,1,233.8,234.13,105,400,2,1,233.7,234.17,1200,1,1,1,233.66,234.25,1,100,1,1,233.58,234.41,505,500,2,1,233.53,234.43,10,105,1,2,233.5,234.5,100,63,1,4,233.45,234.59,15,60,1,1,AAPL,-177,-4.547530687981729,0.05870112462592126
2024-10-21T12:27:59.075099035Z,2024-10-21T12:27:59.074932933Z,10,2,38,A,A,2,234.08,7,130,166102,13212016,233.86,234.0,295,17,3,2,233.82,234.05,200,200,1,1,233.81,234.08,2,7,2,1,233.8,234.1,105,100,2,1,233.7,234.13,1200,400,1,1,233.66,234.17,1,1,1,1,233.58,234.25,505,100,2,1,233.53,234.41,10,500,1,1,233.5,234.43,100,105,1,2,233.45,234.5,15,63,1,4,AAPL,-240,-6.13222612583839,0.07915693037509325
2024-10-21T12:28:13.140654755Z,2024-10-21T12:28:13.140488443Z,10,2,38,C,A,2,234.08,7,130,166312,13223358,233.86,234.0,295,17,3,2,233.82,234.05,200,200,1,1,233.81,234.1,2,100,2,1,233.8,234.13,105,400,2,1,233.7,234.17,1200,1,1,1,233.66,234.25,1,100,1,1,233.58,234.41,505,500,2,1,233.53,234.43,10,105,1,2,233.5,234.5,100,63,1,4,233.45,234.59,15,60,1,1,AAPL,-98,-2.0718816067653276,0.026744576068570364
2024-10-21T12:28:13.787785757Z,2024-10-21T12:28:13.787619066Z,10,2,38,C,B,0,233.86,100,130,166691,13223694,233.86,234.0,195,17,2,2,233.82,234.05,200,200,1,1,233.81,234.1,2,100,2,1,233.8,234.13,105,400,2,1,233.7,234.17,1200,1,1,1,233.66,234.25,1,100,1,1,233.58,234.41,505,500,2,1,233.53,234.43,10,105,1,2,233.5,234.5,100,63,1,4,233.45,234.59,15,60,1,1,AAPL,12,0.3174603174603175,-0.004097889368459276
2024-10-21T12:28:15.143565718Z,2024-10-21T12:28:15.143399309Z,10,2,38,A,A,2,234.07,7,130,166409,13224881,233.86,234.0,195,17,2,2,233.82,234.05,200,200,1,1,233.81,234.07,2,7,2,1,233.8,234.1,105,100,2,1,233.7,234.13,1200,400,1,1,233.66,234.17,1,1,1,1,233.58,234.25,505,100,2,1,233.53,234.41,10,500,1,1,233.5,234.43,100,105,1,2,233.45,234.5,15,63,1,4,AAPL,-51,-1.3421052631578947,0.01732436650113112
2024-10-21T12:28:15.998678832Z,2024-10-21T12:28:15.998512488Z,10,2,38,A,A,1,234.05,200,130,166344,13225383,233.86,234.0,195,17,2,2,233.82,234.05,200,400,1,2,233.81,234.07,2,7,2,1,233.8,234.1,105,100,2,1,233.7,234.13,1200,400,1,1,233.66,234.17,1,1,1,1,233.58,234.25,505,100,2,1,233.53,234.41,10,500,1,1,233.5,234.43,100,105,1,2,233.45,234.5,15,63,1,4,AAPL,-66,-1.7254901960784315,0.02227323397915512
2024-10-21T12:28:16.004651224Z,2024-10-21T12:28:16.004484708Z,10,2,38,C,A,1,234.05,200,130,166516,13225389,233.86,234.0,195,17,2,2,233.82,234.05,200,200,1,1,233.81,234.07,2,7,2,1,233.8,234.1,105,100,2,1,233.7,234.13,1200,400,1,1,233.66,234.17,1,1,1,1,233.58,234.25,505,100,2,1,233.53,234.41,10,500,1,1,233.5,234.43,100,105,1,2,233.45,234.5,15,63,1,4,AAPL,-66,-1.7206703910614527,0.022211018241783183
2024-10-21T12:28:16.009541505Z,2024-10-21T12:28:16.009375121Z,10,2,38,A,A,1,234.05,200,130,166384,13225390,233.86,234.0,195,17,2,2,233.82,234.05,200,400,1,2,233.81,234.07,2,7,2,1,233.8,234.1,105,100,2,1,233.7,234.13,1200,400,1,1,233.66,234.17,1,1,1,1,233.58,234.25,505,100,2,1,233.53,234.41,10,500,1,1,233.5,234.43,100,105,1,2,233.45,234.5,15,63,1,4,AAPL,-66,-1.7170731707317073,0.022164584057305585
2024-10-21T12:28:18.439960157Z,2024-10-21T12:28:18.439793678Z,10,2,38,C,B,1,233.82,200,130,166479,13226392,233.86,234.0,195,17,2,2,233.81,234.05,2,400,2,2,233.8,234.07,105,7,2,1,233.7,234.1,1200,100,1,1,233.66,234.13,1,400,1,1,233.58,234.17,505,1,2,1,233.53,234.25,10,100,1,1,233.5,234.41,100,500,1,1,233.45,234.43,15,105,1,2,233.4,234.5,110,63,2,4,AAPL,-176,-3.949509116409537,0.05098165196911803
2024-10-21T12:28:18.439973348Z,2024-10-21T12:28:18.439806868Z,10,2,38,A,B,3,233.77,400,130,166480,13226393,233.86,234.0,195,17,2,2,233.81,234.05,2,400,2,2,233.8,234.07,105,7,2,1,233.77,234.1,400,100,1,1,233.7,234.13,1200,400,1,1,233.66,234.17,1,1,1,1,233.58,234.25,505,100,2,1,233.53,234.41,10,500,1,1,233.5,234.43,100,105,1,2,233.45,234.5,15,63,1,4,AAPL,-161,-3.663716814159292,0.047292544472634875
2024-10-21T12:28:18.595699607Z,2024-10-21T12:28:18.595532956Z,10,2,38,A,B,3,233.78,400,130,166651,13226507,233.86,234.0,195,17,2,2,233.81,234.05,2,400,2,2,233.8,234.07,105,7,2,1,233.78,234.1,400,100,1,1,233.7,234.13,1200,400,1,1,233.66,234.17,1,1,1,1,233.58,234.25,505,100,2,1,233.53,234.41,10,500,1,1,233.5,234.43,100,105,1,2,233.45,234.5,15,63,1,4,AAPL,-161,-3.7054085155350975,0.047830715609070686
2024-10-21T12:28:21.754746040Z,2024-10-21T12:28:21.754579574Z,10,2,38,C,A,1,234.05,200,130,166466,13230028,233.86,234.0,195,17,2,2,233.81,234.05,2,200,2,1,233.8,234.07,105,7,2,1,233.78,234.1,400,100,1,1,233.7,234.13,1200,400,1,1,233.66,234.17,1,1,1,1,233.58,234.25,505,100,2,1,233.53,234.41,10,500,1,1,233.5,234.43,100,105,1,2,233.45,234.5,15,63,1,4,AAPL,-98,-2.2554660529344073,0.029114348631608247
2024-10-21T12:28:21.754755709Z,2024-10-21T12:28:21.754589712Z,10,2,38,C,A,1,234.05,200,130,165997,13230029,233.86,234.0,195,17,2,2,233.81,234.07,2,7,2,1,233.8,234.1,105,100,2,1,233.78,234.13,400,400,1,1,233.7,234.17,1200,1,1,1,233.66,234.25,1,100,1,1,233.58,234.41,505,500,2,1,233.53,234.43,10,105,1,2,233.5,234.5,100,63,1,4,233.45,234.59,15,60,1,1,AAPL,-38,-0.8855932203389831,0.011431548583581206
2024-10-21T12:28:21.754767171Z,2024-10-21T12:28:21.754600821Z,10,2,38,A,A,1,234.07,400,130,166350,13230030,233.86,234.0,195,17,2,2,233.81,234.07,2,407,2,2,233.8,234.1,105,100,2,1,233.78,234.13,400,400,1,1,233.7,234.17,1200,1,1,1,233.66,234.25,1,100,1,1,233.58,234.41,505,500,2,1,233.53,234.43,10,105,1,2,233.5,234.5,100,63,1,4,233.45,234.59,15,60,1,1,AAPL,-38,-0.8949950932286554,0.011552911263699514
2024-10-21T12:28:21.805412137Z,2024-10-21T12:28:21.805245495Z,10,2,38,A,B,3,233.79,400,130,166642,13230137,233.86,234.0,195,17,2,2,233.81,234.07,2,407,2,2,233.8,234.1,105,100,2,1,233.79,234.13,400,400,1,1,233.7,234.17,1200,1,1,1,233.66,234.25,1,100,1,1,233.58,234.41,505,500,2,1,233.53,234.43,10,105,1,2,233.5,234.5,100,63,1,4,233.45,234.59,15,60,1,1,AAPL,-38,-0.903107861060329,0.011657633722595024
2024-10-21T12:28:21.865391217Z,2024-10-21T12:28:21.865225042Z,10,2,38,C,B,3,233.79,200,130,166175,13230295,233.86,234.0,195,17,2,2,233.81,234.07,2,407,2,2,233.8,234.1,105,100,2,1,233.79,234.13,200,400,1,1,233.7,234.17,1200,1,1,1,233.66,234.25,1,100,1,1,233.58,234.41,505,500,2,1,233.53,234.43,10,105,1,2,233.5,234.5,100,63,1,4,233.45,234.59,15,60,1,1,AAPL,-38,-0.9101796407185628,0.011748918740229347
2024-10-21T12:28:32.979289251Z,2024-10-21T12:28:32.979122877Z,10,2,38,A,B,2,233.8,200,130,166374,13238520,233.86,234.0,195,17,2,2,233.81,234.07,2,407,2,2,233.8,234.1,305,100,3,1,233.7,234.13,1200,400,1,1,233.66,234.17,1,1,1,1,233.58,234.25,505,100,2,1,233.53,234.41,10,500,1,1,233.5,234.43,100,105,1,2,233.45,234.5,15,63,1,4,233.4,234.59,110,60,2,1,AAPL,-148,-3.3159073935772967,0.04280289821304812
2024-10-21T12:28:35.114875495Z,2024-10-21T12:28:35.114709429Z,10,2,38,C,B,2,233.8,200,130,166066,13241058,233.86,234.0,195,17,2,2,233.81,234.07,2,407,2,2,233.8,234.1,105,100,2,1,233.7,234.13,1200,400,1,1,233.66,234.17,1,1,1,1,233.58,234.25,505,100,2,1,233.53,234.41,10,500,1,1,233.5,234.43,100,105,1,2,233.45,234.5,15,63,1,4,233.4,234.59,110,60,2,1,AAPL,-208,-4.285504047093451,0.05531879264018138
2024-10-21T12:28:35.114888161Z,2024-10-21T12:28:35.114721686Z,10,2,38,A,B,3,233.78,200,130,166475,13241059,233.86,234.0,195,17,2,2,233.81,234.07,2,407,2,2,233.8,234.1,105,100,2,1,233.78,234.13,200,400,1,1,233.7,234.17,1200,1,1,1,233.66,234.25,1,100,1,1,233.58,234.41,505,500,2,1,233.53,234.43,10,105,1,2,233.5,234.5,100,63,1,4,233.45,234.59,15,60,1,1,AAPL,-193,-4.037656903765691,0.052119494593197
2024-10-21T12:28:35.213164931Z,2024-10-21T12:28:35.212998331Z,10,2,38,A,A,1,234.06,400,130,166600,13241339,233.86,234.0,195,17,2,2,233.81,234.06,2,400,2,1,233.8,234.07,105,7,2,1,233.78,234.1,200,100,1,1,233.7,234.13,1200,400,1,1,233.66,234.17,1,1,1,1,233.58,234.25,505,100,2,1,233.53,234.41,10,500,1,1,233.5,234.43,100,105,1,2,233.45,234.5,15,63,1,4,AAPL,-193,-4.037656903765691,0.052119494593197
2024-10-21T12:28:35.345220081Z,2024-10-21T12:28:35.345053997Z,10,2,38,A,B,3,233.78,200,130,166084,13241459,233.86,234.0,195,17,2,2,233.81,234.06,2,400,2,1,233.8,234.07,105,7,2,1,233.78,234.1,400,100,2,1,233.7,234.13,1200,400,1,1,233.66,234.17,1,1,1,1,233.58,234.25,505,100,2,1,233.53,234.41,10,500,1,1,233.5,234.43,100,105,1,2,233.45,234.5,15,63,1,4,AAPL,-193,-4.084656084656085,0.05272617654084268
2024-10-21T12:28:42.162258578Z,2024-10-21T12:28:42.162092040Z,10,2,38,C,B,3,233.78,200,130,166538,13247773,233.86,234.0,195,17,2,2,233.81,234.06,2,400,2,1,233.8,234.07,105,7,2,1,233.78,234.1,200,100,1,1,233.7,234.13,1200,400,1,1,233.66,234.17,1,1,1,1,233.58,234.25,505,100,2,1,233.53,234.41,10,500,1,1,233.5,234.43,100,105,1,2,233.45,234.5,15,63,1,4,AAPL,-158,-2.921417565485362,0.03771068484466283
2024-10-21T12:28:42.162271836Z,2024-10-21T12:28:42.162105350Z,10,2,38,A,B,1,233.82,200,130,166486,13247774,233.86,234.0,195,17,2,2,233.82,234.06,200,400,1,1,233.81,234.07,2,7,2,1,233.8,234.1,105,100,2,1,233.7,234.13,1200,400,1,1,233.66,234.17,1,1,1,1,233.58,234.25,505,100,2,1,233.53,234.41,10,500,1,1,233.5,234.43,100,105,1,2,233.45,234.5,15,63,1,4,AAPL,-158,-3.0426409903713894,0.03927547942441615
2024-10-21T12:28:45.429450324Z,2024-10-21T12:28:45.429284120Z,10,2,38,C,B,1,233.82,200,130,166204,13250330,233.86,234.0,195,17,2,2,233.81,234.06,2,400,2,1,233.8,234.07,105,7,2,1,233.7,234.1,1200,100,1,1,233.66,234.13,1,400,1,1,233.58,234.17,505,1,2,1,233.53,234.25,10,100,1,1,233.5,234.41,100,500,1,1,233.45,234.43,15,105,1,2,233.4,234.5,110,63,2,4,AAPL,-268,-4.764444444444444,0.0615011236418368
2024-10-21T12:28:45.429463288Z,2024-10-21T12:28:45.429297045Z,10,2,38,A,B,3,233.78,400,130,166243,13250331,233.86,234.0,195,17,2,2,233.81,234.06,2,400,2,1,233.8,234.07,105,7,2,1,233.78,234.1,400,100,1,1,233.7,234.13,1200,400,1,1,233.66,234.17,1,1,1,1,233.58,234.25,505,100,2,1,233.53,234.41,10,500,1,1,233.5,234.43,100,105,1,2,233.45,234.5,15,63,1,4,AAPL,-253,-4.656441717791411,0.06010698648209116
2024-10-21T12:28:48.483286864Z,2024-10-21T12:28:48.483119828Z,10,2,38,A,B,1,233.82,200,130,167036,13252635,233.86,234.0,195,17,2,2,233.82,234.06,200,400,1,1,233.81,234.07,2,7,2,1,233.8,234.1,105,100,2,1,233.7,234.13,1200,400,1,1,233.66,234.17,1,1,1,1,233.58,234.25,505,100,2,1,233.53,234.41,10,500,1,1,233.5,234.43,100,105,1,2,233.45,234.5,15,63,1,4,AAPL,-253,-4.791666666666667,0.061852517655182196
2024-10-21T12:28:55.560984753Z,2024-10-21T12:28:55.560815833Z,10,2,38,T,A,0,233.86,10,0,168920,13258219,233.86,234.0,195,17,2,2,233.82,234.06,200,400,1,1,233.81,234.07,2,7,2,1,233.8,234.1,105,100,2,1,233.7,234.13,1200,400,1,1,233.66,234.17,1,1,1,1,233.58,234.25,505,100,2,1,233.53,234.41,10,500,1,1,233.5,234.43,100,105,1,2,233.45,234.5,15,63,1,4,AAPL,-95,-2.024866785079929,0.02613769222404486
2024-10-21T12:28:55.560984753Z,2024-10-21T12:28:55.560817191Z,10,2,38,A,N,0,233.9,100,130,167562,13258220,233.86,233.9,185,100,2,1,233.82,234.0,200,17,1,2,233.81,234.06,2,400,2,1,233.8,234.07,105,7,2,1,233.7,234.1,1200,100,1,1,233.66,234.13,1,400,1,1,233.58,234.17,505,1,2,1,233.53,234.25,10,100,1,1,233.5,234.41,100,500,1,1,233.45,234.43,15,105,1,2,AAPL,-200,-4.099560761346998,0.05291857134672153
2024-10-21T12:28:55.561007655Z,2024-10-21T12:28:55.560841422Z,10,2,38,A,A,0,233.9,100,130,166233,13258221,233.86,233.9,185,200,2,2,233.82,234.0,200,17,1,2,233.81,234.06,2,400,2,1,233.8,234.07,105,7,2,1,233.7,234.1,1200,100,1,1,233.66,234.13,1,400,1,1,233.58,234.17,505,1,2,1,233.53,234.25,10,100,1,1,233.5,234.41,100,500,1,1,233.45,234.43,15,105,1,2,AAPL,-200,-3.9850560398505603,0.05144050415201681
2024-10-21T12:28:55.561058773Z,2024-10-21T12:28:55.560892756Z,10,2,38,C,B,1,233.82,200,130,166017,13258225,233.86,233.9,185,200,2,2,233.81,234.0,2,17,2,2,233.8,234.06,105,400,2,1,233.7,234.07,1200,7,1,1,233.66,234.1,1,100,1,1,233.58,234.13,505,400,2,1,233.53,234.17,10,1,1,1,233.5,234.25,100,100,1,1,233.45,234.41,15,500,1,1,233.4,234.43,110,105,2,2,AAPL,-310,-5.481335952848723,0.07075501122731698
2024-10-21T12:28:55.561286132Z,2024-10-21T12:28:55.561120579Z,10,2,38,C,A,0,233.9,100,130,165553,13258227,233.86,233.9,185,100,2,1,233.81,234.0,2,17,2,2,233.8,234.06,105,400,2,1,233.7,234.07,1200,7,1,1,233.66,234.1,1,100,1,1,233.58,234.13,505,400,2,1,233.53,234.17,10,1,1,1,233.5,234.25,100,100,1,1,233.45,234.41,15,500,1,1,233.4,234.43,110,105,2,2,AAPL,-310,-5.028386050283861,0.06490817466829656
2024-10-21T12:28:55.561361290Z,2024-10-21T12:28:55.561195478Z,10,2,38,C,A,0,233.9,100,130,165812,13258228,233.86,234.0,185,17,2,2,233.81,234.06,2,400,2,1,233.8,234.07,105,7,2,1,233.7,234.1,1200,100,1,1,233.66,234.13,1,400,1,1,233.58,234.17,505,1,2,1,233.53,234.25,10,100,1,1,233.5,234.41,100,500,1,1,233.45,234.43,15,105,1,2,233.4,234.5,110,63,2,4,AAPL,-247,-3.864864864864865,0.04988903421682381
2024-10-21T12:28:55.562326440Z,2024-10-21T12:28:55.562160475Z,10,2,38,C,A,2,234.07,7,130,165965,13258230,233.86,234.0,185,17,2,2,233.81,234.06,2,400,2,1,233.8,234.1,105,100,2,1,233.7,234.13,1200,400,1,1,233.66,234.17,1,1,1,1,233.58,234.25,505,100,2,1,233.53,234.41,10,500,1,1,233.5,234.43,100,105,1,2,233.45,234.5,15,63,1,4,233.4,234.59,110,60,2,1,AAPL,-187,-2.847715736040609,0.03675931572321223
2024-10-21T12:28:55.639858396Z,2024-10-21T12:28:55.639691686Z,10,2,38,A,B,3,233.72,400,130,166710,13258325,233.86,234.0,185,17,2,2,233.81,234.06,2,400,2,1,233.8,234.1,105,100,2,1,233.72,234.13,400,400,1,1,233.7,234.17,1200,1,1,1,233.66,234.25,1,100,1,1,233.58,234.41,505,500,2,1,233.53,234.43,10,105,1,2,233.5,234.5,100,63,1,4,233.45,234.59,15,60,1,1,AAPL,-172,-2.7086614173228347,0.03496435369812969
2024-10-21T12:28:55.964596099Z,2024-10-21T12:28:55.964429174Z,10,2,38,A,B,3,233.75,200,130,166925,13258541,233.86,234.0,185,17,2,2,233.81,234.06,2,400,2,1,233.8,234.1,105,100,2,1,233.75,234.13,200,400,1,1,233.7,234.17,1200,1,1,1,233.66,234.25,1,100,1,1,233.58,234.41,505,500,2,1,233.53,234.43,10,105,1,2,233.5,234.5,100,63,1,4,233.45,234.59,15,60,1,1,AAPL,-172,-2.7902665121668595,0.03601774094743603
2024-10-21T12:28:56.442773675Z,2024-10-21T12:28:56.442607241Z,10,2,38,A,A,1,234.05,400,130,166434,13258927,233.86,234.0,185,17,2,2,233.81,234.05,2,400,2,1,233.8,234.1,105,100,2,1,233.75,234.13,200,400,1,1,233.7,234.17,1200,1,1,1,233.66,234.25,1,100,1,1,233.58,234.41,505,500,2,1,233.53,234.43,10,105,1,2,233.5,234.5,100,63,1,4,233.45,234.59,15,60,1,1,AAPL,-172,-2.8650749583564687,0.036983394666816806
2024-10-21T12:28:57.565514672Z,2024-10-21T12:28:57.565348157Z,10,2,38,A,A,2,234.07,7,130,166515,13259953,233.86,234.0,185,17,2,2,233.81,234.05,2,400,2,1,233.8,234.07,105,7,2,1,233.75,234.1,200,100,1,1,233.7,234.13,1200,400,1,1,233.66,234.17,1,1,1,1,233.58,234.25,505,100,2,1,233.53,234.41,10,500,1,1,233.5,234.43,100,105,1,2,233.45,234.5,15,63,1,4,AAPL,-235,-4.00212879191059,0.05166088523686179
2024-10-21T12:28:57.831005951Z,2024-10-21T12:28:57.830839869Z,10,2,38,A,A,1,234.01,200,130,166082,13260122,233.86,234.0,185,17,2,2,233.81,234.01,2,200,2,1,233.8,234.07,105,7,2,1,233.75,234.1,200,100,1,1,233.7,234.13,1200,400,1,1,233.66,234.17,1,1,1,1,233.58,234.25,505,100,2,1,233.53,234.41,10,500,1,1,233.5,234.43,100,105,1,2,233.45,234.5,15,63,1,4,AAPL,-235,-4.082779764946347,0.052701956346483024
2024-10-21T12:28:57.891061549Z,2024-10-21T12:28:57.890894861Z,10,2,38,A,A,0,234.0,200,130,166688,13260139,233.86,234.0,185,217,2,3,233.81,234.07,2,7,2,1,233.8,234.1,105,100,2,1,233.75,234.13,200,400,1,1,233.7,234.17,1200,1,1,1,233.66,234.25,1,100,1,1,233.58,234.41,505,500,2,1,233.53,234.43,10,105,1,2,233.5,234.5,100,63,1,4,233.45,234.59,15,60,1,1,AAPL,-175,-3.100393700787402,0.04002097171115863
2024-10-21T12:28:58.006126423Z,2024-10-21T12:28:58.005959828Z,10,2,38,A,A,0,233.99,200,130,166595,13260238,233.86,233.99,185,200,2,1,233.81,234.0,2,17,2,2,233.8,234.07,105,7,2,1,233.75,234.1,200,100,1,1,233.7,234.13,1200,400,1,1,233.66,234.17,1,1,1,1,233.58,234.25,505,100,2,1,233.53,234.41,10,500,1,1,233.5,234.43,100,105,1,2,233.45,234.5,15,63,1,4,AAPL,-238,-4.286255924170616,0.05532849813378622
2024-10-21T12:28:58.694606149Z,2024-10-21T12:28:58.694439582Z,10,2,38,A,B,1,233.81,200,130,166567,13260587,233.86,233.99,185,200,2,1,233.81,234.0,202,17,3,2,233.8,234.07,105,7,2,1,233.7,234.1,1200,100,1,1,233.66,234.13,1,400,1,1,233.58,234.17,505,1,2,1,233.53,234.25,10,100,1,1,233.5,234.41,100,500,1,1,233.45,234.43,15,105,1,2,233.4,234.5,110,63,2,4,AAPL,-348,-6.097240473061761,0.0787053232712231
2024-10-21T12:29:01.022290262Z,2024-10-21T12:29:01.022123658Z,10,2,38,C,B,1,233.81,200,130,166604,13262995,233.86,233.99,185,200,2,1,233.81,234.0,2,17,2,2,233.8,234.07,105,7,2,1,233.7,234.1,1200,100,1,1,233.66,234.13,1,400,1,1,233.58,234.17,505,1,2,1,233.53,234.25,10,100,1,1,233.5,234.41,100,500,1,1,233.45,234.43,15,105,1,2,233.4,234.5,110,63,2,4,AAPL,-348,-5.95114006514658,0.07681940785000506
2024-10-21T12:29:01.022303152Z,2024-10-21T12:29:01.022136915Z,10,2,38,A,B,3,233.76,400,130,166237,13262996,233.86,233.99,185,200,2,1,233.81,234.0,2,17,2,2,233.8,234.07,105,7,2,1,233.76,234.1,400,100,1,1,233.7,234.13,1200,400,1,1,233.66,234.17,1,1,1,1,233.58,234.25,505,100,2,1,233.53,234.41,10,500,1,1,233.5,234.43,100,105,1,2,233.45,234.5,15,63,1,4,AAPL,-333,-5.782162588792422,0.07463818718784361
2024-10-21T12:29:01.158549246Z,2024-10-21T12:29:01.158380499Z,10,2,38,T,A,0,233.86,85,0,168747,13263131,233.86,233.99,185,200,2,1,233.81,234.0,2,17,2,2,233.8,234.07,105,7,2,1,233.76,234.1,400,100,1,1,233.7,234.13,1200,400,1,1,233.66,234.17,1,1,1,1,233.58,234.25,505,100,2,1,233.53,234.41,10,500,1,1,233.5,234.43,100,105,1,2,233.45,234.5,15,63,1,4,AAPL,-333,-5.8644716692189895,0.07570066173050782
2024-10-21T12:29:01.158549246Z,2024-10-21T12:29:01.158380499Z,10,2,38,T,A,0,233.86,100,130,168747,13263132,233.86,233.99,100,200,1,1,233.81,234.0,2,17,2,2,233.8,234.07,105,7,2,1,233.76,234.1,400,100,1,1,233.7,234.13,1200,400,1,1,233.66,234.17,1,1,1,1,233.58,234.25,505,100,2,1,233.53,234.41,10,500,1,1,233.5,234.43,100,105,1,2,233.45,234.5,15,63,1,4,AAPL,-333,-5.942007434944238,0.07670152064913648
2024-10-21T12:29:01.158549246Z,2024-10-21T12:29:01.158380499Z,10,2,38,C,B,0,233.86,100,130,168747,13263132,233.81,233.99,2,200,2,1,233.8,234.0,105,17,2,2,233.76,234.07,400,7,1,1,233.7,234.1,1200,100,1,1,233.66,234.13,1,400,1,1,233.58,234.17,505,1,2,1,233.53,234.25,10,100,1,1,233.5,234.41,100,500,1,1,233.45,234.43,15,105,1,2,233.4,234.5,110,63,2,4,AAPL,-443,-7.7366398882291305,0.09986726718855214
2024-10-21T12:29:01.158567848Z,2024-10-21T12:29:01.158396024Z,10,2,38,A,B,0,233.86,100,128,171824,13263141,233.86,233.99,100,200,1,1,233.81,234.0,2,17,2,2,233.8,234.07,105,7,2,1,233.76,234.1,400,100,1,1,233.7,234.13,1200,400,1,1,233.66,234.17,1,1,1,1,233.58,234.25,505,100,2,1,233.53,234.41,10,500,1,1,233.5,234.43,100,105,1,2,233.45,234.5,15,63,1,4,AAPL,-428,-7.567494049642979,0.09768387324751898
2024-10-21T12:29:01.158571366Z,2024-10-21T12:29:01.158404180Z,10,2,38,A,A,0,233.92,100,130,167186,13263148,233.86,233.92,100,100,1,1,233.81,233.99,2,200,2,1,233.8,234.0,105,17,2,2,233.76,234.07,400,7,1,1,233.7,234.1,1200,100,1,1,233.66,234.13,1,400,1,1,233.58,234.17,505,1,2,1,233.53,234.25,10,100,1,1,233.5,234.41,100,500,1,1,233.45,234.43,15,105,1,2,AAPL,-533,-9.40280953936622,0.12137477072180132
2024-10-21T12:29:01.158576809Z,2024-10-21T12:29:01.158408745Z,10,2,38,A,A,1,233.96,100,128,168064,13263151,233.86,233.92,100,100,1,1,233.81,233.93,2,130,2,1,233.8,233.96,105,100,2,1,233.76,233.99,400,200,1,1,233.7,234.0,1200,17,1,2,233.66,234.07,1,7,1,1,233.58,234.1,505,100,2,1,233.53,234.13,10,400,1,1,233.5,234.17,100,1,1,1,233.45,234.25,15,100,1,1,AAPL,-633,-11.161209068010075,0.1440728099336917
2024-10-21T12:29:01.158585584Z,2024-10-21T12:29:01.158418184Z,10,2,38,A,A,0,233.92,100,128,167400,13263156,233.86,233.92,100,200,1,2,233.81,233.93,2,130,2,1,233.8,233.96,105,100,2,1,233.76,233.99,400,200,1,1,233.7,234.0,1200,17,1,2,233.66,234.07,1,7,1,1,233.58,234.1,505,100,2,1,233.53,234.13,10,400,1,1,233.5,234.17,100,1,1,1,233.45,234.25,15,100,1,1,AAPL,-633,-11.15587967183227,0.1440040162144891
2024-10-21T12:29:01.158586865Z,2024-10-21T12:29:01.158419809Z,10,2,38,A,A,2,233.96,100,130,167056,13263158,233.86,233.92,100,200,1,2,233.81,233.93,2,130,2,1,233.8,233.96,105,200,2,2,233.76,233.99,400,200,1,1,233.7,234.0,1200,17,1,2,233.66,234.07,1,7,1,1,233.58,234.1,505,100,2,1,233.53,234.13,10,400,1,1,233.5,234.17,100,1,1,1,233.45,234.25,15,100,1,1,AAPL,-633,-11.150910158543747,0.143939867990124
2024-10-21T12:29:01.158590064Z,2024-10-21T12:29:01.158423515Z,10,2,38,A,A,1,233.93,26,130,166549,13263160,233.86,233.92,100,200,1,2,233.81,233.93,2,156,2,2,233.8,233.96,105,200,2,2,233.76,233.99,400,200,1,1,233.7,234.0,1200,17,1,2,233.66,234.07,1,7,1,1,233.58,234.1,505,100,2,1,233.53,234.13,10,400,1,1,233.5,234.17,100,1,1,1,233.45,234.25,15,100,1,1,AAPL,-633,-11.14626526554956,0.14387991007862572
2024-10-21T12:29:01.158592348Z,2024-10-21T12:29:01.158424717Z,10,2,38,T,A,0,233.86,100,0,167631,13263161,233.86,233.92,100,200,1,2,233.81,233.93,2,156,2,2,233.8,233.96,105,200,2,2,233.76,233.99,400,200,1,1,233.7,234.0,1200,17,1,2,233.66,234.07,1,7,1,1,233.58,234.1,505,100,2,1,233.53,234.13,10,400,1,1,233.5,234.17,100,1,1,1,233.45,234.25,15,100,1,1,AAPL,-633,-11.141914191419142,0.14382374488430139
2024-10-21T12:29:01.158592348Z,2024-10-21T12:29:01.158424717Z,10,2,38,T,N,0,233.86,150,130,167631,13263162,233.81,233.92,2,200,2,2,233.8,233.93,105,156,2,2,233.76,233.96,400,200,1,2,233.7,233.99,1200,200,1,1,233.66,234.0,1,17,1,2,233.58,234.07,505,7,2,1,233.53,234.1,10,100,1,1,233.5,234.13,100,400,1,1,233.45,234.17,15,1,1,1,233.4,234.25,110,100,2,1,AAPL,-743,-12.750390015600624,0.16458651621921316
2024-10-21T12:29:01.158594194Z,2024-10-21T12:29:01.158426997Z,10,2,38,T,N,0,233.86,50,0,167197,13263163,233.81,233.92,2,200,2,2,233.8,233.93,105,156,2,2,233.76,233.96,400,200,1,2,233.7,233.99,1200,200,1,1,233.66,234.0,1,17,1,2,233.58,234.07,505,7,2,1,233.53,234.1,10,100,1,1,233.5,234.13,100,400,1,1,233.45,234.17,15,1,1,1,233.4,234.25,110,100,2,1,AAPL,-743,-12.456607495069033,0.16079426817650758
2024-10-21T12:29:01.158594194Z,2024-10-21T12:29:01.158427442Z,10,2,38,C,A,1,233.93,130,130,166752,13263164,233.81,233.92,2,200,2,2,233.8,233.93,105,26,2,1,233.76,233.96,400,200,1,2,233.7,233.99,1200,200,1,1,233.66,234.0,1,17,1,2,233.58,234.07,505,7,2,1,233.53,234.1,10,100,1,1,233.5,234.13,100,400,1,1,233.45,234.17,15,1,1,1,233.4,234.25,110,100,2,1,AAPL,-743,-12.191748710736052,0.15737537788765488
2024-10-21T12:29:01.158598557Z,2024-10-21T12:29:01.158431288Z,10,2,38,A,A,2,233.96,100,130,167269,13263165,233.81,233.92,2,200,2,2,233.8,233.93,105,26,2,1,233.76,233.96,400,300,1,3,233.7,233.99,1200,200,1,1,233.66,234.0,1,17,1,2,233.58,234.07,505,7,2,1,233.53,234.1,10,100,1,1,233.5,234.13,100,400,1,1,233.45,234.17,15,1,1,1,233.4,234.25,110,100,2,1,AAPL,-743,-11.951742627345846,0.15427729499856052
2024-10-21T12:29:01.158601250Z,2024-10-21T12:29:01.158434916Z,10,2,38,A,B,0,233.86,100,130,166334,13263166,233.86,233.92,100,200,1,2,233.81,233.93,2,26,2,1,233.8,233.96,105,300,2,3,233.76,233.99,400,200,1,1,233.7,234.0,1200,17,1,2,233.66,234.07,1,7,1,1,233.58,234.1,505,100,2,1,233.53,234.13,10,400,1,1,233.5,234.17,100,1,1,1,233.45,234.25,15,100,1,1,AAPL,-728,-11.734262687867567,0.1514699874932607
2024-10-21T12:29:01.158603851Z,2024-10-21T12:29:01.158437825Z,10,2,38,A,A,3,233.97,26,130,166026,13263167,233.86,233.92,100,200,1,2,233.81,233.93,2,26,2,1,233.8,233.96,105,300,2,3,233.76,233.97,400,26,1,1,233.7,233.99,1200,200,1,1,233.66,234.0,1,17,1,2,233.58,234.07,505,7,2,1,233.53,234.1,10,100,1,1,233.5,234.13,100,400,1,1,233.45,234.17,15,1,1,1,AAPL,-729,-12.026047319296723,0.15523644608115275
2024-10-21T12:29:01.158622043Z,2024-10-21T12:29:01.158453404Z,10,2,38,C,B,3,233.76,400,130,168639,13263171,233.86,233.92,100,200,1,2,233.81,233.93,2,26,2,1,233.8,233.96,105,300,2,3,233.7,233.97,1200,26,1,1,233.66,233.99,1,200,1,1,233.58,234.0,505,17,2,2,233.53,234.07,10,7,1,1,233.5,234.1,100,100,1,1,233.45,234.13,15,400,1,1,233.4,234.17,110,1,2,1,AAPL,-839,-13.870707927087748,0.17904797362436256
2024-10-21T12:29:01.158626083Z,2024-10-21T12:29:01.158458726Z,10,2,38,C,A,0,233.92,100,128,167357,13263172,233.86,233.92,100,100,1,1,233.81,233.93,2,26,2,1,233.8,233.96,105,300,2,3,233.7,233.97,1200,26,1,1,233.66,233.99,1,200,1,1,233.58,234.0,505,17,2,2,233.53,234.07,10,7,1,1,233.5,234.1,100,100,1,1,233.45,234.13,15,400,1,1,233.4,234.17,110,1,2,1,AAPL,-839,-13.899358045143924,0.17941779941905317
2024-10-21T12:29:01.158642773Z,2024-10-21T12:29:01.158475713Z,10,2,38,C,A,0,233.92,100,128,167060,13263180,233.86,233.93,100,26,1,1,233.81,233.96,2,300,2,3,233.8,233.97,105,26,2,1,233.7,233.99,1200,200,1,1,233.66,234.0,1,17,1,2,233.58,234.07,505,7,2,1,233.53,234.1,10,100,1,1,233.5,234.13,100,400,1,1,233.45,234.17,15,1,1,1,233.4,234.25,110,100,2,1,AAPL,-739,-12.025798769597142,0.1552332377142627
2024-10-21T12:29:01.158651784Z,2024-10-21T12:29:01.158485485Z,10,2,38,A,A,0,233.91,26,130,166299,13263183,233.86,233.91,100,26,1,1,233.81,233.93,2,26,2,1,233.8,233.96,105,300,2,3,233.7,233.97,1200,26,1,1,233.66,233.99,1,200,1,1,233.58,234.0,505,17,2,2,233.53,234.07,10,7,1,1,233.5,234.1,100,100,1,1,233.45,234.13,15,400,1,1,233.4,234.17,110,1,2,1,AAPL,-740,-12.069902912621359,0.15580254949549513
2024-10-21T12:29:01.158666241Z,2024-10-21T12:29:01.158498852Z,10,2,38,T,A,0,233.86,50,128,167389,13263184,233.86,233.91,100,26,1,1,233.81,233.93,2,26,2,1,233.8,233.96,105,300,2,3,233.7,233.97,1200,26,1,1,233.66,233.99,1,200,1,1,233.58,234.0,505,17,2,2,233.53,234.07,10,7,1,1,233.5,234.1,100,100,1,1,233.45,234.13,15,400,1,1,233.4,234.17,110,1,2,1,AAPL,-740,-12.096559589431667,0.1561466432498683
2024-10-21T12:29:01.158666241Z,2024-10-21T12:29:01.158498852Z,10,2,38,C,B,0,233.86,50,128,167389,13263184,233.86,233.91,50,26,1,1,233.81,233.93,2,26,2,1,233.8,233.96,105,300,2,3,233.7,233.97,1200,26,1,1,233.66,233.99,1,200,1,1,233.58,234.0,505,17,2,2,233.53,234.07,10,7,1,1,233.5,234.1,100,100,1,1,233.45,234.13,15,400,1,1,233.4,234.17,110,1,2,1,AAPL,-740,-12.122114668652271,0.1564765171953303
2024-10-21T12:29:01.158674864Z,2024-10-21T12:29:01.158508412Z,10,2,38,A,B,0,233.86,100,130,166452,13263188,233.86,233.91,150,26,2,1,233.81,233.93,2,26,2,1,233.8,233.96,105,300,2,3,233.7,233.97,1200,26,1,1,233.66,233.99,1,200,1,1,233.58,234.0,505,17,2,2,233.53,234.07,10,7,1,1,233.5,234.1,100,100,1,1,233.45,234.13,15,400,1,1,233.4,234.17,110,1,2,1,AAPL,-740,-12.146635053802662,0.15679303494602798
2024-10-21T12:29:01.158688501Z,2024-10-21T12:29:01.158520941Z,10,2,38,T,A,0,233.86,50,0,167560,13263189,233.86,233.91,150,26,2,1,233.81,233.93,2,26,2,1,233.8,233.96,105,300,2,3,233.7,233.97,1200,26,1,1,233.66,233.99,1,200,1,1,233.58,234.0,505,17,2,2,233.53,234.07,10,7,1,1,233.5,234.1,100,100,1,1,233.45,234.13,15,400,1,1,233.4,234.17,110,1,2,1,AAPL,-740,-12.170182338219522,0.15709699157040197
2024-10-21T12:29:01.158688501Z,2024-10-21T12:29:01.158520941Z,10,2,38,T,A,0,233.86,50,130,167560,13263190,233.86,233.91,100,26,1,1,233.81,233.93,2,26,2,1,233.8,233.96,105,300,2,3,233.7,233.97,1200,26,1,1,233.66,233.99,1,200,1,1,233.58,234.0,505,17,2,2,233.53,234.07,10,7,1,1,233.5,234.1,100,100,1,1,233.45,234.13,15,400,1,1,233.4,234.17,110,1,2,1,AAPL,-740,-12.192813321647678,0.15738912025952423
2024-10-21T12:29:01.158688501Z,2024-10-21T12:29:01.158520941Z,10,2,38,C,B,0,233.86,50,130,167560,13263190,233.86,233.91,50,26,1,1,233.81,233.93,2,26,2,1,233.8,233.96,105,300,2,3,233.7,233.97,1200,26,1,1,233.66,233.99,1,200,1,1,233.58,234.0,505,17,2,2,233.53,234.07,10,7,1,1,233.5,234.1,100,100,1,1,233.45,234.13,15,400,1,1,233.4,234.17,110,1,2,1,AAPL,-740,-12.214580467675377,0.15767009823183337
2024-10-21T12:29:01.158696696Z,2024-10-21T12:29:01.158530490Z,10,2,38,C,A,2,233.96,100,130,166206,13263192,233.86,233.91,50,26,1,1,233.81,233.93,2,26,2,1,233.8,233.96,105,200,2,2,233.7,233.97,1200,26,1,1,233.66,233.99,1,200,1,1,233.58,234.0,505,17,2,2,233.53,234.07,10,7,1,1,233.5,234.1,100,100,1,1,233.45,234.13,15,400,1,1,233.4,234.17,110,1,2,1,AAPL,-740,-12.235532309768855,0.1579405519743715
2024-10-21T12:29:01.158698384Z,2024-10-21T12:29:01.158531815Z,10,2,38,C,B,0,233.96,100,130,166569,13263194,233.86,233.91,150,26,2,1,233.81,233.93,2,26,2,1,233.8,233.96,105,100,2,1,233.7,233.97,1200,26,1,1,233.66,233.99,1,200,1,1,233.58,234.0,505,17,2,2,233.53,234.07,10,7,1,1,233.5,234.1,100,100,1,1,233.45,234.13,15,400,1,1,233.4,234.17,110,1,2,1,AAPL,-740,-12.255713812520701,0.15820106190590544
2024-10-21T12:29:01.158723924Z,2024-10-21T12:29:01.158554739Z,10,2,38,T,A,0,233.86,50,128,169185,13263197,233.86,233.91,150,26,2,1,233.81,233.93,2,26,2,1,233.8,233.96,105,100,2,1,233.7,233.97,1200,26,1,1,233.66,233.99,1,200,1,1,233.58,234.0,505,17,2,2,233.53,234.07,10,7,1,1,233.5,234.1,100,100,1,1,233.45,234.13,15,400,1,1,233.4,234.17,110,1,2,1,AAPL,-740,-12.275166693771345,0.15845216653498362
2024-10-21T12:29:01.158723924Z,2024-10-21T12:29:01.158554739Z,10,2,38,C,B,0,233.86,50,128,169185,13263197,233.86,233.91,100,26,1,1,233.81,233.93,2,26,2,1,233.8,233.96,105,100,2,1,233.7,233.97,1200,26,1,1,233.66,233.99,1,200,1,1,233.58,234.0,505,17,2,2,233.53,234.07,10,7,1,1,233.5,234.1,100,100,1,1,233.45,234.13,15,400,1,1,233.4,234.17,110,1,2,1,AAPL,-740,-12.293929712460063,0.1586943661756184
2024-10-21T12:29:01.159002676Z,2024-10-21T12:29:01.158835732Z,10,2,38,C,A,2,233.96,100,130,166944,13263231,233.86,233.91,100,26,1,1,233.81,233.93,2,26,2,1,233.8,233.97,105,26,2,1,233.7,233.99,1200,200,1,1,233.66,234.0,1,17,1,2,233.58,234.07,505,7,2,1,233.53,234.1,10,100,1,1,233.5,234.13,100,400,1,1,233.45,234.17,15,1,1,1,233.4,234.25,110,100,2,1,AAPL,-640,-10.48531684698609,0.13534815556140237
2024-10-21T12:29:01.260977964Z,2024-10-21T12:29:01.260812083Z,10,2,38,C,A,2,233.97,26,130,165881,13263664,233.86,233.91,100,26,1,1,233.81,233.93,2,26,2,1,233.8,233.99,105,200,2,1,233.7,234.0,1200,17,1,2,233.66,234.07,1,7,1,1,233.58,234.1,505,100,2,1,233.53,234.13,10,400,1,1,233.5,234.17,100,1,1,1,233.45,234.25,15,100,1,1,233.4,234.41,110,500,2,1,AAPL,-140,-2.135593220338983,0.0275669879718896
2024-10-21T12:29:01.260986860Z,2024-10-21T12:29:01.260820985Z,10,2,38,C,A,0,233.91,26,130,165875,13263665,233.86,233.93,100,26,1,1,233.81,233.99,2,200,2,1,233.8,234.0,105,17,2,2,233.7,234.07,1200,7,1,1,233.66,234.1,1,100,1,1,233.58,234.13,505,400,2,1,233.53,234.17,10,1,1,1,233.5,234.25,100,100,1,1,233.45,234.41,15,500,1,1,233.4,234.43,110,105,2,2,AAPL,-35,-0.5277587388622345,0.006812495314049332
2024-10-21T12:29:01.261039132Z,2024-10-21T12:29:01.260872777Z,10,2,38,A,B,3,233.74,200,130,166355,13263667,233.86,233.93,100,26,1,1,233.81,233.99,2,200,2,1,233.8,234.0,105,17,2,2,233.74,234.07,200,7,1,1,233.7,234.1,1200,100,1,1,233.66,234.13,1,400,1,1,233.58,234.17,505,1,2,1,233.53,234.25,10,100,1,1,233.5,234.41,100,500,1,1,233.45,234.43,15,105,1,2,AAPL,-20,-0.30209035738368173,0.0038994885210854547
2024-10-21T12:29:01.411202852Z,2024-10-21T12:29:01.411037140Z,10,2,38,C,A,0,233.93,26,130,165712,13264096,233.86,233.99,100,200,1,1,233.81,234.0,2,17,2,2,233.8,234.07,105,7,2,1,233.74,234.1,200,100,1,1,233.7,234.13,1200,400,1,1,233.66,234.17,1,1,1,1,233.58,234.25,505,100,2,1,233.53,234.41,10,500,1,1,233.5,234.43,100,105,1,2,233.45,234.5,15,63,1,4,AAPL,43,0.6542105965567863,-0.008444780342344882
2024-10-21T12:29:01.477305998Z,2024-10-21T12:29:01.477138444Z,10,2,38,T,A,0,233.86,50,130,167554,13264991,233.86,233.99,100,200,1,1,233.81,234.0,2,17,2,2,233.8,234.07,105,7,2,1,233.74,234.1,200,100,1,1,233.7,234.13,1200,400,1,1,233.66,234.17,1,1,1,1,233.58,234.25,505,100,2,1,233.53,234.41,10,500,1,1,233.5,234.43,100,105,1,2,233.45,234.5,15,63,1,4,AAPL,43,0.6588297450799101,-0.00850440593516125
2024-10-21T12:29:01.477305998Z,2024-10-21T12:29:01.477138444Z,10,2,38,C,B,0,233.86,50,130,167554,13264991,233.86,233.99,50,200,1,1,233.81,234.0,2,17,2,2,233.8,234.07,105,7,2,1,233.74,234.1,200,100,1,1,233.7,234.13,1200,400,1,1,233.66,234.17,1,1,1,1,233.58,234.25,505,100,2,1,233.53,234.41,10,500,1,1,233.5,234.43,100,105,1,2,233.45,234.5,15,63,1,4,AAPL,43,0.6633546868871748,-0.008562815474574643
2024-10-21T12:29:01.477315667Z,2024-10-21T12:29:01.477149422Z,10,2,38,A,B,0,233.86,100,130,166245,13264992,233.86,233.99,150,200,2,1,233.81,234.0,2,17,2,2,233.8,234.07,105,7,2,1,233.74,234.1,200,100,1,1,233.7,234.13,1200,400,1,1,233.66,234.17,1,1,1,1,233.58,234.25,505,100,2,1,233.53,234.41,10,500,1,1,233.5,234.43,100,105,1,2,233.45,234.5,15,63,1,4,AAPL,43,0.6677882748802899,-0.008620045786843156
2024-10-21T12:29:01.477365108Z,2024-10-21T12:29:01.477199123Z,10,2,38,C,B,3,233.74,200,130,165985,13264994,233.86,233.99,150,200,2,1,233.81,234.0,2,17,2,2,233.8,234.07,105,7,2,1,233.7,234.1,1200,100,1,1,233.66,234.13,1,400,1,1,233.58,234.17,505,1,2,1,233.53,234.25,10,100,1,1,233.5,234.41,100,500,1,1,233.45,234.43,15,105,1,2,233.4,234.5,110,63,2,4,AAPL,-67,-1.0346835443037976,0.013356058892155227
2024-10-21T12:29:01.541193716Z,2024-10-21T12:29:01.541027344Z,10,2,38,A,B,4,233.66,400,130,166372,13265322,233.86,233.99,150,200,2,1,233.81,234.0,2,17,2,2,233.8,234.07,105,7,2,1,233.7,234.1,1200,100,1,1,233.66,234.13,401,400,2,1,233.58,234.17,505,1,2,1,233.53,234.25,10,100,1,1,233.5,234.41,100,500,1,1,233.45,234.43,15,105,1,2,233.4,234.5,110,63,2,4,AAPL,-67,-1.0291093769354638,0.013284105580385596
2024-10-21T12:29:01.544861244Z,2024-10-21T12:29:01.544694740Z,10,2,38,A,A,0,233.99,200,130,166504,13265329,233.86,233.99,150,400,2,2,233.81,234.0,2,17,2,2,233.8,234.07,105,7,2,1,233.7,234.1,1200,100,1,1,233.66,234.13,401,400,2,1,233.58,234.17,505,1,2,1,233.53,234.25,10,100,1,1,233.5,234.41,100,500,1,1,233.45,234.43,15,105,1,2,233.4,234.5,110,63,2,4,AAPL,-67,-1.0237691001697793,0.01321517141073
2024-10-21T12:29:01.602737737Z,2024-10-21T12:29:01.602571884Z,10,2,38,C,A,0,233.99,200,130,165853,13265457,233.86,233.99,150,200,2,1,233.81,234.0,2,17,2,2,233.8,234.07,105,7,2,1,233.7,234.1,1200,100,1,1,233.66,234.13,401,400,2,1,233.58,234.17,505,1,2,1,233.53,234.25,10,100,1,1,233.5,234.41,100,500,1,1,233.45,234.43,15,105,1,2,233.4,234.5,110,63,2,4,AAPL,-67,-1.0186482955220335,0.013149070264319546
2024-10-21T12:29:01.602775080Z,2024-10-21T12:29:01.602608635Z,10,2,38,A,A,0,233.94,400,130,166445,13265458,233.86,233.94,150,400,2,1,233.81,234.0,2,17,2,2,233.8,234.07,105,7,2,1,233.7,234.1,1200,100,1,1,233.66,234.13,401,400,2,1,233.58,234.17,505,1,2,1,233.53,234.25,10,100,1,1,233.5,234.41,100,500,1,1,233.45,234.43,15,105,1,2,233.4,234.5,110,63,2,4,AAPL,-67,-1.0137337057728117,0.01308563101230597
2024-10-21T12:29:01.646283514Z,2024-10-21T12:29:01.646117074Z,10,2,38,C,A,0,233.94,400,130,166440,13265552,233.86,234.0,150,17,2,2,233.81,234.07,2,7,2,1,233.8,234.1,105,100,2,1,233.7,234.13,1200,400,1,1,233.66,234.17,401,1,2,1,233.58,234.25,505,100,2,1,233.53,234.41,10,500,1,1,233.5,234.43,100,105,1,2,233.45,234.5,15,63,1,4,233.4,234.59,110,60,2,1,AAPL,-7,-0.10545537548504907,0.00136125505544825
2024-10-21T12:29:01.646296993Z,2024-10-21T12:29:01.646130641Z,10,2,38,A,A,0,233.95,200,130,166352,13265553,233.86,233.95,150,200,2,1,233.81,234.0,2,17,2,2,233.8,234.07,105,7,2,1,233.7,234.1,1200,100,1,1,233.66,234.13,401,400,2,1,233.58,234.17,505,1,2,1,233.53,234.25,10,100,1,1,233.5,234.41,100,500,1,1,233.45,234.43,15,105,1,2,233.4,234.5,110,63,2,4,AAPL,-70,-1.0498041410184666,0.013551240869598904
2024-10-21T12:29:01.700803405Z,2024-10-21T12:29:01.700637009Z,10,2,38,A,B,3,233.71,200,130,166396,13265636,233.86,233.95,150,200,2,1,233.81,234.0,2,17,2,2,233.8,234.07,105,7,2,1,233.71,234.1,200,100,1,1,233.7,234.13,1200,400,1,1,233.66,234.17,1,1,1,1,233.58,234.25,505,100,2,1,233.53,234.41,10,500,1,1,233.5,234.43,100,105,1,2,233.45,234.5,15,63,1,4,AAPL,-55,-0.8299123488294686,0.010712800321717238
2024-10-21T12:29:01.702597558Z,2024-10-21T12:29:01.702431410Z,10,2,38,C,A,0,233.95,200,130,166148,13265638,233.86,234.0,150,17,2,2,233.81,234.07,2,7,2,1,233.8,234.1,105,100,2,1,233.71,234.13,200,400,1,1,233.7,234.17,1200,1,1,1,233.66,234.25,1,100,1,1,233.58,234.41,505,500,2,1,233.53,234.43,10,105,1,2,233.5,234.5,100,63,1,4,233.45,234.59,15,60,1,1,AAPL,5,0.07592429577464789,-0.0009800574980574643
2024-10-21T12:29:01.702610835Z,2024-10-21T12:29:01.702443831Z,10,2,38,A,A,0,233.99,200,130,167004,13265639,233.86,233.99,150,200,2,1,233.81,234.0,2,17,2,2,233.8,234.07,105,7,2,1,233.71,234.1,200,100,1,1,233.7,234.13,1200,400,1,1,233.66,234.17,1,1,1,1,233.58,234.25,505,100,2,1,233.53,234.41,10,500,1,1,233.5,234.43,100,105,1,2,233.45,234.5,15,63,1,4,AAPL,-58,-0.8858826096443377,0.011435284122458143
2024-10-21T12:29:01.829025695Z,2024-10-21T12:29:01.828859341Z,10,2,38,A,B,3,233.71,200,130,166354,13265781,233.86,233.99,150,200,2,1,233.81,234.0,2,17,2,2,233.8,234.07,105,7,2,1,233.71,234.1,400,100,2,1,233.7,234.13,1200,400,1,1,233.66,234.17,1,1,1,1,233.58,234.25,505,100,2,1,233.53,234.41,10,500,1,1,233.5,234.43,100,105,1,2,233.45,234.5,15,63,1,4,AAPL,-58,-0.8909562959757681,0.01150077704907901
2024-10-21T12:29:01.883954105Z,2024-10-21T12:29:01.883788028Z,10,2,38,C,B,3,233.71,200,130,166077,13265824,233.86,233.99,150,200,2,1,233.81,234.0,2,17,2,2,233.8,234.07,105,7,2,1,233.71,234.1,200,100,1,1,233.7,234.13,1200,400,1,1,233.66,234.17,1,1,1,1,233.58,234.25,505,100,2,1,233.53,234.41,10,500,1,1,233.5,234.43,100,105,1,2,233.45,234.5,15,63,1,4,AAPL,-58,-0.8959450761639133,0.011565173977356938
2024-10-21T12:29:01.883967618Z,2024-10-21T12:29:01.883801296Z,10,2,38,A,B,3,233.76,400,130,166322,13265825,233.86,233.99,150,200,2,1,233.81,234.0,2,17,2,2,233.8,234.07,105,7,2,1,233.76,234.1,400,100,1,1,233.7,234.13,1200,400,1,1,233.66,234.17,1,1,1,1,233.58,234.25,505,100,2,1,233.53,234.41,10,500,1,1,233.5,234.43,100,105,1,2,233.45,234.5,15,63,1,4,AAPL,-58,-0.9008510638297872,0.011628502190654935
2024-10-21T12:29:04.074542032Z,2024-10-21T12:29:04.074375510Z,10,2,38,A,B,1,233.81,200,130,166522,13268362,233.86,233.99,150,200,2,1,233.81,234.0,202,17,3,2,233.8,234.07,105,7,2,1,233.7,234.1,1200,100,1,1,233.66,234.13,1,400,1,1,233.58,234.17,505,1,2,1,233.53,234.25,10,100,1,1,233.5,234.41,100,500,1,1,233.45,234.43,15,105,1,2,233.4,234.5,110,63,2,4,AAPL,-168,-2.568971009875757,0.03316118081613736
2024-10-21T12:29:04.429667694Z,2024-10-21T12:29:04.429500359Z,10,2,38,T,A,0,233.86,3,130,167335,13268523,233.86,233.99,150,200,2,1,233.81,234.0,202,17,3,2,233.8,234.07,105,7,2,1,233.7,234.1,1200,100,1,1,233.66,234.13,1,400,1,1,233.58,234.17,505,1,2,1,233.53,234.25,10,100,1,1,233.5,234.41,100,500,1,1,233.45,234.43,15,105,1,2,233.4,234.5,110,63,2,4,AAPL,-168,-2.5576642335766424,0.03301522897321613
2024-10-21T12:29:04.429667694Z,2024-10-21T12:29:04.429500359Z,10,2,38,C,B,0,233.86,3,130,167335,13268523,233.86,233.99,147,200,2,1,233.81,234.0,202,17,3,2,233.8,234.07,105,7,2,1,233.7,234.1,1200,100,1,1,233.66,234.13,1,400,1,1,233.58,234.17,505,1,2,1,233.53,234.25,10,100,1,1,233.5,234.41,100,500,1,1,233.45,234.43,15,105,1,2,233.4,234.5,110,63,2,4,AAPL,-168,-2.546758168595719,0.03287444965284442
2024-10-21T12:29:04.493717825Z,2024-10-21T12:29:04.493551721Z,10,2,38,C,B,1,233.81,200,130,166104,13268610,233.86,233.99,147,200,2,1,233.81,234.0,2,17,2,2,233.8,234.07,105,7,2,1,233.7,234.1,1200,100,1,1,233.66,234.13,1,400,1,1,233.58,234.17,505,1,2,1,233.53,234.25,10,100,1,1,233.5,234.41,100,500,1,1,233.45,234.43,15,105,1,2,233.4,234.5,110,63,2,4,AAPL,-168,-2.536231884057971,0.03273857267193008
2024-10-21T12:29:04.493730953Z,2024-10-21T12:29:04.493564498Z,10,2,38,A,B,3,233.78,200,130,166455,13268611,233.86,233.99,147,200,2,1,233.81,234.0,2,17,2,2,233.8,234.07,105,7,2,1,233.78,234.1,200,100,1,1,233.7,234.13,1200,400,1,1,233.66,234.17,1,1,1,1,233.58,234.25,505,100,2,1,233.53,234.41,10,500,1,1,233.5,234.43,100,105,1,2,233.45,234.5,15,63,1,4,AAPL,-153,-2.322348711803475,0.029977693502256847
2024-10-21T12:29:04.660589203Z,2024-10-21T12:29:04.660423222Z,10,2,38,C,B,3,233.78,200,130,165981,13268807,233.86,233.99,147,200,2,1,233.81,234.0,2,17,2,2,233.8,234.07,105,7,2,1,233.7,234.1,1200,100,1,1,233.66,234.13,1,400,1,1,233.58,234.17,505,1,2,1,233.53,234.25,10,100,1,1,233.5,234.41,100,500,1,1,233.45,234.43,15,105,1,2,233.4,234.5,110,63,2,4,AAPL,-263,-3.9758515755374497,0.05132168969119597
2024-10-21T12:29:04.660602729Z,2024-10-21T12:29:04.660436269Z,10,2,38,A,B,4,233.66,400,130,166460,13268808,233.86,233.99,147,200,2,1,233.81,234.0,2,17,2,2,233.8,234.07,105,7,2,1,233.7,234.1,1200,100,1,1,233.66,234.13,401,400,2,1,233.58,234.17,505,1,2,1,233.53,234.25,10,100,1,1,233.5,234.41,100,500,1,1,233.45,234.43,15,105,1,2,233.4,234.5,110,63,2,4,AAPL,-263,-3.9602316602316603,0.051120062333862314
2024-10-21T12:29:04.679306243Z,2024-10-21T12:29:04.679139876Z,10,2,38,A,A,0,233.99,200,130,166367,13268819,233.86,233.99,147,400,2,2,233.81,234.0,2,17,2,2,233.8,234.07,105,7,2,1,233.7,234.1,1200,100,1,1,233.66,234.13,401,400,2,1,233.58,234.17,505,1,2,1,233.53,234.25,10,100,1,1,233.5,234.41,100,500,1,1,233.45,234.43,15,105,1,2,233.4,234.5,110,63,2,4,AAPL,-263,-3.945124845722966,0.050925058261977955
2024-10-21T12:29:04.736956452Z,2024-10-21T12:29:04.736790546Z,10,2,38,C,A,0,233.99,200,130,165906,13268859,233.86,233.99,147,200,2,1,233.81,234.0,2,17,2,2,233.8,234.07,105,7,2,1,233.7,234.1,1200,100,1,1,233.66,234.13,401,400,2,1,233.58,234.17,505,1,2,1,233.53,234.25,10,100,1,1,233.5,234.41,100,500,1,1,233.45,234.43,15,105,1,2,233.4,234.5,110,63,2,4,AAPL,-263,-3.9305062581729873,0.05073635639529366
2024-10-21T12:29:04.736969863Z,2024-10-21T12:29:04.736803679Z,10,2,38,A,A,0,233.94,200,130,166184,13268860,233.86,233.94,147,200,2,1,233.81,234.0,2,17,2,2,233.8,234.07,105,7,2,1,233.7,234.1,1200,100,1,1,233.66,234.13,401,400,2,1,233.58,234.17,505,1,2,1,233.53,234.25,10,100,1,1,233.5,234.41,100,500,1,1,233.45,234.43,15,105,1,2,233.4,234.5,110,63,2,4,AAPL,-263,-3.9163526059380462,0.05055365607708559
2024-10-21T12:29:04.942576593Z,2024-10-21T12:29:04.942410445Z,10,2,38,C,A,0,233.94,200,130,166148,13269072,233.86,234.0,147,17,2,2,233.81,234.07,2,7,2,1,233.8,234.1,105,100,2,1,233.7,234.13,1200,400,1,1,233.66,234.17,401,1,2,1,233.58,234.25,505,100,2,1,233.53,234.41,10,500,1,1,233.5,234.43,100,105,1,2,233.45,234.5,15,63,1,4,233.4,234.59,110,60,2,1,AAPL,-203,-3.013123359580052,0.03889445547040008
2024-10-21T12:29:04.942589417Z,2024-10-21T12:29:04.942423141Z,10,2,38,A,A,0,233.99,200,130,166276,13269073,233.86,233.99,147,200,2,1,233.81,234.0,2,17,2,2,233.8,234.07,105,7,2,1,233.7,234.1,1200,100,1,1,233.66,234.13,401,400,2,1,233.58,234.17,505,1,2,1,233.53,234.25,10,100,1,1,233.5,234.41,100,500,1,1,233.45,234.43,15,105,1,2,233.4,234.5,110,63,2,4,AAPL,-266,-3.9347709855640702,0.050791406995554844
2024-10-21T12:29:04.997130813Z,2024-10-21T12:29:04.996963888Z,10,2,38,A,B,3,233.76,400,130,166925,13269127,233.86,233.99,147,200,2,1,233.81,234.0,2,17,2,2,233.8,234.07,105,7,2,1,233.76,234.1,400,100,1,1,233.7,234.13,1200,400,1,1,233.66,234.17,1,1,1,1,233.58,234.25,505,100,2,1,233.53,234.41,10,500,1,1,233.5,234.43,100,105,1,2,233.45,234.5,15,63,1,4,AAPL,-251,-3.7316814159292035,0.04816985544256202
2024-10-21T12:29:07.476323268Z,2024-10-21T12:29:07.476155585Z,10,2,38,T,A,0,233.86,30,130,167683,13271447,233.86,233.99,147,200,2,1,233.81,234.0,2,17,2,2,233.8,234.07,105,7,2,1,233.76,234.1,400,100,1,1,233.7,234.13,1200,400,1,1,233.66,234.17,1,1,1,1,233.58,234.25,505,100,2,1,233.53,234.41,10,500,1,1,233.5,234.43,100,105,1,2,233.45,234.5,15,63,1,4,AAPL,-156,-2.3273119439201944,0.03004176064704839
2024-10-21T12:29:07.476323268Z,2024-10-21T12:29:07.476155585Z,10,2,38,C,B,0,233.86,30,130,167683,13271447,233.86,233.99,117,200,2,1,233.81,234.0,2,17,2,2,233.8,234.07,105,7,2,1,233.76,234.1,400,100,1,1,233.7,234.13,1200,400,1,1,233.66,234.17,1,1,1,1,233.58,234.25,505,100,2,1,233.53,234.41,10,500,1,1,233.5,234.43,100,105,1,2,233.45,234.5,15,63,1,4,AAPL,-156,-2.3389558232931726,0.030192063934942365
2024-10-21T12:29:07.543978531Z,2024-10-21T12:29:07.543812287Z,10,2,38,C,B,3,233.76,400,130,166244,13271500,233.86,233.99,117,200,2,1,233.81,234.0,2,17,2,2,233.8,234.07,105,7,2,1,233.7,234.1,1200,100,1,1,233.66,234.13,1,400,1,1,233.58,234.17,505,1,2,1,233.53,234.25,10,100,1,1,233.5,234.41,100,500,1,1,233.45,234.43,15,105,1,2,233.4,234.5,110,63,2,4,AAPL,-266,-3.9743364387414313,0.051302131772846246
2024-10-21T12:29:07.573087456Z,2024-10-21T12:29:07.572921012Z,10,2,38,C,A,2,234.07,7,130,166444,13271562,233.86,233.99,117,200,2,1,233.81,234.0,2,17,2,2,233.8,234.1,105,100,2,1,233.7,234.13,1200,400,1,1,233.66,234.17,1,1,1,1,233.58,234.25,505,100,2,1,233.53,234.41,10,500,1,1,233.5,234.43,100,105,1,2,233.45,234.5,15,63,1,4,233.4,234.59,110,60,2,1,AAPL,-206,-3.0682369241427088,0.039605880734779574
2024-10-21T12:29:07.583042273Z,2024-10-21T12:29:07.582875842Z,10,2,38,A,B,3,233.74,200,130,166431,13271567,233.86,233.99,117,200,2,1,233.81,234.0,2,17,2,2,233.8,234.1,105,100,2,1,233.74,234.13,200,400,1,1,233.7,234.17,1200,1,1,1,233.66,234.25,1,100,1,1,233.58,234.41,505,500,2,1,233.53,234.43,10,105,1,2,233.5,234.5,100,63,1,4,233.45,234.59,15,60,1,1,AAPL,-191,-2.859330637529037,0.03690924495438639
2024-10-21T12:29:07.715099060Z,2024-10-21T12:29:07.714932040Z,10,2,38,A,B,3,233.76,200,130,167020,13271618,233.86,233.99,117,200,2,1,233.81,234.0,2,17,2,2,233.8,234.1,105,100,2,1,233.76,234.13,200,400,1,1,233.7,234.17,1200,1,1,1,233.66,234.25,1,100,1,1,233.58,234.41,505,500,2,1,233.53,234.43,10,105,1,2,233.5,234.5,100,63,1,4,233.45,234.59,15,60,1,1,AAPL,-191,-2.8736536160027355,0.03709413099520431
2024-10-21T12:29:08.288393145Z,2024-10-21T12:29:08.288226889Z,10,2,38,A,B,3,233.77,200,130,166256,13272141,233.86,233.99,117,200,2,1,233.81,234.0,2,17,2,2,233.8,234.1,105,100,2,1,233.77,234.13,200,400,1,1,233.7,234.17,1200,1,1,1,233.66,234.25,1,100,1,1,233.58,234.41,505,500,2,1,233.53,234.43,10,105,1,2,233.5,234.5,100,63,1,4,233.45,234.59,15,60,1,1,AAPL,-191,-2.887794105155865,0.037276661399725394
2024-10-21T12:29:08.937139462Z,2024-10-21T12:29:08.936973408Z,10,2,38,C,A,0,233.99,200,130,166054,13272432,233.86,234.0,117,17,2,2,233.81,234.1,2,100,2,1,233.8,234.13,105,400,2,1,233.77,234.17,200,1,1,1,233.7,234.25,1200,100,1,1,233.66,234.41,1,500,1,1,233.58,234.43,505,105,2,2,233.53,234.5,10,63,1,4,233.5,234.59,100,60,1,1,233.45,234.75,15,1,1,1,AAPL,-190,-2.8878831867475023,0.03727781129622338
2024-10-21T12:29:08.937151622Z,2024-10-21T12:29:08.936985355Z,10,2,38,A,A,1,234.01,200,130,166267,13272433,233.86,234.0,117,17,2,2,233.81,234.01,2,200,2,1,233.8,234.1,105,100,2,1,233.77,234.13,200,400,1,1,233.7,234.17,1200,1,1,1,233.66,234.25,1,100,1,1,233.58,234.41,505,500,2,1,233.53,234.43,10,105,1,2,233.5,234.5,100,63,1,4,233.45,234.59,15,60,1,1,AAPL,-250,-3.8180892584422197,0.049285238246996634
2024-10-21T12:29:08.992072347Z,2024-10-21T12:29:08.991905949Z,10,2,38,A,B,3,233.78,200,130,166398,13272483,233.86,234.0,117,17,2,2,233.81,234.01,2,200,2,1,233.8,234.1,105,100,2,1,233.78,234.13,200,400,1,1,233.7,234.17,1200,1,1,1,233.66,234.25,1,100,1,1,233.58,234.41,505,500,2,1,233.53,234.43,10,105,1,2,233.5,234.5,100,63,1,4,233.45,234.59,15,60,1,1,AAPL,-250,-3.836101509147627,0.04951774671059992
2024-10-21T12:29:09.054222160Z,2024-10-21T12:29:09.054055599Z,10,2,38,A,A,0,234.0,200,130,166561,13272549,233.86,234.0,117,217,2,3,233.81,234.1,2,100,2,1,233.8,234.13,105,400,2,1,233.78,234.17,200,1,1,1,233.7,234.25,1200,100,1,1,233.66,234.41,1,500,1,1,233.58,234.43,505,105,2,2,233.53,234.5,10,63,1,4,233.5,234.59,100,60,1,1,233.45,234.75,15,1,1,1,AAPL,-249,-3.8575397827734275,0.04979447948234319
2024-10-21T12:29:09.096780188Z,2024-10-21T12:29:09.096609749Z,10,2,38,T,A,0,233.86,17,0,170439,13272571,233.86,234.0,117,217,2,3,233.81,234.1,2,100,2,1,233.8,234.13,105,400,2,1,233.78,234.17,200,1,1,1,233.7,234.25,1200,100,1,1,233.66,234.41,1,500,1,1,233.58,234.43,505,105,2,2,233.53,234.5,10,63,1,4,233.5,234.59,100,60,1,1,233.45,234.75,15,1,1,1,AAPL,-249,-3.894223492810897,0.05026800570622148
2024-10-21T12:29:09.096780188Z,2024-10-21T12:29:09.096609749Z,10,2,38,T,A,0,233.86,100,0,170439,13272572,233.86,234.0,100,217,1,3,233.81,234.1,2,100,2,1,233.8,234.13,105,400,2,1,233.78,234.17,200,1,1,1,233.7,234.25,1200,100,1,1,233.66,234.41,1,500,1,1,233.58,234.43,505,105,2,2,233.53,234.5,10,63,1,4,233.5,234.59,100,60,1,1,233.45,234.75,15,1,1,1,AAPL,-249,-3.930808632126963,0.05074025954457924
2024-10-21T12:29:09.096780188Z,2024-10-21T12:29:09.096609749Z,10,2,38,T,N,0,233.86,683,130,170439,13272573,233.81,234.0,2,217,2,3,233.8,234.1,105,100,2,1,233.78,234.13,200,400,1,1,233.7,234.17,1200,1,1,1,233.66,234.25,1,100,1,1,233.58,234.41,505,500,2,1,233.53,234.43,10,105,1,2,233.5,234.5,100,63,1,4,233.45,234.59,15,60,1,1,233.4,234.75,110,1,2,1,AAPL,-359,-5.674708818635607,0.0732511361515152
2024-10-21T12:29:09.096791448Z,2024-10-21T12:29:09.096622742Z,10,2,38,A,B,0,233.86,100,130,168706,13272574,233.86,234.0,100,217,1,3,233.81,234.1,2,100,2,1,233.8,234.13,105,400,2,1,233.78,234.17,200,1,1,1,233.7,234.25,1200,100,1,1,233.66,234.41,1,500,1,1,233.58,234.43,505,105,2,2,233.53,234.5,10,63,1,4,233.5,234.59,100,60,1,1,233.45,234.75,15,1,1,1,AAPL,-344,-5.487537387836491,0.0708350615300095
2024-10-21T12:29:09.096803407Z,2024-10-21T12:29:09.096634813Z,10,2,38,A,A,0,233.92,100,130,168594,13272575,233.86,233.92,100,100,1,1,233.81,234.0,2,217,2,3,233.8,234.1,105,100,2,1,233.78,234.13,200,400,1,1,233.7,234.17,1200,1,1,1,233.66,234.25,1,100,1,1,233.58,234.41,505,500,2,1,233.53,234.43,10,105,1,2,233.5,234.5,100,63,1,4,233.45,234.59,15,60,1,1,AAPL,-404,-6.471472215341426,0.08353603814701076
2024-10-21T12:29:09.096806296Z,2024-10-21T12:29:09.096639241Z,10,2,38,A,A,1,233.93,135,130,167055,13272576,233.86,233.92,100,100,1,1,233.81,233.93,2,135,2,1,233.8,234.0,105,217,2,3,233.78,234.1,200,100,1,1,233.7,234.13,1200,400,1,1,233.66,234.17,1,1,1,1,233.58,234.25,505,100,2,1,233.53,234.41,10,500,1,1,233.5,234.43,100,105,1,2,233.45,234.5,15,63,1,4,AAPL,-467,-7.509393715645254,0.09693389371339038
2024-10-21T12:29:09.096808055Z,2024-10-21T12:29:09.096640225Z,10,2,38,A,A,2,233.97,100,130,167830,13272577,233.86,233.92,100,100,1,1,233.81,233.93,2,135,2,1,233.8,233.97,105,100,2,1,233.78,234.0,200,217,1,3,233.7,234.1,1200,100,1,1,233.66,234.13,1,400,1,1,233.58,234.17,505,1,2,1,233.53,234.25,10,100,1,1,233.5,234.41,100,500,1,1,233.45,234.43,15,105,1,2,AAPL,-572,-9.201072386058982,0.11877067663415425
