ts_recv,ts_event,rtype,publisher_id,instrument_id,action,side,depth,price,size,flags,ts_in_delta,sequence,bid_px_00,ask_px_00,bid_sz_00,ask_sz_00,bid_ct_00,ask_ct_00,bid_px_01,ask_px_01,bid_sz_01,ask_sz_01,bid_ct_01,ask_ct_01,bid_px_02,ask_px_02,bid_sz_02,ask_sz_02,bid_ct_02,ask_ct_02,bid_px_03,ask_px_03,bid_sz_03,ask_sz_03,bid_ct_03,ask_ct_03,bid_px_04,ask_px_04,bid_sz_04,ask_sz_04,bid_ct_04,ask_ct_04,bid_px_05,ask_px_05,bid_sz_05,ask_sz_05,bid_ct_05,ask_ct_05,bid_px_06,ask_px_06,bid_sz_06,ask_sz_06,bid_ct_06,ask_ct_06,bid_px_07,ask_px_07,bid_sz_07,ask_sz_07,bid_ct_07,ask_ct_07,bid_px_08,ask_px_08,bid_sz_08,ask_sz_08,bid_ct_08,ask_ct_08,bid_px_09,ask_px_09,bid_sz_09,ask_sz_09,bid_ct_09,ask_ct_09,symbol,ofi_best_level,multi_level_ofi,integrated_ofi
2024-10-21T12:09:15.972968249Z,2024-10-21T12:09:15.972801291Z,10,2,38,T,N,0,233.98,30,130,166958,12187912,233.9,234.0,10,154,1,7,233.74,234.07,400,200,1,1,233.72,234.13,28,400,1,1,233.7,234.14,1200,28,1,1,233.66,234.17,1,1,1,1,233.58,234.25,505,50,2,1,233.53,234.41,10,600,1,2,233.45,234.43,15,105,1,2,233.4,234.5,110,63,2,4,233.39,234.75,10,1,1,1,AAPL,5626,15.88324757524703,-0.2050265428319158
2024-10-21T12:09:16.178222372Z,2024-10-21T12:09:16.178054946Z,10,2,38,T,N,0,233.98,50,130,167426,12188119,233.9,234.0,10,154,1,7,233.74,234.07,400,200,1,1,233.72,234.13,28,400,1,1,233.7,234.14,1200,28,1,1,233.66,234.17,1,1,1,1,233.58,234.25,505,50,2,1,233.53,234.41,10,600,1,2,233.45,234.43,15,105,1,2,233.4,234.5,110,63,2,4,233.39,234.75,10,1,1,1,AAPL,5626,16.387402148188603,-0.21153434727514564
2024-10-21T12:09:17.673807276Z,2024-10-21T12:09:17.673639410Z,10,2,38,T,N,0,233.98,3,130,167866,12189121,233.9,234.0,10,154,1,7,233.74,234.07,400,200,1,1,233.72,234.13,28,400,1,1,233.7,234.14,1200,28,1,1,233.66,234.17,1,1,1,1,233.58,234.25,505,50,2,1,233.53,234.41,10,600,1,2,233.45,234.43,15,105,1,2,233.4,234.5,110,63,2,4,233.39,234.75,10,1,1,1,AAPL,5736,18.472500377396468,-0.23844952815198775
2024-10-21T12:09:18.369511364Z,2024-10-21T12:09:18.369344833Z,10,2,38,A,B,1,233.77,26,130,166531,12189523,233.9,234.0,10,154,1,7,233.77,234.07,26,200,1,1,233.74,234.13,400,400,1,1,233.72,234.14,28,28,1,1,233.7,234.17,1200,1,1,1,233.66,234.25,1,50,1,1,233.58,234.41,505,600,2,2,233.53,234.43,10,105,1,2,233.45,234.5,15,63,1,4,233.4,234.75,110,1,2,1,AAPL,5846,19.307245796637307,-0.2492247154454507
2024-10-21T12:09:18.369536160Z,2024-10-21T12:09:18.369370009Z,10,2,38,C,B,3,233.72,28,130,166151,12189524,233.9,234.0,10,154,1,7,233.77,234.07,26,200,1,1,233.74,234.13,400,400,1,1,233.7,234.14,1200,28,1,1,233.66,234.17,1,1,1,1,233.58,234.25,505,50,2,1,233.53,234.41,10,600,1,2,233.45,234.43,15,105,1,2,233.4,234.5,110,63,2,4,233.39,234.75,10,1,1,1,AAPL,5836,19.847361840460113,-0.25619672319565534
2024-10-21T12:09:18.424192189Z,2024-10-21T12:09:18.424025933Z,10,2,38,A,B,1,233.83,200,130,166256,12189542,233.9,234.0,10,154,1,7,233.83,234.07,200,200,1,1,233.77,234.13,26,400,1,1,233.7,234.14,1200,28,1,1,233.66,234.17,1,1,1,1,233.58,234.25,505,50,2,1,233.53,234.41,10,600,1,2,233.45,234.43,15,105,1,2,233.4,234.5,110,63,2,4,233.39,234.75,10,1,1,1,AAPL,5836,20.419874037788663,-0.263586911882905
2024-10-21T12:09:26.336527240Z,2024-10-21T12:09:26.336360989Z,10,2,38,C,B,1,233.83,200,130,166251,12194498,233.9,234.0,10,154,1,7,233.77,234.07,26,200,1,1,233.7,234.13,1200,400,1,1,233.66,234.14,1,28,1,1,233.58,234.17,505,1,2,1,233.53,234.25,10,50,1,1,233.45,234.41,15,600,1,2,233.4,234.43,110,105,2,2,233.39,234.5,10,63,1,4,233.31,234.75,110,1,2,1,AAPL,5707,41.95730241764456,-0.5415996080454634
2024-10-21T12:09:26.336539345Z,2024-10-21T12:09:26.336373029Z,10,2,38,A,B,1,233.81,200,130,166316,12194499,233.9,234.0,10,154,1,7,233.81,234.07,200,200,1,1,233.77,234.13,26,400,1,1,233.7,234.14,1200,28,1,1,233.66,234.17,1,1,1,1,233.58,234.25,505,50,2,1,233.53,234.41,10,600,1,2,233.45,234.43,15,105,1,2,233.4,234.5,110,63,2,4,233.39,234.75,10,1,1,1,AAPL,5717,43.57961603613777,-0.5625410024934829
2024-10-21T12:09:26.336551701Z,2024-10-21T12:09:26.336385729Z,10,2,38,A,A,1,234.07,200,130,165972,12194500,233.9,234.0,10,154,1,7,233.81,234.07,200,400,1,2,233.77,234.13,26,400,1,1,233.7,234.14,1200,28,1,1,233.66,234.17,1,1,1,1,233.58,234.25,505,50,2,1,233.53,234.41,10,600,1,2,233.45,234.43,15,105,1,2,233.4,234.5,110,63,2,4,233.39,234.75,10,1,1,1,AAPL,5717,45.123608174770965,-0.5824713957486354
2024-10-21T12:09:26.402049735Z,2024-10-21T12:09:26.401883038Z,10,2,38,A,B,1,233.82,200,130,166697,12194620,233.9,234.0,10,154,1,7,233.82,234.07,200,400,1,2,233.77,234.13,26,400,1,1,233.7,234.14,1200,28,1,1,233.66,234.17,1,1,1,1,233.58,234.25,505,50,2,1,233.53,234.41,10,600,1,2,233.45,234.43,15,105,1,2,233.4,234.5,110,63,2,4,233.39,234.75,10,1,1,1,AAPL,5717,46.662820151984235,-0.6023400849999019
2024-10-21T12:09:30.048934813Z,2024-10-21T12:09:30.048768796Z,10,2,38,C,A,1,234.07,200,130,166017,12197231,233.9,234.0,10,154,1,7,233.82,234.07,200,200,1,1,233.77,234.13,26,400,1,1,233.7,234.14,1200,28,1,1,233.66,234.17,1,1,1,1,233.58,234.25,505,50,2,1,233.53,234.41,10,600,1,2,233.45,234.43,15,105,1,2,233.4,234.5,110,63,2,4,233.39,234.75,10,1,1,1,AAPL,5707,45.36031792758316,-0.5855269284439335
2024-10-21T12:09:30.048946954Z,2024-10-21T12:09:30.048780765Z,10,2,38,A,A,1,234.06,200,130,166189,12197232,233.9,234.0,10,154,1,7,233.82,234.06,200,200,1,1,233.77,234.13,26,400,1,1,233.7,234.14,1200,28,1,1,233.66,234.17,1,1,1,1,233.58,234.25,505,50,2,1,233.53,234.41,10,600,1,2,233.45,234.43,15,105,1,2,233.4,234.5,110,63,2,4,233.39,234.75,10,1,1,1,AAPL,5707,46.964290962527556,-0.6062315761925946
2024-10-21T12:09:30.065649441Z,2024-10-21T12:09:30.065483395Z,10,2,38,C,A,3,234.14,28,130,166046,12197308,233.9,234.0,10,154,1,7,233.82,234.06,200,200,1,1,233.77,234.13,26,400,1,1,233.7,234.17,1200,1,1,1,233.66,234.25,1,50,1,1,233.58,234.41,505,600,2,2,233.53,234.43,10,105,1,2,233.45,234.5,15,63,1,4,233.4,234.75,110,1,2,1,233.39,234.79,10,2000,1,1,AAPL,7707,50.70969937606353,-0.6545786245454507
2024-10-21T12:09:30.066411685Z,2024-10-21T12:09:30.066245031Z,10,2,38,A,A,2,234.13,30,130,166654,12197309,233.9,234.0,10,154,1,7,233.82,234.06,200,200,1,1,233.77,234.13,26,430,1,2,233.7,234.17,1200,1,1,1,233.66,234.25,1,50,1,1,233.58,234.41,505,600,2,2,233.53,234.43,10,105,1,2,233.45,234.5,15,63,1,4,233.4,234.75,110,1,2,1,233.39,234.79,10,2000,1,1,AAPL,7707,42.71778290993072,-0.5514161575568828
2024-10-21T12:09:32.078130281Z,2024-10-21T12:09:32.077963808Z,10,2,38,A,B,0,233.9,1,130,166473,12199244,233.9,234.0,11,154,2,7,233.82,234.06,200,200,1,1,233.77,234.13,26,430,1,2,233.7,234.17,1200,1,1,1,233.66,234.25,1,50,1,1,233.58,234.41,505,600,2,2,233.53,234.43,10,105,1,2,233.45,234.5,15,63,1,4,233.4,234.75,110,1,2,1,233.39,234.79,10,2000,1,1,AAPL,7697,36.01216469120399,-0.46485768049336146
2024-10-21T12:09:37.644521809Z,2024-10-21T12:09:37.644355301Z,10,2,38,A,B,1,233.83,200,130,166508,12202648,233.9,234.0,11,154,2,7,233.83,234.06,200,200,1,1,233.77,234.13,26,430,1,2,233.7,234.17,1200,1,1,1,233.66,234.25,1,50,1,1,233.58,234.41,505,600,2,2,233.53,234.43,10,105,1,2,233.45,234.5,15,63,1,4,233.4,234.75,110,1,2,1,233.39,234.79,10,2000,1,1,AAPL,2000,6.706586826347305,-0.08657098019116362
2024-10-21T12:09:38.208305707Z,2024-10-21T12:09:38.208139554Z,10,2,38,A,B,0,233.97,2,130,166153,12203420,233.97,234.0,2,154,1,7,233.9,234.06,11,200,2,1,233.83,234.13,200,430,1,2,233.77,234.17,26,1,1,1,233.7,234.25,1200,50,1,1,233.66,234.41,1,600,1,2,233.58,234.43,505,105,2,2,233.53,234.5,10,63,1,4,233.45,234.75,15,1,1,1,233.4,234.79,110,2000,2,1,AAPL,2110,5.65412958177816,-0.07298549212833841
2024-10-21T12:09:42.372781724Z,2024-10-21T12:09:42.372615871Z,10,2,38,C,A,1,234.06,200,130,165853,12205636,233.97,234.0,2,154,1,7,233.9,234.13,11,430,2,2,233.83,234.17,200,1,1,1,233.77,234.25,26,50,1,1,233.7,234.41,1200,600,1,2,233.66,234.43,1,105,1,2,233.58,234.5,505,63,2,4,233.53,234.75,10,1,1,1,233.45,234.79,15,2000,1,1,233.4,234.89,110,2,2,2,AAPL,2012,4.630609896432682,-0.059773540251832444
2024-10-21T12:09:42.372793881Z,2024-10-21T12:09:42.372627823Z,10,2,38,A,A,1,234.07,200,130,166058,12205637,233.97,234.0,2,154,1,7,233.9,234.07,11,200,2,1,233.83,234.13,200,430,1,2,233.77,234.17,26,1,1,1,233.7,234.25,1200,50,1,1,233.66,234.41,1,600,1,2,233.58,234.43,505,105,2,2,233.53,234.5,10,63,1,4,233.45,234.75,15,1,1,1,233.4,234.79,110,2000,2,1,AAPL,12,0.02488435157122348,-0.00032121595719586664
2024-10-21T12:09:43.901481889Z,2024-10-21T12:09:43.901315169Z,10,2,38,A,B,1,233.95,10,130,166720,12207173,233.97,234.0,2,154,1,7,233.95,234.07,10,200,1,1,233.9,234.13,11,430,2,2,233.83,234.17,200,1,1,1,233.77,234.25,26,50,1,1,233.7,234.41,1200,600,1,2,233.66,234.43,1,105,1,2,233.58,234.5,505,63,2,4,233.53,234.75,10,1,1,1,233.45,234.79,15,2000,1,1,AAPL,27,0.05194805194805195,-0.0006705637148387906
2024-10-21T12:09:45.133575558Z,2024-10-21T12:09:45.133407519Z,10,2,38,T,N,0,233.98,17,130,168039,12207963,233.97,234.0,2,154,1,7,233.95,234.07,10,200,1,1,233.9,234.13,11,430,2,2,233.83,234.17,200,1,1,1,233.77,234.25,26,50,1,1,233.7,234.41,1200,600,1,2,233.66,234.43,1,105,1,2,233.58,234.5,505,63,2,4,233.53,234.75,10,1,1,1,233.45,234.79,15,2000,1,1,AAPL,27,0.048889425398358284,-0.0006310818881955482
2024-10-21T12:09:45.628746056Z,2024-10-21T12:09:45.628579880Z,10,2,38,A,B,9,233.5,100,130,166176,12208190,233.97,234.0,2,154,1,7,233.95,234.07,10,200,1,1,233.9,234.13,11,430,2,2,233.83,234.17,200,1,1,1,233.77,234.25,26,50,1,1,233.7,234.41,1200,600,1,2,233.66,234.43,1,105,1,2,233.58,234.5,505,63,2,4,233.53,234.75,10,1,1,1,233.5,234.79,100,2000,1,1,AAPL,127,0.21769873580458537,-0.002810131805189
2024-10-21T12:09:48.089517540Z,2024-10-21T12:09:48.089350946Z,10,2,38,A,A,1,234.07,200,130,166594,12210108,233.97,234.0,2,154,1,7,233.95,234.07,10,400,1,2,233.9,234.13,11,430,2,2,233.83,234.17,200,1,1,1,233.77,234.25,26,50,1,1,233.7,234.41,1200,600,1,2,233.66,234.43,1,105,1,2,233.58,234.5,505,63,2,4,233.53,234.75,10,1,1,1,233.5,234.79,100,2000,1,1,AAPL,227,0.2861714507370054,-0.0036940016784249865
2024-10-21T12:09:48.587196262Z,2024-10-21T12:09:48.587030358Z,10,2,38,C,A,1,234.07,200,130,165904,12210833,233.97,234.0,2,154,1,7,233.95,234.07,10,200,1,1,233.9,234.13,11,430,2,2,233.83,234.17,200,1,1,1,233.77,234.25,26,50,1,1,233.7,234.41,1200,600,1,2,233.66,234.43,1,105,1,2,233.58,234.5,505,63,2,4,233.53,234.75,10,1,1,1,233.5,234.79,100,2000,1,1,AAPL,227,0.2797042774159479,-0.0036105211319164996
2024-10-21T12:09:48.587209868Z,2024-10-21T12:09:48.587043020Z,10,2,38,A,A,1,234.06,200,130,166848,12210834,233.97,234.0,2,154,1,7,233.95,234.06,10,200,1,1,233.9,234.13,11,430,2,2,233.83,234.17,200,1,1,1,233.77,234.25,26,50,1,1,233.7,234.41,1200,600,1,2,233.66,234.43,1,105,1,2,233.58,234.5,505,63,2,4,233.53,234.75,10,1,1,1,233.5,234.79,100,2000,1,1,AAPL,227,0.2743312922977763,-0.0035411647513496672
2024-10-21T12:09:49.792890933Z,2024-10-21T12:09:49.792724444Z,10,2,38,A,A,1,234.06,200,130,166489,12211836,233.97,234.0,2,154,1,7,233.95,234.06,10,400,1,2,233.9,234.13,11,430,2,2,233.83,234.17,200,1,1,1,233.77,234.25,26,50,1,1,233.7,234.41,1200,600,1,2,233.66,234.43,1,105,1,2,233.58,234.5,505,63,2,4,233.53,234.75,10,1,1,1,233.5,234.79,100,2000,1,1,AAPL,227,0.26979646412123015,-0.003482627595206424
2024-10-21T12:09:53.122619723Z,2024-10-21T12:09:53.122453611Z,10,2,38,C,B,0,233.97,2,130,166112,12214081,233.95,234.0,10,154,1,7,233.9,234.06,11,400,2,2,233.83,234.13,200,430,1,2,233.77,234.17,26,1,1,1,233.7,234.25,1200,50,1,1,233.66,234.41,1,600,1,2,233.58,234.43,505,105,2,2,233.53,234.5,10,63,1,4,233.5,234.75,100,1,1,1,233.45,234.79,15,2000,1,1,AAPL,-1788,-1.8749508454581203,0.02420252457835767
2024-10-21T12:09:53.247175609Z,2024-10-21T12:09:53.247009420Z,10,2,38,A,B,3,233.81,30,130,166189,12214171,233.95,234.0,10,154,1,7,233.9,234.06,11,400,2,2,233.83,234.13,200,430,1,2,233.81,234.17,30,1,1,1,233.77,234.25,26,50,1,1,233.7,234.41,1200,600,1,2,233.66,234.43,1,105,1,2,233.58,234.5,505,63,2,4,233.53,234.75,10,1,1,1,233.5,234.79,100,2000,1,1,AAPL,-1688,-1.7564333453395766,0.02267265902666439
2024-10-21T12:09:53.247209179Z,2024-10-21T12:09:53.247043259Z,10,2,38,C,B,4,233.77,26,130,165920,12214172,233.95,234.0,10,154,1,7,233.9,234.06,11,400,2,2,233.83,234.13,200,430,1,2,233.81,234.17,30,1,1,1,233.7,234.25,1200,50,1,1,233.66,234.41,1,600,1,2,233.58,234.43,505,105,2,2,233.53,234.5,10,63,1,4,233.5,234.75,100,1,1,1,233.45,234.79,15,2000,1,1,AAPL,-1703,-1.7659432634619656,0.02279541639262566
2024-10-21T12:09:53.300084898Z,2024-10-21T12:09:53.299918437Z,10,2,38,A,B,2,233.86,200,130,166461,12214205,233.95,234.0,10,154,1,7,233.9,234.06,11,400,2,2,233.86,234.13,200,430,1,2,233.81,234.17,30,1,1,1,233.7,234.25,1200,50,1,1,233.66,234.41,1,600,1,2,233.58,234.43,505,105,2,2,233.53,234.5,10,63,1,4,233.5,234.75,100,1,1,1,233.45,234.79,15,2000,1,1,AAPL,-1703,-1.7606920081331634,0.02272763134296932
2024-10-21T12:09:54.364146144Z,2024-10-21T12:09:54.363979828Z,10,2,38,C,A,1,234.06,200,130,166316,12214797,233.95,234.0,10,154,1,7,233.9,234.06,11,200,2,1,233.86,234.13,200,430,1,2,233.81,234.17,30,1,1,1,233.7,234.25,1200,50,1,1,233.66,234.41,1,600,1,2,233.58,234.43,505,105,2,2,233.53,234.5,10,63,1,4,233.5,234.75,100,1,1,1,233.45,234.79,15,2000,1,1,AAPL,-1703,-1.7561227120391854,0.02266864926283203
2024-10-21T12:09:54.364156991Z,2024-10-21T12:09:54.363990119Z,10,2,38,C,A,1,234.06,200,130,166872,12214798,233.95,234.0,10,154,1,7,233.9,234.13,11,430,2,2,233.86,234.17,200,1,1,1,233.81,234.25,30,50,1,1,233.7,234.41,1200,600,1,2,233.66,234.43,1,105,1,2,233.58,234.5,505,63,2,4,233.53,234.75,10,1,1,1,233.5,234.79,100,2000,1,1,233.45,234.89,15,2,1,2,AAPL,-1701,-1.8626686849818028,0.024043982133619187
2024-10-21T12:09:54.402511703Z,2024-10-21T12:09:54.402345010Z,10,2,38,A,A,1,234.06,200,130,166693,12214808,233.95,234.0,10,154,1,7,233.9,234.06,11,200,2,1,233.86,234.13,200,430,1,2,233.81,234.17,30,1,1,1,233.7,234.25,1200,50,1,1,233.66,234.41,1,600,1,2,233.58,234.43,505,105,2,2,233.53,234.5,10,63,1,4,233.5,234.75,100,1,1,1,233.45,234.79,15,2000,1,1,AAPL,-3701,-4.029639487055408,0.05201600296009334
2024-10-21T12:09:57.392768641Z,2024-10-21T12:09:57.392602293Z,10,2,38,A,A,1,234.05,200,130,166348,12217320,233.95,234.0,10,154,1,7,233.9,234.05,11,200,2,1,233.86,234.13,200,430,1,2,233.81,234.17,30,1,1,1,233.7,234.25,1200,50,1,1,233.66,234.41,1,600,1,2,233.58,234.43,505,105,2,2,233.53,234.5,10,63,1,4,233.5,234.75,100,1,1,1,233.45,234.79,15,2000,1,1,AAPL,-3701,-4.009179281051341,0.051751895429012595
2024-10-21T12:09:57.433120140Z,2024-10-21T12:09:57.432954262Z,10,2,38,C,A,2,234.13,30,130,165878,12217490,233.95,234.0,10,154,1,7,233.9,234.05,11,200,2,1,233.86,234.13,200,400,1,1,233.81,234.17,30,1,1,1,233.7,234.25,1200,50,1,1,233.66,234.41,1,600,1,2,233.58,234.43,505,105,2,2,233.53,234.5,10,63,1,4,233.5,234.75,100,1,1,1,233.45,234.79,15,2000,1,1,AAPL,-3701,-3.9909419313096457,0.05151648130792419
2024-10-21T12:09:57.433181540Z,2024-10-21T12:09:57.433015324Z,10,2,38,A,A,2,234.12,27,130,166216,12217491,233.95,234.0,10,154,1,7,233.9,234.05,11,200,2,1,233.86,234.12,200,27,1,1,233.81,234.13,30,400,1,1,233.7,234.17,1200,1,1,1,233.66,234.25,1,50,1,1,233.58,234.41,505,600,2,2,233.53,234.43,10,105,1,2,233.5,234.5,100,63,1,4,233.45,234.75,15,1,1,1,AAPL,-3702,-4.18981406628941,0.054083592731915764
2024-10-21T12:10:00.023985986Z,2024-10-21T12:10:00.023818184Z,10,2,38,T,N,0,233.98,2,130,167802,12219639,233.95,234.0,10,154,1,7,233.9,234.05,11,200,2,1,233.86,234.12,200,27,1,1,233.81,234.13,30,400,1,1,233.7,234.17,1200,1,1,1,233.66,234.25,1,50,1,1,233.58,234.41,505,600,2,2,233.53,234.43,10,105,1,2,233.5,234.5,100,63,1,4,233.45,234.75,15,1,1,1,AAPL,-3812,-4.619766103132764,0.05963356475620831
2024-10-21T12:10:01.648468232Z,2024-10-21T12:10:01.648302231Z,10,2,38,C,B,2,233.86,200,130,166001,12221707,233.95,234.0,10,154,1,7,233.9,234.05,11,200,2,1,233.81,234.12,30,27,1,1,233.7,234.13,1200,400,1,1,233.66,234.17,1,1,1,1,233.58,234.25,505,50,2,1,233.53,234.41,10,600,1,2,233.5,234.43,100,105,1,2,233.45,234.5,15,63,1,4,233.4,234.75,110,1,2,1,AAPL,-3922,-4.974001268230818,0.06420615678472598
2024-10-21T12:10:01.648480569Z,2024-10-21T12:10:01.648314395Z,10,2,38,A,B,2,233.84,200,130,166174,12221708,233.95,234.0,10,154,1,7,233.9,234.05,11,200,2,1,233.84,234.12,200,27,1,1,233.81,234.13,30,400,1,1,233.7,234.17,1200,1,1,1,233.66,234.25,1,50,1,1,233.58,234.41,505,600,2,2,233.53,234.43,10,105,1,2,233.5,234.5,100,63,1,4,233.45,234.75,15,1,1,1,AAPL,-3907,-5.188422418736607,0.06697398036677198
2024-10-21T12:10:01.702740055Z,2024-10-21T12:10:01.702573654Z,10,2,38,A,A,1,234.04,200,130,166401,12221881,233.95,234.0,10,154,1,7,233.9,234.04,11,200,2,1,233.84,234.12,200,27,1,1,233.81,234.13,30,400,1,1,233.7,234.17,1200,1,1,1,233.66,234.25,1,50,1,1,233.58,234.41,505,600,2,2,233.53,234.43,10,105,1,2,233.5,234.5,100,63,1,4,233.45,234.75,15,1,1,1,AAPL,-3907,-5.421641678482005,0.0699844565506184
2024-10-21T12:10:01.719186937Z,2024-10-21T12:10:01.719020950Z,10,2,38,C,A,1,234.04,200,130,165987,12221965,233.95,234.0,10,154,1,7,233.9,234.12,11,27,2,1,233.84,234.13,200,400,1,1,233.81,234.17,30,1,1,1,233.7,234.25,1200,50,1,1,233.66,234.41,1,600,1,2,233.58,234.43,505,105,2,2,233.53,234.5,10,63,1,4,233.5,234.75,100,1,1,1,233.45,234.79,15,2000,1,1,AAPL,-1907,-2.6031168240245703,0.03360194698778745
2024-10-21T12:10:01.719199386Z,2024-10-21T12:10:01.719033080Z,10,2,38,A,A,1,234.09,200,130,166306,12221966,233.95,234.0,10,154,1,7,233.9,234.09,11,200,2,1,233.84,234.12,200,27,1,1,233.81,234.13,30,400,1,1,233.7,234.17,1200,1,1,1,233.66,234.25,1,50,1,1,233.58,234.41,505,600,2,2,233.53,234.43,10,105,1,2,233.5,234.5,100,63,1,4,233.45,234.75,15,1,1,1,AAPL,-1908,-2.711768050028425,0.03500445520510793
2024-10-21T12:10:01.724794250Z,2024-10-21T12:10:01.724626959Z,10,2,38,A,A,2,234.11,29,130,167291,12222034,233.95,234.0,10,154,1,7,233.9,234.09,11,200,2,1,233.84,234.11,200,29,1,1,233.81,234.12,30,27,1,1,233.7,234.13,1200,400,1,1,233.66,234.17,1,1,1,1,233.58,234.25,505,50,2,1,233.53,234.41,10,600,1,2,233.5,234.43,100,105,1,2,233.45,234.5,15,63,1,4,AAPL,-1971,-2.9069147427534174,0.037523477310942285
2024-10-21T12:10:01.726233514Z,2024-10-21T12:10:01.726066241Z,10,2,38,A,B,2,233.84,200,128,167273,12222037,233.95,234.0,10,154,1,7,233.9,234.09,11,200,2,1,233.84,234.11,400,29,2,1,233.81,234.12,30,27,1,1,233.7,234.13,1200,400,1,1,233.66,234.17,1,1,1,1,233.58,234.25,505,50,2,1,233.53,234.41,10,600,1,2,233.5,234.43,100,105,1,2,233.45,234.5,15,63,1,4,AAPL,-1971,-3.0120556939098937,0.03888067366663383
2024-10-21T12:10:01.752007708Z,2024-10-21T12:10:01.751841665Z,10,2,38,C,A,2,234.11,29,130,166043,12222181,233.95,234.0,10,154,1,7,233.9,234.09,11,200,2,1,233.84,234.12,400,27,2,1,233.81,234.13,30,400,1,1,233.7,234.17,1200,1,1,1,233.66,234.25,1,50,1,1,233.58,234.41,505,600,2,2,233.53,234.43,10,105,1,2,233.5,234.5,100,63,1,4,233.45,234.75,15,1,1,1,AAPL,-1970,-3.1206155238741795,0.040282002111748864
2024-10-21T12:10:01.781827461Z,2024-10-21T12:10:01.781661443Z,10,2,38,C,B,2,233.84,200,130,166018,12222265,233.95,234.0,10,154,1,7,233.9,234.09,11,200,2,1,233.84,234.12,200,27,1,1,233.81,234.13,30,400,1,1,233.7,234.17,1200,1,1,1,233.66,234.25,1,50,1,1,233.58,234.41,505,600,2,2,233.53,234.43,10,105,1,2,233.5,234.5,100,63,1,4,233.45,234.75,15,1,1,1,AAPL,-1970,-3.2306039357611405,0.04170177119448355
2024-10-21T12:10:01.781840313Z,2024-10-21T12:10:01.781673802Z,10,2,38,A,B,2,233.87,400,130,166511,12222266,233.95,234.0,10,154,1,7,233.9,234.09,11,200,2,1,233.87,234.12,400,27,1,1,233.81,234.13,30,400,1,1,233.7,234.17,1200,1,1,1,233.66,234.25,1,50,1,1,233.58,234.41,505,600,2,2,233.53,234.43,10,105,1,2,233.5,234.5,100,63,1,4,233.45,234.75,15,1,1,1,AAPL,-1970,-3.340492878137011,0.04312025628980449
2024-10-21T12:10:01.842942268Z,2024-10-21T12:10:01.842775879Z,10,2,38,C,A,2,234.12,27,130,166389,12222352,233.95,234.0,10,154,1,7,233.9,234.09,11,200,2,1,233.87,234.13,400,400,1,1,233.81,234.17,30,1,1,1,233.7,234.25,1200,50,1,1,233.66,234.41,1,600,1,2,233.58,234.43,505,105,2,2,233.53,234.5,10,63,1,4,233.5,234.75,100,1,1,1,233.45,234.79,15,2000,1,1,AAPL,30,0.04973395010561779,-0.0006419833099762799
2024-10-21T12:10:02.294263964Z,2024-10-21T12:10:02.294097461Z,10,2,38,A,A,3,234.16,27,130,166503,12222991,233.95,234.0,10,154,1,7,233.9,234.09,11,200,2,1,233.87,234.13,400,400,1,1,233.81,234.16,30,27,1,1,233.7,234.17,1200,1,1,1,233.66,234.25,1,50,1,1,233.58,234.41,505,600,2,2,233.53,234.43,10,105,1,2,233.5,234.5,100,63,1,4,233.45,234.75,15,1,1,1,AAPL,29,0.04960577308566083,-0.0006403287559470883
2024-10-21T12:10:03.086305082Z,2024-10-21T12:10:03.086137168Z,10,2,38,T,N,0,233.99,9,130,167914,12223722,233.95,234.0,10,154,1,7,233.9,234.09,11,200,2,1,233.87,234.13,400,400,1,1,233.81,234.16,30,27,1,1,233.7,234.17,1200,1,1,1,233.66,234.25,1,50,1,1,233.58,234.41,505,600,2,2,233.53,234.43,10,105,1,2,233.5,234.5,100,63,1,4,233.45,234.75,15,1,1,1,AAPL,2027,3.5693714675225086,-0.046074701574853466
2024-10-21T12:10:03.188762601Z,2024-10-21T12:10:03.188596704Z,10,2,38,C,B,2,233.87,400,130,165897,12223900,233.95,234.0,10,154,1,7,233.9,234.09,11,200,2,1,233.81,234.13,30,400,1,1,233.7,234.16,1200,27,1,1,233.66,234.17,1,1,1,1,233.58,234.25,505,50,2,1,233.53,234.41,10,600,1,2,233.5,234.43,100,105,1,2,233.45,234.5,15,63,1,4,233.4,234.75,110,1,2,1,AAPL,1917,3.47361268403171,-0.044838613537322325
2024-10-21T12:10:03.188775201Z,2024-10-21T12:10:03.188608784Z,10,2,38,A,B,2,233.86,400,130,166417,12223901,233.95,234.0,10,154,1,7,233.9,234.09,11,200,2,1,233.86,234.13,400,400,1,1,233.81,234.16,30,27,1,1,233.7,234.17,1200,1,1,1,233.66,234.25,1,50,1,1,233.58,234.41,505,600,2,2,233.53,234.43,10,105,1,2,233.5,234.5,100,63,1,4,233.45,234.75,15,1,1,1,AAPL,1932,3.6085578446909667,-0.0465805331057727
2024-10-21T12:10:03.188787374Z,2024-10-21T12:10:03.188621108Z,10,2,38,A,A,1,234.09,200,130,166266,12223902,233.95,234.0,10,154,1,7,233.9,234.09,11,400,2,2,233.86,234.13,400,400,1,1,233.81,234.16,30,27,1,1,233.7,234.17,1200,1,1,1,233.66,234.25,1,50,1,1,233.58,234.41,505,600,2,2,233.53,234.43,10,105,1,2,233.5,234.5,100,63,1,4,233.45,234.75,15,1,1,1,AAPL,1932,3.71622539035981,-0.04797034363155474
2024-10-21T12:10:03.197697662Z,2024-10-21T12:10:03.197531287Z,10,2,38,A,B,4,233.79,26,130,166375,12224056,233.95,234.0,10,154,1,7,233.9,234.09,11,400,2,2,233.86,234.13,400,400,1,1,233.81,234.16,30,27,1,1,233.79,234.17,26,1,1,1,233.7,234.25,1200,50,1,1,233.66,234.41,1,600,1,2,233.58,234.43,505,105,2,2,233.53,234.5,10,63,1,4,233.5,234.75,100,1,1,1,AAPL,2032,4.012072321101176,-0.05178923980691024
2024-10-21T12:10:03.247897243Z,2024-10-21T12:10:03.247731199Z,10,2,38,C,A,1,234.09,200,130,166044,12224474,233.95,234.0,10,154,1,7,233.9,234.09,11,200,2,1,233.86,234.13,400,400,1,1,233.81,234.16,30,27,1,1,233.79,234.17,26,1,1,1,233.7,234.25,1200,50,1,1,233.66,234.41,1,600,1,2,233.58,234.43,505,105,2,2,233.53,234.5,10,63,1,4,233.5,234.75,100,1,1,1,AAPL,2032,4.114980030376329,-0.05311760869138936
2024-10-21T12:10:03.247911445Z,2024-10-21T12:10:03.247744906Z,10,2,38,A,A,1,234.08,400,130,166539,12224475,233.95,234.0,10,154,1,7,233.9,234.08,11,400,2,1,233.86,234.13,400,400,1,1,233.81,234.16,30,27,1,1,233.79,234.17,26,1,1,1,233.7,234.25,1200,50,1,1,233.66,234.41,1,600,1,2,233.58,234.43,505,105,2,2,233.53,234.5,10,63,1,4,233.5,234.75,100,1,1,1,AAPL,2032,4.217304725844903,-0.0544384518287176
2024-10-21T12:10:03.255171170Z,2024-10-21T12:10:03.255005064Z,10,2,38,C,B,3,233.81,30,130,166106,12224539,233.95,234.0,10,154,1,7,233.9,234.08,11,400,2,1,233.86,234.13,400,400,1,1,233.79,234.16,26,27,1,1,233.7,234.17,1200,1,1,1,233.66,234.25,1,50,1,1,233.58,234.41,505,600,2,2,233.53,234.43,10,105,1,2,233.5,234.5,100,63,1,4,233.45,234.75,15,1,1,1,AAPL,2017,4.297384429929074,-0.055472148797904644
2024-10-21T12:10:03.258081034Z,2024-10-21T12:10:03.257914828Z,10,2,38,C,A,3,234.16,27,130,166206,12224582,233.95,234.0,10,154,1,7,233.9,234.08,11,400,2,1,233.86,234.13,400,400,1,1,233.79,234.17,26,1,1,1,233.7,234.25,1200,50,1,1,233.66,234.41,1,600,1,2,233.58,234.43,505,105,2,2,233.53,234.5,10,63,1,4,233.5,234.75,100,1,1,1,233.45,234.79,15,2000,1,1,AAPL,4017,8.31412195510269,-0.10732160869885085
2024-10-21T12:10:03.460121633Z,2024-10-21T12:10:03.459955473Z,10,2,38,C,A,1,234.08,400,130,166160,12225012,233.95,234.0,10,154,1,7,233.9,234.13,11,400,2,1,233.86,234.17,400,1,1,1,233.79,234.25,26,50,1,1,233.7,234.41,1200,600,1,2,233.66,234.43,1,105,1,2,233.58,234.5,505,63,2,4,233.53,234.75,10,1,1,1,233.5,234.79,100,2000,1,1,233.45,234.89,15,2,1,2,AAPL,4019,8.52770336577991,-0.11007859262401219
2024-10-21T12:10:03.460133284Z,2024-10-21T12:10:03.459967128Z,10,2,38,A,A,1,234.1,400,130,166156,12225013,233.95,234.0,10,154,1,7,233.9,234.1,11,400,2,1,233.86,234.13,400,400,1,1,233.79,234.17,26,1,1,1,233.7,234.25,1200,50,1,1,233.66,234.41,1,600,1,2,233.58,234.43,505,105,2,2,233.53,234.5,10,63,1,4,233.5,234.75,100,1,1,1,233.45,234.79,15,2000,1,1,AAPL,2019,4.168336774258522,-0.05380635629688426
2024-10-21T12:10:03.515049550Z,2024-10-21T12:10:03.514882942Z,10,2,38,A,B,2,233.87,400,130,166608,12225080,233.95,234.0,10,154,1,7,233.9,234.1,11,400,2,1,233.87,234.13,400,400,1,1,233.79,234.17,26,1,1,1,233.7,234.25,1200,50,1,1,233.66,234.41,1,600,1,2,233.58,234.43,505,105,2,2,233.53,234.5,10,63,1,4,233.5,234.75,100,1,1,1,233.45,234.79,15,2000,1,1,AAPL,2019,4.0638343756739275,-0.0524574026022486
2024-10-21T12:10:12.928144456Z,2024-10-21T12:10:12.927978411Z,10,2,38,C,B,3,233.79,26,130,166045,12232536,233.95,234.0,10,154,1,7,233.9,234.1,11,400,2,1,233.87,234.13,400,400,1,1,233.7,234.17,1200,1,1,1,233.66,234.25,1,50,1,1,233.58,234.41,505,600,2,2,233.53,234.43,10,105,1,2,233.5,234.5,100,63,1,4,233.45,234.75,15,1,1,1,233.4,234.79,110,2000,2,1,AAPL,1794,4.406509057414799,-0.056880767847958764
2024-10-21T12:10:12.928202744Z,2024-10-21T12:10:12.928036467Z,10,2,38,A,B,3,233.8,29,130,166277,12232537,233.95,234.0,10,154,1,7,233.9,234.1,11,400,2,1,233.87,234.13,400,400,1,1,233.8,234.17,29,1,1,1,233.7,234.25,1200,50,1,1,233.66,234.41,1,600,1,2,233.58,234.43,505,105,2,2,233.53,234.5,10,63,1,4,233.5,234.75,100,1,1,1,233.45,234.79,15,2000,1,1,AAPL,1809,4.273046475995915,-0.0551579859334855
2024-10-21T12:10:12.928233491Z,2024-10-21T12:10:12.928066550Z,10,2,38,A,A,3,234.16,28,130,166941,12232538,233.95,234.0,10,154,1,7,233.9,234.1,11,400,2,1,233.87,234.13,400,400,1,1,233.8,234.16,29,28,1,1,233.7,234.17,1200,1,1,1,233.66,234.25,1,50,1,1,233.58,234.41,505,600,2,2,233.53,234.43,10,105,1,2,233.5,234.5,100,63,1,4,233.45,234.75,15,1,1,1,AAPL,1808,4.383869321082185,-0.056588526173269024
2024-10-21T12:10:13.161907732Z,2024-10-21T12:10:13.161741583Z,10,2,38,C,B,2,233.87,400,130,166149,12232708,233.95,234.0,10,154,1,7,233.9,234.1,11,400,2,1,233.8,234.13,29,400,1,1,233.7,234.16,1200,28,1,1,233.66,234.17,1,1,1,1,233.58,234.25,505,50,2,1,233.53,234.41,10,600,1,2,233.5,234.43,100,105,1,2,233.45,234.5,15,63,1,4,233.4,234.75,110,1,2,1,AAPL,1713,4.422146739130435,-0.0570826245403558
2024-10-21T12:10:13.161920820Z,2024-10-21T12:10:13.161754596Z,10,2,38,A,B,2,233.84,200,130,166224,12232709,233.95,234.0,10,154,1,7,233.9,234.1,11,400,2,1,233.84,234.13,200,400,1,1,233.8,234.16,29,28,1,1,233.7,234.17,1200,1,1,1,233.66,234.25,1,50,1,1,233.58,234.41,505,600,2,2,233.53,234.43,10,105,1,2,233.5,234.5,100,63,1,4,233.45,234.75,15,1,1,1,AAPL,1728,4.575774035850081,-0.05906569968804342
2024-10-21T12:10:17.086600126Z,2024-10-21T12:10:17.086432603Z,10,2,38,T,N,0,233.99,2,130,167523,12235454,233.95,234.0,10,154,1,7,233.9,234.1,11,400,2,1,233.84,234.13,200,400,1,1,233.8,234.16,29,28,1,1,233.7,234.17,1200,1,1,1,233.66,234.25,1,50,1,1,233.58,234.41,505,600,2,2,233.53,234.43,10,105,1,2,233.5,234.5,100,63,1,4,233.45,234.75,15,1,1,1,AAPL,3641,12.831718061674009,-0.16563632722560245
2024-10-21T12:10:20.742434348Z,2024-10-21T12:10:20.742267983Z,10,2,38,A,B,0,233.96,20,130,166365,12237424,233.96,234.0,20,154,1,7,233.95,234.1,10,400,1,1,233.9,234.13,11,400,2,1,233.84,234.16,200,28,1,1,233.8,234.17,29,1,1,1,233.7,234.25,1200,50,1,1,233.66,234.41,1,600,1,2,233.58,234.43,505,105,2,2,233.53,234.5,10,63,1,4,233.5,234.75,100,1,1,1,AAPL,3742,15.130037824442416,-0.19530384660728325
2024-10-21T12:10:22.089103804Z,2024-10-21T12:10:22.088936277Z,10,2,38,T,N,0,233.99,5,130,167527,12238033,233.96,234.0,20,154,1,7,233.95,234.1,10,400,1,1,233.9,234.13,11,400,2,1,233.84,234.16,200,28,1,1,233.8,234.17,29,1,1,1,233.7,234.25,1200,50,1,1,233.66,234.41,1,600,1,2,233.58,234.43,505,105,2,2,233.53,234.5,10,63,1,4,233.5,234.75,100,1,1,1,AAPL,-100,-0.3803658757471472,0.004909896426799149
2024-10-21T12:10:23.455861213Z,2024-10-21T12:10:23.455694731Z,10,2,38,A,B,3,233.84,200,130,166482,12239081,233.96,234.0,20,154,1,7,233.95,234.1,10,400,1,1,233.9,234.13,11,400,2,1,233.84,234.16,400,28,2,1,233.8,234.17,29,1,1,1,233.7,234.25,1200,50,1,1,233.66,234.41,1,600,1,2,233.58,234.43,505,105,2,2,233.53,234.5,10,63,1,4,233.5,234.75,100,1,1,1,AAPL,-2089,-5.8068102849200836,0.07495634831338706
2024-10-21T12:10:23.510715158Z,2024-10-21T12:10:23.510549173Z,10,2,38,C,B,3,233.84,200,130,165985,12239119,233.96,234.0,20,154,1,7,233.95,234.1,10,400,1,1,233.9,234.13,11,400,2,1,233.84,234.16,200,28,1,1,233.8,234.17,29,1,1,1,233.7,234.25,1200,50,1,1,233.66,234.41,1,600,1,2,233.58,234.43,505,105,2,2,233.53,234.5,10,63,1,4,233.5,234.75,100,1,1,1,AAPL,-91,-0.29867223631209905,0.0038553662127875175
2024-10-21T12:10:23.510728355Z,2024-10-21T12:10:23.510561501Z,10,2,38,A,B,3,233.87,400,130,166854,12239120,233.96,234.0,20,154,1,7,233.95,234.1,10,400,1,1,233.9,234.13,11,400,2,1,233.87,234.16,400,28,1,1,233.8,234.17,29,1,1,1,233.7,234.25,1200,50,1,1,233.66,234.41,1,600,1,2,233.58,234.43,505,105,2,2,233.53,234.5,10,63,1,4,233.5,234.75,100,1,1,1,AAPL,-91,-0.32098765432098764,0.004143421472553267
2024-10-21T12:10:24.014692972Z,2024-10-21T12:10:24.014526498Z,10,2,38,A,B,3,233.88,400,130,166474,12239510,233.96,234.0,20,154,1,7,233.95,234.1,10,400,1,1,233.9,234.13,11,400,2,1,233.88,234.16,400,28,1,1,233.8,234.17,29,1,1,1,233.7,234.25,1200,50,1,1,233.66,234.41,1,600,1,2,233.58,234.43,505,105,2,2,233.53,234.5,10,63,1,4,233.5,234.75,100,1,1,1,AAPL,-91,-0.4466257668711656,0.0057652023924851595
2024-10-21T12:10:29.983091413Z,2024-10-21T12:10:29.982925320Z,10,2,38,C,B,1,233.95,10,130,166093,12243847,233.96,234.0,20,154,1,7,233.9,234.1,11,400,2,1,233.88,234.13,400,400,1,1,233.8,234.16,29,28,1,1,233.7,234.17,1200,1,1,1,233.66,234.25,1,50,1,1,233.58,234.41,505,600,2,2,233.53,234.43,10,105,1,2,233.5,234.5,100,63,1,4,233.45,234.75,15,1,1,1,AAPL,-106,-0.5617611088463107,0.007251409857998849
2024-10-21T12:10:32.696700045Z,2024-10-21T12:10:32.696534026Z,10,2,38,C,B,3,233.8,29,130,166019,12245508,233.96,234.0,20,154,1,7,233.9,234.1,11,400,2,1,233.88,234.13,400,400,1,1,233.7,234.16,1200,28,1,1,233.66,234.17,1,1,1,1,233.58,234.25,505,50,2,1,233.53,234.41,10,600,1,2,233.5,234.43,100,105,1,2,233.45,234.5,15,63,1,4,233.4,234.75,110,1,2,1,AAPL,-216,-1.205501295594977,0.015561034470079999
2024-10-21T12:10:32.696757970Z,2024-10-21T12:10:32.696591804Z,10,2,38,A,B,3,233.81,28,130,166166,12245509,233.96,234.0,20,154,1,7,233.9,234.1,11,400,2,1,233.88,234.13,400,400,1,1,233.81,234.16,28,28,1,1,233.7,234.17,1200,1,1,1,233.66,234.25,1,50,1,1,233.58,234.41,505,600,2,2,233.53,234.43,10,105,1,2,233.5,234.5,100,63,1,4,233.45,234.75,15,1,1,1,AAPL,-201,-1.198092588913173,0.015465400279991996
2024-10-21T12:10:36.255935226Z,2024-10-21T12:10:36.255768918Z,10,2,38,C,B,2,233.88,200,130,166308,12247980,233.96,234.0,20,154,1,7,233.9,234.1,11,400,2,1,233.88,234.13,200,400,1,1,233.81,234.16,28,28,1,1,233.7,234.17,1200,1,1,1,233.66,234.25,1,50,1,1,233.58,234.41,505,600,2,2,233.53,234.43,10,105,1,2,233.5,234.5,100,63,1,4,233.45,234.75,15,1,1,1,AAPL,-10,-0.28169014084507044,0.0036361553551117515
2024-10-21T12:10:36.668045674Z,2024-10-21T12:10:36.667879809Z,10,2,38,C,A,1,234.1,400,130,165865,12248362,233.96,234.0,20,154,1,7,233.9,234.13,11,400,2,1,233.88,234.16,200,28,1,1,233.81,234.17,28,1,1,1,233.7,234.25,1200,50,1,1,233.66,234.41,1,600,1,2,233.58,234.43,505,105,2,2,233.53,234.5,10,63,1,4,233.5,234.75,100,1,1,1,233.45,234.79,15,2000,1,1,AAPL,1990,17.081545064377682,-0.22049458803593966
2024-10-21T12:10:36.668056804Z,2024-10-21T12:10:36.667890580Z,10,2,38,A,A,1,234.12,400,130,166224,12248363,233.96,234.0,20,154,1,7,233.9,234.12,11,400,2,1,233.88,234.13,200,400,1,1,233.81,234.16,28,28,1,1,233.7,234.17,1200,1,1,1,233.66,234.25,1,50,1,1,233.58,234.41,505,600,2,2,233.53,234.43,10,105,1,2,233.5,234.5,100,63,1,4,233.45,234.75,15,1,1,1,AAPL,1989,18.390469416785205,-0.23739064367766158
2024-10-21T12:10:36.719005890Z,2024-10-21T12:10:36.718839166Z,10,2,38,A,B,2,233.89,200,130,166724,12248396,233.96,234.0,20,154,1,7,233.9,234.12,11,400,2,1,233.89,234.13,200,400,1,1,233.81,234.16,28,28,1,1,233.7,234.17,1200,1,1,1,233.66,234.25,1,50,1,1,233.58,234.41,505,600,2,2,233.53,234.43,10,105,1,2,233.5,234.5,100,63,1,4,233.45,234.75,15,1,1,1,AAPL,1989,19.693069306930692,-0.2542050609373893
2024-10-21T12:10:36.744053051Z,2024-10-21T12:10:36.743886554Z,10,2,38,C,A,3,234.16,28,130,166497,12248576,233.96,234.0,20,154,1,7,233.9,234.12,11,400,2,1,233.89,234.13,200,400,1,1,233.81,234.17,28,1,1,1,233.7,234.25,1200,50,1,1,233.66,234.41,1,600,1,2,233.58,234.43,505,105,2,2,233.53,234.5,10,63,1,4,233.5,234.75,100,1,1,1,233.45,234.79,15,2000,1,1,AAPL,3989,24.709890563700185,-0.31896395318585435
2024-10-21T12:10:36.744163347Z,2024-10-21T12:10:36.743997154Z,10,2,38,A,A,4,234.18,29,130,166193,12248578,233.96,234.0,20,154,1,7,233.9,234.12,11,400,2,1,233.89,234.13,200,400,1,1,233.81,234.17,28,1,1,1,233.7,234.18,1200,29,1,1,233.66,234.25,1,50,1,1,233.58,234.41,505,600,2,2,233.53,234.43,10,105,1,2,233.5,234.5,100,63,1,4,233.45,234.75,15,1,1,1,AAPL,3988,26.263840296357277,-0.33902288256486757
2024-10-21T12:10:42.064904504Z,2024-10-21T12:10:42.064737913Z,10,2,38,C,B,2,233.89,200,130,166591,12252326,233.96,234.0,20,154,1,7,233.9,234.12,11,400,2,1,233.81,234.13,28,400,1,1,233.7,234.17,1200,1,1,1,233.66,234.18,1,29,1,1,233.58,234.25,505,50,2,1,233.53,234.41,10,600,1,2,233.5,234.43,100,105,1,2,233.45,234.5,15,63,1,4,233.4,234.75,110,1,2,1,AAPL,3778,23.354626004533277,-0.30146972186620624
2024-10-21T12:10:42.064917654Z,2024-10-21T12:10:42.064751203Z,10,2,38,A,B,2,233.86,200,130,166451,12252327,233.96,234.0,20,154,1,7,233.9,234.12,11,400,2,1,233.86,234.13,200,400,1,1,233.81,234.17,28,1,1,1,233.7,234.18,1200,29,1,1,233.66,234.25,1,50,1,1,233.58,234.41,505,600,2,2,233.53,234.43,10,105,1,2,233.5,234.5,100,63,1,4,233.45,234.75,15,1,1,1,AAPL,3793,24.92832203737934,-0.32178354342909343
2024-10-21T12:10:43.289815837Z,2024-10-21T12:10:43.289649676Z,10,2,38,A,A,1,234.11,400,130,166161,12253919,233.96,234.0,20,154,1,7,233.9,234.11,11,400,2,1,233.86,234.13,200,400,1,1,233.81,234.17,28,1,1,1,233.7,234.18,1200,29,1,1,233.66,234.25,1,50,1,1,233.58,234.41,505,600,2,2,233.53,234.43,10,105,1,2,233.5,234.5,100,63,1,4,233.45,234.75,15,1,1,1,AAPL,3793,25.37123745819398,-0.32750085137045487
2024-10-21T12:10:43.377959609Z,2024-10-21T12:10:43.377793688Z,10,2,38,C,A,4,234.18,29,130,165921,12254130,233.96,234.0,20,154,1,7,233.9,234.11,11,400,2,1,233.86,234.13,200,400,1,1,233.81,234.17,28,1,1,1,233.7,234.25,1200,50,1,1,233.66,234.41,1,600,1,2,233.58,234.43,505,105,2,2,233.53,234.5,10,63,1,4,233.5,234.75,100,1,1,1,233.45,234.79,15,2000,1,1,AAPL,5793,28.96926018532137,-0.373945393475511
2024-10-21T12:10:43.378040281Z,2024-10-21T12:10:43.377874040Z,10,2,38,A,A,3,234.17,28,130,166241,12254131,233.96,234.0,20,154,1,7,233.9,234.11,11,400,2,1,233.86,234.13,200,400,1,1,233.81,234.17,28,29,1,2,233.7,234.25,1200,50,1,1,233.66,234.41,1,600,1,2,233.58,234.43,505,105,2,2,233.53,234.5,10,63,1,4,233.5,234.75,100,1,1,1,233.45,234.79,15,2000,1,1,AAPL,5793,23.66099387338325,-0.3054244260088894
2024-10-21T12:10:45.117465225Z,2024-10-21T12:10:45.117298924Z,10,2,38,A,B,2,233.88,200,130,166301,12255855,233.96,234.0,20,154,1,7,233.9,234.11,11,400,2,1,233.88,234.13,200,400,1,1,233.81,234.17,28,29,1,2,233.7,234.25,1200,50,1,1,233.66,234.41,1,600,1,2,233.58,234.43,505,105,2,2,233.53,234.5,10,63,1,4,233.5,234.75,100,1,1,1,233.45,234.79,15,2000,1,1,AAPL,5793,16.670503597122302,-0.2151887202911552
2024-10-21T12:10:50.850117869Z,2024-10-21T12:10:50.849951366Z,10,2,38,A,B,2,233.89,200,130,166503,12260865,233.96,234.0,20,154,1,7,233.9,234.11,11,400,2,1,233.89,234.13,200,400,1,1,233.81,234.17,28,29,1,2,233.7,234.25,1200,50,1,1,233.66,234.41,1,600,1,2,233.58,234.43,505,105,2,2,233.53,234.5,10,63,1,4,233.5,234.75,100,1,1,1,233.45,234.79,15,2000,1,1,AAPL,5808,14.024468770122343,-0.18103277263482645
2024-10-21T12:10:52.970762824Z,2024-10-21T12:10:52.970596564Z,10,2,38,C,A,4,234.25,50,130,166260,12262701,233.96,234.0,20,154,1,7,233.9,234.11,11,400,2,1,233.89,234.13,200,400,1,1,233.81,234.17,28,29,1,2,233.7,234.41,1200,600,1,2,233.66,234.43,1,105,1,2,233.58,234.5,505,63,2,4,233.53,234.75,10,1,1,1,233.5,234.79,100,2000,1,1,233.45,234.89,15,2,1,2,AAPL,5905,13.426993665746306,-0.17332035396868023
2024-10-21T12:10:53.810450187Z,2024-10-21T12:10:53.810283344Z,10,2,38,C,B,0,233.96,20,130,166843,12263307,233.9,234.0,11,154,2,7,233.89,234.11,200,400,1,1,233.81,234.13,28,400,1,1,233.7,234.17,1200,29,1,2,233.66,234.41,1,600,1,2,233.58,234.43,505,105,2,2,233.53,234.5,10,63,1,4,233.5,234.75,100,1,1,1,233.45,234.79,15,2000,1,1,233.4,234.89,110,2,2,2,AAPL,5795,13.990825688073395,-0.1805984959058371
2024-10-21T12:10:53.881603970Z,2024-10-21T12:10:53.881437911Z,10,2,38,C,B,1,233.89,200,130,166059,12263356,233.9,234.0,11,154,2,7,233.81,234.11,28,400,1,1,233.7,234.13,1200,400,1,1,233.66,234.17,1,29,1,2,233.58,234.41,505,600,2,2,233.53,234.43,10,105,1,2,233.5,234.5,100,63,1,4,233.45,234.75,15,1,1,1,233.4,234.79,110,2000,2,1,233.39,234.89,10,2,1,2,AAPL,5785,14.883421771989065,-0.19212043991404731
2024-10-21T12:10:53.881616413Z,2024-10-21T12:10:53.881449961Z,10,2,38,A,B,1,233.86,200,130,166452,12263357,233.9,234.0,11,154,2,7,233.86,234.11,200,400,1,1,233.81,234.13,28,400,1,1,233.7,234.17,1200,29,1,2,233.66,234.41,1,600,1,2,233.58,234.43,505,105,2,2,233.53,234.5,10,63,1,4,233.5,234.75,100,1,1,1,233.45,234.79,15,2000,1,1,233.4,234.89,110,2,2,2,AAPL,5895,15.970517928286853,-0.2061530592254121
2024-10-21T12:10:54.127813980Z,2024-10-21T12:10:54.127647992Z,10,2,38,C,B,1,233.86,200,130,165988,12263603,233.9,234.0,11,154,2,7,233.81,234.11,28,400,1,1,233.7,234.13,1200,400,1,1,233.66,234.17,1,29,1,2,233.58,234.41,505,600,2,2,233.53,234.43,10,105,1,2,233.5,234.5,100,63,1,4,233.45,234.75,15,1,1,1,233.4,234.79,110,2000,2,1,233.39,234.89,10,2,1,2,AAPL,5885,16.865148861646233,-0.21770126978551294
2024-10-21T12:10:54.127826075Z,2024-10-21T12:10:54.127659727Z,10,2,38,A,B,2,233.78,400,130,166348,12263604,233.9,234.0,11,154,2,7,233.81,234.11,28,400,1,1,233.78,234.13,400,400,1,1,233.7,234.17,1200,29,1,2,233.66,234.41,1,600,1,2,233.58,234.43,505,105,2,2,233.53,234.5,10,63,1,4,233.5,234.75,100,1,1,1,233.45,234.79,15,2000,1,1,233.4,234.89,110,2,2,2,AAPL,5995,17.974593656304243,-0.23202237317661578
2024-10-21T12:10:54.147013785Z,2024-10-21T12:10:54.146847471Z,10,2,38,C,B,1,233.81,28,130,166314,12263624,233.9,234.0,11,154,2,7,233.78,234.11,400,400,1,1,233.7,234.13,1200,400,1,1,233.66,234.17,1,29,1,2,233.58,234.41,505,600,2,2,233.53,234.43,10,105,1,2,233.5,234.5,100,63,1,4,233.45,234.75,15,1,1,1,233.4,234.79,110,2000,2,1,233.39,234.89,10,2,1,2,AAPL,5985,18.871196594671293,-0.2435960390705364
2024-10-21T12:10:54.147055569Z,2024-10-21T12:10:54.146889193Z,10,2,38,A,B,2,233.76,27,130,166376,12263625,233.9,234.0,11,154,2,7,233.78,234.11,400,400,1,1,233.76,234.13,27,400,1,1,233.7,234.17,1200,29,1,2,233.66,234.41,1,600,1,2,233.58,234.43,505,105,2,2,233.53,234.5,10,63,1,4,233.5,234.75,100,1,1,1,233.45,234.79,15,2000,1,1,233.4,234.89,110,2,2,2,AAPL,6095,20.002344116268166,-0.25819728888970567
2024-10-21T12:10:54.147097290Z,2024-10-21T12:10:54.146930519Z,10,2,38,A,A,2,234.13,27,130,166771,12263626,233.9,234.0,11,154,2,7,233.78,234.11,400,400,1,1,233.76,234.13,27,427,1,2,233.7,234.17,1200,29,1,2,233.66,234.41,1,600,1,2,233.58,234.43,505,105,2,2,233.53,234.5,10,63,1,4,233.5,234.75,100,1,1,1,233.45,234.79,15,2000,1,1,233.4,234.89,110,2,2,2,AAPL,6095,20.773044151820294,-0.2681457558578805
2024-10-21T12:10:54.147208464Z,2024-10-21T12:10:54.147042446Z,10,2,38,C,A,3,234.17,28,130,166018,12263627,233.9,234.0,11,154,2,7,233.78,234.11,400,400,1,1,233.76,234.13,27,427,1,2,233.7,234.17,1200,1,1,1,233.66,234.41,1,600,1,2,233.58,234.43,505,105,2,2,233.53,234.5,10,63,1,4,233.5,234.75,100,1,1,1,233.45,234.79,15,2000,1,1,233.4,234.89,110,2,2,2,AAPL,6095,21.530486868376595,-0.27792309269236837
2024-10-21T12:10:54.198522999Z,2024-10-21T12:10:54.198356340Z,10,2,38,A,A,1,234.06,200,130,166659,12263665,233.9,234.0,11,154,2,7,233.78,234.06,400,200,1,1,233.76,234.13,27,427,1,2,233.7,234.17,1200,1,1,1,233.66,234.41,1,600,1,2,233.58,234.43,505,105,2,2,233.53,234.5,10,63,1,4,233.5,234.75,100,1,1,1,233.45,234.79,15,2000,1,1,233.4,234.89,110,2,2,2,AAPL,6095,22.275011420740064,-0.2875336773225829
2024-10-21T12:10:57.184898920Z,2024-10-21T12:10:57.184732013Z,10,2,38,A,B,1,233.82,200,130,166907,12265734,233.9,234.0,11,154,2,7,233.82,234.06,200,200,1,1,233.76,234.13,27,427,1,2,233.7,234.17,1200,1,1,1,233.66,234.41,1,600,1,2,233.58,234.43,505,105,2,2,233.53,234.5,10,63,1,4,233.5,234.75,100,1,1,1,233.45,234.79,15,2000,1,1,233.4,234.89,110,2,2,2,AAPL,2097,8.706949300699302,-0.11239236215880621
2024-10-21T12:10:57.590098060Z,2024-10-21T12:10:57.589931819Z,10,2,38,A,B,1,233.83,200,130,166241,12266072,233.9,234.0,11,154,2,7,233.83,234.06,200,200,1,1,233.76,234.13,27,427,1,2,233.7,234.17,1200,1,1,1,233.66,234.41,1,600,1,2,233.58,234.43,505,105,2,2,233.53,234.5,10,63,1,4,233.5,234.75,100,1,1,1,233.45,234.79,15,2000,1,1,233.4,234.89,110,2,2,2,AAPL,2097,9.05440414507772,-0.1168774314241199
2024-10-21T12:10:57.806772384Z,2024-10-21T12:10:57.806606311Z,10,2,38,C,B,1,233.83,200,130,166073,12266374,233.9,234.0,11,154,2,7,233.76,234.06,27,200,1,1,233.7,234.13,1200,427,1,2,233.66,234.17,1,1,1,1,233.58,234.41,505,600,2,2,233.53,234.43,10,105,1,2,233.5,234.5,100,63,1,4,233.45,234.75,15,1,1,1,233.4,234.79,110,2000,2,1,233.39,234.89,10,2,1,2,AAPL,2087,9.44954721862872,-0.12197807711451351
2024-10-21T12:10:57.806785593Z,2024-10-21T12:10:57.806619389Z,10,2,38,A,B,1,233.78,400,130,166204,12266375,233.9,234.0,11,154,2,7,233.78,234.06,400,200,1,1,233.76,234.13,27,427,1,2,233.7,234.17,1200,1,1,1,233.66,234.41,1,600,1,2,233.58,234.43,505,105,2,2,233.53,234.5,10,63,1,4,233.5,234.75,100,1,1,1,233.45,234.79,15,2000,1,1,233.4,234.89,110,2,2,2,AAPL,2197,10.296974861525351,-0.13291697100886204
2024-10-21T12:10:59.771275683Z,2024-10-21T12:10:59.771109174Z,10,2,38,C,B,2,233.76,27,130,166509,12268147,233.9,234.0,11,154,2,7,233.78,234.06,400,200,1,1,233.7,234.13,1200,427,1,2,233.66,234.17,1,1,1,1,233.58,234.41,505,600,2,2,233.53,234.43,10,105,1,2,233.5,234.5,100,63,1,4,233.45,234.75,15,1,1,1,233.4,234.79,110,2000,2,1,233.39,234.89,10,2,1,2,AAPL,2187,10.702340425531915,-0.13814957219937035
2024-10-21T12:10:59.771327492Z,2024-10-21T12:10:59.771161194Z,10,2,38,A,B,2,233.77,30,130,166298,12268148,233.9,234.0,11,154,2,7,233.78,234.06,400,200,1,1,233.77,234.13,30,427,1,2,233.7,234.17,1200,1,1,1,233.66,234.41,1,600,1,2,233.58,234.43,505,105,2,2,233.53,234.5,10,63,1,4,233.5,234.75,100,1,1,1,233.45,234.79,15,2000,1,1,233.4,234.89,110,2,2,2,AAPL,2297,11.59125315391085,-0.14962397015957365
2024-10-21T12:11:00.807783551Z,2024-10-21T12:11:00.807617417Z,10,2,38,C,B,2,233.77,30,130,166134,12269676,233.9,234.0,11,154,2,7,233.78,234.06,400,200,1,1,233.7,234.13,1200,427,1,2,233.66,234.17,1,1,1,1,233.58,234.41,505,600,2,2,233.53,234.43,10,105,1,2,233.5,234.5,100,63,1,4,233.45,234.75,15,1,1,1,233.4,234.79,110,2000,2,1,233.39,234.89,10,2,1,2,AAPL,2287,12.006509869802604,-0.15498424981546116
2024-10-21T12:11:00.807824165Z,2024-10-21T12:11:00.807657573Z,10,2,38,A,B,1,233.82,26,130,166592,12269677,233.9,234.0,11,154,2,7,233.82,234.06,26,200,1,1,233.78,234.13,400,427,1,2,233.7,234.17,1200,1,1,1,233.66,234.41,1,600,1,2,233.58,234.43,505,105,2,2,233.53,234.5,10,63,1,4,233.5,234.75,100,1,1,1,233.45,234.79,15,2000,1,1,233.4,234.89,110,2,2,2,AAPL,2397,12.935242839352428,-0.16697266144593706
2024-10-21T12:11:00.863321742Z,2024-10-21T12:11:00.863155159Z,10,2,38,A,B,1,233.87,200,130,166583,12269733,233.9,234.0,11,154,2,7,233.87,234.06,200,200,1,1,233.82,234.13,26,427,1,2,233.7,234.17,1200,1,1,1,233.66,234.41,1,600,1,2,233.58,234.43,505,105,2,2,233.53,234.5,10,63,1,4,233.5,234.75,100,1,1,1,233.45,234.79,15,2000,1,1,233.4,234.89,110,2,2,2,AAPL,2397,13.278416085350843,-0.17140246233433423
2024-10-21T12:11:02.807267623Z,2024-10-21T12:11:02.807100841Z,10,2,38,A,B,1,233.88,200,130,166782,12271687,233.9,234.0,11,154,2,7,233.88,234.06,200,200,1,1,233.82,234.13,26,427,1,2,233.7,234.17,1200,1,1,1,233.66,234.41,1,600,1,2,233.58,234.43,505,105,2,2,233.53,234.5,10,63,1,4,233.5,234.75,100,1,1,1,233.45,234.79,15,2000,1,1,233.4,234.89,110,2,2,2,AAPL,2492,13.313880612349736,-0.17186025091499477
2024-10-21T12:11:08.220481984Z,2024-10-21T12:11:08.220315875Z,10,2,38,C,B,1,233.88,200,130,166109,12275485,233.9,234.0,11,154,2,7,233.82,234.06,26,200,1,1,233.7,234.13,1200,427,1,2,233.66,234.17,1,1,1,1,233.58,234.41,505,600,2,2,233.53,234.43,10,105,1,2,233.5,234.5,100,63,1,4,233.45,234.75,15,1,1,1,233.4,234.79,110,2000,2,1,233.39,234.89,10,2,1,2,AAPL,482,6.0184581976112925,-0.07768837396689986
2024-10-21T12:11:08.291615657Z,2024-10-21T12:11:08.291449117Z,10,2,38,A,B,2,233.78,400,130,166540,12275506,233.9,234.0,11,154,2,7,233.82,234.06,26,200,1,1,233.78,234.13,400,427,1,2,233.7,234.17,1200,1,1,1,233.66,234.41,1,600,1,2,233.58,234.43,505,105,2,2,233.53,234.5,10,63,1,4,233.5,234.75,100,1,1,1,233.45,234.79,15,2000,1,1,233.4,234.89,110,2,2,2,AAPL,592,7.48577449947313,-0.09662900856863466
2024-10-21T12:11:08.292173149Z,2024-10-21T12:11:08.292006615Z,10,2,38,A,B,3,233.76,27,130,166534,12275507,233.9,234.0,11,154,2,7,233.82,234.06,26,200,1,1,233.78,234.13,400,427,1,2,233.76,234.17,27,1,1,1,233.7,234.41,1200,600,1,2,233.66,234.43,1,105,1,2,233.58,234.5,505,63,2,4,233.53,234.75,10,1,1,1,233.5,234.79,100,2000,1,1,233.45,234.89,15,2,1,2,AAPL,607,7.959611854183057,-0.1027454677021054
2024-10-21T12:11:08.292210524Z,2024-10-21T12:11:08.292044305Z,10,2,38,C,B,1,233.82,26,130,166219,12275508,233.9,234.0,11,154,2,7,233.78,234.06,400,200,1,1,233.76,234.13,27,427,1,2,233.7,234.17,1200,1,1,1,233.66,234.41,1,600,1,2,233.58,234.43,505,105,2,2,233.53,234.5,10,63,1,4,233.5,234.75,100,1,1,1,233.45,234.79,15,2000,1,1,233.4,234.89,110,2,2,2,AAPL,497,6.584458598726115,-0.084994506099657
2024-10-21T12:11:10.442776750Z,2024-10-21T12:11:10.442610415Z,10,2,38,A,B,1,233.79,400,130,166335,12277136,233.9,234.0,11,154,2,7,233.79,234.06,400,200,1,1,233.76,234.13,27,427,1,2,233.7,234.17,1200,1,1,1,233.66,234.41,1,600,1,2,233.58,234.43,505,105,2,2,233.53,234.5,10,63,1,4,233.5,234.75,100,1,1,1,233.45,234.79,15,2000,1,1,233.4,234.89,110,2,2,2,AAPL,497,6.648005945008671,-0.08581479758304104
2024-10-21T12:11:10.454952399Z,2024-10-21T12:11:10.454786222Z,10,2,38,C,B,2,233.76,27,130,166177,12277212,233.9,234.0,11,154,2,7,233.79,234.06,400,200,1,1,233.7,234.13,1200,427,1,2,233.66,234.17,1,1,1,1,233.58,234.41,505,600,2,2,233.53,234.43,10,105,1,2,233.5,234.5,100,63,1,4,233.45,234.75,15,1,1,1,233.4,234.79,110,2000,2,1,233.39,234.89,10,2,1,2,AAPL,487,6.735490244504816,-0.08694407567259997
2024-10-21T12:11:10.455002886Z,2024-10-21T12:11:10.454836386Z,10,2,38,A,B,2,233.77,27,130,166500,12277213,233.9,234.0,11,154,2,7,233.79,234.06,400,200,1,1,233.77,234.13,27,427,1,2,233.7,234.17,1200,1,1,1,233.66,234.41,1,600,1,2,233.58,234.43,505,105,2,2,233.53,234.5,10,63,1,4,233.5,234.75,100,1,1,1,233.45,234.79,15,2000,1,1,233.4,234.89,110,2,2,2,AAPL,597,8.321557317952415,-0.10741758697612432
2024-10-21T12:11:11.346401450Z,2024-10-21T12:11:11.346234393Z,10,2,38,A,B,1,233.83,200,130,167057,12278338,233.9,234.0,11,154,2,7,233.83,234.06,200,200,1,1,233.77,234.13,27,427,1,2,233.7,234.17,1200,1,1,1,233.66,234.41,1,600,1,2,233.58,234.43,505,105,2,2,233.53,234.5,10,63,1,4,233.5,234.75,100,1,1,1,233.45,234.79,15,2000,1,1,233.4,234.89,110,2,2,2,AAPL,597,15.3348095659876,-0.19794711222659578
2024-10-21T12:11:18.869806122Z,2024-10-21T12:11:18.869640062Z,10,2,38,C,B,1,233.83,200,130,166060,12284656,233.9,234.0,11,154,2,7,233.77,234.06,27,200,1,1,233.7,234.13,1200,427,1,2,233.66,234.17,1,1,1,1,233.58,234.41,505,600,2,2,233.53,234.43,10,105,1,2,233.5,234.5,100,63,1,4,233.45,234.75,15,1,1,1,233.4,234.79,110,2000,2,1,233.39,234.89,10,2,1,2,AAPL,295,8.15668202764977,-0.10528931877347786
2024-10-21T12:11:18.869819499Z,2024-10-21T12:11:18.869653217Z,10,2,38,A,B,1,233.78,400,130,166282,12284657,233.9,234.0,11,154,2,7,233.78,234.06,400,200,1,1,233.77,234.13,27,427,1,2,233.7,234.17,1200,1,1,1,233.66,234.41,1,600,1,2,233.58,234.43,505,105,2,2,233.53,234.5,10,63,1,4,233.5,234.75,100,1,1,1,233.45,234.79,15,2000,1,1,233.4,234.89,110,2,2,2,AAPL,405,10.827067669172932,-0.13975959530324264
2024-10-21T12:11:21.873509615Z,2024-10-21T12:11:21.873343400Z,10,2,38,C,B,2,233.77,27,130,166215,12287082,233.9,234.0,11,154,2,7,233.78,234.06,400,200,1,1,233.7,234.13,1200,427,1,2,233.66,234.17,1,1,1,1,233.58,234.41,505,600,2,2,233.53,234.43,10,105,1,2,233.5,234.5,100,63,1,4,233.45,234.75,15,1,1,1,233.4,234.79,110,2000,2,1,233.39,234.89,10,2,1,2,AAPL,195,5.512367491166078,-0.0711555772318335
2024-10-21T12:11:21.873599230Z,2024-10-21T12:11:21.873432987Z,10,2,38,A,B,1,233.81,26,130,166243,12287083,233.9,234.0,11,154,2,7,233.81,234.06,26,200,1,1,233.78,234.13,400,427,1,2,233.7,234.17,1200,1,1,1,233.66,234.41,1,600,1,2,233.58,234.43,505,105,2,2,233.53,234.5,10,63,1,4,233.5,234.75,100,1,1,1,233.45,234.79,15,2000,1,1,233.4,234.89,110,2,2,2,AAPL,305,8.251821019771072,-0.10651740632614826
2024-10-21T12:11:21.928420269Z,2024-10-21T12:11:21.928253749Z,10,2,38,A,B,1,233.86,200,130,166520,12287102,233.9,234.0,11,154,2,7,233.86,234.06,200,200,1,1,233.81,234.13,26,427,1,2,233.7,234.17,1200,1,1,1,233.66,234.41,1,600,1,2,233.58,234.43,505,105,2,2,233.53,234.5,10,63,1,4,233.5,234.75,100,1,1,1,233.45,234.79,15,2000,1,1,233.4,234.89,110,2,2,2,AAPL,305,7.9589934762348555,-0.10273748546218357
2024-10-21T12:11:22.072521728Z,2024-10-21T12:11:22.072355634Z,10,2,38,C,B,1,233.86,200,130,166094,12287179,233.9,234.0,11,154,2,7,233.81,234.06,26,200,1,1,233.7,234.13,1200,427,1,2,233.66,234.17,1,1,1,1,233.58,234.41,505,600,2,2,233.53,234.43,10,105,1,2,233.5,234.5,100,63,1,4,233.45,234.75,15,1,1,1,233.4,234.79,110,2000,2,1,233.39,234.89,10,2,1,2,AAPL,295,8.15668202764977,-0.10528931877347786
2024-10-21T12:11:22.072534773Z,2024-10-21T12:11:22.072368471Z,10,2,38,A,B,2,233.78,400,130,166302,12287180,233.9,234.0,11,154,2,7,233.81,234.06,26,200,1,1,233.78,234.13,400,427,1,2,233.7,234.17,1200,1,1,1,233.66,234.41,1,600,1,2,233.58,234.43,505,105,2,2,233.53,234.5,10,63,1,4,233.5,234.75,100,1,1,1,233.45,234.79,15,2000,1,1,233.4,234.89,110,2,2,2,AAPL,405,10.827067669172932,-0.13975959530324264
2024-10-21T12:11:22.073030139Z,2024-10-21T12:11:22.072864187Z,10,2,38,C,B,1,233.81,26,130,165952,12287181,233.9,234.0,11,154,2,7,233.78,234.06,400,200,1,1,233.7,234.13,1200,427,1,2,233.66,234.17,1,1,1,1,233.58,234.41,505,600,2,2,233.53,234.43,10,105,1,2,233.5,234.5,100,63,1,4,233.45,234.75,15,1,1,1,233.4,234.79,110,2000,2,1,233.39,234.89,10,2,1,2,AAPL,395,11.108354011579817,-0.14339053828617485
2024-10-21T12:11:22.938136138Z,2024-10-21T12:11:22.937969054Z,10,2,38,T,N,0,233.98,4,130,167084,12287694,233.9,234.0,11,154,2,7,233.78,234.06,400,200,1,1,233.7,234.13,1200,427,1,2,233.66,234.17,1,1,1,1,233.58,234.41,505,600,2,2,233.53,234.43,10,105,1,2,233.5,234.5,100,63,1,4,233.45,234.75,15,1,1,1,233.4,234.79,110,2000,2,1,233.39,234.89,10,2,1,2,AAPL,395,12.110009017132551,-0.15632025319024834
2024-10-21T12:11:23.001029527Z,2024-10-21T12:11:23.000862969Z,10,2,38,A,B,2,233.76,30,130,166558,12287720,233.9,234.0,11,154,2,7,233.78,234.06,400,200,1,1,233.76,234.13,30,427,1,2,233.7,234.17,1200,1,1,1,233.66,234.41,1,600,1,2,233.58,234.43,505,105,2,2,233.53,234.5,10,63,1,4,233.5,234.75,100,1,1,1,233.45,234.79,15,2000,1,1,233.4,234.89,110,2,2,2,AAPL,505,14.88943488943489,-0.1921980593477128
2024-10-21T12:11:25.073082417Z,2024-10-21T12:11:25.072916074Z,10,2,38,C,A,1,234.06,200,130,166343,12288985,233.9,234.0,11,154,2,7,233.78,234.13,400,427,1,2,233.76,234.17,30,1,1,1,233.7,234.41,1200,600,1,2,233.66,234.43,1,105,1,2,233.58,234.5,505,63,2,4,233.53,234.75,10,1,1,1,233.5,234.79,100,2000,1,1,233.45,234.89,15,2,1,2,233.4,235.0,110,213,2,6,AAPL,718,17.67098445595855,-0.2281032788966872
2024-10-21T12:11:25.073096247Z,2024-10-21T12:11:25.072929618Z,10,2,38,A,A,1,234.12,400,130,166629,12288986,233.9,234.0,11,154,2,7,233.78,234.12,400,400,1,1,233.76,234.13,30,427,1,2,233.7,234.17,1200,1,1,1,233.66,234.41,1,600,1,2,233.58,234.43,505,105,2,2,233.53,234.5,10,63,1,4,233.5,234.75,100,1,1,1,233.45,234.79,15,2000,1,1,233.4,234.89,110,2,2,2,AAPL,716,17.294685990338166,-0.22324588602954232
2024-10-21T12:11:25.073458008Z,2024-10-21T12:11:25.073291984Z,10,2,38,C,B,2,233.76,30,130,166024,12288987,233.9,234.0,11,154,2,7,233.78,234.12,400,400,1,1,233.7,234.13,1200,427,1,2,233.66,234.17,1,1,1,1,233.58,234.41,505,600,2,2,233.53,234.43,10,105,1,2,233.5,234.5,100,63,1,4,233.45,234.75,15,1,1,1,233.4,234.79,110,2000,2,1,233.39,234.89,10,2,1,2,AAPL,706,17.776978417266186,-0.22947148620725205
2024-10-21T12:11:25.073555014Z,2024-10-21T12:11:25.073388717Z,10,2,38,A,B,1,233.81,26,130,166297,12288988,233.9,234.0,11,154,2,7,233.81,234.12,26,400,1,1,233.78,234.13,400,427,1,2,233.7,234.17,1200,1,1,1,233.66,234.41,1,600,1,2,233.58,234.43,505,105,2,2,233.53,234.5,10,63,1,4,233.5,234.75,100,1,1,1,233.45,234.79,15,2000,1,1,233.4,234.89,110,2,2,2,AAPL,816,20.170786516853934,-0.2603716026057639
2024-10-21T12:11:25.074138845Z,2024-10-21T12:11:25.073972612Z,10,2,38,C,A,2,234.13,27,130,166233,12288989,233.9,234.0,11,154,2,7,233.81,234.12,26,400,1,1,233.78,234.13,400,400,1,1,233.7,234.17,1200,1,1,1,233.66,234.41,1,600,1,2,233.58,234.43,505,105,2,2,233.53,234.5,10,63,1,4,233.5,234.75,100,1,1,1,233.45,234.79,15,2000,1,1,233.4,234.89,110,2,2,2,AAPL,816,19.839323467230443,-0.25609296104843293
2024-10-21T12:11:25.074266365Z,2024-10-21T12:11:25.074100004Z,10,2,38,A,A,4,234.18,30,130,166361,12288990,233.9,234.0,11,154,2,7,233.81,234.12,26,400,1,1,233.78,234.13,400,400,1,1,233.7,234.17,1200,1,1,1,233.66,234.18,1,30,1,1,233.58,234.41,505,600,2,2,233.53,234.43,10,105,1,2,233.5,234.5,100,63,1,4,233.45,234.75,15,1,1,1,233.4,234.79,110,2000,2,1,AAPL,-1184,-14.200899550224888,0.18331020316168772
2024-10-21T12:11:25.129461870Z,2024-10-21T12:11:25.129294511Z,10,2,38,A,B,1,233.86,200,130,167359,12289009,233.9,234.0,11,154,2,7,233.86,234.12,200,400,1,1,233.81,234.13,26,400,1,1,233.7,234.17,1200,1,1,1,233.66,234.18,1,30,1,1,233.58,234.41,505,600,2,2,233.53,234.43,10,105,1,2,233.5,234.5,100,63,1,4,233.45,234.75,15,1,1,1,233.4,234.79,110,2000,2,1,AAPL,-1184,-9.68586387434555,0.12502853557432686
2024-10-21T12:11:27.120171307Z,2024-10-21T12:11:27.120005157Z,10,2,38,C,B,1,233.86,200,130,166150,12290119,233.9,234.0,11,154,2,7,233.81,234.12,26,400,1,1,233.7,234.13,1200,400,1,1,233.66,234.17,1,1,1,1,233.58,234.18,505,30,2,1,233.53,234.41,10,600,1,2,233.5,234.43,100,105,1,2,233.45,234.5,15,63,1,4,233.4,234.75,110,1,2,1,233.39,234.79,10,2000,1,1,AAPL,-1194,-7.644422556020685,0.09867689344903147
2024-10-21T12:11:27.120184761Z,2024-10-21T12:11:27.120018111Z,10,2,38,A,B,2,233.78,400,130,166650,12290120,233.9,234.0,11,154,2,7,233.81,234.12,26,400,1,1,233.78,234.13,400,400,1,1,233.7,234.17,1200,1,1,1,233.66,234.18,1,30,1,1,233.58,234.41,505,600,2,2,233.53,234.43,10,105,1,2,233.5,234.5,100,63,1,4,233.45,234.75,15,1,1,1,233.4,234.79,110,2000,2,1,AAPL,-1084,-5.720875684128225,0.07384707427943864
2024-10-21T12:11:27.120673190Z,2024-10-21T12:11:27.120506757Z,10,2,38,C,B,1,233.81,26,130,166433,12290123,233.9,234.0,11,154,2,7,233.78,234.12,400,400,1,1,233.7,234.13,1200,400,1,1,233.66,234.17,1,1,1,1,233.58,234.18,505,30,2,1,233.53,234.41,10,600,1,2,233.5,234.43,100,105,1,2,233.45,234.5,15,63,1,4,233.4,234.75,110,1,2,1,233.39,234.79,10,2000,1,1,AAPL,-1094,-5.0044110439470675,0.06459869685903125
2024-10-21T12:11:27.120714598Z,2024-10-21T12:11:27.120548454Z,10,2,38,A,B,2,233.76,29,130,166144,12290124,233.9,234.0,11,154,2,7,233.78,234.12,400,400,1,1,233.76,234.13,29,400,1,1,233.7,234.17,1200,1,1,1,233.66,234.18,1,30,1,1,233.58,234.41,505,600,2,2,233.53,234.43,10,105,1,2,233.5,234.5,100,63,1,4,233.45,234.75,15,1,1,1,233.4,234.79,110,2000,2,1,AAPL,-984,-3.976588628762542,0.051331203833307526
2024-10-21T12:11:27.120816314Z,2024-10-21T12:11:27.120650159Z,10,2,38,A,A,2,234.13,27,130,166155,12290125,233.9,234.0,11,154,2,7,233.78,234.12,400,400,1,1,233.76,234.13,29,427,1,2,233.7,234.17,1200,1,1,1,233.66,234.18,1,30,1,1,233.58,234.41,505,600,2,2,233.53,234.43,10,105,1,2,233.5,234.5,100,63,1,4,233.45,234.75,15,1,1,1,233.4,234.79,110,2000,2,1,AAPL,-984,-3.5864415016401407,0.0462950475755426
2024-10-21T12:11:27.120886583Z,2024-10-21T12:11:27.120720548Z,10,2,38,C,A,4,234.18,30,130,166035,12290126,233.9,234.0,11,154,2,7,233.78,234.12,400,400,1,1,233.76,234.13,29,427,1,2,233.7,234.17,1200,1,1,1,233.66,234.41,1,600,1,2,233.58,234.43,505,105,2,2,233.53,234.5,10,63,1,4,233.5,234.75,100,1,1,1,233.45,234.79,15,2000,1,1,233.4,234.89,110,2,2,2,AAPL,-982,-3.673464462411005,0.04741837054267013
2024-10-21T12:11:27.177695699Z,2024-10-21T12:11:27.177529449Z,10,2,38,A,A,1,234.06,200,130,166250,12290153,233.9,234.0,11,154,2,7,233.78,234.06,400,200,1,1,233.76,234.13,29,427,1,2,233.7,234.17,1200,1,1,1,233.66,234.41,1,600,1,2,233.58,234.43,505,105,2,2,233.53,234.5,10,63,1,4,233.5,234.75,100,1,1,1,233.45,234.79,15,2000,1,1,233.4,234.89,110,2,2,2,AAPL,-982,-3.7665108474169964,0.04861944598712243
2024-10-21T12:11:30.179271563Z,2024-10-21T12:11:30.179103980Z,10,2,38,A,B,1,233.82,200,130,167583,12292157,233.9,234.0,11,154,2,7,233.82,234.06,200,200,1,1,233.76,234.13,29,427,1,2,233.7,234.17,1200,1,1,1,233.66,234.41,1,600,1,2,233.58,234.43,505,105,2,2,233.53,234.5,10,63,1,4,233.5,234.75,100,1,1,1,233.45,234.79,15,2000,1,1,233.4,234.89,110,2,2,2,AAPL,-987,-3.4600181323662738,0.04466313028579523
2024-10-21T12:11:34.156557363Z,2024-10-21T12:11:34.156391256Z,10,2,38,C,B,1,233.82,200,130,166107,12294618,233.9,234.0,11,154,2,7,233.76,234.06,29,200,1,1,233.7,234.13,1200,427,1,2,233.66,234.17,1,1,1,1,233.58,234.41,505,600,2,2,233.53,234.43,10,105,1,2,233.5,234.5,100,63,1,4,233.45,234.75,15,1,1,1,233.4,234.79,110,2000,2,1,233.39,234.89,10,2,1,2,AAPL,-1097,-3.5192794126719726,0.04542809572295215
2024-10-21T12:11:34.156569858Z,2024-10-21T12:11:34.156403417Z,10,2,38,A,B,1,233.78,400,130,166441,12294619,233.9,234.0,11,154,2,7,233.78,234.06,400,200,1,1,233.76,234.13,29,427,1,2,233.7,234.17,1200,1,1,1,233.66,234.41,1,600,1,2,233.58,234.43,505,105,2,2,233.53,234.5,10,63,1,4,233.5,234.75,100,1,1,1,233.45,234.79,15,2000,1,1,233.4,234.89,110,2,2,2,AAPL,-987,-3.2656087249555785,0.04215362531796144
2024-10-21T12:11:36.738842101Z,2024-10-21T12:11:36.738675617Z,10,2,38,C,B,0,233.9,1,130,166484,12295779,233.9,234.0,10,154,1,7,233.78,234.06,400,200,1,1,233.76,234.13,29,427,1,2,233.7,234.17,1200,1,1,1,233.66,234.41,1,600,1,2,233.58,234.43,505,105,2,2,233.53,234.5,10,63,1,4,233.5,234.75,100,1,1,1,233.45,234.79,15,2000,1,1,233.4,234.89,110,2,2,2,AAPL,-987,-3.3634759325746972,0.04341692963527447
2024-10-21T12:11:37.211098382Z,2024-10-21T12:11:37.210931791Z,10,2,38,A,B,1,233.82,200,130,166591,12295954,233.9,234.0,10,154,1,7,233.82,234.06,200,200,1,1,233.76,234.13,29,427,1,2,233.7,234.17,1200,1,1,1,233.66,234.41,1,600,1,2,233.58,234.43,505,105,2,2,233.53,234.5,10,63,1,4,233.5,234.75,100,1,1,1,233.45,234.79,15,2000,1,1,233.4,234.89,110,2,2,2,AAPL,-987,-3.4600181323662738,0.04466313028579523
2024-10-21T12:11:40.138648473Z,2024-10-21T12:11:40.138482175Z,10,2,38,C,B,1,233.82,200,130,166298,12298108,233.9,234.0,10,154,1,7,233.76,234.06,29,200,1,1,233.7,234.13,1200,427,1,2,233.66,234.17,1,1,1,1,233.58,234.41,505,600,2,2,233.53,234.43,10,105,1,2,233.5,234.5,100,63,1,4,233.45,234.75,15,1,1,1,233.4,234.79,110,2000,2,1,233.39,234.89,10,2,1,2,AAPL,-1097,-3.7383314063165582,0.04825569585602442
2024-10-21T12:11:40.138664034Z,2024-10-21T12:11:40.138496802Z,10,2,38,A,B,1,233.78,400,130,167232,12298109,233.9,234.0,10,154,1,7,233.78,234.06,400,200,1,1,233.76,234.13,29,427,1,2,233.7,234.17,1200,1,1,1,233.66,234.41,1,600,1,2,233.58,234.43,505,105,2,2,233.53,234.5,10,63,1,4,233.5,234.75,100,1,1,1,233.45,234.79,15,2000,1,1,233.4,234.89,110,2,2,2,AAPL,-987,-3.4600181323662738,0.04466313028579523
2024-10-21T12:11:43.193642005Z,2024-10-21T12:11:43.193475620Z,10,2,38,A,B,1,233.82,200,130,166385,12299803,233.9,234.0,10,154,1,7,233.82,234.06,200,200,1,1,233.76,234.13,29,427,1,2,233.7,234.17,1200,1,1,1,233.66,234.41,1,600,1,2,233.58,234.43,505,105,2,2,233.53,234.5,10,63,1,4,233.5,234.75,100,1,1,1,233.45,234.79,15,2000,1,1,233.4,234.89,110,2,2,2,AAPL,-1287,-3.503991089660293,0.04523074867550908
2024-10-21T12:11:45.774890873Z,2024-10-21T12:11:45.774723015Z,10,2,38,T,N,0,233.98,50,130,167858,12301317,233.9,234.0,10,154,1,7,233.82,234.06,200,200,1,1,233.76,234.13,29,427,1,2,233.7,234.17,1200,1,1,1,233.66,234.41,1,600,1,2,233.58,234.43,505,105,2,2,233.53,234.5,10,63,1,4,233.5,234.75,100,1,1,1,233.45,234.79,15,2000,1,1,233.4,234.89,110,2,2,2,AAPL,402,1.1302055877701633,-0.014589091006234348
2024-10-21T12:11:45.844109427Z,2024-10-21T12:11:45.843943302Z,10,2,38,C,B,1,233.82,200,130,166125,12301621,233.9,234.0,10,154,1,7,233.76,234.06,29,200,1,1,233.7,234.13,1200,427,1,2,233.66,234.17,1,1,1,1,233.58,234.41,505,600,2,2,233.53,234.43,10,105,1,2,233.5,234.5,100,63,1,4,233.45,234.75,15,1,1,1,233.4,234.79,110,2000,2,1,233.39,234.89,10,2,1,2,AAPL,392,1.1697384588379849,-0.015099395202202867
2024-10-21T12:11:45.844122189Z,2024-10-21T12:11:45.843955896Z,10,2,38,A,B,1,233.78,400,130,166293,12301622,233.9,234.0,10,154,1,7,233.78,234.06,400,200,1,1,233.76,234.13,29,427,1,2,233.7,234.17,1200,1,1,1,233.66,234.41,1,600,1,2,233.58,234.43,505,105,2,2,233.53,234.5,10,63,1,4,233.5,234.75,100,1,1,1,233.45,234.79,15,2000,1,1,233.4,234.89,110,2,2,2,AAPL,502,1.5706587867199724,-0.020274615722267297
2024-10-21T12:11:48.580889153Z,2024-10-21T12:11:48.580722768Z,10,2,38,A,B,1,233.79,400,130,166385,12303381,233.9,234.0,10,154,1,7,233.79,234.06,400,200,1,1,233.76,234.13,29,427,1,2,233.7,234.17,1200,1,1,1,233.66,234.41,1,600,1,2,233.58,234.43,505,105,2,2,233.53,234.5,10,63,1,4,233.5,234.75,100,1,1,1,233.45,234.79,15,2000,1,1,233.4,234.89,110,2,2,2,AAPL,300,6.896551724137931,-0.08902311386652909
2024-10-21T12:11:48.598638403Z,2024-10-21T12:11:48.598471411Z,10,2,38,C,B,2,233.76,29,130,166992,12303469,233.9,234.0,10,154,1,7,233.79,234.06,400,200,1,1,233.7,234.13,1200,427,1,2,233.66,234.17,1,1,1,1,233.58,234.41,505,600,2,2,233.53,234.43,10,105,1,2,233.5,234.5,100,63,1,4,233.45,234.75,15,1,1,1,233.4,234.79,110,2000,2,1,233.39,234.89,10,2,1,2,AAPL,290,7.140151515151516,-0.09216758559685251
2024-10-21T12:11:48.598681245Z,2024-10-21T12:11:48.598514970Z,10,2,38,A,B,2,233.77,28,130,166275,12303470,233.9,234.0,10,154,1,7,233.79,234.06,400,200,1,1,233.77,234.13,28,427,1,2,233.7,234.17,1200,1,1,1,233.66,234.41,1,600,1,2,233.58,234.43,505,105,2,2,233.53,234.5,10,63,1,4,233.5,234.75,100,1,1,1,233.45,234.79,15,2000,1,1,233.4,234.89,110,2,2,2,AAPL,400,9.58904109589041,-0.12377871311579043
2024-10-21T12:11:48.899213107Z,2024-10-21T12:11:48.899046660Z,10,2,38,A,B,1,233.83,200,130,166447,12303858,233.9,234.0,10,154,1,7,233.83,234.06,200,200,1,1,233.77,234.13,28,427,1,2,233.7,234.17,1200,1,1,1,233.66,234.41,1,600,1,2,233.58,234.43,505,105,2,2,233.53,234.5,10,63,1,4,233.5,234.75,100,1,1,1,233.45,234.79,15,2000,1,1,233.4,234.89,110,2,2,2,AAPL,400,9.375,-0.12101579541231298
2024-10-21T12:11:50.835087071Z,2024-10-21T12:11:50.834920978Z,10,2,38,C,B,1,233.83,200,130,166093,12305321,233.9,234.0,10,154,1,7,233.77,234.06,28,200,1,1,233.7,234.13,1200,427,1,2,233.66,234.17,1,1,1,1,233.58,234.41,505,600,2,2,233.53,234.43,10,105,1,2,233.5,234.5,100,63,1,4,233.45,234.75,15,1,1,1,233.4,234.79,110,2000,2,1,233.39,234.89,10,2,1,2,AAPL,390,9.915254237288135,-0.12798958701234456
2024-10-21T12:11:50.924256645Z,2024-10-21T12:11:50.924089402Z,10,2,38,A,B,1,233.83,200,130,167243,12305429,233.9,234.0,10,154,1,7,233.83,234.06,200,200,1,1,233.77,234.13,28,427,1,2,233.7,234.17,1200,1,1,1,233.66,234.41,1,600,1,2,233.58,234.43,505,105,2,2,233.53,234.5,10,63,1,4,233.5,234.75,100,1,1,1,233.45,234.79,15,2000,1,1,233.4,234.89,110,2,2,2,AAPL,500,12.38390092879257,-0.15985574626187887
2024-10-21T12:11:53.326738713Z,2024-10-21T12:11:53.326572732Z,10,2,38,C,B,1,233.83,200,130,165981,12306983,233.9,234.0,10,154,1,7,233.77,234.06,28,200,1,1,233.7,234.13,1200,427,1,2,233.66,234.17,1,1,1,1,233.58,234.41,505,600,2,2,233.53,234.43,10,105,1,2,233.5,234.5,100,63,1,4,233.45,234.75,15,1,1,1,233.4,234.79,110,2000,2,1,233.39,234.89,10,2,1,2,AAPL,490,12.776073619631902,-0.16491804920810915
2024-10-21T12:11:53.326752130Z,2024-10-21T12:11:53.326585955Z,10,2,38,A,B,1,233.79,400,130,166175,12306984,233.9,234.0,10,154,1,7,233.79,234.06,400,200,1,1,233.77,234.13,28,427,1,2,233.7,234.17,1200,1,1,1,233.66,234.41,1,600,1,2,233.58,234.43,505,105,2,2,233.53,234.5,10,63,1,4,233.5,234.75,100,1,1,1,233.45,234.79,15,2000,1,1,233.4,234.89,110,2,2,2,AAPL,600,15.254237288135592,-0.19690705694206856
2024-10-21T12:11:56.382644560Z,2024-10-21T12:11:56.382477901Z,10,2,38,A,B,1,233.83,200,130,166659,12309100,233.9,234.0,10,154,1,7,233.83,234.06,200,200,1,1,233.77,234.13,28,427,1,2,233.7,234.17,1200,1,1,1,233.66,234.41,1,600,1,2,233.58,234.43,505,105,2,2,233.53,234.5,10,63,1,4,233.5,234.75,100,1,1,1,233.45,234.79,15,2000,1,1,233.4,234.89,110,2,2,2,AAPL,500,12.108262108262107,-0.15629770347649158
2024-10-21T12:12:02.086696137Z,2024-10-21T12:12:02.086529609Z,10,2,38,A,A,0,233.97,20,130,166528,12315842,233.9,233.97,10,20,1,1,233.83,234.0,200,154,1,7,233.77,234.06,28,200,1,1,233.7,234.13,1200,427,1,2,233.66,234.17,1,1,1,1,233.58,234.41,505,600,2,2,233.53,234.43,10,105,1,2,233.5,234.5,100,63,1,4,233.45,234.75,15,1,1,1,233.4,234.79,110,2000,2,1,AAPL,-1600,-14.150347441566646,0.18265765877352275
2024-10-21T12:12:02.213968660Z,2024-10-21T12:12:02.213802116Z,10,2,38,C,B,1,233.83,200,130,166544,12315992,233.9,233.97,10,20,1,1,233.77,234.0,28,154,1,7,233.7,234.06,1200,200,1,1,233.66,234.13,1,427,1,2,233.58,234.17,505,1,2,1,233.53,234.41,10,600,1,2,233.5,234.43,100,105,1,2,233.45,234.5,15,63,1,4,233.4,234.75,110,1,2,1,233.39,234.79,10,2000,1,1,AAPL,-1610,-9.331530139103554,0.12045467116774274
2024-10-21T12:12:02.316815369Z,2024-10-21T12:12:02.316648939Z,10,2,38,A,B,1,233.82,200,130,166430,12316513,233.9,233.97,10,20,1,1,233.82,234.0,200,154,1,7,233.77,234.06,28,200,1,1,233.7,234.13,1200,427,1,2,233.66,234.17,1,1,1,1,233.58,234.41,505,600,2,2,233.53,234.43,10,105,1,2,233.5,234.5,100,63,1,4,233.45,234.75,15,1,1,1,233.4,234.79,110,2000,2,1,AAPL,-1500,-6.587976942080703,0.08503992211241318
2024-10-21T12:12:08.967352049Z,2024-10-21T12:12:08.967185824Z,10,2,38,C,A,0,233.97,20,130,166225,12322349,233.9,234.0,10,154,1,7,233.82,234.06,200,200,1,1,233.77,234.13,28,427,1,2,233.7,234.17,1200,1,1,1,233.66,234.41,1,600,1,2,233.58,234.43,505,105,2,2,233.53,234.5,10,63,1,4,233.5,234.75,100,1,1,1,233.45,234.79,15,2000,1,1,233.4,234.89,110,2,2,2,AAPL,-1698,-4.5604297224709045,0.0588676298972555
2024-10-21T12:12:08.996872145Z,2024-10-21T12:12:08.996704242Z,10,2,38,T,N,0,233.96,4,130,167903,12322367,233.9,234.0,10,154,1,7,233.82,234.06,200,200,1,1,233.77,234.13,28,427,1,2,233.7,234.17,1200,1,1,1,233.66,234.41,1,600,1,2,233.58,234.43,505,105,2,2,233.53,234.5,10,63,1,4,233.5,234.75,100,1,1,1,233.45,234.79,15,2000,1,1,233.4,234.89,110,2,2,2,AAPL,-1698,-4.983856765482829,0.06433337500756714
2024-10-21T12:12:08.996899848Z,2024-10-21T12:12:08.996733815Z,10,2,38,C,B,1,233.82,200,130,166033,12322368,233.9,234.0,10,154,1,7,233.77,234.06,28,200,1,1,233.7,234.13,1200,427,1,2,233.66,234.17,1,1,1,1,233.58,234.41,505,600,2,2,233.53,234.43,10,105,1,2,233.5,234.5,100,63,1,4,233.45,234.75,15,1,1,1,233.4,234.79,110,2000,2,1,233.39,234.89,10,2,1,2,AAPL,-1708,-5.504834456489892,0.0710583381722914
2024-10-21T12:12:09.099905611Z,2024-10-21T12:12:09.099739392Z,10,2,38,A,B,1,233.82,200,130,166219,12322505,233.9,234.0,10,154,1,7,233.82,234.06,200,200,1,1,233.77,234.13,28,427,1,2,233.7,234.17,1200,1,1,1,233.66,234.41,1,600,1,2,233.58,234.43,505,105,2,2,233.53,234.5,10,63,1,4,233.5,234.75,100,1,1,1,233.45,234.79,15,2000,1,1,233.4,234.89,110,2,2,2,AAPL,-1598,-5.527817814932257,0.07135501544196064
2024-10-21T12:12:10.232857553Z,2024-10-21T12:12:10.232691130Z,10,2,38,A,B,1,233.83,200,130,166423,12324515,233.9,234.0,10,154,1,7,233.83,234.06,200,200,1,1,233.77,234.13,28,427,1,2,233.7,234.17,1200,1,1,1,233.66,234.41,1,600,1,2,233.58,234.43,505,105,2,2,233.53,234.5,10,63,1,4,233.5,234.75,100,1,1,1,233.45,234.79,15,2000,1,1,233.4,234.89,110,2,2,2,AAPL,-1598,-5.8933333333333335,0.07607321823607799
2024-10-21T12:12:22.882293776Z,2024-10-21T12:12:22.882127538Z,10,2,38,C,B,1,233.83,200,130,166238,12335502,233.9,234.0,10,154,1,7,233.77,234.06,28,200,1,1,233.7,234.13,1200,427,1,2,233.66,234.17,1,1,1,1,233.58,234.41,505,600,2,2,233.53,234.43,10,105,1,2,233.5,234.5,100,63,1,4,233.45,234.75,15,1,1,1,233.4,234.79,110,2000,2,1,233.39,234.89,10,2,1,2,AAPL,92,2.3389830508474576,-0.030192415397783848
2024-10-21T12:12:22.882306926Z,2024-10-21T12:12:22.882140909Z,10,2,38,A,B,1,233.78,400,130,166017,12335503,233.9,234.0,10,154,1,7,233.78,234.06,400,200,1,1,233.77,234.13,28,427,1,2,233.7,234.17,1200,1,1,1,233.66,234.41,1,600,1,2,233.58,234.43,505,105,2,2,233.53,234.5,10,63,1,4,233.5,234.75,100,1,1,1,233.45,234.79,15,2000,1,1,233.4,234.89,110,2,2,2,AAPL,202,4.842465753424658,-0.06250825012347418
2024-10-21T12:12:25.937011711Z,2024-10-21T12:12:25.936845190Z,10,2,38,A,B,1,233.82,200,130,166521,12338576,233.9,234.0,10,154,1,7,233.82,234.06,200,200,1,1,233.77,234.13,28,427,1,2,233.7,234.17,1200,1,1,1,233.66,234.41,1,600,1,2,233.58,234.43,505,105,2,2,233.53,234.5,10,63,1,4,233.5,234.75,100,1,1,1,233.45,234.79,15,2000,1,1,233.4,234.89,110,2,2,2,AAPL,202,4.64367816091954,-0.059942230003462924
2024-10-21T12:12:28.133938919Z,2024-10-21T12:12:28.133772380Z,10,2,38,A,B,1,233.83,200,130,166539,12339995,233.9,234.0,10,154,1,7,233.83,234.06,200,200,1,1,233.77,234.13,28,427,1,2,233.7,234.17,1200,1,1,1,233.66,234.41,1,600,1,2,233.58,234.43,505,105,2,2,233.53,234.5,10,63,1,4,233.5,234.75,100,1,1,1,233.45,234.79,15,2000,1,1,233.4,234.89,110,2,2,2,AAPL,202,4.5,-0.05808758179791023
2024-10-21T12:12:28.677615324Z,2024-10-21T12:12:28.677449361Z,10,2,38,C,B,1,233.83,200,130,165963,12340411,233.9,234.0,10,154,1,7,233.77,234.06,28,200,1,1,233.7,234.13,1200,427,1,2,233.66,234.17,1,1,1,1,233.58,234.41,505,600,2,2,233.53,234.43,10,105,1,2,233.5,234.5,100,63,1,4,233.45,234.75,15,1,1,1,233.4,234.79,110,2000,2,1,233.39,234.89,10,2,1,2,AAPL,192,4.682926829268292,-0.06044886561083341
2024-10-21T12:12:28.677627803Z,2024-10-21T12:12:28.677461375Z,10,2,38,A,B,1,233.78,400,130,166428,12340412,233.9,234.0,10,154,1,7,233.78,234.06,400,200,1,1,233.77,234.13,28,427,1,2,233.7,234.17,1200,1,1,1,233.66,234.41,1,600,1,2,233.58,234.43,505,105,2,2,233.53,234.5,10,63,1,4,233.5,234.75,100,1,1,1,233.45,234.79,15,2000,1,1,233.4,234.89,110,2,2,2,AAPL,302,7.1287553648068664,-0.0920204800823356
2024-10-21T12:12:31.318989443Z,2024-10-21T12:12:31.318823338Z,10,2,38,C,A,1,234.06,200,130,166105,12341951,233.9,234.0,10,154,1,7,233.78,234.13,400,427,1,2,233.77,234.17,28,1,1,1,233.7,234.41,1200,600,1,2,233.66,234.43,1,105,1,2,233.58,234.5,505,63,2,4,233.53,234.75,10,1,1,1,233.5,234.79,100,2000,1,1,233.45,234.89,15,2,1,2,233.4,235.0,110,213,2,6,AAPL,413,7.272955974842767,-0.09388187224472871
2024-10-21T12:12:31.398006757Z,2024-10-21T12:12:31.397839079Z,10,2,38,T,N,0,233.98,50,130,167678,12342316,233.9,234.0,10,154,1,7,233.78,234.13,400,427,1,2,233.77,234.17,28,1,1,1,233.7,234.41,1200,600,1,2,233.66,234.43,1,105,1,2,233.58,234.5,505,63,2,4,233.53,234.75,10,1,1,1,233.5,234.79,100,2000,1,1,233.45,234.89,15,2,1,2,233.4,235.0,110,213,2,6,AAPL,413,5.910554561717352,-0.07629551590550403
2024-10-21T12:12:31.425970357Z,2024-10-21T12:12:31.425804077Z,10,2,38,A,A,1,234.07,200,130,166280,12342547,233.9,234.0,10,154,1,7,233.78,234.07,400,200,1,1,233.77,234.13,28,427,1,2,233.7,234.17,1200,1,1,1,233.66,234.41,1,600,1,2,233.58,234.43,505,105,2,2,233.53,234.5,10,63,1,4,233.5,234.75,100,1,1,1,233.45,234.79,15,2000,1,1,233.4,234.89,110,2,2,2,AAPL,411,6.014634146341463,-0.07763901176891416
2024-10-21T12:12:31.454024371Z,2024-10-21T12:12:31.453857757Z,10,2,38,A,B,1,233.79,400,130,166614,12342589,233.9,234.0,10,154,1,7,233.79,234.07,400,200,1,1,233.77,234.13,28,427,1,2,233.7,234.17,1200,1,1,1,233.66,234.41,1,600,1,2,233.58,234.43,505,105,2,2,233.53,234.5,10,63,1,4,233.5,234.75,100,1,1,1,233.45,234.79,15,2000,1,1,233.4,234.89,110,2,2,2,AAPL,411,6.125186289120716,-0.07906605768816395
2024-10-21T12:12:31.679118349Z,2024-10-21T12:12:31.678952187Z,10,2,38,C,B,2,233.77,28,130,166162,12343225,233.9,234.0,10,154,1,7,233.79,234.07,400,200,1,1,233.7,234.13,1200,427,1,2,233.66,234.17,1,1,1,1,233.58,234.41,505,600,2,2,233.53,234.43,10,105,1,2,233.5,234.5,100,63,1,4,233.45,234.75,15,1,1,1,233.4,234.79,110,2000,2,1,233.39,234.89,10,2,1,2,AAPL,401,6.515509601181684,-0.08410448820304678
2024-10-21T12:12:31.679174617Z,2024-10-21T12:12:31.679008317Z,10,2,38,A,B,1,233.82,30,130,166300,12343226,233.9,234.0,10,154,1,7,233.82,234.07,30,200,1,1,233.79,234.13,400,427,1,2,233.7,234.17,1200,1,1,1,233.66,234.41,1,600,1,2,233.58,234.43,505,105,2,2,233.53,234.5,10,63,1,4,233.5,234.75,100,1,1,1,233.45,234.79,15,2000,1,1,233.4,234.89,110,2,2,2,AAPL,511,8.3656207366985,-0.10798637307405957
2024-10-21T12:12:31.733543975Z,2024-10-21T12:12:31.733377635Z,10,2,38,A,B,1,233.87,200,130,166340,12343455,233.9,234.0,10,154,1,7,233.87,234.07,200,200,1,1,233.82,234.13,30,427,1,2,233.7,234.17,1200,1,1,1,233.66,234.41,1,600,1,2,233.58,234.43,505,105,2,2,233.53,234.5,10,63,1,4,233.5,234.75,100,1,1,1,233.45,234.79,15,2000,1,1,233.4,234.89,110,2,2,2,AAPL,511,8.419518377693283,-0.1086821027696149
2024-10-21T12:12:41.238878627Z,2024-10-21T12:12:41.238712131Z,10,2,38,A,A,1,234.06,200,130,166496,12350539,233.9,234.0,10,154,1,7,233.87,234.06,200,200,1,1,233.82,234.13,30,427,1,2,233.7,234.17,1200,1,1,1,233.66,234.41,1,600,1,2,233.58,234.43,505,105,2,2,233.53,234.5,10,63,1,4,233.5,234.75,100,1,1,1,233.45,234.79,15,2000,1,1,233.4,234.89,110,2,2,2,AAPL,511,8.466272189349112,-0.10928561740493092
2024-10-21T12:12:43.651514581Z,2024-10-21T12:12:43.651347870Z,10,2,38,C,B,1,233.87,200,130,166711,12352115,233.9,234.0,10,154,1,7,233.82,234.06,30,200,1,1,233.7,234.13,1200,427,1,2,233.66,234.17,1,1,1,1,233.58,234.41,505,600,2,2,233.53,234.43,10,105,1,2,233.5,234.5,100,63,1,4,233.45,234.75,15,1,1,1,233.4,234.79,110,2000,2,1,233.39,234.89,10,2,1,2,AAPL,401,6.607097591888467,-0.08528673818124378
2024-10-21T12:12:43.731298274Z,2024-10-21T12:12:43.731132036Z,10,2,38,A,B,2,233.78,400,130,166238,12352210,233.9,234.0,10,154,1,7,233.82,234.06,30,200,1,1,233.78,234.13,400,427,1,2,233.7,234.17,1200,1,1,1,233.66,234.41,1,600,1,2,233.58,234.43,505,105,2,2,233.53,234.5,10,63,1,4,233.5,234.75,100,1,1,1,233.45,234.79,15,2000,1,1,233.4,234.89,110,2,2,2,AAPL,511,8.466272189349112,-0.10928561740493092
2024-10-21T12:12:43.731821725Z,2024-10-21T12:12:43.731655758Z,10,2,38,C,B,1,233.82,30,130,165967,12352211,233.9,234.0,10,154,1,7,233.78,234.06,400,200,1,1,233.7,234.13,1200,427,1,2,233.66,234.17,1,1,1,1,233.58,234.41,505,600,2,2,233.53,234.43,10,105,1,2,233.5,234.5,100,63,1,4,233.45,234.75,15,1,1,1,233.4,234.79,110,2000,2,1,233.39,234.89,10,2,1,2,AAPL,501,8.830787309048178,-0.11399090670095192
2024-10-21T12:12:43.731951886Z,2024-10-21T12:12:43.731785539Z,10,2,38,A,B,2,233.76,29,130,166347,12352212,233.9,234.0,10,154,1,7,233.78,234.06,400,200,1,1,233.76,234.13,29,427,1,2,233.7,234.17,1200,1,1,1,233.66,234.41,1,600,1,2,233.58,234.43,505,105,2,2,233.53,234.5,10,63,1,4,233.5,234.75,100,1,1,1,233.45,234.79,15,2000,1,1,233.4,234.89,110,2,2,2,AAPL,611,10.778390297684675,-0.1391312506814579
2024-10-21T12:12:46.780539855Z,2024-10-21T12:12:46.780372537Z,10,2,38,A,B,1,233.82,200,128,167318,12353700,233.9,234.0,10,154,1,7,233.82,234.06,200,200,1,1,233.76,234.13,29,427,1,2,233.7,234.17,1200,1,1,1,233.66,234.41,1,600,1,2,233.58,234.43,505,105,2,2,233.53,234.5,10,63,1,4,233.5,234.75,100,1,1,1,233.45,234.79,15,2000,1,1,233.4,234.89,110,2,2,2,AAPL,611,10.778390297684675,-0.1391312506814579
2024-10-21T12:12:47.484642192Z,2024-10-21T12:12:47.484476304Z,10,2,38,C,B,1,233.82,200,130,165888,12353973,233.9,234.0,10,154,1,7,233.76,234.06,29,200,1,1,233.7,234.13,1200,427,1,2,233.66,234.17,1,1,1,1,233.58,234.41,505,600,2,2,233.53,234.43,10,105,1,2,233.5,234.5,100,63,1,4,233.45,234.75,15,1,1,1,233.4,234.79,110,2000,2,1,233.39,234.89,10,2,1,2,AAPL,601,11.190580503833516,-0.14445194675167308
2024-10-21T12:12:47.484860069Z,2024-10-21T12:12:47.484693420Z,10,2,38,A,A,0,233.99,100,130,166649,12353975,233.9,233.99,10,100,1,1,233.76,234.0,29,154,1,7,233.7,234.06,1200,200,1,1,233.66,234.13,1,427,1,2,233.58,234.17,505,1,2,1,233.53,234.41,10,600,1,2,233.5,234.43,100,105,1,2,233.45,234.5,15,63,1,4,233.4,234.75,110,1,2,1,233.39,234.79,10,2000,1,1,AAPL,-1399,-13.129301355578727,0.16947763698702067
2024-10-21T12:12:47.485189477Z,2024-10-21T12:12:47.485023375Z,10,2,38,C,A,0,233.99,100,130,166102,12353978,233.9,234.0,10,154,1,7,233.76,234.06,29,200,1,1,233.7,234.13,1200,427,1,2,233.66,234.17,1,1,1,1,233.58,234.41,505,600,2,2,233.53,234.43,10,105,1,2,233.5,234.5,100,63,1,4,233.45,234.75,15,1,1,1,233.4,234.79,110,2000,2,1,233.39,234.89,10,2,1,2,AAPL,-1397,-13.795738045738046,0.17808023604318912
2024-10-21T12:12:47.604634522Z,2024-10-21T12:12:47.604468075Z,10,2,38,A,B,1,233.78,400,130,166447,12354240,233.9,234.0,10,154,1,7,233.78,234.06,400,200,1,1,233.76,234.13,29,427,1,2,233.7,234.17,1200,1,1,1,233.66,234.41,1,600,1,2,233.58,234.43,505,105,2,2,233.53,234.5,10,63,1,4,233.5,234.75,100,1,1,1,233.45,234.79,15,2000,1,1,233.4,234.89,110,2,2,2,AAPL,-1287,-13.0,0.16780856963840732
2024-10-21T12:12:47.736357741Z,2024-10-21T12:12:47.736191420Z,10,2,38,A,A,1,234.06,200,130,166321,12354295,233.9,234.0,10,154,1,7,233.78,234.06,400,400,1,2,233.76,234.13,29,427,1,2,233.7,234.17,1200,1,1,1,233.66,234.41,1,600,1,2,233.58,234.43,505,105,2,2,233.53,234.5,10,63,1,4,233.5,234.75,100,1,1,1,233.45,234.79,15,2000,1,1,233.4,234.89,110,2,2,2,AAPL,-1287,-13.274557956777997,0.17135266025454268
2024-10-21T12:12:48.104314520Z,2024-10-21T12:12:48.104146428Z,10,2,38,T,A,0,233.9,10,130,168092,12354546,233.9,234.0,10,154,1,7,233.78,234.06,400,400,1,2,233.76,234.13,29,427,1,2,233.7,234.17,1200,1,1,1,233.66,234.41,1,600,1,2,233.58,234.43,505,105,2,2,233.53,234.5,10,63,1,4,233.5,234.75,100,1,1,1,233.45,234.79,15,2000,1,1,233.4,234.89,110,2,2,2,AAPL,-1287,-13.534416826003824,0.17470700988166882
2024-10-21T12:12:48.104314520Z,2024-10-21T12:12:48.104146428Z,10,2,38,C,B,0,233.9,10,130,168092,12354546,233.78,234.0,400,154,1,7,233.76,234.06,29,400,1,2,233.7,234.13,1200,427,1,2,233.66,234.17,1,1,1,1,233.58,234.41,505,600,2,2,233.53,234.43,10,105,1,2,233.5,234.5,100,63,1,4,233.45,234.75,15,1,1,1,233.4,234.79,110,2000,2,1,233.39,234.89,10,2,1,2,AAPL,-1297,-14.218779790276454,0.18354100758536807
2024-10-21T12:12:48.104334124Z,2024-10-21T12:12:48.104167967Z,10,2,38,A,A,0,233.98,100,130,166157,12354547,233.78,233.98,400,100,1,1,233.76,234.0,29,154,1,7,233.7,234.06,1200,400,1,2,233.66,234.13,1,427,1,2,233.58,234.17,505,1,2,1,233.53,234.41,10,600,1,2,233.5,234.43,100,105,1,2,233.45,234.5,15,63,1,4,233.4,234.75,110,1,2,1,233.39,234.79,10,2000,1,1,AAPL,-3297,-25.500483403158235,0.32916920345937917
2024-10-21T12:12:48.104345015Z,2024-10-21T12:12:48.104178898Z,10,2,38,C,B,0,233.78,400,130,166117,12354548,233.76,233.98,29,100,1,1,233.7,234.0,1200,154,1,7,233.66,234.06,1,400,1,2,233.58,234.13,505,427,2,2,233.53,234.17,10,1,1,1,233.5,234.41,100,600,1,2,233.45,234.43,15,105,1,2,233.4,234.5,110,63,2,4,233.39,234.75,10,1,1,1,233.31,234.79,110,2000,2,1,AAPL,-3407,-20.484607984607987,0.2644225204231203
2024-10-21T12:12:48.104347234Z,2024-10-21T12:12:48.104181225Z,10,2,38,A,A,0,233.98,100,130,166009,12354549,233.76,233.98,29,200,1,2,233.7,234.0,1200,154,1,7,233.66,234.06,1,400,1,2,233.58,234.13,505,427,2,2,233.53,234.17,10,1,1,1,233.5,234.41,100,600,1,2,233.45,234.43,15,105,1,2,233.4,234.5,110,63,2,4,233.39,234.75,10,1,1,1,233.31,234.79,110,2000,2,1,AAPL,-3407,-16.992518703241895,0.21934540447268513
2024-10-21T12:12:48.104351926Z,2024-10-21T12:12:48.104185923Z,10,2,38,C,A,0,233.98,100,130,166003,12354550,233.76,233.98,29,100,1,1,233.7,234.0,1200,154,1,7,233.66,234.06,1,400,1,2,233.58,234.13,505,427,2,2,233.53,234.17,10,1,1,1,233.5,234.41,100,600,1,2,233.45,234.43,15,105,1,2,233.4,234.5,110,63,2,4,233.39,234.75,10,1,1,1,233.31,234.79,110,2000,2,1,AAPL,-3407,-14.675973197192086,0.1894426207901852
2024-10-21T12:12:48.104356853Z,2024-10-21T12:12:48.104190565Z,10,2,38,A,A,0,233.95,14,130,166288,12354552,233.76,233.95,29,14,1,1,233.7,233.98,1200,100,1,1,233.66,234.0,1,154,1,7,233.58,234.06,505,400,2,2,233.53,234.13,10,427,1,2,233.5,234.17,100,1,1,1,233.45,234.41,15,600,1,2,233.4,234.43,110,105,2,2,233.39,234.5,10,63,1,4,233.31,234.75,110,1,2,1,AAPL,-3408,-15.09037716454495,0.19479189286818255
2024-10-21T12:12:48.104362882Z,2024-10-21T12:12:48.104196514Z,10,2,38,A,A,0,233.95,16,130,166368,12354553,233.76,233.95,29,30,1,2,233.7,233.98,1200,100,1,1,233.66,234.0,1,154,1,7,233.58,234.06,505,400,2,2,233.53,234.13,10,427,1,2,233.5,234.17,100,1,1,1,233.45,234.41,15,600,1,2,233.4,234.43,110,105,2,2,233.39,234.5,10,63,1,4,233.31,234.75,110,1,2,1,AAPL,-3408,-15.493337513716885,0.1999934467001468
2024-10-21T12:12:48.104375784Z,2024-10-21T12:12:48.104209602Z,10,2,38,A,A,1,233.98,16,130,166182,12354554,233.76,233.95,29,30,1,2,233.7,233.98,1200,116,1,2,233.66,234.0,1,154,1,7,233.58,234.06,505,400,2,2,233.53,234.13,10,427,1,2,233.5,234.17,100,1,1,1,233.45,234.41,15,600,1,2,233.4,234.43,110,105,2,2,233.39,234.5,10,63,1,4,233.31,234.75,110,1,2,1,AAPL,-3408,-15.889346491568887,0.20510526978763235
2024-10-21T12:12:48.104385015Z,2024-10-21T12:12:48.104217612Z,10,2,38,C,A,1,233.98,100,130,167403,12354555,233.76,233.95,29,30,1,2,233.7,233.98,1200,16,1,1,233.66,234.0,1,154,1,7,233.58,234.06,505,400,2,2,233.53,234.13,10,427,1,2,233.5,234.17,100,1,1,1,233.45,234.41,15,600,1,2,233.4,234.43,110,105,2,2,233.39,234.5,10,63,1,4,233.31,234.75,110,1,2,1,AAPL,-3408,-16.27858243451464,0.21012966415975418
2024-10-21T12:12:48.176341448Z,2024-10-21T12:12:48.176175311Z,10,2,38,A,B,1,233.71,27,130,166137,12354620,233.76,233.95,29,30,1,2,233.71,233.98,27,16,1,1,233.7,234.0,1200,154,1,7,233.66,234.06,1,400,1,2,233.58,234.13,505,427,2,2,233.53,234.17,10,1,1,1,233.5,234.41,100,600,1,2,233.45,234.43,15,105,1,2,233.4,234.5,110,63,2,4,233.39,234.75,10,1,1,1,AAPL,-3398,-16.35810233713798,0.21115613501490865
2024-10-21T12:12:48.176370376Z,2024-10-21T12:12:48.176204532Z,10,2,38,C,B,0,233.76,29,130,165844,12354621,233.71,233.95,27,30,1,2,233.7,233.98,1200,16,1,1,233.66,234.0,1,154,1,7,233.58,234.06,505,400,2,2,233.53,234.13,10,427,1,2,233.5,234.17,100,1,1,1,233.45,234.41,15,600,1,2,233.4,234.43,110,105,2,2,233.39,234.5,10,63,1,4,233.31,234.75,110,1,2,1,AAPL,-3508,-17.28344880677444,0.22310083251411206
2024-10-21T12:12:48.177018480Z,2024-10-21T12:12:48.176852661Z,10,2,38,C,B,0,233.71,27,130,165819,12354624,233.7,233.95,1200,30,1,2,233.66,233.98,1,16,1,1,233.58,234.0,505,154,2,7,233.53,234.06,10,400,1,2,233.5,234.13,100,427,1,2,233.45,234.17,15,1,1,1,233.4,234.41,110,600,2,2,233.39,234.43,10,105,1,2,233.31,234.5,110,63,2,4,233.3,234.75,100,1,1,1,AAPL,-3608,-18.190207012451303,0.23480558616815228
2024-10-21T12:12:48.180095554Z,2024-10-21T12:12:48.179929431Z,10,2,38,A,A,4,234.08,29,130,166123,12354625,233.7,233.95,1200,30,1,2,233.66,233.98,1,16,1,1,233.58,234.0,505,154,2,7,233.53,234.06,10,400,1,2,233.5,234.08,100,29,1,1,233.45,234.13,15,427,1,2,233.4,234.17,110,1,2,1,233.39,234.41,10,600,1,2,233.31,234.43,110,105,2,2,233.3,234.5,100,63,1,4,AAPL,-3671,-18.83416327146522,0.24311799991698496
2024-10-21T12:12:48.180133214Z,2024-10-21T12:12:48.179967058Z,10,2,38,C,A,5,234.13,27,130,166156,12354626,233.7,233.95,1200,30,1,2,233.66,233.98,1,16,1,1,233.58,234.0,505,154,2,7,233.53,234.06,10,400,1,2,233.5,234.08,100,29,1,1,233.45,234.13,15,400,1,1,233.4,234.17,110,1,2,1,233.39,234.41,10,600,1,2,233.31,234.43,110,105,2,2,233.3,234.5,100,63,1,4,AAPL,-3671,-19.152567638071105,0.24722807540365857
2024-10-21T12:12:48.204420400Z,2024-10-21T12:12:48.204254179Z,10,2,38,C,A,0,233.95,14,130,166221,12354640,233.7,233.95,1200,16,1,1,233.66,233.98,1,16,1,1,233.58,234.0,505,154,2,7,233.53,234.06,10,400,1,2,233.5,234.08,100,29,1,1,233.45,234.13,15,400,1,1,233.4,234.17,110,1,2,1,233.39,234.41,10,600,1,2,233.31,234.43,110,105,2,2,233.3,234.5,100,63,1,4,AAPL,-3671,-19.463328424153165,0.25123948486613074
2024-10-21T12:12:48.204447035Z,2024-10-21T12:12:48.204281167Z,10,2,38,C,A,1,233.98,16,130,165868,12354641,233.7,233.95,1200,16,1,1,233.66,234.0,1,154,1,7,233.58,234.06,505,400,2,2,233.53,234.08,10,29,1,1,233.5,234.13,100,400,1,1,233.45,234.17,15,1,1,1,233.4,234.41,110,600,2,2,233.39,234.43,10,105,1,2,233.31,234.5,110,63,2,4,233.3,234.75,100,1,1,1,AAPL,-3670,-19.85088809297566,0.2562422413026413
2024-10-21T12:12:48.214127843Z,2024-10-21T12:12:48.213961498Z,10,2,38,A,B,1,233.67,400,130,166345,12354647,233.7,233.95,1200,16,1,1,233.67,234.0,400,154,1,7,233.66,234.06,1,400,1,2,233.58,234.08,505,29,2,1,233.53,234.13,10,400,1,1,233.5,234.17,100,1,1,1,233.45,234.41,15,600,1,2,233.4,234.43,110,105,2,2,233.39,234.5,10,63,1,4,233.31,234.75,110,1,2,1,AAPL,-3560,-19.61716937354988,0.25322531791767516
2024-10-21T12:12:48.233136592Z,2024-10-21T12:12:48.232970230Z,10,2,38,C,A,2,234.06,200,130,166362,12354661,233.7,233.95,1200,16,1,1,233.67,234.0,400,154,1,7,233.66,234.06,1,200,1,1,233.58,234.08,505,29,2,1,233.53,234.13,10,400,1,1,233.5,234.17,100,1,1,1,233.45,234.41,15,600,1,2,233.4,234.43,110,105,2,2,233.39,234.5,10,63,1,4,233.31,234.75,110,1,2,1,AAPL,-3560,-19.972667769546142,0.25781421617466593
2024-10-21T12:12:48.233149556Z,2024-10-21T12:12:48.232983049Z,10,2,38,A,A,2,234.01,200,130,166507,12354662,233.7,233.95,1200,16,1,1,233.67,234.0,400,154,1,7,233.66,234.01,1,200,1,1,233.58,234.08,505,29,2,1,233.53,234.13,10,400,1,1,233.5,234.17,100,1,1,1,233.45,234.41,15,600,1,2,233.4,234.43,110,105,2,2,233.39,234.5,10,63,1,4,233.31,234.75,110,1,2,1,AAPL,-3560,-20.322534608248894,0.2623304203105598
2024-10-21T12:12:48.247502164Z,2024-10-21T12:12:48.247336117Z,10,2,38,C,B,1,233.67,400,130,166047,12354665,233.7,233.95,1200,16,1,1,233.66,234.0,1,154,1,7,233.58,234.01,505,200,2,1,233.53,234.08,10,29,1,1,233.5,234.13,100,400,1,1,233.45,234.17,15,1,1,1,233.4,234.41,110,600,2,2,233.39,234.43,10,105,1,2,233.31,234.5,110,63,2,4,233.3,234.75,100,1,1,1,AAPL,-3660,-21.2624867162593,0.2744636525239315
2024-10-21T12:12:48.247514656Z,2024-10-21T12:12:48.247348435Z,10,2,38,A,B,2,233.62,400,130,166221,12354666,233.7,233.95,1200,16,1,1,233.66,234.0,1,154,1,7,233.62,234.01,400,200,1,1,233.58,234.08,505,29,2,1,233.53,234.13,10,400,1,1,233.5,234.17,100,1,1,1,233.45,234.41,15,600,1,2,233.4,234.43,110,105,2,2,233.39,234.5,10,63,1,4,233.31,234.75,110,1,2,1,AAPL,-3550,-20.961619569801773,0.27057995363945253
2024-10-21T12:12:48.307017573Z,2024-10-21T12:12:48.306851049Z,10,2,38,A,B,0,233.72,400,130,166524,12354670,233.72,233.95,400,16,1,1,233.7,234.0,1200,154,1,7,233.66,234.01,1,200,1,1,233.58,234.08,505,29,2,1,233.53,234.13,10,400,1,1,233.5,234.17,100,1,1,1,233.45,234.41,15,600,1,2,233.4,234.43,110,105,2,2,233.39,234.5,10,63,1,4,233.31,234.75,110,1,2,1,AAPL,-3550,-21.2945525563228,0.2748775696589553
2024-10-21T12:12:48.348045881Z,2024-10-21T12:12:48.347879918Z,10,2,38,C,A,2,234.01,200,130,165963,12354690,233.72,233.95,400,16,1,1,233.7,234.0,1200,154,1,7,233.66,234.08,1,29,1,1,233.58,234.13,505,400,2,1,233.53,234.17,10,1,1,1,233.5,234.41,100,600,1,2,233.45,234.43,15,105,1,2,233.4,234.5,110,63,2,4,233.39,234.75,10,1,1,1,233.31,234.79,110,2000,2,1,AAPL,-1550,-8.29330577004925,0.10705290606507038
2024-10-21T12:12:48.348059124Z,2024-10-21T12:12:48.347893041Z,10,2,38,A,A,2,234.06,400,130,166083,12354691,233.72,233.95,400,16,1,1,233.7,234.0,1200,154,1,7,233.66,234.06,1,400,1,1,233.58,234.08,505,29,2,1,233.53,234.13,10,400,1,1,233.5,234.17,100,1,1,1,233.45,234.41,15,600,1,2,233.4,234.43,110,105,2,2,233.39,234.5,10,63,1,4,233.31,234.75,110,1,2,1,AAPL,-1551,-8.430365986230221,0.10882212751365958
2024-10-21T12:12:48.363929061Z,2024-10-21T12:12:48.363762750Z,10,2,38,C,A,0,233.95,16,130,166311,12354719,233.72,234.0,400,154,1,7,233.7,234.06,1200,400,1,1,233.66,234.08,1,29,1,1,233.58,234.13,505,400,2,1,233.53,234.17,10,1,1,1,233.5,234.41,100,600,1,2,233.45,234.43,15,105,1,2,233.4,234.5,110,63,2,4,233.39,234.75,10,1,1,1,233.31,234.79,110,2000,2,1,AAPL,449,2.212770516391686,-0.02856321963797914
2024-10-21T12:12:49.107440196Z,2024-10-21T12:12:49.107274312Z,10,2,38,C,B,0,233.72,400,130,165884,12355060,233.7,234.0,1200,154,1,7,233.66,234.06,1,400,1,1,233.58,234.08,505,29,2,1,233.53,234.13,10,400,1,1,233.5,234.17,100,1,1,1,233.45,234.41,15,600,1,2,233.4,234.43,110,105,2,2,233.39,234.5,10,63,1,4,233.31,234.75,110,1,2,1,233.3,234.79,100,2000,1,1,AAPL,249,1.0855454369308275,-0.014012602080681698
2024-10-21T12:12:49.117722704Z,2024-10-21T12:12:49.117556478Z,10,2,38,A,B,0,233.72,200,130,166226,12355064,233.72,234.0,200,154,1,7,233.7,234.06,1200,400,1,1,233.66,234.08,1,29,1,1,233.58,234.13,505,400,2,1,233.53,234.17,10,1,1,1,233.5,234.41,100,600,1,2,233.45,234.43,15,105,1,2,233.4,234.5,110,63,2,4,233.39,234.75,10,1,1,1,233.31,234.79,110,2000,2,1,AAPL,359,1.4515250065922474,-0.018736795011586524
2024-10-21T12:12:49.170261083Z,2024-10-21T12:12:49.170094147Z,10,2,38,A,B,3,233.65,28,130,166936,12355076,233.72,234.0,200,154,1,7,233.7,234.06,1200,400,1,1,233.66,234.08,1,29,1,1,233.65,234.13,28,400,1,1,233.58,234.17,505,1,2,1,233.53,234.41,10,600,1,2,233.5,234.43,100,105,1,2,233.45,234.5,15,63,1,4,233.4,234.75,110,1,2,1,233.39,234.79,10,2000,1,1,AAPL,369,1.4006622516556293,-0.018080240692064778
2024-10-21T12:12:49.179734911Z,2024-10-21T12:12:49.179568062Z,10,2,38,A,B,0,233.72,200,130,166849,12355080,233.72,234.0,400,154,2,7,233.7,234.06,1200,400,1,1,233.66,234.08,1,29,1,1,233.65,234.13,28,400,1,1,233.58,234.17,505,1,2,1,233.53,234.41,10,600,1,2,233.5,234.43,100,105,1,2,233.45,234.5,15,63,1,4,233.4,234.75,110,1,2,1,233.39,234.79,10,2000,1,1,AAPL,369,1.323074624635841,-0.017078712329616396
2024-10-21T12:12:50.108822491Z,2024-10-21T12:12:50.108656247Z,10,2,38,C,B,0,233.72,200,130,166244,12355613,233.72,234.0,200,154,1,7,233.7,234.06,1200,400,1,1,233.66,234.08,1,29,1,1,233.65,234.13,28,400,1,1,233.58,234.17,505,1,2,1,233.53,234.41,10,600,1,2,233.5,234.43,100,105,1,2,233.45,234.5,15,63,1,4,233.4,234.75,110,1,2,1,233.39,234.79,10,2000,1,1,AAPL,369,1.2563229571984436,-0.01621705834241268
2024-10-21T12:12:50.108831892Z,2024-10-21T12:12:50.108666090Z,10,2,38,C,B,0,233.72,200,130,165802,12355614,233.7,234.0,1200,154,1,7,233.66,234.06,1,400,1,1,233.65,234.08,28,29,1,1,233.58,234.13,505,400,2,1,233.53,234.17,10,1,1,1,233.5,234.41,100,600,1,2,233.45,234.43,15,105,1,2,233.4,234.5,110,63,2,4,233.39,234.75,10,1,1,1,233.31,234.79,110,2000,2,1,AAPL,259,0.8383504887680456,-0.010821722798140417
2024-10-21T12:12:50.212341929Z,2024-10-21T12:12:50.212175433Z,10,2,38,A,B,0,233.72,400,130,166496,12355646,233.72,234.0,400,154,1,7,233.7,234.06,1200,400,1,1,233.66,234.08,1,29,1,1,233.65,234.13,28,400,1,1,233.58,234.17,505,1,2,1,233.53,234.41,10,600,1,2,233.5,234.43,100,105,1,2,233.45,234.5,15,63,1,4,233.4,234.75,110,1,2,1,233.39,234.79,10,2000,1,1,AAPL,269,0.8338803792851933,-0.010764021053644683
2024-10-21T12:12:50.565470381Z,2024-10-21T12:12:50.565304171Z,10,2,38,C,B,3,233.65,28,130,166210,12355988,233.72,234.0,400,154,1,7,233.7,234.06,1200,400,1,1,233.66,234.08,1,29,1,1,233.58,234.13,505,400,2,1,233.53,234.17,10,1,1,1,233.5,234.41,100,600,1,2,233.45,234.43,15,105,1,2,233.4,234.5,110,63,2,4,233.39,234.75,10,1,1,1,233.31,234.79,110,2000,2,1,AAPL,159,0.4722682355629177,-0.006096204391959049
2024-10-21T12:12:50.565594035Z,2024-10-21T12:12:50.565427767Z,10,2,38,A,B,1,233.71,26,130,166268,12355989,233.72,234.0,400,154,1,7,233.71,234.06,26,400,1,1,233.7,234.08,1200,29,1,1,233.66,234.13,1,400,1,1,233.58,234.17,505,1,2,1,233.53,234.41,10,600,1,2,233.5,234.43,100,105,1,2,233.45,234.5,15,63,1,4,233.4,234.75,110,1,2,1,233.39,234.79,10,2000,1,1,AAPL,169,0.4838483146067416,-0.006245684122777801
2024-10-21T12:12:50.565667034Z,2024-10-21T12:12:50.565500981Z,10,2,38,C,A,2,234.08,29,130,166053,12355990,233.72,234.0,400,154,1,7,233.71,234.06,26,400,1,1,233.7,234.13,1200,400,1,1,233.66,234.17,1,1,1,1,233.58,234.41,505,600,2,2,233.53,234.43,10,105,1,2,233.5,234.5,100,63,1,4,233.45,234.75,15,1,1,1,233.4,234.79,110,2000,2,1,233.39,234.89,10,2,1,2,AAPL,171,0.4986499621989416,-0.0064367489928346365
2024-10-21T12:12:50.565721409Z,2024-10-21T12:12:50.565554902Z,10,2,38,A,A,2,234.13,30,130,166507,12355991,233.72,234.0,400,154,1,7,233.71,234.06,26,400,1,1,233.7,234.13,1200,430,1,2,233.66,234.17,1,1,1,1,233.58,234.41,505,600,2,2,233.53,234.43,10,105,1,2,233.5,234.5,100,63,1,4,233.45,234.75,15,1,1,1,233.4,234.79,110,2000,2,1,233.39,234.89,10,2,1,2,AAPL,171,0.5077197149643705,-0.006553824549645453
2024-10-21T12:12:50.574010932Z,2024-10-21T12:12:50.573844808Z,10,2,38,C,B,0,233.72,200,130,166124,12355992,233.72,234.0,200,154,1,7,233.71,234.06,26,400,1,1,233.7,234.13,1200,430,1,2,233.66,234.17,1,1,1,1,233.58,234.41,505,600,2,2,233.53,234.43,10,105,1,2,233.5,234.5,100,63,1,4,233.45,234.75,15,1,1,1,233.4,234.79,110,2000,2,1,233.39,234.89,10,2,1,2,AAPL,171,0.5167835941716136,-0.006670824288502588
2024-10-21T12:12:50.619715566Z,2024-10-21T12:12:50.619549454Z,10,2,38,C,B,0,233.72,200,130,166112,12355999,233.71,234.0,26,154,1,7,233.7,234.06,1200,400,1,1,233.66,234.13,1,430,1,2,233.58,234.17,505,1,2,1,233.53,234.41,10,600,1,2,233.5,234.43,100,105,1,2,233.45,234.5,15,63,1,4,233.4,234.75,110,1,2,1,233.39,234.79,10,2000,1,1,233.31,234.89,110,2,2,2,AAPL,61,0.18707629398471967,-0.0024148465620638456
2024-10-21T12:12:50.619728644Z,2024-10-21T12:12:50.619562205Z,10,2,38,A,A,1,234.05,200,130,166439,12356000,233.71,234.0,26,154,1,7,233.7,234.05,1200,200,1,1,233.66,234.13,1,430,1,2,233.58,234.17,505,1,2,1,233.53,234.41,10,600,1,2,233.5,234.43,100,105,1,2,233.45,234.5,15,63,1,4,233.4,234.75,110,1,2,1,233.39,234.79,10,2000,1,1,233.31,234.89,110,2,2,2,AAPL,61,0.18978650359403498,-0.00244983090036842
2024-10-21T12:12:50.622790340Z,2024-10-21T12:12:50.622623771Z,10,2,38,A,A,1,234.01,200,130,166569,12356003,233.71,234.0,26,154,1,7,233.7,234.01,1200,200,1,1,233.66,234.13,1,430,1,2,233.58,234.17,505,1,2,1,233.53,234.41,10,600,1,2,233.5,234.43,100,105,1,2,233.45,234.5,15,63,1,4,233.4,234.75,110,1,2,1,233.39,234.79,10,2000,1,1,233.31,234.89,110,2,2,2,AAPL,61,0.1924804791956359,-0.0024846056843949907
2024-10-21T12:12:50.641720668Z,2024-10-21T12:12:50.641554545Z,10,2,38,A,B,0,233.77,200,130,166123,12356008,233.77,234.0,200,154,1,7,233.71,234.01,26,200,1,1,233.7,234.13,1200,430,1,2,233.66,234.17,1,1,1,1,233.58,234.41,505,600,2,2,233.53,234.43,10,105,1,2,233.5,234.5,100,63,1,4,233.45,234.75,15,1,1,1,233.4,234.79,110,2000,2,1,233.39,234.89,10,2,1,2,AAPL,71,0.22775876817792984,-0.002939990239272616
2024-10-21T12:12:50.682530531Z,2024-10-21T12:12:50.682363924Z,10,2,38,C,A,1,234.01,200,130,166607,12356017,233.77,234.0,200,154,1,7,233.71,234.13,26,430,1,2,233.7,234.17,1200,1,1,1,233.66,234.41,1,600,1,2,233.58,234.43,505,105,2,2,233.53,234.5,10,63,1,4,233.5,234.75,100,1,1,1,233.45,234.79,15,2000,1,1,233.4,234.89,110,2,2,2,233.39,235.0,10,213,1,6,AAPL,284,0.9207302489968376,-0.011885109700536458
2024-10-21T12:12:50.682542775Z,2024-10-21T12:12:50.682376586Z,10,2,38,A,A,1,234.06,400,130,166189,12356018,233.77,234.0,200,154,1,7,233.71,234.06,26,400,1,1,233.7,234.13,1200,430,1,2,233.66,234.17,1,1,1,1,233.58,234.41,505,600,2,2,233.53,234.43,10,105,1,2,233.5,234.5,100,63,1,4,233.45,234.75,15,1,1,1,233.4,234.79,110,2000,2,1,233.39,234.89,10,2,1,2,AAPL,282,0.9289376510905082,-0.011991053731750774
2024-10-21T12:12:50.736679110Z,2024-10-21T12:12:50.736513051Z,10,2,38,C,B,0,233.77,200,130,166059,12356039,233.71,234.0,26,154,1,7,233.7,234.06,1200,400,1,1,233.66,234.13,1,430,1,2,233.58,234.17,505,1,2,1,233.53,234.41,10,600,1,2,233.5,234.43,100,105,1,2,233.45,234.5,15,63,1,4,233.4,234.75,110,1,2,1,233.39,234.79,10,2000,1,1,233.31,234.89,110,2,2,2,AAPL,172,0.5740166865315852,-0.0074096091627264115
2024-10-21T12:12:50.837873116Z,2024-10-21T12:12:50.837707032Z,10,2,38,A,B,0,233.77,200,130,166084,12356086,233.77,234.0,200,154,1,7,233.71,234.06,26,400,1,1,233.7,234.13,1200,430,1,2,233.66,234.17,1,1,1,1,233.58,234.41,505,600,2,2,233.53,234.43,10,105,1,2,233.5,234.5,100,63,1,4,233.45,234.75,15,1,1,1,233.4,234.79,110,2000,2,1,233.39,234.89,10,2,1,2,AAPL,182,0.6168348028702306,-0.007962320459449411
2024-10-21T12:12:50.886653895Z,2024-10-21T12:12:50.886487788Z,10,2,38,C,B,0,233.77,200,130,166107,12356099,233.71,234.0,26,154,1,7,233.7,234.06,1200,400,1,1,233.66,234.13,1,430,1,2,233.58,234.17,505,1,2,1,233.53,234.41,10,600,1,2,233.5,234.43,100,105,1,2,233.45,234.5,15,63,1,4,233.4,234.75,110,1,2,1,233.39,234.79,10,2000,1,1,233.31,234.89,110,2,2,2,AAPL,72,0.24710261622534915,-0.003189687429437242
2024-10-21T12:12:50.986944410Z,2024-10-21T12:12:50.986777714Z,10,2,38,A,B,0,233.77,200,130,166696,12356148,233.77,234.0,200,154,1,7,233.71,234.06,26,400,1,1,233.7,234.13,1200,430,1,2,233.66,234.17,1,1,1,1,233.58,234.41,505,600,2,2,233.53,234.43,10,105,1,2,233.5,234.5,100,63,1,4,233.45,234.75,15,1,1,1,233.4,234.79,110,2000,2,1,233.39,234.89,10,2,1,2,AAPL,82,0.28566150273151936,-0.0036874190903180195
2024-10-21T12:12:51.039503151Z,2024-10-21T12:12:51.039337327Z,10,2,38,C,B,0,233.77,200,130,165824,12356173,233.71,234.0,26,154,1,7,233.7,234.06,1200,400,1,1,233.66,234.13,1,430,1,2,233.58,234.17,505,1,2,1,233.53,234.41,10,600,1,2,233.5,234.43,100,105,1,2,233.45,234.5,15,63,1,4,233.4,234.75,110,1,2,1,233.39,234.79,10,2000,1,1,233.31,234.89,110,2,2,2,AAPL,-28,-0.09872904770676,0.0012744292521102672
2024-10-21T12:12:51.148063732Z,2024-10-21T12:12:51.147897247Z,10,2,38,A,B,0,233.77,200,130,166485,12356223,233.77,234.0,200,154,1,7,233.71,234.06,26,400,1,1,233.7,234.13,1200,430,1,2,233.66,234.17,1,1,1,1,233.58,234.41,505,600,2,2,233.53,234.43,10,105,1,2,233.5,234.5,100,63,1,4,233.45,234.75,15,1,1,1,233.4,234.79,110,2000,2,1,233.39,234.89,10,2,1,2,AAPL,-18,-0.0643956333026437,0.0008312414704212328
2024-10-21T12:12:51.221545416Z,2024-10-21T12:12:51.221379329Z,10,2,38,C,B,0,233.77,200,130,166087,12356261,233.71,234.0,26,154,1,7,233.7,234.06,1200,400,1,1,233.66,234.13,1,430,1,2,233.58,234.17,505,1,2,1,233.53,234.41,10,600,1,2,233.5,234.43,100,105,1,2,233.45,234.5,15,63,1,4,233.4,234.75,110,1,2,1,233.39,234.79,10,2000,1,1,233.31,234.89,110,2,2,2,AAPL,-128,-0.46329372885356834,0.005980358304720109
2024-10-21T12:12:51.330104268Z,2024-10-21T12:12:51.329937404Z,10,2,38,A,B,0,233.77,200,130,166864,12356295,233.77,234.0,200,154,1,7,233.71,234.06,26,400,1,1,233.7,234.13,1200,430,1,2,233.66,234.17,1,1,1,1,233.58,234.41,505,600,2,2,233.53,234.43,10,105,1,2,233.5,234.5,100,63,1,4,233.45,234.75,15,1,1,1,233.4,234.79,110,2000,2,1,233.39,234.89,10,2,1,2,AAPL,-331,-1.2079014173894649,0.01559201608587161
2024-10-21T12:12:51.374577807Z,2024-10-21T12:12:51.374411634Z,10,2,38,C,B,0,233.77,200,130,166173,12356317,233.71,234.0,26,154,1,7,233.7,234.06,1200,400,1,1,233.66,234.13,1,430,1,2,233.58,234.17,505,1,2,1,233.53,234.41,10,600,1,2,233.5,234.43,100,105,1,2,233.45,234.5,15,63,1,4,233.4,234.75,110,1,2,1,233.39,234.79,10,2000,1,1,233.31,234.89,110,2,2,2,AAPL,-441,-1.6278211347816915,0.021012487404221902
2024-10-21T12:12:51.475205660Z,2024-10-21T12:12:51.475039269Z,10,2,38,A,B,0,233.77,200,130,166391,12356344,233.77,234.0,200,154,1,7,233.71,234.06,26,400,1,1,233.7,234.13,1200,430,1,2,233.66,234.17,1,1,1,1,233.58,234.41,505,600,2,2,233.53,234.43,10,105,1,2,233.5,234.5,100,63,1,4,233.45,234.75,15,1,1,1,233.4,234.79,110,2000,2,1,233.39,234.89,10,2,1,2,AAPL,-429,-1.5602920332682588,0.020140798024688367
2024-10-21T12:12:51.507242100Z,2024-10-21T12:12:51.507076220Z,10,2,38,C,B,0,233.77,200,130,165880,12356356,233.71,234.0,26,154,1,7,233.7,234.06,1200,400,1,1,233.66,234.13,1,430,1,2,233.58,234.17,505,1,2,1,233.53,234.41,10,600,1,2,233.5,234.43,100,105,1,2,233.45,234.5,15,63,1,4,233.4,234.75,110,1,2,1,233.39,234.79,10,2000,1,1,233.31,234.89,110,2,2,2,AAPL,-539,-1.9832555659245434,0.025600559980400592
2024-10-21T12:12:51.709392937Z,2024-10-21T12:12:51.709226597Z,10,2,38,A,B,0,233.77,200,130,166340,12356415,233.77,234.0,200,154,1,7,233.71,234.06,26,400,1,1,233.7,234.13,1200,430,1,2,233.66,234.17,1,1,1,1,233.58,234.41,505,600,2,2,233.53,234.43,10,105,1,2,233.5,234.5,100,63,1,4,233.45,234.75,15,1,1,1,233.4,234.79,110,2000,2,1,233.39,234.89,10,2,1,2,AAPL,-629,-2.2877009065867946,0.029530447453447514
2024-10-21T12:12:52.481412276Z,2024-10-21T12:12:52.481246232Z,10,2,38,C,B,0,233.77,200,130,166044,12356788,233.71,234.0,26,154,1,7,233.7,234.06,1200,400,1,1,233.66,234.13,1,430,1,2,233.58,234.17,505,1,2,1,233.53,234.41,10,600,1,2,233.5,234.43,100,105,1,2,233.45,234.5,15,63,1,4,233.4,234.75,110,1,2,1,233.39,234.79,10,2000,1,1,233.31,234.89,110,2,2,2,AAPL,-739,-2.687775786911989,0.034694754639265045
2024-10-21T12:12:52.583011665Z,2024-10-21T12:12:52.582845276Z,10,2,38,A,B,0,233.77,200,130,166389,12356899,233.77,234.0,200,154,1,7,233.71,234.06,26,400,1,1,233.7,234.13,1200,430,1,2,233.66,234.17,1,1,1,1,233.58,234.41,505,600,2,2,233.53,234.43,10,105,1,2,233.5,234.5,100,63,1,4,233.45,234.75,15,1,1,1,233.4,234.79,110,2000,2,1,233.39,234.89,10,2,1,2,AAPL,-729,-2.6895334848282313,0.03471744362181743
2024-10-21T12:12:53.923027418Z,2024-10-21T12:12:53.922861024Z,10,2,38,C,B,1,233.71,26,130,166394,12357591,233.77,234.0,200,154,1,7,233.7,234.06,1200,400,1,1,233.66,234.13,1,430,1,2,233.58,234.17,505,1,2,1,233.53,234.41,10,600,1,2,233.5,234.43,100,105,1,2,233.45,234.5,15,63,1,4,233.4,234.75,110,1,2,1,233.39,234.79,10,2000,1,1,233.31,234.89,110,2,2,2,AAPL,-839,-3.130847349201695,0.040414078109671965
2024-10-21T12:12:53.923129817Z,2024-10-21T12:12:53.922963386Z,10,2,38,A,B,1,233.76,27,130,166431,12357592,233.77,234.0,200,154,1,7,233.76,234.06,27,400,1,1,233.7,234.13,1200,430,1,2,233.66,234.17,1,1,1,1,233.58,234.41,505,600,2,2,233.53,234.43,10,105,1,2,233.5,234.5,100,63,1,4,233.45,234.75,15,1,1,1,233.4,234.79,110,2000,2,1,233.39,234.89,10,2,1,2,AAPL,-829,-3.1367209358096404,0.04048989643023556
2024-10-21T12:12:59.629031962Z,2024-10-21T12:12:59.628865467Z,10,2,38,A,B,0,233.78,200,130,166495,12361324,233.78,234.0,200,154,1,7,233.76,234.06,27,400,1,1,233.7,234.13,1200,430,1,2,233.66,234.17,1,1,1,1,233.58,234.41,505,600,2,2,233.53,234.43,10,105,1,2,233.5,234.5,100,63,1,4,233.45,234.75,15,1,1,1,233.4,234.79,110,2000,2,1,233.39,234.89,10,2,1,2,AAPL,-829,-3.1798833275618654,0.04104705175501352
2024-10-21T12:12:59.643903867Z,2024-10-21T12:12:59.643737494Z,10,2,38,A,B,1,233.77,26,130,166373,12361417,233.78,234.0,200,154,1,7,233.77,234.06,26,400,1,1,233.76,234.13,27,430,1,2,233.7,234.17,1200,1,1,1,233.66,234.41,1,600,1,2,233.58,234.43,505,105,2,2,233.53,234.5,10,63,1,4,233.5,234.75,100,1,1,1,233.45,234.79,15,2000,1,1,233.4,234.89,110,2,2,2,AAPL,-719,-2.7879319044963213,0.035987605010985274
2024-10-21T12:12:59.691792264Z,2024-10-21T12:12:59.691625988Z,10,2,38,C,B,2,233.76,27,130,166276,12361539,233.78,234.0,200,154,1,7,233.77,234.06,26,400,1,1,233.7,234.13,1200,430,1,2,233.66,234.17,1,1,1,1,233.58,234.41,505,600,2,2,233.53,234.43,10,105,1,2,233.5,234.5,100,63,1,4,233.45,234.75,15,1,1,1,233.4,234.79,110,2000,2,1,233.39,234.89,10,2,1,2,AAPL,-729,-2.864516129032258,0.03697618110146543
2024-10-21T12:12:59.691815700Z,2024-10-21T12:12:59.691649558Z,10,2,38,C,B,1,233.77,26,130,166142,12361540,233.78,234.0,200,154,1,7,233.7,234.06,1200,400,1,1,233.66,234.13,1,430,1,2,233.58,234.17,505,1,2,1,233.53,234.41,10,600,1,2,233.5,234.43,100,105,1,2,233.45,234.5,15,63,1,4,233.4,234.75,110,1,2,1,233.39,234.79,10,2000,1,1,233.31,234.89,110,2,2,2,AAPL,-839,-3.3313921168965246,0.04300278046469782
2024-10-21T12:12:59.691888302Z,2024-10-21T12:12:59.691721965Z,10,2,38,A,B,1,233.77,26,130,166337,12361541,233.78,234.0,200,154,1,7,233.77,234.06,26,400,1,1,233.7,234.13,1200,430,1,2,233.66,234.17,1,1,1,1,233.58,234.41,505,600,2,2,233.53,234.43,10,105,1,2,233.5,234.5,100,63,1,4,233.45,234.75,15,1,1,1,233.4,234.79,110,2000,2,1,233.39,234.89,10,2,1,2,AAPL,-829,-3.334515335150441,0.04304309606376384
2024-10-21T12:13:11.883895663Z,2024-10-21T12:13:11.883729412Z,10,2,38,C,A,1,234.06,400,130,166251,12371151,233.78,234.0,200,154,1,7,233.77,234.13,26,430,1,2,233.7,234.17,1200,1,1,1,233.66,234.41,1,600,1,2,233.58,234.43,505,105,2,2,233.53,234.5,10,63,1,4,233.5,234.75,100,1,1,1,233.45,234.79,15,2000,1,1,233.4,234.89,110,2,2,2,233.39,235.0,10,213,1,6,AAPL,13,0.3556771545827634,-0.00459120573566094
2024-10-21T12:13:11.920775720Z,2024-10-21T12:13:11.920609443Z,10,2,38,A,A,1,234.06,200,130,166277,12371429,233.78,234.0,200,154,1,7,233.77,234.06,26,200,1,1,233.7,234.13,1200,430,1,2,233.66,234.17,1,1,1,1,233.58,234.41,505,600,2,2,233.53,234.43,10,105,1,2,233.5,234.5,100,63,1,4,233.45,234.75,15,1,1,1,233.4,234.79,110,2000,2,1,233.39,234.89,10,2,1,2,AAPL,11,0.32570659488559894,-0.00420433521611912
2024-10-21T12:13:11.948803197Z,2024-10-21T12:13:11.948637105Z,10,2,38,A,A,1,234.06,200,130,166092,12371519,233.78,234.0,200,154,1,7,233.77,234.06,26,400,1,2,233.7,234.13,1200,430,1,2,233.66,234.17,1,1,1,1,233.58,234.41,505,600,2,2,233.53,234.43,10,105,1,2,233.5,234.5,100,63,1,4,233.45,234.75,15,1,1,1,233.4,234.79,110,2000,2,1,233.39,234.89,10,2,1,2,AAPL,11,0.34966887417218545,-0.004513648740146667
2024-10-21T12:13:21.543158873Z,2024-10-21T12:13:21.542992246Z,10,2,38,C,A,1,234.06,200,130,166627,12379437,233.78,234.0,200,154,1,7,233.77,234.06,26,200,1,1,233.7,234.13,1200,430,1,2,233.66,234.17,1,1,1,1,233.58,234.41,505,600,2,2,233.53,234.43,10,105,1,2,233.5,234.5,100,63,1,4,233.45,234.75,15,1,1,1,233.4,234.79,110,2000,2,1,233.39,234.89,10,2,1,2,AAPL,211,6.517374517374518,-0.08412856119680177
2024-10-21T12:13:21.543168132Z,2024-10-21T12:13:21.543002194Z,10,2,38,C,A,1,234.06,200,130,165938,12379438,233.78,234.0,200,154,1,7,233.77,234.13,26,430,1,2,233.7,234.17,1200,1,1,1,233.66,234.41,1,600,1,2,233.58,234.43,505,105,2,2,233.53,234.5,10,63,1,4,233.5,234.75,100,1,1,1,233.45,234.79,15,2000,1,1,233.4,234.89,110,2,2,2,233.39,235.0,10,213,1,6,AAPL,424,8.79668049792531,-0.1135506439940707
2024-10-21T12:13:21.543179396Z,2024-10-21T12:13:21.543013145Z,10,2,38,A,A,1,234.08,400,130,166251,12379439,233.78,234.0,200,154,1,7,233.77,234.08,26,400,1,1,233.7,234.13,1200,430,1,2,233.66,234.17,1,1,1,1,233.58,234.41,505,600,2,2,233.53,234.43,10,105,1,2,233.5,234.5,100,63,1,4,233.45,234.75,15,1,1,1,233.4,234.79,110,2000,2,1,233.39,234.89,10,2,1,2,AAPL,422,10.25101214574899,-0.1323236681172368
2024-10-21T12:13:21.617302321Z,2024-10-21T12:13:21.617135979Z,10,2,38,C,B,1,233.77,26,130,166342,12379657,233.78,234.0,200,154,1,7,233.7,234.08,1200,400,1,1,233.66,234.13,1,430,1,2,233.58,234.17,505,1,2,1,233.53,234.41,10,600,1,2,233.5,234.43,100,105,1,2,233.45,234.5,15,63,1,4,233.4,234.75,110,1,2,1,233.39,234.79,10,2000,1,1,233.31,234.89,110,2,2,2,AAPL,312,7.207920792079208,-0.09304237524505753
2024-10-21T12:13:21.617386770Z,2024-10-21T12:13:21.617220419Z,10,2,38,A,B,1,233.72,26,130,166351,12379659,233.78,234.0,200,154,1,7,233.72,234.08,26,400,1,1,233.7,234.13,1200,430,1,2,233.66,234.17,1,1,1,1,233.58,234.41,505,600,2,2,233.53,234.43,10,105,1,2,233.5,234.5,100,63,1,4,233.45,234.75,15,1,1,1,233.4,234.79,110,2000,2,1,233.39,234.89,10,2,1,2,AAPL,322,8.336569579288026,-0.10761137052241407
2024-10-21T12:13:22.557998386Z,2024-10-21T12:13:22.557831797Z,10,2,38,A,A,1,234.07,400,130,166589,12380655,233.78,234.0,200,154,1,7,233.72,234.07,26,400,1,1,233.7,234.13,1200,430,1,2,233.66,234.17,1,1,1,1,233.58,234.41,505,600,2,2,233.53,234.43,10,105,1,2,233.5,234.5,100,63,1,4,233.45,234.75,15,1,1,1,233.4,234.79,110,2000,2,1,233.39,234.89,10,2,1,2,AAPL,322,9.2,-0.11875683389794979
2024-10-21T12:13:25.372097284Z,2024-10-21T12:13:25.371930587Z,10,2,38,A,B,0,233.79,200,130,166697,12382998,233.79,234.0,200,154,1,7,233.72,234.07,26,400,1,1,233.7,234.13,1200,430,1,2,233.66,234.17,1,1,1,1,233.58,234.41,505,600,2,2,233.53,234.43,10,105,1,2,233.5,234.5,100,63,1,4,233.45,234.75,15,1,1,1,233.4,234.79,110,2000,2,1,233.39,234.89,10,2,1,2,AAPL,322,10.031152647975077,-0.1294856444370169
2024-10-21T12:13:25.495708682Z,2024-10-21T12:13:25.495542627Z,10,2,38,C,B,1,233.72,26,130,166055,12383140,233.79,234.0,200,154,1,7,233.7,234.07,1200,400,1,1,233.66,234.13,1,430,1,2,233.58,234.17,505,1,2,1,233.53,234.41,10,600,1,2,233.5,234.43,100,105,1,2,233.45,234.5,15,63,1,4,233.4,234.75,110,1,2,1,233.39,234.79,10,2000,1,1,233.31,234.89,110,2,2,2,AAPL,212,6.185676392572944,-0.0798468852064407
2024-10-21T12:13:25.495754875Z,2024-10-21T12:13:25.495588580Z,10,2,38,A,B,1,233.73,27,130,166295,12383141,233.79,234.0,200,154,1,7,233.73,234.07,27,400,1,1,233.7,234.13,1200,430,1,2,233.66,234.17,1,1,1,1,233.58,234.41,505,600,2,2,233.53,234.43,10,105,1,2,233.5,234.5,100,63,1,4,233.45,234.75,15,1,1,1,233.4,234.79,110,2000,2,1,233.39,234.89,10,2,1,2,AAPL,222,6.955613577023499,-0.0897855050244461
2024-10-21T12:13:29.150506254Z,2024-10-21T12:13:29.150340169Z,10,2,38,A,A,3,234.15,30,130,166085,12386039,233.79,234.0,200,154,1,7,233.73,234.07,27,400,1,1,233.7,234.13,1200,430,1,2,233.66,234.15,1,30,1,1,233.58,234.17,505,1,2,1,233.53,234.41,10,600,1,2,233.5,234.43,100,105,1,2,233.45,234.5,15,63,1,4,233.4,234.75,110,1,2,1,233.39,234.79,10,2000,1,1,AAPL,-1778,-16.652737752161382,0.214959392519516
2024-10-21T12:13:29.268802068Z,2024-10-21T12:13:29.268636112Z,10,2,38,C,A,2,234.13,30,130,165956,12386279,233.79,234.0,200,154,1,7,233.73,234.07,27,400,1,1,233.7,234.13,1200,400,1,1,233.66,234.15,1,30,1,1,233.58,234.17,505,1,2,1,233.53,234.41,10,600,1,2,233.5,234.43,100,105,1,2,233.45,234.5,15,63,1,4,233.4,234.75,110,1,2,1,233.39,234.79,10,2000,1,1,AAPL,-1778,-10.402005850396993,0.134272747932728
2024-10-21T12:13:32.213848825Z,2024-10-21T12:13:32.213682828Z,10,2,38,C,A,1,234.07,400,130,165997,12388761,233.79,234.0,200,154,1,7,233.73,234.13,27,400,1,1,233.7,234.15,1200,30,1,1,233.66,234.17,1,1,1,1,233.58,234.41,505,600,2,2,233.53,234.43,10,105,1,2,233.5,234.5,100,63,1,4,233.45,234.75,15,1,1,1,233.4,234.79,110,2000,2,1,233.39,234.89,10,2,1,2,AAPL,-1987,-10.478576137112723,0.13526114410892567
2024-10-21T12:13:32.213862106Z,2024-10-21T12:13:32.213695191Z,10,2,38,A,A,1,234.09,400,130,166915,12388762,233.79,234.0,200,154,1,7,233.73,234.09,27,400,1,1,233.7,234.13,1200,400,1,1,233.66,234.15,1,30,1,1,233.58,234.17,505,1,2,1,233.53,234.41,10,600,1,2,233.5,234.43,100,105,1,2,233.45,234.5,15,63,1,4,233.4,234.75,110,1,2,1,233.39,234.79,10,2000,1,1,AAPL,-3987,-15.799725651577504,0.2039484124823442
2024-10-21T12:13:32.278971542Z,2024-10-21T12:13:32.278804796Z,10,2,38,A,B,0,233.8,200,130,166746,12388939,233.8,234.0,200,154,1,7,233.73,234.09,27,400,1,1,233.7,234.13,1200,400,1,1,233.66,234.15,1,30,1,1,233.58,234.17,505,1,2,1,233.53,234.41,10,600,1,2,233.5,234.43,100,105,1,2,233.45,234.5,15,63,1,4,233.4,234.75,110,1,2,1,233.39,234.79,10,2000,1,1,AAPL,-3987,-13.024851242562129,0.16812935821287564
2024-10-21T12:13:32.362493854Z,2024-10-21T12:13:32.362327800Z,10,2,38,C,A,3,234.15,30,130,166054,12389254,233.8,234.0,200,154,1,7,233.73,234.09,27,400,1,1,233.7,234.13,1200,400,1,1,233.66,234.17,1,1,1,1,233.58,234.41,505,600,2,2,233.53,234.43,10,105,1,2,233.5,234.5,100,63,1,4,233.45,234.75,15,1,1,1,233.4,234.79,110,2000,2,1,233.39,234.89,10,2,1,2,AAPL,-3985,-13.928696260048932,0.17979650740974193
2024-10-21T12:13:32.402038108Z,2024-10-21T12:13:32.401872088Z,10,2,38,C,B,1,233.73,27,130,166020,12389357,233.8,234.0,200,154,1,7,233.7,234.09,1200,400,1,1,233.66,234.13,1,400,1,1,233.58,234.17,505,1,2,1,233.53,234.41,10,600,1,2,233.5,234.43,100,105,1,2,233.45,234.5,15,63,1,4,233.4,234.75,110,1,2,1,233.39,234.79,10,2000,1,1,233.31,234.89,110,2,2,2,AAPL,-4095,-15.070730304772859,0.19453828429616402
2024-10-21T12:13:32.412797711Z,2024-10-21T12:13:32.412631196Z,10,2,38,A,A,2,234.11,27,130,166515,12389377,233.8,234.0,200,154,1,7,233.7,234.09,1200,400,1,1,233.66,234.11,1,27,1,1,233.58,234.13,505,400,2,1,233.53,234.17,10,1,1,1,233.5,234.41,100,600,1,2,233.45,234.43,15,105,1,2,233.4,234.5,110,63,2,4,233.39,234.75,10,1,1,1,233.31,234.79,110,2000,2,1,AAPL,-6095,-19.179083757519667,0.24757035479419892
2024-10-21T12:13:34.144890619Z,2024-10-21T12:13:34.144724456Z,10,2,38,A,B,0,233.89,100,130,166163,12390756,233.89,234.0,100,154,1,7,233.8,234.09,200,400,1,1,233.7,234.11,1200,27,1,1,233.66,234.13,1,400,1,1,233.58,234.17,505,1,2,1,233.53,234.41,10,600,1,2,233.5,234.43,100,105,1,2,233.45,234.5,15,63,1,4,233.4,234.75,110,1,2,1,233.39,234.79,10,2000,1,1,AAPL,-6085,-17.09403043308623,0.2206557535639696
2024-10-21T12:13:34.145338999Z,2024-10-21T12:13:34.145172866Z,10,2,38,C,B,0,233.89,100,130,166133,12390759,233.8,234.0,200,154,1,7,233.7,234.09,1200,400,1,1,233.66,234.11,1,27,1,1,233.58,234.13,505,400,2,1,233.53,234.17,10,1,1,1,233.5,234.41,100,600,1,2,233.45,234.43,15,105,1,2,233.4,234.5,110,63,2,4,233.39,234.75,10,1,1,1,233.31,234.79,110,2000,2,1,AAPL,-6195,-15.772864321608042,0.2036016769930549
2024-10-21T12:13:34.215444342Z,2024-10-21T12:13:34.215278319Z,10,2,38,C,A,2,234.11,27,130,166023,12390798,233.8,234.0,200,154,1,7,233.7,234.09,1200,400,1,1,233.66,234.13,1,400,1,1,233.58,234.17,505,1,2,1,233.53,234.41,10,600,1,2,233.5,234.43,100,105,1,2,233.45,234.5,15,63,1,4,233.4,234.75,110,1,2,1,233.39,234.79,10,2000,1,1,233.31,234.89,110,2,2,2,AAPL,-6193,-16.474030724213605,0.21265257938534313
2024-10-21T12:13:34.277590859Z,2024-10-21T12:13:34.277424242Z,10,2,38,A,A,1,234.06,200,130,166617,12390835,233.8,234.0,200,154,1,7,233.7,234.06,1200,200,1,1,233.66,234.13,1,400,1,1,233.58,234.17,505,1,2,1,233.53,234.41,10,600,1,2,233.5,234.43,100,105,1,2,233.45,234.5,15,63,1,4,233.4,234.75,110,1,2,1,233.39,234.79,10,2000,1,1,233.31,234.89,110,2,2,2,AAPL,-6193,-17.16984619446828,0.22163441006193643
2024-10-21T12:13:35.061243869Z,2024-10-21T12:13:35.061077358Z,10,2,38,A,B,0,233.81,200,130,166511,12391575,233.81,234.0,200,154,1,7,233.7,234.06,1200,200,1,1,233.66,234.13,1,400,1,1,233.58,234.17,505,1,2,1,233.53,234.41,10,600,1,2,233.5,234.43,100,105,1,2,233.45,234.5,15,63,1,4,233.4,234.75,110,1,2,1,233.39,234.79,10,2000,1,1,233.31,234.89,110,2,2,2,AAPL,-6193,-17.855448528929955,0.2304844059916877
2024-10-21T12:13:35.075339842Z,2024-10-21T12:13:35.075174042Z,10,2,38,C,B,0,233.81,200,130,165800,12391728,233.7,234.0,1200,154,1,7,233.66,234.06,1,200,1,1,233.58,234.13,505,400,2,1,233.53,234.17,10,1,1,1,233.5,234.41,100,600,1,2,233.45,234.43,15,105,1,2,233.4,234.5,110,63,2,4,233.39,234.75,10,1,1,1,233.31,234.79,110,2000,2,1,233.3,234.89,100,2,1,2,AAPL,-6293,-18.842543774002475,0.24322617838957175
2024-10-21T12:13:35.075350085Z,2024-10-21T12:13:35.075183720Z,10,2,38,A,B,0,233.74,200,130,166365,12391729,233.74,234.0,200,154,1,7,233.7,234.06,1200,200,1,1,233.66,234.13,1,400,1,1,233.58,234.17,505,1,2,1,233.53,234.41,10,600,1,2,233.5,234.43,100,105,1,2,233.45,234.5,15,63,1,4,233.4,234.75,110,1,2,1,233.39,234.79,10,2000,1,1,233.31,234.89,110,2,2,2,AAPL,-6183,-19.178287560581584,0.24756007720425044
2024-10-21T12:13:35.077639622Z,2024-10-21T12:13:35.077473825Z,10,2,38,C,A,1,234.06,200,130,165797,12391777,233.74,234.0,200,154,1,7,233.7,234.13,1200,400,1,1,233.66,234.17,1,1,1,1,233.58,234.41,505,600,2,2,233.53,234.43,10,105,1,2,233.5,234.5,100,63,1,4,233.45,234.75,15,1,1,1,233.4,234.79,110,2000,2,1,233.39,234.89,10,2,1,2,233.31,235.0,110,213,2,6,AAPL,-5970,-18.894796809722752,0.24390067894214745
2024-10-21T12:13:35.077651330Z,2024-10-21T12:13:35.077485044Z,10,2,38,A,A,1,234.08,200,130,166286,12391778,233.74,234.0,200,154,1,7,233.7,234.08,1200,200,1,1,233.66,234.13,1,400,1,1,233.58,234.17,505,1,2,1,233.53,234.41,10,600,1,2,233.5,234.43,100,105,1,2,233.45,234.5,15,63,1,4,233.4,234.75,110,1,2,1,233.39,234.79,10,2000,1,1,233.31,234.89,110,2,2,2,AAPL,-5972,-19.51879321181647,0.251955443841752
2024-10-21T12:13:35.086732850Z,2024-10-21T12:13:35.086566953Z,10,2,38,C,B,0,233.74,200,130,165897,12391883,233.7,234.0,1200,154,1,7,233.66,234.08,1,200,1,1,233.58,234.13,505,400,2,1,233.53,234.17,10,1,1,1,233.5,234.41,100,600,1,2,233.45,234.43,15,105,1,2,233.4,234.5,110,63,2,4,233.39,234.75,10,1,1,1,233.31,234.79,110,2000,2,1,233.3,234.89,100,2,1,2,AAPL,-6072,-20.477641768673493,0.26433259805913883
2024-10-21T12:13:35.086745457Z,2024-10-21T12:13:35.086579076Z,10,2,38,A,B,0,233.72,400,130,166381,12391884,233.72,234.0,400,154,1,7,233.7,234.08,1200,200,1,1,233.66,234.13,1,400,1,1,233.58,234.17,505,1,2,1,233.53,234.41,10,600,1,2,233.5,234.43,100,105,1,2,233.45,234.5,15,63,1,4,233.4,234.75,110,1,2,1,233.39,234.79,10,2000,1,1,233.31,234.89,110,2,2,2,AAPL,-5962,-20.706524435623912,0.2672870959788291
2024-10-21T12:13:35.108265805Z,2024-10-21T12:13:35.108095991Z,10,2,38,T,N,0,233.94,50,0,169814,12392002,233.72,234.0,400,154,1,7,233.7,234.08,1200,200,1,1,233.66,234.13,1,400,1,1,233.58,234.17,505,1,2,1,233.53,234.41,10,600,1,2,233.5,234.43,100,105,1,2,233.45,234.5,15,63,1,4,233.4,234.75,110,1,2,1,233.39,234.79,10,2000,1,1,233.31,234.89,110,2,2,2,AAPL,-5962,-21.29810298102981,0.27492339978908553
2024-10-21T12:13:35.108265805Z,2024-10-21T12:13:35.108095991Z,10,2,38,T,N,0,233.93,50,0,169814,12392003,233.72,234.0,400,154,1,7,233.7,234.08,1200,200,1,1,233.66,234.13,1,400,1,1,233.58,234.17,505,1,2,1,233.53,234.41,10,600,1,2,233.5,234.43,100,105,1,2,233.45,234.5,15,63,1,4,233.4,234.75,110,1,2,1,233.39,234.79,10,2000,1,1,233.31,234.89,110,2,2,2,AAPL,-5962,-21.88157572791779,0.28245507110279816
2024-10-21T12:13:35.108265805Z,2024-10-21T12:13:35.108095991Z,10,2,38,T,N,0,233.9,250,130,169814,12392004,233.72,234.0,400,154,1,7,233.7,234.08,1200,200,1,1,233.66,234.13,1,400,1,1,233.58,234.17,505,1,2,1,233.53,234.41,10,600,1,2,233.5,234.43,100,105,1,2,233.45,234.5,15,63,1,4,233.4,234.75,110,1,2,1,233.39,234.79,10,2000,1,1,233.31,234.89,110,2,2,2,AAPL,-5962,-22.45710814094775,0.2898842457959596
2024-10-21T12:13:35.146538430Z,2024-10-21T12:13:35.146372690Z,10,2,38,C,B,0,233.72,400,130,165740,12392297,233.7,234.0,1200,154,1,7,233.66,234.08,1,200,1,1,233.58,234.13,505,400,2,1,233.53,234.17,10,1,1,1,233.5,234.41,100,600,1,2,233.45,234.43,15,105,1,2,233.4,234.5,110,63,2,4,233.39,234.75,10,1,1,1,233.31,234.79,110,2000,2,1,233.3,234.89,100,2,1,2,AAPL,-6062,-23.425190194420964,0.3023805892333405
2024-10-21T12:13:35.146551508Z,2024-10-21T12:13:35.146384339Z,10,2,38,A,B,0,233.7,200,128,167169,12392298,233.7,234.0,1400,154,2,7,233.66,234.08,1,200,1,1,233.58,234.13,505,400,2,1,233.53,234.17,10,1,1,1,233.5,234.41,100,600,1,2,233.45,234.43,15,105,1,2,233.4,234.5,110,63,2,4,233.39,234.75,10,1,1,1,233.31,234.79,110,2000,2,1,233.3,234.89,100,2,1,2,AAPL,-6062,-24.009361497839652,0.3099212777603016
2024-10-21T12:13:35.168035257Z,2024-10-21T12:13:35.167869345Z,10,2,38,C,B,0,233.7,200,130,165912,12392426,233.7,234.0,1200,154,1,7,233.66,234.08,1,200,1,1,233.58,234.13,505,400,2,1,233.53,234.17,10,1,1,1,233.5,234.41,100,600,1,2,233.45,234.43,15,105,1,2,233.4,234.5,110,63,2,4,233.39,234.75,10,1,1,1,233.31,234.79,110,2000,2,1,233.3,234.89,100,2,1,2,AAPL,-6062,-24.586424907550995,0.317370215096788
2024-10-21T12:13:35.175958206Z,2024-10-21T12:13:35.175791647Z,10,2,38,A,B,2,233.64,200,130,166559,12392448,233.7,234.0,1200,154,1,7,233.66,234.08,1,200,1,1,233.64,234.13,200,400,1,1,233.58,234.17,505,1,2,1,233.53,234.41,10,600,1,2,233.5,234.43,100,105,1,2,233.45,234.5,15,63,1,4,233.4,234.75,110,1,2,1,233.39,234.79,10,2000,1,1,233.31,234.89,110,2,2,2,AAPL,-5952,-24.68538926413082,0.31864768179854536
2024-10-21T12:13:35.334095780Z,2024-10-21T12:13:35.333929432Z,10,2,38,A,B,2,233.65,200,130,166348,12392747,233.7,234.0,1200,154,1,7,233.66,234.08,1,200,1,1,233.65,234.13,200,400,1,1,233.58,234.17,505,1,2,1,233.53,234.41,10,600,1,2,233.5,234.43,100,105,1,2,233.45,234.5,15,63,1,4,233.4,234.75,110,1,2,1,233.39,234.79,10,2000,1,1,233.31,234.89,110,2,2,2,AAPL,-5952,-25.223307828134196,0.3255913237068032
2024-10-21T12:13:35.352463215Z,2024-10-21T12:13:35.352296693Z,10,2,38,A,B,0,233.7,200,130,166522,12392766,233.7,234.0,1400,154,2,7,233.66,234.08,1,200,1,1,233.58,234.13,505,400,2,1,233.53,234.17,10,1,1,1,233.5,234.41,100,600,1,2,233.45,234.43,15,105,1,2,233.4,234.5,110,63,2,4,233.39,234.75,10,1,1,1,233.31,234.79,110,2000,2,1,233.3,234.89,100,2,1,2,AAPL,-6052,-26.20219985958343,0.338227206139721
2024-10-21T12:13:35.424517936Z,2024-10-21T12:13:35.424351548Z,10,2,38,A,B,0,233.72,200,130,166388,12392793,233.72,234.0,200,154,1,7,233.7,234.08,1200,200,1,1,233.66,234.13,1,400,1,1,233.58,234.17,505,1,2,1,233.53,234.41,10,600,1,2,233.5,234.43,100,105,1,2,233.45,234.5,15,63,1,4,233.4,234.75,110,1,2,1,233.39,234.79,10,2000,1,1,233.31,234.89,110,2,2,2,AAPL,-5942,-26.24924436177633,0.33883447311067033
2024-10-21T12:13:38.132138622Z,2024-10-21T12:13:38.131971887Z,10,2,38,A,B,0,233.77,200,130,166735,12394618,233.77,234.0,200,154,1,7,233.7,234.08,1200,200,1,1,233.66,234.13,1,400,1,1,233.58,234.17,505,1,2,1,233.53,234.41,10,600,1,2,233.5,234.43,100,105,1,2,233.45,234.5,15,63,1,4,233.4,234.75,110,1,2,1,233.39,234.79,10,2000,1,1,233.31,234.89,110,2,2,2,AAPL,-5942,-26.765765765765767,0.34550191295613875
2024-10-21T12:13:42.509253965Z,2024-10-21T12:13:42.509087486Z,10,2,38,A,B,1,233.76,29,130,166479,12397192,233.77,234.0,200,154,1,7,233.76,234.08,29,200,1,1,233.7,234.13,1200,400,1,1,233.66,234.17,1,1,1,1,233.58,234.41,505,600,2,2,233.53,234.43,10,105,1,2,233.5,234.5,100,63,1,4,233.45,234.75,15,1,1,1,233.4,234.79,110,2000,2,1,233.39,234.89,10,2,1,2,AAPL,-6043,-24.946039983487648,0.3220122529055062
2024-10-21T12:13:42.509287026Z,2024-10-21T12:13:42.509120725Z,10,2,38,A,A,2,234.13,29,130,166301,12397193,233.77,234.0,200,154,1,7,233.76,234.08,29,200,1,1,233.7,234.13,1200,429,1,2,233.66,234.17,1,1,1,1,233.58,234.41,505,600,2,2,233.53,234.43,10,105,1,2,233.5,234.5,100,63,1,4,233.45,234.75,15,1,1,1,233.4,234.79,110,2000,2,1,233.39,234.89,10,2,1,2,AAPL,-6043,-25.640638811951206,0.3309783787421972
2024-10-21T12:13:45.327521347Z,2024-10-21T12:13:45.327353906Z,10,2,38,A,A,1,234.07,200,130,167441,12399281,233.77,234.0,200,154,1,7,233.76,234.07,29,200,1,1,233.7,234.13,1200,429,1,2,233.66,234.17,1,1,1,1,233.58,234.41,505,600,2,2,233.53,234.43,10,105,1,2,233.5,234.5,100,63,1,4,233.45,234.75,15,1,1,1,233.4,234.79,110,2000,2,1,233.39,234.89,10,2,1,2,AAPL,-6043,-25.640638811951206,0.3309783787421972
2024-10-21T12:13:45.348446565Z,2024-10-21T12:13:45.348280342Z,10,2,38,C,A,2,234.13,29,130,166223,12399379,233.77,234.0,200,154,1,7,233.76,234.07,29,200,1,1,233.7,234.13,1200,400,1,1,233.66,234.17,1,1,1,1,233.58,234.41,505,600,2,2,233.53,234.43,10,105,1,2,233.5,234.5,100,63,1,4,233.45,234.75,15,1,1,1,233.4,234.79,110,2000,2,1,233.39,234.89,10,2,1,2,AAPL,-6043,-26.3342559331017,0.33993183235581065
2024-10-21T12:13:45.348489295Z,2024-10-21T12:13:45.348322946Z,10,2,38,A,A,2,234.12,26,130,166349,12399380,233.77,234.0,200,154,1,7,233.76,234.07,29,200,1,1,233.7,234.12,1200,26,1,1,233.66,234.13,1,400,1,1,233.58,234.17,505,1,2,1,233.53,234.41,10,600,1,2,233.5,234.43,100,105,1,2,233.45,234.5,15,63,1,4,233.4,234.75,110,1,2,1,233.39,234.79,10,2000,1,1,AAPL,-8043,-32.18724659049023,0.41548429314991303
2024-10-21T12:13:45.469223815Z,2024-10-21T12:13:45.469056600Z,10,2,38,T,N,0,233.98,18,130,167215,12399561,233.77,234.0,200,154,1,7,233.76,234.07,29,200,1,1,233.7,234.12,1200,26,1,1,233.66,234.13,1,400,1,1,233.58,234.17,505,1,2,1,233.53,234.41,10,600,1,2,233.5,234.43,100,105,1,2,233.45,234.5,15,63,1,4,233.4,234.75,110,1,2,1,233.39,234.79,10,2000,1,1,AAPL,-8043,-29.12325503835342,0.375933213169279
2024-10-21T12:13:45.811636426Z,2024-10-21T12:13:45.811467280Z,10,2,38,T,N,0,233.98,77,0,169146,12400065,233.77,234.0,200,154,1,7,233.76,234.07,29,200,1,1,233.7,234.12,1200,26,1,1,233.66,234.13,1,400,1,1,233.58,234.17,505,1,2,1,233.53,234.41,10,600,1,2,233.5,234.43,100,105,1,2,233.45,234.5,15,63,1,4,233.4,234.75,110,1,2,1,233.39,234.79,10,2000,1,1,AAPL,-7943,-25.695387978142076,0.3316851002243038
2024-10-21T12:13:45.811636426Z,2024-10-21T12:13:45.811467280Z,10,2,38,T,B,0,234.0,20,0,169146,12400066,233.77,234.0,200,154,1,7,233.76,234.07,29,200,1,1,233.7,234.12,1200,26,1,1,233.66,234.13,1,400,1,1,233.58,234.17,505,1,2,1,233.53,234.41,10,600,1,2,233.5,234.43,100,105,1,2,233.45,234.5,15,63,1,4,233.4,234.75,110,1,2,1,233.39,234.79,10,2000,1,1,AAPL,-7943,-24.25830821780189,0.3131347695289967
2024-10-21T12:13:45.811636426Z,2024-10-21T12:13:45.811467280Z,10,2,38,T,B,0,234.0,3,130,169146,12400067,233.77,234.0,200,134,1,6,233.76,234.07,29,200,1,1,233.7,234.12,1200,26,1,1,233.66,234.13,1,400,1,1,233.58,234.17,505,1,2,1,233.53,234.41,10,600,1,2,233.5,234.43,100,105,1,2,233.45,234.5,15,63,1,4,233.4,234.75,110,1,2,1,233.39,234.79,10,2000,1,1,AAPL,-7943,-23.03602900167317,0.2973571597630495
2024-10-21T12:13:45.811636426Z,2024-10-21T12:13:45.811467280Z,10,2,38,C,A,0,234.0,3,130,169146,12400067,233.77,234.0,200,131,1,6,233.76,234.07,29,200,1,1,233.7,234.12,1200,26,1,1,233.66,234.13,1,400,1,1,233.58,234.17,505,1,2,1,233.53,234.41,10,600,1,2,233.5,234.43,100,105,1,2,233.45,234.5,15,63,1,4,233.4,234.75,110,1,2,1,233.39,234.79,10,2000,1,1,AAPL,-7943,-21.983739837398375,0.28377384133974576
2024-10-21T12:13:45.811643125Z,2024-10-21T12:13:45.811476289Z,10,2,38,C,A,1,234.07,200,130,166836,12400068,233.77,234.0,200,131,1,6,233.76,234.12,29,26,1,1,233.7,234.13,1200,400,1,1,233.66,234.17,1,1,1,1,233.58,234.41,505,600,2,2,233.53,234.43,10,105,1,2,233.5,234.5,100,63,1,4,233.45,234.75,15,1,1,1,233.4,234.79,110,2000,2,1,233.39,234.89,10,2,1,2,AAPL,-7941,-22.51831102811495,0.2906742741769803
2024-10-21T12:13:45.811657243Z,2024-10-21T12:13:45.811491355Z,10,2,38,A,B,0,233.9,100,130,165888,12400070,233.9,234.0,100,131,1,6,233.77,234.12,200,26,1,1,233.76,234.13,29,400,1,1,233.7,234.17,1200,1,1,1,233.66,234.41,1,600,1,2,233.58,234.43,505,105,2,2,233.53,234.5,10,63,1,4,233.5,234.75,100,1,1,1,233.45,234.79,15,2000,1,1,233.4,234.89,110,2,2,2,AAPL,-7831,-22.66023631540873,0.2925062956736179
2024-10-21T12:13:45.811666921Z,2024-10-21T12:13:45.811500957Z,10,2,38,A,B,0,233.92,100,130,165964,12400071,233.92,234.0,100,131,1,6,233.9,234.12,100,26,1,1,233.77,234.13,200,400,1,1,233.76,234.17,29,1,1,1,233.7,234.41,1200,600,1,2,233.66,234.43,1,105,1,2,233.58,234.5,505,63,2,4,233.53,234.75,10,1,1,1,233.5,234.79,100,2000,1,1,233.45,234.89,15,2,1,2,AAPL,-7816,-23.141775115334298,0.2987221677690721
2024-10-21T12:13:45.811683758Z,2024-10-21T12:13:45.811510984Z,10,2,38,T,B,0,234.0,27,0,172774,12400072,233.92,234.0,100,131,1,6,233.9,234.12,100,26,1,1,233.77,234.13,200,400,1,1,233.76,234.17,29,1,1,1,233.7,234.41,1200,600,1,2,233.66,234.43,1,105,1,2,233.58,234.5,505,63,2,4,233.53,234.75,10,1,1,1,233.5,234.79,100,2000,1,1,233.45,234.89,15,2,1,2,AAPL,-7816,-23.666104669166984,0.305490397957365
2024-10-21T12:13:45.811683758Z,2024-10-21T12:13:45.811510984Z,10,2,38,T,B,0,234.0,50,0,172774,12400073,233.92,234.0,100,104,1,5,233.9,234.12,100,26,1,1,233.77,234.13,200,400,1,1,233.76,234.17,29,1,1,1,233.7,234.41,1200,600,1,2,233.66,234.43,1,105,1,2,233.58,234.5,505,63,2,4,233.53,234.75,10,1,1,1,233.5,234.79,100,2000,1,1,233.45,234.89,15,2,1,2,AAPL,-7816,-24.189821182943607,0.3122507148091241
2024-10-21T12:13:45.811683758Z,2024-10-21T12:13:45.811510984Z,10,2,38,T,B,0,234.0,2,0,172774,12400074,233.92,234.0,100,54,1,4,233.9,234.12,100,26,1,1,233.77,234.13,200,400,1,1,233.76,234.17,29,1,1,1,233.7,234.41,1200,600,1,2,233.66,234.43,1,105,1,2,233.58,234.5,505,63,2,4,233.53,234.75,10,1,1,1,233.5,234.79,100,2000,1,1,233.45,234.89,15,2,1,2,AAPL,-7816,-24.712925731175034,0.3190031321945134
2024-10-21T12:13:45.811683758Z,2024-10-21T12:13:45.811510984Z,10,2,38,T,B,0,234.0,1,0,172774,12400075,233.92,234.0,100,52,1,3,233.9,234.12,100,26,1,1,233.77,234.13,200,400,1,1,233.76,234.17,29,1,1,1,233.7,234.41,1200,600,1,2,233.66,234.43,1,105,1,2,233.58,234.5,505,63,2,4,233.53,234.75,10,1,1,1,233.5,234.79,100,2000,1,1,233.45,234.89,15,2,1,2,AAPL,-7816,-25.23541938586247,0.3257476639513013
2024-10-21T12:13:45.811683758Z,2024-10-21T12:13:45.811510984Z,10,2,38,T,B,0,234.0,50,0,172774,12400076,233.92,234.0,100,51,1,2,233.9,234.12,100,26,1,1,233.77,234.13,200,400,1,1,233.76,234.17,29,1,1,1,233.7,234.41,1200,600,1,2,233.66,234.43,1,105,1,2,233.58,234.5,505,63,2,4,233.53,234.75,10,1,1,1,233.5,234.79,100,2000,1,1,233.45,234.89,15,2,1,2,AAPL,-7816,-25.757303216504752,0.3324843238849547
2024-10-21T12:13:45.811683758Z,2024-10-21T12:13:45.811510984Z,10,2,38,T,B,0,234.0,1,130,172774,12400077,233.92,234.0,100,1,1,1,233.9,234.12,100,26,1,1,233.77,234.13,200,400,1,1,233.76,234.17,29,1,1,1,233.7,234.41,1200,600,1,2,233.66,234.43,1,105,1,2,233.58,234.5,505,63,2,4,233.53,234.75,10,1,1,1,233.5,234.79,100,2000,1,1,233.45,234.89,15,2,1,2,AAPL,-7816,-26.278578290105667,0.3392131257687335
2024-10-21T12:13:45.811683758Z,2024-10-21T12:13:45.811510984Z,10,2,38,C,A,0,234.0,1,130,172774,12400077,233.92,234.12,100,26,1,1,233.9,234.13,100,400,1,1,233.77,234.17,200,1,1,1,233.76,234.41,29,600,1,2,233.7,234.43,1200,105,1,2,233.66,234.5,1,63,1,4,233.58,234.75,505,1,2,1,233.53,234.79,10,2000,1,1,233.5,234.89,100,2,1,2,233.45,235.0,15,213,1,6,AAPL,-7603,-25.88167211328976,0.3340897213216469
2024-10-21T12:13:45.811695806Z,2024-10-21T12:13:45.811530148Z,10,2,38,C,B,1,233.9,100,130,165658,12400078,233.92,234.12,100,26,1,1,233.77,234.13,200,400,1,1,233.76,234.17,29,1,1,1,233.7,234.41,1200,600,1,2,233.66,234.43,1,105,1,2,233.58,234.5,505,63,2,4,233.53,234.75,10,1,1,1,233.5,234.79,100,2000,1,1,233.45,234.89,15,2,1,2,233.4,235.0,110,213,2,6,AAPL,-7713,-26.489982827704633,0.3419420098510067
2024-10-21T12:13:45.811710080Z,2024-10-21T12:13:45.811542984Z,10,2,38,A,B,0,233.96,100,130,167096,12400079,233.96,234.12,100,26,1,1,233.92,234.13,100,400,1,1,233.77,234.17,200,1,1,1,233.76,234.41,29,600,1,2,233.7,234.43,1200,105,1,2,233.66,234.5,1,63,1,4,233.58,234.75,505,1,2,1,233.53,234.79,10,2000,1,1,233.5,234.89,100,2,1,2,233.45,235.0,15,213,1,6,AAPL,-7698,-26.75149530524276,0.34531770483548896
2024-10-21T12:13:45.811712078Z,2024-10-21T12:13:45.811544514Z,10,2,38,A,B,0,233.96,24,130,167564,12400080,233.96,234.12,124,26,2,1,233.92,234.13,100,400,1,1,233.77,234.17,200,1,1,1,233.76,234.41,29,600,1,2,233.7,234.43,1200,105,1,2,233.66,234.5,1,63,1,4,233.58,234.75,505,1,2,1,233.53,234.79,10,2000,1,1,233.5,234.89,100,2,1,2,233.45,235.0,15,213,1,6,AAPL,-7698,-27.059791079422983,0.34929729505785423
2024-10-21T12:13:45.811715761Z,2024-10-21T12:13:45.811549682Z,10,2,38,A,B,1,233.94,100,130,166079,12400081,233.96,234.12,124,26,2,1,233.94,234.13,100,400,1,1,233.92,234.17,100,1,1,1,233.77,234.41,200,600,1,2,233.76,234.43,29,105,1,2,233.7,234.5,1200,63,1,4,233.66,234.75,1,1,1,1,233.58,234.79,505,2000,2,1,233.53,234.89,10,2,1,2,233.5,235.0,100,213,1,6,AAPL,-7598,-26.932650649862154,0.34765612170186844
2024-10-21T12:13:45.811718296Z,2024-10-21T12:13:45.811550754Z,10,2,38,A,B,0,233.96,28,130,167542,12400082,233.96,234.12,152,26,3,1,233.94,234.13,100,400,1,1,233.92,234.17,100,1,1,1,233.77,234.41,200,600,1,2,233.76,234.43,29,105,1,2,233.7,234.5,1200,63,1,4,233.66,234.75,1,1,1,1,233.58,234.79,505,2000,2,1,233.53,234.89,10,2,1,2,233.5,235.0,100,213,1,6,AAPL,-7598,-27.152464182450213,0.3504935520473121
2024-10-21T12:13:45.811721349Z,2024-10-21T12:13:45.811554820Z,10,2,38,A,B,0,233.96,100,130,166529,12400083,233.96,234.12,252,26,4,1,233.94,234.13,100,400,1,1,233.92,234.17,100,1,1,1,233.77,234.41,200,600,1,2,233.76,234.43,29,105,1,2,233.7,234.5,1200,63,1,4,233.66,234.75,1,1,1,1,233.58,234.79,505,2000,2,1,233.53,234.89,10,2,1,2,233.5,235.0,100,213,1,6,AAPL,-7598,-27.367852318775327,0.35327385782221976
2024-10-21T12:13:45.811732936Z,2024-10-21T12:13:45.811565809Z,10,2,38,A,B,0,233.96,100,128,167127,12400085,233.96,234.12,352,26,5,1,233.94,234.13,100,400,1,1,233.93,234.17,28,1,1,1,233.92,234.41,100,600,1,2,233.77,234.43,200,105,1,2,233.76,234.5,29,63,1,4,233.7,234.75,1200,1,1,1,233.66,234.79,1,2000,1,1,233.58,234.89,505,2,2,2,233.53,235.0,10,213,1,6,AAPL,-7588,-27.621802854679565,0.3565519406059888
2024-10-21T12:13:45.811742859Z,2024-10-21T12:13:45.811576962Z,10,2,38,A,B,0,233.96,100,130,165897,12400087,233.96,234.12,452,26,6,1,233.94,234.13,100,400,1,1,233.93,234.17,28,1,1,1,233.92,234.41,100,600,1,2,233.77,234.43,200,105,1,2,233.76,234.5,29,63,1,4,233.7,234.75,1200,1,1,1,233.66,234.79,1,2000,1,1,233.58,234.89,505,2,2,2,233.53,235.0,10,213,1,6,AAPL,-7588,-27.907672796448956,0.3602420503006762
2024-10-21T12:13:45.811753896Z,2024-10-21T12:13:45.811587865Z,10,2,38,A,B,0,233.96,100,130,166031,12400088,233.96,234.12,552,26,7,1,233.94,234.13,100,400,1,1,233.93,234.17,28,1,1,1,233.92,234.41,100,600,1,2,233.77,234.43,200,105,1,2,233.76,234.5,29,63,1,4,233.7,234.75,1200,1,1,1,233.66,234.79,1,2000,1,1,233.58,234.89,505,2,2,2,233.53,235.0,10,213,1,6,AAPL,-7588,-28.189528696911502,0.3638803453391966
2024-10-21T12:13:45.811765786Z,2024-10-21T12:13:45.811599315Z,10,2,38,A,B,1,233.94,100,130,166471,12400089,233.96,234.12,552,26,7,1,233.94,234.13,200,400,2,1,233.93,234.17,28,1,1,1,233.92,234.41,100,600,1,2,233.77,234.43,200,105,1,2,233.76,234.5,29,63,1,4,233.7,234.75,1200,1,1,1,233.66,234.79,1,2000,1,1,233.58,234.89,505,2,2,2,233.53,235.0,10,213,1,6,AAPL,-7588,-28.467454511348713,0.3674679094458349
2024-10-21T12:13:45.811791584Z,2024-10-21T12:13:45.811625820Z,10,2,38,C,B,0,233.96,100,130,165764,12400091,233.96,234.12,452,26,6,1,233.94,234.13,200,400,2,1,233.93,234.17,28,1,1,1,233.92,234.41,100,600,1,2,233.77,234.43,200,105,1,2,233.76,234.5,29,63,1,4,233.7,234.75,1200,1,1,1,233.66,234.79,1,2000,1,1,233.58,234.89,505,2,2,2,233.53,235.0,10,213,1,6,AAPL,-7588,-28.741531869974228,0.3710057963320826
2024-10-21T12:13:45.811800458Z,2024-10-21T12:13:45.811631245Z,10,2,38,T,N,0,234.0,145,130,169213,12400092,233.96,234.12,452,26,6,1,233.94,234.13,200,400,2,1,233.93,234.17,28,1,1,1,233.92,234.41,100,600,1,2,233.77,234.43,200,105,1,2,233.76,234.5,29,63,1,4,233.7,234.75,1200,1,1,1,233.66,234.79,1,2000,1,1,233.58,234.89,505,2,2,2,233.53,235.0,10,213,1,6,AAPL,-7588,-29.01184015786877,0.37449503072846646
2024-10-21T12:13:45.811805292Z,2024-10-21T12:13:45.811639570Z,10,2,38,C,B,1,233.94,100,130,165722,12400093,233.96,234.12,452,26,6,1,233.94,234.13,100,400,1,1,233.93,234.17,28,1,1,1,233.92,234.41,100,600,1,2,233.77,234.43,200,105,1,2,233.76,234.5,29,63,1,4,233.7,234.75,1200,1,1,1,233.66,234.79,1,2000,1,1,233.58,234.89,505,2,2,2,233.53,235.0,10,213,1,6,AAPL,-7588,-29.27845659163987,0.3779366093740989
2024-10-21T12:13:45.811808010Z,2024-10-21T12:13:45.811642361Z,10,2,38,C,B,0,233.96,100,130,165649,12400094,233.96,234.12,352,26,5,1,233.94,234.13,100,400,1,1,233.93,234.17,28,1,1,1,233.92,234.41,100,600,1,2,233.77,234.43,200,105,1,2,233.76,234.5,29,63,1,4,233.7,234.75,1200,1,1,1,233.66,234.79,1,2000,1,1,233.58,234.89,505,2,2,2,233.53,235.0,10,213,1,6,AAPL,-7588,-29.541456292961858,0.3813315019659582
2024-10-21T12:13:45.811822560Z,2024-10-21T12:13:45.811656818Z,10,2,38,C,B,0,233.96,100,130,165742,12400095,233.96,234.12,252,26,4,1,233.94,234.13,100,400,1,1,233.93,234.17,28,1,1,1,233.92,234.41,100,600,1,2,233.77,234.43,200,105,1,2,233.76,234.5,29,63,1,4,233.7,234.75,1200,1,1,1,233.66,234.79,1,2000,1,1,233.58,234.89,505,2,2,2,233.53,235.0,10,213,1,6,AAPL,-7588,-29.80091235914323,0.38468065206979696
2024-10-21T12:13:45.811837891Z,2024-10-21T12:13:45.811672313Z,10,2,38,C,B,0,233.96,100,130,165578,12400096,233.96,234.12,152,26,3,1,233.94,234.13,100,400,1,1,233.93,234.17,28,1,1,1,233.92,234.41,100,600,1,2,233.77,234.43,200,105,1,2,233.76,234.5,29,63,1,4,233.7,234.75,1200,1,1,1,233.66,234.79,1,2000,1,1,233.58,234.89,505,2,2,2,233.53,235.0,10,213,1,6,AAPL,-7588,-30.05689593086064,0.3879849779944761
2024-10-21T12:13:45.811853381Z,2024-10-21T12:13:45.811687403Z,10,2,38,C,B,0,233.96,100,130,165978,12400097,233.96,234.12,52,26,2,1,233.94,234.13,100,400,1,1,233.93,234.17,28,1,1,1,233.92,234.41,100,600,1,2,233.77,234.43,200,105,1,2,233.76,234.5,29,63,1,4,233.7,234.75,1200,1,1,1,233.66,234.79,1,2000,1,1,233.58,234.89,505,2,2,2,233.53,235.0,10,213,1,6,AAPL,-7588,-30.309476257191406,0.3912453736314275
2024-10-21T12:13:45.811867704Z,2024-10-21T12:13:45.811702067Z,10,2,38,C,B,1,233.94,100,130,165637,12400098,233.96,234.12,52,26,2,1,233.93,234.13,28,400,1,1,233.92,234.17,100,1,1,1,233.77,234.41,200,600,1,2,233.76,234.43,29,105,1,2,233.7,234.5,1200,63,1,4,233.66,234.75,1,1,1,1,233.58,234.79,505,2000,2,1,233.53,234.89,10,2,1,2,233.5,235.0,100,213,1,6,AAPL,-7688,-30.87914943886592,0.3985989153066707
2024-10-21T12:13:45.812203001Z,2024-10-21T12:13:45.812035805Z,10,2,38,A,B,3,233.9,100,130,167196,12400100,233.96,234.12,52,26,2,1,233.93,234.13,28,400,1,1,233.92,234.17,100,1,1,1,233.9,234.41,100,600,1,2,233.77,234.43,200,105,1,2,233.76,234.5,29,63,1,4,233.7,234.75,1200,1,1,1,233.66,234.79,1,2000,1,1,233.58,234.89,505,2,2,2,233.53,235.0,10,213,1,6,AAPL,-7678,-31.0877563594754,0.4012916867654514
2024-10-21T12:13:45.812647427Z,2024-10-21T12:13:45.812481448Z,10,2,38,C,B,3,233.9,100,130,165979,12400102,233.96,234.12,52,26,2,1,233.93,234.13,28,400,1,1,233.92,234.17,100,1,1,1,233.77,234.41,200,600,1,2,233.76,234.43,29,105,1,2,233.7,234.5,1200,63,1,4,233.66,234.75,1,1,1,1,233.58,234.79,505,2000,2,1,233.53,234.89,10,2,1,2,233.5,235.0,100,213,1,6,AAPL,-7778,-31.6583323642284,0.4086568823983436
2024-10-21T12:13:45.813181508Z,2024-10-21T12:13:45.813014463Z,10,2,38,T,N,0,234.08,1,130,167045,12400103,233.96,234.12,52,26,2,1,233.93,234.13,28,400,1,1,233.92,234.17,100,1,1,1,233.77,234.41,200,600,1,2,233.76,234.43,29,105,1,2,233.7,234.5,1200,63,1,4,233.66,234.75,1,1,1,1,233.58,234.79,505,2000,2,1,233.53,234.89,10,2,1,2,233.5,235.0,100,213,1,6,AAPL,-7778,-31.82102624679478,0.4107569922231422
2024-10-21T12:13:45.813988388Z,2024-10-21T12:13:45.813822327Z,10,2,38,C,B,2,233.92,100,130,166061,12400110,233.96,234.12,52,26,2,1,233.93,234.13,28,400,1,1,233.77,234.17,200,1,1,1,233.76,234.41,29,600,1,2,233.7,234.43,1200,105,1,2,233.66,234.5,1,63,1,4,233.58,234.75,505,1,2,1,233.53,234.79,10,2000,1,1,233.5,234.89,100,2,1,2,233.45,235.0,15,213,1,6,AAPL,-7793,-32.120445373100154,0.4146219995545028
2024-10-21T12:13:45.885716957Z,2024-10-21T12:13:45.885550872Z,10,2,38,C,A,0,234.12,26,130,166085,12401368,233.96,234.13,52,400,2,1,233.93,234.17,28,1,1,1,233.77,234.41,200,600,1,2,233.76,234.43,29,105,1,2,233.7,234.5,1200,63,1,4,233.66,234.75,1,1,1,1,233.58,234.79,505,2000,2,1,233.53,234.89,10,2,1,2,233.5,235.0,100,213,1,6,233.45,235.03,15,2,1,1,AAPL,-7791,-32.542369971963154,0.420068350587615
2024-10-21T12:13:45.885769234Z,2024-10-21T12:13:45.885603142Z,10,2,38,A,A,2,234.18,27,130,166092,12401370,233.96,234.13,52,400,2,1,233.93,234.17,28,1,1,1,233.77,234.18,200,27,1,1,233.76,234.41,29,600,1,2,233.7,234.43,1200,105,1,2,233.66,234.5,1,63,1,4,233.58,234.75,505,1,2,1,233.53,234.79,10,2000,1,1,233.5,234.89,100,2,1,2,233.45,235.0,15,213,1,6,AAPL,-8004,-33.67039963617759,0.43462935400773167
2024-10-21T12:13:45.911785815Z,2024-10-21T12:13:45.911619430Z,10,2,38,C,B,0,233.96,24,130,166385,12401559,233.96,234.13,28,400,1,1,233.93,234.17,28,1,1,1,233.77,234.18,200,27,1,1,233.76,234.41,29,600,1,2,233.7,234.43,1200,105,1,2,233.66,234.5,1,63,1,4,233.58,234.75,505,1,2,1,233.53,234.79,10,2000,1,1,233.5,234.89,100,2,1,2,233.45,235.0,15,213,1,6,AAPL,-8004,-33.905676362609434,0.4376663886947882
2024-10-21T12:13:45.911812280Z,2024-10-21T12:13:45.911645974Z,10,2,38,C,B,1,233.93,28,130,166306,12401560,233.96,234.13,28,400,1,1,233.77,234.17,200,1,1,1,233.76,234.18,29,27,1,1,233.7,234.41,1200,600,1,2,233.66,234.43,1,105,1,2,233.58,234.5,505,63,2,4,233.53,234.75,10,1,1,1,233.5,234.79,100,2000,1,1,233.45,234.89,15,2,1,2,233.4,235.0,110,213,2,6,AAPL,-8114,-34.51509808860157,0.44553301855211974
2024-10-21T12:13:45.935434703Z,2024-10-21T12:13:45.935267342Z,10,2,38,A,B,1,233.78,200,128,167361,12401727,233.96,234.13,28,400,1,1,233.78,234.17,200,1,1,1,233.76,234.18,29,27,1,1,233.7,234.41,1200,600,1,2,233.66,234.43,1,105,1,2,233.58,234.5,505,63,2,4,233.53,234.75,10,1,1,1,233.5,234.79,100,2000,1,1,233.45,234.89,15,2,1,2,233.4,235.0,110,213,2,6,AAPL,-8114,-34.65597958730863,0.4473515664587771
2024-10-21T12:13:45.969762895Z,2024-10-21T12:13:45.969596688Z,10,2,38,A,A,0,234.12,200,130,166207,12401874,233.96,234.12,28,200,1,1,233.78,234.13,200,400,1,1,233.76,234.17,29,1,1,1,233.7,234.18,1200,27,1,1,233.66,234.41,1,600,1,2,233.58,234.43,505,105,2,2,233.53,234.5,10,63,1,4,233.5,234.75,100,1,1,1,233.45,234.79,15,2000,1,1,233.4,234.89,110,2,2,2,AAPL,-8116,-35.005972130059725,0.4518693932267134
2024-10-21T12:13:45.972375870Z,2024-10-21T12:13:45.972210032Z,10,2,38,C,A,0,234.12,200,130,165838,12401877,233.96,234.13,28,400,1,1,233.78,234.17,200,1,1,1,233.76,234.18,29,27,1,1,233.7,234.41,1200,600,1,2,233.66,234.43,1,105,1,2,233.58,234.5,505,63,2,4,233.53,234.75,10,1,1,1,233.5,234.79,100,2000,1,1,233.45,234.89,15,2,1,2,233.4,235.0,110,213,2,6,AAPL,-7903,-34.21868405908306,0.4417068020664076
2024-10-21T12:13:45.973746612Z,2024-10-21T12:13:45.973580511Z,10,2,38,A,A,3,234.19,200,130,166101,12401884,233.96,234.13,28,400,1,1,233.78,234.17,200,1,1,1,233.76,234.18,29,27,1,1,233.7,234.19,1200,200,1,1,233.66,234.41,1,600,1,2,233.58,234.43,505,105,2,2,233.53,234.5,10,63,1,4,233.5,234.75,100,1,1,1,233.45,234.79,15,2000,1,1,233.4,234.89,110,2,2,2,AAPL,-7905,-34.55454470945004,0.44604220939993905
2024-10-21T12:13:46.001542260Z,2024-10-21T12:13:46.001375930Z,10,2,38,A,A,3,234.19,200,130,166330,12401962,233.96,234.13,28,400,1,1,233.78,234.17,200,1,1,1,233.76,234.18,29,27,1,1,233.7,234.19,1200,400,1,2,233.66,234.41,1,600,1,2,233.58,234.43,505,105,2,2,233.53,234.5,10,63,1,4,233.5,234.75,100,1,1,1,233.45,234.79,15,2000,1,1,233.4,234.89,110,2,2,2,AAPL,-7905,-34.87974942121749,0.45024006613235174
2024-10-21T12:13:46.030544628Z,2024-10-21T12:13:46.030378750Z,10,2,38,C,A,3,234.19,200,130,165878,12402092,233.96,234.13,28,400,1,1,233.78,234.17,200,1,1,1,233.76,234.18,29,27,1,1,233.7,234.19,1200,200,1,1,233.66,234.41,1,600,1,2,233.58,234.43,505,105,2,2,233.53,234.5,10,63,1,4,233.5,234.75,100,1,1,1,233.45,234.79,15,2000,1,1,233.4,234.89,110,2,2,2,AAPL,-7905,-35.20297607733456,0.45441238942712187
2024-10-21T12:13:46.030557325Z,2024-10-21T12:13:46.030391116Z,10,2,38,A,A,0,234.12,400,130,166209,12402093,233.96,234.12,28,400,1,1,233.78,234.13,200,400,1,1,233.76,234.17,29,1,1,1,233.7,234.18,1200,27,1,1,233.66,234.41,1,600,1,2,233.58,234.43,505,105,2,2,233.53,234.5,10,63,1,4,233.5,234.75,100,1,1,1,233.45,234.79,15,2000,1,1,233.4,234.89,110,2,2,2,AAPL,-7905,-35.52424267034841,0.45855941153837243
2024-10-21T12:13:46.063401404Z,2024-10-21T12:13:46.063235483Z,10,2,38,C,B,0,233.96,28,130,165921,12402125,233.78,234.12,200,400,1,1,233.76,234.13,29,400,1,1,233.7,234.17,1200,1,1,1,233.66,234.18,1,27,1,1,233.58,234.41,505,600,2,2,233.53,234.43,10,105,1,2,233.5,234.5,100,63,1,4,233.45,234.75,15,1,1,1,233.4,234.79,110,2000,2,1,233.39,234.89,10,2,1,2,AAPL,-7915,-35.98603556060729,0.4645203964909516
2024-10-21T12:13:46.072888556Z,2024-10-21T12:13:46.072722298Z,10,2,38,C,A,0,234.12,400,130,166258,12402143,233.78,234.13,200,400,1,1,233.76,234.17,29,1,1,1,233.7,234.18,1200,27,1,1,233.66,234.41,1,600,1,2,233.58,234.43,505,105,2,2,233.53,234.5,10,63,1,4,233.5,234.75,100,1,1,1,233.45,234.79,15,2000,1,1,233.4,234.89,110,2,2,2,233.39,235.0,10,213,1,6,AAPL,-7702,-35.221929305428525,0.45465704435762017
2024-10-21T12:13:46.072911952Z,2024-10-21T12:13:46.072745549Z,10,2,38,A,A,0,234.13,200,130,166403,12402144,233.78,234.13,200,600,1,2,233.76,234.17,29,1,1,1,233.7,234.18,1200,27,1,1,233.66,234.41,1,600,1,2,233.58,234.43,505,105,2,2,233.53,234.5,10,63,1,4,233.5,234.75,100,1,1,1,233.45,234.79,15,2000,1,1,233.4,234.89,110,2,2,2,233.39,235.0,10,213,1,6,AAPL,-7702,-35.423804048453086,0.4572629145017027
2024-10-21T12:13:46.073218239Z,2024-10-21T12:13:46.073052339Z,10,2,38,C,B,1,233.76,29,130,165900,12402146,233.78,234.13,200,600,1,2,233.7,234.17,1200,1,1,1,233.66,234.18,1,27,1,1,233.58,234.41,505,600,2,2,233.53,234.43,10,105,1,2,233.5,234.5,100,63,1,4,233.45,234.75,15,1,1,1,233.4,234.79,110,2000,2,1,233.39,234.89,10,2,1,2,233.31,235.0,110,213,2,6,AAPL,-7812,-36.03626723223754,0.4651688045653223
2024-10-21T12:13:46.073303600Z,2024-10-21T12:13:46.073137112Z,10,2,38,A,B,0,233.81,27,130,166488,12402147,233.81,234.13,27,600,1,2,233.78,234.17,200,1,1,1,233.7,234.18,1200,27,1,1,233.66,234.41,1,600,1,2,233.58,234.43,505,105,2,2,233.53,234.5,10,63,1,4,233.5,234.75,100,1,1,1,233.45,234.79,15,2000,1,1,233.4,234.89,110,2,2,2,233.39,235.0,10,213,1,6,AAPL,-7802,-36.189863742982894,0.46715148231683207
2024-10-21T12:13:46.123490913Z,2024-10-21T12:13:46.123324204Z,10,2,38,A,B,0,233.83,200,130,166709,12402220,233.83,234.13,200,600,1,2,233.81,234.17,27,1,1,1,233.7,234.18,1200,27,1,1,233.66,234.41,1,600,1,2,233.58,234.43,505,105,2,2,233.53,234.5,10,63,1,4,233.5,234.75,100,1,1,1,233.45,234.79,15,2000,1,1,233.4,234.89,110,2,2,2,233.39,235.0,10,213,1,6,AAPL,-7802,-36.38725567258817,0.4696994867295418
2024-10-21T12:13:46.134519400Z,2024-10-21T12:13:46.134353286Z,10,2,38,C,B,0,233.83,200,130,166114,12402230,233.81,234.13,27,600,1,2,233.7,234.17,1200,1,1,1,233.66,234.18,1,27,1,1,233.58,234.41,505,600,2,2,233.53,234.43,10,105,1,2,233.5,234.5,100,63,1,4,233.45,234.75,15,1,1,1,233.4,234.79,110,2000,2,1,233.39,234.89,10,2,1,2,233.31,235.0,110,213,2,6,AAPL,-7912,-37.001740757099434,0.47763147619846275
2024-10-21T12:13:46.134533664Z,2024-10-21T12:13:46.134366429Z,10,2,38,A,B,1,233.78,200,130,167235,12402231,233.81,234.13,27,600,1,2,233.78,234.17,200,1,1,1,233.7,234.18,1200,27,1,1,233.66,234.41,1,600,1,2,233.58,234.43,505,105,2,2,233.53,234.5,10,63,1,4,233.5,234.75,100,1,1,1,233.45,234.79,15,2000,1,1,233.4,234.89,110,2,2,2,233.39,235.0,10,213,1,6,AAPL,-7902,-37.15034097954123,0.47954966010430167
2024-10-21T12:13:46.134975052Z,2024-10-21T12:13:46.134809159Z,10,2,38,C,B,0,233.81,27,130,165893,12402233,233.78,234.13,200,600,1,2,233.7,234.17,1200,1,1,1,233.66,234.18,1,27,1,1,233.58,234.41,505,600,2,2,233.53,234.43,10,105,1,2,233.5,234.5,100,63,1,4,233.45,234.75,15,1,1,1,233.4,234.79,110,2000,2,1,233.39,234.89,10,2,1,2,233.31,235.0,110,213,2,6,AAPL,-8012,-37.76631228384783,0.48750083422076285
2024-10-21T12:13:47.415528384Z,2024-10-21T12:13:47.415362307Z,10,2,38,A,B,1,233.76,27,130,166077,12403393,233.78,234.13,200,600,1,2,233.76,234.17,27,1,1,1,233.7,234.18,1200,27,1,1,233.66,234.41,1,600,1,2,233.58,234.43,505,105,2,2,233.53,234.5,10,63,1,4,233.5,234.75,100,1,1,1,233.45,234.79,15,2000,1,1,233.4,234.89,110,2,2,2,233.39,235.0,10,213,1,6,AAPL,-8002,-37.91257832798411,0.4893888877325457
2024-10-21T12:13:48.136535794Z,2024-10-21T12:13:48.136368928Z,10,2,38,C,A,0,234.13,200,130,166866,12404229,233.78,234.13,200,400,1,1,233.76,234.17,27,1,1,1,233.7,234.18,1200,27,1,1,233.66,234.41,1,600,1,2,233.58,234.43,505,105,2,2,233.53,234.5,10,63,1,4,233.5,234.75,100,1,1,1,233.45,234.79,15,2000,1,1,233.4,234.89,110,2,2,2,233.39,235.0,10,213,1,6,AAPL,-8002,-38.10379676299993,0.4918572025070457
2024-10-21T12:13:48.136548342Z,2024-10-21T12:13:48.136382005Z,10,2,38,A,A,1,234.16,200,130,166337,12404230,233.78,234.13,200,400,1,1,233.76,234.16,27,200,1,1,233.7,234.17,1200,1,1,1,233.66,234.18,1,27,1,1,233.58,234.41,505,600,2,2,233.53,234.43,10,105,1,2,233.5,234.5,100,63,1,4,233.45,234.75,15,1,1,1,233.4,234.79,110,2000,2,1,233.39,234.89,10,2,1,2,AAPL,-8004,-38.50707720355506,0.49706288819109984
2024-10-21T12:13:54.483454950Z,2024-10-21T12:13:54.483288659Z,10,2,38,A,A,1,234.16,200,130,166291,12409382,233.78,234.13,200,400,1,1,233.76,234.16,27,400,1,2,233.7,234.17,1200,1,1,1,233.66,234.18,1,27,1,1,233.58,234.41,505,600,2,2,233.53,234.43,10,105,1,2,233.5,234.5,100,63,1,4,233.45,234.75,15,1,1,1,233.4,234.79,110,2000,2,1,233.39,234.89,10,2,1,2,AAPL,-1800,-12.15678391959799,0.15692404007314845
2024-10-21T12:13:54.519925421Z,2024-10-21T12:13:54.519759447Z,10,2,38,C,A,1,234.16,200,130,165974,12409407,233.78,234.13,200,400,1,1,233.76,234.16,27,200,1,1,233.7,234.17,1200,1,1,1,233.66,234.18,1,27,1,1,233.58,234.41,505,600,2,2,233.53,234.43,10,105,1,2,233.5,234.5,100,63,1,4,233.45,234.75,15,1,1,1,233.4,234.79,110,2000,2,1,233.39,234.89,10,2,1,2,AAPL,-1800,-12.295576003535981,0.1587156170795152
2024-10-21T12:13:54.519938916Z,2024-10-21T12:13:54.519772638Z,10,2,38,A,A,1,234.15,200,130,166278,12409408,233.78,234.13,200,400,1,1,233.76,234.15,27,200,1,1,233.7,234.17,1200,1,1,1,233.66,234.18,1,27,1,1,233.58,234.41,505,600,2,2,233.53,234.43,10,105,1,2,233.5,234.5,100,63,1,4,233.45,234.75,15,1,1,1,233.4,234.79,110,2000,2,1,233.39,234.89,10,2,1,2,AAPL,-1800,-12.43423430659866,0.16050546719531805
2024-10-21T12:13:55.034277634Z,2024-10-21T12:13:55.034111535Z,10,2,38,C,A,3,234.18,27,130,166099,12410122,233.78,234.13,200,400,1,1,233.76,234.15,27,200,1,1,233.7,234.17,1200,1,1,1,233.66,234.41,1,600,1,2,233.58,234.43,505,105,2,2,233.53,234.5,10,63,1,4,233.5,234.75,100,1,1,1,233.45,234.79,15,2000,1,1,233.4,234.89,110,2,2,2,233.39,235.0,10,213,1,6,AAPL,-1587,-10.991879627418198,0.14188704599343058
2024-10-21T12:13:55.034369213Z,2024-10-21T12:13:55.034202690Z,10,2,38,A,A,2,234.17,28,130,166523,12410123,233.78,234.13,200,400,1,1,233.76,234.15,27,200,1,1,233.7,234.17,1200,29,1,2,233.66,234.41,1,600,1,2,233.58,234.43,505,105,2,2,233.53,234.5,10,63,1,4,233.5,234.75,100,1,1,1,233.45,234.79,15,2000,1,1,233.4,234.89,110,2,2,2,233.39,235.0,10,213,1,6,AAPL,-1587,-11.020398500690472,0.14225517763431667
2024-10-21T12:13:56.094704759Z,2024-10-21T12:13:56.094538941Z,10,2,38,C,B,0,233.78,200,130,165818,12410937,233.76,234.13,27,400,1,1,233.7,234.15,1200,200,1,1,233.66,234.17,1,29,1,2,233.58,234.41,505,600,2,2,233.53,234.43,10,105,1,2,233.5,234.5,100,63,1,4,233.45,234.75,15,1,1,1,233.4,234.79,110,2000,2,1,233.39,234.89,10,2,1,2,233.31,235.0,110,213,2,6,AAPL,-1948,-11.879557870664465,0.15334550878560677
2024-10-21T12:13:56.094717739Z,2024-10-21T12:13:56.094551306Z,10,2,38,A,B,0,233.76,200,130,166433,12410939,233.76,234.13,227,400,2,1,233.7,234.15,1200,200,1,1,233.66,234.17,1,29,1,2,233.58,234.41,505,600,2,2,233.53,234.43,10,105,1,2,233.5,234.5,100,63,1,4,233.45,234.75,15,1,1,1,233.4,234.79,110,2000,2,1,233.39,234.89,10,2,1,2,233.31,235.0,110,213,2,6,AAPL,-1948,-11.88201871657754,0.15337727424966627
2024-10-21T12:13:56.154373830Z,2024-10-21T12:13:56.154206963Z,10,2,38,A,A,1,234.15,200,130,166867,12411142,233.76,234.13,227,400,2,1,233.7,234.15,1200,400,1,2,233.66,234.17,1,29,1,2,233.58,234.41,505,600,2,2,233.53,234.43,10,105,1,2,233.5,234.5,100,63,1,4,233.45,234.75,15,1,1,1,233.4,234.79,110,2000,2,1,233.39,234.89,10,2,1,2,233.31,235.0,110,213,2,6,AAPL,-1948,-11.884414031905685,0.1534081938219008
2024-10-21T12:13:56.211883968Z,2024-10-21T12:13:56.211718188Z,10,2,38,C,A,1,234.15,200,130,165780,12411252,233.76,234.13,227,400,2,1,233.7,234.15,1200,200,1,1,233.66,234.17,1,29,1,2,233.58,234.41,505,600,2,2,233.53,234.43,10,105,1,2,233.5,234.5,100,63,1,4,233.45,234.75,15,1,1,1,233.4,234.79,110,2000,2,1,233.39,234.89,10,2,1,2,233.31,235.0,110,213,2,6,AAPL,-1948,-11.886746399804736,0.15343830084659388
2024-10-21T12:13:56.211897481Z,2024-10-21T12:13:56.211731379Z,10,2,38,A,A,1,234.14,200,130,166102,12411253,233.76,234.13,227,400,2,1,233.7,234.14,1200,200,1,1,233.66,234.17,1,29,1,2,233.58,234.41,505,600,2,2,233.53,234.43,10,105,1,2,233.5,234.5,100,63,1,4,233.45,234.75,15,1,1,1,233.4,234.79,110,2000,2,1,233.39,234.89,10,2,1,2,233.31,235.0,110,213,2,6,AAPL,-1948,-11.88901826942381,0.15346762693822324
2024-10-21T12:14:01.071130699Z,2024-10-21T12:14:01.070964390Z,10,2,38,C,A,2,234.17,28,130,166309,12416529,233.76,234.13,227,400,2,1,233.7,234.14,1200,200,1,1,233.66,234.17,1,1,1,1,233.58,234.41,505,600,2,2,233.53,234.43,10,105,1,2,233.5,234.5,100,63,1,4,233.45,234.75,15,1,1,1,233.4,234.79,110,2000,2,1,233.39,234.89,10,2,1,2,233.31,235.0,110,213,2,6,AAPL,-1948,-11.789138397834051,0.15217834244690442
2024-10-21T12:14:01.071182062Z,2024-10-21T12:14:01.071015450Z,10,2,38,A,A,2,234.16,27,130,166612,12416530,233.76,234.13,227,400,2,1,233.7,234.14,1200,200,1,1,233.66,234.16,1,27,1,1,233.58,234.17,505,1,2,1,233.53,234.41,10,600,1,2,233.5,234.43,100,105,1,2,233.45,234.5,15,63,1,4,233.4,234.75,110,1,2,1,233.39,234.79,10,2000,1,1,233.31,234.89,110,2,2,2,AAPL,-1950,-11.903440621531631,0.15365379572884136
2024-10-21T12:14:01.088302919Z,2024-10-21T12:14:01.088137086Z,10,2,38,C,B,0,233.76,27,130,165833,12416650,233.76,234.13,200,400,1,1,233.7,234.14,1200,200,1,1,233.66,234.16,1,27,1,1,233.58,234.17,505,1,2,1,233.53,234.41,10,600,1,2,233.5,234.43,100,105,1,2,233.45,234.5,15,63,1,4,233.4,234.75,110,1,2,1,233.39,234.79,10,2000,1,1,233.31,234.89,110,2,2,2,AAPL,-1950,-12.004735595895816,0.1549613468641962
2024-10-21T12:14:06.103621053Z,2024-10-21T12:14:06.103454338Z,10,2,38,A,B,0,233.97,5,130,166715,12421860,233.97,234.13,5,400,1,1,233.76,234.14,200,200,1,1,233.7,234.16,1200,27,1,1,233.66,234.17,1,1,1,1,233.58,234.41,505,600,2,2,233.53,234.43,10,105,1,2,233.5,234.5,100,63,1,4,233.45,234.75,15,1,1,1,233.4,234.79,110,2000,2,1,233.39,234.89,10,2,1,2,AAPL,-91,-0.9087018544935807,0.011729842956179687
2024-10-21T12:14:07.746906258Z,2024-10-21T12:14:07.746740079Z,10,2,38,C,B,1,233.76,200,130,166179,12423513,233.97,234.13,5,400,1,1,233.7,234.14,1200,200,1,1,233.66,234.16,1,27,1,1,233.58,234.17,505,1,2,1,233.53,234.41,10,600,1,2,233.5,234.43,100,105,1,2,233.45,234.5,15,63,1,4,233.4,234.75,110,1,2,1,233.39,234.79,10,2000,1,1,233.31,234.89,110,2,2,2,AAPL,-1,-0.011322011322011322,0.00014614850195204408
2024-10-21T12:14:07.746920572Z,2024-10-21T12:14:07.746754069Z,10,2,38,A,B,1,233.73,200,130,166503,12423514,233.97,234.13,5,400,1,1,233.73,234.14,200,200,1,1,233.7,234.16,1200,27,1,1,233.66,234.17,1,1,1,1,233.58,234.41,505,600,2,2,233.53,234.43,10,105,1,2,233.5,234.5,100,63,1,4,233.45,234.75,15,1,1,1,233.4,234.79,110,2000,2,1,233.39,234.89,10,2,1,2,AAPL,9,0.10746268656716418,-0.0013871661324874084
2024-10-21T12:14:10.801508542Z,2024-10-21T12:14:10.801342166Z,10,2,38,A,B,1,233.8,200,130,166376,12425721,233.97,234.13,5,400,1,1,233.8,234.14,200,200,1,1,233.7,234.16,1200,27,1,1,233.66,234.17,1,1,1,1,233.58,234.41,505,600,2,2,233.53,234.43,10,105,1,2,233.5,234.5,100,63,1,4,233.45,234.75,15,1,1,1,233.4,234.79,110,2000,2,1,233.39,234.89,10,2,1,2,AAPL,11,0.13395415472779368,-0.0017291273155379196
2024-10-21T12:14:17.947604712Z,2024-10-21T12:14:17.947438449Z,10,2,38,A,B,1,233.81,200,130,166263,12431541,233.97,234.13,5,400,1,1,233.81,234.14,200,200,1,1,233.7,234.16,1200,27,1,1,233.66,234.17,1,1,1,1,233.58,234.41,505,600,2,2,233.53,234.43,10,105,1,2,233.5,234.5,100,63,1,4,233.45,234.75,15,1,1,1,233.4,234.79,110,2000,2,1,233.39,234.89,10,2,1,2,AAPL,-92,-2.082036775106082,0.026875662551162614
2024-10-21T12:14:17.957549086Z,2024-10-21T12:14:17.957382887Z,10,2,38,C,B,1,233.81,200,130,166199,12431585,233.97,234.13,5,400,1,1,233.7,234.14,1200,200,1,1,233.66,234.16,1,27,1,1,233.58,234.17,505,1,2,1,233.53,234.41,10,600,1,2,233.5,234.43,100,105,1,2,233.45,234.5,15,63,1,4,233.4,234.75,110,1,2,1,233.39,234.79,10,2000,1,1,233.31,234.89,110,2,2,2,AAPL,-202,-4.43956043956044,0.05730740670660741
2024-10-21T12:14:17.957562118Z,2024-10-21T12:14:17.957395933Z,10,2,38,A,B,1,233.74,200,130,166185,12431586,233.97,234.13,5,400,1,1,233.74,234.14,200,200,1,1,233.7,234.16,1200,27,1,1,233.66,234.17,1,1,1,1,233.58,234.41,505,600,2,2,233.53,234.43,10,105,1,2,233.5,234.5,100,63,1,4,233.45,234.75,15,1,1,1,233.4,234.79,110,2000,2,1,233.39,234.89,10,2,1,2,AAPL,-192,-4.620938628158845,0.05964870012139999
2024-10-21T12:14:17.957619401Z,2024-10-21T12:14:17.957453277Z,10,2,38,C,A,1,234.14,200,130,166124,12431587,233.97,234.13,5,400,1,1,233.74,234.16,200,27,1,1,233.7,234.17,1200,1,1,1,233.66,234.41,1,600,1,2,233.58,234.43,505,105,2,2,233.53,234.5,10,63,1,4,233.5,234.75,100,1,1,1,233.45,234.79,15,2000,1,1,233.4,234.89,110,2,2,2,233.39,235.0,10,213,1,6,AAPL,21,0.43833017077798864,-0.005658119922124083
2024-10-21T12:14:17.957631871Z,2024-10-21T12:14:17.957465815Z,10,2,38,A,A,1,234.15,200,130,166056,12431588,233.97,234.13,5,400,1,1,233.74,234.15,200,200,1,1,233.7,234.16,1200,27,1,1,233.66,234.17,1,1,1,1,233.58,234.41,505,600,2,2,233.53,234.43,10,105,1,2,233.5,234.5,100,63,1,4,233.45,234.75,15,1,1,1,233.4,234.79,110,2000,2,1,233.39,234.89,10,2,1,2,AAPL,19,0.4277673545966229,-0.005521771377912667
2024-10-21T12:14:18.057051301Z,2024-10-21T12:14:18.056884935Z,10,2,38,A,B,1,233.75,200,130,166366,12431913,233.97,234.13,5,400,1,1,233.75,234.15,200,200,1,1,233.7,234.16,1200,27,1,1,233.66,234.17,1,1,1,1,233.58,234.41,505,600,2,2,233.53,234.43,10,105,1,2,233.5,234.5,100,63,1,4,233.45,234.75,15,1,1,1,233.4,234.79,110,2000,2,1,233.39,234.89,10,2,1,2,AAPL,19,0.4582560296846011,-0.005915329913042188
2024-10-21T12:14:21.022420708Z,2024-10-21T12:14:21.022254267Z,10,2,38,A,B,1,233.77,200,130,166441,12433640,233.97,234.13,5,400,1,1,233.77,234.15,200,200,1,1,233.7,234.16,1200,27,1,1,233.66,234.17,1,1,1,1,233.58,234.41,505,600,2,2,233.53,234.43,10,105,1,2,233.5,234.5,100,63,1,4,233.45,234.75,15,1,1,1,233.4,234.79,110,2000,2,1,233.39,234.89,10,2,1,2,AAPL,19,0.4880733944954128,-0.0063002229391413336
2024-10-21T12:14:21.336855528Z,2024-10-21T12:14:21.336689135Z,10,2,38,C,A,1,234.15,200,130,166393,12433903,233.97,234.13,5,400,1,1,233.77,234.16,200,27,1,1,233.7,234.17,1200,1,1,1,233.66,234.41,1,600,1,2,233.58,234.43,505,105,2,2,233.53,234.5,10,63,1,4,233.5,234.75,100,1,1,1,233.45,234.79,15,2000,1,1,233.4,234.89,110,2,2,2,233.39,235.0,10,213,1,6,AAPL,234,7.3315926892950385,-0.09463877556630805
2024-10-21T12:14:21.336867325Z,2024-10-21T12:14:21.336700928Z,10,2,38,A,A,2,234.17,200,130,166397,12433905,233.97,234.13,5,400,1,1,233.77,234.16,200,27,1,1,233.7,234.17,1200,201,1,2,233.66,234.41,1,600,1,2,233.58,234.43,505,105,2,2,233.53,234.5,10,63,1,4,233.5,234.75,100,1,1,1,233.45,234.79,15,2000,1,1,233.4,234.89,110,2,2,2,233.39,235.0,10,213,1,6,AAPL,234,6.151668351870576,-0.07940789746286615
2024-10-21T12:14:21.392793975Z,2024-10-21T12:14:21.392627701Z,10,2,38,A,B,1,233.78,200,130,166274,12433982,233.97,234.13,5,400,1,1,233.78,234.16,200,27,1,1,233.7,234.17,1200,201,1,2,233.66,234.41,1,600,1,2,233.58,234.43,505,105,2,2,233.53,234.5,10,63,1,4,233.5,234.75,100,1,1,1,233.45,234.79,15,2000,1,1,233.4,234.89,110,2,2,2,233.39,235.0,10,213,1,6,AAPL,234,5.405940594059406,-0.06978178143379316
2024-10-21T12:14:21.427147627Z,2024-10-21T12:14:21.426981432Z,10,2,38,C,A,1,234.16,27,130,166195,12434166,233.97,234.13,5,400,1,1,233.78,234.17,200,201,1,2,233.7,234.41,1200,600,1,2,233.66,234.43,1,105,1,2,233.58,234.5,505,63,2,4,233.53,234.75,10,1,1,1,233.5,234.79,100,2000,1,1,233.45,234.89,15,2,1,2,233.4,235.0,110,213,2,6,233.39,235.03,10,2,1,1,AAPL,236,5.784313725490197,-0.07466595481648593
2024-10-21T12:14:21.740752948Z,2024-10-21T12:14:21.740586460Z,10,2,38,A,B,2,233.76,29,130,166488,12434650,233.97,234.13,5,400,1,1,233.78,234.17,200,201,1,2,233.76,234.41,29,600,1,2,233.7,234.43,1200,105,1,2,233.66,234.5,1,63,1,4,233.58,234.75,505,1,2,1,233.53,234.79,10,2000,1,1,233.5,234.89,100,2,1,2,233.45,235.0,15,213,1,6,233.4,235.03,110,2,2,1,AAPL,346,8.2874251497006,-0.10697699695050933
2024-10-21T12:14:21.740783568Z,2024-10-21T12:14:21.740617322Z,10,2,38,A,A,2,234.18,28,130,166246,12434651,233.97,234.13,5,400,1,1,233.78,234.17,200,201,1,2,233.76,234.18,29,28,1,1,233.7,234.41,1200,600,1,2,233.66,234.43,1,105,1,2,233.58,234.5,505,63,2,4,233.53,234.75,10,1,1,1,233.5,234.79,100,2000,1,1,233.45,234.89,15,2,1,2,233.4,235.0,110,213,2,6,AAPL,133,2.7257383966244726,-0.035184789349695274
2024-10-21T12:14:28.747385812Z,2024-10-21T12:14:28.747219089Z,10,2,38,A,B,1,233.79,200,130,166723,12439708,233.97,234.13,5,400,1,1,233.79,234.17,200,201,1,2,233.76,234.18,29,28,1,1,233.7,234.41,1200,600,1,2,233.66,234.43,1,105,1,2,233.58,234.5,505,63,2,4,233.53,234.75,10,1,1,1,233.5,234.79,100,2000,1,1,233.45,234.89,15,2,1,2,233.4,235.0,110,213,2,6,AAPL,223,3.6240520043336946,-0.04678053716480311
2024-10-21T12:14:37.348331123Z,2024-10-21T12:14:37.348164372Z,10,2,38,C,B,1,233.79,200,130,166751,12446142,233.97,234.13,5,400,1,1,233.76,234.17,29,201,1,2,233.7,234.18,1200,28,1,1,233.66,234.41,1,600,1,2,233.58,234.43,505,105,2,2,233.53,234.5,10,63,1,4,233.5,234.75,100,1,1,1,233.45,234.79,15,2000,1,1,233.4,234.89,110,2,2,2,233.39,235.0,10,213,1,6,AAPL,213,3.1064657267865825,-0.040099351557137834
2024-10-21T12:14:37.348344285Z,2024-10-21T12:14:37.348177626Z,10,2,38,A,B,1,233.77,200,130,166659,12446143,233.97,234.13,5,400,1,1,233.77,234.17,200,201,1,2,233.76,234.18,29,28,1,1,233.7,234.41,1200,600,1,2,233.66,234.43,1,105,1,2,233.58,234.5,505,63,2,4,233.53,234.75,10,1,1,1,233.5,234.79,100,2000,1,1,233.45,234.89,15,2,1,2,233.4,235.0,110,213,2,6,AAPL,323,4.3428571428571425,-0.056059126560522886
2024-10-21T12:14:37.485597454Z,2024-10-21T12:14:37.485431160Z,10,2,38,A,B,1,233.78,200,130,166294,12446234,233.97,234.13,5,400,1,1,233.78,234.17,200,201,1,2,233.76,234.18,29,28,1,1,233.7,234.41,1200,600,1,2,233.66,234.43,1,105,1,2,233.58,234.5,505,63,2,4,233.53,234.75,10,1,1,1,233.5,234.79,100,2000,1,1,233.45,234.89,15,2,1,2,233.4,235.0,110,213,2,6,AAPL,323,4.062893081761007,-0.052445252049545796
2024-10-21T12:14:41.549332947Z,2024-10-21T12:14:41.549166803Z,10,2,38,C,B,2,233.76,29,130,166144,12448595,233.97,234.13,5,400,1,1,233.78,234.17,200,201,1,2,233.7,234.18,1200,28,1,1,233.66,234.41,1,600,1,2,233.58,234.43,505,105,2,2,233.53,234.5,10,63,1,4,233.5,234.75,100,1,1,1,233.45,234.79,15,2000,1,1,233.4,234.89,110,2,2,2,233.39,235.0,10,213,1,6,AAPL,-13,-0.09837837837837839,0.001269902689155515
2024-10-21T12:14:41.549378383Z,2024-10-21T12:14:41.549212050Z,10,2,38,A,B,1,233.81,28,130,166333,12448596,233.97,234.13,5,400,1,1,233.81,234.17,28,201,1,2,233.78,234.18,200,28,1,1,233.7,234.41,1200,600,1,2,233.66,234.43,1,105,1,2,233.58,234.5,505,63,2,4,233.53,234.75,10,1,1,1,233.5,234.79,100,2000,1,1,233.45,234.89,15,2,1,2,233.4,235.0,110,213,2,6,AAPL,97,0.7142199723884032,-0.0092194024595139
2024-10-21T12:14:41.599757577Z,2024-10-21T12:14:41.599590898Z,10,2,38,A,B,1,233.87,200,130,166679,12448666,233.97,234.13,5,400,1,1,233.87,234.17,200,201,1,2,233.81,234.18,28,28,1,1,233.7,234.41,1200,600,1,2,233.66,234.43,1,105,1,2,233.58,234.5,505,63,2,4,233.53,234.75,10,1,1,1,233.5,234.79,100,2000,1,1,233.45,234.89,15,2,1,2,233.4,235.0,110,213,2,6,AAPL,97,0.6995192307692308,-0.009029640119226431
2024-10-21T12:14:43.206124405Z,2024-10-21T12:14:43.205958056Z,10,2,38,A,A,1,234.16,200,130,166349,12449507,233.97,234.13,5,400,1,1,233.87,234.16,200,200,1,1,233.81,234.17,28,1,1,1,233.7,234.18,1200,28,1,1,233.66,234.41,1,600,1,2,233.58,234.43,505,105,2,2,233.53,234.5,10,63,1,4,233.5,234.75,100,1,1,1,233.45,234.79,15,2000,1,1,233.4,234.89,110,2,2,2,AAPL,198,1.4578923147722043,-0.018818986463750024
2024-10-21T12:14:49.824860694Z,2024-10-21T12:14:49.824694031Z,10,2,38,A,A,1,234.16,200,130,166663,12453535,233.97,234.13,5,400,1,1,233.87,234.16,200,400,1,2,233.81,234.17,28,1,1,1,233.7,234.18,1200,28,1,1,233.66,234.41,1,600,1,2,233.58,234.43,505,105,2,2,233.53,234.5,10,63,1,4,233.5,234.75,100,1,1,1,233.45,234.79,15,2000,1,1,233.4,234.89,110,2,2,2,AAPL,198,1.614678899082569,-0.020842842806181858
2024-10-21T12:14:52.414059791Z,2024-10-21T12:14:52.413893215Z,10,2,38,C,B,1,233.87,200,130,166576,12455999,233.97,234.13,5,400,1,1,233.81,234.16,28,400,1,2,233.7,234.17,1200,1,1,1,233.66,234.18,1,28,1,1,233.58,234.41,505,600,2,2,233.53,234.43,10,105,1,2,233.5,234.5,100,63,1,4,233.45,234.75,15,1,1,1,233.4,234.79,110,2000,2,1,233.39,234.89,10,2,1,2,AAPL,188,1.7142857142857142,-0.022128602589680087
2024-10-21T12:14:52.414071390Z,2024-10-21T12:14:52.413904869Z,10,2,38,A,B,1,233.85,200,130,166521,12456000,233.97,234.13,5,400,1,1,233.85,234.16,200,400,1,2,233.81,234.17,28,1,1,1,233.7,234.18,1200,28,1,1,233.66,234.41,1,600,1,2,233.58,234.43,505,105,2,2,233.53,234.5,10,63,1,4,233.5,234.75,100,1,1,1,233.45,234.79,15,2000,1,1,233.4,234.89,110,2,2,2,AAPL,298,2.857142857142857,-0.03688100431613348
2024-10-21T12:14:52.473505418Z,2024-10-21T12:14:52.473339217Z,10,2,38,C,A,1,234.16,200,130,166201,12456232,233.97,234.13,5,400,1,1,233.85,234.16,200,200,1,1,233.81,234.17,28,1,1,1,233.7,234.18,1200,28,1,1,233.66,234.41,1,600,1,2,233.58,234.43,505,105,2,2,233.53,234.5,10,63,1,4,233.5,234.75,100,1,1,1,233.45,234.79,15,2000,1,1,233.4,234.89,110,2,2,2,AAPL,298,2.9827115559599635,-0.03850188921919922
2024-10-21T12:14:52.473518693Z,2024-10-21T12:14:52.473352225Z,10,2,38,A,A,1,234.15,200,130,166468,12456234,233.97,234.13,5,400,1,1,233.85,234.15,200,200,1,1,233.81,234.17,28,1,1,1,233.7,234.18,1200,28,1,1,233.66,234.41,1,600,1,2,233.58,234.43,505,105,2,2,233.53,234.5,10,63,1,4,233.5,234.75,100,1,1,1,233.45,234.79,15,2000,1,1,233.4,234.89,110,2,2,2,AAPL,298,3.0961038961038962,-0.03996559740439192
2024-10-21T12:14:52.474565706Z,2024-10-21T12:14:52.474399706Z,10,2,38,C,A,3,234.18,28,130,166000,12456246,233.97,234.13,5,400,1,1,233.85,234.15,200,200,1,1,233.81,234.17,28,1,1,1,233.7,234.41,1200,600,1,2,233.66,234.43,1,105,1,2,233.58,234.5,505,63,2,4,233.53,234.75,10,1,1,1,233.5,234.79,100,2000,1,1,233.45,234.89,15,2,1,2,233.4,235.0,110,213,2,6,AAPL,511,5.0459551842005315,-0.06513496322463057
2024-10-21T12:14:52.474619355Z,2024-10-21T12:14:52.474453011Z,10,2,38,A,A,2,234.17,29,130,166344,12456247,233.97,234.13,5,400,1,1,233.85,234.15,200,200,1,1,233.81,234.17,28,30,1,2,233.7,234.41,1200,600,1,2,233.66,234.43,1,105,1,2,233.58,234.5,505,63,2,4,233.53,234.75,10,1,1,1,233.5,234.79,100,2000,1,1,233.45,234.89,15,2,1,2,233.4,235.0,110,213,2,6,AAPL,511,4.840324763193505,-0.062480613468989595
2024-10-21T12:14:53.024832003Z,2024-10-21T12:14:53.024665699Z,10,2,38,A,A,1,234.15,200,130,166304,12457068,233.97,234.13,5,400,1,1,233.85,234.15,200,400,1,2,233.81,234.17,28,30,1,2,233.7,234.41,1200,600,1,2,233.66,234.43,1,105,1,2,233.58,234.5,505,63,2,4,233.53,234.75,10,1,1,1,233.5,234.79,100,2000,1,1,233.45,234.89,15,2,1,2,233.4,235.0,110,213,2,6,AAPL,511,4.675205855443733,-0.06034920056670149
2024-10-21T12:14:59.069231899Z,2024-10-21T12:14:59.069065580Z,10,2,38,A,B,1,233.86,200,130,166319,12461167,233.97,234.13,5,400,1,1,233.86,234.15,200,400,1,2,233.81,234.17,28,30,1,2,233.7,234.41,1200,600,1,2,233.66,234.43,1,105,1,2,233.58,234.5,505,63,2,4,233.53,234.75,10,1,1,1,233.5,234.79,100,2000,1,1,233.45,234.89,15,2,1,2,233.4,235.0,110,213,2,6,AAPL,411,3.9099890230515917,-0.0504715127123201
2024-10-21T12:15:05.174166268Z,2024-10-21T12:15:05.174000161Z,10,2,38,C,A,1,234.15,200,130,166107,12470009,233.97,234.13,5,400,1,1,233.86,234.15,200,200,1,1,233.81,234.17,28,30,1,2,233.7,234.41,1200,600,1,2,233.66,234.43,1,105,1,2,233.58,234.5,505,63,2,4,233.53,234.75,10,1,1,1,233.5,234.79,100,2000,1,1,233.45,234.89,15,2,1,2,233.4,235.0,110,213,2,6,AAPL,313,3.016867469879518,-0.038942785762240216
2024-10-21T12:15:05.174176083Z,2024-10-21T12:15:05.174010189Z,10,2,38,C,A,1,234.15,200,130,165894,12470010,233.97,234.13,5,400,1,1,233.86,234.17,200,30,1,2,233.81,234.41,28,600,1,2,233.7,234.43,1200,105,1,2,233.66,234.5,1,63,1,4,233.58,234.75,505,1,2,1,233.53,234.79,10,2000,1,1,233.5,234.89,100,2,1,2,233.45,235.0,15,213,1,6,233.4,235.03,110,2,2,1,AAPL,315,3.168724279835391,-0.0409030068444361
2024-10-21T12:15:05.174191104Z,2024-10-21T12:15:05.174024191Z,10,2,38,A,A,1,234.16,200,130,166913,12470011,233.97,234.13,5,400,1,1,233.86,234.16,200,200,1,1,233.81,234.17,28,30,1,2,233.7,234.41,1200,600,1,2,233.66,234.43,1,105,1,2,233.58,234.5,505,63,2,4,233.53,234.75,10,1,1,1,233.5,234.79,100,2000,1,1,233.45,234.89,15,2,1,2,233.4,235.0,110,213,2,6,AAPL,102,0.9752988047808765,-0.012589499800025165
2024-10-21T12:15:08.174832295Z,2024-10-21T12:15:08.174665588Z,10,2,38,A,A,1,234.16,200,130,166707,12472897,233.97,234.13,5,400,1,1,233.86,234.16,200,400,1,2,233.81,234.17,28,30,1,2,233.7,234.41,1200,600,1,2,233.66,234.43,1,105,1,2,233.58,234.5,505,63,2,4,233.53,234.75,10,1,1,1,233.5,234.79,100,2000,1,1,233.45,234.89,15,2,1,2,233.4,235.0,110,213,2,6,AAPL,102,0.9361101306036004,-0.012083638618508682
2024-10-21T12:15:12.192782193Z,2024-10-21T12:15:12.192615974Z,10,2,38,A,A,0,234.07,100,130,166219,12475949,233.97,234.07,5,100,1,1,233.86,234.13,200,400,1,1,233.81,234.16,28,400,1,2,233.7,234.17,1200,30,1,2,233.66,234.41,1,600,1,2,233.58,234.43,505,105,2,2,233.53,234.5,10,63,1,4,233.5,234.75,100,1,1,1,233.45,234.79,15,2000,1,1,233.4,234.89,110,2,2,2,AAPL,100,0.9177550300035298,-0.011846704527949687
2024-10-21T12:15:12.193180932Z,2024-10-21T12:15:12.193015032Z,10,2,38,C,A,0,234.07,100,130,165900,12475950,233.97,234.13,5,400,1,1,233.86,234.16,200,400,1,2,233.81,234.17,28,30,1,2,233.7,234.41,1200,600,1,2,233.66,234.43,1,105,1,2,233.58,234.5,505,63,2,4,233.53,234.75,10,1,1,1,233.5,234.79,100,2000,1,1,233.45,234.89,15,2,1,2,233.4,235.0,110,213,2,6,AAPL,313,2.776932826362484,-0.035845625044140635
2024-10-21T12:15:12.197936547Z,2024-10-21T12:15:12.197769369Z,10,2,38,A,A,0,234.07,148,128,167178,12475955,233.97,234.07,5,148,1,1,233.86,234.13,200,400,1,1,233.81,234.16,28,400,1,2,233.7,234.17,1200,30,1,2,233.66,234.41,1,600,1,2,233.58,234.43,505,105,2,2,233.53,234.5,10,63,1,4,233.5,234.75,100,1,1,1,233.45,234.79,15,2000,1,1,233.4,234.89,110,2,2,2,AAPL,311,2.854957160342717,-0.03685279057354157
2024-10-21T12:15:12.197969503Z,2024-10-21T12:15:12.197802997Z,10,2,38,C,B,1,233.86,200,130,166506,12475958,233.97,234.07,5,148,1,1,233.81,234.13,28,400,1,1,233.7,234.16,1200,400,1,2,233.66,234.17,1,30,1,2,233.58,234.41,505,600,2,2,233.53,234.43,10,105,1,2,233.5,234.5,100,63,1,4,233.45,234.75,15,1,1,1,233.4,234.79,110,2000,2,1,233.39,234.89,10,2,1,2,AAPL,301,2.9365853658536585,-0.03790647614346012
2024-10-21T12:15:12.202040946Z,2024-10-21T12:15:12.201874823Z,10,2,38,C,A,0,234.07,148,130,166123,12475962,233.97,234.13,5,400,1,1,233.81,234.16,28,400,1,2,233.7,234.17,1200,30,1,2,233.66,234.41,1,600,1,2,233.58,234.43,505,105,2,2,233.53,234.5,10,63,1,4,233.5,234.75,100,1,1,1,233.45,234.79,15,2000,1,1,233.4,234.89,110,2,2,2,233.39,235.0,10,213,1,6,AAPL,514,4.988866685697973,-0.06439804481874452
2024-10-21T12:15:12.264617436Z,2024-10-21T12:15:12.264450843Z,10,2,38,A,B,2,233.75,28,130,166593,12476000,233.97,234.13,5,400,1,1,233.81,234.16,28,400,1,2,233.75,234.17,28,30,1,2,233.7,234.41,1200,600,1,2,233.66,234.43,1,105,1,2,233.58,234.5,505,63,2,4,233.53,234.75,10,1,1,1,233.5,234.79,100,2000,1,1,233.45,234.89,15,2,1,2,233.4,235.0,110,213,2,6,AAPL,624,5.871406168322007,-0.07579017468247984
2024-10-21T12:15:12.264644369Z,2024-10-21T12:15:12.264477828Z,10,2,38,C,B,1,233.81,28,130,166541,12476001,233.97,234.13,5,400,1,1,233.75,234.16,28,400,1,2,233.7,234.17,1200,30,1,2,233.66,234.41,1,600,1,2,233.58,234.43,505,105,2,2,233.53,234.5,10,63,1,4,233.5,234.75,100,1,1,1,233.45,234.79,15,2000,1,1,233.4,234.89,110,2,2,2,233.39,235.0,10,213,1,6,AAPL,614,5.762410471721412,-0.07438321991761156
2024-10-21T12:15:12.268501792Z,2024-10-21T12:15:12.268335051Z,10,2,38,A,B,4,233.63,200,130,166741,12476005,233.97,234.13,5,400,1,1,233.75,234.16,28,400,1,2,233.7,234.17,1200,30,1,2,233.66,234.41,1,600,1,2,233.63,234.43,200,105,1,2,233.58,234.5,505,63,2,4,233.53,234.75,10,1,1,1,233.5,234.79,100,2000,1,1,233.45,234.89,15,2,1,2,233.4,235.0,110,213,2,6,AAPL,724,6.623970722781336,-0.08550454248589409
2024-10-21T12:15:12.268802483Z,2024-10-21T12:15:12.268635983Z,10,2,38,C,B,1,233.75,28,130,166500,12476006,233.97,234.13,5,400,1,1,233.7,234.16,1200,400,1,2,233.66,234.17,1,30,1,2,233.63,234.41,200,600,1,2,233.58,234.43,505,105,2,2,233.53,234.5,10,63,1,4,233.5,234.75,100,1,1,1,233.45,234.79,15,2000,1,1,233.4,234.89,110,2,2,2,233.39,235.0,10,213,1,6,AAPL,714,6.526224156692057,-0.08424279545185501
2024-10-21T12:15:12.270394146Z,2024-10-21T12:15:12.270227323Z,10,2,38,C,A,2,234.17,29,130,166823,12476010,233.97,234.13,5,400,1,1,233.7,234.16,1200,400,1,2,233.66,234.17,1,1,1,1,233.63,234.41,200,600,1,2,233.58,234.43,505,105,2,2,233.53,234.5,10,63,1,4,233.5,234.75,100,1,1,1,233.45,234.79,15,2000,1,1,233.4,234.89,110,2,2,2,233.39,235.0,10,213,1,6,AAPL,714,6.52054794520548,-0.0841695249187375
2024-10-21T12:15:12.270492635Z,2024-10-21T12:15:12.270326143Z,10,2,38,A,A,0,234.12,27,130,166492,12476011,233.97,234.12,5,27,1,1,233.7,234.13,1200,400,1,1,233.66,234.16,1,400,1,2,233.63,234.17,200,1,1,1,233.58,234.41,505,600,2,2,233.53,234.43,10,105,1,2,233.5,234.5,100,63,1,4,233.45,234.75,15,1,1,1,233.4,234.79,110,2000,2,1,233.39,234.89,10,2,1,2,AAPL,712,6.780952380952381,-0.08753091691029012
2024-10-21T12:15:12.270531958Z,2024-10-21T12:15:12.270365637Z,10,2,38,A,A,2,234.15,26,130,166321,12476012,233.97,234.12,5,27,1,1,233.7,234.13,1200,400,1,1,233.66,234.15,1,26,1,1,233.63,234.16,200,400,1,2,233.58,234.17,505,1,2,1,233.53,234.41,10,600,1,2,233.5,234.43,100,105,1,2,233.45,234.5,15,63,1,4,233.4,234.75,110,1,2,1,233.39,234.79,10,2000,1,1,AAPL,-1288,-9.03859649122807,0.11667338067166999
2024-10-21T12:15:12.319033039Z,2024-10-21T12:15:12.318866641Z,10,2,38,A,B,3,233.64,200,130,166398,12476109,233.97,234.12,5,27,1,1,233.7,234.13,1200,400,1,1,233.66,234.15,1,26,1,1,233.64,234.16,200,400,1,2,233.58,234.17,505,1,2,1,233.53,234.41,10,600,1,2,233.5,234.43,100,105,1,2,233.45,234.5,15,63,1,4,233.4,234.75,110,1,2,1,233.39,234.79,10,2000,1,1,AAPL,-1288,-7.27683615819209,0.09393195901532751
2024-10-21T12:15:12.319045020Z,2024-10-21T12:15:12.318878820Z,10,2,38,C,A,3,234.16,200,130,166200,12476110,233.97,234.12,5,27,1,1,233.7,234.13,1200,400,1,1,233.66,234.15,1,26,1,1,233.64,234.16,200,200,1,1,233.58,234.17,505,1,2,1,233.53,234.41,10,600,1,2,233.5,234.43,100,105,1,2,233.45,234.5,15,63,1,4,233.4,234.75,110,1,2,1,233.39,234.79,10,2000,1,1,AAPL,-1288,-6.167219152854512,0.07960863266823892
2024-10-21T12:15:12.319057841Z,2024-10-21T12:15:12.318890689Z,10,2,38,A,A,2,234.15,400,130,167152,12476111,233.97,234.12,5,27,1,1,233.7,234.13,1200,400,1,1,233.66,234.15,1,426,1,2,233.64,234.17,200,1,1,1,233.58,234.41,505,600,2,2,233.53,234.43,10,105,1,2,233.5,234.5,100,63,1,4,233.45,234.75,15,1,1,1,233.4,234.79,110,2000,2,1,233.39,234.89,10,2,1,2,AAPL,-1286,-6.387417218543046,0.08245102670211099
2024-10-21T12:15:12.327981136Z,2024-10-21T12:15:12.327814809Z,10,2,38,A,A,0,234.05,200,130,166327,12476126,233.97,234.05,5,200,1,1,233.7,234.12,1200,27,1,1,233.66,234.13,1,400,1,1,233.64,234.15,200,26,1,1,233.58,234.17,505,1,2,1,233.53,234.41,10,600,1,2,233.5,234.43,100,105,1,2,233.45,234.5,15,63,1,4,233.4,234.75,110,1,2,1,233.39,234.79,10,2000,1,1,AAPL,-3286,-14.284738394659215,0.18439242443589243
2024-10-21T12:15:12.391178086Z,2024-10-21T12:15:12.391011950Z,10,2,38,C,A,1,234.12,27,130,166136,12476246,233.97,234.05,5,200,1,1,233.7,234.13,1200,400,1,1,233.66,234.15,1,26,1,1,233.64,234.17,200,1,1,1,233.58,234.41,505,600,2,2,233.53,234.43,10,105,1,2,233.5,234.5,100,63,1,4,233.45,234.75,15,1,1,1,233.4,234.79,110,2000,2,1,233.39,234.89,10,2,1,2,AAPL,-3284,-14.772142081588335,0.19068400255435872
2024-10-21T12:15:12.404855221Z,2024-10-21T12:15:12.404688523Z,10,2,38,A,B,3,233.65,200,130,166698,12476254,233.97,234.05,5,200,1,1,233.7,234.13,1200,400,1,1,233.66,234.15,1,26,1,1,233.65,234.17,200,1,1,1,233.58,234.41,505,600,2,2,233.53,234.43,10,105,1,2,233.5,234.5,100,63,1,4,233.45,234.75,15,1,1,1,233.4,234.79,110,2000,2,1,233.39,234.89,10,2,1,2,AAPL,-3284,-15.267317526731754,0.19707590125971092
2024-10-21T12:15:12.446982743Z,2024-10-21T12:15:12.446815675Z,10,2,38,A,B,2,233.69,200,130,167068,12476283,233.97,234.05,5,200,1,1,233.7,234.13,1200,400,1,1,233.69,234.15,200,26,1,1,233.66,234.17,1,1,1,1,233.58,234.41,505,600,2,2,233.53,234.43,10,105,1,2,233.5,234.5,100,63,1,4,233.45,234.75,15,1,1,1,233.4,234.79,110,2000,2,1,233.39,234.89,10,2,1,2,AAPL,-3384,-15.340941066124747,0.19802625978565364
2024-10-21T12:15:12.518924447Z,2024-10-21T12:15:12.518757844Z,10,2,38,A,B,2,233.69,200,130,166603,12476376,233.97,234.05,5,200,1,1,233.7,234.13,1200,400,1,1,233.69,234.15,400,26,2,1,233.66,234.17,1,1,1,1,233.58,234.41,505,600,2,2,233.53,234.43,10,105,1,2,233.5,234.5,100,63,1,4,233.45,234.75,15,1,1,1,233.4,234.79,110,2000,2,1,233.39,234.89,10,2,1,2,AAPL,-3597,-15.670576407506703,0.20228130864254396
2024-10-21T12:15:12.519057354Z,2024-10-21T12:15:12.518889885Z,10,2,38,C,A,0,234.05,200,130,167469,12476377,233.97,234.13,5,400,1,1,233.7,234.15,1200,26,1,1,233.69,234.17,400,1,2,1,233.66,234.41,1,600,1,2,233.58,234.43,505,105,2,2,233.53,234.5,10,63,1,4,233.5,234.75,100,1,1,1,233.45,234.79,15,2000,1,1,233.4,234.89,110,2,2,2,233.39,235.0,10,213,1,6,AAPL,-3384,-15.028867505551444,0.19399790456859434
2024-10-21T12:15:12.519068158Z,2024-10-21T12:15:12.518901713Z,10,2,38,A,A,0,234.1,400,130,166445,12476378,233.97,234.1,5,400,1,1,233.7,234.13,1200,400,1,1,233.69,234.15,400,26,2,1,233.66,234.17,1,1,1,1,233.58,234.41,505,600,2,2,233.53,234.43,10,105,1,2,233.5,234.5,100,63,1,4,233.45,234.75,15,1,1,1,233.4,234.79,110,2000,2,1,233.39,234.89,10,2,1,2,AAPL,-3386,-15.57932791060718,0.20110344096974678
2024-10-21T12:15:12.521808610Z,2024-10-21T12:15:12.521642022Z,10,2,38,C,A,0,234.1,200,130,166588,12476383,233.97,234.1,5,200,1,1,233.7,234.13,1200,400,1,1,233.69,234.15,400,26,2,1,233.66,234.17,1,1,1,1,233.58,234.41,505,600,2,2,233.53,234.43,10,105,1,2,233.5,234.5,100,63,1,4,233.45,234.75,15,1,1,1,233.4,234.79,110,2000,2,1,233.39,234.89,10,2,1,2,AAPL,-3386,-16.119839120085363,0.20808054965713593
2024-10-21T12:15:12.529759184Z,2024-10-21T12:15:12.529592990Z,10,2,38,C,B,2,233.69,200,130,166194,12476384,233.97,234.1,5,200,1,1,233.7,234.13,1200,400,1,1,233.69,234.15,200,26,1,1,233.66,234.17,1,1,1,1,233.58,234.41,505,600,2,2,233.53,234.43,10,105,1,2,233.5,234.5,100,63,1,4,233.45,234.75,15,1,1,1,233.4,234.79,110,2000,2,1,233.39,234.89,10,2,1,2,AAPL,-3386,-16.65928659286593,0.21504392725731752
2024-10-21T12:15:12.529771785Z,2024-10-21T12:15:12.529605412Z,10,2,38,A,B,1,233.7,400,130,166373,12476385,233.97,234.1,5,200,1,1,233.7,234.13,1600,400,2,1,233.66,234.15,1,26,1,1,233.58,234.17,505,1,2,1,233.53,234.41,10,600,1,2,233.5,234.43,100,105,1,2,233.45,234.5,15,63,1,4,233.4,234.75,110,1,2,1,233.39,234.79,10,2000,1,1,233.31,234.89,110,2,2,2,AAPL,-3496,-17.612090680100756,0.22734305733612556
2024-10-21T12:15:12.575269816Z,2024-10-21T12:15:12.575103526Z,10,2,38,A,B,1,233.87,400,130,166290,12476419,233.97,234.1,5,200,1,1,233.87,234.13,400,400,1,1,233.7,234.15,1200,26,1,1,233.66,234.17,1,1,1,1,233.58,234.41,505,600,2,2,233.53,234.43,10,105,1,2,233.5,234.5,100,63,1,4,233.45,234.75,15,1,1,1,233.4,234.79,110,2000,2,1,233.39,234.89,10,2,1,2,AAPL,-3486,-18.11056092215277,0.23377748643813015
2024-10-21T12:15:12.619539368Z,2024-10-21T12:15:12.619373396Z,10,2,38,C,A,0,234.1,200,130,165972,12476439,233.97,234.13,5,400,1,1,233.87,234.15,400,26,1,1,233.7,234.17,1200,1,1,1,233.66,234.41,1,600,1,2,233.58,234.43,505,105,2,2,233.53,234.5,10,63,1,4,233.5,234.75,100,1,1,1,233.45,234.79,15,2000,1,1,233.4,234.89,110,2,2,2,233.39,235.0,10,213,1,6,AAPL,-3273,-17.223568808802423,0.22232788045183244
2024-10-21T12:15:12.619552121Z,2024-10-21T12:15:12.619385902Z,10,2,38,A,A,1,234.15,200,130,166219,12476440,233.97,234.13,5,400,1,1,233.87,234.15,400,226,1,2,233.7,234.17,1200,1,1,1,233.66,234.41,1,600,1,2,233.58,234.43,505,105,2,2,233.53,234.5,10,63,1,4,233.5,234.75,100,1,1,1,233.45,234.79,15,2000,1,1,233.4,234.89,110,2,2,2,233.39,235.0,10,213,1,6,AAPL,-3273,-17.43548766157462,0.22506340349514894
2024-10-21T12:15:12.656104126Z,2024-10-21T12:15:12.655937741Z,10,2,38,C,A,1,234.15,26,130,166385,12476454,233.97,234.13,5,400,1,1,233.87,234.15,400,200,1,1,233.7,234.17,1200,1,1,1,233.66,234.41,1,600,1,2,233.58,234.43,505,105,2,2,233.53,234.5,10,63,1,4,233.5,234.75,100,1,1,1,233.45,234.79,15,2000,1,1,233.4,234.89,110,2,2,2,233.39,235.0,10,213,1,6,AAPL,-3273,-17.64012935016939,0.2277049903452625
2024-10-21T12:15:12.669851013Z,2024-10-21T12:15:12.669684284Z,10,2,38,A,B,1,233.9,200,130,166729,12476460,233.97,234.13,5,400,1,1,233.9,234.15,200,200,1,1,233.7,234.17,1200,1,1,1,233.66,234.41,1,600,1,2,233.58,234.43,505,105,2,2,233.53,234.5,10,63,1,4,233.5,234.75,100,1,1,1,233.45,234.79,15,2000,1,1,233.4,234.89,110,2,2,2,233.39,235.0,10,213,1,6,AAPL,-3273,-17.837862387404435,0.23025739789516028
2024-10-21T12:15:13.051742504Z,2024-10-21T12:15:13.051576352Z,10,2,38,A,A,3,234.22,30,130,166152,12476843,233.97,234.13,5,400,1,1,233.9,234.15,200,200,1,1,233.7,234.17,1200,1,1,1,233.66,234.22,1,30,1,1,233.58,234.41,505,600,2,2,233.53,234.43,10,105,1,2,233.5,234.5,100,63,1,4,233.45,234.75,15,1,1,1,233.4,234.79,110,2000,2,1,233.39,234.89,10,2,1,2,AAPL,-3275,-18.27906976744186,0.23595265784577488
2024-10-21T12:15:13.051772118Z,2024-10-21T12:15:13.051605161Z,10,2,38,A,B,2,233.85,27,130,166957,12476844,233.97,234.13,5,400,1,1,233.9,234.15,200,200,1,1,233.85,234.17,27,1,1,1,233.7,234.22,1200,30,1,1,233.66,234.41,1,600,1,2,233.58,234.43,505,105,2,2,233.53,234.5,10,63,1,4,233.5,234.75,100,1,1,1,233.45,234.79,15,2000,1,1,233.4,234.89,110,2,2,2,AAPL,-3165,-17.999538887181064,0.232344374985288
2024-10-21T12:15:13.946134251Z,2024-10-21T12:15:13.945967888Z,10,2,38,A,A,1,234.15,200,130,166363,12477920,233.97,234.13,5,400,1,1,233.9,234.15,200,400,1,2,233.85,234.17,27,1,1,1,233.7,234.22,1200,30,1,1,233.66,234.41,1,600,1,2,233.58,234.43,505,105,2,2,233.53,234.5,10,63,1,4,233.5,234.75,100,1,1,1,233.45,234.79,15,2000,1,1,233.4,234.89,110,2,2,2,AAPL,-3165,-18.328253581225237,0.2365875398027249
2024-10-21T12:15:13.946655760Z,2024-10-21T12:15:13.946489728Z,10,2,38,C,A,3,234.22,30,130,166032,12477923,233.97,234.13,5,400,1,1,233.9,234.15,200,400,1,2,233.85,234.17,27,1,1,1,233.7,234.41,1200,600,1,2,233.66,234.43,1,105,1,2,233.58,234.5,505,63,2,4,233.53,234.75,10,1,1,1,233.5,234.79,100,2000,1,1,233.45,234.89,15,2,1,2,233.4,235.0,110,213,2,6,AAPL,-2952,-17.123224511043357,0.22103260098426944
2024-10-21T12:15:13.946698478Z,2024-10-21T12:15:13.946532120Z,10,2,38,A,A,2,234.17,27,130,166358,12477924,233.97,234.13,5,400,1,1,233.9,234.15,200,400,1,2,233.85,234.17,27,28,1,2,233.7,234.41,1200,600,1,2,233.66,234.43,1,105,1,2,233.58,234.5,505,63,2,4,233.53,234.75,10,1,1,1,233.5,234.79,100,2000,1,1,233.45,234.89,15,2,1,2,233.4,235.0,110,213,2,6,AAPL,-2952,-17.15032679738562,0.22138244682311753
2024-10-21T12:15:14.001175416Z,2024-10-21T12:15:14.001009338Z,10,2,38,C,A,1,234.15,200,130,166078,12478031,233.97,234.13,5,400,1,1,233.9,234.15,200,200,1,1,233.85,234.17,27,28,1,2,233.7,234.41,1200,600,1,2,233.66,234.43,1,105,1,2,233.58,234.5,505,63,2,4,233.53,234.75,10,1,1,1,233.5,234.79,100,2000,1,1,233.45,234.89,15,2,1,2,233.4,235.0,110,213,2,6,AAPL,-2952,-17.17618675938409,0.22171625630264577
2024-10-21T12:15:14.001188780Z,2024-10-21T12:15:14.001022189Z,10,2,38,A,A,0,234.1,400,130,166591,12478032,233.97,234.1,5,400,1,1,233.9,234.13,200,400,1,1,233.85,234.17,27,28,1,2,233.7,234.41,1200,600,1,2,233.66,234.43,1,105,1,2,233.58,234.5,505,63,2,4,233.53,234.75,10,1,1,1,233.5,234.79,100,2000,1,1,233.45,234.89,15,2,1,2,233.4,235.0,110,213,2,6,AAPL,-2952,-17.200887902330745,0.22203510733851592
2024-10-21T12:15:14.207349948Z,2024-10-21T12:15:14.207183672Z,10,2,38,A,B,1,233.9,100,130,166276,12478133,233.97,234.1,5,400,1,1,233.9,234.13,300,400,2,1,233.85,234.17,27,28,1,2,233.7,234.41,1200,600,1,2,233.66,234.43,1,105,1,2,233.58,234.5,505,63,2,4,233.53,234.75,10,1,1,1,233.5,234.79,100,2000,1,1,233.45,234.89,15,2,1,2,233.4,235.0,110,213,2,6,AAPL,-2952,-17.224506411561165,0.22233998335781965
2024-10-21T12:15:14.207645338Z,2024-10-21T12:15:14.207479344Z,10,2,38,C,B,1,233.9,100,130,165994,12478134,233.97,234.1,5,400,1,1,233.9,234.13,200,400,1,1,233.85,234.17,27,28,1,2,233.7,234.41,1200,600,1,2,233.66,234.43,1,105,1,2,233.58,234.5,505,63,2,4,233.53,234.75,10,1,1,1,233.5,234.79,100,2000,1,1,233.45,234.89,15,2,1,2,233.4,235.0,110,213,2,6,AAPL,-2952,-17.24711193732572,0.2226317834304715
2024-10-21T12:15:14.278543569Z,2024-10-21T12:15:14.278377067Z,10,2,38,C,A,0,234.1,200,130,166502,12478168,233.97,234.1,5,200,1,1,233.9,234.13,200,400,1,1,233.85,234.17,27,28,1,2,233.7,234.41,1200,600,1,2,233.66,234.43,1,105,1,2,233.58,234.5,505,63,2,4,233.53,234.75,10,1,1,1,233.5,234.79,100,2000,1,1,233.45,234.89,15,2,1,2,233.4,235.0,110,213,2,6,AAPL,-2952,-17.26876828079298,0.22291133112438216
2024-10-21T12:15:14.278726070Z,2024-10-21T12:15:14.278559734Z,10,2,38,C,A,0,234.1,200,130,166336,12478169,233.97,234.13,5,400,1,1,233.9,234.17,200,28,1,2,233.85,234.41,27,600,1,2,233.7,234.43,1200,105,1,2,233.66,234.5,1,63,1,4,233.58,234.75,505,1,2,1,233.53,234.79,10,2000,1,1,233.5,234.89,100,2,1,2,233.45,235.0,15,213,1,6,233.4,235.03,110,2,2,1,AAPL,-2950,-17.513067045234564,0.22606482544941084
2024-10-21T12:15:14.278738674Z,2024-10-21T12:15:14.278572418Z,10,2,38,A,A,1,234.16,200,130,166256,12478170,233.97,234.13,5,400,1,1,233.9,234.16,200,200,1,1,233.85,234.17,27,28,1,2,233.7,234.41,1200,600,1,2,233.66,234.43,1,105,1,2,233.58,234.5,505,63,2,4,233.53,234.75,10,1,1,1,233.5,234.79,100,2000,1,1,233.45,234.89,15,2,1,2,233.4,235.0,110,213,2,6,AAPL,-3163,-18.794058154235145,0.2426003089664035
2024-10-21T12:15:14.279136295Z,2024-10-21T12:15:14.278970387Z,10,2,38,C,A,2,234.17,27,130,165908,12478171,233.97,234.13,5,400,1,1,233.9,234.16,200,200,1,1,233.85,234.17,27,1,1,1,233.7,234.41,1200,600,1,2,233.66,234.43,1,105,1,2,233.58,234.5,505,63,2,4,233.53,234.75,10,1,1,1,233.5,234.79,100,2000,1,1,233.45,234.89,15,2,1,2,233.4,235.0,110,213,2,6,AAPL,-3163,-18.809886638171342,0.24280462860093258
2024-10-21T12:15:14.280757598Z,2024-10-21T12:15:14.280591359Z,10,2,38,A,A,1,234.16,200,130,166239,12478172,233.97,234.13,5,400,1,1,233.9,234.16,200,400,1,2,233.85,234.17,27,1,1,1,233.7,234.41,1200,600,1,2,233.66,234.43,1,105,1,2,233.58,234.5,505,63,2,4,233.53,234.75,10,1,1,1,233.5,234.79,100,2000,1,1,233.45,234.89,15,2,1,2,233.4,235.0,110,213,2,6,AAPL,-3163,-18.825094133365724,0.24300093229449812
2024-10-21T12:15:15.249067573Z,2024-10-21T12:15:15.248901194Z,10,2,38,C,A,1,234.16,200,130,166379,12479022,233.97,234.13,5,400,1,1,233.9,234.16,200,200,1,1,233.85,234.17,27,1,1,1,233.7,234.41,1200,600,1,2,233.66,234.43,1,105,1,2,233.58,234.5,505,63,2,4,233.53,234.75,10,1,1,1,233.5,234.79,100,2000,1,1,233.45,234.89,15,2,1,2,233.4,235.0,110,213,2,6,AAPL,-3163,-18.839716481029246,0.24318968269804972
2024-10-21T12:15:15.249079309Z,2024-10-21T12:15:15.248912868Z,10,2,38,A,A,1,234.15,400,130,166441,12479023,233.97,234.13,5,400,1,1,233.9,234.15,200,400,1,1,233.85,234.17,27,1,1,1,233.7,234.41,1200,600,1,2,233.66,234.43,1,105,1,2,233.58,234.5,505,63,2,4,233.53,234.75,10,1,1,1,233.5,234.79,100,2000,1,1,233.45,234.89,15,2,1,2,233.4,235.0,110,213,2,6,AAPL,-3163,-18.853786816269285,0.2433713075312008
2024-10-21T12:15:17.923200888Z,2024-10-21T12:15:17.923034484Z,10,2,38,A,A,3,234.22,27,130,166404,12482317,233.97,234.13,5,400,1,1,233.9,234.15,200,400,1,1,233.85,234.17,27,1,1,1,233.7,234.22,1200,27,1,1,233.66,234.41,1,600,1,2,233.58,234.43,505,105,2,2,233.53,234.5,10,63,1,4,233.5,234.75,100,1,1,1,233.45,234.79,15,2000,1,1,233.4,234.89,110,2,2,2,AAPL,-3165,-19.110543427775198,0.2466856121252017
2024-10-21T12:15:24.014356772Z,2024-10-21T12:15:24.014190176Z,10,2,38,C,B,1,233.9,200,130,166596,12489125,233.97,234.13,5,400,1,1,233.85,234.15,27,400,1,1,233.7,234.17,1200,1,1,1,233.66,234.22,1,27,1,1,233.58,234.41,505,600,2,2,233.53,234.43,10,105,1,2,233.5,234.5,100,63,1,4,233.45,234.75,15,1,1,1,233.4,234.79,110,2000,2,1,233.39,234.89,10,2,1,2,AAPL,-3175,-19.523443504996155,0.252015471460743
2024-10-21T12:15:24.014368498Z,2024-10-21T12:15:24.014202142Z,10,2,38,A,B,1,233.87,400,130,166356,12489126,233.97,234.13,5,400,1,1,233.87,234.15,400,400,1,1,233.85,234.17,27,1,1,1,233.7,234.22,1200,27,1,1,233.66,234.41,1,600,1,2,233.58,234.43,505,105,2,2,233.53,234.5,10,63,1,4,233.5,234.75,100,1,1,1,233.45,234.79,15,2000,1,1,233.4,234.89,110,2,2,2,AAPL,-3065,-19.08311306901615,0.24633153141227673
2024-10-21T12:15:24.015016662Z,2024-10-21T12:15:24.014850794Z,10,2,38,C,B,2,233.85,27,130,165868,12489129,233.97,234.13,5,400,1,1,233.87,234.15,400,400,1,1,233.7,234.17,1200,1,1,1,233.66,234.22,1,27,1,1,233.58,234.41,505,600,2,2,233.53,234.43,10,105,1,2,233.5,234.5,100,63,1,4,233.45,234.75,15,1,1,1,233.4,234.79,110,2000,2,1,233.39,234.89,10,2,1,2,AAPL,-3075,-19.492868462757528,0.2516207980680739
2024-10-21T12:15:24.015063463Z,2024-10-21T12:15:24.014897264Z,10,2,38,A,B,2,233.79,29,130,166199,12489130,233.97,234.13,5,400,1,1,233.87,234.15,400,400,1,1,233.79,234.17,29,1,1,1,233.7,234.22,1200,27,1,1,233.66,234.41,1,600,1,2,233.58,234.43,505,105,2,2,233.53,234.5,10,63,1,4,233.5,234.75,100,1,1,1,233.45,234.79,15,2000,1,1,233.4,234.89,110,2,2,2,AAPL,-2965,-19.018601667735727,0.24549879556810467
2024-10-21T12:15:24.015171797Z,2024-10-21T12:15:24.015005588Z,10,2,38,C,A,3,234.22,27,130,166209,12489131,233.97,234.13,5,400,1,1,233.87,234.15,400,400,1,1,233.79,234.17,29,1,1,1,233.7,234.41,1200,600,1,2,233.66,234.43,1,105,1,2,233.58,234.5,505,63,2,4,233.53,234.75,10,1,1,1,233.5,234.79,100,2000,1,1,233.45,234.89,15,2,1,2,233.4,235.0,110,213,2,6,AAPL,-2752,-17.641025641025642,0.22771655998269083
2024-10-21T12:15:24.015226111Z,2024-10-21T12:15:24.015059897Z,10,2,38,A,A,2,234.17,30,130,166214,12489132,233.97,234.13,5,400,1,1,233.87,234.15,400,400,1,1,233.79,234.17,29,31,1,2,233.7,234.41,1200,600,1,2,233.66,234.43,1,105,1,2,233.58,234.5,505,63,2,4,233.53,234.75,10,1,1,1,233.5,234.79,100,2000,1,1,233.45,234.89,15,2,1,2,233.4,235.0,110,213,2,6,AAPL,-2752,-17.630120820455186,0.22757579672560685
2024-10-21T12:15:24.066676377Z,2024-10-21T12:15:24.066509814Z,10,2,38,A,A,0,234.1,200,130,166563,12489179,233.97,234.1,5,200,1,1,233.87,234.13,400,400,1,1,233.79,234.17,29,31,1,2,233.7,234.41,1200,600,1,2,233.66,234.43,1,105,1,2,233.58,234.5,505,63,2,4,233.53,234.75,10,1,1,1,233.5,234.79,100,2000,1,1,233.45,234.89,15,2,1,2,233.4,235.0,110,213,2,6,AAPL,-2752,-17.619604812893257,0.22744005240350887
2024-10-21T12:15:27.519404999Z,2024-10-21T12:15:27.519238798Z,10,2,38,C,B,1,233.87,400,130,166201,12491655,233.97,234.1,5,200,1,1,233.79,234.13,29,400,1,1,233.7,234.17,1200,31,1,2,233.66,234.41,1,600,1,2,233.58,234.43,505,105,2,2,233.53,234.5,10,63,1,4,233.5,234.75,100,1,1,1,233.45,234.79,15,2000,1,1,233.4,234.89,110,2,2,2,233.39,235.0,10,213,1,6,AAPL,-2551,-16.249331740886085,0.20975208592446654
2024-10-21T12:15:27.519418174Z,2024-10-21T12:15:27.519251700Z,10,2,38,A,B,1,233.84,200,130,166474,12491656,233.97,234.1,5,200,1,1,233.84,234.13,200,400,1,1,233.79,234.17,29,31,1,2,233.7,234.41,1200,600,1,2,233.66,234.43,1,105,1,2,233.58,234.5,505,63,2,4,233.53,234.75,10,1,1,1,233.5,234.79,100,2000,1,1,233.45,234.89,15,2,1,2,233.4,235.0,110,213,2,6,AAPL,-2441,-15.540824304702333,0.2006064228902996
2024-10-21T12:15:29.175384059Z,2024-10-21T12:15:29.175215826Z,10,2,38,T,A,0,233.97,5,0,168233,12493180,233.97,234.1,5,200,1,1,233.84,234.13,200,400,1,1,233.79,234.17,29,31,1,2,233.7,234.41,1200,600,1,2,233.66,234.43,1,105,1,2,233.58,234.5,505,63,2,4,233.53,234.75,10,1,1,1,233.5,234.79,100,2000,1,1,233.45,234.89,15,2,1,2,233.4,235.0,110,213,2,6,AAPL,-2441,-15.540824304702333,0.2006064228902996
2024-10-21T12:15:29.175384059Z,2024-10-21T12:15:29.175215826Z,10,2,38,A,N,0,233.95,295,130,168233,12493181,233.84,233.95,200,295,1,1,233.79,234.1,29,200,1,1,233.7,234.13,1200,400,1,1,233.66,234.17,1,31,1,2,233.58,234.41,505,600,2,2,233.53,234.43,10,105,1,2,233.5,234.5,100,63,1,4,233.45,234.75,15,1,1,1,233.4,234.79,110,2000,2,1,233.39,234.89,10,2,1,2,AAPL,-2453,-15.880567027570041,0.2049919413802602
2024-10-21T12:15:29.175406869Z,2024-10-21T12:15:29.175239385Z,10,2,38,A,A,1,234.07,100,130,167484,12493182,233.84,233.95,200,295,1,1,233.79,234.07,29,100,1,1,233.7,234.1,1200,200,1,1,233.66,234.13,1,400,1,1,233.58,234.17,505,31,2,2,233.53,234.41,10,600,1,2,233.5,234.43,100,105,1,2,233.45,234.5,15,63,1,4,233.4,234.75,110,1,2,1,233.39,234.79,10,2000,1,1,AAPL,-4453,-26.367623444399843,0.34036255192068254
2024-10-21T12:15:29.175410757Z,2024-10-21T12:15:29.175244705Z,10,2,38,A,A,1,234.04,38,130,166052,12493183,233.84,233.95,200,295,1,1,233.79,234.04,29,38,1,1,233.7,234.07,1200,100,1,1,233.66,234.1,1,200,1,1,233.58,234.13,505,400,2,1,233.53,234.17,10,31,1,2,233.5,234.41,100,600,1,2,233.45,234.43,15,105,1,2,233.4,234.5,110,63,2,4,233.39,234.75,10,1,1,1,AAPL,-4454,-26.80575756055971,0.3460181411008806
2024-10-21T12:15:29.175418381Z,2024-10-21T12:15:29.175252395Z,10,2,38,A,A,2,234.07,100,130,165986,12493184,233.84,233.95,200,295,1,1,233.79,234.04,29,38,1,1,233.7,234.07,1200,200,1,2,233.66,234.1,1,200,1,1,233.58,234.13,505,400,2,1,233.53,234.17,10,31,1,2,233.5,234.41,100,600,1,2,233.45,234.43,15,105,1,2,233.4,234.5,110,63,2,4,233.39,234.75,10,1,1,1,AAPL,-4454,-27.23749373433584,0.3515911433918445
2024-10-21T12:15:29.175428571Z,2024-10-21T12:15:29.175261243Z,10,2,38,T,B,0,233.95,187,130,167328,12493185,233.84,233.95,200,295,1,1,233.79,234.04,29,38,1,1,233.7,234.07,1200,200,1,2,233.66,234.1,1,200,1,1,233.58,234.13,505,400,2,1,233.53,234.17,10,31,1,2,233.5,234.41,100,600,1,2,233.45,234.43,15,105,1,2,233.4,234.5,110,63,2,4,233.39,234.75,10,1,1,1,AAPL,-4454,-27.668754070437355,0.35715800340284254
2024-10-21T12:15:29.175428571Z,2024-10-21T12:15:29.175261243Z,10,2,38,C,A,0,233.95,187,130,167328,12493185,233.84,233.95,200,108,1,1,233.79,234.04,29,38,1,1,233.7,234.07,1200,200,1,2,233.66,234.1,1,200,1,1,233.58,234.13,505,400,2,1,233.53,234.17,10,31,1,2,233.5,234.41,100,600,1,2,233.45,234.43,15,105,1,2,233.4,234.5,110,63,2,4,233.39,234.75,10,1,1,1,AAPL,-4454,-28.099539355097136,0.362718731282845
2024-10-21T12:15:29.175431546Z,2024-10-21T12:15:29.175265540Z,10,2,38,A,A,1,234.04,38,130,166006,12493186,233.84,233.95,200,108,1,1,233.79,234.04,29,76,1,2,233.7,234.07,1200,200,1,2,233.66,234.1,1,200,1,1,233.58,234.13,505,400,2,1,233.53,234.17,10,31,1,2,233.5,234.41,100,600,1,2,233.45,234.43,15,105,1,2,233.4,234.5,110,63,2,4,233.39,234.75,10,1,1,1,AAPL,-4454,-28.529850372816895,0.36827333715847577
2024-10-21T12:15:29.175437237Z,2024-10-21T12:15:29.175269965Z,10,2,38,T,B,0,233.95,108,130,167272,12493187,233.84,233.95,200,108,1,1,233.79,234.04,29,76,1,2,233.7,234.07,1200,200,1,2,233.66,234.1,1,200,1,1,233.58,234.13,505,400,2,1,233.53,234.17,10,31,1,2,233.5,234.41,100,600,1,2,233.45,234.43,15,105,1,2,233.4,234.5,110,63,2,4,233.39,234.75,10,1,1,1,AAPL,-4454,-28.959687906371908,0.37382183113407336
2024-10-21T12:15:29.175437237Z,2024-10-21T12:15:29.175269965Z,10,2,38,C,A,0,233.95,108,130,167272,12493187,233.84,234.04,200,76,1,2,233.79,234.07,29,200,1,2,233.7,234.1,1200,200,1,1,233.66,234.13,1,400,1,1,233.58,234.17,505,31,2,2,233.53,234.41,10,600,1,2,233.5,234.43,100,105,1,2,233.45,234.5,15,63,1,4,233.4,234.75,110,1,2,1,233.39,234.79,10,2000,1,1,AAPL,-2454,-14.721323395746229,0.1900280170941997
2024-10-21T12:15:29.175453602Z,2024-10-21T12:15:29.175287761Z,10,2,38,C,A,1,234.07,100,130,165841,12493188,233.84,234.04,200,76,1,2,233.79,234.07,29,100,1,1,233.7,234.1,1200,200,1,1,233.66,234.13,1,400,1,1,233.58,234.17,505,31,2,2,233.53,234.41,10,600,1,2,233.5,234.43,100,105,1,2,233.45,234.5,15,63,1,4,233.4,234.75,110,1,2,1,233.39,234.79,10,2000,1,1,AAPL,-2454,-13.693512117931206,0.17676066783355643
2024-10-21T12:15:29.175459603Z,2024-10-21T12:15:29.175293157Z,10,2,38,C,A,0,234.04,38,130,166446,12493190,233.84,234.04,200,38,1,1,233.79,234.07,29,100,1,1,233.7,234.1,1200,200,1,1,233.66,234.13,1,400,1,1,233.58,234.17,505,31,2,2,233.53,234.41,10,600,1,2,233.5,234.43,100,105,1,2,233.45,234.5,15,63,1,4,233.4,234.75,110,1,2,1,233.39,234.79,10,2000,1,1,AAPL,-2454,-12.824469720258223,0.16554276308673832
2024-10-21T12:15:29.175464536Z,2024-10-21T12:15:29.175298862Z,10,2,38,C,A,1,234.07,100,130,165674,12493191,233.84,234.04,200,38,1,1,233.79,234.1,29,200,1,1,233.7,234.13,1200,400,1,1,233.66,234.17,1,31,1,2,233.58,234.41,505,600,2,2,233.53,234.43,10,105,1,2,233.5,234.5,100,63,1,4,233.45,234.75,15,1,1,1,233.4,234.79,110,2000,2,1,233.39,234.89,10,2,1,2,AAPL,-2452,-12.996466431095406,0.16776295708889974
2024-10-21T12:15:29.175475521Z,2024-10-21T12:15:29.175307953Z,10,2,38,A,A,1,234.08,38,130,167568,12493192,233.84,234.04,200,38,1,1,233.79,234.08,29,38,1,1,233.7,234.1,1200,200,1,1,233.66,234.13,1,400,1,1,233.58,234.17,505,31,2,2,233.53,234.41,10,600,1,2,233.5,234.43,100,105,1,2,233.45,234.5,15,63,1,4,233.4,234.75,110,1,2,1,233.39,234.79,10,2000,1,1,AAPL,-4452,-22.223489980745917,0.2868686204648037
2024-10-21T12:15:29.175484200Z,2024-10-21T12:15:29.175318339Z,10,2,38,C,A,2,234.1,200,130,165861,12493193,233.84,234.04,200,38,1,1,233.79,234.08,29,38,1,1,233.7,234.13,1200,400,1,1,233.66,234.17,1,31,1,2,233.58,234.41,505,600,2,2,233.53,234.43,10,105,1,2,233.5,234.5,100,63,1,4,233.45,234.75,15,1,1,1,233.4,234.79,110,2000,2,1,233.39,234.89,10,2,1,2,AAPL,-4450,-22.52120607313422,0.29071164443572817
2024-10-21T12:15:29.175542211Z,2024-10-21T12:15:29.175376083Z,10,2,38,A,B,0,233.89,38,130,166128,12493194,233.89,234.04,38,38,1,1,233.84,234.08,200,38,1,1,233.79,234.13,29,400,1,1,233.7,234.17,1200,31,1,2,233.66,234.41,1,600,1,2,233.58,234.43,505,105,2,2,233.53,234.5,10,63,1,4,233.5,234.75,100,1,1,1,233.45,234.79,15,2000,1,1,233.4,234.89,110,2,2,2,AAPL,-4340,-22.185303514376997,0.28637569613396424
2024-10-21T12:15:29.175555082Z,2024-10-21T12:15:29.175388906Z,10,2,38,A,B,1,233.86,38,130,166176,12493195,233.89,234.04,38,38,1,1,233.86,234.08,38,38,1,1,233.84,234.13,200,400,1,1,233.79,234.17,29,31,1,2,233.7,234.41,1200,600,1,2,233.66,234.43,1,105,1,2,233.58,234.5,505,63,2,4,233.53,234.75,10,1,1,1,233.5,234.79,100,2000,1,1,233.45,234.89,15,2,1,2,AAPL,-4325,-22.402171213680063,0.2891751006278735
2024-10-21T12:15:29.246556838Z,2024-10-21T12:15:29.246390784Z,10,2,38,C,B,2,233.84,200,130,166054,12493277,233.89,234.04,38,38,1,1,233.86,234.08,38,38,1,1,233.79,234.13,29,400,1,1,233.7,234.17,1200,31,1,2,233.66,234.41,1,600,1,2,233.58,234.43,505,105,2,2,233.53,234.5,10,63,1,4,233.5,234.75,100,1,1,1,233.45,234.79,15,2000,1,1,233.4,234.89,110,2,2,2,AAPL,-4435,-23.19445916816849,0.29940223204206134
2024-10-21T12:15:29.246589766Z,2024-10-21T12:15:29.246423576Z,10,2,38,A,B,3,233.76,400,130,166190,12493278,233.89,234.04,38,38,1,1,233.86,234.08,38,38,1,1,233.79,234.13,29,400,1,1,233.76,234.17,400,31,1,2,233.7,234.41,1200,600,1,2,233.66,234.43,1,105,1,2,233.58,234.5,505,63,2,4,233.53,234.75,10,1,1,1,233.5,234.79,100,2000,1,1,233.45,234.89,15,2,1,2,AAPL,-4420,-23.414324057070207,0.302240325312854
2024-10-21T12:15:29.246983004Z,2024-10-21T12:15:29.246816914Z,10,2,38,C,B,2,233.79,29,130,166090,12493279,233.89,234.04,38,38,1,1,233.86,234.08,38,38,1,1,233.76,234.13,400,400,1,1,233.7,234.17,1200,31,1,2,233.66,234.41,1,600,1,2,233.58,234.43,505,105,2,2,233.53,234.5,10,63,1,4,233.5,234.75,100,1,1,1,233.45,234.79,15,2000,1,1,233.4,234.89,110,2,2,2,AAPL,-4530,-24.221190375685946,0.31265563937564744
2024-10-21T12:15:29.247077109Z,2024-10-21T12:15:29.246910849Z,10,2,38,A,B,3,233.74,28,130,166260,12493280,233.89,234.04,38,38,1,1,233.86,234.08,38,38,1,1,233.76,234.13,400,400,1,1,233.74,234.17,28,31,1,2,233.7,234.41,1200,600,1,2,233.66,234.43,1,105,1,2,233.58,234.5,505,63,2,4,233.53,234.75,10,1,1,1,233.5,234.79,100,2000,1,1,233.45,234.89,15,2,1,2,AAPL,-4515,-24.444014765336615,0.31553193492240356
2024-10-21T12:15:29.283930892Z,2024-10-21T12:15:29.283764753Z,10,2,38,C,A,1,234.08,38,130,166139,12493295,233.89,234.04,38,38,1,1,233.86,234.13,38,400,1,1,233.76,234.17,400,31,1,2,233.74,234.41,28,600,1,2,233.7,234.43,1200,105,1,2,233.66,234.5,1,63,1,4,233.58,234.75,505,1,2,1,233.53,234.79,10,2000,1,1,233.5,234.89,100,2,1,2,233.45,235.0,15,213,1,6,AAPL,-4302,-23.40571269138214,0.3021291667775657
2024-10-21T12:15:29.283941482Z,2024-10-21T12:15:29.283775550Z,10,2,38,C,B,1,233.86,38,130,165932,12493296,233.89,234.04,38,38,1,1,233.76,234.13,400,400,1,1,233.74,234.17,28,31,1,2,233.7,234.41,1200,600,1,2,233.66,234.43,1,105,1,2,233.58,234.5,505,63,2,4,233.53,234.75,10,1,1,1,233.5,234.79,100,2000,1,1,233.45,234.89,15,2,1,2,233.4,235.0,110,213,2,6,AAPL,-4412,-24.041109118499104,0.3103310872074005
2024-10-21T12:15:29.283989568Z,2024-10-21T12:15:29.283823523Z,10,2,38,A,A,1,234.1,400,130,166045,12493297,233.89,234.04,38,38,1,1,233.76,234.1,400,400,1,1,233.74,234.13,28,400,1,1,233.7,234.17,1200,31,1,2,233.66,234.41,1,600,1,2,233.58,234.43,505,105,2,2,233.53,234.5,10,63,1,4,233.5,234.75,100,1,1,1,233.45,234.79,15,2000,1,1,233.4,234.89,110,2,2,2,AAPL,-4414,-24.2627456369383,0.31319204929500954
2024-10-21T12:15:29.425498174Z,2024-10-21T12:15:29.425332139Z,10,2,38,C,A,0,234.04,38,130,166035,12493515,233.89,234.1,38,400,1,1,233.76,234.13,400,400,1,1,233.74,234.17,28,31,1,2,233.7,234.41,1200,600,1,2,233.66,234.43,1,105,1,2,233.58,234.5,505,63,2,4,233.53,234.75,10,1,1,1,233.5,234.79,100,2000,1,1,233.45,234.89,15,2,1,2,233.4,235.0,110,213,2,6,AAPL,-4201,-23.12398491386633,0.29849252559507833
2024-10-21T12:15:29.425509152Z,2024-10-21T12:15:29.425342648Z,10,2,38,C,B,0,233.89,38,130,166504,12493516,233.76,234.1,400,400,1,1,233.74,234.13,28,400,1,1,233.7,234.17,1200,31,1,2,233.66,234.41,1,600,1,2,233.58,234.43,505,105,2,2,233.53,234.5,10,63,1,4,233.5,234.75,100,1,1,1,233.45,234.79,15,2000,1,1,233.4,234.89,110,2,2,2,233.39,235.0,10,213,1,6,AAPL,-4211,-23.288730019558912,0.30061911332901686
2024-10-21T12:15:29.496660616Z,2024-10-21T12:15:29.496494580Z,10,2,38,C,B,0,233.76,200,130,166036,12493549,233.76,234.1,200,400,1,1,233.74,234.13,28,400,1,1,233.7,234.17,1200,31,1,2,233.66,234.41,1,600,1,2,233.58,234.43,505,105,2,2,233.53,234.5,10,63,1,4,233.5,234.75,100,1,1,1,233.45,234.79,15,2000,1,1,233.4,234.89,110,2,2,2,233.39,235.0,10,213,1,6,AAPL,-4211,-23.396793520099074,0.3020140349794602
