ts_recv,ts_event,rtype,publisher_id,instrument_id,action,side,depth,price,size,flags,ts_in_delta,sequence,bid_px_00,ask_px_00,bid_sz_00,ask_sz_00,bid_ct_00,ask_ct_00,bid_px_01,ask_px_01,bid_sz_01,ask_sz_01,bid_ct_01,ask_ct_01,bid_px_02,ask_px_02,bid_sz_02,ask_sz_02,bid_ct_02,ask_ct_02,bid_px_03,ask_px_03,bid_sz_03,ask_sz_03,bid_ct_03,ask_ct_03,bid_px_04,ask_px_04,bid_sz_04,ask_sz_04,bid_ct_04,ask_ct_04,bid_px_05,ask_px_05,bid_sz_05,ask_sz_05,bid_ct_05,ask_ct_05,bid_px_06,ask_px_06,bid_sz_06,ask_sz_06,bid_ct_06,ask_ct_06,bid_px_07,ask_px_07,bid_sz_07,ask_sz_07,bid_ct_07,ask_ct_07,bid_px_08,ask_px_08,bid_sz_08,ask_sz_08,bid_ct_08,ask_ct_08,bid_px_09,ask_px_09,bid_sz_09,ask_sz_09,bid_ct_09,ask_ct_09,symbol,ofi_best_level,multi_level_ofi,integrated_ofi
2024-10-21T12:01:42.535353192Z,2024-10-21T12:01:42.535186906Z,10,2,38,C,A,0,233.73,200,130,166286,11753360,233.59,233.74,1,1,1,1,233.58,233.78,500,178,1,3,233.53,233.8,10,25,1,1,233.51,233.94,200,200,1,1,233.47,233.98,27,44,1,3,233.45,234.0,15,154,1,7,233.4,234.13,110,400,2,1,233.39,234.17,10,1,1,1,233.31,234.41,110,600,2,2,233.3,234.43,100,5,1,1,AAPL,199,1.0514374514374516,-0.013572324214613163
2024-10-21T12:01:42.535365626Z,2024-10-21T12:01:42.535199542Z,10,2,38,A,A,1,233.77,200,130,166084,11753361,233.59,233.74,1,1,1,1,233.58,233.77,500,200,1,1,233.53,233.78,10,178,1,3,233.51,233.8,200,25,1,1,233.47,233.94,27,200,1,1,233.45,233.98,15,44,1,3,233.4,234.0,110,154,2,7,233.39,234.13,10,400,1,1,233.31,234.17,110,1,2,1,233.3,234.41,100,600,1,2,AAPL,-401,-2.0232655921513665,0.026117023462886618
2024-10-21T12:01:42.538464981Z,2024-10-21T12:01:42.538298989Z,10,2,38,C,A,2,233.78,28,130,165992,11753363,233.59,233.74,1,1,1,1,233.58,233.77,500,200,1,1,233.53,233.78,10,150,1,2,233.51,233.8,200,25,1,1,233.47,233.94,27,200,1,1,233.45,233.98,15,44,1,3,233.4,234.0,110,154,2,7,233.39,234.13,10,400,1,1,233.31,234.17,110,1,2,1,233.3,234.41,100,600,1,2,AAPL,-401,-1.9448627951499682,0.02510497259977469
2024-10-21T12:01:42.538562627Z,2024-10-21T12:01:42.538396440Z,10,2,38,A,A,4,233.84,28,130,166187,11753364,233.59,233.74,1,1,1,1,233.58,233.77,500,200,1,1,233.53,233.78,10,150,1,2,233.51,233.8,200,25,1,1,233.47,233.84,27,28,1,1,233.45,233.94,15,200,1,1,233.4,233.98,110,44,2,3,233.39,234.0,10,154,1,7,233.31,234.13,110,400,2,1,233.3,234.17,100,1,1,1,AAPL,-402,-2.026209677419355,0.02615502675040313
2024-10-21T12:01:44.768109270Z,2024-10-21T12:01:44.767942496Z,10,2,38,A,B,3,233.52,200,130,166774,11755446,233.59,233.74,1,1,1,1,233.58,233.77,500,200,1,1,233.53,233.78,10,150,1,2,233.52,233.8,200,25,1,1,233.47,233.84,27,28,1,1,233.45,233.94,15,200,1,1,233.4,233.98,110,44,2,3,233.39,234.0,10,154,1,7,233.31,234.13,110,400,2,1,233.3,234.17,100,1,1,1,AAPL,-402,-2.1007838745800673,0.027117656700977877
2024-10-21T12:01:44.773438472Z,2024-10-21T12:01:44.773272494Z,10,2,38,C,B,4,233.47,27,130,165978,11755521,233.59,233.74,1,1,1,1,233.58,233.77,500,200,1,1,233.53,233.78,10,150,1,2,233.52,233.8,200,25,1,1,233.45,233.84,15,28,1,1,233.4,233.94,110,200,2,1,233.39,233.98,10,44,1,3,233.31,234.0,110,154,2,7,233.3,234.13,100,400,1,1,233.25,234.17,55,1,2,1,AAPL,-457,-2.4846163351044113,0.03207230102262253
2024-10-21T12:01:44.773482065Z,2024-10-21T12:01:44.773315201Z,10,2,38,A,B,4,233.48,26,130,166864,11755522,233.59,233.74,1,1,1,1,233.58,233.77,500,200,1,1,233.53,233.78,10,150,1,2,233.52,233.8,200,25,1,1,233.48,233.84,26,28,1,1,233.45,233.94,15,200,1,1,233.4,233.98,110,44,2,3,233.39,234.0,10,154,1,7,233.31,234.13,110,400,2,1,233.3,234.17,100,1,1,1,AAPL,-357,-2.004149377593361,0.02587026464581894
2024-10-21T12:01:46.087880619Z,2024-10-21T12:01:46.087712989Z,10,2,38,A,B,0,233.6,100,130,167630,11756647,233.6,233.74,100,1,1,1,233.59,233.77,1,200,1,1,233.58,233.78,500,150,1,2,233.53,233.8,10,25,1,1,233.52,233.84,200,28,1,1,233.48,233.94,26,200,1,1,233.45,233.98,15,44,1,3,233.4,234.0,110,154,2,7,233.39,234.13,10,400,1,1,233.31,234.17,110,1,2,1,AAPL,-247,-1.4275737507525585,0.01842762378208639
2024-10-21T12:01:46.088253818Z,2024-10-21T12:01:46.088087887Z,10,2,38,C,B,0,233.6,100,130,165931,11756649,233.59,233.74,1,1,1,1,233.58,233.77,500,200,1,1,233.53,233.78,10,150,1,2,233.52,233.8,200,25,1,1,233.48,233.84,26,28,1,1,233.45,233.94,15,200,1,1,233.4,233.98,110,44,2,3,233.39,234.0,10,154,1,7,233.31,234.13,110,400,2,1,233.3,234.17,100,1,1,1,AAPL,-347,-2.064001903402332,0.02664286208776119
2024-10-21T12:01:48.662615443Z,2024-10-21T12:01:48.662449384Z,10,2,38,C,B,3,233.52,200,130,166059,11758360,233.59,233.74,1,1,1,1,233.58,233.77,500,200,1,1,233.53,233.78,10,150,1,2,233.48,233.8,26,25,1,1,233.45,233.84,15,28,1,1,233.4,233.94,110,200,2,1,233.39,233.98,10,44,1,3,233.31,234.0,110,154,2,7,233.3,234.13,100,400,1,1,233.25,234.17,55,1,2,1,AAPL,-402,-2.470337981564642,0.03188799101613791
2024-10-21T12:01:48.662628317Z,2024-10-21T12:01:48.662461832Z,10,2,38,A,B,3,233.5,400,130,166485,11758361,233.59,233.74,1,1,1,1,233.58,233.77,500,200,1,1,233.53,233.78,10,150,1,2,233.5,233.8,400,25,1,1,233.48,233.84,26,28,1,1,233.45,233.94,15,200,1,1,233.4,233.98,110,44,2,3,233.39,234.0,10,154,1,7,233.31,234.13,110,400,2,1,233.3,234.17,100,1,1,1,AAPL,-302,-1.9044727315193273,0.02458360346089299
2024-10-21T12:01:48.663172461Z,2024-10-21T12:01:48.663006081Z,10,2,38,C,B,4,233.48,26,130,166380,11758362,233.59,233.74,1,1,1,1,233.58,233.77,500,200,1,1,233.53,233.78,10,150,1,2,233.5,233.8,400,25,1,1,233.45,233.84,15,28,1,1,233.4,233.94,110,200,2,1,233.39,233.98,10,44,1,3,233.31,234.0,110,154,2,7,233.3,234.13,100,400,1,1,233.25,234.17,55,1,2,1,AAPL,-357,-2.319526627218935,0.029941265042446825
2024-10-21T12:01:48.663226638Z,2024-10-21T12:01:48.663060459Z,10,2,38,A,B,5,233.42,30,130,166179,11758363,233.59,233.74,1,1,1,1,233.58,233.77,500,200,1,1,233.53,233.78,10,150,1,2,233.5,233.8,400,25,1,1,233.45,233.84,15,28,1,1,233.42,233.94,30,200,1,1,233.4,233.98,110,44,2,3,233.39,234.0,10,154,1,7,233.31,234.13,110,400,2,1,233.3,234.17,100,1,1,1,AAPL,-257,-1.7094036697247708,0.02206558344239679
2024-10-21T12:01:50.803574222Z,2024-10-21T12:01:50.803408210Z,10,2,38,C,B,5,233.42,30,130,166012,11760607,233.59,233.74,1,1,1,1,233.58,233.77,500,200,1,1,233.53,233.78,10,150,1,2,233.5,233.8,400,25,1,1,233.45,233.84,15,28,1,1,233.4,233.94,110,200,2,1,233.39,233.98,10,44,1,3,233.31,234.0,110,154,2,7,233.3,234.13,100,400,1,1,233.25,234.17,55,1,2,1,AAPL,-312,-2.1330902461257972,0.02753467870092371
2024-10-21T12:01:50.803616384Z,2024-10-21T12:01:50.803449763Z,10,2,38,A,B,5,233.43,28,130,166621,11760608,233.59,233.74,1,1,1,1,233.58,233.77,500,200,1,1,233.53,233.78,10,150,1,2,233.5,233.8,400,25,1,1,233.45,233.84,15,28,1,1,233.43,233.94,28,200,1,1,233.4,233.98,110,44,2,3,233.39,234.0,10,154,1,7,233.31,234.13,110,400,2,1,233.3,234.17,100,1,1,1,AAPL,-212,-1.4806804100484396,0.019113143207833777
2024-10-21T12:01:59.276634577Z,2024-10-21T12:01:59.276468415Z,10,2,38,C,B,0,233.59,1,130,166162,11767546,233.58,233.74,500,1,1,1,233.53,233.77,10,200,1,1,233.5,233.78,400,150,1,2,233.45,233.8,15,25,1,1,233.43,233.84,28,28,1,1,233.4,233.94,110,200,2,1,233.39,233.98,10,44,1,3,233.31,234.0,110,154,2,7,233.3,234.13,100,400,1,1,233.25,234.17,55,1,2,1,AAPL,-461,-5.667306953515175,0.07315559027470626
2024-10-21T12:01:59.277728883Z,2024-10-21T12:01:59.277562747Z,10,2,38,A,B,0,233.6,1,130,166136,11767548,233.6,233.74,1,1,1,1,233.58,233.77,500,200,1,1,233.53,233.78,10,150,1,2,233.5,233.8,400,25,1,1,233.45,233.84,15,28,1,1,233.43,233.94,28,200,1,1,233.4,233.98,110,44,2,3,233.39,234.0,10,154,1,7,233.31,234.13,110,400,2,1,233.3,234.17,100,1,1,1,AAPL,-361,-4.539201183431953,0.05859360445328321
2024-10-21T12:02:01.448205203Z,2024-10-21T12:02:01.448038651Z,10,2,38,C,A,0,233.74,1,130,166552,11770015,233.6,233.77,1,200,1,1,233.58,233.78,500,150,1,2,233.53,233.8,10,25,1,1,233.5,233.84,400,28,1,1,233.45,233.94,15,200,1,1,233.43,233.98,28,44,1,3,233.4,234.0,110,154,2,7,233.39,234.13,10,400,1,1,233.31,234.17,110,1,2,1,233.3,234.41,100,600,1,2,AAPL,239,2.527614571092832,-0.032627337367098816
2024-10-21T12:02:05.406703925Z,2024-10-21T12:02:05.406537956Z,10,2,38,C,A,0,233.77,200,130,165969,11773218,233.6,233.78,1,150,1,2,233.58,233.8,500,25,1,1,233.53,233.84,10,28,1,1,233.5,233.94,400,200,1,1,233.45,233.98,15,44,1,3,233.43,234.0,28,154,1,7,233.4,234.13,110,400,2,1,233.39,234.17,10,1,1,1,233.31,234.41,110,600,2,2,233.3,234.43,100,5,1,1,AAPL,795,11.598784194528875,-0.14972118347911206
2024-10-21T12:02:05.406716483Z,2024-10-21T12:02:05.406550192Z,10,2,38,A,A,1,233.79,200,130,166291,11773219,233.6,233.78,1,150,1,2,233.58,233.79,500,200,1,1,233.53,233.8,10,25,1,1,233.5,233.84,400,28,1,1,233.45,233.94,15,200,1,1,233.43,233.98,28,44,1,3,233.4,234.0,110,154,2,7,233.39,234.13,10,400,1,1,233.31,234.17,110,1,2,1,233.3,234.41,100,600,1,2,AAPL,195,2.162046908315565,-0.02790846147504429
2024-10-21T12:02:05.521557542Z,2024-10-21T12:02:05.521390954Z,10,2,38,A,A,0,233.78,200,130,166588,11773477,233.6,233.78,1,350,1,3,233.58,233.8,500,25,1,1,233.53,233.84,10,28,1,1,233.5,233.94,400,200,1,1,233.45,233.98,15,44,1,3,233.43,234.0,28,154,1,7,233.4,234.13,110,400,2,1,233.39,234.17,10,1,1,1,233.31,234.41,110,600,2,2,233.3,234.43,100,5,1,1,AAPL,200,2.2857142857142856,-0.029504803452906785
2024-10-21T12:02:07.782965431Z,2024-10-21T12:02:07.782798949Z,10,2,38,A,A,0,233.77,200,130,166482,11776121,233.6,233.77,1,200,1,1,233.58,233.78,500,150,1,2,233.53,233.8,10,25,1,1,233.5,233.84,400,28,1,1,233.45,233.94,15,200,1,1,233.43,233.98,28,44,1,3,233.4,234.0,110,154,2,7,233.39,234.13,10,400,1,1,233.31,234.17,110,1,2,1,233.3,234.41,100,600,1,2,AAPL,-410,-3.6283185840707963,0.04683561167579783
2024-10-21T12:02:17.703635930Z,2024-10-21T12:02:17.703470063Z,10,2,38,C,A,0,233.77,200,130,165867,11784564,233.6,233.78,1,150,1,2,233.58,233.8,500,25,1,1,233.53,233.84,10,28,1,1,233.5,233.94,400,200,1,1,233.45,233.98,15,44,1,3,233.43,234.0,28,154,1,7,233.4,234.13,110,400,2,1,233.39,234.17,10,1,1,1,233.31,234.41,110,600,2,2,233.3,234.43,100,5,1,1,AAPL,-540,-3.3592534992223952,0.04336242498133268
2024-10-21T12:02:17.703649148Z,2024-10-21T12:02:17.703482613Z,10,2,38,A,A,1,233.79,200,130,166535,11784566,233.6,233.78,1,150,1,2,233.58,233.79,500,200,1,1,233.53,233.8,10,25,1,1,233.5,233.84,400,28,1,1,233.45,233.94,15,200,1,1,233.43,233.98,28,44,1,3,233.4,234.0,110,154,2,7,233.39,234.13,10,400,1,1,233.31,234.17,110,1,2,1,233.3,234.41,100,600,1,2,AAPL,-1140,-6.271393643031785,0.08095335360588957
2024-10-21T12:02:17.758238230Z,2024-10-21T12:02:17.758071973Z,10,2,38,A,B,3,233.51,400,130,166257,11784675,233.6,233.78,1,150,1,2,233.58,233.79,500,200,1,1,233.53,233.8,10,25,1,1,233.51,233.84,400,28,1,1,233.45,233.94,15,200,1,1,233.43,233.98,28,44,1,3,233.4,234.0,110,154,2,7,233.39,234.13,10,400,1,1,233.31,234.17,110,1,2,1,233.3,234.41,100,600,1,2,AAPL,-1140,-5.740181268882175,0.07409627755356121
2024-10-21T12:02:17.837953734Z,2024-10-21T12:02:17.837786779Z,10,2,38,A,A,1,233.79,200,130,166955,11784898,233.6,233.78,1,150,1,2,233.58,233.79,500,400,1,2,233.53,233.8,10,25,1,1,233.51,233.84,400,28,1,1,233.45,233.94,15,200,1,1,233.43,233.98,28,44,1,3,233.4,234.0,110,154,2,7,233.39,234.13,10,400,1,1,233.31,234.17,110,1,2,1,233.3,234.41,100,600,1,2,AAPL,-1140,-5.368150684931506,0.06929397600321481
2024-10-21T12:02:18.878285269Z,2024-10-21T12:02:18.878119302Z,10,2,38,C,B,5,233.43,28,130,165967,11786478,233.6,233.78,1,150,1,2,233.58,233.79,500,400,1,2,233.53,233.8,10,25,1,1,233.51,233.84,400,28,1,1,233.45,233.94,15,200,1,1,233.4,233.98,110,44,2,3,233.39,234.0,10,154,1,7,233.31,234.13,110,400,2,1,233.3,234.17,100,1,1,1,233.25,234.41,55,600,2,2,AAPL,-1195,-5.383893373380889,0.06949718815944206
2024-10-21T12:02:18.878320710Z,2024-10-21T12:02:18.878154633Z,10,2,38,A,A,4,233.86,29,130,166077,11786480,233.6,233.78,1,150,1,2,233.58,233.79,500,400,1,2,233.53,233.8,10,25,1,1,233.51,233.84,400,28,1,1,233.45,233.86,15,29,1,1,233.4,233.94,110,200,2,1,233.39,233.98,10,44,1,3,233.31,234.0,110,154,2,7,233.3,234.13,100,400,1,1,233.25,234.17,55,1,2,1,AAPL,-1196,-5.7767044399033995,0.07456773148338665
2024-10-21T12:02:18.939708856Z,2024-10-21T12:02:18.939543004Z,10,2,38,C,A,3,233.84,28,130,165852,11786586,233.6,233.78,1,150,1,2,233.58,233.79,500,400,1,2,233.53,233.8,10,25,1,1,233.51,233.86,400,29,1,1,233.45,233.94,15,200,1,1,233.4,233.98,110,44,2,3,233.39,234.0,10,154,1,7,233.31,234.13,110,400,2,1,233.3,234.17,100,1,1,1,233.25,234.41,55,600,2,2,AAPL,-596,-2.7638290824776415,0.035676477311969594
2024-10-21T12:02:30.307328523Z,2024-10-21T12:02:30.307162147Z,10,2,38,A,B,5,233.43,29,130,166376,11794146,233.6,233.78,1,150,1,2,233.58,233.79,500,400,1,2,233.53,233.8,10,25,1,1,233.51,233.86,400,29,1,1,233.45,233.94,15,200,1,1,233.43,233.98,29,44,1,3,233.4,234.0,110,154,2,7,233.39,234.13,10,400,1,1,233.31,234.17,110,1,2,1,233.3,234.41,100,600,1,2,AAPL,49,0.1835635682509951,-0.0023695030635324343
2024-10-21T12:02:44.176454629Z,2024-10-21T12:02:44.176288366Z,10,2,38,A,B,0,233.6,100,130,166263,11806117,233.6,233.78,101,150,2,2,233.58,233.79,500,400,1,2,233.53,233.8,10,25,1,1,233.51,233.86,400,29,1,1,233.45,233.94,15,200,1,1,233.43,233.98,29,44,1,3,233.4,234.0,110,154,2,7,233.39,234.13,10,400,1,1,233.31,234.17,110,1,2,1,233.3,234.41,100,600,1,2,AAPL,100,0.2857142857142857,-0.003688100431613348
2024-10-21T12:02:44.176788700Z,2024-10-21T12:02:44.176621537Z,10,2,38,C,B,0,233.6,100,130,167163,11806118,233.6,233.78,1,150,1,2,233.58,233.79,500,400,1,2,233.53,233.8,10,25,1,1,233.51,233.86,400,29,1,1,233.45,233.94,15,200,1,1,233.43,233.98,29,44,1,3,233.4,234.0,110,154,2,7,233.39,234.13,10,400,1,1,233.31,234.17,110,1,2,1,233.3,234.41,100,600,1,2,AAPL,100,0.2857142857142857,-0.003688100431613348
2024-10-21T12:02:48.812888135Z,2024-10-21T12:02:48.812722097Z,10,2,38,C,B,0,233.6,1,130,166038,11809007,233.58,233.78,500,150,1,2,233.53,233.79,10,400,1,2,233.51,233.8,400,25,1,1,233.45,233.86,15,29,1,1,233.43,233.94,29,200,1,1,233.4,233.98,110,44,2,3,233.39,234.0,10,154,1,7,233.31,234.13,110,400,2,1,233.3,234.17,100,1,1,1,233.25,234.41,55,600,2,2,AAPL,45,0.1306715063520871,-0.0016867537364184458
2024-10-21T12:02:48.884031773Z,2024-10-21T12:02:48.883865862Z,10,2,38,C,B,2,233.51,400,130,165911,11809083,233.58,233.78,500,150,1,2,233.53,233.79,10,400,1,2,233.45,233.8,15,25,1,1,233.43,233.86,29,29,1,1,233.4,233.94,110,200,2,1,233.39,233.98,10,44,1,3,233.31,234.0,110,154,2,7,233.3,234.13,100,400,1,1,233.25,234.17,55,1,2,1,233.24,234.41,1,600,1,2,AAPL,44,0.13110846245530391,-0.0016923941193934908
2024-10-21T12:02:48.884046853Z,2024-10-21T12:02:48.883880917Z,10,2,38,A,B,2,233.48,200,130,165936,11809084,233.58,233.78,500,150,1,2,233.53,233.79,10,400,1,2,233.48,233.8,200,25,1,1,233.45,233.86,15,29,1,1,233.43,233.94,29,200,1,1,233.4,233.98,110,44,2,3,233.39,234.0,10,154,1,7,233.31,234.13,110,400,2,1,233.3,234.17,100,1,1,1,233.25,234.41,55,600,2,2,AAPL,99,0.2961854899027674,-0.0038232664160180257
2024-10-21T12:02:49.759499338Z,2024-10-21T12:02:49.759332649Z,10,2,38,A,B,2,233.51,200,130,166689,11810239,233.58,233.78,500,150,1,2,233.53,233.79,10,400,1,2,233.51,233.8,200,25,1,1,233.45,233.86,15,29,1,1,233.43,233.94,29,200,1,1,233.4,233.98,110,44,2,3,233.39,234.0,10,154,1,7,233.31,234.13,110,400,2,1,233.3,234.17,100,1,1,1,233.25,234.41,55,600,2,2,AAPL,99,0.2970424346335191,-0.003834328159827765
2024-10-21T12:02:54.518778131Z,2024-10-21T12:02:54.518612296Z,10,2,38,C,A,1,233.79,200,130,165835,11814397,233.58,233.78,500,150,1,2,233.53,233.79,10,200,1,1,233.51,233.8,200,25,1,1,233.45,233.86,15,29,1,1,233.43,233.94,29,200,1,1,233.4,233.98,110,44,2,3,233.39,234.0,10,154,1,7,233.31,234.13,110,400,2,1,233.3,234.17,100,1,1,1,233.25,234.41,55,600,2,2,AAPL,-1,-0.003029647262497295,3.910775181758365e-05
2024-10-21T12:02:54.518790915Z,2024-10-21T12:02:54.518624596Z,10,2,38,A,A,0,233.78,400,130,166319,11814398,233.58,233.78,500,550,1,3,233.53,233.8,10,25,1,1,233.51,233.86,200,29,1,1,233.45,233.94,15,200,1,1,233.43,233.98,29,44,1,3,233.4,234.0,110,154,2,7,233.39,234.13,10,400,1,1,233.31,234.17,110,1,2,1,233.3,234.41,100,600,1,2,233.25,234.43,55,5,2,1,AAPL,4,0.013672292245246742,-0.0001764867542579342
2024-10-21T12:02:54.524106300Z,2024-10-21T12:02:54.523940080Z,10,2,38,A,A,2,233.85,26,130,166220,11814473,233.58,233.78,500,550,1,3,233.53,233.8,10,25,1,1,233.51,233.85,200,26,1,1,233.45,233.86,15,29,1,1,233.43,233.94,29,200,1,1,233.4,233.98,110,44,2,3,233.39,234.0,10,154,1,7,233.31,234.13,110,400,2,1,233.3,234.17,100,1,1,1,233.25,234.41,55,600,2,2,AAPL,-596,-2.0104947526236883,0.02595217297717729
2024-10-21T12:02:54.524183296Z,2024-10-21T12:02:54.524017462Z,10,2,38,C,A,3,233.86,29,130,165834,11814475,233.58,233.78,500,550,1,3,233.53,233.8,10,25,1,1,233.51,233.85,200,26,1,1,233.45,233.94,15,200,1,1,233.43,233.98,29,44,1,3,233.4,234.0,110,154,2,7,233.39,234.13,10,400,1,1,233.31,234.17,110,1,2,1,233.3,234.41,100,600,1,2,233.25,234.43,55,5,2,1,AAPL,-591,-2.190511489992587,0.028275892300934802
2024-10-21T12:02:56.706794368Z,2024-10-21T12:02:56.706628033Z,10,2,38,C,B,2,233.51,200,130,166335,11816088,233.58,233.78,500,550,1,3,233.53,233.8,10,25,1,1,233.45,233.85,15,26,1,1,233.43,233.94,29,200,1,1,233.4,233.98,110,44,2,3,233.39,234.0,10,154,1,7,233.31,234.13,110,400,2,1,233.3,234.17,100,1,1,1,233.25,234.41,55,600,2,2,233.24,234.43,1,5,1,1,AAPL,-592,-2.4109589041095894,0.031121505011970172
2024-10-21T12:02:56.706805799Z,2024-10-21T12:02:56.706639645Z,10,2,38,A,B,2,233.49,200,130,166154,11816089,233.58,233.78,500,550,1,3,233.53,233.8,10,25,1,1,233.49,233.85,200,26,1,1,233.45,233.94,15,200,1,1,233.43,233.98,29,44,1,3,233.4,234.0,110,154,2,7,233.39,234.13,10,400,1,1,233.31,234.17,110,1,2,1,233.3,234.41,100,600,1,2,233.25,234.43,55,5,2,1,AAPL,-537,-2.3595752471622116,0.030458226706190934
2024-10-21T12:02:56.761583278Z,2024-10-21T12:02:56.761416724Z,10,2,38,A,A,0,233.77,200,130,166554,11816211,233.58,233.77,500,200,1,1,233.53,233.78,10,150,1,2,233.49,233.8,200,25,1,1,233.45,233.85,15,26,1,1,233.43,233.94,29,200,1,1,233.4,233.98,110,44,2,3,233.39,234.0,10,154,1,7,233.31,234.13,110,400,2,1,233.3,234.17,100,1,1,1,233.25,234.41,55,600,2,2,AAPL,-1137,-4.832761157430113,0.06238297978710778
2024-10-21T12:02:56.763195832Z,2024-10-21T12:02:56.763029737Z,10,2,38,A,B,2,233.49,200,130,166095,11816232,233.58,233.77,500,200,1,1,233.53,233.78,10,150,1,2,233.49,233.8,400,25,2,1,233.45,233.85,15,26,1,1,233.43,233.94,29,200,1,1,233.4,233.98,110,44,2,3,233.39,234.0,10,154,1,7,233.31,234.13,110,400,2,1,233.3,234.17,100,1,1,1,233.25,234.41,55,600,2,2,AAPL,-1137,-4.701122268163024,0.06068373873197709
2024-10-21T12:02:56.828759239Z,2024-10-21T12:02:56.828592562Z,10,2,38,A,A,3,233.84,29,130,166677,11816538,233.58,233.77,500,200,1,1,233.53,233.78,10,150,1,2,233.49,233.8,400,25,2,1,233.45,233.84,15,29,1,1,233.43,233.85,29,26,1,1,233.4,233.94,110,200,2,1,233.39,233.98,10,44,1,3,233.31,234.0,110,154,2,7,233.3,234.13,100,400,1,1,233.25,234.17,55,1,2,1,AAPL,-1138,-5.0,0.06454175755323359
2024-10-21T12:02:56.828796257Z,2024-10-21T12:02:56.828630121Z,10,2,38,C,A,4,233.85,26,130,166136,11816539,233.58,233.77,500,200,1,1,233.53,233.78,10,150,1,2,233.49,233.8,400,25,2,1,233.45,233.84,15,29,1,1,233.43,233.94,29,200,1,1,233.4,233.98,110,44,2,3,233.39,234.0,10,154,1,7,233.31,234.13,110,400,2,1,233.3,234.17,100,1,1,1,233.25,234.41,55,600,2,2,AAPL,-538,-2.3006815448349593,0.02969800609478737
2024-10-21T12:02:58.875252013Z,2024-10-21T12:02:58.875085988Z,10,2,38,C,B,2,233.49,200,130,166025,11818220,233.58,233.77,500,200,1,1,233.53,233.78,10,150,1,2,233.49,233.8,200,25,1,1,233.45,233.84,15,29,1,1,233.43,233.94,29,200,1,1,233.4,233.98,110,44,2,3,233.39,234.0,10,154,1,7,233.31,234.13,110,400,2,1,233.3,234.17,100,1,1,1,233.25,234.41,55,600,2,2,AAPL,-538,-2.2477267141803883,0.029014446526511396
2024-10-21T12:02:58.875264160Z,2024-10-21T12:02:58.875097976Z,10,2,38,A,B,2,233.5,400,130,166184,11818221,233.58,233.77,500,200,1,1,233.53,233.78,10,150,1,2,233.5,233.8,400,25,1,1,233.45,233.84,15,29,1,1,233.43,233.94,29,200,1,1,233.4,233.98,110,44,2,3,233.39,234.0,10,154,1,7,233.31,234.13,110,400,2,1,233.3,234.17,100,1,1,1,233.25,234.41,55,600,2,2,AAPL,-538,-2.202661207778915,0.028432725128875878
2024-10-21T12:02:59.629858436Z,2024-10-21T12:02:59.629692844Z,10,2,38,C,B,2,233.5,400,130,165592,11818945,233.58,233.77,500,200,1,1,233.53,233.78,10,150,1,2,233.45,233.8,15,25,1,1,233.43,233.84,29,29,1,1,233.4,233.94,110,200,2,1,233.39,233.98,10,44,1,3,233.31,234.0,110,154,2,7,233.3,234.13,100,400,1,1,233.25,234.17,55,1,2,1,233.24,234.41,1,600,1,2,AAPL,-539,-2.180327868852459,0.028144438539606777
2024-10-21T12:02:59.629870364Z,2024-10-21T12:02:59.629704420Z,10,2,38,A,B,2,233.49,400,130,165944,11818946,233.58,233.77,500,200,1,1,233.53,233.78,10,150,1,2,233.49,233.8,400,25,1,1,233.45,233.84,15,29,1,1,233.43,233.94,29,200,1,1,233.4,233.98,110,44,2,3,233.39,234.0,10,154,1,7,233.31,234.13,110,400,2,1,233.3,234.17,100,1,1,1,233.25,234.41,55,600,2,2,AAPL,-484,-1.9265598567021596,0.024868711836612645
2024-10-21T12:03:04.465282370Z,2024-10-21T12:03:04.465116162Z,10,2,38,A,B,2,233.5,400,130,166208,11824666,233.58,233.77,500,200,1,1,233.53,233.78,10,150,1,2,233.5,233.8,400,25,1,1,233.45,233.84,15,29,1,1,233.43,233.94,29,200,1,1,233.4,233.98,110,44,2,3,233.39,234.0,10,154,1,7,233.31,234.13,110,400,2,1,233.3,234.17,100,1,1,1,233.25,234.41,55,600,2,2,AAPL,-484,-1.9767841788478073,0.025517025041252625
2024-10-21T12:03:23.013424282Z,2024-10-21T12:03:23.013257512Z,10,2,38,C,B,2,233.5,400,130,166770,11850697,233.58,233.77,500,200,1,1,233.53,233.78,10,150,1,2,233.45,233.8,15,25,1,1,233.43,233.84,29,29,1,1,233.4,233.94,110,200,2,1,233.39,233.98,10,44,1,3,233.31,234.0,110,154,2,7,233.3,234.13,100,400,1,1,233.25,234.17,55,1,2,1,233.24,234.41,1,600,1,2,AAPL,-1,-0.0031847133757961785,4.110939971543541e-05
2024-10-21T12:03:23.013436299Z,2024-10-21T12:03:23.013270046Z,10,2,38,A,B,2,233.48,400,130,166253,11850699,233.58,233.77,500,200,1,1,233.53,233.78,10,150,1,2,233.48,233.8,400,25,1,1,233.45,233.84,15,29,1,1,233.43,233.94,29,200,1,1,233.4,233.98,110,44,2,3,233.39,234.0,10,154,1,7,233.31,234.13,110,400,2,1,233.3,234.17,100,1,1,1,233.25,234.41,55,600,2,2,AAPL,54,0.1695447409733124,-0.002188543113265064
2024-10-21T12:03:36.462407761Z,2024-10-21T12:03:36.462240600Z,10,2,38,A,A,0,233.76,200,130,167161,11869933,233.58,233.76,500,200,1,1,233.53,233.78,10,150,1,2,233.48,233.8,400,25,1,1,233.45,233.84,15,29,1,1,233.43,233.94,29,200,1,1,233.4,233.98,110,44,2,3,233.39,234.0,10,154,1,7,233.31,234.13,110,400,2,1,233.3,234.17,100,1,1,1,233.25,234.41,55,600,2,2,AAPL,54,0.1695447409733124,-0.002188543113265064
2024-10-21T12:03:36.477423785Z,2024-10-21T12:03:36.477257436Z,10,2,38,A,B,5,233.4,28,130,166349,11870139,233.58,233.76,500,200,1,1,233.53,233.78,10,150,1,2,233.48,233.8,400,25,1,1,233.45,233.84,15,29,1,1,233.43,233.94,29,200,1,1,233.4,233.98,138,44,3,3,233.39,234.0,10,154,1,7,233.31,234.13,110,400,2,1,233.3,234.17,100,1,1,1,233.25,234.41,55,600,2,2,AAPL,54,0.16835541699142634,-0.002173190901246836
2024-10-21T12:03:36.477651445Z,2024-10-21T12:03:36.477483536Z,10,2,38,C,B,4,233.43,29,130,167909,11870145,233.58,233.76,500,200,1,1,233.53,233.78,10,150,1,2,233.48,233.8,400,25,1,1,233.45,233.84,15,29,1,1,233.4,233.94,138,200,3,1,233.39,233.98,10,44,1,3,233.31,234.0,110,154,2,7,233.3,234.13,100,400,1,1,233.25,234.17,55,1,2,1,233.24,234.41,1,600,1,2,AAPL,53,0.16735080517840228,-0.0021602230188325737
2024-10-21T12:03:36.477692453Z,2024-10-21T12:03:36.477526397Z,10,2,38,C,A,3,233.84,29,130,166056,11870147,233.58,233.76,500,200,1,1,233.53,233.78,10,150,1,2,233.48,233.8,400,25,1,1,233.45,233.94,15,200,1,1,233.4,233.98,138,44,3,3,233.39,234.0,10,154,1,7,233.31,234.13,110,400,2,1,233.3,234.17,100,1,1,1,233.25,234.41,55,600,2,2,233.24,234.43,1,5,1,1,AAPL,58,0.21935077213993065,-0.002831456870913998
2024-10-21T12:03:36.477737613Z,2024-10-21T12:03:36.477570977Z,10,2,38,A,A,3,233.83,27,130,166636,11870149,233.58,233.76,500,200,1,1,233.53,233.78,10,150,1,2,233.48,233.8,400,25,1,1,233.45,233.83,15,27,1,1,233.4,233.94,138,200,3,1,233.39,233.98,10,44,1,3,233.31,234.0,110,154,2,7,233.3,234.13,100,400,1,1,233.25,234.17,55,1,2,1,233.24,234.41,1,600,1,2,AAPL,-542,-2.010598834128246,0.025953516497823872
2024-10-21T12:03:37.923082663Z,2024-10-21T12:03:37.922916443Z,10,2,38,C,A,3,233.83,27,130,166220,11873649,233.58,233.76,500,200,1,1,233.53,233.78,10,150,1,2,233.48,233.8,400,25,1,1,233.45,233.94,15,200,1,1,233.4,233.98,138,44,3,3,233.39,234.0,10,154,1,7,233.31,234.13,110,400,2,1,233.3,234.17,100,1,1,1,233.25,234.41,55,600,2,2,233.24,234.43,1,5,1,1,AAPL,-537,-2.273015873015873,0.029340887878168413
2024-10-21T12:03:37.923156406Z,2024-10-21T12:03:37.922990125Z,10,2,38,A,A,3,233.82,27,130,166281,11873650,233.58,233.76,500,200,1,1,233.53,233.78,10,150,1,2,233.48,233.8,400,25,1,1,233.45,233.82,15,27,1,1,233.4,233.94,138,200,3,1,233.39,233.98,10,44,1,3,233.31,234.0,110,154,2,7,233.3,234.13,100,400,1,1,233.25,234.17,55,1,2,1,233.24,234.41,1,600,1,2,AAPL,-1137,-4.671536178954577,0.06030183109264912
2024-10-21T12:03:38.391279949Z,2024-10-21T12:03:38.391113474Z,10,2,38,A,B,0,233.66,1,130,166475,11873925,233.66,233.76,1,200,1,1,233.58,233.78,500,150,1,2,233.53,233.8,10,25,1,1,233.48,233.82,400,27,1,1,233.45,233.94,15,200,1,1,233.4,233.98,138,44,3,3,233.39,234.0,10,154,1,7,233.31,234.13,110,400,2,1,233.3,234.17,100,1,1,1,233.25,234.41,55,600,2,2,AAPL,-1082,-4.297061159650516,0.055467975911516074
2024-10-21T12:03:38.520252527Z,2024-10-21T12:03:38.520085682Z,10,2,38,A,B,5,233.41,27,130,166845,11874245,233.66,233.76,1,200,1,1,233.58,233.78,500,150,1,2,233.53,233.8,10,25,1,1,233.48,233.82,400,27,1,1,233.45,233.94,15,200,1,1,233.41,233.98,27,44,1,3,233.4,234.0,138,154,3,7,233.39,234.13,10,400,1,1,233.31,234.17,110,1,2,1,233.3,234.41,100,600,1,2,AAPL,-982,-3.766387726638772,0.048617856700838846
2024-10-21T12:03:38.520281859Z,2024-10-21T12:03:38.520115737Z,10,2,38,C,B,6,233.4,28,130,166122,11874246,233.66,233.76,1,200,1,1,233.58,233.78,500,150,1,2,233.53,233.8,10,25,1,1,233.48,233.82,400,27,1,1,233.45,233.94,15,200,1,1,233.41,233.98,27,44,1,3,233.4,234.0,110,154,2,7,233.39,234.13,10,400,1,1,233.31,234.17,110,1,2,1,233.3,234.41,100,600,1,2,AAPL,-982,-3.661901802361715,0.04726911566235579
2024-10-21T12:03:55.424297621Z,2024-10-21T12:03:55.424131689Z,10,2,38,C,B,5,233.41,27,130,165932,11897535,233.66,233.76,1,200,1,1,233.58,233.78,500,150,1,2,233.53,233.8,10,25,1,1,233.48,233.82,400,27,1,1,233.45,233.94,15,200,1,1,233.4,233.98,110,44,2,3,233.39,234.0,10,154,1,7,233.31,234.13,110,400,2,1,233.3,234.17,100,1,1,1,233.25,234.41,55,600,2,2,AAPL,-1091,-4.1134532990574115,0.053097901106862466
2024-10-21T12:03:55.424354377Z,2024-10-21T12:03:55.424188038Z,10,2,38,A,B,5,233.42,30,130,166339,11897536,233.66,233.76,1,200,1,1,233.58,233.78,500,150,1,2,233.53,233.8,10,25,1,1,233.48,233.82,400,27,1,1,233.45,233.94,15,200,1,1,233.42,233.98,30,44,1,3,233.4,234.0,110,154,2,7,233.39,234.13,10,400,1,1,233.31,234.17,110,1,2,1,233.3,234.41,100,600,1,2,AAPL,-991,-3.639479724560061,0.04697968360049296
2024-10-21T12:03:55.618384707Z,2024-10-21T12:03:55.618218602Z,10,2,38,C,A,0,233.76,200,130,166105,11897697,233.66,233.78,1,150,1,2,233.58,233.8,500,25,1,1,233.53,233.82,10,27,1,1,233.48,233.94,400,200,1,1,233.45,233.98,15,44,1,3,233.42,234.0,30,154,1,7,233.4,234.13,110,400,2,1,233.39,234.17,10,1,1,1,233.31,234.41,110,600,2,2,233.3,234.43,100,5,1,1,AAPL,-986,-3.8608433734939758,0.049837123392611336
2024-10-21T12:03:55.618397628Z,2024-10-21T12:03:55.618231402Z,10,2,38,A,A,0,233.78,200,130,166226,11897698,233.66,233.78,1,350,1,3,233.58,233.8,500,25,1,1,233.53,233.82,10,27,1,1,233.48,233.94,400,200,1,1,233.45,233.98,15,44,1,3,233.42,234.0,30,154,1,7,233.4,234.13,110,400,2,1,233.39,234.17,10,1,1,1,233.31,234.41,110,600,2,2,233.3,234.43,100,5,1,1,AAPL,-986,-4.093106004447739,0.05283525107575012
2024-10-21T12:03:55.674543945Z,2024-10-21T12:03:55.674377683Z,10,2,38,A,B,3,233.49,400,130,166262,11897798,233.66,233.78,1,350,1,3,233.58,233.8,500,25,1,1,233.53,233.82,10,27,1,1,233.49,233.94,400,200,1,1,233.45,233.98,15,44,1,3,233.42,234.0,30,154,1,7,233.4,234.13,110,400,2,1,233.39,234.17,10,1,1,1,233.31,234.41,110,600,2,2,233.3,234.43,100,5,1,1,AAPL,-986,-4.3182481751824815,0.05574146535546422
2024-10-21T12:03:55.688611614Z,2024-10-21T12:03:55.688445687Z,10,2,38,C,A,2,233.82,27,130,165927,11897840,233.66,233.78,1,350,1,3,233.58,233.8,500,25,1,1,233.53,233.94,10,200,1,1,233.49,233.98,400,44,1,3,233.45,234.0,15,154,1,7,233.42,234.13,30,400,1,1,233.4,234.17,110,1,2,1,233.39,234.41,10,600,1,2,233.31,234.43,110,5,2,1,233.3,234.5,100,63,1,4,AAPL,-923,-4.211607015542564,0.05436490378132917
2024-10-21T12:03:55.688655741Z,2024-10-21T12:03:55.688489469Z,10,2,38,A,A,2,233.85,27,130,166272,11897841,233.66,233.78,1,350,1,3,233.58,233.8,500,25,1,1,233.53,233.85,10,27,1,1,233.49,233.94,400,200,1,1,233.45,233.98,15,44,1,3,233.42,234.0,30,154,1,7,233.4,234.13,110,400,2,1,233.39,234.17,10,1,1,1,233.31,234.41,110,600,2,2,233.3,234.43,100,5,1,1,AAPL,-928,-4.432705816240517,0.05721892481932077
2024-10-21T12:03:55.728613443Z,2024-10-21T12:03:55.728447009Z,10,2,38,A,A,0,233.77,200,130,166434,11897883,233.66,233.77,1,200,1,1,233.58,233.78,500,150,1,2,233.53,233.8,10,25,1,1,233.49,233.85,400,27,1,1,233.45,233.94,15,200,1,1,233.42,233.98,30,44,1,3,233.4,234.0,110,154,2,7,233.39,234.13,10,400,1,1,233.31,234.17,110,1,2,1,233.3,234.41,100,600,1,2,AAPL,-1528,-7.03607060629317,0.09082407263976142
2024-10-21T12:03:56.332391241Z,2024-10-21T12:03:56.332225034Z,10,2,38,C,B,5,233.42,30,130,166207,11898284,233.66,233.77,1,200,1,1,233.58,233.78,500,150,1,2,233.53,233.8,10,25,1,1,233.49,233.85,400,27,1,1,233.45,233.94,15,200,1,1,233.4,233.98,110,44,2,3,233.39,234.0,10,154,1,7,233.31,234.13,110,400,2,1,233.3,234.17,100,1,1,1,233.25,234.41,55,600,2,2,AAPL,-1583,-7.099492505606042,0.0916427448095648
2024-10-21T12:03:56.332419452Z,2024-10-21T12:03:56.332253646Z,10,2,38,C,A,3,233.85,27,130,165806,11898285,233.66,233.77,1,200,1,1,233.58,233.78,500,150,1,2,233.53,233.8,10,25,1,1,233.49,233.94,400,200,1,1,233.45,233.98,15,44,1,3,233.4,234.0,110,154,2,7,233.39,234.13,10,400,1,1,233.31,234.17,110,1,2,1,233.3,234.41,100,600,1,2,233.25,234.43,55,5,2,1,AAPL,-1578,-7.397163951716864,0.09548519247064582
2024-10-21T12:03:56.332477635Z,2024-10-21T12:03:56.332311467Z,10,2,38,A,A,3,233.84,27,130,166168,11898286,233.66,233.77,1,200,1,1,233.58,233.78,500,150,1,2,233.53,233.8,10,25,1,1,233.49,233.84,400,27,1,1,233.45,233.94,15,200,1,1,233.4,233.98,110,44,2,3,233.39,234.0,10,154,1,7,233.31,234.13,110,400,2,1,233.3,234.17,100,1,1,1,233.25,234.41,55,600,2,2,AAPL,-2178,-9.956029603831084,0.1285159297766564
2024-10-21T12:03:56.332508686Z,2024-10-21T12:03:56.332342495Z,10,2,38,A,B,4,233.47,30,130,166191,11898287,233.66,233.77,1,200,1,1,233.58,233.78,500,150,1,2,233.53,233.8,10,25,1,1,233.49,233.84,400,27,1,1,233.47,233.94,30,200,1,1,233.45,233.98,15,44,1,3,233.4,234.0,110,154,2,7,233.39,234.13,10,400,1,1,233.31,234.17,110,1,2,1,233.3,234.41,100,600,1,2,AAPL,-2078,-9.246763754045308,0.11936047687312405
2024-10-21T12:03:56.389159167Z,2024-10-21T12:03:56.388992803Z,10,2,38,A,B,2,233.57,200,130,166364,11898316,233.66,233.77,1,200,1,1,233.58,233.78,500,150,1,2,233.57,233.8,200,25,1,1,233.53,233.84,10,27,1,1,233.47,233.94,30,200,1,1,233.45,233.98,15,44,1,3,233.4,234.0,110,154,2,7,233.39,234.13,10,400,1,1,233.31,234.17,110,1,2,1,233.3,234.41,100,600,1,2,AAPL,-2078,-9.02795617680393,0.11653603175289938
2024-10-21T12:03:56.896271800Z,2024-10-21T12:03:56.896105724Z,10,2,38,C,B,4,233.47,30,130,166076,11898637,233.66,233.77,1,200,1,1,233.58,233.78,500,150,1,2,233.57,233.8,200,25,1,1,233.53,233.84,10,27,1,1,233.45,233.94,15,200,1,1,233.4,233.98,110,44,2,3,233.39,234.0,10,154,1,7,233.31,234.13,110,400,2,1,233.3,234.17,100,1,1,1,233.25,234.41,55,600,2,2,AAPL,-1537,-6.6940974212034385,0.0864097625594077
2024-10-21T12:03:56.896375276Z,2024-10-21T12:03:56.896208906Z,10,2,38,A,B,4,233.52,28,130,166370,11898638,233.66,233.77,1,200,1,1,233.58,233.78,500,150,1,2,233.57,233.8,200,25,1,1,233.53,233.84,10,27,1,1,233.52,233.94,28,200,1,1,233.45,233.98,15,44,1,3,233.4,234.0,110,154,2,7,233.39,234.13,10,400,1,1,233.31,234.17,110,1,2,1,233.3,234.41,100,600,1,2,AAPL,-1437,-6.098673740053051,0.07872382438535526
2024-10-21T12:04:00.333582745Z,2024-10-21T12:04:00.333416396Z,10,2,38,A,B,1,233.58,200,130,166349,11905464,233.66,233.77,1,200,1,1,233.58,233.78,700,150,2,2,233.53,233.8,10,25,1,1,233.52,233.84,28,27,1,1,233.45,233.94,15,200,1,1,233.4,233.98,110,44,2,3,233.39,234.0,10,154,1,7,233.31,234.13,110,400,2,1,233.3,234.17,100,1,1,1,233.25,234.41,55,600,2,2,AAPL,-1052,-4.538150444863844,0.05858004115050028
2024-10-21T12:04:00.453772968Z,2024-10-21T12:04:00.453606564Z,10,2,38,A,B,2,233.53,27,130,166404,11905750,233.66,233.77,1,200,1,1,233.58,233.78,700,150,2,2,233.53,233.8,37,25,2,1,233.52,233.84,28,27,1,1,233.45,233.94,15,200,1,1,233.4,233.98,110,44,2,3,233.39,234.0,10,154,1,7,233.31,234.13,110,400,2,1,233.3,234.17,100,1,1,1,233.25,234.41,55,600,2,2,AAPL,-1052,-4.430571039266692,0.0571913683677458
2024-10-21T12:04:00.453798276Z,2024-10-21T12:04:00.453632315Z,10,2,38,C,B,3,233.52,28,130,165961,11905751,233.66,233.77,1,200,1,1,233.58,233.78,700,150,2,2,233.53,233.8,37,25,2,1,233.45,233.84,15,27,1,1,233.4,233.94,110,200,2,1,233.39,233.98,10,44,1,3,233.31,234.0,110,154,2,7,233.3,234.13,100,400,1,1,233.25,234.17,55,1,2,1,233.24,234.41,1,600,1,2,AAPL,-1053,-4.370302052109753,0.056413395096333384
2024-10-21T12:04:01.301630237Z,2024-10-21T12:04:01.301464181Z,10,2,38,A,B,1,233.65,18,130,166056,11906476,233.66,233.77,1,200,1,1,233.65,233.78,18,150,1,2,233.58,233.8,700,25,2,1,233.53,233.84,37,27,2,1,233.45,233.94,15,200,1,1,233.4,233.98,110,44,2,3,233.39,234.0,10,154,1,7,233.31,234.13,110,400,2,1,233.3,234.17,100,1,1,1,233.25,234.41,55,600,2,2,AAPL,-998,-4.065173116089613,0.05247468353411579
2024-10-21T12:04:01.372372505Z,2024-10-21T12:04:01.372206492Z,10,2,38,C,B,2,233.58,200,130,166013,11906511,233.66,233.77,1,200,1,1,233.65,233.78,18,150,1,2,233.58,233.8,500,25,1,1,233.53,233.84,37,27,2,1,233.45,233.94,15,200,1,1,233.4,233.98,110,44,2,3,233.39,234.0,10,154,1,7,233.31,234.13,110,400,2,1,233.3,234.17,100,1,1,1,233.25,234.41,55,600,2,2,AAPL,-998,-3.998397435897436,0.05161271958183264
2024-10-21T12:04:01.372385835Z,2024-10-21T12:04:01.372219216Z,10,2,38,A,B,3,233.55,400,130,166619,11906512,233.66,233.77,1,200,1,1,233.65,233.78,18,150,1,2,233.58,233.8,500,25,1,1,233.55,233.84,400,27,1,1,233.53,233.94,37,200,2,1,233.45,233.98,15,44,1,3,233.4,234.0,110,154,2,7,233.39,234.13,10,400,1,1,233.31,234.17,110,1,2,1,233.3,234.41,100,600,1,2,AAPL,-898,-3.5301385248970423,0.04556826896064691
2024-10-21T12:04:01.372962808Z,2024-10-21T12:04:01.372796891Z,10,2,38,C,B,4,233.53,27,130,165917,11906513,233.66,233.77,1,200,1,1,233.65,233.78,18,150,1,2,233.58,233.8,500,25,1,1,233.55,233.84,400,27,1,1,233.53,233.94,10,200,1,1,233.45,233.98,15,44,1,3,233.4,234.0,110,154,2,7,233.39,234.13,10,400,1,1,233.31,234.17,110,1,2,1,233.3,234.41,100,600,1,2,AAPL,-898,-3.470836261419536,0.04480277449830227
2024-10-21T12:04:01.644624077Z,2024-10-21T12:04:01.644457609Z,10,2,38,A,B,2,233.58,200,130,166468,11906692,233.66,233.77,1,200,1,1,233.65,233.78,18,150,1,2,233.58,233.8,700,25,2,1,233.53,233.84,10,27,1,1,233.45,233.94,15,200,1,1,233.4,233.98,110,44,2,3,233.39,234.0,10,154,1,7,233.31,234.13,110,400,2,1,233.3,234.17,100,1,1,1,233.25,234.41,55,600,2,2,AAPL,-953,-3.6413323365728054,0.04700359776756632
2024-10-21T12:04:05.632716292Z,2024-10-21T12:04:05.632550110Z,10,2,38,A,B,3,233.53,26,130,166182,11911165,233.66,233.77,1,200,1,1,233.65,233.78,18,150,1,2,233.58,233.8,700,25,2,1,233.53,233.84,36,27,2,1,233.45,233.94,15,200,1,1,233.4,233.98,110,44,2,3,233.39,234.0,10,154,1,7,233.31,234.13,110,400,2,1,233.3,234.17,100,1,1,1,233.25,234.41,55,600,2,2,AAPL,-953,-3.6035922483062865,0.04651643544217925
2024-10-21T12:04:12.155215428Z,2024-10-21T12:04:12.155049282Z,10,2,38,C,A,0,233.77,200,130,166146,11915766,233.66,233.78,1,150,1,2,233.65,233.8,18,25,1,1,233.58,233.84,700,27,2,1,233.53,233.94,36,200,2,1,233.45,233.98,15,44,1,3,233.4,234.0,110,154,2,7,233.39,234.13,10,400,1,1,233.31,234.17,110,1,2,1,233.3,234.41,100,600,1,2,233.25,234.43,55,5,2,1,AAPL,-948,-3.7164811039673826,0.04797364447268734
2024-10-21T12:04:12.156423591Z,2024-10-21T12:04:12.156256239Z,10,2,38,T,N,0,233.72,38,130,167352,11915773,233.66,233.78,1,150,1,2,233.65,233.8,18,25,1,1,233.58,233.84,700,27,2,1,233.53,233.94,36,200,2,1,233.45,233.98,15,44,1,3,233.4,234.0,110,154,2,7,233.39,234.13,10,400,1,1,233.31,234.17,110,1,2,1,233.3,234.41,100,600,1,2,233.25,234.43,55,5,2,1,AAPL,-948,-3.8470422974871235,0.04965897425228973
2024-10-21T12:04:12.260942337Z,2024-10-21T12:04:12.260774944Z,10,2,38,A,A,2,233.82,200,130,167393,11915806,233.66,233.78,1,150,1,2,233.65,233.8,18,25,1,1,233.58,233.82,700,200,2,1,233.53,233.84,36,27,2,1,233.45,233.94,15,200,1,1,233.4,233.98,110,44,2,3,233.39,234.0,10,154,1,7,233.31,234.13,110,400,2,1,233.3,234.17,100,1,1,1,233.25,234.41,55,600,2,2,AAPL,-1548,-6.20625139208553,0.08011247453248055
2024-10-21T12:04:16.431012384Z,2024-10-21T12:04:16.430845992Z,10,2,38,A,A,2,233.82,200,130,166392,11920715,233.66,233.78,1,150,1,2,233.65,233.8,18,25,1,1,233.58,233.82,700,400,2,2,233.53,233.84,36,27,2,1,233.45,233.94,15,200,1,1,233.4,233.98,110,44,2,3,233.39,234.0,10,154,1,7,233.31,234.13,110,400,2,1,233.3,234.17,100,1,1,1,233.25,234.41,55,600,2,2,AAPL,-506,-1.741624598439651,0.02248150251624795
2024-10-21T12:04:16.500019710Z,2024-10-21T12:04:16.499853888Z,10,2,38,C,B,2,233.58,200,130,165822,11920772,233.66,233.78,1,150,1,2,233.65,233.8,18,25,1,1,233.58,233.82,500,400,1,2,233.53,233.84,36,27,2,1,233.45,233.94,15,200,1,1,233.4,233.98,110,44,2,3,233.39,234.0,10,154,1,7,233.31,234.13,110,400,2,1,233.3,234.17,100,1,1,1,233.25,234.41,55,600,2,2,AAPL,-506,-1.727883897129442,0.02230413271373297
2024-10-21T12:04:16.509584729Z,2024-10-21T12:04:16.509417925Z,10,2,38,A,B,3,233.57,200,130,166804,11920777,233.66,233.78,1,150,1,2,233.65,233.8,18,25,1,1,233.58,233.82,500,400,1,2,233.57,233.84,200,27,1,1,233.53,233.94,36,200,2,1,233.45,233.98,15,44,1,3,233.4,234.0,110,154,2,7,233.39,234.13,10,400,1,1,233.31,234.17,110,1,2,1,233.3,234.41,100,600,1,2,AAPL,-406,-1.3706682553867542,0.01769306764501711
2024-10-21T12:04:19.069768586Z,2024-10-21T12:04:19.069602567Z,10,2,38,C,B,3,233.57,200,130,166019,11924539,233.66,233.78,1,150,1,2,233.65,233.8,18,25,1,1,233.58,233.82,500,400,1,2,233.53,233.84,36,27,2,1,233.45,233.94,15,200,1,1,233.4,233.98,110,44,2,3,233.39,234.0,10,154,1,7,233.31,234.13,110,400,2,1,233.3,234.17,100,1,1,1,233.25,234.41,55,600,2,2,AAPL,-506,-1.727883897129442,0.02230413271373297
2024-10-21T12:04:19.069781475Z,2024-10-21T12:04:19.069614798Z,10,2,38,A,B,3,233.54,400,130,166677,11924540,233.66,233.78,1,150,1,2,233.65,233.8,18,25,1,1,233.58,233.82,500,400,1,2,233.54,233.84,400,27,1,1,233.53,233.94,36,200,2,1,233.45,233.98,15,44,1,3,233.4,234.0,110,154,2,7,233.39,234.13,10,400,1,1,233.31,234.17,110,1,2,1,233.3,234.41,100,600,1,2,AAPL,-406,-1.3706682553867542,0.01769306764501711
2024-10-21T12:04:19.070763821Z,2024-10-21T12:04:19.070597243Z,10,2,38,C,B,4,233.53,26,130,166578,11924541,233.66,233.78,1,150,1,2,233.65,233.8,18,25,1,1,233.58,233.82,500,400,1,2,233.54,233.84,400,27,1,1,233.53,233.94,10,200,1,1,233.45,233.98,15,44,1,3,233.4,234.0,110,154,2,7,233.39,234.13,10,400,1,1,233.31,234.17,110,1,2,1,233.3,234.41,100,600,1,2,AAPL,-406,-1.3569770680531055,0.017516336986316258
2024-10-21T12:04:19.070807458Z,2024-10-21T12:04:19.070641181Z,10,2,38,A,B,5,233.47,28,130,166277,11924542,233.66,233.78,1,150,1,2,233.65,233.8,18,25,1,1,233.58,233.82,500,400,1,2,233.54,233.84,400,27,1,1,233.53,233.94,10,200,1,1,233.47,233.98,28,44,1,3,233.45,234.0,15,154,1,7,233.4,234.13,110,400,2,1,233.39,234.17,10,1,1,1,233.31,234.41,110,600,2,2,AAPL,-296,-0.9797056005574427,0.012646384268944717
2024-10-21T12:04:19.475154065Z,2024-10-21T12:04:19.474987580Z,10,2,38,A,B,3,233.57,200,130,166485,11924892,233.66,233.78,1,150,1,2,233.65,233.8,18,25,1,1,233.58,233.82,500,400,1,2,233.57,233.84,200,27,1,1,233.53,233.94,10,200,1,1,233.47,233.98,28,44,1,3,233.45,234.0,15,154,1,7,233.4,234.13,110,400,2,1,233.39,234.17,10,1,1,1,233.31,234.41,110,600,2,2,AAPL,-296,-0.9712082683947175,0.012536697718485534
2024-10-21T12:04:19.885077953Z,2024-10-21T12:04:19.884911653Z,10,2,38,C,B,5,233.47,28,130,166300,11925176,233.66,233.78,1,150,1,2,233.65,233.8,18,25,1,1,233.58,233.82,500,400,1,2,233.57,233.84,200,27,1,1,233.53,233.94,10,200,1,1,233.45,233.98,15,44,1,3,233.4,234.0,110,154,2,7,233.39,234.13,10,400,1,1,233.31,234.17,110,1,2,1,233.3,234.41,100,600,1,2,AAPL,-396,-1.2902024668373282,0.016654386961839747
2024-10-21T12:04:19.885215852Z,2024-10-21T12:04:19.885049397Z,10,2,38,A,B,5,233.52,29,130,166455,11925177,233.66,233.78,1,150,1,2,233.65,233.8,18,25,1,1,233.58,233.82,500,400,1,2,233.57,233.84,200,27,1,1,233.53,233.94,10,200,1,1,233.52,233.98,29,44,1,3,233.45,234.0,15,154,1,7,233.4,234.13,110,400,2,1,233.39,234.17,10,1,1,1,233.31,234.41,110,600,2,2,AAPL,-286,-0.9252260863171825,0.011943143549002153
2024-10-21T12:04:26.481227392Z,2024-10-21T12:04:26.481060587Z,10,2,38,C,B,3,233.57,200,130,166805,11934662,233.66,233.78,1,150,1,2,233.65,233.8,18,25,1,1,233.58,233.82,500,400,1,2,233.53,233.84,10,27,1,1,233.52,233.94,29,200,1,1,233.45,233.98,15,44,1,3,233.4,234.0,110,154,2,7,233.39,234.13,10,400,1,1,233.31,234.17,110,1,2,1,233.3,234.41,100,600,1,2,AAPL,-430,-1.4384707287933094,0.018568285805040198
2024-10-21T12:04:26.481239121Z,2024-10-21T12:04:26.481072450Z,10,2,38,A,B,3,233.56,200,130,166671,11934663,233.66,233.78,1,150,1,2,233.65,233.8,18,25,1,1,233.58,233.82,500,400,1,2,233.56,233.84,200,27,1,1,233.53,233.94,10,200,1,1,233.52,233.98,29,44,1,3,233.45,234.0,15,154,1,7,233.4,234.13,110,400,2,1,233.39,234.17,10,1,1,1,233.31,234.41,110,600,2,2,AAPL,-320,-1.0572687224669604,0.013647596310815913
2024-10-21T12:04:26.536084575Z,2024-10-21T12:04:26.535918353Z,10,2,38,C,A,2,233.82,200,130,166222,11934785,233.66,233.78,1,150,1,2,233.65,233.8,18,25,1,1,233.58,233.82,500,200,1,1,233.56,233.84,200,27,1,1,233.53,233.94,10,200,1,1,233.52,233.98,29,44,1,3,233.45,234.0,15,154,1,7,233.4,234.13,110,400,2,1,233.39,234.17,10,1,1,1,233.31,234.41,110,600,2,2,AAPL,-320,-1.0459652706843718,0.013501687381922615
2024-10-21T12:04:26.536096505Z,2024-10-21T12:04:26.535930308Z,10,2,38,A,A,2,233.81,400,130,166197,11934786,233.66,233.78,1,150,1,2,233.65,233.8,18,25,1,1,233.58,233.81,500,400,1,1,233.56,233.84,200,27,1,1,233.53,233.94,10,200,1,1,233.52,233.98,29,44,1,3,233.45,234.0,15,154,1,7,233.4,234.13,110,400,2,1,233.39,234.17,10,1,1,1,233.31,234.41,110,600,2,2,AAPL,-320,-1.0361904761904763,0.013375510898651076
2024-10-21T12:04:26.555239082Z,2024-10-21T12:04:26.555072803Z,10,2,38,C,A,3,233.84,27,130,166279,11935024,233.66,233.78,1,150,1,2,233.65,233.8,18,25,1,1,233.58,233.81,500,400,1,1,233.56,233.94,200,200,1,1,233.53,233.98,10,44,1,3,233.52,234.0,29,154,1,7,233.45,234.13,15,400,1,1,233.4,234.17,110,1,2,1,233.39,234.41,10,600,1,2,233.31,234.43,110,5,2,1,AAPL,-315,-1.068299576071597,0.013789986446607045
2024-10-21T12:04:26.555299312Z,2024-10-21T12:04:26.555132343Z,10,2,38,A,A,3,233.83,30,130,166969,11935025,233.66,233.78,1,150,1,2,233.65,233.8,18,25,1,1,233.58,233.81,500,400,1,1,233.56,233.83,200,30,1,1,233.53,233.94,10,200,1,1,233.52,233.98,29,44,1,3,233.45,234.0,15,154,1,7,233.4,234.13,110,400,2,1,233.39,234.17,10,1,1,1,233.31,234.41,110,600,2,2,AAPL,-915,-3.070198675496689,0.039631203710833236
2024-10-21T12:04:26.566319697Z,2024-10-21T12:04:26.566152901Z,10,2,38,A,B,3,233.56,200,130,166796,11935064,233.66,233.78,1,150,1,2,233.65,233.8,18,25,1,1,233.58,233.81,500,400,1,1,233.56,233.83,400,30,2,1,233.53,233.94,10,200,1,1,233.52,233.98,29,44,1,3,233.45,234.0,15,154,1,7,233.4,234.13,110,400,2,1,233.39,234.17,10,1,1,1,233.31,234.41,110,600,2,2,AAPL,-915,-3.041130037390943,0.039255975512228494
2024-10-21T12:04:26.621314387Z,2024-10-21T12:04:26.621148067Z,10,2,38,C,B,3,233.56,200,130,166320,11935247,233.66,233.78,1,150,1,2,233.65,233.8,18,25,1,1,233.58,233.81,500,400,1,1,233.56,233.83,200,30,1,1,233.53,233.94,10,200,1,1,233.52,233.98,29,44,1,3,233.45,234.0,15,154,1,7,233.4,234.13,110,400,2,1,233.39,234.17,10,1,1,1,233.31,234.41,110,600,2,2,AAPL,-915,-3.015300117693213,0.03892255382927841
2024-10-21T12:04:26.621327019Z,2024-10-21T12:04:26.621160396Z,10,2,38,A,B,2,233.58,400,130,166623,11935248,233.66,233.78,1,150,1,2,233.65,233.8,18,25,1,1,233.58,233.81,900,400,2,1,233.53,233.83,10,30,1,1,233.52,233.94,29,200,1,1,233.45,233.98,15,44,1,3,233.4,234.0,110,154,2,7,233.39,234.13,10,400,1,1,233.31,234.17,110,1,2,1,233.3,234.41,100,600,1,2,AAPL,-1015,-3.321680922275939,0.042877424950947
2024-10-21T12:04:27.723486293Z,2024-10-21T12:04:27.723319849Z,10,2,38,A,B,2,233.59,400,130,166444,11936720,233.66,233.78,1,150,1,2,233.65,233.8,18,25,1,1,233.59,233.81,400,400,1,1,233.58,233.83,500,30,1,1,233.53,233.94,10,200,1,1,233.52,233.98,29,44,1,3,233.45,234.0,15,154,1,7,233.4,234.13,110,400,2,1,233.39,234.17,10,1,1,1,233.31,234.41,110,600,2,2,AAPL,-905,-2.9410102437301306,0.037963594022481305
2024-10-21T12:04:27.735219832Z,2024-10-21T12:04:27.735053874Z,10,2,38,C,B,2,233.59,400,130,165958,11936743,233.66,233.78,1,150,1,2,233.65,233.8,18,25,1,1,233.58,233.81,500,400,1,1,233.53,233.83,10,30,1,1,233.52,233.94,29,200,1,1,233.45,233.98,15,44,1,3,233.4,234.0,110,154,2,7,233.39,234.13,10,400,1,1,233.31,234.17,110,1,2,1,233.3,234.41,100,600,1,2,AAPL,-1005,-3.247391450690003,0.041918470338175536
2024-10-21T12:04:27.735232654Z,2024-10-21T12:04:27.735066380Z,10,2,38,A,B,3,233.57,200,130,166274,11936744,233.66,233.78,1,150,1,2,233.65,233.8,18,25,1,1,233.58,233.81,500,400,1,1,233.57,233.83,200,30,1,1,233.53,233.94,10,200,1,1,233.52,233.98,29,44,1,3,233.45,234.0,15,154,1,7,233.4,234.13,110,400,2,1,233.39,234.17,10,1,1,1,233.31,234.41,110,600,2,2,AAPL,-895,-2.8750401541920976,0.03711202891753553
2024-10-21T12:04:40.612698742Z,2024-10-21T12:04:40.612532228Z,10,2,38,A,A,8,234.15,50,130,166514,11955462,233.66,233.78,1,150,1,2,233.65,233.8,18,25,1,1,233.58,233.81,500,400,1,1,233.57,233.83,200,30,1,1,233.53,233.94,10,200,1,1,233.52,233.98,29,44,1,3,233.45,234.0,15,154,1,7,233.4,234.13,110,400,2,1,233.39,234.15,10,50,1,1,233.31,234.17,110,1,2,1,AAPL,-566,-1.8381214089432927,0.023727117265885223
2024-10-21T12:04:47.058864380Z,2024-10-21T12:04:47.058697813Z,10,2,38,A,A,0,233.72,3,130,166567,11962920,233.66,233.72,1,3,1,1,233.65,233.78,18,150,1,2,233.58,233.8,500,25,1,1,233.57,233.81,200,400,1,1,233.53,233.83,10,30,1,1,233.52,233.94,29,200,1,1,233.45,233.98,15,44,1,3,233.4,234.0,110,154,2,7,233.39,234.13,10,400,1,1,233.31,234.15,110,50,2,1,AAPL,69,0.28858218318695106,-0.003725120260287008
2024-10-21T12:04:51.210658197Z,2024-10-21T12:04:51.210492220Z,10,2,38,C,A,3,233.81,400,130,165977,11968430,233.66,233.72,1,3,1,1,233.65,233.78,18,150,1,2,233.58,233.8,500,25,1,1,233.57,233.83,200,30,1,1,233.53,233.94,10,200,1,1,233.52,233.98,29,44,1,3,233.45,234.0,15,154,1,7,233.4,234.13,110,400,2,1,233.39,234.15,10,50,1,1,233.31,234.17,110,1,2,1,AAPL,-50,-0.7853403141361257,0.010137448830350827
2024-10-21T12:04:51.210670708Z,2024-10-21T12:04:51.210504256Z,10,2,38,A,A,3,233.83,400,130,166452,11968431,233.66,233.72,1,3,1,1,233.65,233.78,18,150,1,2,233.58,233.8,500,25,1,1,233.57,233.83,200,430,1,2,233.53,233.94,10,200,1,1,233.52,233.98,29,44,1,3,233.45,234.0,15,154,1,7,233.4,234.13,110,400,2,1,233.39,234.15,10,50,1,1,233.31,234.17,110,1,2,1,AAPL,-50,-0.8113590263691683,0.010473307513709304
2024-10-21T12:04:51.271539805Z,2024-10-21T12:04:51.271373633Z,10,2,38,C,B,5,233.52,29,130,166172,11968508,233.66,233.72,1,3,1,1,233.65,233.78,18,150,1,2,233.58,233.8,500,25,1,1,233.57,233.83,200,430,1,2,233.53,233.94,10,200,1,1,233.45,233.98,15,44,1,3,233.4,234.0,110,154,2,7,233.39,234.13,10,400,1,1,233.31,234.15,110,50,2,1,233.3,234.17,100,1,1,1,AAPL,-150,-2.5252525252525255,0.03259684724910788
2024-10-21T12:04:51.271604678Z,2024-10-21T12:04:51.271438407Z,10,2,38,A,B,4,233.53,27,130,166271,11968509,233.66,233.72,1,3,1,1,233.65,233.78,18,150,1,2,233.58,233.8,500,25,1,1,233.57,233.83,200,430,1,2,233.53,233.94,37,200,2,1,233.45,233.98,15,44,1,3,233.4,234.0,110,154,2,7,233.39,234.13,10,400,1,1,233.31,234.15,110,50,2,1,233.3,234.17,100,1,1,1,AAPL,-150,-2.5899280575539567,0.03343170175419294
2024-10-21T12:04:51.271676560Z,2024-10-21T12:04:51.271510236Z,10,2,38,A,A,3,233.82,200,130,166324,11968510,233.66,233.72,1,3,1,1,233.65,233.78,18,150,1,2,233.58,233.8,500,25,1,1,233.57,233.82,200,200,1,1,233.53,233.83,37,30,2,1,233.45,233.94,15,200,1,1,233.4,233.98,110,44,2,3,233.39,234.0,10,154,1,7,233.31,234.13,110,400,2,1,233.3,234.15,100,50,1,1,AAPL,-200,-3.3136094674556213,0.042773235774924034
2024-10-21T12:04:51.316610309Z,2024-10-21T12:04:51.316443773Z,10,2,38,A,A,3,233.82,200,130,166536,11968577,233.66,233.72,1,3,1,1,233.65,233.78,18,150,1,2,233.58,233.8,500,25,1,1,233.57,233.82,200,400,1,2,233.53,233.83,37,30,2,1,233.45,233.94,15,200,1,1,233.4,233.98,110,44,2,3,233.39,234.0,10,154,1,7,233.31,234.13,110,400,2,1,233.3,234.15,100,50,1,1,AAPL,-200,-3.2160804020100504,0.041514296315647736
2024-10-21T12:04:54.735907876Z,2024-10-21T12:04:54.735741554Z,10,2,38,A,B,2,233.58,5,130,166322,11972208,233.66,233.72,1,3,1,1,233.65,233.78,18,150,1,2,233.58,233.8,505,25,2,1,233.57,233.82,200,400,1,2,233.53,233.83,37,30,2,1,233.45,233.94,15,200,1,1,233.4,233.98,110,44,2,3,233.39,234.0,10,154,1,7,233.31,234.13,110,400,2,1,233.3,234.15,100,50,1,1,AAPL,-200,-3.1441048034934496,0.040585209989806276
2024-10-21T12:05:01.936659665Z,2024-10-21T12:05:01.936493423Z,10,2,38,C,A,3,233.82,200,130,166242,11982930,233.66,233.72,1,3,1,1,233.65,233.78,18,150,1,2,233.58,233.8,505,25,2,1,233.57,233.82,200,200,1,1,233.53,233.83,37,30,2,1,233.45,233.94,15,200,1,1,233.4,233.98,110,44,2,3,233.39,234.0,10,154,1,7,233.31,234.13,110,400,2,1,233.3,234.15,100,50,1,1,AAPL,-199,-3.025337837837838,0.03905212424927073
2024-10-21T12:05:01.936672067Z,2024-10-21T12:05:01.936505877Z,10,2,38,A,A,1,233.77,200,130,166190,11982931,233.66,233.72,1,3,1,1,233.65,233.77,18,200,1,1,233.58,233.78,505,150,2,2,233.57,233.8,200,25,1,1,233.53,233.83,37,30,2,1,233.45,233.94,15,200,1,1,233.4,233.98,110,44,2,3,233.39,234.0,10,154,1,7,233.31,234.13,110,400,2,1,233.3,234.15,100,50,1,1,AAPL,-199,-2.9835082458770614,0.038512173172694106
2024-10-21T12:05:05.090904204Z,2024-10-21T12:05:05.090737406Z,10,2,38,C,A,9,234.15,50,130,166798,11987492,233.66,233.72,1,3,1,1,233.65,233.77,18,200,1,1,233.58,233.78,505,150,2,2,233.57,233.8,200,25,1,1,233.53,233.83,37,30,2,1,233.45,233.94,15,200,1,1,233.4,233.98,110,44,2,3,233.39,234.0,10,154,1,7,233.31,234.13,110,400,2,1,233.3,234.17,100,1,1,1,AAPL,-198,-3.035540069686411,0.039183818244165225
2024-10-21T12:05:15.858379034Z,2024-10-21T12:05:15.858212657Z,10,2,38,C,A,1,233.77,200,130,166377,12002579,233.66,233.72,1,3,1,1,233.65,233.78,18,150,1,2,233.58,233.8,505,25,2,1,233.57,233.83,200,30,1,1,233.53,233.94,37,200,2,1,233.45,233.98,15,44,1,3,233.4,234.0,110,154,2,7,233.39,234.13,10,400,1,1,233.31,234.17,110,1,2,1,233.3,234.25,100,50,1,1,AAPL,51,0.7404718693284936,-0.00955827117303786
2024-10-21T12:05:15.858393121Z,2024-10-21T12:05:15.858226719Z,10,2,38,A,A,3,233.82,200,130,166402,12002580,233.66,233.72,1,3,1,1,233.65,233.78,18,150,1,2,233.58,233.8,505,25,2,1,233.57,233.82,200,200,1,1,233.53,233.83,37,30,2,1,233.45,233.94,15,200,1,1,233.4,233.98,110,44,2,3,233.39,234.0,10,154,1,7,233.31,234.13,110,400,2,1,233.3,234.17,100,1,1,1,AAPL,50,0.7668711656441718,-0.009899042569514354
2024-10-21T12:05:18.858766649Z,2024-10-21T12:05:18.858600266Z,10,2,38,A,A,3,233.82,200,130,166383,12004906,233.66,233.72,1,3,1,1,233.65,233.78,18,150,1,2,233.58,233.8,505,25,2,1,233.57,233.82,200,400,1,2,233.53,233.83,37,30,2,1,233.45,233.94,15,200,1,1,233.4,233.98,110,44,2,3,233.39,234.0,10,154,1,7,233.31,234.13,110,400,2,1,233.3,234.17,100,1,1,1,AAPL,50,0.796812749003984,-0.010285539052308142
2024-10-21T12:05:27.769411797Z,2024-10-21T12:05:27.769244591Z,10,2,38,T,B,0,233.72,3,130,167206,12010755,233.66,233.72,1,3,1,1,233.65,233.78,18,150,1,2,233.58,233.8,505,25,2,1,233.57,233.82,200,400,1,2,233.53,233.83,37,30,2,1,233.45,233.94,15,200,1,1,233.4,233.98,110,44,2,3,233.39,234.0,10,154,1,7,233.31,234.13,110,400,2,1,233.3,234.17,100,1,1,1,AAPL,49,0.8653421633554084,-0.011170140821575084
2024-10-21T12:05:27.769411797Z,2024-10-21T12:05:27.769244591Z,10,2,38,C,A,0,233.72,3,130,167206,12010755,233.66,233.78,1,150,1,2,233.65,233.8,18,25,1,1,233.58,233.82,505,400,2,2,233.57,233.83,200,30,1,1,233.53,233.94,37,200,2,1,233.45,233.98,15,44,1,3,233.4,234.0,110,154,2,7,233.39,234.13,10,400,1,1,233.31,234.17,110,1,2,1,233.3,234.25,100,50,1,1,AAPL,99,1.6417910447761195,-0.021192815913002077
2024-10-21T12:05:27.769433447Z,2024-10-21T12:05:27.769266569Z,10,2,38,A,B,0,233.68,100,130,166878,12010756,233.68,233.78,100,150,1,2,233.66,233.8,1,25,1,1,233.65,233.82,18,400,1,2,233.58,233.83,505,30,2,1,233.57,233.94,200,200,1,1,233.53,233.98,37,44,2,3,233.45,234.0,15,154,1,7,233.4,234.13,110,400,2,1,233.39,234.17,10,1,1,1,233.31,234.25,110,50,2,1,AAPL,209,3.2870249017038007,-0.04243007285544163
2024-10-21T12:05:27.769446609Z,2024-10-21T12:05:27.769279547Z,10,2,38,A,B,0,233.68,100,130,167062,12010757,233.68,233.78,200,150,2,2,233.66,233.8,1,25,1,1,233.65,233.82,18,400,1,2,233.58,233.83,505,30,2,1,233.57,233.94,200,200,1,1,233.53,233.98,37,44,2,3,233.45,234.0,15,154,1,7,233.4,234.13,110,400,2,1,233.39,234.17,10,1,1,1,233.31,234.25,110,50,2,1,AAPL,209,3.1700975081256773,-0.04092073295791148
2024-10-21T12:05:27.769448769Z,2024-10-21T12:05:27.769282701Z,10,2,38,A,B,1,233.67,13,130,166068,12010758,233.68,233.78,200,150,2,2,233.67,233.8,13,25,1,1,233.66,233.82,1,400,1,2,233.65,233.83,18,30,1,1,233.58,233.94,505,200,2,1,233.57,233.98,200,44,1,3,233.53,234.0,37,154,2,7,233.45,234.13,15,400,1,1,233.4,234.17,110,1,2,1,233.39,234.25,10,50,1,1,AAPL,219,3.5645981688708037,-0.04601308615799196
2024-10-21T12:05:27.769485951Z,2024-10-21T12:05:27.769319506Z,10,2,38,C,B,0,233.68,100,130,166445,12010760,233.68,233.78,100,150,1,2,233.67,233.8,13,25,1,1,233.66,233.82,1,400,1,2,233.65,233.83,18,30,1,1,233.58,233.94,505,200,2,1,233.57,233.98,200,44,1,3,233.53,234.0,37,154,2,7,233.45,234.13,15,400,1,1,233.4,234.17,110,1,2,1,233.39,234.25,10,50,1,1,AAPL,219,3.7794822627037394,-0.04878688557523429
2024-10-21T12:05:27.769550286Z,2024-10-21T12:05:27.769383987Z,10,2,38,C,B,0,233.68,100,130,166299,12010767,233.67,233.78,13,150,1,2,233.66,233.8,1,25,1,1,233.65,233.82,18,400,1,2,233.58,233.83,505,30,2,1,233.57,233.94,200,200,1,1,233.53,233.98,37,44,2,3,233.45,234.0,15,154,1,7,233.4,234.13,110,400,2,1,233.39,234.17,10,1,1,1,233.31,234.25,110,50,2,1,AAPL,109,1.8121363258520367,-0.02339169267930993
2024-10-21T12:05:27.870746889Z,2024-10-21T12:05:27.870580890Z,10,2,38,C,B,0,233.67,13,130,165999,12010841,233.66,233.78,1,150,1,2,233.65,233.8,18,25,1,1,233.58,233.82,505,400,2,2,233.57,233.83,200,30,1,1,233.53,233.94,37,200,2,1,233.45,233.98,15,44,1,3,233.4,234.0,110,154,2,7,233.39,234.13,10,400,1,1,233.31,234.17,110,1,2,1,233.3,234.25,100,50,1,1,AAPL,9,0.14634146341463414,-0.001889027050338544
2024-10-21T12:05:30.107907731Z,2024-10-21T12:05:30.107740673Z,10,2,38,A,B,0,233.7,1200,130,167058,12012202,233.7,233.78,1200,150,1,2,233.66,233.8,1,25,1,1,233.65,233.82,18,400,1,2,233.58,233.83,505,30,2,1,233.57,233.94,200,200,1,1,233.53,233.98,37,44,2,3,233.45,234.0,15,154,1,7,233.4,234.13,110,400,2,1,233.39,234.17,10,1,1,1,233.31,234.25,110,50,2,1,AAPL,119,1.8876404494382024,-0.02436632644706347
2024-10-21T12:05:35.113275906Z,2024-10-21T12:05:35.113109625Z,10,2,38,C,B,4,233.57,200,130,166281,12015205,233.7,233.78,1200,150,1,2,233.66,233.8,1,25,1,1,233.65,233.82,18,400,1,2,233.58,233.83,505,30,2,1,233.53,233.94,37,200,2,1,233.45,233.98,15,44,1,3,233.4,234.0,110,154,2,7,233.39,234.13,10,400,1,1,233.31,234.17,110,1,2,1,233.3,234.25,100,50,1,1,AAPL,19,0.2970535177390259,-0.0038344712244494763
2024-10-21T12:05:35.113289385Z,2024-10-21T12:05:35.113122799Z,10,2,38,A,B,5,233.52,400,130,166586,12015206,233.7,233.78,1200,150,1,2,233.66,233.8,1,25,1,1,233.65,233.82,18,400,1,2,233.58,233.83,505,30,2,1,233.53,233.94,37,200,2,1,233.52,233.98,400,44,1,3,233.45,234.0,15,154,1,7,233.4,234.13,110,400,2,1,233.39,234.17,10,1,1,1,233.31,234.25,110,50,2,1,AAPL,129,1.98134942402633,-0.02557595483074928
2024-10-21T12:05:40.025362817Z,2024-10-21T12:05:40.025196163Z,10,2,38,C,A,2,233.82,200,130,166654,12018306,233.7,233.78,1200,150,1,2,233.66,233.8,1,25,1,1,233.65,233.82,18,200,1,1,233.58,233.83,505,30,2,1,233.53,233.94,37,200,2,1,233.52,233.98,400,44,1,3,233.45,234.0,15,154,1,7,233.4,234.13,110,400,2,1,233.39,234.17,10,1,1,1,233.31,234.25,110,50,2,1,AAPL,80,1.177191906805641,-0.015195606928535686
2024-10-21T12:05:40.028175209Z,2024-10-21T12:05:40.028003470Z,10,2,38,T,B,0,233.78,50,0,171739,12018310,233.7,233.78,1200,150,1,2,233.66,233.8,1,25,1,1,233.65,233.82,18,200,1,1,233.58,233.83,505,30,2,1,233.53,233.94,37,200,2,1,233.52,233.98,400,44,1,3,233.45,234.0,15,154,1,7,233.4,234.13,110,400,2,1,233.39,234.17,10,1,1,1,233.31,234.25,110,50,2,1,AAPL,80,1.1613623673925182,-0.01499127366953946
2024-10-21T12:05:40.028175209Z,2024-10-21T12:05:40.028003470Z,10,2,38,T,B,0,233.78,100,0,171739,12018311,233.7,233.78,1200,100,1,1,233.66,233.8,1,25,1,1,233.65,233.82,18,200,1,1,233.58,233.83,505,30,2,1,233.53,233.94,37,200,2,1,233.52,233.98,400,44,1,3,233.45,234.0,15,154,1,7,233.4,234.13,110,400,2,1,233.39,234.17,10,1,1,1,233.31,234.25,110,50,2,1,AAPL,80,1.1481291645310097,-0.014820454835391413
2024-10-21T12:05:40.028175209Z,2024-10-21T12:05:40.028006695Z,10,2,38,C,N,0,233.82,200,130,168514,12018313,233.78,233.8,256,25,1,1,233.7,233.83,1200,30,1,1,233.66,233.94,1,200,1,1,233.65,233.98,18,44,1,3,233.58,234.0,505,154,2,7,233.53,234.13,37,400,2,1,233.52,234.17,400,1,1,1,233.45,234.25,15,50,1,1,233.4,234.41,110,600,2,2,233.39,234.43,10,5,1,1,AAPL,95,1.449643947100712,-0.018712513634457348
2024-10-21T12:05:40.028197600Z,2024-10-21T12:05:40.028030027Z,10,2,38,A,B,1,233.74,100,130,167573,12018314,233.78,233.8,256,25,1,1,233.74,233.83,100,30,1,1,233.7,233.94,1200,200,1,1,233.66,233.98,1,44,1,3,233.65,234.0,18,154,1,7,233.58,234.13,505,400,2,1,233.53,234.17,37,1,2,1,233.52,234.25,400,50,1,1,233.45,234.41,15,600,1,2,233.4,234.43,110,5,2,1,AAPL,205,3.1523306102835176,-0.040691391595311134
2024-10-21T12:05:40.028200070Z,2024-10-21T12:05:40.028032659Z,10,2,38,A,B,2,233.72,100,130,167411,12018315,233.78,233.8,256,25,1,1,233.74,233.83,100,30,1,1,233.72,233.94,100,200,1,1,233.7,233.98,1200,44,1,3,233.66,234.0,1,154,1,7,233.65,234.13,18,400,1,1,233.58,234.17,505,1,2,1,233.53,234.25,37,50,2,1,233.52,234.41,400,600,1,2,233.45,234.43,15,5,1,1,AAPL,220,3.5602094240837694,-0.045956434697590406
2024-10-21T12:05:40.028209847Z,2024-10-21T12:05:40.028041901Z,10,2,38,A,B,2,233.72,100,128,167946,12018316,233.78,233.8,256,25,1,1,233.74,233.83,100,30,1,1,233.72,233.94,200,200,2,1,233.7,233.98,1200,44,1,3,233.66,234.0,1,154,1,7,233.65,234.13,18,400,1,1,233.58,234.17,505,1,2,1,233.53,234.25,37,50,2,1,233.52,234.41,400,600,1,2,233.45,234.43,15,5,1,1,AAPL,220,3.7340876944837342,-0.048200916531976425
2024-10-21T12:05:40.028210843Z,2024-10-21T12:05:40.028043931Z,10,2,38,A,B,1,233.74,100,130,166912,12018318,233.78,233.8,256,25,1,1,233.74,233.83,200,30,2,1,233.72,233.94,200,200,2,1,233.7,233.98,1200,44,1,3,233.66,234.0,1,154,1,7,233.65,234.13,18,400,1,1,233.58,234.17,505,1,2,1,233.53,234.25,37,50,2,1,233.52,234.41,400,600,1,2,233.45,234.43,15,5,1,1,AAPL,220,3.90471742176553,-0.05040346502989563
2024-10-21T12:05:40.028215296Z,2024-10-21T12:05:40.028048443Z,10,2,38,A,B,1,233.74,32,130,166853,12018319,233.78,233.8,256,25,1,1,233.74,233.83,232,30,3,1,233.72,233.94,200,200,2,1,233.7,233.98,1200,44,1,3,233.66,234.0,1,154,1,7,233.65,234.13,18,400,1,1,233.58,234.17,505,1,2,1,233.53,234.25,37,50,2,1,233.52,234.41,400,600,1,2,233.45,234.43,15,5,1,1,AAPL,220,4.072188801480796,-0.052565244467233284
2024-10-21T12:05:40.028222153Z,2024-10-21T12:05:40.028054971Z,10,2,38,A,B,2,233.72,100,128,167182,12018320,233.78,233.8,256,25,1,1,233.74,233.83,232,30,3,1,233.72,233.94,300,200,3,1,233.7,233.98,1200,44,1,3,233.66,234.0,1,154,1,7,233.65,234.13,18,400,1,1,233.58,234.17,505,1,2,1,233.53,234.25,37,50,2,1,233.52,234.41,400,600,1,2,233.45,234.43,15,5,1,1,AAPL,220,4.236588720770289,-0.05468737641374401
2024-10-21T12:05:40.028229221Z,2024-10-21T12:05:40.028063174Z,10,2,38,A,B,3,233.71,32,130,166047,12018322,233.78,233.8,256,25,1,1,233.74,233.83,232,30,3,1,233.72,233.94,300,200,3,1,233.71,233.98,32,44,1,3,233.7,234.0,1200,154,1,7,233.66,234.13,1,400,1,1,233.65,234.17,18,1,1,1,233.58,234.25,505,50,2,1,233.53,234.41,37,600,2,2,233.52,234.43,400,5,1,1,AAPL,620,10.549110595514307,-0.1361716276915864
2024-10-21T12:05:40.028232731Z,2024-10-21T12:05:40.028066207Z,10,2,38,C,B,1,233.74,100,130,166524,12018323,233.78,233.8,256,25,1,1,233.74,233.83,132,30,2,1,233.72,233.94,300,200,3,1,233.71,233.98,32,44,1,3,233.7,234.0,1200,154,1,7,233.66,234.13,1,400,1,1,233.65,234.17,18,1,1,1,233.58,234.25,505,50,2,1,233.53,234.41,37,600,2,2,233.52,234.43,400,5,1,1,AAPL,620,9.535272484119023,-0.12308464897480587
2024-10-21T12:05:40.028243957Z,2024-10-21T12:05:40.028077104Z,10,2,38,C,B,1,233.74,100,130,166853,12018324,233.78,233.8,256,25,1,1,233.74,233.83,32,30,1,1,233.72,233.94,300,200,3,1,233.71,233.98,32,44,1,3,233.7,234.0,1200,154,1,7,233.66,234.13,1,400,1,1,233.65,234.17,18,1,1,1,233.58,234.25,505,50,2,1,233.53,234.41,37,600,2,2,233.52,234.43,400,5,1,1,AAPL,620,8.763250883392226,-0.11311912277881223
2024-10-21T12:05:40.028264359Z,2024-10-21T12:05:40.028094970Z,10,2,38,T,B,0,233.8,25,130,169389,12018325,233.78,233.8,256,25,1,1,233.74,233.83,32,30,1,1,233.72,233.94,300,200,3,1,233.71,233.98,32,44,1,3,233.7,234.0,1200,154,1,7,233.66,234.13,1,400,1,1,233.65,234.17,18,1,1,1,233.58,234.25,505,50,2,1,233.53,234.41,37,600,2,2,233.52,234.43,400,5,1,1,AAPL,620,8.155748487240201,-0.10527726830572173
2024-10-21T12:05:40.028264359Z,2024-10-21T12:05:40.028094970Z,10,2,38,C,A,0,233.8,25,130,169389,12018325,233.78,233.83,256,30,1,1,233.74,233.94,32,200,1,1,233.72,233.98,300,44,3,3,233.71,234.0,32,154,1,7,233.7,234.13,1200,400,1,1,233.66,234.17,1,1,1,1,233.65,234.25,18,50,1,1,233.58,234.41,505,600,2,2,233.53,234.43,37,5,2,1,233.52,234.5,400,63,1,4,AAPL,683,8.329268292682928,-0.10751712294843546
2024-10-21T12:05:40.028266286Z,2024-10-21T12:05:40.028097758Z,10,2,38,A,B,4,233.7,100,130,168528,12018326,233.78,233.83,256,30,1,1,233.74,233.94,32,200,1,1,233.72,233.98,300,44,3,3,233.71,234.0,32,154,1,7,233.7,234.13,1300,400,2,1,233.66,234.17,1,1,1,1,233.65,234.25,18,50,1,1,233.58,234.41,505,600,2,2,233.53,234.43,37,5,2,1,233.52,234.5,400,63,1,4,AAPL,683,7.802411677596784,-0.10071627256519405
2024-10-21T12:05:40.028281310Z,2024-10-21T12:05:40.028115361Z,10,2,38,A,B,0,233.79,100,130,165949,12018327,233.79,233.83,100,30,1,1,233.78,233.94,256,200,1,1,233.74,233.98,32,44,1,3,233.72,234.0,300,154,3,7,233.71,234.13,32,400,1,1,233.7,234.17,1300,1,2,1,233.66,234.25,1,50,1,1,233.65,234.41,18,600,1,2,233.58,234.43,505,5,2,1,233.53,234.5,37,63,2,4,AAPL,720,8.353014294592915,-0.10782364468806209
2024-10-21T12:05:40.028288152Z,2024-10-21T12:05:40.028121192Z,10,2,38,A,B,5,233.7,100,128,166960,12018328,233.79,233.83,100,30,1,1,233.78,233.94,256,200,1,1,233.74,233.98,32,44,1,3,233.72,234.0,300,154,3,7,233.71,234.13,32,400,1,1,233.7,234.17,1400,1,3,1,233.66,234.25,1,50,1,1,233.65,234.41,18,600,1,2,233.58,234.43,505,5,2,1,233.53,234.5,37,63,2,4,AAPL,720,8.475745889993911,-0.10940790726296061
2024-10-21T12:05:40.028294528Z,2024-10-21T12:05:40.028128644Z,10,2,38,C,B,3,233.72,100,130,165884,12018330,233.79,233.83,100,30,1,1,233.78,233.94,256,200,1,1,233.74,233.98,32,44,1,3,233.72,234.0,200,154,2,7,233.71,234.13,32,400,1,1,233.7,234.17,1400,1,3,1,233.66,234.25,1,50,1,1,233.65,234.41,18,600,1,2,233.58,234.43,505,5,2,1,233.53,234.5,37,63,2,4,AAPL,720,8.593594589218222,-0.1109291396976205
2024-10-21T12:05:40.028323326Z,2024-10-21T12:05:40.028156649Z,10,2,38,C,B,3,233.72,100,130,166677,12018331,233.79,233.83,100,30,1,1,233.78,233.94,256,200,1,1,233.74,233.98,32,44,1,3,233.72,234.0,100,154,1,7,233.71,234.13,32,400,1,1,233.7,234.17,1400,1,3,1,233.66,234.25,1,50,1,1,233.65,234.41,18,600,1,2,233.58,234.43,505,5,2,1,233.53,234.5,37,63,2,4,AAPL,720,8.706846108835578,-0.11239103012195623
2024-10-21T12:05:40.028531746Z,2024-10-21T12:05:40.028365786Z,10,2,38,C,B,0,233.79,100,130,165960,12018340,233.78,233.83,256,30,1,1,233.74,233.94,32,200,1,1,233.72,233.98,100,44,1,3,233.71,234.0,32,154,1,7,233.7,234.13,1400,400,3,1,233.66,234.17,1,1,1,1,233.65,234.25,18,50,1,1,233.58,234.41,505,600,2,2,233.53,234.43,37,5,2,1,233.52,234.5,400,63,1,4,AAPL,320,3.663685152057245,-0.04729213576709209
2024-10-21T12:05:40.028595126Z,2024-10-21T12:05:40.028429209Z,10,2,38,C,B,2,233.72,100,130,165917,12018342,233.78,233.83,256,30,1,1,233.74,233.94,32,200,1,1,233.71,233.98,32,44,1,3,233.7,234.0,1400,154,3,7,233.66,234.13,1,400,1,1,233.65,234.17,18,1,1,1,233.58,234.25,505,50,2,1,233.53,234.41,37,600,2,2,233.52,234.43,400,5,1,1,233.45,234.5,15,63,1,4,AAPL,305,3.5515172900494,-0.045844233576097106
2024-10-21T12:05:40.028651521Z,2024-10-21T12:05:40.028485091Z,10,2,38,C,B,3,233.7,100,130,166430,12018343,233.78,233.83,256,30,1,1,233.74,233.94,32,200,1,1,233.71,233.98,32,44,1,3,233.7,234.0,1300,154,2,7,233.66,234.13,1,400,1,1,233.65,234.17,18,1,1,1,233.58,234.25,505,50,2,1,233.53,234.41,37,600,2,2,233.52,234.43,400,5,1,1,233.45,234.5,15,63,1,4,AAPL,305,3.6094674556213016,-0.046592274683399396
2024-10-21T12:05:40.028749890Z,2024-10-21T12:05:40.028584035Z,10,2,38,C,B,3,233.7,100,130,165855,12018344,233.78,233.83,256,30,1,1,233.74,233.94,32,200,1,1,233.71,233.98,32,44,1,3,233.7,234.0,1200,154,1,7,233.66,234.13,1,400,1,1,233.65,234.17,18,1,1,1,233.58,234.25,505,50,2,1,233.53,234.41,37,600,2,2,233.52,234.43,400,5,1,1,233.45,234.5,15,63,1,4,AAPL,305,3.6658653846153846,-0.04732027897532751
2024-10-21T12:05:40.055731072Z,2024-10-21T12:05:40.055564914Z,10,2,38,C,B,0,233.78,256,130,166158,12018442,233.74,233.83,32,30,1,1,233.71,233.94,32,200,1,1,233.7,233.98,1200,44,1,3,233.66,234.0,1,154,1,7,233.65,234.13,18,400,1,1,233.58,234.17,505,1,2,1,233.53,234.25,37,50,2,1,233.52,234.41,400,600,1,2,233.45,234.43,15,5,1,1,233.4,234.5,110,63,2,4,AAPL,195,2.3411705852926463,-0.030220652861343993
2024-10-21T12:05:40.071193978Z,2024-10-21T12:05:40.071027333Z,10,2,38,A,B,0,233.78,326,130,166645,12018463,233.78,233.83,326,30,1,1,233.74,233.94,32,200,1,1,233.71,233.98,32,44,1,3,233.7,234.0,1200,154,1,7,233.66,234.13,1,400,1,1,233.65,234.17,18,1,1,1,233.58,234.25,505,50,2,1,233.53,234.41,37,600,2,2,233.52,234.43,400,5,1,1,233.45,234.5,15,63,1,4,AAPL,210,2.5580246913580247,-0.03301988188896296
2024-10-21T12:05:40.096468671Z,2024-10-21T12:05:40.096302346Z,10,2,38,C,A,0,233.83,30,130,166325,12018476,233.78,233.94,326,200,1,1,233.74,233.98,32,44,1,3,233.71,234.0,32,154,1,7,233.7,234.13,1200,400,1,1,233.66,234.17,1,1,1,1,233.65,234.25,18,50,1,1,233.58,234.41,505,600,2,2,233.53,234.43,37,5,2,1,233.52,234.5,400,63,1,4,233.45,234.75,15,1,1,1,AAPL,211,2.6327368248235103,-0.0339842923698458
2024-10-21T12:05:40.096512056Z,2024-10-21T12:05:40.096345392Z,10,2,38,A,A,0,233.89,28,130,166664,12018477,233.78,233.89,326,28,1,1,233.74,233.94,32,200,1,1,233.71,233.98,32,44,1,3,233.7,234.0,1200,154,1,7,233.66,234.13,1,400,1,1,233.65,234.17,18,1,1,1,233.58,234.25,505,50,2,1,233.53,234.41,37,600,2,2,233.52,234.43,400,5,1,1,233.45,234.5,15,63,1,4,AAPL,148,1.8712919435889124,-0.02415529418688697
2024-10-21T12:05:40.133930729Z,2024-10-21T12:05:40.133764520Z,10,2,38,C,B,2,233.71,32,130,166209,12018494,233.78,233.89,326,28,1,1,233.74,233.94,32,200,1,1,233.7,233.98,1200,44,1,3,233.66,234.0,1,154,1,7,233.65,234.13,18,400,1,1,233.58,234.17,505,1,2,1,233.53,234.25,37,50,2,1,233.52,234.41,400,600,1,2,233.45,234.43,15,5,1,1,233.4,234.5,110,63,2,4,AAPL,38,0.47934405550299586,-0.006187541562971621
2024-10-21T12:05:40.147927019Z,2024-10-21T12:05:40.147760543Z,10,2,38,A,B,5,233.58,400,130,166476,12018505,233.78,233.89,326,28,1,1,233.74,233.94,32,200,1,1,233.7,233.98,1200,44,1,3,233.66,234.0,1,154,1,7,233.65,234.13,18,400,1,1,233.58,234.17,905,1,3,1,233.53,234.25,37,50,2,1,233.45,234.41,15,600,1,2,233.4,234.43,110,5,2,1,233.39,234.5,10,63,1,4,AAPL,28,0.3579111457521434,-0.004620042878946978
2024-10-21T12:05:40.167228800Z,2024-10-21T12:05:40.167062454Z,10,2,38,A,A,0,233.88,200,130,166346,12018509,233.78,233.88,326,200,1,1,233.74,233.89,32,28,1,1,233.7,233.94,1200,200,1,1,233.66,233.98,1,44,1,3,233.65,234.0,18,154,1,7,233.58,234.13,905,400,3,1,233.53,234.17,37,1,2,1,233.45,234.25,15,50,1,1,233.4,234.41,110,600,2,2,233.39,234.43,10,5,1,1,AAPL,23,0.3004665629860031,-0.0038785280122192
2024-10-21T12:05:40.279206575Z,2024-10-21T12:05:40.279040532Z,10,2,38,C,B,1,233.74,32,130,166043,12018540,233.78,233.88,326,200,1,1,233.7,233.89,1200,28,1,1,233.66,233.94,1,200,1,1,233.65,233.98,18,44,1,3,233.58,234.0,905,154,3,7,233.53,234.13,37,400,2,1,233.45,234.17,15,1,1,1,233.4,234.25,110,50,2,1,233.39,234.41,10,600,1,2,233.31,234.43,110,5,2,1,AAPL,-87,-1.1431627196333078,0.01475634621889362
2024-10-21T12:05:40.371473684Z,2024-10-21T12:05:40.371306716Z,10,2,38,A,B,4,233.59,400,130,166968,12018572,233.78,233.88,326,200,1,1,233.7,233.89,1200,28,1,1,233.66,233.94,1,200,1,1,233.65,233.98,18,44,1,3,233.59,234.0,400,154,1,7,233.58,234.13,505,400,2,1,233.53,234.17,37,1,2,1,233.45,234.25,15,50,1,1,233.4,234.41,110,600,2,2,233.39,234.43,10,5,1,1,AAPL,-77,-1.0329268292682927,0.013333382596972893
2024-10-21T12:05:40.371700587Z,2024-10-21T12:05:40.371534341Z,10,2,38,C,A,0,233.88,200,130,166246,12018573,233.78,233.89,326,28,1,1,233.7,233.94,1200,200,1,1,233.66,233.98,1,44,1,3,233.65,234.0,18,154,1,7,233.59,234.13,400,400,1,1,233.58,234.17,505,1,2,1,233.53,234.25,37,50,2,1,233.45,234.41,15,600,1,2,233.4,234.43,110,5,2,1,233.39,234.5,10,63,1,4,AAPL,-14,-0.18995929443690637,0.0024520613453060253
2024-10-21T12:05:40.371712816Z,2024-10-21T12:05:40.371545573Z,10,2,38,A,A,1,233.92,200,130,167243,12018574,233.78,233.89,326,28,1,1,233.7,233.92,1200,200,1,1,233.66,233.94,1,200,1,1,233.65,233.98,18,44,1,3,233.59,234.0,400,154,1,7,233.58,234.13,505,400,2,1,233.53,234.17,37,1,2,1,233.45,234.25,15,50,1,1,233.4,234.41,110,600,2,2,233.39,234.43,10,5,1,1,AAPL,-19,-0.2629362214199759,0.003394073170970286
2024-10-21T12:05:40.371963906Z,2024-10-21T12:05:40.371797762Z,10,2,38,A,B,5,233.58,27,130,166144,12018575,233.78,233.89,326,28,1,1,233.7,233.92,1200,200,1,1,233.66,233.94,1,200,1,1,233.65,233.98,18,44,1,3,233.59,234.0,400,154,1,7,233.58,234.13,532,400,3,1,233.53,234.17,37,1,2,1,233.45,234.25,15,50,1,1,233.4,234.41,110,600,2,2,233.39,234.43,10,5,1,1,AAPL,-19,-0.2680474260843464,0.0034600503974208372
2024-10-21T12:05:40.371997976Z,2024-10-21T12:05:40.371831552Z,10,2,38,C,B,6,233.53,27,130,166424,12018576,233.78,233.89,326,28,1,1,233.7,233.92,1200,200,1,1,233.66,233.94,1,200,1,1,233.65,233.98,18,44,1,3,233.59,234.0,400,154,1,7,233.58,234.13,532,400,3,1,233.53,234.17,10,1,1,1,233.45,234.25,15,50,1,1,233.4,234.41,110,600,2,2,233.39,234.43,10,5,1,1,AAPL,-19,-0.27313566936208444,0.003525731230221565
2024-10-21T12:05:40.422288699Z,2024-10-21T12:05:40.422122396Z,10,2,38,A,B,2,233.68,200,130,166303,12018592,233.78,233.89,326,28,1,1,233.7,233.92,1200,200,1,1,233.68,233.94,200,200,1,1,233.66,233.98,1,44,1,3,233.65,234.0,18,154,1,7,233.58,234.13,532,400,3,1,233.53,234.17,10,1,1,1,233.45,234.25,15,50,1,1,233.4,234.41,110,600,2,2,233.39,234.43,10,5,1,1,AAPL,-19,-0.27820110563275063,0.003591117662158104
2024-10-21T12:05:41.923099064Z,2024-10-21T12:05:41.922932814Z,10,2,38,C,B,5,233.58,27,130,166250,12019448,233.78,233.89,326,28,1,1,233.7,233.92,1200,200,1,1,233.68,233.94,200,200,1,1,233.66,233.98,1,44,1,3,233.65,234.0,18,154,1,7,233.58,234.13,505,400,2,1,233.53,234.17,10,1,1,1,233.45,234.25,15,50,1,1,233.4,234.41,110,600,2,2,233.39,234.43,10,5,1,1,AAPL,-19,-0.28324388789505067,0.0036562116681915268
2024-10-21T12:05:41.923167380Z,2024-10-21T12:05:41.923000912Z,10,2,38,A,B,5,233.63,28,130,166468,12019449,233.78,233.89,326,28,1,1,233.7,233.92,1200,200,1,1,233.68,233.94,200,200,1,1,233.66,233.98,1,44,1,3,233.65,234.0,18,154,1,7,233.63,234.13,28,400,1,1,233.58,234.17,505,1,2,1,233.53,234.25,10,50,1,1,233.45,234.41,15,600,1,2,233.4,234.43,110,5,2,1,AAPL,91,1.3603986516195223,-0.01756050398971462
2024-10-21T12:05:41.948798033Z,2024-10-21T12:05:41.948630132Z,10,2,38,T,N,0,233.79,162,130,167901,12019456,233.78,233.89,326,28,1,1,233.7,233.92,1200,200,1,1,233.68,233.94,200,200,1,1,233.66,233.98,1,44,1,3,233.65,234.0,18,154,1,7,233.63,234.13,28,400,1,1,233.58,234.17,505,1,2,1,233.53,234.25,10,50,1,1,233.45,234.41,15,600,1,2,233.4,234.43,110,5,2,1,AAPL,91,1.3640818679734792,-0.017608048241101258
2024-10-21T12:05:41.952129039Z,2024-10-21T12:05:41.951962933Z,10,2,38,C,B,2,233.68,200,130,166106,12019457,233.78,233.89,326,28,1,1,233.7,233.92,1200,200,1,1,233.66,233.94,1,200,1,1,233.65,233.98,18,44,1,3,233.63,234.0,28,154,1,7,233.58,234.13,505,400,2,1,233.53,234.17,10,1,1,1,233.45,234.25,15,50,1,1,233.4,234.41,110,600,2,2,233.39,234.43,10,5,1,1,AAPL,81,1.2348626492161656,-0.0159400411434507
2024-10-21T12:05:41.952142239Z,2024-10-21T12:05:41.951975929Z,10,2,38,A,B,3,233.65,400,130,166310,12019458,233.78,233.89,326,28,1,1,233.7,233.92,1200,200,1,1,233.66,233.94,1,200,1,1,233.65,233.98,418,44,2,3,233.63,234.0,28,154,1,7,233.58,234.13,505,400,2,1,233.53,234.17,10,1,1,1,233.45,234.25,15,50,1,1,233.4,234.41,110,600,2,2,233.39,234.43,10,5,1,1,AAPL,81,1.2554535017221584,-0.016205835105501935
2024-10-21T12:05:41.952733597Z,2024-10-21T12:05:41.952567424Z,10,2,38,C,A,0,233.89,28,130,166173,12019459,233.78,233.92,326,200,1,1,233.7,233.94,1200,200,1,1,233.66,233.98,1,44,1,3,233.65,234.0,418,154,2,7,233.63,234.13,28,400,1,1,233.58,234.17,505,1,2,1,233.53,234.25,10,50,1,1,233.45,234.41,15,600,1,2,233.4,234.43,110,5,2,1,233.39,234.5,10,63,1,4,AAPL,144,2.249680443118875,-0.02903966594640591
2024-10-21T12:05:41.952786117Z,2024-10-21T12:05:41.952619801Z,10,2,38,A,A,2,233.95,29,130,166316,12019460,233.78,233.92,326,200,1,1,233.7,233.94,1200,200,1,1,233.66,233.95,1,29,1,1,233.65,233.98,418,44,2,3,233.63,234.0,28,154,1,7,233.58,234.13,505,400,2,1,233.53,234.17,10,1,1,1,233.45,234.25,15,50,1,1,233.4,234.41,110,600,2,2,233.39,234.43,10,5,1,1,AAPL,139,2.2063492063492065,-0.028480331110791967
2024-10-21T12:05:43.153890594Z,2024-10-21T12:05:43.153724103Z,10,2,38,A,B,2,233.69,200,130,166491,12020040,233.78,233.92,326,200,1,1,233.7,233.94,1200,200,1,1,233.69,233.95,200,29,1,1,233.66,233.98,1,44,1,3,233.65,234.0,18,154,1,7,233.63,234.13,28,400,1,1,233.58,234.17,505,1,2,1,233.53,234.25,10,50,1,1,233.45,234.41,15,600,1,2,233.4,234.43,110,5,2,1,AAPL,249,3.9584437316971135,-0.05109698312386247
2024-10-21T12:05:43.258851703Z,2024-10-21T12:05:43.258685033Z,10,2,38,T,A,0,233.78,250,130,166670,12020063,233.78,233.92,326,200,1,1,233.7,233.94,1200,200,1,1,233.69,233.95,200,29,1,1,233.66,233.98,1,44,1,3,233.65,234.0,18,154,1,7,233.63,234.13,28,400,1,1,233.58,234.17,505,1,2,1,233.53,234.25,10,50,1,1,233.45,234.41,15,600,1,2,233.4,234.43,110,5,2,1,AAPL,249,3.964315124897063,-0.051172773131144635
2024-10-21T12:05:43.258851703Z,2024-10-21T12:05:43.258685033Z,10,2,38,C,B,0,233.78,250,130,166670,12020063,233.78,233.92,76,200,1,1,233.7,233.94,1200,200,1,1,233.69,233.95,200,29,1,1,233.66,233.98,1,44,1,3,233.65,234.0,18,154,1,7,233.63,234.13,28,400,1,1,233.58,234.17,505,1,2,1,233.53,234.25,10,50,1,1,233.45,234.41,15,600,1,2,233.4,234.43,110,5,2,1,AAPL,249,3.9700040535062833,-0.05124620782135142
2024-10-21T12:05:43.258921916Z,2024-10-21T12:05:43.258755715Z,10,2,38,C,B,2,233.69,200,130,166201,12020064,233.78,233.92,76,200,1,1,233.7,233.94,1200,200,1,1,233.66,233.95,1,29,1,1,233.65,233.98,18,44,1,3,233.63,234.0,28,154,1,7,233.58,234.13,505,400,2,1,233.53,234.17,10,1,1,1,233.45,234.25,15,50,1,1,233.4,234.41,110,600,2,2,233.39,234.43,10,5,1,1,AAPL,239,3.8673139158576055,-0.0499206474279056
2024-10-21T12:05:43.337489880Z,2024-10-21T12:05:43.337323654Z,10,2,38,A,B,5,233.59,200,130,166226,12020098,233.78,233.92,76,200,1,1,233.7,233.94,1200,200,1,1,233.66,233.95,1,29,1,1,233.65,233.98,18,44,1,3,233.63,234.0,28,154,1,7,233.59,234.13,200,400,1,1,233.58,234.17,505,1,2,1,233.53,234.25,10,50,1,1,233.45,234.41,15,600,1,2,233.4,234.43,110,5,2,1,AAPL,349,5.6536980480679855,-0.07297992173951878
2024-10-21T12:05:43.337620382Z,2024-10-21T12:05:43.337453873Z,10,2,38,A,A,0,233.92,200,130,166509,12020100,233.78,233.92,76,400,1,2,233.7,233.94,1200,200,1,1,233.66,233.95,1,29,1,1,233.65,233.98,18,44,1,3,233.63,234.0,28,154,1,7,233.59,234.13,200,400,1,1,233.58,234.17,505,1,2,1,233.53,234.25,10,50,1,1,233.45,234.41,15,600,1,2,233.4,234.43,110,5,2,1,AAPL,349,5.659952916557677,-0.0730606617806366
2024-10-21T12:05:43.338078299Z,2024-10-21T12:05:43.337912322Z,10,2,38,C,B,4,233.63,28,130,165977,12020101,233.78,233.92,76,400,1,2,233.7,233.94,1200,200,1,1,233.66,233.95,1,29,1,1,233.65,233.98,18,44,1,3,233.59,234.0,200,154,1,7,233.58,234.13,505,400,2,1,233.53,234.17,10,1,1,1,233.45,234.25,15,50,1,1,233.4,234.41,110,600,2,2,233.39,234.43,10,5,1,1,AAPL,339,5.575512335204281,-0.07197067307476358
2024-10-21T12:05:43.338131765Z,2024-10-21T12:05:43.337965586Z,10,2,38,A,B,7,233.52,26,130,166179,12020102,233.78,233.92,76,400,1,2,233.7,233.94,1200,200,1,1,233.66,233.95,1,29,1,1,233.65,233.98,18,44,1,3,233.59,234.0,200,154,1,7,233.58,234.13,505,400,2,1,233.53,234.17,10,1,1,1,233.52,234.25,26,50,1,1,233.45,234.41,15,600,1,2,233.4,234.43,110,5,2,1,AAPL,449,7.390946502057613,-0.09540493544494445
2024-10-21T12:05:43.365944776Z,2024-10-21T12:05:43.365778374Z,10,2,38,A,B,4,233.59,200,130,166402,12020108,233.78,233.92,76,400,1,2,233.7,233.94,1200,200,1,1,233.66,233.95,1,29,1,1,233.65,233.98,18,44,1,3,233.59,234.0,400,154,2,7,233.58,234.13,505,400,2,1,233.53,234.17,10,1,1,1,233.52,234.25,26,50,1,1,233.45,234.41,15,600,1,2,233.4,234.43,110,5,2,1,AAPL,449,7.397034596375618,-0.09548352270643125
2024-10-21T12:05:43.393956628Z,2024-10-21T12:05:43.393790686Z,10,2,38,C,A,0,233.92,200,130,165942,12020113,233.78,233.92,76,200,1,1,233.7,233.94,1200,200,1,1,233.66,233.95,1,29,1,1,233.65,233.98,18,44,1,3,233.59,234.0,400,154,2,7,233.58,234.13,505,400,2,1,233.53,234.17,10,1,1,1,233.52,234.25,26,50,1,1,233.45,234.41,15,600,1,2,233.4,234.43,110,5,2,1,AAPL,449,7.402947789158132,-0.09555985227741816
2024-10-21T12:05:43.393969995Z,2024-10-21T12:05:43.393803680Z,10,2,38,A,A,0,233.88,200,130,166315,12020114,233.78,233.88,76,200,1,1,233.7,233.94,1200,200,1,1,233.66,233.95,1,29,1,1,233.65,233.98,18,44,1,3,233.59,234.0,400,154,2,7,233.58,234.13,505,400,2,1,233.53,234.17,10,1,1,1,233.52,234.25,26,50,1,1,233.45,234.41,15,600,1,2,233.4,234.43,110,5,2,1,AAPL,449,7.408693510651398,-0.09563402007013551
2024-10-21T12:05:43.596230510Z,2024-10-21T12:05:43.596064460Z,10,2,38,C,B,4,233.59,200,130,166050,12020213,233.78,233.88,76,200,1,1,233.7,233.94,1200,200,1,1,233.66,233.95,1,29,1,1,233.65,233.98,18,44,1,3,233.59,234.0,200,154,1,7,233.58,234.13,505,400,2,1,233.53,234.17,10,1,1,1,233.52,234.25,26,50,1,1,233.45,234.41,15,600,1,2,233.4,234.43,110,5,2,1,AAPL,449,7.414278776104905,-0.09570611663988965
2024-10-21T12:05:43.596242797Z,2024-10-21T12:05:43.596076460Z,10,2,38,A,B,3,233.65,400,130,166337,12020214,233.78,233.88,76,200,1,1,233.7,233.94,1200,200,1,1,233.66,233.95,1,29,1,1,233.65,233.98,418,44,2,3,233.58,234.0,505,154,2,7,233.53,234.13,10,400,1,1,233.52,234.17,26,1,1,1,233.45,234.25,15,50,1,1,233.4,234.41,110,600,2,2,233.39,234.43,10,5,1,1,AAPL,439,7.34238274148588,-0.09477805735280566
2024-10-21T12:05:45.923051933Z,2024-10-21T12:05:45.922885872Z,10,2,38,C,B,6,233.52,26,130,166061,12021802,233.78,233.88,76,200,1,1,233.7,233.94,1200,200,1,1,233.66,233.95,1,29,1,1,233.65,233.98,418,44,2,3,233.58,234.0,505,154,2,7,233.53,234.13,10,400,1,1,233.45,234.17,15,1,1,1,233.4,234.25,110,50,2,1,233.39,234.41,10,600,1,2,233.31,234.43,110,5,2,1,AAPL,329,5.50561797752809,-0.07106845213726844
2024-10-21T12:05:45.923182693Z,2024-10-21T12:05:45.923016443Z,10,2,38,A,B,4,233.58,29,130,166250,12021803,233.78,233.88,76,200,1,1,233.7,233.94,1200,200,1,1,233.66,233.95,1,29,1,1,233.65,233.98,418,44,2,3,233.58,234.0,534,154,3,7,233.53,234.13,10,400,1,1,233.45,234.17,15,1,1,1,233.4,234.25,110,50,2,1,233.39,234.41,10,600,1,2,233.31,234.43,110,5,2,1,AAPL,329,5.508548520221672,-0.07110628061247416
2024-10-21T12:05:46.352924753Z,2024-10-21T12:05:46.352758108Z,10,2,38,A,B,1,233.76,100,130,166645,12022103,233.78,233.88,76,200,1,1,233.76,233.94,100,200,1,1,233.7,233.95,1200,29,1,1,233.66,233.98,1,44,1,3,233.65,234.0,418,154,2,7,233.58,234.13,534,400,3,1,233.53,234.17,10,1,1,1,233.45,234.25,15,50,1,1,233.4,234.41,110,600,2,2,233.39,234.43,10,5,1,1,AAPL,339,5.745762711864407,-0.07416832478151249
2024-10-21T12:05:46.952584387Z,2024-10-21T12:05:46.952418271Z,10,2,38,C,A,0,233.88,200,130,166116,12022312,233.78,233.94,76,200,1,1,233.76,233.95,100,29,1,1,233.7,233.98,1200,44,1,3,233.66,234.0,1,154,1,7,233.65,234.13,418,400,2,1,233.58,234.17,534,1,3,1,233.53,234.25,10,50,1,1,233.45,234.41,15,600,1,2,233.4,234.43,110,5,2,1,233.39,234.5,10,63,1,4,AAPL,402,6.849340646516513,-0.0884136966813954
2024-10-21T12:05:46.952599898Z,2024-10-21T12:05:46.952433308Z,10,2,38,A,A,0,233.93,400,130,166590,12022313,233.78,233.93,76,400,1,1,233.76,233.94,100,200,1,1,233.7,233.95,1200,29,1,1,233.66,233.98,1,44,1,3,233.65,234.0,418,154,2,7,233.58,234.13,534,400,3,1,233.53,234.17,10,1,1,1,233.45,234.25,15,50,1,1,233.4,234.41,110,600,2,2,233.39,234.43,10,5,1,1,AAPL,397,6.844827586206897,-0.08835544051253012
2024-10-21T12:05:47.007188854Z,2024-10-21T12:05:47.007021590Z,10,2,38,A,B,3,233.68,200,130,167264,12022361,233.78,233.93,76,400,1,1,233.76,233.94,100,200,1,1,233.7,233.95,1200,29,1,1,233.68,233.98,200,44,1,3,233.66,234.0,1,154,1,7,233.65,234.13,18,400,1,1,233.58,234.17,534,1,3,1,233.53,234.25,10,50,1,1,233.45,234.41,15,600,1,2,233.4,234.43,110,5,2,1,AAPL,507,8.742384182089896,-0.11284976806353408
2024-10-21T12:05:48.195697508Z,2024-10-21T12:05:48.195531738Z,10,2,38,C,A,0,233.93,400,130,165770,12023323,233.78,233.94,76,200,1,1,233.76,233.95,100,29,1,1,233.7,233.98,1200,44,1,3,233.68,234.0,200,154,1,7,233.66,234.13,1,400,1,1,233.65,234.17,18,1,1,1,233.58,234.25,534,50,3,1,233.53,234.41,10,600,1,2,233.45,234.43,15,5,1,1,233.4,234.5,110,63,2,4,AAPL,610,10.539956803455723,-0.13605346732603885
2024-10-21T12:05:48.195783198Z,2024-10-21T12:05:48.195615637Z,10,2,38,T,A,0,233.78,76,0,167561,12023325,233.78,233.94,76,200,1,1,233.76,233.95,100,29,1,1,233.7,233.98,1200,44,1,3,233.68,234.0,200,154,1,7,233.66,234.13,1,400,1,1,233.65,234.17,18,1,1,1,233.58,234.25,534,50,3,1,233.53,234.41,10,600,1,2,233.45,234.43,15,5,1,1,233.4,234.5,110,63,2,4,AAPL,610,10.464942814520139,-0.13508516038864257
2024-10-21T12:05:48.195783198Z,2024-10-21T12:05:48.195615637Z,10,2,38,T,A,0,233.76,100,130,167561,12023326,233.76,233.94,100,200,1,1,233.7,233.95,1200,29,1,1,233.68,233.98,200,44,1,3,233.66,234.0,1,154,1,7,233.65,234.13,18,400,1,1,233.58,234.17,534,1,3,1,233.53,234.25,10,50,1,1,233.45,234.41,15,600,1,2,233.4,234.43,110,5,2,1,233.39,234.5,10,63,1,4,AAPL,600,10.348650979425896,-0.1335840245034279
2024-10-21T12:05:48.195783198Z,2024-10-21T12:05:48.195615637Z,10,2,38,C,B,0,233.76,100,130,167561,12023326,233.7,233.94,1200,200,1,1,233.68,233.95,200,29,1,1,233.66,233.98,1,44,1,3,233.65,234.0,18,154,1,7,233.58,234.13,534,400,3,1,233.53,234.17,10,1,1,1,233.45,234.25,15,50,1,1,233.4,234.41,110,600,2,2,233.39,234.43,10,5,1,1,233.31,234.5,110,63,2,4,AAPL,490,8.393244873341375,-0.10834295514002397
2024-10-21T12:05:48.195805043Z,2024-10-21T12:05:48.195638794Z,10,2,38,A,A,0,233.85,100,130,166249,12023327,233.7,233.85,1200,100,1,1,233.68,233.94,200,200,1,1,233.66,233.95,1,29,1,1,233.65,233.98,18,44,1,3,233.58,234.0,534,154,3,7,233.53,234.13,10,400,1,1,233.45,234.17,15,1,1,1,233.4,234.25,110,50,2,1,233.39,234.41,10,600,1,2,233.31,234.43,110,5,2,1,AAPL,485,8.30933967876264,-0.10725987739483245
2024-10-21T12:05:48.195809855Z,2024-10-21T12:05:48.195643749Z,10,2,38,A,A,1,233.9,100,130,166106,12023328,233.7,233.85,1200,100,1,1,233.68,233.9,200,100,1,1,233.66,233.94,1,200,1,1,233.65,233.95,18,29,1,1,233.58,233.98,534,44,3,3,233.53,234.0,10,154,1,7,233.45,234.13,15,400,1,1,233.4,234.17,110,1,2,1,233.39,234.25,10,50,1,1,233.31,234.41,110,600,2,2,AAPL,-115,-1.8420186505759737,0.0237774242308018
2024-10-21T12:05:48.195817817Z,2024-10-21T12:05:48.195651625Z,10,2,38,A,A,2,233.91,100,130,166192,12023329,233.7,233.85,1200,100,1,1,233.68,233.9,200,100,1,1,233.66,233.91,1,100,1,1,233.65,233.94,18,200,1,1,233.58,233.95,534,29,3,1,233.53,233.98,10,44,1,3,233.45,234.0,15,154,1,7,233.4,234.13,110,400,2,1,233.39,234.17,10,1,1,1,233.31,234.25,110,50,2,1,AAPL,-165,-2.6328840970350402,0.033986193411319976
2024-10-21T12:05:48.195819428Z,2024-10-21T12:05:48.195652834Z,10,2,38,A,A,0,233.85,33,130,166594,12023331,233.7,233.85,1200,133,1,2,233.68,233.9,200,200,1,2,233.66,233.91,1,100,1,1,233.65,233.94,18,200,1,1,233.58,233.95,534,29,3,1,233.53,233.98,10,44,1,3,233.45,234.0,15,154,1,7,233.4,234.13,110,400,2,1,233.39,234.17,10,1,1,1,233.31,234.25,110,50,2,1,AAPL,-165,-2.6232114467408585,0.03386133544128312
2024-10-21T12:05:48.195835783Z,2024-10-21T12:05:48.195667975Z,10,2,38,A,A,0,233.91,33,130,167808,12023333,233.7,233.84,1200,100,1,1,233.68,233.85,200,133,1,2,233.66,233.9,1,200,1,2,233.65,233.91,18,133,1,2,233.58,233.94,534,200,3,1,233.53,233.95,10,29,1,1,233.45,233.98,15,44,1,3,233.4,234.0,110,154,2,7,233.39,234.13,10,400,1,1,233.31,234.17,110,1,2,1,AAPL,-166,-2.6432013408757595,0.03411937202143704
2024-10-21T12:05:48.195836860Z,2024-10-21T12:05:48.195671113Z,10,2,38,C,B,1,233.68,200,130,165747,12023334,233.7,233.84,1200,100,1,1,233.66,233.85,1,133,1,2,233.65,233.9,18,200,1,2,233.58,233.91,534,133,3,2,233.53,233.94,10,200,1,1,233.45,233.95,15,29,1,1,233.4,233.98,110,44,2,3,233.39,234.0,10,154,1,7,233.31,234.13,110,400,2,1,233.3,234.17,100,1,1,1,AAPL,-266,-4.246294184720639,0.054812657953989034
2024-10-21T12:05:48.195841831Z,2024-10-21T12:05:48.195675914Z,10,2,38,A,A,3,233.91,100,130,165917,12023335,233.7,233.84,1200,100,1,1,233.66,233.85,1,133,1,2,233.65,233.9,18,200,1,2,233.58,233.91,534,233,3,3,233.53,233.94,10,200,1,1,233.45,233.95,15,29,1,1,233.4,233.98,110,44,2,3,233.39,234.0,10,154,1,7,233.31,234.13,110,400,2,1,233.3,234.17,100,1,1,1,AAPL,-266,-4.256873204759951,0.05494921566329465
2024-10-21T12:05:48.195845200Z,2024-10-21T12:05:48.195679038Z,10,2,38,A,A,2,233.9,100,130,166162,12023336,233.7,233.84,1200,100,1,1,233.66,233.85,1,133,1,2,233.65,233.9,18,300,1,3,233.58,233.91,534,233,3,3,233.53,233.94,10,200,1,1,233.45,233.95,15,29,1,1,233.4,233.98,110,44,2,3,233.39,234.0,10,154,1,7,233.31,234.13,110,400,2,1,233.3,234.17,100,1,1,1,AAPL,-266,-4.267235252309879,0.05508297261543916
2024-10-21T12:05:48.195856309Z,2024-10-21T12:05:48.195690635Z,10,2,38,C,A,1,233.85,100,130,165674,12023338,233.7,233.84,1200,100,1,1,233.66,233.85,1,33,1,1,233.65,233.9,18,300,1,3,233.58,233.91,534,233,3,3,233.53,233.94,10,200,1,1,233.45,233.95,15,29,1,1,233.4,233.98,110,44,2,3,233.39,234.0,10,154,1,7,233.31,234.13,110,400,2,1,233.3,234.17,100,1,1,1,AAPL,-266,-4.277386934673367,0.05521401409981149
2024-10-21T12:05:48.195867603Z,2024-10-21T12:05:48.195701993Z,10,2,38,C,A,2,233.9,100,130,165610,12023340,233.7,233.84,1200,100,1,1,233.66,233.85,1,33,1,1,233.65,233.9,18,200,1,2,233.58,233.91,534,233,3,3,233.53,233.94,10,200,1,1,233.45,233.95,15,29,1,1,233.4,233.98,110,44,2,3,233.39,234.0,10,154,1,7,233.31,234.13,110,400,2,1,233.3,234.17,100,1,1,1,AAPL,-266,-4.287334593572779,0.05534242197759311
2024-10-21T12:05:48.195872903Z,2024-10-21T12:05:48.195706051Z,10,2,38,C,A,3,233.91,100,130,166852,12023341,233.7,233.84,1200,100,1,1,233.66,233.85,1,33,1,1,233.65,233.9,18,200,1,2,233.58,233.91,534,133,3,2,233.53,233.94,10,200,1,1,233.45,233.95,15,29,1,1,233.4,233.98,110,44,2,3,233.39,234.0,10,154,1,7,233.31,234.13,110,400,2,1,233.3,234.17,100,1,1,1,AAPL,-266,-4.2970843183609135,0.05546827485229042
2024-10-21T12:05:48.195937493Z,2024-10-21T12:05:48.195771617Z,10,2,38,C,A,3,233.91,100,130,165876,12023342,233.7,233.84,1200,100,1,1,233.66,233.85,1,33,1,1,233.65,233.9,18,200,1,2,233.58,233.91,534,33,3,1,233.53,233.94,10,200,1,1,233.45,233.95,15,29,1,1,233.4,233.98,110,44,2,3,233.39,234.0,10,154,1,7,233.31,234.13,110,400,2,1,233.3,234.17,100,1,1,1,AAPL,-266,-4.306641958451185,0.0555916482301879
2024-10-21T12:05:48.195966195Z,2024-10-21T12:05:48.195800135Z,10,2,38,C,A,0,233.84,100,130,166060,12023344,233.7,233.85,1200,33,1,1,233.66,233.9,1,200,1,2,233.65,233.91,18,33,1,1,233.58,233.94,534,200,3,1,233.53,233.95,10,29,1,1,233.45,233.98,15,44,1,3,233.4,234.0,110,154,2,7,233.39,234.13,10,400,1,1,233.31,234.17,110,1,2,1,233.3,234.25,100,50,1,1,AAPL,-216,-3.4882245506104006,0.04502722864734673
2024-10-21T12:05:48.196014405Z,2024-10-21T12:05:48.195848770Z,10,2,38,C,A,1,233.9,100,130,165635,12023346,233.7,233.85,1200,33,1,1,233.66,233.9,1,100,1,1,233.65,233.91,18,33,1,1,233.58,233.94,534,200,3,1,233.53,233.95,10,29,1,1,233.45,233.98,15,44,1,3,233.4,234.0,110,154,2,7,233.39,234.13,10,400,1,1,233.31,234.17,110,1,2,1,233.3,234.25,100,50,1,1,AAPL,-216,-3.479579266559272,0.04491563228190538
2024-10-21T12:05:48.196120006Z,2024-10-21T12:05:48.195954138Z,10,2,38,C,A,1,233.9,100,130,165868,12023347,233.7,233.85,1200,33,1,1,233.66,233.91,1,33,1,1,233.65,233.94,18,200,1,1,233.58,233.95,534,29,3,1,233.53,233.98,10,44,1,3,233.45,234.0,15,154,1,7,233.4,234.13,110,400,2,1,233.39,234.17,10,1,1,1,233.31,234.25,110,50,2,1,233.3,234.41,100,600,1,2,AAPL,384,5.8693681684884025,-0.07576386746424903
2024-10-21T12:05:48.259989271Z,2024-10-21T12:05:48.259822838Z,10,2,38,A,B,3,233.59,400,130,166433,12023416,233.7,233.85,1200,33,1,1,233.66,233.91,1,33,1,1,233.65,233.94,18,200,1,1,233.59,233.95,400,29,1,1,233.58,233.98,534,44,3,3,233.53,234.0,10,154,1,7,233.45,234.13,15,400,1,1,233.4,234.17,110,1,2,1,233.39,234.25,10,50,1,1,233.31,234.41,110,600,2,2,AAPL,494,7.185154225528714,-0.09274849640133322
2024-10-21T12:05:48.263512682Z,2024-10-21T12:05:48.263346529Z,10,2,38,C,B,4,233.58,29,130,166153,12023419,233.7,233.85,1200,33,1,1,233.66,233.91,1,33,1,1,233.65,233.94,18,200,1,1,233.59,233.95,400,29,1,1,233.58,233.98,505,44,2,3,233.53,234.0,10,154,1,7,233.45,234.13,15,400,1,1,233.4,234.17,110,1,2,1,233.39,234.25,10,50,1,1,233.31,234.41,110,600,2,2,AAPL,494,6.86056971514243,-0.0885586454463559
2024-10-21T12:05:48.297368202Z,2024-10-21T12:05:48.297202075Z,10,2,38,A,A,2,233.93,400,130,166127,12023433,233.7,233.85,1200,33,1,1,233.66,233.91,1,33,1,1,233.65,233.93,18,400,1,1,233.59,233.94,400,200,1,1,233.58,233.95,505,29,2,1,233.53,233.98,10,44,1,3,233.45,234.0,15,154,1,7,233.4,234.13,110,400,2,1,233.39,234.17,10,1,1,1,233.31,234.25,110,50,2,1,AAPL,444,6.158497623314892,-0.07949605209923101
2024-10-21T12:05:48.297397398Z,2024-10-21T12:05:48.297231678Z,10,2,38,C,A,1,233.91,33,130,165720,12023434,233.7,233.85,1200,33,1,1,233.66,233.93,1,400,1,1,233.65,233.94,18,200,1,1,233.59,233.95,400,29,1,1,233.58,233.98,505,44,2,3,233.53,234.0,10,154,1,7,233.45,234.13,15,400,1,1,233.4,234.17,110,1,2,1,233.39,234.25,10,50,1,1,233.31,234.41,110,600,2,2,AAPL,1044,13.87580299785867,-0.17911374258884524
2024-10-21T12:05:48.313398298Z,2024-10-21T12:05:48.313231819Z,10,2,38,A,A,1,233.88,200,130,166479,12023436,233.7,233.85,1200,33,1,1,233.66,233.88,1,200,1,1,233.65,233.94,18,200,1,1,233.59,233.95,400,29,1,1,233.58,233.98,505,44,2,3,233.53,234.0,10,154,1,7,233.45,234.13,15,400,1,1,233.4,234.17,110,1,2,1,233.39,234.25,10,50,1,1,233.31,234.41,110,600,2,2,AAPL,1044,13.331088191959587,-0.17208237240124616
2024-10-21T12:05:48.453931984Z,2024-10-21T12:05:48.453765847Z,10,2,38,C,A,0,233.85,33,130,166137,12023463,233.7,233.88,1200,200,1,1,233.66,233.94,1,200,1,1,233.65,233.95,18,29,1,1,233.59,233.98,400,44,1,3,233.58,234.0,505,154,2,7,233.53,234.13,10,400,1,1,233.45,234.17,15,1,1,1,233.4,234.25,110,50,2,1,233.39,234.41,10,600,1,2,233.31,234.43,110,5,2,1,AAPL,1049,13.433741648106905,-0.17340745929697848
2024-10-21T12:05:48.461595380Z,2024-10-21T12:05:48.461428130Z,10,2,38,A,A,0,233.88,200,130,167250,12023464,233.7,233.88,1200,400,1,2,233.66,233.94,1,200,1,1,233.65,233.95,18,29,1,1,233.59,233.98,400,44,1,3,233.58,234.0,505,154,2,7,233.53,234.13,10,400,1,1,233.45,234.17,15,1,1,1,233.4,234.25,110,50,2,1,233.39,234.41,10,600,1,2,233.31,234.43,110,5,2,1,AAPL,1049,13.471932610646967,-0.17390044166597554
2024-10-21T12:05:48.825810960Z,2024-10-21T12:05:48.825644162Z,10,2,38,A,B,3,233.62,200,130,166798,12023548,233.7,233.88,1200,400,1,2,233.66,233.94,1,200,1,1,233.65,233.95,18,29,1,1,233.62,233.98,200,44,1,3,233.58,234.0,505,154,2,7,233.53,234.13,10,400,1,1,233.45,234.17,15,1,1,1,233.4,234.25,110,50,2,1,233.39,234.41,10,600,1,2,233.31,234.43,110,5,2,1,AAPL,1049,13.509521852308536,-0.17438565681036175
2024-10-21T12:05:49.592266377Z,2024-10-21T12:05:49.592099813Z,10,2,38,A,B,2,233.65,200,130,166564,12023911,233.7,233.88,1200,400,1,2,233.66,233.94,1,200,1,1,233.65,233.95,218,29,2,1,233.58,233.98,505,44,2,3,233.53,234.0,10,154,1,7,233.45,234.13,15,400,1,1,233.4,234.17,110,1,2,1,233.39,234.25,10,50,1,1,233.31,234.41,110,600,2,2,233.3,234.43,100,5,1,1,AAPL,949,12.263483642793988,-0.15830135760625108
2024-10-21T12:05:52.517347120Z,2024-10-21T12:05:52.517180690Z,10,2,38,A,B,4,233.57,29,130,166430,12025554,233.7,233.88,1200,400,1,2,233.66,233.94,1,200,1,1,233.65,233.95,218,29,2,1,233.58,233.98,505,44,2,3,233.57,234.0,29,154,1,7,233.53,234.13,10,400,1,1,233.45,234.17,15,1,1,1,233.4,234.25,110,50,2,1,233.39,234.41,10,600,1,2,233.31,234.43,110,5,2,1,AAPL,949,12.301132487378906,-0.15878734212612292
2024-10-21T12:05:55.930276631Z,2024-10-21T12:05:55.930110286Z,10,2,38,C,B,2,233.65,18,130,166345,12028586,233.7,233.88,1200,400,1,2,233.66,233.94,1,200,1,1,233.65,233.95,200,29,1,1,233.58,233.98,505,44,2,3,233.57,234.0,29,154,1,7,233.53,234.13,10,400,1,1,233.45,234.17,15,1,1,1,233.4,234.25,110,50,2,1,233.39,234.41,10,600,1,2,233.31,234.43,110,5,2,1,AAPL,939,12.205766438498236,-0.15755632364498973
2024-10-21T12:05:57.923095285Z,2024-10-21T12:05:57.922929284Z,10,2,38,C,B,4,233.57,29,130,166001,12029987,233.7,233.88,1200,400,1,2,233.66,233.94,1,200,1,1,233.65,233.95,200,29,1,1,233.58,233.98,505,44,2,3,233.53,234.0,10,154,1,7,233.45,234.13,15,400,1,1,233.4,234.17,110,1,2,1,233.39,234.25,10,50,1,1,233.31,234.41,110,600,2,2,233.3,234.43,100,5,1,1,AAPL,839,10.942476661175178,-0.14124933513949706
2024-10-21T12:05:57.923232470Z,2024-10-21T12:05:57.923066098Z,10,2,38,A,B,3,233.58,30,130,166372,12029988,233.7,233.88,1200,400,1,2,233.66,233.94,1,200,1,1,233.65,233.95,200,29,1,1,233.58,233.98,535,44,3,3,233.53,234.0,10,154,1,7,233.45,234.13,15,400,1,1,233.4,234.17,110,1,2,1,233.39,234.25,10,50,1,1,233.31,234.41,110,600,2,2,233.3,234.43,100,5,1,1,AAPL,839,10.978531997546513,-0.14171475009521287
2024-10-21T12:06:05.427305884Z,2024-10-21T12:06:05.427139071Z,10,2,38,A,A,0,233.8,5,130,166813,12035523,233.7,233.8,1200,5,1,1,233.66,233.88,1,400,1,2,233.65,233.94,200,200,1,1,233.58,233.95,535,29,3,1,233.53,233.98,10,44,1,3,233.45,234.0,15,154,1,7,233.4,234.13,110,400,2,1,233.39,234.17,10,1,1,1,233.31,234.25,110,50,2,1,233.3,234.41,100,600,1,2,AAPL,-120,-1.0892586989409985,0.014060534171960116
2024-10-21T12:06:06.690962423Z,2024-10-21T12:06:06.690796307Z,10,2,38,C,A,1,233.88,200,130,166116,12036944,233.7,233.8,1200,5,1,1,233.66,233.88,1,200,1,1,233.65,233.94,200,200,1,1,233.58,233.95,535,29,3,1,233.53,233.98,10,44,1,3,233.45,234.0,15,154,1,7,233.4,234.13,110,400,2,1,233.39,234.17,10,1,1,1,233.31,234.25,110,50,2,1,233.3,234.41,100,600,1,2,AAPL,-20,-0.16357206012378425,0.002111445649398446
2024-10-21T12:06:06.690975076Z,2024-10-21T12:06:06.690808686Z,10,2,38,A,A,1,233.87,200,130,166390,12036945,233.7,233.8,1200,5,1,1,233.66,233.87,1,200,1,1,233.65,233.94,200,200,1,1,233.58,233.95,535,29,3,1,233.53,233.98,10,44,1,3,233.45,234.0,15,154,1,7,233.4,234.13,110,400,2,1,233.39,234.17,10,1,1,1,233.31,234.25,110,50,2,1,233.3,234.41,100,600,1,2,AAPL,-20,-0.15592942141977842,0.0020127917825382654
2024-10-21T12:06:06.702077630Z,2024-10-21T12:06:06.701910843Z,10,2,38,C,A,3,233.95,29,130,166787,12037042,233.7,233.8,1200,5,1,1,233.66,233.87,1,200,1,1,233.65,233.94,200,200,1,1,233.58,233.98,535,44,3,3,233.53,234.0,10,154,1,7,233.45,234.13,15,400,1,1,233.4,234.17,110,1,2,1,233.39,234.25,10,50,1,1,233.31,234.41,110,600,2,2,233.3,234.43,100,5,1,1,AAPL,-15,-0.11874555972800163,0.00153280942529754
2024-10-21T12:06:06.702133954Z,2024-10-21T12:06:06.701967763Z,10,2,38,A,A,2,233.94,26,130,166191,12037043,233.7,233.8,1200,5,1,1,233.66,233.87,1,200,1,1,233.65,233.94,200,226,1,2,233.58,233.98,535,44,3,3,233.53,234.0,10,154,1,7,233.45,234.13,15,400,1,1,233.4,234.17,110,1,2,1,233.39,234.25,10,50,1,1,233.31,234.41,110,600,2,2,233.3,234.43,100,5,1,1,AAPL,-15,-0.12050612572805784,0.001555535430083959
2024-10-21T12:06:06.737721359Z,2024-10-21T12:06:06.737555073Z,10,2,38,C,B,2,233.65,200,130,166286,12037240,233.7,233.8,1200,5,1,1,233.66,233.87,1,200,1,1,233.58,233.94,535,226,3,2,233.53,233.98,10,44,1,3,233.45,234.0,15,154,1,7,233.4,234.13,110,400,2,1,233.39,234.17,10,1,1,1,233.31,234.25,110,50,2,1,233.3,234.41,100,600,1,2,233.25,234.43,55,5,2,1,AAPL,-70,-0.5729686564184467,0.007396080821632277
2024-10-21T12:06:06.737734292Z,2024-10-21T12:06:06.737568257Z,10,2,38,A,B,2,233.63,200,130,166035,12037241,233.7,233.8,1200,5,1,1,233.66,233.87,1,200,1,1,233.63,233.94,200,226,1,2,233.58,233.98,535,44,3,3,233.53,234.0,10,154,1,7,233.45,234.13,15,400,1,1,233.4,234.17,110,1,2,1,233.39,234.25,10,50,1,1,233.31,234.41,110,600,2,2,233.3,234.43,100,5,1,1,AAPL,30,0.2489380618393757,-0.0032133800066017713
2024-10-21T12:06:06.784818334Z,2024-10-21T12:06:06.784651971Z,10,2,38,A,B,2,233.63,200,130,166363,12037447,233.7,233.8,1200,5,1,1,233.66,233.87,1,200,1,1,233.63,233.94,400,226,2,2,233.58,233.98,535,44,3,3,233.53,234.0,10,154,1,7,233.45,234.13,15,400,1,1,233.4,234.17,110,1,2,1,233.39,234.25,10,50,1,1,233.31,234.41,110,600,2,2,233.3,234.43,100,5,1,1,AAPL,30,0.2522487289792726,-0.0032561152617783078
2024-10-21T12:06:06.795657010Z,2024-10-21T12:06:06.795491217Z,10,2,38,C,B,2,233.63,200,130,165793,12037500,233.7,233.8,1200,5,1,1,233.66,233.87,1,200,1,1,233.63,233.94,200,226,1,2,233.58,233.98,535,44,3,3,233.53,234.0,10,154,1,7,233.45,234.13,15,400,1,1,233.4,234.17,110,1,2,1,233.39,234.25,10,50,1,1,233.31,234.41,110,600,2,2,233.3,234.43,100,5,1,1,AAPL,30,0.2554921126487951,-0.0032979819982683956
2024-10-21T12:06:06.795669136Z,2024-10-21T12:06:06.795502438Z,10,2,38,A,B,2,233.64,200,130,166698,12037501,233.7,233.8,1200,5,1,1,233.66,233.87,1,200,1,1,233.64,233.94,200,226,1,2,233.58,233.98,535,44,3,3,233.53,234.0,10,154,1,7,233.45,234.13,15,400,1,1,233.4,234.17,110,1,2,1,233.39,234.25,10,50,1,1,233.31,234.41,110,600,2,2,233.3,234.43,100,5,1,1,AAPL,30,0.25867024334163635,-0.0033390064263983657
2024-10-21T12:06:07.734864255Z,2024-10-21T12:06:07.734697882Z,10,2,38,A,B,0,233.74,100,130,166373,12038529,233.74,233.8,100,5,1,1,233.7,233.87,1200,200,1,1,233.66,233.94,1,226,1,2,233.64,233.98,200,44,1,3,233.58,234.0,535,154,3,7,233.53,234.13,10,400,1,1,233.45,234.17,15,1,1,1,233.4,234.25,110,50,2,1,233.39,234.41,10,600,1,2,233.31,234.43,110,5,2,1,AAPL,-28,-0.23265700483091786,0.003003218399771719
2024-10-21T12:06:07.735268195Z,2024-10-21T12:06:07.735102284Z,10,2,38,C,B,0,233.74,100,130,165911,12038532,233.7,233.8,1200,5,1,1,233.66,233.87,1,200,1,1,233.64,233.94,200,226,1,2,233.58,233.98,535,44,3,3,233.53,234.0,10,154,1,7,233.45,234.13,15,400,1,1,233.4,234.17,110,1,2,1,233.39,234.25,10,50,1,1,233.31,234.41,110,600,2,2,233.3,234.43,100,5,1,1,AAPL,-128,-1.0773792443806791,0.013907189996740758
2024-10-21T12:06:07.797485159Z,2024-10-21T12:06:07.797318931Z,10,2,38,C,A,2,233.94,26,130,166228,12038578,233.7,233.8,1200,5,1,1,233.66,233.87,1,200,1,1,233.64,233.94,200,200,1,1,233.58,233.98,535,44,3,3,233.53,234.0,10,154,1,7,233.45,234.13,15,400,1,1,233.4,234.17,110,1,2,1,233.39,234.25,10,50,1,1,233.31,234.41,110,600,2,2,233.3,234.43,100,5,1,1,AAPL,-128,-1.090909090909091,0.014081838011614603
2024-10-21T12:06:07.797594793Z,2024-10-21T12:06:07.797428592Z,10,2,38,A,A,2,233.93,29,130,166201,12038579,233.7,233.8,1200,5,1,1,233.66,233.87,1,200,1,1,233.64,233.93,200,29,1,1,233.58,233.94,535,200,3,1,233.53,233.98,10,44,1,3,233.45,234.0,15,154,1,7,233.4,234.13,110,400,2,1,233.39,234.17,10,1,1,1,233.31,234.25,110,50,2,1,233.3,234.41,100,600,1,2,AAPL,-728,-5.948134991119005,0.07678061729814162
2024-10-21T12:06:07.802522549Z,2024-10-21T12:06:07.802356464Z,10,2,38,C,A,1,233.87,200,130,166085,12038584,233.7,233.8,1200,5,1,1,233.66,233.93,1,29,1,1,233.64,233.94,200,200,1,1,233.58,233.98,535,44,3,3,233.53,234.0,10,154,1,7,233.45,234.13,15,400,1,1,233.4,234.17,110,1,2,1,233.39,234.25,10,50,1,1,233.31,234.41,110,600,2,2,233.3,234.43,100,5,1,1,AAPL,-723,-5.9799384073911135,0.0771911469746214
2024-10-21T12:06:07.802534762Z,2024-10-21T12:06:07.802368533Z,10,2,38,A,A,1,233.92,200,130,166229,12038585,233.7,233.8,1200,5,1,1,233.66,233.92,1,200,1,1,233.64,233.93,200,29,1,1,233.58,233.94,535,200,3,1,233.53,233.98,10,44,1,3,233.45,234.0,15,154,1,7,233.4,234.13,110,400,2,1,233.39,234.17,10,1,1,1,233.31,234.25,110,50,2,1,233.3,234.41,100,600,1,2,AAPL,-1323,-10.526978864484045,0.1358859435279087
2024-10-21T12:06:07.806114373Z,2024-10-21T12:06:07.805948070Z,10,2,38,A,B,2,233.64,200,130,166303,12038589,233.7,233.8,1200,5,1,1,233.66,233.92,1,200,1,1,233.64,233.93,400,29,2,1,233.58,233.94,535,200,3,1,233.53,233.98,10,44,1,3,233.45,234.0,15,154,1,7,233.4,234.13,110,400,2,1,233.39,234.17,10,1,1,1,233.31,234.25,110,50,2,1,233.3,234.41,100,600,1,2,AAPL,-1323,-10.156991774383078,0.1311100201144841
2024-10-21T12:06:07.846595428Z,2024-10-21T12:06:07.846428844Z,10,2,38,A,A,1,233.92,200,130,166584,12038617,233.7,233.8,1200,5,1,1,233.66,233.92,1,400,1,2,233.64,233.93,400,29,2,1,233.58,233.94,535,200,3,1,233.53,233.98,10,44,1,3,233.45,234.0,15,154,1,7,233.4,234.13,110,400,2,1,233.39,234.17,10,1,1,1,233.31,234.25,110,50,2,1,233.3,234.41,100,600,1,2,AAPL,-1323,-9.825473449684367,0.1268306650470524
2024-10-21T12:06:07.849075752Z,2024-10-21T12:06:07.848909781Z,10,2,38,C,B,2,233.64,200,130,165971,12038620,233.7,233.8,1200,5,1,1,233.66,233.92,1,400,1,2,233.64,233.93,200,29,1,1,233.58,233.94,535,200,3,1,233.53,233.98,10,44,1,3,233.45,234.0,15,154,1,7,233.4,234.13,110,400,2,1,233.39,234.17,10,1,1,1,233.31,234.25,110,50,2,1,233.3,234.41,100,600,1,2,AAPL,-1323,-9.526720790681257,0.12297426070989989
2024-10-21T12:06:07.896688660Z,2024-10-21T12:06:07.896522805Z,10,2,38,C,A,1,233.92,200,130,165855,12038640,233.7,233.8,1200,5,1,1,233.66,233.92,1,200,1,1,233.64,233.93,200,29,1,1,233.58,233.94,535,200,3,1,233.53,233.98,10,44,1,3,233.45,234.0,15,154,1,7,233.4,234.13,110,400,2,1,233.39,234.17,10,1,1,1,233.31,234.25,110,50,2,1,233.3,234.41,100,600,1,2,AAPL,-1323,-9.256104944500503,0.11948105624304763
2024-10-21T12:06:07.896701378Z,2024-10-21T12:06:07.896534876Z,10,2,38,A,A,1,233.89,200,130,166502,12038641,233.7,233.8,1200,5,1,1,233.66,233.89,1,200,1,1,233.64,233.93,200,29,1,1,233.58,233.94,535,200,3,1,233.53,233.98,10,44,1,3,233.45,234.0,15,154,1,7,233.4,234.13,110,400,2,1,233.39,234.17,10,1,1,1,233.31,234.25,110,50,2,1,233.3,234.41,100,600,1,2,AAPL,-1323,-9.009829746225506,0.11630204941535975
2024-10-21T12:06:08.694191792Z,2024-10-21T12:06:08.694025455Z,10,2,38,A,A,1,233.88,200,130,166337,12039365,233.7,233.8,1200,5,1,1,233.66,233.88,1,200,1,1,233.64,233.93,200,29,1,1,233.58,233.94,535,200,3,1,233.53,233.98,10,44,1,3,233.45,234.0,15,154,1,7,233.4,234.13,110,400,2,1,233.39,234.17,10,1,1,1,233.31,234.25,110,50,2,1,233.3,234.41,100,600,1,2,AAPL,-1825,-10.780590717299578,0.13915965447131798
2024-10-21T12:06:17.681130355Z,2024-10-21T12:06:17.680964159Z,10,2,38,C,B,3,233.58,30,130,166196,12045252,233.7,233.8,1200,5,1,1,233.66,233.88,1,200,1,1,233.64,233.93,200,29,1,1,233.58,233.94,505,200,2,1,233.53,233.98,10,44,1,3,233.45,234.0,15,154,1,7,233.4,234.13,110,400,2,1,233.39,234.17,10,1,1,1,233.31,234.25,110,50,2,1,233.3,234.41,100,600,1,2,AAPL,-1835,-9.429599177800617,0.12172058079155564
2024-10-21T12:06:17.681173092Z,2024-10-21T12:06:17.681006872Z,10,2,38,A,B,4,233.55,29,130,166220,12045253,233.7,233.8,1200,5,1,1,233.66,233.88,1,200,1,1,233.64,233.93,200,29,1,1,233.58,233.94,505,200,2,1,233.55,233.98,29,44,1,3,233.53,234.0,10,154,1,7,233.45,234.13,15,400,1,1,233.4,234.17,110,1,2,1,233.39,234.25,10,50,1,1,233.31,234.41,110,600,2,2,AAPL,-1725,-8.591954022988505,0.1109079626920508
2024-10-21T12:06:17.696271989Z,2024-10-21T12:06:17.696105981Z,10,2,38,C,A,2,233.93,29,130,166008,12045305,233.7,233.8,1200,5,1,1,233.66,233.88,1,200,1,1,233.64,233.94,200,200,1,1,233.58,233.98,505,44,2,3,233.55,234.0,29,154,1,7,233.53,234.13,10,400,1,1,233.45,234.17,15,1,1,1,233.4,234.25,110,50,2,1,233.39,234.41,10,600,1,2,233.31,234.43,110,5,2,1,AAPL,-1720,-8.79962103268593,0.11358860145039007
2024-10-21T12:06:18.819345163Z,2024-10-21T12:06:18.819178890Z,10,2,38,A,B,0,233.74,100,130,166273,12045986,233.74,233.8,100,5,1,1,233.7,233.88,1200,200,1,1,233.66,233.94,1,200,1,1,233.64,233.98,200,44,1,3,233.58,234.0,505,154,2,7,233.55,234.13,29,400,1,1,233.53,234.17,10,1,1,1,233.45,234.25,15,50,1,1,233.4,234.41,110,600,2,2,233.39,234.43,10,5,1,1,AAPL,-1610,-8.08108108108108,0.10431343518063159
2024-10-21T12:06:18.819759953Z,2024-10-21T12:06:18.819594049Z,10,2,38,C,B,0,233.74,100,130,165904,12045987,233.7,233.8,1200,5,1,1,233.66,233.88,1,200,1,1,233.64,233.94,200,200,1,1,233.58,233.98,505,44,2,3,233.55,234.0,29,154,1,7,233.53,234.13,10,400,1,1,233.45,234.17,15,1,1,1,233.4,234.25,110,50,2,1,233.39,234.41,10,600,1,2,233.31,234.43,110,5,2,1,AAPL,-1720,-8.866825775656324,0.11445610389583455
2024-10-21T12:06:18.820405900Z,2024-10-21T12:06:18.820239929Z,10,2,38,C,B,2,233.64,200,130,165971,12045988,233.7,233.8,1200,5,1,1,233.66,233.88,1,200,1,1,233.58,233.94,505,200,2,1,233.55,233.98,29,44,1,3,233.53,234.0,10,154,1,7,233.45,234.13,15,400,1,1,233.4,234.17,110,1,2,1,233.39,234.25,10,50,1,1,233.31,234.41,110,600,2,2,233.3,234.43,100,5,1,1,AAPL,-1820,-9.63327032136106,0.12434963950520923
2024-10-21T12:06:18.821259996Z,2024-10-21T12:06:18.821093344Z,10,2,38,C,A,0,233.8,5,130,166652,12045989,233.7,233.88,1200,200,1,1,233.66,233.94,1,200,1,1,233.58,233.98,505,44,2,3,233.55,234.0,29,154,1,7,233.53,234.13,10,400,1,1,233.45,234.17,15,1,1,1,233.4,234.25,110,50,2,1,233.39,234.41,10,600,1,2,233.31,234.43,110,5,2,1,233.3,234.5,100,63,1,4,AAPL,-1757,-9.48580471004375,0.12244610155859299
2024-10-21T12:06:18.873329140Z,2024-10-21T12:06:18.873162917Z,10,2,38,A,B,2,233.63,200,130,166223,12046004,233.7,233.88,1200,200,1,1,233.66,233.94,1,200,1,1,233.63,233.98,200,44,1,3,233.58,234.0,505,154,2,7,233.55,234.13,29,400,1,1,233.53,234.17,10,1,1,1,233.45,234.25,15,50,1,1,233.4,234.41,110,600,2,2,233.39,234.43,10,5,1,1,233.31,234.5,110,63,2,4,AAPL,-1647,-9.052766581165262,0.11685629317351673
2024-10-21T12:06:18.892386164Z,2024-10-21T12:06:18.892219598Z,10,2,38,C,A,0,233.88,200,130,166566,12046028,233.7,233.94,1200,200,1,1,233.66,233.98,1,44,1,3,233.63,234.0,200,154,1,7,233.58,234.13,505,400,2,1,233.55,234.17,29,1,1,1,233.53,234.25,10,50,1,1,233.45,234.41,15,600,1,2,233.4,234.43,110,5,2,1,233.39,234.5,10,63,1,4,233.31,234.75,110,1,2,1,AAPL,-1646,-9.254738369456788,0.11946341601201767
2024-10-21T12:06:18.892397427Z,2024-10-21T12:06:18.892231335Z,10,2,38,A,A,0,233.91,400,130,166092,12046029,233.7,233.91,1200,400,1,1,233.66,233.94,1,200,1,1,233.63,233.98,200,44,1,3,233.58,234.0,505,154,2,7,233.55,234.13,29,400,1,1,233.53,234.17,10,1,1,1,233.45,234.25,15,50,1,1,233.4,234.41,110,600,2,2,233.39,234.43,10,5,1,1,233.31,234.5,110,63,2,4,AAPL,-1709,-9.765714285714285,0.12605927275254422
2024-10-21T12:06:18.892456423Z,2024-10-21T12:06:18.892290341Z,10,2,38,C,A,0,233.91,200,130,166082,12046031,233.7,233.91,1200,200,1,1,233.66,233.94,1,200,1,1,233.63,233.98,200,44,1,3,233.58,234.0,505,154,2,7,233.55,234.13,29,400,1,1,233.53,234.17,10,1,1,1,233.45,234.25,15,50,1,1,233.4,234.41,110,600,2,2,233.39,234.43,10,5,1,1,233.31,234.5,110,63,2,4,AAPL,-1709,-9.917699815352151,0.12802115539364162
2024-10-21T12:06:19.678167259Z,2024-10-21T12:06:19.678000980Z,10,2,38,A,B,2,233.63,200,130,166279,12046958,233.7,233.91,1200,200,1,1,233.66,233.94,1,200,1,1,233.63,233.98,400,44,2,3,233.58,234.0,505,154,2,7,233.55,234.13,29,400,1,1,233.53,234.17,10,1,1,1,233.45,234.25,15,50,1,1,233.4,234.41,110,600,2,2,233.39,234.43,10,5,1,1,233.31,234.5,110,63,2,4,AAPL,-1709,-10.065130781222935,0.12992424612465586
2024-10-21T12:06:19.696893580Z,2024-10-21T12:06:19.696727473Z,10,2,38,C,B,2,233.63,200,130,166107,12047035,233.7,233.91,1200,200,1,1,233.66,233.94,1,200,1,1,233.63,233.98,200,44,1,3,233.58,234.0,505,154,2,7,233.55,234.13,29,400,1,1,233.53,234.17,10,1,1,1,233.45,234.25,15,50,1,1,233.4,234.41,110,600,2,2,233.39,234.43,10,5,1,1,233.31,234.5,110,63,2,4,AAPL,-1709,-10.208208891543647,0.1317711486661547
2024-10-21T12:06:19.696905409Z,2024-10-21T12:06:19.696738939Z,10,2,38,A,B,2,233.64,400,130,166470,12047036,233.7,233.91,1200,200,1,1,233.66,233.94,1,200,1,1,233.64,233.98,400,44,1,3,233.58,234.0,505,154,2,7,233.55,234.13,29,400,1,1,233.53,234.17,10,1,1,1,233.45,234.25,15,50,1,1,233.4,234.41,110,600,2,2,233.39,234.43,10,5,1,1,233.31,234.5,110,63,2,4,AAPL,-1709,-10.347124117053482,0.1335643152272164
2024-10-21T12:06:22.179197708Z,2024-10-21T12:06:22.179031254Z,10,2,38,C,B,2,233.64,200,130,166454,12050374,233.7,233.91,1200,200,1,1,233.66,233.94,1,200,1,1,233.64,233.98,200,44,1,3,233.58,234.0,505,154,2,7,233.55,234.13,29,400,1,1,233.53,234.17,10,1,1,1,233.45,234.25,15,50,1,1,233.4,234.41,110,600,2,2,233.39,234.43,10,5,1,1,233.31,234.5,110,63,2,4,AAPL,-1709,-10.482055532532117,0.13530605736804374
2024-10-21T12:06:29.265753510Z,2024-10-21T12:06:29.265587376Z,10,2,38,C,B,4,233.55,29,130,166134,12057133,233.7,233.91,1200,200,1,1,233.66,233.94,1,200,1,1,233.64,233.98,200,44,1,3,233.58,234.0,505,154,2,7,233.53,234.13,10,400,1,1,233.45,234.17,15,1,1,1,233.4,234.25,110,50,2,1,233.39,234.41,10,600,1,2,233.31,234.43,110,5,2,1,233.3,234.5,100,63,1,4,AAPL,-74,-0.6948356807511737,0.008969183209275654
2024-10-21T12:06:29.265819664Z,2024-10-21T12:06:29.265653484Z,10,2,38,A,B,4,233.56,30,130,166180,12057134,233.7,233.91,1200,200,1,1,233.66,233.94,1,200,1,1,233.64,233.98,200,44,1,3,233.58,234.0,505,154,2,7,233.56,234.13,30,400,1,1,233.53,234.17,10,1,1,1,233.45,234.25,15,50,1,1,233.4,234.41,110,600,2,2,233.39,234.43,10,5,1,1,233.31,234.5,110,63,2,4,AAPL,36,0.3418039653728009,-0.004412125732765033
2024-10-21T12:06:29.265865941Z,2024-10-21T12:06:29.265699161Z,10,2,38,A,A,1,233.94,28,130,166780,12057136,233.7,233.91,1200,200,1,1,233.66,233.94,1,228,1,2,233.64,233.98,200,44,1,3,233.58,234.0,505,154,2,7,233.56,234.13,30,400,1,1,233.53,234.17,10,1,1,1,233.45,234.25,15,50,1,1,233.4,234.41,110,600,2,2,233.39,234.43,10,5,1,1,233.31,234.5,110,63,2,4,AAPL,36,0.3452317527970165,-0.004456372817740583
2024-10-21T12:06:31.862605353Z,2024-10-21T12:06:31.862439229Z,10,2,38,C,B,4,233.56,30,130,166124,12059004,233.7,233.91,1200,200,1,1,233.66,233.94,1,228,1,2,233.64,233.98,200,44,1,3,233.58,234.0,505,154,2,7,233.53,234.13,10,400,1,1,233.45,234.17,15,1,1,1,233.4,234.25,110,50,2,1,233.39,234.41,10,600,1,2,233.31,234.43,110,5,2,1,233.3,234.5,100,63,1,4,AAPL,-64,-0.6208833290783763,0.00801458025884422
2024-10-21T12:06:31.862676130Z,2024-10-21T12:06:31.862509699Z,10,2,38,A,B,4,233.57,27,130,166431,12059008,233.7,233.91,1200,200,1,1,233.66,233.94,1,228,1,2,233.64,233.98,200,44,1,3,233.58,234.0,505,154,2,7,233.57,234.13,27,400,1,1,233.53,234.17,10,1,1,1,233.45,234.25,15,50,1,1,233.4,234.41,110,600,2,2,233.39,234.43,10,5,1,1,233.31,234.5,110,63,2,4,AAPL,46,0.44987775061124696,-0.005807180141709036
2024-10-21T12:06:39.033053296Z,2024-10-21T12:06:39.032886978Z,10,2,38,C,A,0,233.91,200,130,166318,12066080,233.7,233.94,1200,228,1,2,233.66,233.98,1,44,1,3,233.64,234.0,200,154,1,7,233.58,234.13,505,400,2,1,233.57,234.17,27,1,1,1,233.53,234.25,10,50,1,1,233.45,234.41,15,600,1,2,233.4,234.43,110,5,2,1,233.39,234.5,10,63,1,4,233.31,234.75,110,1,2,1,AAPL,21,0.25485436893203883,-0.003289749778198799
2024-10-21T12:06:39.137323341Z,2024-10-21T12:06:39.137156502Z,10,2,38,A,A,0,233.92,200,130,166839,12066185,233.7,233.92,1200,200,1,1,233.66,233.94,1,228,1,2,233.64,233.98,200,44,1,3,233.58,234.0,505,154,2,7,233.57,234.13,27,400,1,1,233.53,234.17,10,1,1,1,233.45,234.25,15,50,1,1,233.4,234.41,110,600,2,2,233.39,234.43,10,5,1,1,233.31,234.5,110,63,2,4,AAPL,-42,-0.5074135090609555,0.006549871936209537
2024-10-21T12:06:46.758190934Z,2024-10-21T12:06:46.758024329Z,10,2,38,A,B,2,233.64,200,130,166605,12071674,233.7,233.92,1200,200,1,1,233.66,233.94,1,228,1,2,233.64,233.98,400,44,2,3,233.58,234.0,505,154,2,7,233.57,234.13,27,400,1,1,233.53,234.17,10,1,1,1,233.45,234.25,15,50,1,1,233.4,234.41,110,600,2,2,233.39,234.43,10,5,1,1,233.31,234.5,110,63,2,4,AAPL,-42,-0.5161290322580645,0.006662374973237016
2024-10-21T12:06:46.813021764Z,2024-10-21T12:06:46.812855420Z,10,2,38,C,B,2,233.64,200,130,166344,12071825,233.7,233.92,1200,200,1,1,233.66,233.94,1,228,1,2,233.64,233.98,200,44,1,3,233.58,234.0,505,154,2,7,233.57,234.13,27,400,1,1,233.53,234.17,10,1,1,1,233.45,234.25,15,50,1,1,233.4,234.41,110,600,2,2,233.39,234.43,10,5,1,1,233.31,234.5,110,63,2,4,AAPL,-42,-0.512542372881356,0.006616077113253504
2024-10-21T12:06:46.813033905Z,2024-10-21T12:06:46.812867723Z,10,2,38,A,B,2,233.65,200,130,166182,12071826,233.7,233.92,1200,200,1,1,233.66,233.94,1,228,1,2,233.65,233.98,200,44,1,3,233.58,234.0,505,154,2,7,233.57,234.13,27,400,1,1,233.53,234.17,10,1,1,1,233.45,234.25,15,50,1,1,233.4,234.41,110,600,2,2,233.39,234.43,10,5,1,1,233.31,234.5,110,63,2,4,AAPL,-42,-0.5097087378640777,0.006579499556397598
2024-10-21T12:06:46.863551302Z,2024-10-21T12:06:46.863385247Z,10,2,38,C,B,4,233.57,27,130,166055,12072246,233.7,233.92,1200,200,1,1,233.66,233.94,1,228,1,2,233.65,233.98,200,44,1,3,233.58,234.0,505,154,2,7,233.53,234.13,10,400,1,1,233.45,234.17,15,1,1,1,233.4,234.25,110,50,2,1,233.39,234.41,10,600,1,2,233.31,234.43,110,5,2,1,233.3,234.5,100,63,1,4,AAPL,-142,-1.7250138045278853,0.02226708454956397
2024-10-21T12:06:46.888783692Z,2024-10-21T12:06:46.888617346Z,10,2,38,A,B,3,233.58,26,130,166346,12072288,233.7,233.92,1200,200,1,1,233.66,233.94,1,228,1,2,233.65,233.98,200,44,1,3,233.58,234.0,531,154,3,7,233.53,234.13,10,400,1,1,233.45,234.17,15,1,1,1,233.4,234.25,110,50,2,1,233.39,234.41,10,600,1,2,233.31,234.43,110,5,2,1,233.3,234.5,100,63,1,4,AAPL,-142,-1.7264437689969605,0.02228554303357853
2024-10-21T12:06:48.285314626Z,2024-10-21T12:06:48.285146479Z,10,2,38,C,A,0,233.92,200,130,168147,12073283,233.7,233.94,1200,228,1,2,233.66,233.98,1,44,1,3,233.65,234.0,200,154,1,7,233.58,234.13,531,400,3,1,233.53,234.17,10,1,1,1,233.45,234.25,15,50,1,1,233.4,234.41,110,600,2,2,233.39,234.43,10,5,1,1,233.31,234.5,110,63,2,4,233.3,234.75,100,1,1,1,AAPL,-141,-1.7667469879518072,0.022805791150858252
2024-10-21T12:06:48.317496644Z,2024-10-21T12:06:48.317330539Z,10,2,38,A,A,0,233.93,200,130,166105,12073312,233.7,233.93,1200,200,1,1,233.66,233.94,1,228,1,2,233.65,233.98,200,44,1,3,233.58,234.0,531,154,3,7,233.53,234.13,10,400,1,1,233.45,234.17,15,1,1,1,233.4,234.25,110,50,2,1,233.39,234.41,10,600,1,2,233.31,234.43,110,5,2,1,233.3,234.5,100,63,1,4,AAPL,-204,-2.552278820375335,0.03294571216658358
2024-10-21T12:06:48.791673239Z,2024-10-21T12:06:48.791506901Z,10,2,38,A,A,0,233.79,20,130,166338,12073929,233.7,233.79,1200,20,1,1,233.66,233.93,1,200,1,1,233.65,233.94,200,228,1,2,233.58,233.98,531,44,3,3,233.53,234.0,10,154,1,7,233.45,234.13,15,400,1,1,233.4,234.17,110,1,2,1,233.39,234.25,10,50,1,1,233.31,234.41,110,600,2,2,233.3,234.43,100,5,1,1,AAPL,-209,-2.676056338028169,0.03454347587356164
2024-10-21T12:06:48.791702674Z,2024-10-21T12:06:48.791534978Z,10,2,38,T,B,0,233.79,20,130,167696,12073930,233.7,233.79,1200,20,1,1,233.66,233.93,1,200,1,1,233.65,233.94,200,228,1,2,233.58,233.98,531,44,3,3,233.53,234.0,10,154,1,7,233.45,234.13,15,400,1,1,233.4,234.17,110,1,2,1,233.39,234.25,10,50,1,1,233.31,234.41,110,600,2,2,233.3,234.43,100,5,1,1,AAPL,-209,-2.7320261437908497,0.035265953800328945
2024-10-21T12:06:48.791702674Z,2024-10-21T12:06:48.791534978Z,10,2,38,C,A,0,233.79,20,130,167696,12073930,233.7,233.93,1200,200,1,1,233.66,233.94,1,228,1,2,233.65,233.98,200,44,1,3,233.58,234.0,531,154,3,7,233.53,234.13,10,400,1,1,233.45,234.17,15,1,1,1,233.4,234.25,110,50,2,1,233.39,234.41,10,600,1,2,233.31,234.43,110,5,2,1,233.3,234.5,100,63,1,4,AAPL,-146,-1.9011872845653006,0.02454119375674083
2024-10-21T12:06:48.791739905Z,2024-10-21T12:06:48.791573564Z,10,2,38,A,B,0,233.74,100,130,166341,12073931,233.74,233.93,100,200,1,1,233.7,233.94,1200,228,1,2,233.66,233.98,1,44,1,3,233.65,234.0,200,154,1,7,233.58,234.13,531,400,3,1,233.53,234.17,10,1,1,1,233.45,234.25,15,50,1,1,233.4,234.41,110,600,2,2,233.39,234.43,10,5,1,1,233.31,234.5,110,63,2,4,AAPL,-36,-0.4655172413793104,0.006009060185990713
2024-10-21T12:06:48.791752199Z,2024-10-21T12:06:48.791586310Z,10,2,38,A,B,1,233.71,100,130,165889,12073932,233.74,233.93,100,200,1,1,233.71,233.94,100,228,1,2,233.7,233.98,1200,44,1,3,233.66,234.0,1,154,1,7,233.65,234.13,200,400,1,1,233.58,234.17,531,1,3,1,233.53,234.25,10,50,1,1,233.45,234.41,15,600,1,2,233.4,234.43,110,5,2,1,233.39,234.5,10,63,1,4,AAPL,-26,-0.3458172908645432,0.004463931148939082
2024-10-21T12:06:48.893935165Z,2024-10-21T12:06:48.893768793Z,10,2,38,C,B,1,233.71,100,130,166372,12074008,233.74,233.93,100,200,1,1,233.7,233.94,1200,228,1,2,233.66,233.98,1,44,1,3,233.65,234.0,200,154,1,7,233.58,234.13,531,400,3,1,233.53,234.17,10,1,1,1,233.45,234.25,15,50,1,1,233.4,234.41,110,600,2,2,233.39,234.43,10,5,1,1,233.31,234.5,110,63,2,4,AAPL,-136,-1.7953795379537953,0.02317539017093008
2024-10-21T12:06:49.043931536Z,2024-10-21T12:06:49.043764990Z,10,2,38,C,B,0,233.74,100,130,166546,12074117,233.7,233.93,1200,200,1,1,233.66,233.94,1,228,1,2,233.65,233.98,200,44,1,3,233.58,234.0,531,154,3,7,233.53,234.13,10,400,1,1,233.45,234.17,15,1,1,1,233.4,234.25,110,50,2,1,233.39,234.41,10,600,1,2,233.31,234.43,110,5,2,1,233.3,234.5,100,63,1,4,AAPL,-236,-3.1042906357657376,0.04007127471767312
2024-10-21T12:06:49.574608384Z,2024-10-21T12:06:49.574441885Z,10,2,38,A,B,1,233.66,200,130,166499,12074442,233.7,233.93,1200,200,1,1,233.66,233.94,201,228,2,2,233.58,233.98,531,44,3,3,233.53,234.0,10,154,1,7,233.45,234.13,15,400,1,1,233.4,234.17,110,1,2,1,233.39,234.25,10,50,1,1,233.31,234.41,110,600,2,2,233.3,234.43,100,5,1,1,233.25,234.5,55,63,2,4,AAPL,-301,-4.082084225553176,0.052692978079506486
2024-10-21T12:06:51.353744448Z,2024-10-21T12:06:51.353578115Z,10,2,38,C,B,1,233.66,200,130,166333,12075742,233.7,233.93,1200,200,1,1,233.66,233.94,1,228,1,2,233.58,233.98,531,44,3,3,233.53,234.0,10,154,1,7,233.45,234.13,15,400,1,1,233.4,234.17,110,1,2,1,233.39,234.25,10,50,1,1,233.31,234.41,110,600,2,2,233.3,234.43,100,5,1,1,233.25,234.5,55,63,2,4,AAPL,-301,-4.123287671232877,0.053224846639789894
2024-10-21T12:06:51.353758889Z,2024-10-21T12:06:51.353591847Z,10,2,38,A,B,2,233.64,200,130,167042,12075743,233.7,233.93,1200,200,1,1,233.66,233.94,1,228,1,2,233.64,233.98,200,44,1,3,233.58,234.0,531,154,3,7,233.53,234.13,10,400,1,1,233.45,234.17,15,1,1,1,233.4,234.25,110,50,2,1,233.39,234.41,10,600,1,2,233.31,234.43,110,5,2,1,233.3,234.5,100,63,1,4,AAPL,-201,-2.738241972105093,0.03534618989713902
2024-10-21T12:06:53.388625485Z,2024-10-21T12:06:53.388459101Z,10,2,38,A,B,2,233.65,200,130,166384,12077374,233.7,233.93,1200,200,1,1,233.66,233.94,1,228,1,2,233.65,233.98,200,44,1,3,233.58,234.0,531,154,3,7,233.53,234.13,10,400,1,1,233.45,234.17,15,1,1,1,233.4,234.25,110,50,2,1,233.39,234.41,10,600,1,2,233.31,234.43,110,5,2,1,233.3,234.5,100,63,1,4,AAPL,-211,-2.9003436426116838,0.037438655240501134
2024-10-21T12:06:56.110327183Z,2024-10-21T12:06:56.110160994Z,10,2,38,A,B,0,233.8,100,130,166189,12079383,233.8,233.93,100,200,1,1,233.7,233.94,1200,228,1,2,233.66,233.98,1,44,1,3,233.65,234.0,200,154,1,7,233.58,234.13,531,400,3,1,233.53,234.17,10,1,1,1,233.45,234.25,15,50,1,1,233.4,234.41,110,600,2,2,233.39,234.43,10,5,1,1,233.31,234.5,110,63,2,4,AAPL,-101,-1.3759325332468377,0.017761020794084783
2024-10-21T12:06:56.110361628Z,2024-10-21T12:06:56.110195323Z,10,2,38,C,A,0,233.93,200,130,166305,12079385,233.8,233.94,100,228,1,2,233.7,233.98,1200,44,1,3,233.66,234.0,1,154,1,7,233.65,234.13,200,400,1,1,233.58,234.17,531,1,3,1,233.53,234.25,10,50,1,1,233.45,234.41,15,600,1,2,233.4,234.43,110,5,2,1,233.39,234.5,10,63,1,4,233.31,234.75,110,1,2,1,AAPL,-100,-1.3775829680651221,0.01778232518686461
2024-10-21T12:06:56.110625865Z,2024-10-21T12:06:56.110459619Z,10,2,38,C,B,0,233.8,100,130,166246,12079387,233.7,233.94,1200,228,1,2,233.66,233.98,1,44,1,3,233.65,234.0,200,154,1,7,233.58,234.13,531,400,3,1,233.53,234.17,10,1,1,1,233.45,234.25,15,50,1,1,233.4,234.41,110,600,2,2,233.39,234.43,10,5,1,1,233.31,234.5,110,63,2,4,233.3,234.75,100,1,1,1,AAPL,-200,-2.792109256449165,0.03604152773837627
2024-10-21T12:06:56.110674106Z,2024-10-21T12:06:56.110506828Z,10,2,38,A,A,0,233.94,200,130,167278,12079388,233.7,233.94,1200,428,1,3,233.66,233.98,1,44,1,3,233.65,234.0,200,154,1,7,233.58,234.13,531,400,3,1,233.53,234.17,10,1,1,1,233.45,234.25,15,50,1,1,233.4,234.41,110,600,2,2,233.39,234.43,10,5,1,1,233.31,234.5,110,63,2,4,233.3,234.75,100,1,1,1,AAPL,-200,-2.8268551236749118,0.03649003960606846
2024-10-21T12:06:56.200245289Z,2024-10-21T12:06:56.200078370Z,10,2,38,A,B,2,233.65,200,130,166919,12079603,233.7,233.94,1200,428,1,3,233.66,233.98,1,44,1,3,233.65,234.0,400,154,2,7,233.58,234.13,531,400,3,1,233.53,234.17,10,1,1,1,233.45,234.25,15,50,1,1,233.4,234.41,110,600,2,2,233.39,234.43,10,5,1,1,233.31,234.5,110,63,2,4,233.3,234.75,100,1,1,1,AAPL,-200,-2.8595939376608523,0.03691264372504066
2024-10-21T12:06:56.253580648Z,2024-10-21T12:06:56.253414674Z,10,2,38,C,B,2,233.65,200,130,165974,12079693,233.7,233.94,1200,428,1,3,233.66,233.98,1,44,1,3,233.65,234.0,200,154,1,7,233.58,234.13,531,400,3,1,233.53,234.17,10,1,1,1,233.45,234.25,15,50,1,1,233.4,234.41,110,600,2,2,233.39,234.43,10,5,1,1,233.31,234.5,110,63,2,4,233.3,234.75,100,1,1,1,AAPL,-200,-2.8904947192884936,0.03731152187624399
2024-10-21T12:06:56.253593165Z,2024-10-21T12:06:56.253426681Z,10,2,38,A,B,1,233.66,400,130,166484,12079694,233.7,233.94,1200,428,1,3,233.66,233.98,401,44,2,3,233.58,234.0,531,154,3,7,233.53,234.13,10,400,1,1,233.45,234.17,15,1,1,1,233.4,234.25,110,50,2,1,233.39,234.41,10,600,1,2,233.31,234.43,110,5,2,1,233.3,234.5,100,63,1,4,233.25,234.75,55,1,2,1,AAPL,-255,-3.768472906403941,0.04864477293421054
2024-10-21T12:06:56.253936800Z,2024-10-21T12:06:56.253770667Z,10,2,38,C,B,1,233.66,200,130,166133,12079695,233.7,233.94,1200,428,1,3,233.66,233.98,201,44,2,3,233.58,234.0,531,154,3,7,233.53,234.13,10,400,1,1,233.45,234.17,15,1,1,1,233.4,234.25,110,50,2,1,233.39,234.41,10,600,1,2,233.31,234.43,110,5,2,1,233.3,234.5,100,63,1,4,233.25,234.75,55,1,2,1,AAPL,-255,-3.849056603773585,0.049684975625885475
2024-10-21T12:06:56.254080762Z,2024-10-21T12:06:56.253914719Z,10,2,38,C,B,2,233.58,26,130,166043,12079696,233.7,233.94,1200,428,1,3,233.66,233.98,201,44,2,3,233.58,234.0,505,154,2,7,233.53,234.13,10,400,1,1,233.45,234.17,15,1,1,1,233.4,234.25,110,50,2,1,233.39,234.41,10,600,1,2,233.31,234.43,110,5,2,1,233.3,234.5,100,63,1,4,233.25,234.75,55,1,2,1,AAPL,-255,-3.9272437599575145,0.050694242921525474
2024-10-21T12:06:56.254173312Z,2024-10-21T12:06:56.254006802Z,10,2,38,A,B,2,233.64,26,130,166510,12079697,233.7,233.94,1200,428,1,3,233.66,233.98,201,44,2,3,233.64,234.0,26,154,1,7,233.58,234.13,505,400,2,1,233.53,234.17,10,1,1,1,233.45,234.25,15,50,1,1,233.4,234.41,110,600,2,2,233.39,234.43,10,5,1,1,233.31,234.5,110,63,2,4,233.3,234.75,100,1,1,1,AAPL,-155,-2.404965089216447,0.031044134742439743
2024-10-21T12:06:56.262214424Z,2024-10-21T12:06:56.262048229Z,10,2,38,C,B,1,233.66,200,130,166195,12079704,233.7,233.94,1200,428,1,3,233.66,233.98,1,44,1,3,233.64,234.0,26,154,1,7,233.58,234.13,505,400,2,1,233.53,234.17,10,1,1,1,233.45,234.25,15,50,1,1,233.4,234.41,110,600,2,2,233.39,234.43,10,5,1,1,233.31,234.5,110,63,2,4,233.3,234.75,100,1,1,1,AAPL,-155,-2.421875,0.03126241381484752
2024-10-21T12:06:56.262227751Z,2024-10-21T12:06:56.262061304Z,10,2,38,A,B,3,233.61,400,130,166447,12079705,233.7,233.94,1200,428,1,3,233.66,233.98,1,44,1,3,233.64,234.0,26,154,1,7,233.61,234.13,400,400,1,1,233.58,234.17,505,1,2,1,233.53,234.25,10,50,1,1,233.45,234.41,15,600,1,2,233.4,234.43,110,5,2,1,233.39,234.5,10,63,1,4,233.31,234.75,110,1,2,1,AAPL,-45,-0.7060554057367002,0.009114011363241616
2024-10-21T12:06:56.281031560Z,2024-10-21T12:06:56.280865568Z,10,2,38,C,B,2,233.64,26,130,165992,12079723,233.7,233.94,1200,428,1,3,233.66,233.98,1,44,1,3,233.61,234.0,400,154,1,7,233.58,234.13,505,400,2,1,233.53,234.17,10,1,1,1,233.45,234.25,15,50,1,1,233.4,234.41,110,600,2,2,233.39,234.43,10,5,1,1,233.31,234.5,110,63,2,4,233.3,234.75,100,1,1,1,AAPL,-145,-2.289473684210526,0.02955333109016485
2024-10-21T12:06:56.344079966Z,2024-10-21T12:06:56.343913221Z,10,2,38,A,B,1,233.66,200,130,166745,12079737,233.7,233.94,1200,428,1,3,233.66,233.98,201,44,2,3,233.58,234.0,505,154,2,7,233.53,234.13,10,400,1,1,233.45,234.17,15,1,1,1,233.4,234.25,110,50,2,1,233.39,234.41,10,600,1,2,233.31,234.43,110,5,2,1,233.3,234.5,100,63,1,4,233.25,234.75,55,1,2,1,AAPL,-200,-3.2105760151085927,0.04144324375467313
2024-10-21T12:06:57.182057820Z,2024-10-21T12:06:57.181891624Z,10,2,38,A,B,2,233.58,26,130,166196,12080361,233.7,233.94,1200,428,1,3,233.66,233.98,201,44,2,3,233.58,234.0,531,154,3,7,233.53,234.13,10,400,1,1,233.45,234.17,15,1,1,1,233.4,234.25,110,50,2,1,233.39,234.41,10,600,1,2,233.31,234.43,110,5,2,1,233.3,234.5,100,63,1,4,233.25,234.75,55,1,2,1,AAPL,-200,-3.2618825722273996,0.042105526828763756
2024-10-21T12:06:59.254157093Z,2024-10-21T12:06:59.253990761Z,10,2,38,A,B,1,233.66,200,130,166332,12081445,233.7,233.94,1200,428,1,3,233.66,233.98,401,44,3,3,233.58,234.0,531,154,3,7,233.53,234.13,10,400,1,1,233.45,234.17,15,1,1,1,233.4,234.25,110,50,2,1,233.39,234.41,10,600,1,2,233.31,234.43,110,5,2,1,233.3,234.5,100,63,1,4,233.25,234.75,55,1,2,1,AAPL,-138,-2.309055118110236,0.0298060951220248
2024-10-21T12:06:59.254687091Z,2024-10-21T12:06:59.254521031Z,10,2,38,C,B,2,233.58,26,130,166060,12081446,233.7,233.94,1200,428,1,3,233.66,233.98,401,44,3,3,233.58,234.0,505,154,2,7,233.53,234.13,10,400,1,1,233.45,234.17,15,1,1,1,233.4,234.25,110,50,2,1,233.39,234.41,10,600,1,2,233.31,234.43,110,5,2,1,233.3,234.5,100,63,1,4,233.25,234.75,55,1,2,1,AAPL,-138,-2.3446601941747574,0.030265697959428954
2024-10-21T12:06:59.254744498Z,2024-10-21T12:06:59.254578130Z,10,2,38,A,B,2,233.64,29,130,166368,12081447,233.7,233.94,1200,428,1,3,233.66,233.98,401,44,3,3,233.64,234.0,29,154,1,7,233.58,234.13,505,400,2,1,233.53,234.17,10,1,1,1,233.45,234.25,15,50,1,1,233.4,234.41,110,600,2,2,233.39,234.43,10,5,1,1,233.31,234.5,110,63,2,4,233.3,234.75,100,1,1,1,AAPL,-38,-0.6481876332622601,0.008367033815003417
2024-10-21T12:06:59.308630752Z,2024-10-21T12:06:59.308464431Z,10,2,38,C,B,1,233.66,200,130,166321,12081505,233.7,233.94,1200,428,1,3,233.66,233.98,201,44,2,3,233.64,234.0,29,154,1,7,233.58,234.13,505,400,2,1,233.53,234.17,10,1,1,1,233.45,234.25,15,50,1,1,233.4,234.41,110,600,2,2,233.39,234.43,10,5,1,1,233.31,234.5,110,63,2,4,233.3,234.75,100,1,1,1,AAPL,-38,-0.6506247107820454,0.0083984924682875
2024-10-21T12:06:59.308644001Z,2024-10-21T12:06:59.308477350Z,10,2,38,A,B,0,233.7,200,130,166651,12081506,233.7,233.94,1400,428,2,3,233.66,233.98,1,44,1,3,233.64,234.0,29,154,1,7,233.58,234.13,505,400,2,1,233.53,234.17,10,1,1,1,233.45,234.25,15,50,1,1,233.4,234.41,110,600,2,2,233.39,234.43,10,5,1,1,233.31,234.5,110,63,2,4,233.3,234.75,100,1,1,1,AAPL,-38,-0.6529504860954104,0.0084285143935672
2024-10-21T12:07:03.723802492Z,2024-10-21T12:07:03.723636278Z,10,2,38,A,A,0,233.93,200,130,166214,12085903,233.7,233.93,1400,200,2,1,233.66,233.94,1,228,1,2,233.64,233.98,29,44,1,3,233.58,234.0,505,154,2,7,233.53,234.13,10,400,1,1,233.45,234.17,15,1,1,1,233.4,234.25,110,50,2,1,233.39,234.41,10,600,1,2,233.31,234.43,110,5,2,1,233.3,234.5,100,63,1,4,AAPL,-101,-1.7178368948975142,0.022174442477294994
2024-10-21T12:07:06.239612135Z,2024-10-21T12:07:06.239446409Z,10,2,38,C,B,0,233.7,200,130,165726,12087785,233.7,233.93,1200,200,1,1,233.66,233.94,1,228,1,2,233.64,233.98,29,44,1,3,233.58,234.0,505,154,2,7,233.53,234.13,10,400,1,1,233.45,234.17,15,1,1,1,233.4,234.25,110,50,2,1,233.39,234.41,10,600,1,2,233.31,234.43,110,5,2,1,233.3,234.5,100,63,1,4,AAPL,-101,-1.7014108233312277,0.02196240897157833
2024-10-21T12:07:06.347640980Z,2024-10-21T12:07:06.347474732Z,10,2,38,A,B,0,233.7,200,130,166248,12087873,233.7,233.93,1400,200,2,1,233.66,233.94,1,228,1,2,233.64,233.98,29,44,1,3,233.58,234.0,505,154,2,7,233.53,234.13,10,400,1,1,233.45,234.17,15,1,1,1,233.4,234.25,110,50,2,1,233.39,234.41,10,600,1,2,233.31,234.43,110,5,2,1,233.3,234.5,100,63,1,4,AAPL,-101,-1.6860749185667752,0.02176444772214497
2024-10-21T12:07:21.424194481Z,2024-10-21T12:07:21.424028257Z,10,2,38,C,A,0,233.93,200,130,166224,12101250,233.7,233.94,1400,228,2,2,233.66,233.98,1,44,1,3,233.64,234.0,29,154,1,7,233.58,234.13,505,400,2,1,233.53,234.17,10,1,1,1,233.45,234.25,15,50,1,1,233.4,234.41,110,600,2,2,233.39,234.43,10,5,1,1,233.31,234.5,110,63,2,4,233.3,234.75,100,1,1,1,AAPL,-62,-0.8406779661016949,0.010851766693696223
2024-10-21T12:07:21.424207907Z,2024-10-21T12:07:21.424041784Z,10,2,38,A,A,1,233.95,200,130,166123,12101251,233.7,233.94,1400,228,2,2,233.66,233.95,1,200,1,1,233.64,233.98,29,44,1,3,233.58,234.0,505,154,2,7,233.53,234.13,10,400,1,1,233.45,234.17,15,1,1,1,233.4,234.25,110,50,2,1,233.39,234.41,10,600,1,2,233.31,234.43,110,5,2,1,233.3,234.5,100,63,1,4,AAPL,-125,-1.6600265604249669,0.021428206358975296
2024-10-21T12:07:21.478515734Z,2024-10-21T12:07:21.478349682Z,10,2,38,A,B,0,233.71,200,130,166052,12101383,233.71,233.94,200,228,1,2,233.7,233.95,1200,200,1,1,233.66,233.98,1,44,1,3,233.64,234.0,29,154,1,7,233.58,234.13,505,400,2,1,233.53,234.17,10,1,1,1,233.45,234.25,15,50,1,1,233.4,234.41,110,600,2,2,233.39,234.43,10,5,1,1,233.31,234.5,110,63,2,4,AAPL,-15,-0.19438444924406045,0.0025091827990457983
2024-10-21T12:07:21.488225088Z,2024-10-21T12:07:21.488058823Z,10,2,38,C,B,3,233.64,29,130,166265,12101519,233.71,233.94,200,228,1,2,233.7,233.95,1200,200,1,1,233.66,233.98,1,44,1,3,233.58,234.0,505,154,2,7,233.53,234.13,10,400,1,1,233.45,234.17,15,1,1,1,233.4,234.25,110,50,2,1,233.39,234.41,10,600,1,2,233.31,234.43,110,5,2,1,233.3,234.5,100,63,1,4,AAPL,-115,-1.4784205693296602,0.019083972389477698
2024-10-21T12:07:21.488266872Z,2024-10-21T12:07:21.488100749Z,10,2,38,A,B,3,233.65,26,130,166123,12101521,233.71,233.94,200,228,1,2,233.7,233.95,1200,200,1,1,233.66,233.98,1,44,1,3,233.65,234.0,26,154,1,7,233.58,234.13,505,400,2,1,233.53,234.17,10,1,1,1,233.45,234.25,15,50,1,1,233.4,234.41,110,600,2,2,233.39,234.43,10,5,1,1,233.31,234.5,110,63,2,4,AAPL,-5,-0.06339144215530904,0.0008182790181075573
2024-10-21T12:07:21.502658985Z,2024-10-21T12:07:21.502492836Z,10,2,38,C,A,0,233.94,28,130,166149,12101598,233.71,233.94,200,200,1,1,233.7,233.95,1200,200,1,1,233.66,233.98,1,44,1,3,233.65,234.0,26,154,1,7,233.58,234.13,505,400,2,1,233.53,234.17,10,1,1,1,233.45,234.25,15,50,1,1,233.4,234.41,110,600,2,2,233.39,234.43,10,5,1,1,233.31,234.5,110,63,2,4,AAPL,-5,-0.0627177700348432,0.0008095830215736618
2024-10-21T12:07:21.502714841Z,2024-10-21T12:07:21.502548349Z,10,2,38,A,A,2,233.97,26,130,166492,12101599,233.71,233.94,200,200,1,1,233.7,233.95,1200,200,1,1,233.66,233.97,1,26,1,1,233.65,233.98,26,44,1,3,233.58,234.0,505,154,2,7,233.53,234.13,10,400,1,1,233.45,234.17,15,1,1,1,233.4,234.25,110,50,2,1,233.39,234.41,10,600,1,2,233.31,234.43,110,5,2,1,AAPL,-10,-0.12903225806451613,0.001665593743309254
2024-10-21T12:07:24.037497828Z,2024-10-21T12:07:24.037331253Z,10,2,38,A,A,0,233.94,200,130,166575,12104033,233.71,233.94,200,400,1,2,233.7,233.97,1200,26,1,1,233.66,233.98,1,44,1,3,233.65,234.0,26,154,1,7,233.58,234.13,505,400,2,1,233.53,234.17,10,1,1,1,233.45,234.25,15,50,1,1,233.4,234.41,110,600,2,2,233.39,234.43,10,5,1,1,233.31,234.5,110,63,2,4,AAPL,116,1.4871794871794872,-0.019197035579936145
2024-10-21T12:07:24.051809302Z,2024-10-21T12:07:24.051643239Z,10,2,38,C,A,1,233.97,26,130,166063,12104141,233.71,233.94,200,400,1,2,233.7,233.98,1200,44,1,3,233.66,234.0,1,154,1,7,233.65,234.13,26,400,1,1,233.58,234.17,505,1,2,1,233.53,234.25,10,50,1,1,233.45,234.41,15,600,1,2,233.4,234.43,110,5,2,1,233.39,234.5,10,63,1,4,233.31,234.75,110,1,2,1,AAPL,117,1.540394973070018,-0.019883959777620978
2024-10-21T12:07:24.051851741Z,2024-10-21T12:07:24.051685450Z,10,2,38,A,A,1,233.96,26,130,166291,12104142,233.71,233.94,200,400,1,2,233.7,233.96,1200,26,1,1,233.66,233.98,1,44,1,3,233.65,234.0,26,154,1,7,233.58,234.13,505,400,2,1,233.53,234.17,10,1,1,1,233.45,234.25,15,50,1,1,233.4,234.41,110,600,2,2,233.39,234.43,10,5,1,1,233.31,234.5,110,63,2,4,AAPL,54,0.7028199566160521,-0.009072247048697477
2024-10-21T12:07:31.492356327Z,2024-10-21T12:07:31.492189570Z,10,2,38,A,A,0,233.93,200,130,166757,12109685,233.71,233.93,200,200,1,1,233.7,233.94,1200,200,1,1,233.66,233.96,1,26,1,1,233.65,233.98,26,44,1,3,233.58,234.0,505,154,2,7,233.53,234.13,10,400,1,1,233.45,234.17,15,1,1,1,233.4,234.25,110,50,2,1,233.39,234.41,10,600,1,2,233.31,234.43,110,5,2,1,AAPL,49,0.6601347213717085,-0.008521251027848844
2024-10-21T12:07:31.505625526Z,2024-10-21T12:07:31.505459563Z,10,2,38,C,A,2,233.96,26,130,165963,12109738,233.71,233.93,200,200,1,1,233.7,233.94,1200,200,1,1,233.66,233.98,1,44,1,3,233.65,234.0,26,154,1,7,233.58,234.13,505,400,2,1,233.53,234.17,10,1,1,1,233.45,234.25,15,50,1,1,233.4,234.41,110,600,2,2,233.39,234.43,10,5,1,1,233.31,234.5,110,63,2,4,AAPL,112,1.4883720930232558,-0.019212430155381162
2024-10-21T12:07:31.506685578Z,2024-10-21T12:07:31.506518669Z,10,2,38,A,A,2,233.95,29,130,166909,12109739,233.71,233.93,200,200,1,1,233.7,233.94,1200,200,1,1,233.66,233.95,1,29,1,1,233.65,233.98,26,44,1,3,233.58,234.0,505,154,2,7,233.53,234.13,10,400,1,1,233.45,234.17,15,1,1,1,233.4,234.25,110,50,2,1,233.39,234.41,10,600,1,2,233.31,234.43,110,5,2,1,AAPL,107,1.448204060385216,-0.018693927070598214
2024-10-21T12:07:32.030718105Z,2024-10-21T12:07:32.030551990Z,10,2,38,C,B,0,233.71,200,130,166115,12110208,233.7,233.93,1200,200,1,1,233.66,233.94,1,200,1,1,233.65,233.95,26,29,1,1,233.58,233.98,505,44,2,3,233.53,234.0,10,154,1,7,233.45,234.13,15,400,1,1,233.4,234.17,110,1,2,1,233.39,234.25,10,50,1,1,233.31,234.41,110,600,2,2,233.3,234.43,100,5,1,1,AAPL,7,0.09674234945705824,-0.0012487842527575304
2024-10-21T12:07:32.030730303Z,2024-10-21T12:07:32.030564032Z,10,2,38,A,B,1,233.69,200,130,166271,12110209,233.7,233.93,1200,200,1,1,233.69,233.94,200,200,1,1,233.66,233.95,1,29,1,1,233.65,233.98,26,44,1,3,233.58,234.0,505,154,2,7,233.53,234.13,10,400,1,1,233.45,234.17,15,1,1,1,233.4,234.25,110,50,2,1,233.39,234.41,10,600,1,2,233.31,234.43,110,5,2,1,AAPL,117,1.6394208313872023,-0.02116222036542269
2024-10-21T12:07:33.189754626Z,2024-10-21T12:07:33.189588145Z,10,2,38,A,B,0,233.7,200,130,166481,12111500,233.7,233.93,1400,200,2,1,233.66,233.94,1,200,1,1,233.65,233.95,26,29,1,1,233.58,233.98,505,44,2,3,233.53,234.0,10,154,1,7,233.45,234.13,15,400,1,1,233.4,234.17,110,1,2,1,233.39,234.25,10,50,1,1,233.31,234.41,110,600,2,2,233.3,234.43,100,5,1,1,AAPL,17,0.24220837043633126,-0.0031265107844130964
2024-10-21T12:07:34.413671182Z,2024-10-21T12:07:34.413504555Z,10,2,38,A,B,0,233.71,200,130,166627,12112520,233.71,233.93,200,200,1,1,233.7,233.94,1200,200,1,1,233.66,233.95,1,29,1,1,233.65,233.98,26,44,1,3,233.58,234.0,505,154,2,7,233.53,234.13,10,400,1,1,233.45,234.17,15,1,1,1,233.4,234.25,110,50,2,1,233.39,234.41,10,600,1,2,233.31,234.43,110,5,2,1,AAPL,127,1.828886065226599,-0.0236079042028685
2024-10-21T12:07:51.491464688Z,2024-10-21T12:07:51.491296294Z,10,2,38,T,N,0,233.87,50,0,168394,12127009,233.71,233.93,200,200,1,1,233.7,233.94,1200,200,1,1,233.66,233.95,1,29,1,1,233.65,233.98,26,44,1,3,233.58,234.0,505,154,2,7,233.53,234.13,10,400,1,1,233.45,234.17,15,1,1,1,233.4,234.25,110,50,2,1,233.39,234.41,10,600,1,2,233.31,234.43,110,5,2,1,AAPL,73,1.2192066805845512,-0.015737948397114163
2024-10-21T12:07:51.491464688Z,2024-10-21T12:07:51.491296294Z,10,2,38,T,N,0,233.88,50,130,168394,12127010,233.71,233.93,200,200,1,1,233.7,233.94,1200,200,1,1,233.66,233.95,1,29,1,1,233.65,233.98,26,44,1,3,233.58,234.0,505,154,2,7,233.53,234.13,10,400,1,1,233.45,234.17,15,1,1,1,233.4,234.25,110,50,2,1,233.39,234.41,10,600,1,2,233.31,234.43,110,5,2,1,AAPL,73,1.2246039142590865,-0.015807617786570163
2024-10-21T12:07:51.493630333Z,2024-10-21T12:07:51.493462211Z,10,2,38,T,N,0,233.9,150,130,168122,12127014,233.71,233.93,200,200,1,1,233.7,233.94,1200,200,1,1,233.66,233.95,1,29,1,1,233.65,233.98,26,44,1,3,233.58,234.0,505,154,2,7,233.53,234.13,10,400,1,1,233.45,234.17,15,1,1,1,233.4,234.25,110,50,2,1,233.39,234.41,10,600,1,2,233.31,234.43,110,5,2,1,AAPL,78,1.3084808946877913,-0.01689033133359552
2024-10-21T12:07:51.493889366Z,2024-10-21T12:07:51.493723176Z,10,2,38,A,B,0,233.86,100,130,166190,12127015,233.86,233.93,100,200,1,1,233.71,233.94,200,200,1,1,233.7,233.95,1200,29,1,1,233.66,233.98,1,44,1,3,233.65,234.0,26,154,1,7,233.58,234.13,505,400,2,1,233.53,234.17,10,1,1,1,233.45,234.25,15,50,1,1,233.4,234.41,110,600,2,2,233.39,234.43,10,5,1,1,AAPL,88,1.6176470588235294,-0.020881156855457928
2024-10-21T12:07:51.493891476Z,2024-10-21T12:07:51.493724386Z,10,2,38,A,B,1,233.83,100,130,167090,12127016,233.86,233.93,100,200,1,1,233.83,233.94,100,200,1,1,233.71,233.95,200,29,1,1,233.7,233.98,1200,44,1,3,233.66,234.0,1,154,1,7,233.65,234.13,26,400,1,1,233.58,234.17,505,1,2,1,233.53,234.25,10,50,1,1,233.45,234.41,15,600,1,2,233.4,234.43,110,5,2,1,AAPL,198,3.6209476309226933,-0.0467404648215936
2024-10-21T12:07:51.493922927Z,2024-10-21T12:07:51.493756947Z,10,2,38,C,A,0,233.93,200,130,165980,12127018,233.86,233.94,100,200,1,1,233.83,233.95,100,29,1,1,233.71,233.98,200,44,1,3,233.7,234.0,1200,154,1,7,233.66,234.13,1,400,1,1,233.65,234.17,26,1,1,1,233.58,234.25,505,50,2,1,233.53,234.41,10,600,1,2,233.45,234.43,15,5,1,1,233.4,234.5,110,63,2,4,AAPL,261,4.5523255813953485,-0.05876301879556035
2024-10-21T12:07:51.494284128Z,2024-10-21T12:07:51.494118408Z,10,2,38,C,B,0,233.86,100,130,165720,12127025,233.83,233.94,100,200,1,1,233.71,233.95,200,29,1,1,233.7,233.98,1200,44,1,3,233.66,234.0,1,154,1,7,233.65,234.13,26,400,1,1,233.58,234.17,505,1,2,1,233.53,234.25,10,50,1,1,233.45,234.41,15,600,1,2,233.4,234.43,110,5,2,1,233.39,234.5,10,63,1,4,AAPL,251,4.503795721187025,-0.05813657830122876
2024-10-21T12:07:51.502564185Z,2024-10-21T12:07:51.502398180Z,10,2,38,C,B,0,233.83,100,130,166005,12127032,233.71,233.94,200,200,1,1,233.7,233.95,1200,29,1,1,233.66,233.98,1,44,1,3,233.65,234.0,26,154,1,7,233.58,234.13,505,400,2,1,233.53,234.17,10,1,1,1,233.45,234.25,15,50,1,1,233.4,234.41,110,600,2,2,233.39,234.43,10,5,1,1,233.31,234.5,110,63,2,4,AAPL,141,2.43403205918619,-0.031419341408158594
2024-10-21T12:07:51.568178423Z,2024-10-21T12:07:51.568012126Z,10,2,38,A,B,0,233.71,200,130,166297,12127155,233.71,233.94,400,200,2,1,233.7,233.95,1200,29,1,1,233.66,233.98,1,44,1,3,233.65,234.0,26,154,1,7,233.58,234.13,505,400,2,1,233.53,234.17,10,1,1,1,233.45,234.25,15,50,1,1,233.4,234.41,110,600,2,2,233.39,234.43,10,5,1,1,233.31,234.5,110,63,2,4,AAPL,83,1.4319840743198409,-0.018484553788968558
2024-10-21T12:07:51.601109855Z,2024-10-21T12:07:51.600943259Z,10,2,38,A,A,3,233.99,200,130,166596,12127168,233.71,233.94,400,200,2,1,233.7,233.95,1200,29,1,1,233.66,233.98,1,44,1,3,233.65,233.99,26,200,1,1,233.58,234.0,505,154,2,7,233.53,234.13,10,400,1,1,233.45,234.17,15,1,1,1,233.4,234.25,110,50,2,1,233.39,234.41,10,600,1,2,233.31,234.43,110,5,2,1,AAPL,78,1.3464858199753391,-0.017380912268343054
2024-10-21T12:07:51.615987022Z,2024-10-21T12:07:51.615820733Z,10,2,38,C,A,3,233.99,200,130,166289,12127177,233.71,233.94,400,200,2,1,233.7,233.95,1200,29,1,1,233.66,233.98,1,44,1,3,233.65,234.0,26,154,1,7,233.58,234.13,505,400,2,1,233.53,234.17,10,1,1,1,233.45,234.25,15,50,1,1,233.4,234.41,110,600,2,2,233.39,234.43,10,5,1,1,233.31,234.5,110,63,2,4,AAPL,141,2.3565459610027855,-0.030419123615618725
2024-10-21T12:07:51.619969198Z,2024-10-21T12:07:51.619802962Z,10,2,38,C,B,3,233.65,26,130,166236,12127178,233.71,233.94,400,200,2,1,233.7,233.95,1200,29,1,1,233.66,233.98,1,44,1,3,233.58,234.0,505,154,2,7,233.53,234.13,10,400,1,1,233.45,234.17,15,1,1,1,233.4,234.25,110,50,2,1,233.39,234.41,10,600,1,2,233.31,234.43,110,5,2,1,233.3,234.5,100,63,1,4,AAPL,41,0.6700715015321757,-0.008649518479044174
2024-10-21T12:07:51.620051180Z,2024-10-21T12:07:51.619884656Z,10,2,38,A,B,2,233.69,28,130,166524,12127179,233.71,233.94,400,200,2,1,233.7,233.95,1200,29,1,1,233.69,233.98,28,44,1,3,233.66,234.0,1,154,1,7,233.58,234.13,505,400,2,1,233.53,234.17,10,1,1,1,233.45,234.25,15,50,1,1,233.4,234.41,110,600,2,2,233.39,234.43,10,5,1,1,233.31,234.5,110,63,2,4,AAPL,151,2.4091975598310653,-0.03109876896089172
2024-10-21T12:07:51.620064221Z,2024-10-21T12:07:51.619898253Z,10,2,38,C,A,1,233.95,29,130,165968,12127180,233.71,233.94,400,200,2,1,233.7,233.98,1200,44,1,3,233.69,234.0,28,154,1,7,233.66,234.13,1,400,1,1,233.58,234.17,505,1,2,1,233.53,234.25,10,50,1,1,233.45,234.41,15,600,1,2,233.4,234.43,110,5,2,1,233.39,234.5,10,63,1,4,233.31,234.75,110,1,2,1,AAPL,152,2.440677966101695,-0.03150512911073097
2024-10-21T12:07:51.620087853Z,2024-10-21T12:07:51.619921024Z,10,2,38,A,B,0,233.72,28,130,166829,12127181,233.72,233.94,28,200,1,1,233.71,233.98,400,44,2,3,233.7,234.0,1200,154,1,7,233.69,234.13,28,400,1,1,233.66,234.17,1,1,1,1,233.58,234.25,505,50,2,1,233.53,234.41,10,600,1,2,233.45,234.43,15,5,1,1,233.4,234.5,110,63,2,4,233.39,234.75,10,1,1,1,AAPL,162,2.7323568575233024,-0.03527022276943684
2024-10-21T12:07:51.620126136Z,2024-10-21T12:07:51.619959682Z,10,2,38,A,A,3,234.07,30,130,166454,12127184,233.72,233.94,28,200,1,1,233.71,233.98,400,44,2,3,233.7,234.0,1200,154,1,7,233.69,234.07,28,30,1,1,233.66,234.13,1,400,1,1,233.58,234.17,505,1,2,1,233.53,234.25,10,50,1,1,233.45,234.41,15,600,1,2,233.4,234.43,110,5,2,1,233.39,234.5,10,63,1,4,AAPL,99,1.702493551160791,-0.02197638520299269
2024-10-21T12:07:51.628357454Z,2024-10-21T12:07:51.628191317Z,10,2,38,C,B,1,233.71,200,130,166137,12127189,233.72,233.94,28,200,1,1,233.71,233.98,200,44,1,3,233.7,234.0,1200,154,1,7,233.69,234.07,28,30,1,1,233.66,234.13,1,400,1,1,233.58,234.17,505,1,2,1,233.53,234.25,10,50,1,1,233.45,234.41,15,600,1,2,233.4,234.43,110,5,2,1,233.39,234.5,10,63,1,4,AAPL,99,1.7332221759066277,-0.02237304109265071
2024-10-21T12:07:51.628367420Z,2024-10-21T12:07:51.628201644Z,10,2,38,C,B,1,233.71,200,130,165776,12127190,233.72,233.94,28,200,1,1,233.7,233.98,1200,44,1,3,233.69,234.0,28,154,1,7,233.66,234.07,1,30,1,1,233.58,234.13,505,400,2,1,233.53,234.17,10,1,1,1,233.45,234.25,15,50,1,1,233.4,234.41,110,600,2,2,233.39,234.43,10,5,1,1,233.31,234.5,110,63,2,4,AAPL,-11,-0.18818040435458788,0.0024290988068246546
2024-10-21T12:07:51.628378547Z,2024-10-21T12:07:51.628212387Z,10,2,38,A,B,3,233.67,200,130,166160,12127191,233.72,233.94,28,200,1,1,233.7,233.98,1200,44,1,3,233.69,234.0,28,154,1,7,233.67,234.07,200,30,1,1,233.66,234.13,1,400,1,1,233.58,234.17,505,1,2,1,233.53,234.25,10,50,1,1,233.45,234.41,15,600,1,2,233.4,234.43,110,5,2,1,233.39,234.5,10,63,1,4,AAPL,-1,-0.017391304347826087,0.0002244930697503777
2024-10-21T12:07:51.686702996Z,2024-10-21T12:07:51.686536494Z,10,2,38,A,A,2,234.0,200,130,166502,12127218,233.72,233.94,28,200,1,1,233.7,233.98,1200,44,1,3,233.69,234.0,28,354,1,8,233.67,234.07,200,30,1,1,233.66,234.13,1,400,1,1,233.58,234.17,505,1,2,1,233.53,234.25,10,50,1,1,233.45,234.41,15,600,1,2,233.4,234.43,110,5,2,1,233.39,234.5,10,63,1,4,AAPL,-1,-0.017660044150110375,0.000227962057583165
2024-10-21T12:07:51.794965675Z,2024-10-21T12:07:51.794799198Z,10,2,38,A,B,3,233.68,200,130,166477,12127318,233.72,233.94,28,200,1,1,233.7,233.98,1200,44,1,3,233.69,234.0,28,354,1,8,233.68,234.07,200,30,1,1,233.66,234.13,1,400,1,1,233.58,234.17,505,1,2,1,233.53,234.25,10,50,1,1,233.45,234.41,15,600,1,2,233.4,234.43,110,5,2,1,233.39,234.5,10,63,1,4,AAPL,-1,-0.01791472590469366,0.00023124957919467429
2024-10-21T12:07:51.814199410Z,2024-10-21T12:07:51.814032926Z,10,2,38,A,B,1,233.71,200,130,166484,12127371,233.72,233.94,28,200,1,1,233.71,233.98,200,44,1,3,233.7,234.0,1200,354,1,8,233.69,234.07,28,30,1,1,233.66,234.13,1,400,1,1,233.58,234.17,505,1,2,1,233.53,234.25,10,50,1,1,233.45,234.41,15,600,1,2,233.4,234.43,110,5,2,1,233.39,234.5,10,63,1,4,AAPL,-1,-0.018156424581005585,0.00023436951066816664
2024-10-21T12:07:52.076717628Z,2024-10-21T12:07:52.076548886Z,10,2,38,T,N,0,233.93,50,130,168742,12127534,233.72,233.94,28,200,1,1,233.71,233.98,200,44,1,3,233.7,234.0,1200,354,1,8,233.69,234.07,28,30,1,1,233.66,234.13,1,400,1,1,233.58,234.17,505,1,2,1,233.53,234.25,10,50,1,1,233.45,234.41,15,600,1,2,233.4,234.43,110,5,2,1,233.39,234.5,10,63,1,4,AAPL,-11,-0.20242914979757085,0.0026130266215884045
2024-10-21T12:07:52.076756699Z,2024-10-21T12:07:52.076590310Z,10,2,38,A,B,0,233.82,5,130,166389,12127535,233.82,233.94,5,200,1,1,233.72,233.98,28,44,1,3,233.71,234.0,200,354,1,8,233.7,234.07,1200,30,1,1,233.69,234.13,28,400,1,1,233.66,234.17,1,1,1,1,233.58,234.25,505,50,2,1,233.53,234.41,10,600,1,2,233.45,234.43,15,5,1,1,233.4,234.5,110,63,2,4,AAPL,99,1.7813148788927335,-0.022993838607892492
2024-10-21T12:07:52.083929289Z,2024-10-21T12:07:52.083763088Z,10,2,38,C,B,0,233.82,5,130,166201,12127537,233.72,233.94,28,200,1,1,233.71,233.98,200,44,1,3,233.7,234.0,1200,354,1,8,233.69,234.07,28,30,1,1,233.66,234.13,1,400,1,1,233.58,234.17,505,1,2,1,233.53,234.25,10,50,1,1,233.45,234.41,15,600,1,2,233.4,234.43,110,5,2,1,233.39,234.5,10,63,1,4,AAPL,89,1.6220047249409382,-0.02093740714146747
2024-10-21T12:07:52.139486617Z,2024-10-21T12:07:52.139320651Z,10,2,38,C,B,3,233.69,28,130,165966,12127647,233.72,233.94,28,200,1,1,233.71,233.98,200,44,1,3,233.7,234.0,1200,354,1,8,233.66,234.07,1,30,1,1,233.58,234.13,505,400,2,1,233.53,234.17,10,1,1,1,233.45,234.25,15,50,1,1,233.4,234.41,110,600,2,2,233.39,234.43,10,5,1,1,233.31,234.5,110,63,2,4,AAPL,-21,-0.375,0.004840631816492519
2024-10-21T12:07:52.139521177Z,2024-10-21T12:07:52.139355221Z,10,2,38,C,B,0,233.72,28,130,165956,12127648,233.71,233.94,200,200,1,1,233.7,233.98,1200,44,1,3,233.66,234.0,1,354,1,8,233.58,234.07,505,30,2,1,233.53,234.13,10,400,1,1,233.45,234.17,15,1,1,1,233.4,234.25,110,50,2,1,233.39,234.41,10,600,1,2,233.31,234.43,110,5,2,1,233.3,234.5,100,63,1,4,AAPL,-121,-2.127311306456502,0.027460082116313633
2024-10-21T12:07:52.139597427Z,2024-10-21T12:07:52.139430957Z,10,2,38,A,B,1,233.7,29,130,166470,12127649,233.71,233.94,200,200,1,1,233.7,233.98,1229,44,2,3,233.66,234.0,1,354,1,8,233.58,234.07,505,30,2,1,233.53,234.13,10,400,1,1,233.45,234.17,15,1,1,1,233.4,234.25,110,50,2,1,233.39,234.41,10,600,1,2,233.31,234.43,110,5,2,1,233.3,234.5,100,63,1,4,AAPL,-121,-2.097053726169844,0.027069506634111836
2024-10-21T12:07:52.330401624Z,2024-10-21T12:07:52.330233710Z,10,2,38,T,N,0,233.93,50,130,167914,12127818,233.71,233.94,200,200,1,1,233.7,233.98,1229,44,2,3,233.66,234.0,1,354,1,8,233.58,234.07,505,30,2,1,233.53,234.13,10,400,1,1,233.45,234.17,15,1,1,1,233.4,234.25,110,50,2,1,233.39,234.41,10,600,1,2,233.31,234.43,110,5,2,1,233.3,234.5,100,63,1,4,AAPL,-121,-2.06951724137931,0.026714056009068045
2024-10-21T12:07:52.330433594Z,2024-10-21T12:07:52.330267041Z,10,2,38,A,B,0,233.82,5,130,166553,12127819,233.82,233.94,5,200,1,1,233.71,233.98,200,44,1,3,233.7,234.0,1229,354,2,8,233.66,234.07,1,30,1,1,233.58,234.13,505,400,2,1,233.53,234.17,10,1,1,1,233.45,234.25,15,50,1,1,233.4,234.41,110,600,2,2,233.39,234.43,10,5,1,1,233.31,234.5,110,63,2,4,AAPL,-11,-0.18536071616640337,0.0023927012805411503
2024-10-21T12:07:52.333928834Z,2024-10-21T12:07:52.333762726Z,10,2,38,C,B,0,233.82,5,130,166108,12127822,233.71,233.94,200,200,1,1,233.7,233.98,1229,44,2,3,233.66,234.0,1,354,1,8,233.58,234.07,505,30,2,1,233.53,234.13,10,400,1,1,233.45,234.17,15,1,1,1,233.4,234.25,110,50,2,1,233.39,234.41,10,600,1,2,233.31,234.43,110,5,2,1,233.3,234.5,100,63,1,4,AAPL,-111,-1.8495329462257006,0.023874421400403398
2024-10-21T12:07:53.655001137Z,2024-10-21T12:07:53.654833970Z,10,2,38,T,N,0,233.93,50,130,167167,12128538,233.71,233.94,200,200,1,1,233.7,233.98,1229,44,2,3,233.66,234.0,1,354,1,8,233.58,234.07,505,30,2,1,233.53,234.13,10,400,1,1,233.45,234.17,15,1,1,1,233.4,234.25,110,50,2,1,233.39,234.41,10,600,1,2,233.31,234.43,110,5,2,1,233.3,234.5,100,63,1,4,AAPL,-11,-0.18064195073401346,0.0023317897976435726
2024-10-21T12:07:53.655037705Z,2024-10-21T12:07:53.654870612Z,10,2,38,A,B,0,233.82,5,130,167093,12128540,233.82,233.94,5,200,1,1,233.71,233.98,200,44,1,3,233.7,234.0,1229,354,2,8,233.66,234.07,1,30,1,1,233.58,234.13,505,400,2,1,233.53,234.17,10,1,1,1,233.45,234.25,15,50,1,1,233.4,234.41,110,600,2,2,233.39,234.43,10,5,1,1,233.31,234.5,110,63,2,4,AAPL,99,1.6059160305343512,-0.020729728618719873
2024-10-21T12:07:53.663929398Z,2024-10-21T12:07:53.663763591Z,10,2,38,C,B,0,233.82,5,130,165807,12128556,233.71,233.94,200,200,1,1,233.7,233.98,1229,44,2,3,233.66,234.0,1,354,1,8,233.58,234.07,505,30,2,1,233.53,234.13,10,400,1,1,233.45,234.17,15,1,1,1,233.4,234.25,110,50,2,1,233.39,234.41,10,600,1,2,233.31,234.43,110,5,2,1,233.3,234.5,100,63,1,4,AAPL,-1,-0.016073478760045924,0.00020748211383358673
2024-10-21T12:07:54.619949683Z,2024-10-21T12:07:54.619783229Z,10,2,38,A,B,0,233.71,200,130,166454,12129129,233.71,233.94,400,200,2,1,233.7,233.98,1229,44,2,3,233.66,234.0,1,354,1,8,233.58,234.07,505,30,2,1,233.53,234.13,10,400,1,1,233.45,234.17,15,1,1,1,233.4,234.25,110,50,2,1,233.39,234.41,10,600,1,2,233.31,234.43,110,5,2,1,233.3,234.5,100,63,1,4,AAPL,-111,-1.7647058823529411,0.022779443842317736
2024-10-21T12:07:54.620103538Z,2024-10-21T12:07:54.619937567Z,10,2,38,C,A,2,234.0,200,130,165971,12129132,233.71,233.94,400,200,2,1,233.7,233.98,1229,44,2,3,233.66,234.0,1,154,1,7,233.58,234.07,505,30,2,1,233.53,234.13,10,400,1,1,233.45,234.17,15,1,1,1,233.4,234.25,110,50,2,1,233.39,234.41,10,600,1,2,233.31,234.43,110,5,2,1,233.3,234.5,100,63,1,4,AAPL,-111,-1.7503285151116952,0.022593855732170074
2024-10-21T12:07:54.620115428Z,2024-10-21T12:07:54.619949131Z,10,2,38,A,A,3,234.05,400,130,166297,12129133,233.71,233.94,400,200,2,1,233.7,233.98,1229,44,2,3,233.66,234.0,1,154,1,7,233.58,234.05,505,400,2,1,233.53,234.07,10,30,1,1,233.45,234.13,15,400,1,1,233.4,234.17,110,1,2,1,233.39,234.25,10,50,1,1,233.31,234.41,110,600,2,2,233.3,234.43,100,5,1,1,AAPL,-116,-1.8377221151787626,0.023721963041616664
2024-10-21T12:07:54.620548789Z,2024-10-21T12:07:54.620382308Z,10,2,38,A,B,0,233.72,29,130,166481,12129141,233.72,233.94,29,200,1,1,233.71,233.98,400,44,2,3,233.7,234.0,1229,154,2,7,233.66,234.05,1,400,1,1,233.58,234.07,505,30,2,1,233.53,234.13,10,400,1,1,233.45,234.17,15,1,1,1,233.4,234.25,110,50,2,1,233.39,234.41,10,600,1,2,233.31,234.43,110,5,2,1,AAPL,-6,-0.09527789385708316,0.001229880545101317
2024-10-21T12:07:54.620656776Z,2024-10-21T12:07:54.620490674Z,10,2,38,C,A,4,234.07,30,130,166102,12129142,233.72,233.94,29,200,1,1,233.71,233.98,400,44,2,3,233.7,234.0,1229,154,2,7,233.66,234.05,1,400,1,1,233.58,234.13,505,400,2,1,233.53,234.17,10,1,1,1,233.45,234.25,15,50,1,1,233.4,234.41,110,600,2,2,233.39,234.43,10,5,1,1,233.31,234.5,110,63,2,4,AAPL,57,0.8965517241379309,-0.01157300480264878
2024-10-21T12:07:54.620699903Z,2024-10-21T12:07:54.620533693Z,10,2,38,A,A,4,234.12,28,130,166210,12129143,233.72,233.94,29,200,1,1,233.71,233.98,400,44,2,3,233.7,234.0,1229,154,2,7,233.66,234.05,1,400,1,1,233.58,234.12,505,28,2,1,233.53,234.13,10,400,1,1,233.45,234.17,15,1,1,1,233.4,234.25,110,50,2,1,233.39,234.41,10,600,1,2,233.31,234.43,110,5,2,1,AAPL,52,0.8198659834450138,-0.010583118305930301
2024-10-21T12:07:54.677928883Z,2024-10-21T12:07:54.677762815Z,10,2,38,C,B,1,233.71,200,130,166068,12129187,233.72,233.94,29,200,1,1,233.71,233.98,200,44,1,3,233.7,234.0,1229,154,2,7,233.66,234.05,1,400,1,1,233.58,234.12,505,28,2,1,233.53,234.13,10,400,1,1,233.45,234.17,15,1,1,1,233.4,234.25,110,50,2,1,233.39,234.41,10,600,1,2,233.31,234.43,110,5,2,1,AAPL,52,0.8217382925419155,-0.01060728672988969
2024-10-21T12:07:54.677941254Z,2024-10-21T12:07:54.677774981Z,10,2,38,A,B,0,233.8,200,130,166273,12129188,233.8,233.94,200,200,1,1,233.72,233.98,29,44,1,3,233.7,234.0,1229,154,2,7,233.66,234.05,1,400,1,1,233.58,234.12,505,28,2,1,233.53,234.13,10,400,1,1,233.45,234.17,15,1,1,1,233.4,234.25,110,50,2,1,233.39,234.41,10,600,1,2,233.31,234.43,110,5,2,1,AAPL,52,0.8235294117647058,-0.010630407126414944
2024-10-21T12:07:54.740726585Z,2024-10-21T12:07:54.740560308Z,10,2,38,C,B,1,233.72,29,130,166277,12129249,233.8,233.94,200,200,1,1,233.7,233.98,1229,44,2,3,233.66,234.0,1,154,1,7,233.58,234.05,505,400,2,1,233.53,234.12,10,28,1,1,233.45,234.13,15,400,1,1,233.4,234.17,110,1,2,1,233.39,234.25,10,50,1,1,233.31,234.41,110,600,2,2,233.3,234.43,100,5,1,1,AAPL,-48,-0.7631724902939545,0.009851298767969986
2024-10-21T12:07:54.740757905Z,2024-10-21T12:07:54.740591753Z,10,2,38,C,B,1,233.7,29,130,166152,12129250,233.8,233.94,200,200,1,1,233.7,233.98,1200,44,1,3,233.66,234.0,1,154,1,7,233.58,234.05,505,400,2,1,233.53,234.12,10,28,1,1,233.45,234.13,15,400,1,1,233.4,234.17,110,1,2,1,233.39,234.25,10,50,1,1,233.31,234.41,110,600,2,2,233.3,234.43,100,5,1,1,AAPL,-48,-0.7660500544069642,0.009888443377035136
2024-10-21T12:07:54.740834864Z,2024-10-21T12:07:54.740668620Z,10,2,38,A,B,1,233.75,29,130,166244,12129251,233.8,233.94,200,200,1,1,233.75,233.98,29,44,1,3,233.7,234.0,1200,154,1,7,233.66,234.05,1,400,1,1,233.58,234.12,505,28,2,1,233.53,234.13,10,400,1,1,233.45,234.17,15,1,1,1,233.4,234.25,110,50,2,1,233.39,234.41,10,600,1,2,233.31,234.43,110,5,2,1,AAPL,62,0.9912950790548943,-0.012795985331214904
2024-10-21T12:07:57.005517492Z,2024-10-21T12:07:57.005348310Z,10,2,38,T,N,0,233.93,50,0,169182,12130684,233.8,233.94,200,200,1,1,233.75,233.98,29,44,1,3,233.7,234.0,1200,154,1,7,233.66,234.05,1,400,1,1,233.58,234.12,505,28,2,1,233.53,234.13,10,400,1,1,233.45,234.17,15,1,1,1,233.4,234.25,110,50,2,1,233.39,234.41,10,600,1,2,233.31,234.43,110,5,2,1,AAPL,62,0.9930362116991645,-0.012818460483413802
2024-10-21T12:07:57.005517492Z,2024-10-21T12:07:57.005348926Z,10,2,38,T,N,0,233.93,50,130,168566,12130685,233.8,233.94,200,200,1,1,233.75,233.98,29,44,1,3,233.7,234.0,1200,154,1,7,233.66,234.05,1,400,1,1,233.58,234.12,505,28,2,1,233.53,234.13,10,400,1,1,233.45,234.17,15,1,1,1,233.4,234.25,110,50,2,1,233.39,234.41,10,600,1,2,233.31,234.43,110,5,2,1,AAPL,62,0.9947089947089947,-0.01284005335450573
2024-10-21T12:07:57.005814257Z,2024-10-21T12:07:57.005648252Z,10,2,38,A,B,0,233.91,100,130,166005,12130686,233.91,233.94,100,200,1,1,233.8,233.98,200,44,1,3,233.75,234.0,29,154,1,7,233.7,234.05,1200,400,1,1,233.66,234.12,1,28,1,1,233.58,234.13,505,400,2,1,233.53,234.17,10,1,1,1,233.45,234.25,15,50,1,1,233.4,234.41,110,600,2,2,233.39,234.43,10,5,1,1,AAPL,72,1.1767109295199183,-0.015189398304662942
2024-10-21T12:07:57.006239314Z,2024-10-21T12:07:57.006073356Z,10,2,38,C,B,0,233.91,100,130,165958,12130687,233.8,233.94,200,200,1,1,233.75,233.98,29,44,1,3,233.7,234.0,1200,154,1,7,233.66,234.05,1,400,1,1,233.58,234.12,505,28,2,1,233.53,234.13,10,400,1,1,233.45,234.17,15,1,1,1,233.4,234.25,110,50,2,1,233.39,234.41,10,600,1,2,233.31,234.43,110,5,2,1,AAPL,-38,-0.6218066455167808,0.008026498751986706
2024-10-21T12:07:57.069517287Z,2024-10-21T12:07:57.069351091Z,10,2,38,C,A,3,234.05,200,130,166196,12130710,233.8,233.94,200,200,1,1,233.75,233.98,29,44,1,3,233.7,234.0,1200,154,1,7,233.66,234.05,1,200,1,1,233.58,234.12,505,28,2,1,233.53,234.13,10,400,1,1,233.45,234.17,15,1,1,1,233.4,234.25,110,50,2,1,233.39,234.41,10,600,1,2,233.31,234.43,110,5,2,1,AAPL,-38,-0.6225425950196593,0.008035998646863945
2024-10-21T12:07:57.259009812Z,2024-10-21T12:07:57.258842550Z,10,2,38,T,N,0,233.93,50,130,167262,12130840,233.8,233.94,200,200,1,1,233.75,233.98,29,44,1,3,233.7,234.0,1200,154,1,7,233.66,234.05,1,200,1,1,233.58,234.12,505,28,2,1,233.53,234.13,10,400,1,1,233.45,234.17,15,1,1,1,233.4,234.25,110,50,2,1,233.39,234.41,10,600,1,2,233.31,234.43,110,5,2,1,AAPL,-38,-0.623251326579836,0.008045147202969397
2024-10-21T12:07:58.008991267Z,2024-10-21T12:07:58.008823092Z,10,2,38,T,B,0,233.94,50,130,168175,12131171,233.8,233.94,200,200,1,1,233.75,233.98,29,44,1,3,233.7,234.0,1200,154,1,7,233.66,234.05,1,200,1,1,233.58,234.12,505,28,2,1,233.53,234.13,10,400,1,1,233.45,234.17,15,1,1,1,233.4,234.25,110,50,2,1,233.39,234.41,10,600,1,2,233.31,234.43,110,5,2,1,AAPL,-38,-0.6239343227028734,0.008053963557005973
2024-10-21T12:07:58.008991267Z,2024-10-21T12:07:58.008823092Z,10,2,38,C,A,0,233.94,50,130,168175,12131171,233.8,233.94,200,150,1,1,233.75,233.98,29,44,1,3,233.7,234.0,1200,154,1,7,233.66,234.05,1,200,1,1,233.58,234.12,505,28,2,1,233.53,234.13,10,400,1,1,233.45,234.17,15,1,1,1,233.4,234.25,110,50,2,1,233.39,234.41,10,600,1,2,233.31,234.43,110,5,2,1,AAPL,-38,-0.6245929601488602,0.008062465480676845
2024-10-21T12:07:58.009054960Z,2024-10-21T12:07:58.008889077Z,10,2,38,C,A,3,234.05,200,130,165883,12131172,233.8,233.94,200,150,1,1,233.75,233.98,29,44,1,3,233.7,234.0,1200,154,1,7,233.66,234.12,1,28,1,1,233.58,234.13,505,400,2,1,233.53,234.17,10,1,1,1,233.45,234.25,15,50,1,1,233.4,234.41,110,600,2,2,233.39,234.43,10,5,1,1,233.31,234.5,110,63,2,4,AAPL,25,0.4077318030806403,-0.005263145436234693
2024-10-21T12:07:58.037113337Z,2024-10-21T12:07:58.036947209Z,10,2,38,A,A,3,234.05,200,130,166128,12131183,233.8,233.94,200,150,1,1,233.75,233.98,29,44,1,3,233.7,234.0,1200,154,1,7,233.66,234.05,1,200,1,1,233.58,234.12,505,28,2,1,233.53,234.13,10,400,1,1,233.45,234.17,15,1,1,1,233.4,234.25,110,50,2,1,233.39,234.41,10,600,1,2,233.31,234.43,110,5,2,1,AAPL,20,0.3265548463707882,-0.004215284744459371
2024-10-21T12:07:58.162823341Z,2024-10-21T12:07:58.162656656Z,10,2,38,A,A,3,234.05,200,130,166685,12131260,233.8,233.94,200,150,1,1,233.75,233.98,29,44,1,3,233.7,234.0,1200,154,1,7,233.66,234.05,1,400,1,2,233.58,234.12,505,28,2,1,233.53,234.13,10,400,1,1,233.45,234.17,15,1,1,1,233.4,234.25,110,50,2,1,233.39,234.41,10,600,1,2,233.31,234.43,110,5,2,1,AAPL,20,0.3269118505545826,-0.00421989307995456
2024-10-21T12:08:07.337883263Z,2024-10-21T12:08:07.337716526Z,10,2,38,A,B,0,233.81,200,130,166737,12137724,233.81,233.94,200,150,1,1,233.75,233.98,29,44,1,3,233.7,234.0,1200,154,1,7,233.66,234.05,1,400,1,2,233.58,234.12,505,28,2,1,233.53,234.13,10,400,1,1,233.45,234.17,15,1,1,1,233.4,234.25,110,50,2,1,233.39,234.41,10,600,1,2,233.31,234.43,110,5,2,1,AAPL,20,0.3272570690397588,-0.004224349281509188
2024-10-21T12:08:07.341641992Z,2024-10-21T12:08:07.341475627Z,10,2,38,A,B,1,233.76,29,130,166365,12137749,233.81,233.94,200,150,1,1,233.76,233.98,29,44,1,3,233.75,234.0,29,154,1,7,233.7,234.05,1200,400,1,2,233.66,234.12,1,28,1,1,233.58,234.13,505,400,2,1,233.53,234.17,10,1,1,1,233.45,234.25,15,50,1,1,233.4,234.41,110,600,2,2,233.39,234.43,10,5,1,1,AAPL,30,0.4984245201947866,-0.00643383890819974
2024-10-21T12:08:07.343219276Z,2024-10-21T12:08:07.343053018Z,10,2,38,C,B,2,233.75,29,130,166258,12137753,233.81,233.94,200,150,1,1,233.76,233.98,29,44,1,3,233.7,234.0,1200,154,1,7,233.66,234.05,1,400,1,2,233.58,234.12,505,28,2,1,233.53,234.13,10,400,1,1,233.45,234.17,15,1,1,1,233.4,234.25,110,50,2,1,233.39,234.41,10,600,1,2,233.31,234.43,110,5,2,1,AAPL,-80,-1.330139495561505,0.017169908166902215
2024-10-21T12:08:11.981052333Z,2024-10-21T12:08:11.980882050Z,10,2,38,T,N,0,233.93,44,0,170283,12141046,233.81,233.94,200,150,1,1,233.76,233.98,29,44,1,3,233.7,234.0,1200,154,1,7,233.66,234.05,1,400,1,2,233.58,234.12,505,28,2,1,233.53,234.13,10,400,1,1,233.45,234.17,15,1,1,1,233.4,234.25,110,50,2,1,233.39,234.41,10,600,1,2,233.31,234.43,110,5,2,1,AAPL,-59,-0.9365079365079365,0.012088773636954863
2024-10-21T12:08:11.981052333Z,2024-10-21T12:08:11.980882050Z,10,2,38,T,B,0,233.94,56,130,170283,12141047,233.81,233.94,200,150,1,1,233.76,233.98,29,44,1,3,233.7,234.0,1200,154,1,7,233.66,234.05,1,400,1,2,233.58,234.12,505,28,2,1,233.53,234.13,10,400,1,1,233.45,234.17,15,1,1,1,233.4,234.25,110,50,2,1,233.39,234.41,10,600,1,2,233.31,234.43,110,5,2,1,AAPL,-59,-0.9386090148888436,0.012115895095247032
2024-10-21T12:08:11.981052333Z,2024-10-21T12:08:11.980882050Z,10,2,38,C,A,0,233.94,56,130,170283,12141047,233.81,233.94,200,94,1,1,233.76,233.98,29,44,1,3,233.7,234.0,1200,154,1,7,233.66,234.05,1,400,1,2,233.58,234.12,505,28,2,1,233.53,234.13,10,400,1,1,233.45,234.17,15,1,1,1,233.4,234.25,110,50,2,1,233.39,234.41,10,600,1,2,233.31,234.43,110,5,2,1,AAPL,-59,-0.9406137903547229,0.012141773441660524
2024-10-21T12:08:22.863475945Z,2024-10-21T12:08:22.863309742Z,10,2,38,C,B,0,233.81,200,130,166203,12147416,233.76,233.94,29,94,1,1,233.7,233.98,1200,44,1,3,233.66,234.0,1,154,1,7,233.58,234.05,505,400,2,2,233.53,234.12,10,28,1,1,233.45,234.13,15,400,1,1,233.4,234.17,110,1,2,1,233.39,234.25,10,50,1,1,233.31,234.41,110,600,2,2,233.3,234.43,100,5,1,1,AAPL,-200,-4.028776978417266,0.052004869395411234
2024-10-21T12:08:22.863490039Z,2024-10-21T12:08:22.863323283Z,10,2,38,A,B,1,233.73,400,130,166756,12147417,233.76,233.94,29,94,1,1,233.73,233.98,400,44,1,3,233.7,234.0,1200,154,1,7,233.66,234.05,1,400,1,2,233.58,234.12,505,28,2,1,233.53,234.13,10,400,1,1,233.45,234.17,15,1,1,1,233.4,234.25,110,50,2,1,233.39,234.41,10,600,1,2,233.31,234.43,110,5,2,1,AAPL,-90,-1.7777777777777777,0.022948180463371944
2024-10-21T12:08:22.882115852Z,2024-10-21T12:08:22.881949837Z,10,2,38,C,B,0,233.76,29,130,166015,12147431,233.73,233.94,400,94,1,1,233.7,233.98,1200,44,1,3,233.66,234.0,1,154,1,7,233.58,234.05,505,400,2,2,233.53,234.12,10,28,1,1,233.45,234.13,15,400,1,1,233.4,234.17,110,1,2,1,233.39,234.25,10,50,1,1,233.31,234.41,110,600,2,2,233.3,234.43,100,5,1,1,AAPL,-190,-3.7377049180327866,0.048247608925040195
2024-10-21T12:08:22.882158439Z,2024-10-21T12:08:22.881992297Z,10,2,38,A,B,1,233.71,30,130,166142,12147432,233.73,233.94,400,94,1,1,233.71,233.98,30,44,1,3,233.7,234.0,1200,154,1,7,233.66,234.05,1,400,1,2,233.58,234.12,505,28,2,1,233.53,234.13,10,400,1,1,233.45,234.17,15,1,1,1,233.4,234.25,110,50,2,1,233.39,234.41,10,600,1,2,233.31,234.43,110,5,2,1,AAPL,-80,-1.5533980582524272,0.020051808171878398
2024-10-21T12:08:22.934611176Z,2024-10-21T12:08:22.934444989Z,10,2,38,C,B,0,233.73,200,130,166187,12147478,233.73,233.94,200,94,1,1,233.71,233.98,30,44,1,3,233.7,234.0,1200,154,1,7,233.66,234.05,1,400,1,2,233.58,234.12,505,28,2,1,233.53,234.13,10,400,1,1,233.45,234.17,15,1,1,1,233.4,234.25,110,50,2,1,233.39,234.41,10,600,1,2,233.31,234.43,110,5,2,1,AAPL,-80,-1.537117903930131,0.019841658217238625
2024-10-21T12:08:25.917930565Z,2024-10-21T12:08:25.917764011Z,10,2,38,A,B,0,233.77,200,130,166554,12149527,233.77,233.94,200,94,1,1,233.71,233.98,30,44,1,3,233.7,234.0,1200,154,1,7,233.66,234.05,1,400,1,2,233.58,234.12,505,28,2,1,233.53,234.13,10,400,1,1,233.45,234.17,15,1,1,1,233.4,234.25,110,50,2,1,233.39,234.41,10,600,1,2,233.31,234.43,110,5,2,1,AAPL,-80,-1.5238095238095237,0.01966986896860452
2024-10-21T12:08:36.931357634Z,2024-10-21T12:08:36.931191504Z,10,2,38,C,A,3,234.05,200,130,166130,12157931,233.77,233.94,200,94,1,1,233.71,233.98,30,44,1,3,233.7,234.0,1200,154,1,7,233.66,234.05,1,200,1,1,233.58,234.12,505,28,2,1,233.53,234.13,10,400,1,1,233.45,234.17,15,1,1,1,233.4,234.25,110,50,2,1,233.39,234.41,10,600,1,2,233.31,234.43,110,5,2,1,AAPL,20,0.356687898089172,-0.004604252768128766
2024-10-21T12:08:36.931367641Z,2024-10-21T12:08:36.931201585Z,10,2,38,C,A,3,234.05,200,130,166056,12157932,233.77,233.94,200,94,1,1,233.71,233.98,30,44,1,3,233.7,234.0,1200,154,1,7,233.66,234.12,1,28,1,1,233.58,234.13,505,400,2,1,233.53,234.17,10,1,1,1,233.45,234.25,15,50,1,1,233.4,234.41,110,600,2,2,233.39,234.43,10,5,1,1,233.31,234.5,110,63,2,4,AAPL,83,1.3862212943632568,-0.017893831739184594
2024-10-21T12:08:36.931379398Z,2024-10-21T12:08:36.931212780Z,10,2,38,A,A,3,234.07,400,130,166618,12157933,233.77,233.94,200,94,1,1,233.71,233.98,30,44,1,3,233.7,234.0,1200,154,1,7,233.66,234.07,1,400,1,1,233.58,234.12,505,28,2,1,233.53,234.13,10,400,1,1,233.45,234.17,15,1,1,1,233.4,234.25,110,50,2,1,233.39,234.41,10,600,1,2,233.31,234.43,110,5,2,1,AAPL,78,1.3084808946877913,-0.01689033133359552
2024-10-21T12:08:36.986147102Z,2024-10-21T12:08:36.985980884Z,10,2,38,A,B,0,233.78,200,130,166218,12158018,233.78,233.94,200,94,1,1,233.71,233.98,30,44,1,3,233.7,234.0,1200,154,1,7,233.66,234.07,1,400,1,1,233.58,234.12,505,28,2,1,233.53,234.13,10,400,1,1,233.45,234.17,15,1,1,1,233.4,234.25,110,50,2,1,233.39,234.41,10,600,1,2,233.31,234.43,110,5,2,1,AAPL,78,1.3131313131313131,-0.016950360569536096
2024-10-21T12:08:37.008771530Z,2024-10-21T12:08:37.008605354Z,10,2,38,A,B,1,233.72,28,130,166176,12158236,233.78,233.94,200,94,1,1,233.72,233.98,28,44,1,3,233.71,234.0,30,154,1,7,233.7,234.07,1200,400,1,1,233.66,234.12,1,28,1,1,233.58,234.13,505,400,2,1,233.53,234.17,10,1,1,1,233.45,234.25,15,50,1,1,233.4,234.41,110,600,2,2,233.39,234.43,10,5,1,1,AAPL,88,1.6093100581878637,-0.020773539920708267
2024-10-21T12:08:37.008823724Z,2024-10-21T12:08:37.008657827Z,10,2,38,C,B,2,233.71,30,130,165897,12158237,233.78,233.94,200,94,1,1,233.72,233.98,28,44,1,3,233.7,234.0,1200,154,1,7,233.66,234.07,1,400,1,1,233.58,234.12,505,28,2,1,233.53,234.13,10,400,1,1,233.45,234.17,15,1,1,1,233.4,234.25,110,50,2,1,233.39,234.41,10,600,1,2,233.31,234.43,110,5,2,1,AAPL,-22,-0.4006069802731411,0.005171175718984421
2024-10-21T12:08:37.017872239Z,2024-10-21T12:08:37.017706043Z,10,2,38,A,A,4,234.09,27,130,166196,12158260,233.78,233.94,200,94,1,1,233.72,233.98,28,44,1,3,233.7,234.0,1200,154,1,7,233.66,234.07,1,400,1,1,233.58,234.09,505,27,2,1,233.53,234.12,10,28,1,1,233.45,234.13,15,400,1,1,233.4,234.17,110,1,2,1,233.39,234.25,10,50,1,1,233.31,234.41,110,600,2,2,AAPL,-622,-7.9743589743589745,0.10293582871310589
2024-10-21T12:08:37.017900433Z,2024-10-21T12:08:37.017734583Z,10,2,38,C,A,5,234.12,28,130,165850,12158261,233.78,233.94,200,94,1,1,233.72,233.98,28,44,1,3,233.7,234.0,1200,154,1,7,233.66,234.07,1,400,1,1,233.58,234.09,505,27,2,1,233.53,234.13,10,400,1,1,233.45,234.17,15,1,1,1,233.4,234.25,110,50,2,1,233.39,234.41,10,600,1,2,233.31,234.43,110,5,2,1,AAPL,-617,-8.061595893607093,0.1040619135314665
2024-10-21T12:08:37.054287009Z,2024-10-21T12:08:37.054120455Z,10,2,38,A,A,3,234.04,200,130,166554,12158303,233.78,233.94,200,94,1,1,233.72,233.98,28,44,1,3,233.7,234.0,1200,154,1,7,233.66,234.04,1,200,1,1,233.58,234.09,505,27,2,1,233.53,234.13,10,400,1,1,233.45,234.17,15,1,1,1,233.4,234.25,110,50,2,1,233.39,234.41,10,600,1,2,233.31,234.43,110,5,2,1,AAPL,-617,-8.197519929140833,0.10581646876088166
2024-10-21T12:08:37.140290334Z,2024-10-21T12:08:37.140123992Z,10,2,38,A,A,3,234.03,200,130,166342,12158500,233.78,233.94,200,94,1,1,233.72,233.98,28,44,1,3,233.7,234.0,1200,154,1,7,233.66,234.03,1,200,1,1,233.58,234.09,505,27,2,1,233.53,234.13,10,400,1,1,233.45,234.17,15,1,1,1,233.4,234.25,110,50,2,1,233.39,234.41,10,600,1,2,233.31,234.43,110,5,2,1,AAPL,-617,-8.320269700800674,0.1074009659613185
2024-10-21T12:08:37.210727255Z,2024-10-21T12:08:37.210561446Z,10,2,38,C,B,0,233.78,200,130,165809,12158736,233.72,233.94,28,94,1,1,233.7,233.98,1200,44,1,3,233.66,234.0,1,154,1,7,233.58,234.03,505,200,2,1,233.53,234.09,10,27,1,1,233.45,234.13,15,400,1,1,233.4,234.17,110,1,2,1,233.39,234.25,10,50,1,1,233.31,234.41,110,600,2,2,233.3,234.43,100,5,1,1,AAPL,-717,-9.837772397094431,0.12698942418343248
2024-10-21T12:08:37.210738801Z,2024-10-21T12:08:37.210572545Z,10,2,38,A,B,0,233.76,200,130,166256,12158737,233.76,233.94,200,94,1,1,233.72,233.98,28,44,1,3,233.7,234.0,1200,154,1,7,233.66,234.03,1,200,1,1,233.58,234.09,505,27,2,1,233.53,234.13,10,400,1,1,233.45,234.17,15,1,1,1,233.4,234.25,110,50,2,1,233.39,234.41,10,600,1,2,233.31,234.43,110,5,2,1,AAPL,-607,-8.427304280755882,0.10878260594317475
2024-10-21T12:08:37.269487007Z,2024-10-21T12:08:37.269320274Z,10,2,38,A,A,3,234.02,200,130,166733,12158910,233.76,233.94,200,94,1,1,233.72,233.98,28,44,1,3,233.7,234.0,1200,154,1,7,233.66,234.02,1,200,1,1,233.58,234.09,505,27,2,1,233.53,234.13,10,400,1,1,233.45,234.17,15,1,1,1,233.4,234.25,110,50,2,1,233.39,234.41,10,600,1,2,233.31,234.43,110,5,2,1,AAPL,-607,-8.517725258493353,0.10994979170774638
2024-10-21T12:08:37.923028889Z,2024-10-21T12:08:37.922862859Z,10,2,38,C,A,4,234.09,27,130,166030,12159796,233.76,233.94,200,94,1,1,233.72,233.98,28,44,1,3,233.7,234.0,1200,154,1,7,233.66,234.02,1,200,1,1,233.58,234.13,505,400,2,1,233.53,234.17,10,1,1,1,233.45,234.25,15,50,1,1,233.4,234.41,110,600,2,2,233.39,234.43,10,5,1,1,233.31,234.5,110,63,2,4,AAPL,-544,-7.5529330093717455,0.09749591422133723
2024-10-21T12:08:37.923113415Z,2024-10-21T12:08:37.922947266Z,10,2,38,A,A,4,234.07,29,130,166149,12159797,233.76,233.94,200,94,1,1,233.72,233.98,28,44,1,3,233.7,234.0,1200,154,1,7,233.66,234.02,1,200,1,1,233.58,234.07,505,29,2,1,233.53,234.13,10,400,1,1,233.45,234.17,15,1,1,1,233.4,234.25,110,50,2,1,233.39,234.41,10,600,1,2,233.31,234.43,110,5,2,1,AAPL,-549,-7.696261682242991,0.09934605111231375
2024-10-21T12:08:38.864240686Z,2024-10-21T12:08:38.864074729Z,10,2,38,A,A,0,233.93,100,130,165957,12160370,233.76,233.93,200,100,1,1,233.72,233.94,28,94,1,1,233.7,233.98,1200,44,1,3,233.66,234.0,1,154,1,7,233.58,234.02,505,200,2,1,233.53,234.07,10,29,1,1,233.45,234.13,15,400,1,1,233.4,234.17,110,1,2,1,233.39,234.25,10,50,1,1,233.31,234.41,110,600,2,2,AAPL,-1149,-13.641662169454937,0.17609137047281584
2024-10-21T12:08:38.864263169Z,2024-10-21T12:08:38.864096354Z,10,2,38,C,B,0,233.76,200,130,166815,12160371,233.72,233.93,28,100,1,1,233.7,233.94,1200,94,1,1,233.66,233.98,1,44,1,3,233.58,234.0,505,154,2,7,233.53,234.02,10,200,1,1,233.45,234.07,15,29,1,1,233.4,234.13,110,400,2,1,233.39,234.17,10,1,1,1,233.31,234.25,110,50,2,1,233.3,234.41,100,600,1,2,AAPL,-1249,-13.039945528824331,0.16832420056575045
2024-10-21T12:08:38.864605497Z,2024-10-21T12:08:38.864439490Z,10,2,38,C,A,0,233.93,100,130,166007,12160377,233.72,233.94,28,94,1,1,233.7,233.98,1200,44,1,3,233.66,234.0,1,154,1,7,233.58,234.02,505,200,2,1,233.53,234.07,10,29,1,1,233.45,234.13,15,400,1,1,233.4,234.17,110,1,2,1,233.39,234.25,10,50,1,1,233.31,234.41,110,600,2,2,233.3,234.43,100,5,1,1,AAPL,-1244,-13.236976280203946,0.17086754276296537
2024-10-21T12:08:38.972616790Z,2024-10-21T12:08:38.972450149Z,10,2,38,A,B,0,233.74,200,130,166641,12160439,233.74,233.94,200,94,1,1,233.72,233.98,28,44,1,3,233.7,234.0,1200,154,1,7,233.66,234.02,1,200,1,1,233.58,234.07,505,29,2,1,233.53,234.13,10,400,1,1,233.45,234.17,15,1,1,1,233.4,234.25,110,50,2,1,233.39,234.41,10,600,1,2,233.31,234.43,110,5,2,1,AAPL,-1134,-12.256809338521402,0.15821520334061154
2024-10-21T12:08:38.985975726Z,2024-10-21T12:08:38.985809168Z,10,2,38,A,A,2,234.0,200,130,166558,12160448,233.74,233.94,200,94,1,1,233.72,233.98,28,44,1,3,233.7,234.0,1200,354,1,8,233.66,234.07,1,29,1,1,233.58,234.13,505,400,2,1,233.53,234.17,10,1,1,1,233.45,234.25,15,50,1,1,233.4,234.41,110,600,2,2,233.39,234.43,10,5,1,1,233.31,234.5,110,63,2,4,AAPL,-1071,-11.604917691185664,0.14980035680994727
2024-10-21T12:08:39.005029517Z,2024-10-21T12:08:39.004863316Z,10,2,38,C,A,2,234.0,200,130,166201,12160461,233.74,233.94,200,94,1,1,233.72,233.98,28,44,1,3,233.7,234.0,1200,154,1,7,233.66,234.07,1,29,1,1,233.58,234.13,505,400,2,1,233.53,234.17,10,1,1,1,233.45,234.25,15,50,1,1,233.4,234.41,110,600,2,2,233.39,234.43,10,5,1,1,233.31,234.5,110,63,2,4,AAPL,-1071,-11.631938857602574,0.15014915552428443
2024-10-21T12:08:39.005042528Z,2024-10-21T12:08:39.004876187Z,10,2,38,A,A,3,234.02,200,130,166341,12160462,233.74,233.94,200,94,1,1,233.72,233.98,28,44,1,3,233.7,234.0,1200,154,1,7,233.66,234.02,1,200,1,1,233.58,234.07,505,29,2,1,233.53,234.13,10,400,1,1,233.45,234.17,15,1,1,1,233.4,234.25,110,50,2,1,233.39,234.41,10,600,1,2,233.31,234.43,110,5,2,1,AAPL,-1076,-11.845095341065461,0.15290065433959674
2024-10-21T12:08:39.005488223Z,2024-10-21T12:08:39.005322111Z,10,2,38,A,B,0,233.75,29,130,166112,12160463,233.75,233.94,29,94,1,1,233.74,233.98,200,44,1,3,233.72,234.0,28,154,1,7,233.7,234.02,1200,200,1,1,233.66,234.07,1,29,1,1,233.58,234.13,505,400,2,1,233.53,234.17,10,1,1,1,233.45,234.25,15,50,1,1,233.4,234.41,110,600,2,2,233.39,234.43,10,5,1,1,AAPL,-1066,-12.118384947079576,0.15642837263823312
2024-10-21T12:08:39.005516016Z,2024-10-21T12:08:39.005350151Z,10,2,38,C,B,2,233.72,28,130,165865,12160464,233.75,233.94,29,94,1,1,233.74,233.98,200,44,1,3,233.7,234.0,1200,154,1,7,233.66,234.02,1,200,1,1,233.58,234.07,505,29,2,1,233.53,234.13,10,400,1,1,233.45,234.17,15,1,1,1,233.4,234.25,110,50,2,1,233.39,234.41,10,600,1,2,233.31,234.43,110,5,2,1,AAPL,-1176,-13.525014376078206,0.17458563975296768
2024-10-21T12:08:39.007865569Z,2024-10-21T12:08:39.007699591Z,10,2,38,C,A,3,234.02,200,130,165978,12160465,233.75,233.94,29,94,1,1,233.74,233.98,200,44,1,3,233.7,234.0,1200,154,1,7,233.66,234.07,1,29,1,1,233.58,234.13,505,400,2,1,233.53,234.17,10,1,1,1,233.45,234.25,15,50,1,1,233.4,234.41,110,600,2,2,233.39,234.43,10,5,1,1,233.31,234.5,110,63,2,4,AAPL,-1113,-12.802597402597403,0.16526042752201994
2024-10-21T12:08:39.007878744Z,2024-10-21T12:08:39.007712438Z,10,2,38,A,A,3,234.06,400,130,166306,12160466,233.75,233.94,29,94,1,1,233.74,233.98,200,44,1,3,233.7,234.0,1200,154,1,7,233.66,234.06,1,400,1,1,233.58,234.07,505,29,2,1,233.53,234.13,10,400,1,1,233.45,234.17,15,1,1,1,233.4,234.25,110,50,2,1,233.39,234.41,10,600,1,2,233.31,234.43,110,5,2,1,AAPL,-1118,-12.99763851044505,0.1677780867011433
2024-10-21T12:08:39.069902920Z,2024-10-21T12:08:39.069736562Z,10,2,38,A,B,0,233.75,200,130,166358,12160501,233.75,233.94,229,94,2,1,233.7,233.98,1200,44,1,3,233.66,234.0,1,154,1,7,233.58,234.06,505,400,2,1,233.53,234.07,10,29,1,1,233.45,234.13,15,400,1,1,233.4,234.17,110,1,2,1,233.39,234.25,10,50,1,1,233.31,234.41,110,600,2,2,233.3,234.43,100,5,1,1,AAPL,-1218,-14.329411764705883,0.18496908399962006
2024-10-21T12:08:39.162940859Z,2024-10-21T12:08:39.162773976Z,10,2,38,A,B,0,233.76,200,130,166883,12160573,233.76,233.94,200,94,1,1,233.75,233.98,29,44,1,3,233.7,234.0,1200,154,1,7,233.66,234.06,1,400,1,1,233.58,234.07,505,29,2,1,233.53,234.13,10,400,1,1,233.45,234.17,15,1,1,1,233.4,234.25,110,50,2,1,233.39,234.41,10,600,1,2,233.31,234.43,110,5,2,1,AAPL,-1108,-13.16052401746725,0.1698806700817758
2024-10-21T12:08:41.638694239Z,2024-10-21T12:08:41.638527966Z,10,2,38,A,B,0,233.77,200,130,166273,12161762,233.77,233.94,200,94,1,1,233.75,233.98,29,44,1,3,233.7,234.0,1200,154,1,7,233.66,234.06,1,400,1,1,233.58,234.07,505,29,2,1,233.53,234.13,10,400,1,1,233.45,234.17,15,1,1,1,233.4,234.25,110,50,2,1,233.39,234.41,10,600,1,2,233.31,234.43,110,5,2,1,AAPL,-1108,-13.280821917808218,0.17143351766536974
2024-10-21T12:08:41.645478168Z,2024-10-21T12:08:41.645312053Z,10,2,38,A,B,1,233.76,28,130,166115,12161778,233.77,233.94,200,94,1,1,233.76,233.98,28,44,1,3,233.75,234.0,29,154,1,7,233.7,234.06,1200,400,1,1,233.66,234.07,1,29,1,1,233.58,234.13,505,400,2,1,233.53,234.17,10,1,1,1,233.45,234.25,15,50,1,1,233.4,234.41,110,600,2,2,233.39,234.43,10,5,1,1,AAPL,-1098,-13.502305721605465,0.17429250845869973
2024-10-21T12:08:41.701463079Z,2024-10-21T12:08:41.701297052Z,10,2,38,C,B,1,233.76,28,130,166027,12161796,233.77,233.94,200,94,1,1,233.75,233.98,29,44,1,3,233.7,234.0,1200,154,1,7,233.66,234.06,1,400,1,1,233.58,234.07,505,29,2,1,233.53,234.13,10,400,1,1,233.45,234.17,15,1,1,1,233.4,234.25,110,50,2,1,233.39,234.41,10,600,1,2,233.31,234.43,110,5,2,1,AAPL,-1208,-14.973534338358458,0.19328364459626993
2024-10-21T12:08:41.701486252Z,2024-10-21T12:08:41.701320255Z,10,2,38,C,B,1,233.75,29,130,165997,12161797,233.77,233.94,200,94,1,1,233.7,233.98,1200,44,1,3,233.66,234.0,1,154,1,7,233.58,234.06,505,400,2,1,233.53,234.07,10,29,1,1,233.45,234.13,15,400,1,1,233.4,234.17,110,1,2,1,233.39,234.25,10,50,1,1,233.31,234.41,110,600,2,2,233.3,234.43,100,5,1,1,AAPL,-1308,-16.363456790123454,0.21122525217619237
2024-10-21T12:08:41.701557283Z,2024-10-21T12:08:41.701391064Z,10,2,38,A,B,1,233.76,30,130,166219,12161798,233.77,233.94,200,94,1,1,233.76,233.98,30,44,1,3,233.7,234.0,1200,154,1,7,233.66,234.06,1,400,1,1,233.58,234.07,505,29,2,1,233.53,234.13,10,400,1,1,233.45,234.17,15,1,1,1,233.4,234.25,110,50,2,1,233.39,234.41,10,600,1,2,233.31,234.43,110,5,2,1,AAPL,-1198,-15.095961227786752,0.1948639739193654
2024-10-21T12:08:44.045945399Z,2024-10-21T12:08:44.045776235Z,10,2,38,T,B,0,233.94,94,0,169164,12162738,233.77,233.94,200,94,1,1,233.76,233.98,30,44,1,3,233.7,234.0,1200,154,1,7,233.66,234.06,1,400,1,1,233.58,234.07,505,29,2,1,233.53,234.13,10,400,1,1,233.45,234.17,15,1,1,1,233.4,234.25,110,50,2,1,233.39,234.41,10,600,1,2,233.31,234.43,110,5,2,1,AAPL,-1218,-14.827826086956522,0.19140279126917203
2024-10-21T12:08:44.045945399Z,2024-10-21T12:08:44.045776717Z,10,2,38,T,N,0,233.94,94,130,168682,12162739,233.77,233.98,200,44,1,3,233.76,234.0,30,154,1,7,233.7,234.06,1200,400,1,1,233.66,234.07,1,29,1,1,233.58,234.13,505,400,2,1,233.53,234.17,10,1,1,1,233.45,234.25,15,50,1,1,233.4,234.41,110,600,2,2,233.39,234.43,10,5,1,1,233.31,234.5,110,63,2,4,AAPL,-1155,-14.040182340030391,0.18123560891868667
2024-10-21T12:08:44.045968264Z,2024-10-21T12:08:44.045799937Z,10,2,38,A,B,0,233.86,100,130,168327,12162740,233.86,233.98,100,44,1,3,233.77,234.0,200,154,1,7,233.76,234.06,30,400,1,1,233.7,234.07,1200,29,1,1,233.66,234.13,1,400,1,1,233.58,234.17,505,1,2,1,233.53,234.25,10,50,1,1,233.45,234.41,15,600,1,2,233.4,234.43,110,5,2,1,233.39,234.5,10,63,1,4,AAPL,-1145,-14.131087391594395,0.18240904327836832
2024-10-21T12:08:44.045981222Z,2024-10-21T12:08:44.045814276Z,10,2,38,A,B,1,233.81,100,130,166946,12162742,233.86,233.98,100,44,1,3,233.81,234.0,100,154,1,7,233.77,234.06,200,400,1,1,233.76,234.07,30,29,1,1,233.7,234.13,1200,400,1,1,233.66,234.17,1,1,1,1,233.58,234.25,505,50,2,1,233.53,234.41,10,600,1,2,233.45,234.43,15,5,1,1,233.4,234.5,110,63,2,4,AAPL,-1035,-12.75085102934025,0.16459246714661546
2024-10-21T12:08:44.045992597Z,2024-10-21T12:08:44.045826034Z,10,2,38,C,B,0,233.86,100,130,166563,12162744,233.85,233.98,57,44,1,3,233.81,234.0,100,154,1,7,233.77,234.06,200,400,1,1,233.76,234.07,30,29,1,1,233.7,234.13,1200,400,1,1,233.66,234.17,1,1,1,1,233.58,234.25,505,50,2,1,233.53,234.41,10,600,1,2,233.45,234.43,15,5,1,1,233.4,234.5,110,63,2,4,AAPL,-1035,-12.72942289498581,0.164315865256151
2024-10-21T12:08:44.046005890Z,2024-10-21T12:08:44.045839714Z,10,2,38,A,B,1,233.8,57,130,166176,12162746,233.85,233.98,57,44,1,3,233.8,234.0,57,154,1,7,233.77,234.06,200,400,1,1,233.76,234.07,30,29,1,1,233.7,234.13,1200,400,1,1,233.66,234.17,1,1,1,1,233.58,234.25,505,50,2,1,233.53,234.41,10,600,1,2,233.45,234.43,15,5,1,1,233.4,234.5,110,63,2,4,AAPL,-1035,-12.709132770529548,0.1640539531974748
2024-10-21T12:08:44.046241847Z,2024-10-21T12:08:44.046075488Z,10,2,38,A,B,0,233.88,100,130,166359,12162751,233.88,233.98,100,44,1,3,233.85,234.0,57,154,1,7,233.8,234.06,57,400,1,1,233.77,234.07,200,29,1,1,233.76,234.13,30,400,1,1,233.7,234.17,1200,1,1,1,233.66,234.25,1,50,1,1,233.58,234.41,505,600,2,2,233.53,234.43,10,5,1,1,233.45,234.5,15,63,1,4,AAPL,-1020,-12.686182314576065,0.16375770064469763
2024-10-21T12:08:44.046743441Z,2024-10-21T12:08:44.046577511Z,10,2,38,C,B,0,233.88,100,130,165930,12162753,233.85,233.98,57,44,1,3,233.8,234.0,57,154,1,7,233.77,234.06,200,400,1,1,233.76,234.07,30,29,1,1,233.7,234.13,1200,400,1,1,233.66,234.17,1,1,1,1,233.58,234.25,505,50,2,1,233.53,234.41,10,600,1,2,233.45,234.43,15,5,1,1,233.4,234.5,110,63,2,4,AAPL,-1130,-14.028968371268105,0.18109085506807368
2024-10-21T12:08:44.062866261Z,2024-10-21T12:08:44.062697315Z,10,2,38,T,N,0,233.94,44,130,168946,12162795,233.85,233.98,57,44,1,3,233.8,234.0,57,154,1,7,233.77,234.06,200,400,1,1,233.76,234.07,30,29,1,1,233.7,234.13,1200,400,1,1,233.66,234.17,1,1,1,1,233.58,234.25,505,50,2,1,233.53,234.41,10,600,1,2,233.45,234.43,15,5,1,1,233.4,234.5,110,63,2,4,AAPL,-1130,-14.004899841475718,0.18078017002516905
2024-10-21T12:08:44.062883209Z,2024-10-21T12:08:44.062714891Z,10,2,38,T,N,0,233.94,27,0,168318,12162796,233.85,233.98,57,44,1,3,233.8,234.0,57,154,1,7,233.77,234.06,200,400,1,1,233.76,234.07,30,29,1,1,233.7,234.13,1200,400,1,1,233.66,234.17,1,1,1,1,233.58,234.25,505,50,2,1,233.53,234.41,10,600,1,2,233.45,234.43,15,5,1,1,233.4,234.5,110,63,2,4,AAPL,-1130,-13.982002249718786,0.18048459986202328
2024-10-21T12:08:44.062883209Z,2024-10-21T12:08:44.062714891Z,10,2,38,T,N,0,233.95,17,130,168318,12162797,233.85,233.98,57,44,1,3,233.8,234.0,57,154,1,7,233.77,234.06,200,400,1,1,233.76,234.07,30,29,1,1,233.7,234.13,1200,400,1,1,233.66,234.17,1,1,1,1,233.58,234.25,505,50,2,1,233.53,234.41,10,600,1,2,233.45,234.43,15,5,1,1,233.4,234.5,110,63,2,4,AAPL,-1130,-13.9601921757035,0.1802030677601608
2024-10-21T12:08:44.071158229Z,2024-10-21T12:08:44.070991133Z,10,2,38,T,N,0,233.95,37,130,167096,12162801,233.85,233.98,57,44,1,3,233.8,234.0,57,154,1,7,233.77,234.06,200,400,1,1,233.76,234.07,30,29,1,1,233.7,234.13,1200,400,1,1,233.66,234.17,1,1,1,1,233.58,234.25,505,50,2,1,233.53,234.41,10,600,1,2,233.45,234.43,15,5,1,1,233.4,234.5,110,63,2,4,AAPL,-1130,-13.93939393939394,0.17993459681507545
2024-10-21T12:08:44.071167823Z,2024-10-21T12:08:44.071001755Z,10,2,38,A,B,0,233.89,100,130,166068,12162802,233.89,233.98,100,44,1,3,233.85,234.0,57,154,1,7,233.8,234.06,57,400,1,1,233.77,234.07,200,29,1,1,233.76,234.13,30,400,1,1,233.7,234.17,1200,1,1,1,233.66,234.25,1,50,1,1,233.58,234.41,505,600,2,2,233.53,234.43,10,5,1,1,233.45,234.5,15,63,1,4,AAPL,-1115,-13.907908704883228,0.17952817434061605
2024-10-21T12:08:44.071413124Z,2024-10-21T12:08:44.071247115Z,10,2,38,C,B,0,233.89,100,130,166009,12162803,233.85,233.98,57,44,1,3,233.8,234.0,57,154,1,7,233.77,234.06,200,400,1,1,233.76,234.07,30,29,1,1,233.7,234.13,1200,400,1,1,233.66,234.17,1,1,1,1,233.58,234.25,505,50,2,1,233.53,234.41,10,600,1,2,233.45,234.43,15,5,1,1,233.4,234.5,110,63,2,4,AAPL,-1225,-15.25489687378389,0.19691557110546817
2024-10-21T12:08:44.078888724Z,2024-10-21T12:08:44.078717275Z,10,2,38,T,N,0,233.95,46,0,171449,12162804,233.85,233.98,57,44,1,3,233.8,234.0,57,154,1,7,233.77,234.06,200,400,1,1,233.76,234.07,30,29,1,1,233.7,234.13,1200,400,1,1,233.66,234.17,1,1,1,1,233.58,234.25,505,50,2,1,233.53,234.41,10,600,1,2,233.45,234.43,15,5,1,1,233.4,234.5,110,63,2,4,AAPL,-1225,-15.230905861456483,0.19660588668524975
2024-10-21T12:08:44.078888724Z,2024-10-21T12:08:44.078717275Z,10,2,38,T,N,0,233.96,10,0,171449,12162805,233.85,233.98,57,44,1,3,233.8,234.0,57,154,1,7,233.77,234.06,200,400,1,1,233.76,234.07,30,29,1,1,233.7,234.13,1200,400,1,1,233.66,234.17,1,1,1,1,233.58,234.25,505,50,2,1,233.53,234.41,10,600,1,2,233.45,234.43,15,5,1,1,233.4,234.5,110,63,2,4,AAPL,-1225,-15.207945375543142,0.19630950466222508
2024-10-21T12:08:44.078888724Z,2024-10-21T12:08:44.078717275Z,10,2,38,T,B,0,233.98,4,0,171449,12162806,233.85,233.98,57,44,1,3,233.8,234.0,57,154,1,7,233.77,234.06,200,400,1,1,233.76,234.07,30,29,1,1,233.7,234.13,1200,400,1,1,233.66,234.17,1,1,1,1,233.58,234.25,505,50,2,1,233.53,234.41,10,600,1,2,233.45,234.43,15,5,1,1,233.4,234.5,110,63,2,4,AAPL,-1225,-15.18595041322314,0.19602558595713504
2024-10-21T12:08:44.078888724Z,2024-10-21T12:08:44.078717275Z,10,2,38,T,B,0,233.98,9,0,171449,12162807,233.85,233.98,57,40,1,2,233.8,234.0,57,154,1,7,233.77,234.06,200,400,1,1,233.76,234.07,30,29,1,1,233.7,234.13,1200,400,1,1,233.66,234.17,1,1,1,1,233.58,234.25,505,50,2,1,233.53,234.41,10,600,1,2,233.45,234.43,15,5,1,1,233.4,234.5,110,63,2,4,AAPL,-1225,-15.164861326032614,0.19575336060664109
2024-10-21T12:08:44.078888724Z,2024-10-21T12:08:44.078717275Z,10,2,38,T,B,0,233.98,31,130,171449,12162808,233.85,233.98,57,31,1,1,233.8,234.0,57,154,1,7,233.77,234.06,200,400,1,1,233.76,234.07,30,29,1,1,233.7,234.13,1200,400,1,1,233.66,234.17,1,1,1,1,233.58,234.25,505,50,2,1,233.53,234.41,10,600,1,2,233.45,234.43,15,5,1,1,233.4,234.5,110,63,2,4,AAPL,-1225,-15.144623279682762,0.19549212079046843
2024-10-21T12:08:44.078888724Z,2024-10-21T12:08:44.078717275Z,10,2,38,C,A,0,233.98,31,130,171449,12162808,233.85,234.0,57,154,1,7,233.8,234.06,57,400,1,1,233.77,234.07,200,29,1,1,233.76,234.13,30,400,1,1,233.7,234.17,1200,1,1,1,233.66,234.25,1,50,1,1,233.58,234.41,505,600,2,2,233.53,234.43,10,5,1,1,233.45,234.5,15,63,1,4,233.4,234.75,110,1,2,1,AAPL,-1224,-15.220725388601036,0.19647447356308703
2024-10-21T12:08:44.078913355Z,2024-10-21T12:08:44.078746374Z,10,2,38,A,B,0,233.92,100,130,166981,12162809,233.92,234.0,100,154,1,7,233.85,234.06,57,400,1,1,233.8,234.07,57,29,1,1,233.77,234.13,200,400,1,1,233.76,234.17,30,1,1,1,233.7,234.25,1200,50,1,1,233.66,234.41,1,600,1,2,233.58,234.43,505,5,2,1,233.53,234.5,10,63,1,4,233.45,234.75,15,1,1,1,AAPL,-1209,-15.284450063211127,0.1972970540628557
2024-10-21T12:08:44.078924745Z,2024-10-21T12:08:44.078758339Z,10,2,38,A,B,1,233.91,57,130,166406,12162811,233.92,234.0,100,154,1,7,233.91,234.06,57,400,1,1,233.88,234.07,100,29,1,1,233.85,234.13,57,400,1,1,233.8,234.17,57,1,1,1,233.77,234.25,200,50,1,1,233.76,234.41,30,600,1,2,233.7,234.43,1200,5,1,1,233.66,234.5,1,63,1,4,233.58,234.75,505,1,2,1,AAPL,-704,-8.563918757467144,0.11054607363000678
2024-10-21T12:08:44.078926114Z,2024-10-21T12:08:44.078760028Z,10,2,38,A,B,2,233.88,100,130,166086,12162812,233.92,234.0,100,154,1,7,233.91,234.06,57,400,1,1,233.88,234.07,200,29,2,1,233.85,234.13,57,400,1,1,233.8,234.17,57,1,1,1,233.77,234.25,200,50,1,1,233.76,234.41,30,600,1,2,233.7,234.43,1200,5,1,1,233.66,234.5,1,63,1,4,233.58,234.75,505,1,2,1,AAPL,-704,-8.262740656851642,0.10665836083995296
2024-10-21T12:08:44.078938721Z,2024-10-21T12:08:44.078772524Z,10,2,38,A,B,0,233.87,57,130,166197,12162814,233.91,234.0,57,154,1,7,233.88,234.06,200,400,2,1,233.87,234.07,57,29,1,1,233.85,234.13,57,400,1,1,233.8,234.17,57,1,1,1,233.77,234.25,200,50,1,1,233.76,234.41,30,600,1,2,233.7,234.43,1200,5,1,1,233.66,234.5,1,63,1,4,233.58,234.75,505,1,2,1,AAPL,-704,-7.991388589881594,0.10315565297636302
2024-10-21T12:08:44.078950012Z,2024-10-21T12:08:44.078783923Z,10,2,38,C,B,1,233.88,100,130,166089,12162816,233.91,234.0,57,154,1,7,233.87,234.06,57,400,1,1,233.85,234.07,57,29,1,1,233.8,234.13,57,400,1,1,233.77,234.17,200,1,1,1,233.76,234.25,30,50,1,1,233.7,234.41,1200,600,1,2,233.66,234.43,1,5,1,1,233.58,234.5,505,63,2,4,233.53,234.75,10,1,1,1,AAPL,-714,-8.235777126099707,0.10631030610703884
2024-10-21T12:08:44.115378536Z,2024-10-21T12:08:44.115212449Z,10,2,38,C,A,2,234.07,29,130,166087,12162846,233.91,234.0,57,154,1,7,233.87,234.06,57,400,1,1,233.85,234.13,57,400,1,1,233.8,234.17,57,1,1,1,233.77,234.25,200,50,1,1,233.76,234.41,30,600,1,2,233.7,234.43,1200,5,1,1,233.66,234.5,1,63,1,4,233.58,234.75,505,1,2,1,233.53,234.79,10,2000,1,1,AAPL,1286,12.607843137254902,-0.16274647100678116
2024-10-21T12:08:44.115433457Z,2024-10-21T12:08:44.115267046Z,10,2,38,A,A,2,234.13,29,130,166411,12162847,233.91,234.0,57,154,1,7,233.87,234.06,57,400,1,1,233.85,234.13,57,429,1,2,233.8,234.17,57,1,1,1,233.77,234.25,200,50,1,1,233.76,234.41,30,600,1,2,233.7,234.43,1200,5,1,1,233.66,234.5,1,63,1,4,233.58,234.75,505,1,2,1,233.53,234.79,10,2000,1,1,AAPL,1286,11.009964912280703,-0.14212049720760597
2024-10-21T12:08:44.149362032Z,2024-10-21T12:08:44.149196088Z,10,2,38,C,B,3,233.8,57,130,165944,12162860,233.91,234.0,57,154,1,7,233.87,234.06,57,400,1,1,233.85,234.13,57,429,1,2,233.77,234.17,200,1,1,1,233.76,234.25,30,50,1,1,233.7,234.41,1200,600,1,2,233.66,234.43,1,5,1,1,233.58,234.5,505,63,2,4,233.53,234.75,10,1,1,1,233.45,234.79,15,2000,1,1,AAPL,1271,9.689763295419613,-0.12507887067223888
2024-10-21T12:08:44.179575366Z,2024-10-21T12:08:44.179409160Z,10,2,38,C,B,1,233.87,57,130,166206,12162872,233.91,234.0,57,154,1,7,233.85,234.06,57,400,1,1,233.77,234.13,200,429,1,2,233.76,234.17,30,1,1,1,233.7,234.25,1200,50,1,1,233.66,234.41,1,600,1,2,233.58,234.43,505,5,2,1,233.53,234.5,10,63,1,4,233.45,234.75,15,1,1,1,233.4,234.79,110,2000,2,1,AAPL,1161,7.961142857142857,-0.10276523042647431
2024-10-21T12:08:44.303932890Z,2024-10-21T12:08:44.303766562Z,10,2,38,C,B,1,233.85,57,130,166328,12162939,233.91,234.0,57,154,1,7,233.77,234.06,200,400,1,1,233.76,234.13,30,429,1,2,233.7,234.17,1200,1,1,1,233.66,234.25,1,50,1,1,233.58,234.41,505,600,2,2,233.53,234.43,10,5,1,1,233.45,234.5,15,63,1,4,233.4,234.75,110,1,2,1,233.39,234.79,10,2000,1,1,AAPL,1151,7.227274957076282,-0.0932922056100348
2024-10-21T12:08:44.333929473Z,2024-10-21T12:08:44.333763421Z,10,2,38,C,B,0,233.91,57,130,166052,12162944,233.77,234.0,200,154,1,7,233.76,234.06,30,400,1,1,233.7,234.13,1200,429,1,2,233.66,234.17,1,1,1,1,233.58,234.25,505,50,2,1,233.53,234.41,10,600,1,2,233.45,234.43,15,5,1,1,233.4,234.5,110,63,2,4,233.39,234.75,10,1,1,1,233.31,234.79,110,2000,2,1,AAPL,1041,6.016003556345854,-0.07765668859461303
2024-10-21T12:08:45.555160782Z,2024-10-21T12:08:45.554994588Z,10,2,38,A,A,6,234.43,100,130,166194,12163887,233.77,234.0,200,154,1,7,233.76,234.06,30,400,1,1,233.7,234.13,1200,429,1,2,233.66,234.17,1,1,1,1,233.58,234.25,505,50,2,1,233.53,234.41,10,600,1,2,233.45,234.43,15,105,1,2,233.4,234.5,110,63,2,4,233.39,234.75,10,1,1,1,233.31,234.79,110,2000,2,1,AAPL,1041,5.584718553139606,-0.07208951017195639
2024-10-21T12:08:46.627106793Z,2024-10-21T12:08:46.626940215Z,10,2,38,A,B,0,233.9,1,130,166578,12164437,233.9,234.0,1,154,1,7,233.77,234.06,200,400,1,1,233.76,234.13,30,429,1,2,233.7,234.17,1200,1,1,1,233.66,234.25,1,50,1,1,233.58,234.41,505,600,2,2,233.53,234.43,10,105,1,2,233.45,234.5,15,63,1,4,233.4,234.75,110,1,2,1,233.39,234.79,10,2000,1,1,AAPL,1051,5.2351698113207545,-0.06757741214245436
2024-10-21T12:08:56.736557653Z,2024-10-21T12:08:56.736391728Z,10,2,38,C,B,0,233.9,1,130,165925,12171166,233.77,234.0,200,154,1,7,233.76,234.06,30,400,1,1,233.7,234.13,1200,429,1,2,233.66,234.17,1,1,1,1,233.58,234.25,505,50,2,1,233.53,234.41,10,600,1,2,233.45,234.43,15,105,1,2,233.4,234.5,110,63,2,4,233.39,234.75,10,1,1,1,233.31,234.79,110,2000,2,1,AAPL,941,4.407340090877316,-0.05689149512001004
2024-10-21T12:09:01.138408018Z,2024-10-21T12:09:01.138241817Z,10,2,38,C,B,0,233.77,200,130,166201,12174514,233.76,234.0,30,154,1,7,233.7,234.06,1200,400,1,1,233.66,234.13,1,429,1,2,233.58,234.17,505,1,2,1,233.53,234.25,10,50,1,1,233.45,234.41,15,600,1,2,233.4,234.43,110,105,2,2,233.39,234.5,10,63,1,4,233.31,234.75,110,1,2,1,233.3,234.79,100,2000,1,1,AAPL,1969,6.139933736113818,-0.07925642291783555
2024-10-21T12:09:01.138421298Z,2024-10-21T12:09:01.138255251Z,10,2,38,A,B,1,233.73,200,130,166047,12174515,233.76,234.0,30,154,1,7,233.73,234.06,200,400,1,1,233.7,234.13,1200,429,1,2,233.66,234.17,1,1,1,1,233.58,234.25,505,50,2,1,233.53,234.41,10,600,1,2,233.45,234.43,15,105,1,2,233.4,234.5,110,63,2,4,233.39,234.75,10,1,1,1,233.31,234.79,110,2000,2,1,AAPL,2079,6.140032414910858,-0.0792576966984344
2024-10-21T12:09:01.157563262Z,2024-10-21T12:09:01.157397025Z,10,2,38,A,B,2,233.7,30,130,166237,12174545,233.76,234.0,30,154,1,7,233.73,234.06,200,400,1,1,233.7,234.13,1230,429,2,2,233.66,234.17,1,1,1,1,233.58,234.25,505,50,2,1,233.53,234.41,10,600,1,2,233.45,234.43,15,105,1,2,233.4,234.5,110,63,2,4,233.39,234.75,10,1,1,1,233.31,234.79,110,2000,2,1,AAPL,2079,5.845556485355648,-0.0754564978883113
2024-10-21T12:09:01.157592129Z,2024-10-21T12:09:01.157426276Z,10,2,38,C,B,0,233.76,30,130,165853,12174546,233.73,234.0,200,154,1,7,233.7,234.06,1230,400,2,1,233.66,234.13,1,429,1,2,233.58,234.17,505,1,2,1,233.53,234.25,10,50,1,1,233.45,234.41,15,600,1,2,233.4,234.43,110,105,2,2,233.39,234.5,10,63,1,4,233.31,234.75,110,1,2,1,233.3,234.79,100,2000,1,1,AAPL,1979,5.322720875684128,-0.06870755205638804
2024-10-21T12:09:02.549604073Z,2024-10-21T12:09:02.549437699Z,10,2,38,A,A,1,234.05,400,130,166374,12175916,233.73,234.0,200,154,1,7,233.7,234.05,1230,400,2,1,233.66,234.13,1,429,1,2,233.58,234.17,505,1,2,1,233.53,234.25,10,50,1,1,233.45,234.41,15,600,1,2,233.4,234.43,110,105,2,2,233.39,234.5,10,63,1,4,233.31,234.75,110,1,2,1,233.3,234.79,100,2000,1,1,AAPL,2069,4.8016066646831295,-0.06198082664359383
2024-10-21T12:09:02.576676374Z,2024-10-21T12:09:02.576510264Z,10,2,38,C,A,2,234.13,29,130,166110,12176238,233.73,234.0,200,154,1,7,233.7,234.05,1230,400,2,1,233.66,234.13,1,400,1,1,233.58,234.17,505,1,2,1,233.53,234.25,10,50,1,1,233.45,234.41,15,600,1,2,233.4,234.43,110,105,2,2,233.39,234.5,10,63,1,4,233.31,234.75,110,1,2,1,233.3,234.79,100,2000,1,1,AAPL,2069,4.635116213945674,-0.05983170938230873
2024-10-21T12:09:02.576729551Z,2024-10-21T12:09:02.576563332Z,10,2,38,A,A,2,234.12,29,130,166219,12176242,233.73,234.0,200,154,1,7,233.7,234.05,1230,400,2,1,233.66,234.12,1,29,1,1,233.58,234.13,505,400,2,1,233.53,234.17,10,1,1,1,233.45,234.25,15,50,1,1,233.4,234.41,110,600,2,2,233.39,234.43,10,105,1,2,233.31,234.5,110,63,2,4,233.3,234.75,100,1,1,1,AAPL,2068,4.735304794616179,-0.061124978798956404
2024-10-21T12:09:04.139010031Z,2024-10-21T12:09:04.138843955Z,10,2,38,C,B,1,233.7,30,130,166076,12177517,233.73,234.0,200,154,1,7,233.7,234.05,1200,400,1,1,233.66,234.12,1,29,1,1,233.58,234.13,505,400,2,1,233.53,234.17,10,1,1,1,233.45,234.25,15,50,1,1,233.4,234.41,110,600,2,2,233.39,234.43,10,105,1,2,233.31,234.5,110,63,2,4,233.3,234.75,100,1,1,1,AAPL,-436,-0.4791735355533575,0.006185340431522111
2024-10-21T12:09:04.139060689Z,2024-10-21T12:09:04.138894379Z,10,2,38,A,B,0,233.75,30,130,166310,12177518,233.75,234.0,30,154,1,7,233.73,234.05,200,400,1,1,233.7,234.12,1200,29,1,1,233.66,234.13,1,400,1,1,233.58,234.17,505,1,2,1,233.53,234.25,10,50,1,1,233.45,234.41,15,600,1,2,233.4,234.43,110,105,2,2,233.39,234.5,10,63,1,4,233.31,234.75,110,1,2,1,AAPL,-326,-0.38061879743140686,0.004913161228804238
2024-10-21T12:09:04.194772872Z,2024-10-21T12:09:04.194606283Z,10,2,38,A,B,0,233.81,200,130,166589,12177532,233.81,234.0,200,154,1,7,233.75,234.05,30,400,1,1,233.7,234.12,1200,29,1,1,233.66,234.13,1,400,1,1,233.58,234.17,505,1,2,1,233.53,234.25,10,50,1,1,233.45,234.41,15,600,1,2,233.4,234.43,110,105,2,2,233.39,234.5,10,63,1,4,233.31,234.75,110,1,2,1,AAPL,-201,-0.25775839958963837,0.0033272360267247885
2024-10-21T12:09:06.506770293Z,2024-10-21T12:09:06.506604143Z,10,2,38,C,B,1,233.75,30,130,166150,12179760,233.81,234.0,200,154,1,7,233.7,234.05,1200,400,1,1,233.66,234.12,1,29,1,1,233.58,234.13,505,400,2,1,233.53,234.17,10,1,1,1,233.45,234.25,15,50,1,1,233.4,234.41,110,600,2,2,233.39,234.43,10,105,1,2,233.31,234.5,110,63,2,4,233.3,234.75,100,1,1,1,AAPL,-181,-0.27257457283521574,0.0035184883990213413
2024-10-21T12:09:06.565190241Z,2024-10-21T12:09:06.565023952Z,10,2,38,A,B,1,233.76,30,130,166289,12179817,233.81,234.0,200,154,1,7,233.76,234.05,30,400,1,1,233.7,234.12,1200,29,1,1,233.66,234.13,1,400,1,1,233.58,234.17,505,1,2,1,233.53,234.25,10,50,1,1,233.45,234.41,15,600,1,2,233.4,234.43,110,105,2,2,233.39,234.5,10,63,1,4,233.31,234.75,110,1,2,1,AAPL,-71,-0.11441068139963168,0.001476853292079056
2024-10-21T12:09:06.773559043Z,2024-10-21T12:09:06.773392628Z,10,2,38,A,B,0,233.82,200,130,166415,12180059,233.82,234.0,200,154,1,7,233.76,234.05,30,400,1,1,233.7,234.12,1200,29,1,1,233.66,234.13,1,400,1,1,233.58,234.17,505,1,2,1,233.53,234.25,10,50,1,1,233.45,234.41,15,600,1,2,233.4,234.43,110,105,2,2,233.39,234.5,10,63,1,4,233.31,234.75,110,1,2,1,AAPL,-81,-0.14654002713704206,0.0018915901806646478
2024-10-21T12:09:10.542697180Z,2024-10-21T12:09:10.542530771Z,10,2,38,A,B,0,233.9,10,130,166409,12183116,233.9,234.0,10,154,1,7,233.82,234.05,200,400,1,1,233.76,234.12,30,29,1,1,233.7,234.13,1200,400,1,1,233.66,234.17,1,1,1,1,233.58,234.25,505,50,2,1,233.53,234.41,10,600,1,2,233.45,234.43,15,105,1,2,233.4,234.5,110,63,2,4,233.39,234.75,10,1,1,1,AAPL,-71,-0.137525826446281,0.0017752317095607898
2024-10-21T12:09:12.689323526Z,2024-10-21T12:09:12.689157352Z,10,2,38,C,A,1,234.05,400,130,166174,12184428,233.9,234.0,10,154,1,7,233.82,234.12,200,29,1,1,233.76,234.13,30,400,1,1,233.7,234.17,1200,1,1,1,233.66,234.25,1,50,1,1,233.58,234.41,505,600,2,2,233.53,234.43,10,105,1,2,233.45,234.5,15,63,1,4,233.4,234.75,110,1,2,1,233.39,234.79,10,2000,1,1,AAPL,1929,3.5277174534232483,-0.04553701691903078
2024-10-21T12:09:12.689337452Z,2024-10-21T12:09:12.689170703Z,10,2,38,A,A,1,234.06,200,130,166749,12184429,233.9,234.0,10,154,1,7,233.82,234.06,200,200,1,1,233.76,234.12,30,29,1,1,233.7,234.13,1200,400,1,1,233.66,234.17,1,1,1,1,233.58,234.25,505,50,2,1,233.53,234.41,10,600,1,2,233.45,234.43,15,105,1,2,233.4,234.5,110,63,2,4,233.39,234.75,10,1,1,1,AAPL,1928,3.7439031355302985,-0.04832761769523752
2024-10-21T12:09:12.782742680Z,2024-10-21T12:09:12.782576498Z,10,2,38,A,A,1,234.06,200,130,166182,12184538,233.9,234.0,10,154,1,7,233.82,234.06,200,400,1,2,233.76,234.12,30,29,1,1,233.7,234.13,1200,400,1,1,233.66,234.17,1,1,1,1,233.58,234.25,505,50,2,1,233.53,234.41,10,600,1,2,233.45,234.43,15,105,1,2,233.4,234.5,110,63,2,4,233.39,234.75,10,1,1,1,AAPL,1928,3.9616438356164383,-0.05113829119012371
2024-10-21T12:09:13.223660901Z,2024-10-21T12:09:13.223494596Z,10,2,38,A,B,1,233.83,200,130,166305,12185116,233.9,234.0,10,154,1,7,233.83,234.06,200,400,1,2,233.76,234.12,30,29,1,1,233.7,234.13,1200,400,1,1,233.66,234.17,1,1,1,1,233.58,234.25,505,50,2,1,233.53,234.41,10,600,1,2,233.45,234.43,15,105,1,2,233.4,234.5,110,63,2,4,233.39,234.75,10,1,1,1,AAPL,1928,4.179111288574525,-0.05394543751503172
2024-10-21T12:09:13.231090564Z,2024-10-21T12:09:13.230924474Z,10,2,38,C,B,2,233.76,30,130,166090,12185219,233.9,234.0,10,154,1,7,233.83,234.06,200,400,1,2,233.7,234.12,1200,29,1,1,233.66,234.13,1,400,1,1,233.58,234.17,505,1,2,1,233.53,234.25,10,50,1,1,233.45,234.41,15,600,1,2,233.4,234.43,110,105,2,2,233.39,234.5,10,63,1,4,233.31,234.75,110,1,2,1,AAPL,1818,4.121981634735291,-0.053207987861593316
2024-10-21T12:09:13.231145907Z,2024-10-21T12:09:13.230979969Z,10,2,38,A,B,2,233.77,27,130,165938,12185224,233.9,234.0,10,154,1,7,233.83,234.06,200,400,1,2,233.77,234.12,27,29,1,1,233.7,234.13,1200,400,1,1,233.66,234.17,1,1,1,1,233.58,234.25,505,50,2,1,233.53,234.41,10,600,1,2,233.45,234.43,15,105,1,2,233.4,234.5,110,63,2,4,233.39,234.75,10,1,1,1,AAPL,1828,4.349175777488246,-0.056140689717408515
2024-10-21T12:09:13.352430022Z,2024-10-21T12:09:13.352263576Z,10,2,38,C,A,2,234.12,29,130,166446,12185591,233.9,234.0,10,154,1,7,233.83,234.06,200,400,1,2,233.77,234.13,27,400,1,1,233.7,234.17,1200,1,1,1,233.66,234.25,1,50,1,1,233.58,234.41,505,600,2,2,233.53,234.43,10,105,1,2,233.45,234.5,15,63,1,4,233.4,234.75,110,1,2,1,233.39,234.79,10,2000,1,1,AAPL,3828,8.565936021970199,-0.11057211318930214
2024-10-21T12:09:13.352490529Z,2024-10-21T12:09:13.352324097Z,10,2,38,A,A,3,234.14,28,130,166432,12185592,233.9,234.0,10,154,1,7,233.83,234.06,200,400,1,2,233.77,234.13,27,400,1,1,233.7,234.14,1200,28,1,1,233.66,234.17,1,1,1,1,233.58,234.25,505,50,2,1,233.53,234.41,10,600,1,2,233.45,234.43,15,105,1,2,233.4,234.5,110,63,2,4,233.39,234.75,10,1,1,1,AAPL,3827,8.947951611263596,-0.11550330469844816
2024-10-21T12:09:14.174425372Z,2024-10-21T12:09:14.174258870Z,10,2,38,C,A,1,234.06,200,130,166502,12186227,233.9,234.0,10,154,1,7,233.83,234.06,200,200,1,1,233.77,234.13,27,400,1,1,233.7,234.14,1200,28,1,1,233.66,234.17,1,1,1,1,233.58,234.25,505,50,2,1,233.53,234.41,10,600,1,2,233.45,234.43,15,105,1,2,233.4,234.5,110,63,2,4,233.39,234.75,10,1,1,1,AAPL,3827,9.331775463550926,-0.12045783790194356
2024-10-21T12:09:14.174436198Z,2024-10-21T12:09:14.174269739Z,10,2,38,C,A,1,234.06,200,130,166459,12186228,233.9,234.0,10,154,1,7,233.83,234.13,200,400,1,1,233.77,234.14,27,28,1,1,233.7,234.17,1200,1,1,1,233.66,234.25,1,50,1,1,233.58,234.41,505,600,2,2,233.53,234.43,10,105,1,2,233.45,234.5,15,63,1,4,233.4,234.75,110,1,2,1,233.39,234.79,10,2000,1,1,AAPL,5827,13.429361604056234,-0.17335092014874035
2024-10-21T12:09:14.199575399Z,2024-10-21T12:09:14.199409178Z,10,2,38,A,A,1,234.07,200,130,166221,12186266,233.9,234.0,10,154,1,7,233.83,234.07,200,200,1,1,233.77,234.13,27,400,1,1,233.7,234.14,1200,28,1,1,233.66,234.17,1,1,1,1,233.58,234.25,505,50,2,1,233.53,234.41,10,600,1,2,233.45,234.43,15,105,1,2,233.4,234.5,110,63,2,4,233.39,234.75,10,1,1,1,AAPL,5826,13.957062563346541,-0.18016266962376506
2024-10-21T12:09:15.368534989Z,2024-10-21T12:09:15.368368108Z,10,2,38,C,B,1,233.83,200,130,166881,12187413,233.9,234.0,10,154,1,7,233.77,234.07,27,200,1,1,233.7,234.13,1200,400,1,1,233.66,234.14,1,28,1,1,233.58,234.17,505,1,2,1,233.53,234.25,10,50,1,1,233.45,234.41,15,600,1,2,233.4,234.43,110,105,2,2,233.39,234.5,10,63,1,4,233.31,234.75,110,1,2,1,AAPL,5716,14.147866342760233,-0.1826256318779969
2024-10-21T12:09:15.368547658Z,2024-10-21T12:09:15.368381335Z,10,2,38,A,B,2,233.74,400,130,166323,12187414,233.9,234.0,10,154,1,7,233.77,234.07,27,200,1,1,233.74,234.13,400,400,1,1,233.7,234.14,1200,28,1,1,233.66,234.17,1,1,1,1,233.58,234.25,505,50,2,1,233.53,234.41,10,600,1,2,233.45,234.43,15,105,1,2,233.4,234.5,110,63,2,4,233.39,234.75,10,1,1,1,AAPL,5726,14.690122778083197,-0.189625268554056
2024-10-21T12:09:15.369048334Z,2024-10-21T12:09:15.368882161Z,10,2,38,C,B,1,233.77,27,130,166173,12187416,233.9,234.0,10,154,1,7,233.74,234.07,400,200,1,1,233.7,234.13,1200,400,1,1,233.66,234.14,1,28,1,1,233.58,234.17,505,1,2,1,233.53,234.25,10,50,1,1,233.45,234.41,15,600,1,2,233.4,234.43,110,105,2,2,233.39,234.5,10,63,1,4,233.31,234.75,110,1,2,1,AAPL,5616,14.846984821550663,-0.19165009894981241
2024-10-21T12:09:15.369149972Z,2024-10-21T12:09:15.368983400Z,10,2,38,A,B,2,233.72,28,130,166572,12187417,233.9,234.0,10,154,1,7,233.74,234.07,400,200,1,1,233.72,234.13,28,400,1,1,233.7,234.14,1200,28,1,1,233.66,234.17,1,1,1,1,233.58,234.25,505,50,2,1,233.53,234.41,10,600,1,2,233.45,234.43,15,105,1,2,233.4,234.5,110,63,2,4,233.39,234.75,10,1,1,1,AAPL,5626,15.378587699316629,-0.19851221576008682
